Workbook

Sheet README
A2: Supplementary Material 3 to
A4: Advancing Metrics for Animal Welfare and Antibiotic Use in Sustainability Assessments of Diets
A5: by
A6: Lotta Rydhmer, Professor in Animal Breeding, Swedish University of Agricultural Sciences
A7: Elin Röös, Associate Professor in Sustainable Food Systems, Swedish University of Agricultural Sciences
A10: Explanation of the sheets:
A11: Diet assessment | B11: Calculations of the carbon footprint, PAALA and use of antibiotics for the different diet scenarios, including figures
A12: Cons data | B12: Diet data from FAOSTAT Food Balance Sheets
A13: Yields | B13: Yields of bonefree meat and fish
A14: Footprints Ireland | B14: Carbon footprint, PAALA and use of antibiotics for average products on the Irish market, from SAFAD, https://safad.se/
A15: Footprints Italy | B15: Carbon footprint, PAALA and use of antibiotics for average products on the Italian market, from SAFAD, https://safad.se/
A16: Footprints Poland | B16: Carbon footprint, PAALA and use of antibiotics for average products on the Polish market, from SAFAD, https://safad.se/

Sheet Diet assessment
A2: Diet assessment
A4: Baseline | O4: Scenarios
B5: Consumption, kg per year | E5: Carbon footprint, kg CO2e per year | H5: Animal welfare index | K5: Use of antibiotics index | O5: Consumption, kg per year | R5: Carbon footprint, kg CO2e per year | U5: Animal welfare index | X5: Use of antibiotics index
B6: Ireland | C6: Italy | D6: Poland | E6: Ireland | F6: Italy | G6: Poland | H6: Ireland | I6: Italy | J6: Poland | K6: Ireland | L6: Italy | M6: Poland | O6: Ireland, beef to chicken | P6: Ireland, beef to mussels | Q6: Italy, beef to rabbit | R6: Ireland, beef to chicken | S6: Ireland, beef to mussels | T6: Italy, beef to rabbit | U6: Ireland, beef to chicken | V6: Ireland, beef to mussels | W6: Italy, beef to rabbit | X6: Ireland, beef to chicken | Y6: Ireland, beef to mussels | Z6: Italy, beef to rabbit
A7: Aquatic Animals, Others | B7: ='Cons data'!B5*Yields!C18 -> 0.0038605714 | C7: ='Cons data'!C5*Yields!C18 -> 0.0057908571 | D7: ='Cons data'!D5*Yields!C18 -> 0.0028954286 | E7: =B7*'Footprints Ireland'!G5 -> 0.05970575 | F7: =C7*'Footprints Italy'!G5 -> 0.089558626 | G7: =D7*'Footprints Poland'!G5 -> 0.044779313 | H7: =B7*'Footprints Ireland'!X5 -> 0.060468899 | I7: =C7*'Footprints Italy'!X5 -> 0.090703349 | J7: =D7*'Footprints Poland'!X5 -> 0.045351674 | K7: =B7*'Footprints Ireland'!Y5 -> 0 | L7: =C7*'Footprints Italy'!Y5 -> 0 | M7: =D7*'Footprints Poland'!Y5 -> 0 | O7: ='Cons data'!$B$5*Yields!$C$18 -> 0.0038605714 | P7: ='Cons data'!$B$5*Yields!$C$18 -> 0.0038605714 | Q7: ='Cons data'!C5*Yields!C18 -> 0.0057908571 | R7: =O7*'Footprints Ireland'!G5 -> 0.05970575 | S7: =P7*'Footprints Ireland'!G5 -> 0.05970575 | T7: =Q7*'Footprints Italy'!G5 -> 0.089558626 | U7: =O7*'Footprints Ireland'!X5 -> 0.060468899 | V7: =P7*'Footprints Ireland'!X5 -> 0.060468899 | W7: =Q7*'Footprints Italy'!X5 -> 0.090703349 | X7: =O7*'Footprints Ireland'!Y5 -> 0 | Y7: =P7*'Footprints Ireland'!Y5 -> 0 | Z7: =Q7*'Footprints Italy'!Y5 -> 0
A8: Bovine Meat | B8: ='Cons data'!B6 -> 20.612 | C8: ='Cons data'!C6*Yields!C6 -> 11.56063 | D8: ='Cons data'!D6*Yields!C6 -> 0.72558 | E8: =B8*'Footprints Ireland'!G6 -> 663.56546 | F8: =C8*'Footprints Italy'!G6 -> 377.55634 | G8: =D8*'Footprints Poland'!G6 -> 23.612498 | H8: =B8*'Footprints Ireland'!X6 -> 7.72513 | I8: =C8*'Footprints Italy'!X6 -> 5.8804606 | J8: =D8*'Footprints Poland'!X6 -> 0.33427151 | K8: =B8*'Footprints Ireland'!Y6 -> 210.50568 | L8: =C8*'Footprints Italy'!Y6 -> 340.81256 | M8: =D8*'Footprints Poland'!Y6 -> 30.197672 | O8: ='Cons data'!$B$6/2 -> 10.306 | P8: ='Cons data'!$B$6/2 -> 10.306 | Q8: ='Cons data'!C6*Yields!C6/2 -> 5.780315 | R8: =O8*'Footprints Ireland'!G6 -> 331.78273 | S8: =P8*'Footprints Ireland'!G6 -> 331.78273 | T8: =Q8*'Footprints Italy'!G6 -> 188.77817 | U8: =O8*'Footprints Ireland'!X6 -> 3.862565 | V8: =P8*'Footprints Ireland'!X6 -> 3.862565 | W8: =Q8*'Footprints Italy'!X6 -> 2.9402303 | X8: =O8*'Footprints Ireland'!Y6 -> 105.25284 | Y8: =P8*'Footprints Ireland'!Y6 -> 105.25284 | Z8: =Q8*'Footprints Italy'!Y6 -> 170.40628
A9: Butter, Ghee | B9: ='Cons data'!B7 -> 1.912 | C9: ='Cons data'!C7 -> 2.464 | D9: ='Cons data'!D7 -> 4.514 | E9: =B9*'Footprints Ireland'!G7 -> 13.590685 | F9: =C9*'Footprints Italy'!G7 -> 22.608344 | G9: =D9*'Footprints Poland'!G7 -> 38.375928 | H9: =B9*'Footprints Ireland'!X7 -> 0.11712437 | I9: =C9*'Footprints Italy'!X7 -> 0.14564386 | J9: =D9*'Footprints Poland'!X7 -> 0.33464003 | K9: =B9*'Footprints Ireland'!Y7 -> 19.835928 | L9: =C9*'Footprints Italy'!Y7 -> 64.488284 | M9: =D9*'Footprints Poland'!Y7 -> 190.43279 | O9: ='Cons data'!$B$7 -> 1.912 | P9: ='Cons data'!$B$7 -> 1.912 | Q9: ='Cons data'!C7 -> 2.464 | R9: =O9*'Footprints Ireland'!G7 -> 13.590685 | S9: =P9*'Footprints Ireland'!G7 -> 13.590685 | T9: =Q9*'Footprints Italy'!G7 -> 22.608344 | U9: =O9*'Footprints Ireland'!X7 -> 0.11712437 | V9: =P9*'Footprints Ireland'!X7 -> 0.11712437 | W9: =Q9*'Footprints Italy'!X7 -> 0.14564386 | X9: =O9*'Footprints Ireland'!Y7 -> 19.835928 | Y9: =P9*'Footprints Ireland'!Y7 -> 19.835928 | Z9: =Q9*'Footprints Italy'!Y7 -> 64.488284
A10: Cephalopods | B10: ='Cons data'!B8*Yields!C11 -> 0.1617 | C10: ='Cons data'!C8*Yields!C11 -> 2.8371 | D10: ='Cons data'!D8*Yields!C11 -> 0.02499 | E10: =B10*'Footprints Ireland'!G8 -> 1.7323526 | F10: =C10*'Footprints Italy'!G8 -> 30.394913 | G10: =D10*'Footprints Poland'!G8 -> 0.26772721 | H10: =B10*'Footprints Ireland'!X8 -> 0.09985474 | I10: =C10*'Footprints Italy'!X8 -> 1.7519968 | J10: =D10*'Footprints Poland'!X8 -> 0.015432096 | K10: =B10*'Footprints Ireland'!Y8 -> 0 | L10: =C10*'Footprints Italy'!Y8 -> 0 | M10: =D10*'Footprints Poland'!Y8 -> 0 | O10: ='Cons data'!$B$8*Yields!$C$11 -> 0.1617 | P10: ='Cons data'!$B$8*Yields!$C$11 -> 0.1617 | Q10: ='Cons data'!C8*Yields!C11 -> 2.8371 | R10: =O10*'Footprints Ireland'!G8 -> 1.7323526 | S10: =P10*'Footprints Ireland'!G8 -> 1.7323526 | T10: =Q10*'Footprints Italy'!G8 -> 30.394913 | U10: =O10*'Footprints Ireland'!X8 -> 0.09985474 | V10: =P10*'Footprints Ireland'!X8 -> 0.09985474 | W10: =Q10*'Footprints Italy'!X8 -> 1.7519968 | X10: =O10*'Footprints Ireland'!Y8 -> 0 | Y10: =P10*'Footprints Ireland'!Y8 -> 0 | Z10: =Q10*'Footprints Italy'!Y8 -> 0
A11: Cream | B11: ='Cons data'!B9 -> 2.318 | C11: ='Cons data'!C9 -> 4.146 | D11: ='Cons data'!D9 -> 6.626 | E11: =B11*'Footprints Ireland'!G9 -> 8.11002 | F11: =C11*'Footprints Italy'!G9 -> 18.916299 | G11: =D11*'Footprints Poland'!G9 -> 27.519155 | H11: =B11*'Footprints Ireland'!X9 -> 0.07203717 | I11: =C11*'Footprints Italy'!X9 -> 0.12432675 | J11: =D11*'Footprints Poland'!X9 -> 0.24920204 | K11: =B11*'Footprints Ireland'!Y9 -> 12.200058 | L11: =C11*'Footprints Italy'!Y9 -> 55.049482 | M11: =D11*'Footprints Poland'!Y9 -> 141.8128 | O11: ='Cons data'!$B$9 -> 2.318 | P11: ='Cons data'!$B$9 -> 2.318 | Q11: ='Cons data'!C9 -> 4.146 | R11: =O11*'Footprints Ireland'!G9 -> 8.11002 | S11: =P11*'Footprints Ireland'!G9 -> 8.11002 | T11: =Q11*'Footprints Italy'!G9 -> 18.916299 | U11: =O11*'Footprints Ireland'!X9 -> 0.07203717 | V11: =P11*'Footprints Ireland'!X9 -> 0.07203717 | W11: =Q11*'Footprints Italy'!X9 -> 0.12432675 | X11: =O11*'Footprints Ireland'!Y9 -> 12.200058 | Y11: =P11*'Footprints Ireland'!Y9 -> 12.200058 | Z11: =Q11*'Footprints Italy'!Y9 -> 55.049482
A12: Crustaceans | B12: ='Cons data'!B10*Yields!C12 -> 0.337 | C12: ='Cons data'!C10*Yields!C12 -> 1.136 | D12: ='Cons data'!D10*Yields!C12 -> 0.119 | E12: =B12*'Footprints Ireland'!G10 -> 5.2118808 | F12: =C12*'Footprints Italy'!G10 -> 17.568832 | G12: =D12*'Footprints Poland'!G10 -> 1.8403971 | H12: =B12*'Footprints Ireland'!X10 -> 5.2784981 | I12: =C12*'Footprints Italy'!X10 -> 17.793394 | J12: =D12*'Footprints Poland'!X10 -> 1.8639207 | K12: =B12*'Footprints Ireland'!Y10 -> 0 | L12: =C12*'Footprints Italy'!Y10 -> 0 | M12: =D12*'Footprints Poland'!Y10 -> 0 | O12: ='Cons data'!$B$10*Yields!$C$12 -> 0.337 | P12: ='Cons data'!$B$10*Yields!$C$12 -> 0.337 | Q12: ='Cons data'!C10*Yields!C12 -> 1.136 | R12: =O12*'Footprints Ireland'!G10 -> 5.2118808 | S12: =P12*'Footprints Ireland'!G10 -> 5.2118808 | T12: =Q12*'Footprints Italy'!G10 -> 17.568832 | U12: =O12*'Footprints Ireland'!X10 -> 5.2784981 | V12: =P12*'Footprints Ireland'!X10 -> 5.2784981 | W12: =Q12*'Footprints Italy'!X10 -> 17.793394 | X12: =O12*'Footprints Ireland'!Y10 -> 0 | Y12: =P12*'Footprints Ireland'!Y10 -> 0 | Z12: =Q12*'Footprints Italy'!Y10 -> 0
A13: Demersal Fish | B13: ='Cons data'!B11*Yields!C13 -> 5.038432 | C13: ='Cons data'!C11*Yields!C13 -> 4.228684 | D13: ='Cons data'!D11*Yields!C13 -> 2.450924 | E13: =B13*'Footprints Ireland'!G11 -> 34.267931 | F13: =C13*'Footprints Italy'!G11 -> 28.760585 | G13: =D13*'Footprints Poland'!G11 -> 16.66949 | H13: =B13*'Footprints Ireland'!X11 -> 59.581384 | I13: =C13*'Footprints Italy'!X11 -> 50.005804 | J13: =D13*'Footprints Poland'!X11 -> 28.983113 | K13: =B13*'Footprints Ireland'!Y11 -> 502.12797 | L13: =C13*'Footprints Italy'!Y11 -> 421.42883 | M13: =D13*'Footprints Poland'!Y11 -> 244.25803 | O13: ='Cons data'!$B$11*Yields!$C$13 -> 5.038432 | P13: ='Cons data'!$B$11*Yields!$C$13 -> 5.038432 | Q13: ='Cons data'!C11*Yields!C13 -> 4.228684 | R13: =O13*'Footprints Ireland'!G11 -> 34.267931 | S13: =P13*'Footprints Ireland'!G11 -> 34.267931 | T13: =Q13*'Footprints Italy'!G11 -> 28.760585 | U13: =O13*'Footprints Ireland'!X11 -> 59.581384 | V13: =P13*'Footprints Ireland'!X11 -> 59.581384 | W13: =Q13*'Footprints Italy'!X11 -> 50.005804 | X13: =O13*'Footprints Ireland'!Y11 -> 502.12797 | Y13: =P13*'Footprints Ireland'!Y11 -> 502.12797 | Z13: =Q13*'Footprints Italy'!Y11 -> 421.42883
A14: Eggs | B14: ='Cons data'!B12 -> 11.692 | C14: ='Cons data'!C12 -> 11.608 | D14: ='Cons data'!D12 -> 8.364 | E14: =B14*'Footprints Ireland'!G12 -> 12.290783 | F14: =C14*'Footprints Italy'!G12 -> 13.970663 | G14: =D14*'Footprints Poland'!G12 -> 11.713966 | H14: =B14*'Footprints Ireland'!X12 -> 94.217209 | I14: =C14*'Footprints Italy'!X12 -> 108.70738 | J14: =D14*'Footprints Poland'!X12 -> 91.338499 | K14: =B14*'Footprints Ireland'!Y12 -> 5.1076173 | L14: =C14*'Footprints Italy'!Y12 -> 17.701897 | M14: =D14*'Footprints Poland'!Y12 -> 16.924576 | O14: ='Cons data'!$B$12 -> 11.692 | P14: ='Cons data'!$B$12 -> 11.692 | Q14: ='Cons data'!C12 -> 11.608 | R14: =O14*'Footprints Ireland'!G12 -> 12.290783 | S14: =P14*'Footprints Ireland'!G12 -> 12.290783 | T14: =Q14*'Footprints Italy'!G12 -> 13.970663 | U14: =O14*'Footprints Ireland'!X12 -> 94.217209 | V14: =P14*'Footprints Ireland'!X12 -> 94.217209 | W14: =Q14*'Footprints Italy'!X12 -> 108.70738 | X14: =O14*'Footprints Ireland'!Y12 -> 5.1076173 | Y14: =P14*'Footprints Ireland'!Y12 -> 5.1076173 | Z14: =Q14*'Footprints Italy'!Y12 -> 17.701897
A15: Freshwater Fish | B15: ='Cons data'!B13*Yields!C14 -> 1.10704 | C15: ='Cons data'!C13*Yields!C14 -> 1.40896 | D15: ='Cons data'!D13*Yields!C14 -> 0.37814 | E15: =B15*'Footprints Ireland'!G13 -> 14.243324 | F15: =C15*'Footprints Italy'!G13 -> 18.127867 | G15: =D15*'Footprints Poland'!G13 -> 4.8651997 | H15: =B15*'Footprints Ireland'!X13 -> 6.544304 | I15: =C15*'Footprints Italy'!X13 -> 8.3291142 | J15: =D15*'Footprints Poland'!X13 -> 2.2353873 | K15: =B15*'Footprints Ireland'!Y13 -> 0 | L15: =C15*'Footprints Italy'!Y13 -> 0 | M15: =D15*'Footprints Poland'!Y13 -> 0 | O15: ='Cons data'!$B$13*Yields!$C$14 -> 1.10704 | P15: ='Cons data'!$B$13*Yields!$C$14 -> 1.10704 | Q15: ='Cons data'!C13*Yields!C14 -> 1.40896 | R15: =O15*'Footprints Ireland'!G13 -> 14.243324 | S15: =P15*'Footprints Ireland'!G13 -> 14.243324 | T15: =Q15*'Footprints Italy'!G13 -> 18.127867 | U15: =O15*'Footprints Ireland'!X13 -> 6.544304 | V15: =P15*'Footprints Ireland'!X13 -> 6.544304 | W15: =Q15*'Footprints Italy'!X13 -> 8.3291142 | X15: =O15*'Footprints Ireland'!Y13 -> 0 | Y15: =P15*'Footprints Ireland'!Y13 -> 0 | Z15: =Q15*'Footprints Italy'!Y13 -> 0
A16: Marine Fish, Other | B16: ='Cons data'!B14*Yields!C15 -> 0.003912 | C16: ='Cons data'!C14*Yields!C15 -> 0.479872 | D16: ='Cons data'!D14*Yields!C15 -> 0 | E16: =B16*'Footprints Ireland'!G14 -> 0.026725271 | F16: =C16*'Footprints Italy'!G14 -> 3.2782999 | G16: =D16*'Footprints Poland'!G14 -> 0 | H16: =B16*'Footprints Ireland'!X14 -> 0.014096879 | I16: =C16*'Footprints Italy'!X14 -> 1.7292172 | J16: =D16*'Footprints Poland'!X14 -> 0 | K16: =B16*'Footprints Ireland'!Y14 -> 0 | L16: =C16*'Footprints Italy'!Y14 -> 0 | M16: =D16*'Footprints Poland'!Y14 -> 0 | O16: ='Cons data'!$B$14*Yields!$C$15 -> 0.003912 | P16: ='Cons data'!$B$14*Yields!$C$15 -> 0.003912 | Q16: ='Cons data'!C14*Yields!C15 -> 0.479872 | R16: =O16*'Footprints Ireland'!G14 -> 0.026725271 | S16: =P16*'Footprints Ireland'!G14 -> 0.026725271 | T16: =Q16*'Footprints Italy'!G14 -> 3.2782999 | U16: =O16*'Footprints Ireland'!X14 -> 0.014096879 | V16: =P16*'Footprints Ireland'!X14 -> 0.014096879 | W16: =Q16*'Footprints Italy'!X14 -> 1.7292172 | X16: =O16*'Footprints Ireland'!Y14 -> 0 | Y16: =P16*'Footprints Ireland'!Y14 -> 0 | Z16: =Q16*'Footprints Italy'!Y14 -> 0
A17: Meat, Other | B17: ='Cons data'!B15*Yields!C9 -> 0.69459 | C17: ='Cons data'!C15*Yields!C9 -> 0.93023 | D17: ='Cons data'!D15*Yields!C9 -> 0.06987 | E17: =B17*'Footprints Ireland'!G15 -> 4.4486834 | F17: =C17*'Footprints Italy'!G15 -> 7.5555221 | G17: =D17*'Footprints Poland'!G15 -> 0.53733539 | H17: =B17*'Footprints Ireland'!X15 -> 3.0728004 | I17: =C17*'Footprints Italy'!X15 -> 3.6289143 | J17: =D17*'Footprints Poland'!X15 -> 0.31759446 | K17: =B17*'Footprints Ireland'!Y15 -> 62.913032 | L17: =C17*'Footprints Italy'!Y15 -> 213.92101 | M17: =D17*'Footprints Poland'!Y15 -> 22.217656 | O17: ='Cons data'!$B$15*Yields!$C$9 -> 0.69459 | P17: ='Cons data'!$B$15*Yields!$C$9 -> 0.69459 | Q17: ='Cons data'!C15*Yields!C9 -> 0.93023 | R17: =O17*'Footprints Ireland'!G15 -> 4.4486834 | S17: =P17*'Footprints Ireland'!G15 -> 4.4486834 | T17: =Q17*'Footprints Italy'!G15 -> 7.5555221 | U17: =O17*'Footprints Ireland'!X15 -> 3.0728004 | V17: =P17*'Footprints Ireland'!X15 -> 3.0728004 | W17: =Q17*'Footprints Italy'!X15 -> 3.6289143 | X17: =O17*'Footprints Ireland'!Y15 -> 62.913032 | Y17: =P17*'Footprints Ireland'!Y15 -> 62.913032 | Z17: =Q17*'Footprints Italy'!Y15 -> 213.92101
A18: Milk - Excluding Butter | B18: ='Cons data'!B16 -> 288.688 | C18: ='Cons data'!C16 -> 217.016 | D18: ='Cons data'!D16 -> 174.926 | E18: =B18*'Footprints Ireland'!G16 -> 286.60388 | F18: =C18*'Footprints Italy'!G16 -> 276.17413 | G18: =D18*'Footprints Poland'!G16 -> 205.91547 | H18: =B18*'Footprints Ireland'!X16 -> 2.3559283 | I18: =C18*'Footprints Italy'!X16 -> 1.7089021 | J18: =D18*'Footprints Poland'!X16 -> 1.7276058 | K18: =B18*'Footprints Ireland'!Y16 -> 398.99488 | L18: =C18*'Footprints Italy'!Y16 -> 756.6688 | M18: =D18*'Footprints Poland'!Y16 -> 983.12442 | O18: ='Cons data'!$B$16 -> 288.688 | P18: ='Cons data'!$B$16 -> 288.688 | Q18: ='Cons data'!C16 -> 217.016 | R18: =O18*'Footprints Ireland'!G16 -> 286.60388 | S18: =P18*'Footprints Ireland'!G16 -> 286.60388 | T18: =Q18*'Footprints Italy'!G16 -> 276.17413 | U18: =O18*'Footprints Ireland'!X16 -> 2.3559283 | V18: =P18*'Footprints Ireland'!X16 -> 2.3559283 | W18: =Q18*'Footprints Italy'!X16 -> 1.7089021 | X18: =O18*'Footprints Ireland'!Y16 -> 398.99488 | Y18: =P18*'Footprints Ireland'!Y16 -> 398.99488 | Z18: =Q18*'Footprints Italy'!Y16 -> 756.6688
A19: Molluscs, Other | B19: ='Cons data'!B17*Yields!C16 -> 0.35343 | C19: ='Cons data'!C17*Yields!C16 -> 1.95811 | D19: ='Cons data'!D17*Yields!C16 -> 0.09009 | E19: =B19*'Footprints Ireland'!G17 -> 5.2335641 | F19: =C19*'Footprints Italy'!G17 -> 28.995542 | G19: =D19*'Footprints Poland'!G17 -> 1.3340458 | H19: =B19*'Footprints Ireland'!X17 -> 4.8112669 | I19: =C19*'Footprints Italy'!X17 -> 26.655886 | J19: =D19*'Footprints Poland'!X17 -> 1.2264014 | K19: =B19*'Footprints Ireland'!Y17 -> 0 | L19: =C19*'Footprints Italy'!Y17 -> 0 | M19: =D19*'Footprints Poland'!Y17 -> 0 | O19: ='Cons data'!$B$17*Yields!$C$16 -> 0.35343 | P19: ='Cons data'!$B$17*Yields!$C$16 -> 0.35343 | Q19: ='Cons data'!C17*Yields!C16 -> 1.95811 | R19: =O19*'Footprints Ireland'!G17 -> 5.2335641 | S19: =P19*'Footprints Ireland'!G17 -> 5.2335641 | T19: =Q19*'Footprints Italy'!G17 -> 28.995542 | U19: =O19*'Footprints Ireland'!X17 -> 4.8112669 | V19: =P19*'Footprints Ireland'!X17 -> 4.8112669 | W19: =Q19*'Footprints Italy'!X17 -> 26.655886 | X19: =O19*'Footprints Ireland'!Y17 -> 0 | Y19: =P19*'Footprints Ireland'!Y17 -> 0 | Z19: =Q19*'Footprints Italy'!Y17 -> 0
A20: Mutton & Goat Meat | B20: ='Cons data'!B18*Yields!C6 -> 2.34771 | C20: ='Cons data'!C18*Yields!C6 -> 0.58797 | D20: ='Cons data'!D18*Yields!C6 -> 0.02224 | E20: =B20*'Footprints Ireland'!G18 -> 113.73048 | F20: =C20*'Footprints Italy'!G18 -> 25.386262 | G20: =D20*'Footprints Poland'!G18 -> 1.0252084 | H20: =B20*'Footprints Ireland'!X18 -> 10.356911 | I20: =C20*'Footprints Italy'!X18 -> 2.8503346 | J20: =D20*'Footprints Poland'!X18 -> 0.14262585 | K20: =B20*'Footprints Ireland'!Y18 -> 62.56921 | L20: =C20*'Footprints Italy'!Y18 -> 44.649471 | M20: =D20*'Footprints Poland'!Y18 -> 1.7806285 | O20: ='Cons data'!$B$18*Yields!$C$6 -> 2.34771 | P20: ='Cons data'!$B$18*Yields!$C$6 -> 2.34771 | Q20: ='Cons data'!C18*Yields!C6 -> 0.58797 | R20: =O20*'Footprints Ireland'!G18 -> 113.73048 | S20: =P20*'Footprints Ireland'!G18 -> 113.73048 | T20: =Q20*'Footprints Italy'!G18 -> 25.386262 | U20: =O20*'Footprints Ireland'!X18 -> 10.356911 | V20: =P20*'Footprints Ireland'!X18 -> 10.356911 | W20: =Q20*'Footprints Italy'!X18 -> 2.8503346 | X20: =O20*'Footprints Ireland'!Y18 -> 62.56921 | Y20: =P20*'Footprints Ireland'!Y18 -> 62.56921 | Z20: =Q20*'Footprints Italy'!Y18 -> 44.649471
A21: Offals, Edible | B21: ='Cons data'!B19 -> 2.642 | C21: ='Cons data'!C19 -> 2.542 | D21: ='Cons data'!D19 -> 1.06 | E21: =B21*'Footprints Ireland'!G19 -> 16.92138 | F21: =C21*'Footprints Italy'!G19 -> 20.646654 | G21: =D21*'Footprints Poland'!G19 -> 8.1519324 | H21: =B21*'Footprints Ireland'!X19 -> 11.687958 | I21: =C21*'Footprints Italy'!X19 -> 9.91658 | J21: =D21*'Footprints Poland'!X19 -> 4.8182357 | K21: =B21*'Footprints Ireland'!Y19 -> 239.30122 | L21: =C21*'Footprints Italy'!Y19 -> 584.57286 | M21: =D21*'Footprints Poland'!Y19 -> 337.06477 | O21: ='Cons data'!$B$19 -> 2.642 | P21: ='Cons data'!$B$19 -> 2.642 | Q21: ='Cons data'!C19 -> 2.542 | R21: =O21*'Footprints Ireland'!G19 -> 16.92138 | S21: =P21*'Footprints Ireland'!G19 -> 16.92138 | T21: =Q21*'Footprints Italy'!G19 -> 20.646654 | U21: =O21*'Footprints Ireland'!X19 -> 11.687958 | V21: =P21*'Footprints Ireland'!X19 -> 11.687958 | W21: =Q21*'Footprints Italy'!X19 -> 9.91658 | X21: =O21*'Footprints Ireland'!Y19 -> 239.30122 | Y21: =P21*'Footprints Ireland'!Y19 -> 239.30122 | Z21: =Q21*'Footprints Italy'!Y19 -> 584.57286
A22: Pelagic Fish | B22: ='Cons data'!B20*Yields!C17 -> 3.38104 | C22: ='Cons data'!C20*Yields!C17 -> 2.74976 | D22: ='Cons data'!D20*Yields!C17 -> 2.82048 | E22: =B22*'Footprints Ireland'!G20 -> 17.785524 | F22: =C22*'Footprints Italy'!G20 -> 14.464757 | G22: =D22*'Footprints Poland'!G20 -> 14.83677 | H22: =B22*'Footprints Ireland'!X20 -> 36.232829 | I22: =C22*'Footprints Italy'!X20 -> 29.467733 | J22: =D22*'Footprints Poland'!X20 -> 30.225602 | K22: =B22*'Footprints Ireland'!Y20 -> 0 | L22: =C22*'Footprints Italy'!Y20 -> 0 | M22: =D22*'Footprints Poland'!Y20 -> 0 | O22: ='Cons data'!$B$20*Yields!$C$17 -> 3.38104 | P22: ='Cons data'!$B$20*Yields!$C$17 -> 3.38104 | Q22: ='Cons data'!C20*Yields!C17 -> 2.74976 | R22: =O22*'Footprints Ireland'!G20 -> 17.785524 | S22: =P22*'Footprints Ireland'!G20 -> 17.785524 | T22: =Q22*'Footprints Italy'!G20 -> 14.464757 | U22: =O22*'Footprints Ireland'!X20 -> 36.232829 | V22: =P22*'Footprints Ireland'!X20 -> 36.232829 | W22: =Q22*'Footprints Italy'!X20 -> 29.467733 | X22: =O22*'Footprints Ireland'!Y20 -> 0 | Y22: =P22*'Footprints Ireland'!Y20 -> 0 | Z22: =Q22*'Footprints Italy'!Y20 -> 0
A23: Pigmeat | B23: ='Cons data'!B21*Yields!C7 -> 17.14304 | C23: ='Cons data'!C21*Yields!C7 -> 21.8241 | D23: ='Cons data'!D21*Yields!C7 -> 32.47124 | E23: =B23*'Footprints Ireland'!G21 -> 109.79709 | F23: =C23*'Footprints Italy'!G21 -> 177.25989 | G23: =D23*'Footprints Poland'!G21 -> 249.72014 | H23: =B23*'Footprints Ireland'!X21 -> 75.839185 | I23: =C23*'Footprints Italy'!X21 -> 85.137857 | J23: =D23*'Footprints Poland'!X21 -> 147.5982 | K23: =B23*'Footprints Ireland'!Y21 -> 1552.7443 | L23: =C23*'Footprints Italy'!Y21 -> 5018.7948 | M23: =D23*'Footprints Poland'!Y21 -> 10325.388 | O23: ='Cons data'!$B$21*Yields!$C$7 -> 17.14304 | P23: ='Cons data'!$B$21*Yields!$C$7 -> 17.14304 | Q23: ='Cons data'!C21*Yields!C7 -> 21.8241 | R23: =O23*'Footprints Ireland'!G21 -> 109.79709 | S23: =P23*'Footprints Ireland'!G21 -> 109.79709 | T23: =Q23*'Footprints Italy'!G21 -> 177.25989 | U23: =O23*'Footprints Ireland'!X21 -> 75.839185 | V23: =P23*'Footprints Ireland'!X21 -> 75.839185 | W23: =Q23*'Footprints Italy'!X21 -> 85.137857 | X23: =O23*'Footprints Ireland'!Y21 -> 1552.7443 | Y23: =P23*'Footprints Ireland'!Y21 -> 1552.7443 | Z23: =Q23*'Footprints Italy'!Y21 -> 5018.7948
A24: Poultry Meat | B24: ='Cons data'!B22*Yields!C8 -> 20.33878 | C24: ='Cons data'!C22*Yields!C8 -> 15.30452 | D24: ='Cons data'!D22*Yields!C8 -> 24.10562 | E24: =B24*'Footprints Ireland'!G22 -> 49.343551 | F24: =C24*'Footprints Italy'!G22 -> 33.606183 | G24: =D24*'Footprints Poland'!G22 -> 72.106842 | H24: =B24*'Footprints Ireland'!X22 -> 1909.0576 | I24: =C24*'Footprints Italy'!X22 -> 1447.1691 | J24: =D24*'Footprints Poland'!X22 -> 2286.2167 | K24: =B24*'Footprints Ireland'!Y22 -> 783.87055 | L24: =C24*'Footprints Italy'!Y22 -> 1900.4355 | M24: =D24*'Footprints Poland'!Y22 -> 4018.7271 | O24: ='Cons data'!$B$22*Yields!$C$8+O8 -> 30.64478 | P24: ='Cons data'!B22*Yields!C8 -> 20.33878 | Q24: ='Cons data'!C22*Yields!C8 -> 15.30452 | R24: =O24*'Footprints Ireland'!G22 -> 74.346754 | S24: =P24*'Footprints Ireland'!G22 -> 49.343551 | T24: =Q24*'Footprints Italy'!G22 -> 33.606183 | U24: =O24*'Footprints Ireland'!X22 -> 2876.4091 | V24: =P24*'Footprints Ireland'!X22 -> 1909.0576 | W24: =Q24*'Footprints Italy'!X22 -> 1447.1691 | X24: =O24*'Footprints Ireland'!Y22 -> 1181.0709 | Y24: =P24*'Footprints Ireland'!Y22 -> 783.87055 | Z24: =Q24*'Footprints Italy'!Y22 -> 1900.4355
A25: Mussels | P25: =P8 -> 10.306 | S25: =P25*'Footprints Ireland'!G23 -> 22.49006 | V25: =P25*'Footprints Ireland'!X23 -> 46.067437 | Y25: =P25*'Footprints Ireland'!Y23 -> 0
A26: Rabbit | Q26: =Q8 -> 5.780315 | T26: =Q26*'Footprints Italy'!G24 -> 64.313676 | W26: =Q26*'Footprints Italy'!X24 -> 706.05303 | Z26: =Q26*'Footprints Italy'!Y24 -> 21743.839
B27: Ireland | C27: Italy | D27: Poland | E27: Ireland | F27: Italy | G27: Poland | H27: Ireland | I27: Italy | J27: Poland | K27: Ireland | L27: Italy | M27: Poland | O27: Ireland | P27: Italy | Q27: Poland | R27: Ireland, beef to chicken | S27: Ireland, beef to mussels | T27: Italy, beef to rabbit | U27: Ireland, beef to chicken | V27: Ireland, beef to mussels | W27: Italy, beef to rabbit | X27: Ireland, beef to chicken | Y27: Ireland, beef to mussels | Z27: Italy, beef to rabbit
A28: Ruminant meat | B28: =B8+B20 -> 22.95971 | C28: =C8+C20 -> 12.1486 | D28: =D8+D20 -> 0.74782 | E28: =E8+E20 -> 777.29595 | F28: =F8+F20 -> 402.9426 | G28: =G8+G20 -> 24.637707 | H28: =H8+H20 -> 18.082041 | I28: =I8+I20 -> 8.7307952 | ... M28: =M8+M20 -> 31.978301 | O28: =O8+O20 -> 12.65371 | P28: =P8+P20 -> 12.65371 | Q28: =Q8+Q20 -> 6.368285 | R28: ='Diet assessment'!R8+'Diet assessment'!R20 -> 445.51321 | S28: ='Diet assessment'!S8+'Diet assessment'!S20 -> 445.51321 | T28: ='Diet assessment'!T8+'Diet assessment'!T20 -> 214.16443 | U28: ='Diet assessment'!U8+'Diet assessment'!U20 -> 14.219476 | V28: ='Diet assessment'!V8+'Diet assessment'!V20 -> 14.219476 | W28: ='Diet assessment'!W8+'Diet assessment'!W20 -> 5.7905649 | X28: ='Diet assessment'!X8+'Diet assessment'!X20 -> 167.82205 | Y28: ='Diet assessment'!Y8+'Diet assessment'!Y20 -> 167.82205 | Z28: ='Diet assessment'!Z8+'Diet assessment'!Z20 -> 215.05575
A29: Pig meat | B29: =B23+B21 -> 19.78504 | C29: =C23+C21 -> 24.3661 | D29: =D23+D21 -> 33.53124 | E29: =E23+E21 -> 126.71847 | F29: =F23+F21 -> 197.90655 | G29: =G23+G21 -> 257.87208 | H29: =H23+H21 -> 87.527143 | I29: =I23+I21 -> 95.054437 | ... M29: =M23+M21 -> 10662.453 | O29: =O23+O21 -> 19.78504 | P29: =P23+P21 -> 19.78504 | Q29: =Q23+Q21 -> 24.3661 | R29: ='Diet assessment'!R23+'Diet assessment'!R21 -> 126.71847 | S29: ='Diet assessment'!S23+'Diet assessment'!S21 -> 126.71847 | T29: ='Diet assessment'!T23+'Diet assessment'!T21 -> 197.90655 | U29: ='Diet assessment'!U23+'Diet assessment'!U21 -> 87.527143 | V29: ='Diet assessment'!V23+'Diet assessment'!V21 -> 87.527143 | W29: ='Diet assessment'!W23+'Diet assessment'!W21 -> 95.054437 | X29: ='Diet assessment'!X23+'Diet assessment'!X21 -> 1792.0455 | Y29: ='Diet assessment'!Y23+'Diet assessment'!Y21 -> 1792.0455 | Z29: ='Diet assessment'!Z23+'Diet assessment'!Z21 -> 5603.3677
A30: Poultry meat | B30: =B24 -> 20.33878 | C30: =C24 -> 15.30452 | D30: =D24 -> 24.10562 | E30: =E24 -> 49.343551 | F30: =F24 -> 33.606183 | G30: =G24 -> 72.106842 | H30: =H24 -> 1909.0576 | I30: =I24 -> 1447.1691 | ... M30: =M24 -> 4018.7271 | O30: =O24 -> 30.64478 | P30: =P24 -> 20.33878 | Q30: =Q24 -> 15.30452 | R30: ='Diet assessment'!R24 -> 74.346754 | S30: ='Diet assessment'!S24 -> 49.343551 | T30: ='Diet assessment'!T24 -> 33.606183 | U30: ='Diet assessment'!U24 -> 2876.4091 | V30: ='Diet assessment'!V24 -> 1909.0576 | W30: ='Diet assessment'!W24 -> 1447.1691 | X30: ='Diet assessment'!X24 -> 1181.0709 | Y30: ='Diet assessment'!Y24 -> 783.87055 | Z30: ='Diet assessment'!Z24 -> 1900.4355
A31: Egg | B31: =B14 -> 11.692 | C31: =C14 -> 11.608 | D31: =D14 -> 8.364 | E31: =E14 -> 12.290783 | F31: =F14 -> 13.970663 | G31: =G14 -> 11.713966 | H31: =H14 -> 94.217209 | I31: =I14 -> 108.70738 | ... M31: =M14 -> 16.924576 | O31: =O14 -> 11.692 | P31: =P14 -> 11.692 | Q31: =Q14 -> 11.608 | R31: ='Diet assessment'!R14 -> 12.290783 | S31: ='Diet assessment'!S14 -> 12.290783 | T31: ='Diet assessment'!T14 -> 13.970663 | U31: ='Diet assessment'!U14 -> 94.217209 | V31: ='Diet assessment'!V14 -> 94.217209 | W31: ='Diet assessment'!W14 -> 108.70738 | X31: ='Diet assessment'!X14 -> 5.1076173 | Y31: ='Diet assessment'!Y14 -> 5.1076173 | Z31: ='Diet assessment'!Z14 -> 17.701897
A32: Dairy | B32: =B11+B18+B9 -> 292.918 | C32: =C11+C18+C9 -> 223.626 | D32: =D11+D18+D9 -> 186.066 | E32: =E11+E18+E9 -> 308.30459 | F32: =F11+F18+F9 -> 317.69877 | G32: =G11+G18+G9 -> 271.81055 | H32: =H11+H18+H9 -> 2.5450899 | I32: =I11+I18+I9 -> 1.9788727 | ... M32: =M11+M18+M9 -> 1315.37 | O32: =O11+O18+O9 -> 292.918 | P32: =P11+P18+P9 -> 292.918 | Q32: =Q11+Q18+Q9 -> 223.626 | R32: ='Diet assessment'!R11+'Diet assessment'!R18+'Diet assessment'!R9 -> 308.30459 | S32: ='Diet assessment'!S11+'Diet assessment'!S18+'Diet assessment'!S9 -> 308.30459 | T32: ='Diet assessment'!T11+'Diet assessment'!T18+'Diet assessment'!T9 -> 317.69877 | U32: ='Diet assessment'!U11+'Diet assessment'!U18+'Diet assessment'!U9 -> 2.5450899 | V32: ='Diet assessment'!V11+'Diet assessment'!V18+'Diet assessment'!V9 -> 2.5450899 | W32: ='Diet assessment'!W11+'Diet assessment'!W18+'Diet assessment'!W9 -> 1.9788727 | X32: ='Diet assessment'!X11+'Diet assessment'!X18+'Diet assessment'!X9 -> 431.03086 | Y32: ='Diet assessment'!Y11+'Diet assessment'!Y18+'Diet assessment'!Y9 -> 431.03086 | Z32: ='Diet assessment'!Z11+'Diet assessment'!Z18+'Diet assessment'!Z9 -> 876.20656
A33: Blue food | B33: =B10+B12+B13+B15+B22+B19 -> 10.378642 | C33: =C10+C12+C13+C15+C22+C19 -> 14.318614 | D33: =D10+D12+D13+D15+D22+D19 -> 5.883624 | E33: =E10+E12+E13+E15+E22+E19 -> 78.474576 | F33: =F10+F12+F13+F15+F22+F19 -> 138.3125 | G33: =G10+G12+G13+G15+G22+G19 -> 39.81363 | H33: =H10+H12+H13+H15+H22+H19 -> 112.54814 | I33: =I10+I12+I13+I15+I22+I19 -> 134.00393 | ... M33: =M10+M12+M13+M15+M22+M19 -> 244.25803 | O33: =O10+O12+O13+O15+O22+O19 -> 10.378642 | P33: =P10+P12+P13+P15+P22+P19 -> 10.378642 | Q33: =Q10+Q12+Q13+Q15+Q22+Q19 -> 14.318614 | R33: ='Diet assessment'!R10+'Diet assessment'!R12+'Diet assessment'!R13+'Diet assessment'!R15+'Diet assessment'!R22+'Diet assessment'!R19 -> 78.474576 | S33: ='Diet assessment'!S10+'Diet assessment'!S12+'Diet assessment'!S13+'Diet assessment'!S15+'Diet assessment'!S22+'Diet assessment'!S19 -> 78.474576 | T33: ='Diet assessment'!T10+'Diet assessment'!T12+'Diet assessment'!T13+'Diet assessment'!T15+'Diet assessment'!T22+'Diet assessment'!T19 -> 138.3125 | U33: ='Diet assessment'!U10+'Diet assessment'!U12+'Diet assessment'!U13+'Diet assessment'!U15+'Diet assessment'!U22+'Diet assessment'!U19 -> 112.54814 | V33: ='Diet assessment'!V10+'Diet assessment'!V12+'Diet assessment'!V13+'Diet assessment'!V15+'Diet assessment'!V22+'Diet assessment'!V19 -> 112.54814 | W33: ='Diet assessment'!W10+'Diet assessment'!W12+'Diet assessment'!W13+'Diet assessment'!W15+'Diet assessment'!W22+'Diet assessment'!W19 -> 134.00393 | X33: ='Diet assessment'!X10+'Diet assessment'!X12+'Diet assessment'!X13+'Diet assessment'!X15+'Diet assessment'!X22+'Diet assessment'!X19 -> 502.12797 | Y33: ='Diet assessment'!Y10+'Diet assessment'!Y12+'Diet assessment'!Y13+'Diet assessment'!Y15+'Diet assessment'!Y22+'Diet assessment'!Y19 -> 502.12797 | Z33: ='Diet assessment'!Z10+'Diet assessment'!Z12+'Diet assessment'!Z13+'Diet assessment'!Z15+'Diet assessment'!Z22+'Diet assessment'!Z19 -> 421.42883
A34: Mussels | P34: =P25 -> 10.306 | S34: ='Diet assessment'!S25 -> 22.49006 | V34: ='Diet assessment'!V25 -> 46.067437 | Y34: ='Diet assessment'!Y25 -> 0
A35: Rabbit | Q35: =Q26 -> 5.780315 | T35: ='Diet assessment'!T26 -> 64.313676 | W35: ='Diet assessment'!W26 -> 706.05303 | Z35: ='Diet assessment'!Z26 -> 21743.839
A36: Sum: | E36: =SUM(E28:E35) -> 1352.4279 | F36: =SUM(F28:F35) -> 1104.4373 | G36: =SUM(G28:G35) -> 677.95477 | H36: =SUM(H28:H35) -> 2223.9773 | I36: =SUM(I28:I35) -> 1795.6445 | J36: =SUM(J28:J35) -> 2597.3099 | K36: =SUM(K28:K35) -> 3787.2574 | L36: =SUM(L28:L35) -> 9204.6026 | M36: =SUM(M28:M35) -> 16289.711 | R36: =SUM(R28:R35) -> 1045.6484 | S36: =SUM(S28:S34) -> 1043.1352 | T36: =SUM(T28:T35) -> 979.97277 | U36: =SUM(U28:U35) -> 3187.4661 | V36: =SUM(V28:V35) -> 2266.1821 | W36: =SUM(W28:W35) -> 2498.7573 | X36: =SUM(X28:X35) -> 4079.2048 | Y36: =SUM(Y28:Y35) -> 3682.0045 | Z36: =SUM(Z28:Z35) -> 30778.035
A39: Baseline | P39: Scenarios Ireland | AG39: Scenario Italy

Sheet Cons data
A2: Consumption data
B4: Ireland | C4: Italy | D4: Polen | F4: Source: FAOSTAT Food Balance Sheets average 2017-2021
A5: Aquatic Animals, Others | B5: 0.008 | C5: 0.012 | D5: 0.006
A6: Bovine Meat | B6: 20.612 | C6: 16.634 | D6: 1.044
A7: Butter, Ghee | B7: 1.912 | C7: 2.464 | D7: 4.514
A8: Cephalopods | B8: 0.22 | C8: 3.86 | D8: 0.034
A9: Cream | B9: 2.318 | C9: 4.146 | D9: 6.626
A10: Crustaceans | B10: 0.674 | C10: 2.272 | D10: 0.238
A11: Demersal Fish | B11: 9.296 | C11: 7.802 | D11: 4.522
A12: Eggs | B12: 11.692 | C12: 11.608 | D12: 8.364
A13: Freshwater Fish | B13: 2.992 | C13: 3.808 | D13: 1.022
A14: Marine Fish, Other | B14: 0.012 | C14: 1.472 | D14: 0
A15: Meat, Other | B15: 1.014 | C15: 1.358 | D15: 0.102
A16: Milk - Excluding Butter | B16: 288.688 | C16: 217.016 | D16: 174.926
... A22: Poultry Meat | B22: 26.414 | C22: 19.876 | D22: 31.306
A24: Total ruminant meat | B24: =B6+B18 -> 23.99 | C24: =C6+C18 -> 17.48 | D24: =D6+D18 -> 1.076
A25: Pigmeat | B25: =B21 -> 29.056 | C25: =C21 -> 36.99 | D25: =D21 -> 55.036
A26: Total poultry meat | B26: =B22 -> 26.414 | C26: =C22 -> 19.876 | D26: =D22 -> 31.306
A27: Total blue food | B27: =B5+B8+B10+B11+B13+B14+B17+B20 -> 20.622 | C27: =C5+C8+C10+C11+C13+C14+C17+C20 -> 29.6 | D27: =D5+D8+D10+D11+D13+D14+D17+D20 -> 11.48
A28: Total milk | B28: =B16 -> 288.688 | C28: =C16 -> 217.016 | D28: =D16 -> 174.926
A29: Butter | B29: =B7 -> 1.912 | C29: =C7 -> 2.464 | D29: =D7 -> 4.514
A30: Cream | B30: =B9 -> 2.318 | C30: =C9 -> 4.146 | D30: =D9 -> 6.626
A32: Total meat and seafood | B32: =SUM(B24:B27) -> 100.082 | C32: =SUM(C24:C27) -> 103.946 | D32: =SUM(D24:D27) -> 98.898

Sheet Yields
A2: Yields
A4: Conversion to bonefree meat-fish
C5: Carcass weight->bonefree
A6: Ruminant | C6: 0.695
A7: Pig | C7: 0.59
A8: Poultry | C8: 0.77
A9: Meat, other | C9: =AVERAGE(C6:C8) -> 0.685
C10: Live weight->edible weight
A11: Cephalopods | B11: Octopus | C11: 0.735
A12: Crustaceans | B12: Crab | C12: 0.5
A13: Demersal Fish | B13: Salmon | C13: 0.542
A14: Freshwater Fish | B14: Perch | C14: 0.37
A15: Marine Fish, Other | B15: Cod | C15: 0.326
A16: Molluscs, Other | B16: Snail | C16: 0.385
A17: Pelagic Fish | B17: Herring | C17: 0.52
A18: Aquatic animals, other | C18: =AVERAGE(C11:C17) -> 0.48257143
A21: FAOSTAT Food Balance Sheets gives supply in carcass weight for meat and liveweight for fish
A22: https://www.fao.org/economic/the-statistics-division-ess/publications-studies/publications/food-balance-sheets/en/

Sheet Footprints Ireland
A2: Footprints Ireland | C2: Source: https://safad.se/ Version 1.245
A4: FAOSTAT name | B4: Code | C4: Name | D4: L1 Category | E4: L2 Category | F4: Amount (g) | G4: Carbon footprint, total (kg CO2e) | H4: Carbon dioxide, total (kg CO2) | I4: Methane, fossil, total (kg CH4) | J4: Methane, biogenic, total (kg CH4) | K4: Nitrous oxide, total (kg N2O) | L4: Carbon footprint, primary production (kg CO2e) | M4: Carbon dioxide, primary production (kg CO2) | N4: Methane, fossil, primary production (kg CH4) | O4: Methane, biogenic, primary production (kg CH4) | P4: Nitrous oxide, primary production (kg N2O) | Q4: Cropland (m2*year/kg) | R4: New N input (kg N/kg) | S4: New P input (kg P/kg) | T4: Water (m3/kg) | U4: Pesticides (g a.i/kg) | V4: Biodiversity (E/MSY/kg) | W4: Ammonia (kg NH3/kg) | X4: Animal welfare (index) | Y4: Antibiotics (index) | Z4: Mineral fertiliser production (kg CO2e) | AA4: Capital goods (kg CO2e) | AB4: Soil emissions (kg CO2e) | AC4: Energy primary production (kg CO2e) | AD4: Land use change (kg CO2e) | AE4: Enteric fermentation (kg CO2e) | AF4: Manure management (kg CO2e) | AG4: Mineral fertiliser production (kg CO2) | AH4: Capital goods (kg CO2) | AI4: Energy primary production (kg CO2) | AJ4: Land use change (kg CO2) | AK4: Mineral fertiliser production (kg CH4, fossil) | AL4: Capital goods (kg CH4, fossil) | AM4: Energy primary production (kg CH4, fossil) | AN4: Soil emissions (kg CH4, biogenic) | AO4: Enteric fermentation (kg CH4, biogenic) | AP4: Manure management (kg CH4, biogenic) | AQ4: Mineral fertiliser production (kg N2O) | AR4: Capital goods (kg N2O) | AS4: Soil emissions (kg N2O) | AT4: Energy primary production (kg N2O) | AU4: Manure management (kg N2O) | AV4: Processing (kg CO2e) | AW4: Processing (kg CO2) | AX4: Processing (kg CH4, fossil) | AY4: Processing (kg N2O) | AZ4: Packaging (kg CO2e) | BA4: Packaging (kg CO2) | BB4: Packaging (kg CH4, fossil) | BC4: Packaging (kg CH4, biogenic) | BD4: Packaging (kg N2O) | BE4: Transports (kg CO2e) | BF4: Transports (kg CO2) | BG4: Transports (kg CH4, fossil) | BH4: Transports (kg N2O)
A5: Aquatic Animals, Others | B5: A.07.04.001 | C5: Crab (Cancer spp.) | D5: Fish and other seafood (including amphibians, reptiles, snails and insects) | E5: Crustaceans | F5: 1000 | G5: 15.465522 | H5: 15.437059 | I5: 0.00075647881 | J5: 1.4206898e-05 | K5: 2.0278824e-05 | L5: 15.06452 | M5: 15.06452 | N5: 0 | O5: 0 | P5: 0 | Q5: 0 | R5: 0 | S5: 0 | T5: 0 | U5: 0 | V5: 0 | W5: 0 | X5: 15.663199 | Y5: 0 | Z5: 0 | AA5: 0 | AB5: 0 | AC5: 15.06452 | AD5: 0 | AE5: 0 | AF5: 0 | AG5: 0 | AH5: 0 | AI5: 15.06452 | AJ5: 0 | AK5: 0 | AL5: 0 | AM5: 0 | AN5: 0 | AO5: 0 | AP5: 0 | AQ5: 0 | AR5: 0 | AS5: 0 | AT5: 0 | AU5: 0 | AV5: 0 | AW5: 0 | AX5: 0 | AY5: 0 | AZ5: 0.13254929 | BA5: 0.11476727 | BB5: 0.00052683544 | BC5: 1.4206898e-05 | BD5: 6.2224755e-06 | BE5: 0.26845257 | BF5: 0.25777181 | BG5: 0.00022964337 | BH5: 1.4056349e-05
A6: Bovine Meat | B6: A.06.01.001 | C6: Beef meat (Bos spp.) | D6: Meat and meat products (including edible offal) | E6: Livestock meat | F6: 1000 | G6: 32.193162 | H6: 4.7187251 | I6: 0.0089788387 | J6: 0.7898955 | K6: 0.021537325 | L6: 32.017664 | M6: 4.5831291 | N6: 0.0076740908 | O6: 0.78986961 | P6: 0.021536143 | Q6: 11.788427 | R6: 0.59432732 | S6: 0.031865779 | T6: 0.072335627 | U6: 3.0843475 | V6: 2.6086767e-12 | W6: 0.19863122 | X6: 0.37478799 | Y6: 10.212773 | Z6: 2.0481926 | AA6: 0.98042073 | AB6: 2.9345973 | AC6: 2.4877444 | AD6: 0.10862925 | AE6: 18.766206 | AF6: 4.6918735 | AG6: 1.2216932 | AH6: 0.8729046 | AI6: 2.4301624 | AJ6: 0.10851483 | AK6: 0.0022355685 | AL6: 0.0031051228 | AM6: 0.50596366 | AN6: 0 | AO6: 0.69504466 | AP6: 0.094824954 | AQ6: 0.0027834415 | AR6: 5.4884511e-05 | AS6: 0.010749441 | AT6: 0.50471518 | AU6: 0.0078080577 | AV6: 0 | AW6: 0 | AX6: 0 | AY6: 0 | AZ6: 0.16715055 | BA6: 0.12759129 | BB6: 0.0012976377 | BC6: 2.5882108e-05 | BD6: 6.9902061e-07 | BE6: 0.0083482584 | BF6: 0.0080046431 | BG6: 7.1101341e-06 | BH6: 4.8253969e-07
A7: Butter, Ghee | B7: A.11.01.001 | C7: Butter | D7: Animal and vegetable fats and oils | E7: Animal fat | F7: 1000 | G7: 7.108099 | H7: 1.793202 | I7: 0.0036138537 | J7: 0.14701036 | K7: 0.0045345214 | L7: 6.5731793 | M7: 1.2851842 | N7: 0.0029673871 | O7: 0.14696075 | P7: 0.0045114535 | Q7: 2.6603215 | R7: 0.1110424 | S7: 0.0056218016 | T7: 0.019989336 | U7: 0.43161232 | V7: 7.0507383e-13 | W7: 0.0035198733 | X7: 0.061257517 | Y7: 10.374439 | Z7: 0.35055735 | AA7: 0.20250654 | AB7: 0.73111118 | AC7: 0.93884282 | AD7: 0.045427279 | AE7: 3.5061059 | AF7: 0.7986282 | AG7: 0.21123707 | AH7: 0.18138056 | AI7: 0.91253448 | AJ7: 0.045427279 | AK7: 0.00039154347 | AL7: 0.00064192384 | AM7: 0.28107556 | AN7: 0 | AO7: 0.12985577 | AP7: 0.017104974 | AQ7: 0.00046759077 | AR7: 7.3137627e-06 | AS7: 0.0026780629 | AT7: 0.28041911 | AU7: 0.0012336773 | AV7: 0.33107503 | AW7: 0.32262273 | AX7: 0.00017801225 | AY7: 1.1529421e-05 | AZ7: 0.096777195 | BA7: 0.08268709 | BB7: 0.00037723014 | BC7: 4.9615312e-05 | BD7: 5.5275943e-06 | BE7: 0.10706748 | BF7: 0.10270802 | BG7: 9.122425e-05 | BH7: 6.010902e-06
A8: Cephalopods | B8: A.07.05.002 | C8: Octopus (Octopus vulgaris) | D8: Fish and other seafood (including amphibians, reptiles, snails and insects) | E8: Water molluscs | F8: 1000 | G8: 10.713374 | H8: 10.684911 | I8: 0.00075647881 | J8: 1.4206898e-05 | K8: 2.0278824e-05 | L8: 10.312372 | M8: 10.312372 | N8: 0 | O8: 0 | P8: 0 | Q8: 0 | R8: 0 | S8: 0 | T8: 0 | U8: 0 | V8: 0 | W8: 0 | X8: 0.61753086 | Y8: 0 | Z8: 0 | AA8: 0 | AB8: 0 | AC8: 10.312372 | AD8: 0 | AE8: 0 | AF8: 0 | AG8: 0 | AH8: 0 | AI8: 10.312372 | AJ8: 0 | AK8: 0 | AL8: 0 | AM8: 0 | AN8: 0 | AO8: 0 | AP8: 0 | AQ8: 0 | AR8: 0 | AS8: 0 | AT8: 0 | AU8: 0 | AV8: 0 | AW8: 0 | AX8: 0 | AY8: 0 | AZ8: 0.13254929 | BA8: 0.11476727 | BB8: 0.00052683544 | BC8: 1.4206898e-05 | BD8: 6.2224755e-06 | BE8: 0.26845257 | BF8: 0.25777181 | BG8: 0.00022964337 | BH8: 1.4056349e-05
A9: Cream | B9: A.08.05.001.004 | C9: Cream 40 % fat | D9: Milk and dairy products | E9: Cream and cream products | F9: 1000 | G9: 3.4987144 | H9: 0.79995161 | I9: 0.0019193301 | J9: 0.074602254 | K9: 0.0022978238 | L9: 3.3347194 | M9: 0.65200238 | N9: 0.0015054212 | O9: 0.074556442 | P9: 0.0022887603 | Q9: 1.34964 | R9: 0.056334268 | S9: 0.0028520644 | T9: 0.010141033 | U9: 0.21896649 | V9: 3.5769957e-13 | W9: 0.0017857097 | X9: 0.031077295 | Y9: 5.2631829 | Z9: 0.17784551 | AA9: 0.10273605 | AB9: 0.3709089 | AC9: 0.47629576 | AD9: 0.023046265 | AE9: 1.7787252 | AF9: 0.40516177 | AG9: 0.10716524 | AH9: 0.092018374 | AI9: 0.46294895 | AJ9: 0.023046265 | AK9: 0.00019863867 | AL9: 0.00032566218 | AM9: 0.14259586 | AN9: 0 | AO9: 0.06587871 | AP9: 0.0086777319 | AQ9: 0.00023721916 | AR9: 3.7104338e-06 | AS9: 0.0013586406 | AT9: 0.14226283 | AU9: 0.00062587183 | AV9: 0.011033314 | AW9: 0.010587129 | AX9: 1.1409576e-05 | AY9: 3.8893475e-07 | AZ9: 0.08935693 | BA9: 0.076347166 | BB9: 0.00034830651 | BC9: 4.5811123e-05 | BD9: 5.1037732e-06 | BE9: 0.063604717 | BF9: 0.061014929 | BG9: 5.4192857e-05 | BH9: 3.5708483e-06
A10: Crustaceans | B10: A.07.04.001 | C10: Crab (Cancer spp.) | D10: Fish and other seafood (including amphibians, reptiles, snails and insects) | E10: Crustaceans | F10: 1000 | G10: 15.465522 | H10: 15.437059 | I10: 0.00075647881 | J10: 1.4206898e-05 | K10: 2.0278824e-05 | L10: 15.06452 | M10: 15.06452 | N10: 0 | O10: 0 | P10: 0 | Q10: 0 | R10: 0 | S10: 0 | T10: 0 | U10: 0 | V10: 0 | W10: 0 | X10: 15.663199 | Y10: 0 | Z10: 0 | AA10: 0 | AB10: 0 | AC10: 15.06452 | AD10: 0 | AE10: 0 | AF10: 0 | AG10: 0 | AH10: 0 | AI10: 15.06452 | AJ10: 0 | AK10: 0 | AL10: 0 | AM10: 0 | AN10: 0 | AO10: 0 | AP10: 0 | AQ10: 0 | AR10: 0 | AS10: 0 | AT10: 0 | AU10: 0 | AV10: 0 | AW10: 0 | AX10: 0 | AY10: 0 | AZ10: 0.13254929 | BA10: 0.11476727 | BB10: 0.00052683544 | BC10: 1.4206898e-05 | BD10: 6.2224755e-06 | BE10: 0.26845257 | BF10: 0.25777181 | BG10: 0.00022964337 | BH10: 1.4056349e-05
A11: Demersal Fish | B11: I.07.01.006.001 | C11: Salmon (Salmo salar) | D11: Fish and other seafood (including amphibians, reptiles, snails and insects) | E11: Fish meat | F11: 1000 | G11: 6.8013086 | H11: 4.1060372 | I11: 0.0015624228 | J11: 1.8453188e-05 | K11: 0.0097004137 | L11: 6.4268277 | M11: 3.7636599 | N11: 0.00065091671 | O11: 0 | P11: 0.0096841409 | Q11: 5.3688854 | R11: 0.069999123 | S11: 0.010547821 | T11: 0.045471931 | U11: 0.00059360692 | V11: 1.3168238e-12 | W11: 0.0021385837 | X11: 11.825382 | Y11: 99.65957 | Z11: 3.6129575 | AA11: 0.086281674 | AB11: 1.8943168 | AC11: 0.61367362 | AD11: 0.21959812 | AE11: 0 | AF11: 0 | AG11: 2.8441065 | AH11: 0.086281674 | AI11: 0.61367362 | AJ11: 0.21959812 | AK11: 0.00065091671 | AL11: 0 | AM11: 0 | AN11: 0 | AO11: 0 | AP11: 0 | AQ11: 0.0027452515 | AR11: 0 | AS11: 0.0069388894 | AT11: 0 | AU11: 0 | AV11: 0 | AW11: 0 | AX11: 0 | AY11: 0 | AZ11: 0.10602834 | BA11: 0.084605512 | BB11: 0.00068186277 | BC11: 1.8453188e-05 | BD11: 2.2164258e-06 | BE11: 0.26845257 | BF11: 0.25777181 | BG11: 0.00022964337 | BH11: 1.4056349e-05
A12: Eggs | B12: A.09.01.001 | C12: Whole egg, chicken | D12: Eggs and egg products | E12: Eggs, fresh | F12: 1000 | G12: 1.051213 | H12: 0.56992626 | I12: 0.00086722125 | J12: 0.0012155517 | K12: 0.001548072 | L12: 0.99356234 | M12: 0.5178337 | N12: 0.00071735212 | O12: 0.0012092095 | P12: 0.0015446992 | Q12: 4.934153 | R12: 0.056741192 | S12: 0.0068444881 | T12: 0.021383091 | U12: 0.88535806 | V12: 6.7384753e-13 | W12: 0.0023657573 | X12: 8.0582628 | Y12: 0.43684719 | Z12: 0.24362692 | AA12: 0.0725419 | AB12: 0.33154342 | AC12: 0.29289072 | AD12: 0.01973066 | AE12: 0 | AF12: 0.033228718 | AG12: 0.14952796 | AH12: 0.064790146 | AI12: 0.28611668 | AJ12: 0.01973066 | AK12: 0.00026996363 | AL12: 0.00023773625 | AM12: 0.047532184 | AN12: 0 | AO12: 0 | AP12: 0.0012092095 | AQ12: 0.00031521628 | AR12: 2.4440071e-06 | AS12: 0.0012144448 | AT12: 0.047384976 | AU12: 2.1247622e-06 | AV12: 0 | AW12: 0 | AX12: 0 | AY12: 0 | AZ12: 0.044823494 | BA12: 0.039790356 | BB12: 0.00013894839 | BC12: 6.3421725e-06 | BD12: 2.6418931e-06 | BE12: 0.012827187 | BF12: 0.012302207 | BG12: 1.0920734e-05 | BH12: 7.3092307e-07
A13: Freshwater Fish | B13: A.07.01.010 | C13: Perch (Perca) | D13: Fish and other seafood (including amphibians, reptiles, snails and insects) | E13: Fish meat | F13: 1000 | G13: 12.866133 | H13: 12.83403 | I13: 0.00091150614 | J13: 1.8453188e-05 | K13: 1.6272774e-05 | L13: 12.491652 | M13: 12.491652 | N13: 0 | O13: 0 | P13: 0 | Q13: 0 | R13: 0 | S13: 0 | T13: 0 | U13: 0 | V13: 0 | W13: 0 | X13: 5.9115335 | Y13: 0 | Z13: 0 | AA13: 0 | AB13: 0 | AC13: 12.491652 | AD13: 0 | AE13: 0 | AF13: 0 | AG13: 0 | AH13: 0 | AI13: 12.491652 | AJ13: 0 | AK13: 0 | AL13: 0 | AM13: 0 | AN13: 0 | AO13: 0 | AP13: 0 | AQ13: 0 | AR13: 0 | AS13: 0 | AT13: 0 | AU13: 0 | AV13: 0 | AW13: 0 | AX13: 0 | AY13: 0 | AZ13: 0.10602834 | BA13: 0.084605512 | BB13: 0.00068186277 | BC13: 1.8453188e-05 | BD13: 2.2164258e-06 | BE13: 0.26845257 | BF13: 0.25777181 | BG13: 0.00022964337 | BH13: 1.4056349e-05
A14: Marine Fish, Other | B14: I.07.01.017.001 | C14: Cod (Gadus morhua) | D14: Fish and other seafood (including amphibians, reptiles, snails and insects) | E14: Fish meat | F14: 1000 | G14: 6.8316131 | H14: 6.7995096 | I14: 0.00091150614 | J14: 1.8453188e-05 | K14: 1.6272774e-05 | L14: 6.4571322 | M14: 6.4571322 | N14: 0 | O14: 0 | P14: 0 | Q14: 0 | R14: 0 | S14: 0 | T14: 0 | U14: 0 | V14: 0 | W14: 0 | X14: 3.6034967 | Y14: 0 | Z14: 0 | AA14: 0 | AB14: 0 | AC14: 6.4571322 | AD14: 0 | AE14: 0 | AF14: 0 | AG14: 0 | AH14: 0 | AI14: 6.4571322 | AJ14: 0 | AK14: 0 | AL14: 0 | AM14: 0 | AN14: 0 | AO14: 0 | AP14: 0 | AQ14: 0 | AR14: 0 | AS14: 0 | AT14: 0 | AU14: 0 | AV14: 0 | AW14: 0 | AX14: 0 | AY14: 0 | AZ14: 0.10602834 | BA14: 0.084605512 | BB14: 0.00068186277 | BC14: 1.8453188e-05 | BD14: 2.2164258e-06 | BE14: 0.26845257 | BF14: 0.25777181 | BG14: 0.00022964337 | BH14: 1.4056349e-05
A15: Meat, Other | B15: A.06.01.003 | C15: Pork / piglet meat (Sus scrofa) | D15: Meat and meat products (including edible offal) | E15: Livestock meat | F15: 1000 | G15: 6.4047617 | H15: 3.4224285 | I15: 0.0054712266 | J15: 0.042156212 | K15: 0.0061577764 | L15: 6.2062631 | M15: 3.264768 | N15: 0.0041468906 | O15: 0.04213033 | P15: 0.0061553072 | Q15: 12.472189 | R15: 0.16280307 | S15: 0.024126722 | T15: 0.32207142 | U15: 2.671007 | V15: 2.6438603e-12 | W15: 0.056903818 | X15: 4.4239053 | Y15: 90.575782 | Z15: 0.71817999 | AA15: 0.21462086 | AB15: 0.98570762 | AC15: 2.4088774 | AD15: 0.33922634 | AE15: 0.31705491 | AF15: 1.222596 | AG15: 0.43712319 | AH15: 0.19169827 | AI15: 2.3374676 | AJ15: 0.33922634 | AK15: 0.00079580701 | AL15: 0.00070246351 | AM15: 0.54791402 | AN15: 0 | AO15: 0.011742775 | AP15: 0.030387555 | AQ15: 0.00094264377 | AR15: 7.28636e-06 | AS15: 0.0036106506 | AT15: 0.54630041 | AU15: 0.0014730111 | AV15: 0 | AW15: 0 | AX15: 0 | AY15: 0 | AZ15: 0.16715055 | BA15: 0.12759129 | BB15: 0.0012976377 | BC15: 2.5882108e-05 | BD15: 6.9902061e-07 | BE15: 0.031348031 | BF15: 0.030069185 | BG15: 2.6698193e-05 | BH15: 1.7701125e-06
A16: Milk - Excluding Butter | B16: A.08.01.001.003 | C16: Cow milk, 1 - 2.9% fat (semi-skimmed milk) | D16: Milk and dairy products | E16: Liquid milk | F16: 1000 | G16: 0.99278073 | H16: 0.27417066 | I16: 0.0007692664 | J16: 0.019624126 | K16: 0.00060745249 | L16: 0.87568806 | M16: 0.17121401 | N16: 0.00039531942 | O16: 0.019578315 | P16: 0.00060102209 | Q16: 0.35441172 | R16: 0.014793222 | S16: 0.0007489442 | T16: 0.0026630071 | U16: 0.057499992 | V16: 9.3930914e-14 | W16: 0.0004689224 | X16: 0.0081608114 | Y16: 1.3820972 | Z16: 0.046701736 | AA16: 0.026978203 | AB16: 0.097399646 | AC16: 0.12507394 | AD16: 0.0060518852 | AE16: 0.46708829 | AF16: 0.10639436 | AG16: 0.028141295 | AH16: 0.024163769 | AI16: 0.12156911 | AJ16: 0.0060518852 | AK16: 5.2161964e-05 | AL16: 8.5517984e-05 | AM16: 0.037445276 | AN16: 0 | AO16: 0.017299566 | AP16: 0.0022787483 | AQ16: 6.2293091e-05 | AR16: 9.7434961e-07 | AS16: 0.00035677526 | AT16: 0.037357823 | AU16: 0.0001643522 | AV16: 0.011033314 | AW16: 0.010587129 | AX16: 1.1409576e-05 | AY16: 3.8893475e-07 | AZ16: 0.08935693 | BA16: 0.076347166 | BB16: 0.00034830651 | BC16: 4.5811123e-05 | BD16: 5.1037732e-06 | BE16: 0.016702422 | BF16: 0.016022351 | BG16: 1.4230894e-05 | BH16: 9.3769484e-07
... A23: Mussels | B23: A.07.05.007 | C23: Mussel (Mytilus edulis) | D23: Fish and other seafood (including amphibians, reptiles, snails and insects) | E23: Water molluscs | F23: 1000 | G23: 2.1822297 | H23: 2.153767 | I23: 0.00075647881 | J23: 1.4206898e-05 | K23: 2.0278824e-05 | L23: 1.7812279 | M23: 1.7812279 | N23: 0 | O23: 0 | P23: 0 | Q23: 0 | R23: 0 | S23: 0 | T23: 0 | U23: 0 | V23: 0 | W23: 0 | X23: 4.4699629 | Y23: 0 | Z23: 0 | AA23: 0 | AB23: 0 | AC23: 1.7812279 | AD23: 0 | AE23: 0 | AF23: 0 | AG23: 0 | AH23: 0 | AI23: 1.7812279 | AJ23: 0 | AK23: 0 | AL23: 0 | AM23: 0 | AN23: 0 | AO23: 0 | AP23: 0 | AQ23: 0 | AR23: 0 | AS23: 0 | AT23: 0 | AU23: 0 | AV23: 0 | AW23: 0 | AX23: 0 | AY23: 0 | AZ23: 0.13254929 | BA23: 0.11476727 | BB23: 0.00052683544 | BC23: 1.4206898e-05 | BD23: 6.2224755e-06 | BE23: 0.26845257 | BF23: 0.25777181 | BG23: 0.00022964337 | BH23: 1.4056349e-05

Sheet Footprints Italy
A2: Footprints Italy | C2: Source: https://safad.se/ Version 1.245
A4: FAOSTAT name | B4: Code | C4: Name | D4: L1 Category | E4: L2 Category | F4: Amount (g) | G4: Carbon footprint, total (kg CO2e) | H4: Carbon dioxide, total (kg CO2) | I4: Methane, fossil, total (kg CH4) | J4: Methane, biogenic, total (kg CH4) | K4: Nitrous oxide, total (kg N2O) | L4: Carbon footprint, primary production (kg CO2e) | M4: Carbon dioxide, primary production (kg CO2) | N4: Methane, fossil, primary production (kg CH4) | O4: Methane, biogenic, primary production (kg CH4) | P4: Nitrous oxide, primary production (kg N2O) | Q4: Cropland (m2*year/kg) | R4: New N input (kg N/kg) | S4: New P input (kg P/kg) | T4: Water (m3/kg) | U4: Pesticides (g a.i/kg) | V4: Biodiversity (E/MSY/kg) | W4: Ammonia (kg NH3/kg) | X4: Animal welfare (index) | Y4: Antibiotics (index) | Z4: Mineral fertiliser production (kg CO2e) | AA4: Capital goods (kg CO2e) | AB4: Soil emissions (kg CO2e) | AC4: Energy primary production (kg CO2e) | AD4: Land use change (kg CO2e) | AE4: Enteric fermentation (kg CO2e) | AF4: Manure management (kg CO2e) | AG4: Mineral fertiliser production (kg CO2) | AH4: Capital goods (kg CO2) | AI4: Energy primary production (kg CO2) | AJ4: Land use change (kg CO2) | AK4: Mineral fertiliser production (kg CH4, fossil) | AL4: Capital goods (kg CH4, fossil) | AM4: Energy primary production (kg CH4, fossil) | AN4: Soil emissions (kg CH4, biogenic) | AO4: Enteric fermentation (kg CH4, biogenic) | AP4: Manure management (kg CH4, biogenic) | AQ4: Mineral fertiliser production (kg N2O) | AR4: Capital goods (kg N2O) | AS4: Soil emissions (kg N2O) | AT4: Energy primary production (kg N2O) | AU4: Manure management (kg N2O) | AV4: Processing (kg CO2e) | AW4: Processing (kg CO2) | AX4: Processing (kg CH4, fossil) | AY4: Processing (kg N2O) | AZ4: Packaging (kg CO2e) | BA4: Packaging (kg CO2) | BB4: Packaging (kg CH4, fossil) | BC4: Packaging (kg CH4, biogenic) | BD4: Packaging (kg N2O) | BE4: Transports (kg CO2e) | BF4: Transports (kg CO2) | BG4: Transports (kg CH4, fossil) | BH4: Transports (kg N2O)
A5: Aquatic Animals, Others | B5: A.07.04.001 | C5: Crab (Cancer spp.) | D5: Fish and other seafood (including amphibians, reptiles, snails and insects) | E5: Crustaceans | F5: 1000 | G5: 15.465522 | H5: 15.437059 | I5: 0.00075647881 | J5: 1.4206898e-05 | K5: 2.0278824e-05 | L5: 15.06452 | M5: 15.06452 | N5: 0 | O5: 0 | P5: 0 | Q5: 0 | R5: 0 | S5: 0 | T5: 0 | U5: 0 | V5: 0 | W5: 0 | X5: 15.663199 | Y5: 0 | Z5: 0 | AA5: 0 | AB5: 0 | AC5: 15.06452 | AD5: 0 | AE5: 0 | AF5: 0 | AG5: 0 | AH5: 0 | AI5: 15.06452 | AJ5: 0 | AK5: 0 | AL5: 0 | AM5: 0 | AN5: 0 | AO5: 0 | AP5: 0 | AQ5: 0 | AR5: 0 | AS5: 0 | AT5: 0 | AU5: 0 | AV5: 0 | AW5: 0 | AX5: 0 | AY5: 0 | AZ5: 0.13254929 | BA5: 0.11476727 | BB5: 0.00052683544 | BC5: 1.4206898e-05 | BD5: 6.2224755e-06 | BE5: 0.26845257 | BF5: 0.25777181 | BG5: 0.00022964337 | BH5: 1.4056349e-05
A6: Bovine Meat | B6: A.06.01.001 | C6: Beef meat (Bos spp.) | D6: Meat and meat products (including edible offal) | E6: Livestock meat | F6: 1000 | G6: 32.658803 | H6: 6.084773 | I6: 0.022165822 | J6: 0.73141423 | K6: 0.022583532 | L6: 32.426619 | M6: 5.8948138 | N6: 0.020812656 | O6: 0.73138835 | P6: 0.022579129 | Q6: 26.041837 | R6: 0.52241435 | S6: 0.031061251 | T6: 0.80751833 | U6: 1.918571 | V6: 4.7380869e-11 | W6: 0.24970909 | X6: 0.50866264 | Y6: 29.480449 | Z6: 1.5596789 | AA6: 0.77906915 | AB6: 2.8896938 | AC6: 4.5691368 | AD6: 0.47254439 | AE6: 16.525253 | AF6: 5.6312425 | AG6: 0.9347433 | AH6: 0.69488893 | AI6: 4.4491055 | AJ6: 0.47247611 | AK6: 0.0017000881 | AL6: 0.0024587223 | AM6: 2.561057 | AN6: 0 | AO6: 0.61204642 | AP6: 0.11934194 | AQ6: 0.0021035641 | AR6: 3.9964454e-05 | AS6: 0.010584959 | AT6: 2.5577299 | AU6: 0.0088242131 | AV6: 0 | AW6: 0 | AX6: 0 | AY6: 0 | AZ6: 0.16715055 | BA6: 0.12759129 | BB6: 0.0012976377 | BC6: 2.5882108e-05 | BD6: 6.9902061e-07 | BE6: 0.065033594 | BF6: 0.062367845 | BG6: 5.5528303e-05 | BH6: 3.7033184e-06
A7: Butter, Ghee | B7: A.11.01.001 | C7: Butter | D7: Animal and vegetable fats and oils | E7: Animal fat | F7: 1000 | G7: 9.1754641 | H7: 2.8169196 | I7: 0.010229061 | J7: 0.16992752 | K7: 0.0053687743 | L7: 8.4426917 | M7: 2.1266441 | N7: 0.0091710726 | O7: 0.16987791 | P7: 0.0053335024 | Q7: 7.3094063 | R7: 0.11765166 | S7: 0.0082685943 | T7: 0.065078972 | U7: 0.57168424 | V7: 3.9034732e-12 | W7: 0.003714676 | X7: 0.059108709 | Y7: 26.172193 | Z7: 0.33928082 | AA7: 0.18623861 | AB7: 0.63223724 | AC7: 1.9232486 | AD7: 0.20290369 | AE7: 3.7263422 | AF7: 1.4324405 | AG7: 0.20462306 | AH7: 0.16683693 | AI7: 1.8643309 | AJ7: 0.20290369 | AK7: 0.00038194324 | AL7: 0.00058920619 | AM7: 1.1948961 | AN7: 0 | AO7: 0.13801267 | AP7: 0.031865232 | AQ7: 0.00045155989 | AR7: 6.7521379e-06 | AS7: 0.0023158873 | AT7: 1.1931836 | AU7: 0.0020955285 | AV7: 0.33574934 | AW7: 0.31980427 | AX7: 0.00042563402 | AY7: 1.1945702e-05 | AZ7: 0.096777195 | BA7: 0.08268709 | BB7: 0.00037723014 | BC7: 4.9615312e-05 | BD7: 5.5275943e-06 | BE7: 0.30024591 | BF7: 0.28778419 | BG7: 0.00025512419 | BH7: 1.7798604e-05
A8: Cephalopods | B8: A.07.05.002 | C8: Octopus (Octopus vulgaris) | D8: Fish and other seafood (including amphibians, reptiles, snails and insects) | E8: Water molluscs | F8: 1000 | G8: 10.713374 | H8: 10.684911 | I8: 0.00075647881 | J8: 1.4206898e-05 | K8: 2.0278824e-05 | L8: 10.312372 | M8: 10.312372 | N8: 0 | O8: 0 | P8: 0 | Q8: 0 | R8: 0 | S8: 0 | T8: 0 | U8: 0 | V8: 0 | W8: 0 | X8: 0.61753086 | Y8: 0 | Z8: 0 | AA8: 0 | AB8: 0 | AC8: 10.312372 | AD8: 0 | AE8: 0 | AF8: 0 | AG8: 0 | AH8: 0 | AI8: 10.312372 | AJ8: 0 | AK8: 0 | AL8: 0 | AM8: 0 | AN8: 0 | AO8: 0 | AP8: 0 | AQ8: 0 | AR8: 0 | AS8: 0 | AT8: 0 | AU8: 0 | AV8: 0 | AW8: 0 | AX8: 0 | AY8: 0 | AZ8: 0.13254929 | BA8: 0.11476727 | BB8: 0.00052683544 | BC8: 1.4206898e-05 | BD8: 6.2224755e-06 | BE8: 0.26845257 | BF8: 0.25777181 | BG8: 0.00022964337 | BH8: 1.4056349e-05
A9: Cream | B9: A.08.05.001.004 | C9: Cream 40 % fat | D9: Milk and dairy products | E9: Cream and cream products | F9: 1000 | G9: 4.562542 | H9: 1.3364142 | I9: 0.005196947 | J9: 0.086228636 | K9: 0.0027219255 | L9: 4.2831645 | M9: 1.0788936 | N9: 0.0046526882 | O9: 0.086182824 | P9: 0.0027058039 | Q9: 3.7082237 | R9: 0.059687291 | S9: 0.004194841 | T9: 0.033016004 | U9: 0.29002808 | V9: 1.9803184e-12 | W9: 0.0018845374 | X9: 0.029987157 | Y9: 13.277733 | Z9: 0.17212467 | AA9: 0.094482972 | AB9: 0.32074795 | AC9: 0.97570659 | AD9: 0.10293753 | AE9: 1.8904559 | AF9: 0.72670881 | AG9: 0.10380981 | AH9: 0.084640071 | AI9: 0.94581636 | AJ9: 0.10293753 | AK9: 0.00019376827 | AL9: 0.00029891735 | AM9: 0.60619725 | AN9: 0 | AO9: 0.070016887 | AP9: 0.016165938 | AQ9: 0.00022908633 | AR9: 3.4255091e-06 | AS9: 0.0011749009 | AT9: 0.60532846 | AU9: 0.001063108 | AV9: 0.011655929 | AW9: 0.010211713 | AX9: 4.439262e-05 | AY9: 4.4438309e-07 | AZ9: 0.08935693 | BA9: 0.076347166 | BB9: 0.00034830651 | BC9: 4.5811123e-05 | BD9: 5.1037732e-06 | BE9: 0.17836468 | BF9: 0.17096164 | BG9: 0.00015155958 | BH9: 1.0573474e-05
A10: Crustaceans | B10: A.07.04.001 | C10: Crab (Cancer spp.) | D10: Fish and other seafood (including amphibians, reptiles, snails and insects) | E10: Crustaceans | F10: 1000 | G10: 15.465522 | H10: 15.437059 | I10: 0.00075647881 | J10: 1.4206898e-05 | K10: 2.0278824e-05 | L10: 15.06452 | M10: 15.06452 | N10: 0 | O10: 0 | P10: 0 | Q10: 0 | R10: 0 | S10: 0 | T10: 0 | U10: 0 | V10: 0 | W10: 0 | X10: 15.663199 | Y10: 0 | Z10: 0 | AA10: 0 | AB10: 0 | AC10: 15.06452 | AD10: 0 | AE10: 0 | AF10: 0 | AG10: 0 | AH10: 0 | AI10: 15.06452 | AJ10: 0 | AK10: 0 | AL10: 0 | AM10: 0 | AN10: 0 | AO10: 0 | AP10: 0 | AQ10: 0 | AR10: 0 | AS10: 0 | AT10: 0 | AU10: 0 | AV10: 0 | AW10: 0 | AX10: 0 | AY10: 0 | AZ10: 0.13254929 | BA10: 0.11476727 | BB10: 0.00052683544 | BC10: 1.4206898e-05 | BD10: 6.2224755e-06 | BE10: 0.26845257 | BF10: 0.25777181 | BG10: 0.00022964337 | BH10: 1.4056349e-05
A11: Demersal Fish | B11: I.07.01.006.001 | C11: Salmon (Salmo salar) | D11: Fish and other seafood (including amphibians, reptiles, snails and insects) | E11: Fish meat | F11: 1000 | G11: 6.8013086 | H11: 4.1060372 | I11: 0.0015624228 | J11: 1.8453188e-05 | K11: 0.0097004137 | L11: 6.4268277 | M11: 3.7636599 | N11: 0.00065091671 | O11: 0 | P11: 0.0096841409 | Q11: 5.3688854 | R11: 0.069999123 | S11: 0.010547821 | T11: 0.045471931 | U11: 0.00059360692 | V11: 1.3168238e-12 | W11: 0.0021385837 | X11: 11.825382 | Y11: 99.65957 | Z11: 3.6129575 | AA11: 0.086281674 | AB11: 1.8943168 | AC11: 0.61367362 | AD11: 0.21959812 | AE11: 0 | AF11: 0 | AG11: 2.8441065 | AH11: 0.086281674 | AI11: 0.61367362 | AJ11: 0.21959812 | AK11: 0.00065091671 | AL11: 0 | AM11: 0 | AN11: 0 | AO11: 0 | AP11: 0 | AQ11: 0.0027452515 | AR11: 0 | AS11: 0.0069388894 | AT11: 0 | AU11: 0 | AV11: 0 | AW11: 0 | AX11: 0 | AY11: 0 | AZ11: 0.10602834 | BA11: 0.084605512 | BB11: 0.00068186277 | BC11: 1.8453188e-05 | BD11: 2.2164258e-06 | BE11: 0.26845257 | BF11: 0.25777181 | BG11: 0.00022964337 | BH11: 1.4056349e-05
A12: Eggs | B12: A.09.01.001 | C12: Whole egg, chicken | D12: Eggs and egg products | E12: Eggs, fresh | F12: 1000 | G12: 1.2035375 | H12: 0.79032268 | I12: 0.0016360766 | J12: 0.001947045 | K12: 0.0011424525 | L12: 1.1277801 | M12: 0.72086129 | N12: 0.001470716 | O12: 0.0019407028 | P12: 0.0011380678 | Q12: 4.3051644 | R12: 0.058030951 | S12: 0.011177054 | T12: 0.19143196 | U12: 0.50015505 | V12: 2.0705511e-12 | W12: 0.0030278062 | X12: 9.364867 | Y12: 1.5249739 | Z12: 0.30602574 | AA12: 0.075762116 | AB12: 0.19359303 | AC12: 0.43357747 | AD12: 0.065822203 | AE12: 0 | AF12: 0.052999574 | AG12: 0.18448827 | AH12: 0.067650314 | AI12: 0.41946692 | AJ12: 0.065822203 | AK12: 0.00035336216 | AL12: 0.0002489759 | AM12: 0.17253034 | AN12: 0 | AO12: 0 | AP12: 0.0019407028 | AQ12: 0.00040662006 | AR12: 2.5359723e-06 | AS12: 0.00070913196 | AT12: 0.17214421 | AU12: 2.1999914e-06 | AV12: 0 | AW12: 0 | AX12: 0 | AY12: 0 | AZ12: 0.044823494 | BA12: 0.039790356 | BB12: 0.00013894839 | BC12: 6.3421725e-06 | BD12: 2.6418931e-06 | BE12: 0.030933891 | BF12: 0.029671037 | BG12: 2.6412259e-05 | BH12: 1.7427419e-06
A13: Freshwater Fish | B13: A.07.01.010 | C13: Perch (Perca) | D13: Fish and other seafood (including amphibians, reptiles, snails and insects) | E13: Fish meat | F13: 1000 | G13: 12.866133 | H13: 12.83403 | I13: 0.00091150614 | J13: 1.8453188e-05 | K13: 1.6272774e-05 | L13: 12.491652 | M13: 12.491652 | N13: 0 | O13: 0 | P13: 0 | Q13: 0 | R13: 0 | S13: 0 | T13: 0 | U13: 0 | V13: 0 | W13: 0 | X13: 5.9115335 | Y13: 0 | Z13: 0 | AA13: 0 | AB13: 0 | AC13: 12.491652 | AD13: 0 | AE13: 0 | AF13: 0 | AG13: 0 | AH13: 0 | AI13: 12.491652 | AJ13: 0 | AK13: 0 | AL13: 0 | AM13: 0 | AN13: 0 | AO13: 0 | AP13: 0 | AQ13: 0 | AR13: 0 | AS13: 0 | AT13: 0 | AU13: 0 | AV13: 0 | AW13: 0 | AX13: 0 | AY13: 0 | AZ13: 0.10602834 | BA13: 0.084605512 | BB13: 0.00068186277 | BC13: 1.8453188e-05 | BD13: 2.2164258e-06 | BE13: 0.26845257 | BF13: 0.25777181 | BG13: 0.00022964337 | BH13: 1.4056349e-05
