Workbook

Sheet Footprints, results per kg
A2: Blue food
F4: Climate | L4: Land | M4: Nitrogen | N4: Phosphorus | O4: Water | P4: Pesticides | Q4: Biodiversity | R4: Ammonia | S4: Labour | T4: Animal welfare | U4: Use of antibiotics
A5: Code | B5: Species | C5: Category | D5: Country | E5: Country code | F5: Carbon footprint, kg CO2e/kg | G5: Carbon dioxide, kg CO2/kg | H5: Methane, fossil, kg CH4/kg | I5: Methane, biogenic, kg CH4/kg | J5: Nitrous oxide, kg N2O/kg | K5: HFCs, kg HFCs/kg | L5: Cropland use, m2/kg | M5: New N input, kg N/kg | N5: New P input, kg P/kg | O5: Blue freshwater use, m3/kg | P5: Pesticide use, g a.i./kg | Q5: Extinction rate, E/MSY/kg | R5: Ammonia emission, kg NH3/kg | S5: Labour requirements, h/kg | T5: Animal welfare index per kg of bonefree meat
A6: BF-01 | B6: Herrings | C6: Blue food | D6: Rest of World | E6: RoW | F6: ='Data Gephart'!K5/1000 -> 3.8779404 | L6: ='Data Gephart'!M5/1000 -> 0 | M6: ='Data Gephart'!N5/1000 -> 0 | N6: ='Data Gephart'!O5/1000 -> 0 | O6: ='Data Gephart'!L5/1000 -> 0
A7: BF-02 | B7: Herring roe | C7: Blue food | D7: Rest of World | E7: RoW | F7: ='Data Gephart'!K6/1000 -> 3.8779404 | L7: ='Data Gephart'!M6/1000 -> 0 | M7: ='Data Gephart'!N6/1000 -> 0 | N7: ='Data Gephart'!O6/1000 -> 0 | O7: ='Data Gephart'!L6/1000 -> 0
A8: BF-03 | B8: Sprat | C8: Blue food | D8: Rest of World | E8: RoW | F8: ='Data Gephart'!K7/1000 -> 3.8779404 | L8: ='Data Gephart'!M7/1000 -> 0 | M8: ='Data Gephart'!N7/1000 -> 0 | N8: ='Data Gephart'!O7/1000 -> 0 | O8: ='Data Gephart'!L7/1000 -> 0
A9: BF-04 | B9: European sardine | C9: Blue food | D9: Rest of World | E9: RoW | F9: ='Data Gephart'!K8/1000 -> 3.878 | L9: ='Data Gephart'!M8/1000 -> 0 | M9: ='Data Gephart'!N8/1000 -> 0 | N9: ='Data Gephart'!O8/1000 -> 0 | O9: ='Data Gephart'!L8/1000 -> 0
A10: BF-05 | B10: Anchovies | C10: Blue food | D10: Rest of World | E10: RoW | F10: ='Data Gephart'!K9/1000 -> 3.878 | L10: ='Data Gephart'!M9/1000 -> 0 | M10: ='Data Gephart'!N9/1000 -> 0 | N10: ='Data Gephart'!O9/1000 -> 0 | O10: ='Data Gephart'!L9/1000 -> 0
A11: BF-06 | B11: Char | C11: Blue food | D11: Rest of World | E11: RoW | F11: ='Data Gephart'!K10/1000 -> 5.4095472 | L11: ='Data Gephart'!M10/1000 -> 3.8139923 | M11: ='Data Gephart'!N10/1000 -> 0.09888904 | N11: ='Data Gephart'!O10/1000 -> 0.023219567 | O11: ='Data Gephart'!L10/1000 -> 0.11258051
A12: BF-07 | B12: Smelt | C12: Blue food | D12: Rest of World | E12: RoW | F12: ='Data Gephart'!K11/1000 -> 6.8813387 | L12: ='Data Gephart'!M11/1000 -> 0 | M12: ='Data Gephart'!N11/1000 -> 0 | N12: ='Data Gephart'!O11/1000 -> 0 | O12: ='Data Gephart'!L11/1000 -> 0
A13: BF-08 | B13: Whitefishes or coregonus | C13: Blue food | D13: Rest of World | E13: RoW | F13: ='Data Gephart'!K12/1000 -> 9.6651743 | L13: ='Data Gephart'!M12/1000 -> 0 | M13: ='Data Gephart'!N12/1000 -> 0 | N13: ='Data Gephart'!O12/1000 -> 0 | O13: ='Data Gephart'!L12/1000 -> 0
A14: BF-09 | B14: Perch | C14: Blue food | D14: Rest of World | E14: RoW | F14: ='Data Gephart'!K13/1000 -> 9.9146496 | L14: ='Data Gephart'!M13/1000 -> 0 | M14: ='Data Gephart'!N13/1000 -> 0 | N14: ='Data Gephart'!O13/1000 -> 0 | O14: ='Data Gephart'!L13/1000 -> 0
A15: BF-10 | B15: Sea bass | C15: Blue food | D15: Rest of World | E15: RoW | F15: ='Data Gephart'!K14/1000 -> 9.9146496 | L15: ='Data Gephart'!M14/1000 -> 0 | M15: ='Data Gephart'!N14/1000 -> 0 | N15: ='Data Gephart'!O14/1000 -> 0 | O15: ='Data Gephart'!L14/1000 -> 0
A16: BF-11 | B16: Mackerel | C16: Blue food | D16: Rest of World | E16: RoW | F16: ='Data Gephart'!K15/1000 -> 6.8813387 | L16: ='Data Gephart'!M15/1000 -> 0 | M16: ='Data Gephart'!N15/1000 -> 0 | N16: ='Data Gephart'!O15/1000 -> 0 | O16: ='Data Gephart'!L15/1000 -> 0
A17: BF-12 | B17: Tuna and bonito (generic) | C17: Blue food | D17: Rest of World | E17: RoW | F17: ='Data Gephart'!K16/1000 -> 7.6290538 | L17: ='Data Gephart'!M16/1000 -> 0 | M17: ='Data Gephart'!N16/1000 -> 0 | N17: ='Data Gephart'!O16/1000 -> 0 | O17: ='Data Gephart'!L16/1000 -> 0
... A24: BF-19 | B24: Carps | C24: Blue food | D24: Rest of World | E24: RoW | F24: ='Data Gephart'!K23/1000 -> 0 | L24: ='Data Gephart'!M23/1000 -> 0 | M24: ='Data Gephart'!N23/1000 -> 0 | N24: ='Data Gephart'!O23/1000 -> 0 | O24: ='Data Gephart'!L23/1000 -> 0
A25: BF-20 | B25: Freshwater bream - Europe | C25: Blue food | D25: Rest of World | E25: RoW | F25: ='Data Gephart'!K26/1000 -> 9.6651743 | L25: ='Data Gephart'!M26/1000 -> 0 | M25: ='Data Gephart'!N26/1000 -> 0 | N25: ='Data Gephart'!O26/1000 -> 0 | O25: ='Data Gephart'!L26/1000 -> 0
A26: BF-21 | B26: River eels | C26: Blue food | D26: Rest of World | E26: RoW | F26: ='Data Gephart'!K27/1000 -> 9.6651743 | L26: ='Data Gephart'!M27/1000 -> 0 | M26: ='Data Gephart'!N27/1000 -> 0 | N26: ='Data Gephart'!O27/1000 -> 0 | O26: ='Data Gephart'!L27/1000 -> 0
A27: BF-22 | B27: Anglerfish and monkfish | C27: Blue food | D27: Rest of World | E27: RoW | F27: ='Data Gephart'!K28/1000 -> 20.313314 | L27: ='Data Gephart'!M28/1000 -> 0 | M27: ='Data Gephart'!N28/1000 -> 0 | N27: ='Data Gephart'!O28/1000 -> 0 | O27: ='Data Gephart'!L28/1000 -> 0
A28: BF-23 | B28: Sharks | C28: Blue food | D28: Rest of World | E28: RoW | F28: ='Data Gephart'!K29/1000 -> 7.6290538 | L28: ='Data Gephart'!M29/1000 -> 0 | M28: ='Data Gephart'!N29/1000 -> 0 | N28: ='Data Gephart'!O29/1000 -> 0 | O28: ='Data Gephart'!L29/1000 -> 0
A29: BF-24 | B29: Rays | C29: Blue food | D29: Rest of World | E29: RoW | F29: ='Data Gephart'!K30/1000 -> 7.6290538 | L29: ='Data Gephart'!M30/1000 -> 0 | M29: ='Data Gephart'!N30/1000 -> 0 | N29: ='Data Gephart'!O30/1000 -> 0 | O29: ='Data Gephart'!L30/1000 -> 0
A30: BF-25 | B30: Sturgeon roe | C30: Blue food | D30: Rest of World | E30: RoW | F30: ='Data Gephart'!K31/1000 -> 7.6290538 | L30: ='Data Gephart'!M31/1000 -> 0 | M30: ='Data Gephart'!N31/1000 -> 0 | N30: ='Data Gephart'!O31/1000 -> 0 | O30: ='Data Gephart'!L31/1000 -> 0
A31: BF-26 | B31: Bonito | C31: Blue food | D31: Rest of World | E31: RoW | F31: ='Data Gephart'!K32/1000 -> 7.6290538 | L31: ='Data Gephart'!M32/1000 -> 0 | M31: ='Data Gephart'!N32/1000 -> 0 | N31: ='Data Gephart'!O32/1000 -> 0 | O31: ='Data Gephart'!L32/1000 -> 0
A32: BF-27 | B32: Sardines and sardine-type fishes | C32: Blue food | D32: Rest of World | E32: RoW | F32: ='Data Gephart'!K33/1000 -> 3.8779404 | L32: ='Data Gephart'!M33/1000 -> 0 | M32: ='Data Gephart'!N33/1000 -> 0 | N32: ='Data Gephart'!O33/1000 -> 0 | O32: ='Data Gephart'!L33/1000 -> 0
A33: BF-28 | B33: Swordfish | C33: Blue food | D33: Rest of World | E33: RoW | F33: ='Data Gephart'!K34/1000 -> 7.6290538 | L33: ='Data Gephart'!M34/1000 -> 0 | M33: ='Data Gephart'!N34/1000 -> 0 | N33: ='Data Gephart'!O34/1000 -> 0 | O33: ='Data Gephart'!L34/1000 -> 0
A34: BF-29 | B34: Freshwater crabs | C34: Blue food | D34: Rest of World | E34: RoW | F34: ='Data Gephart'!K35/1000 -> 11.956739 | L34: ='Data Gephart'!M35/1000 -> 0 | M34: ='Data Gephart'!N35/1000 -> 0 | N34: ='Data Gephart'!O35/1000 -> 0 | O34: ='Data Gephart'!L35/1000 -> 0
A35: BF-30 | B35: Lobsters | C35: Blue food | D35: Rest of World | E35: RoW | F35: ='Data Gephart'!K36/1000 -> 19.444952 | L35: ='Data Gephart'!M36/1000 -> 0 | M35: ='Data Gephart'!N36/1000 -> 0 | N35: ='Data Gephart'!O36/1000 -> 0 | O35: ='Data Gephart'!L36/1000 -> 0
A36: BF-31 | B36: Lobster, norway | C36: Blue food | D36: Rest of World | E36: RoW | F36: ='Data Gephart'!K37/1000 -> 19.444952 | L36: ='Data Gephart'!M37/1000 -> 0 | M36: ='Data Gephart'!N37/1000 -> 0 | N36: ='Data Gephart'!O37/1000 -> 0 | O36: ='Data Gephart'!L37/1000 -> 0
... A51: BF-46 | B51: Snails | C51: Blue food | D51: Rest of World | E51: RoW | F51: ='Data Gephart'!K52/1000 -> 11.400049 | L51: ='Data Gephart'!M52/1000 -> 0 | M51: ='Data Gephart'!N52/1000 -> 0 | N51: ='Data Gephart'!O52/1000 -> 0 | O51: ='Data Gephart'!L52/1000 -> 0
A52: BF-47 | B52: Salmons | C52: Blue food | D52: Rest of World | E52: RoW | F52: ='Data Gephart'!K53/1000 -> 5.100986 | L52: ='Data Gephart'!M53/1000 -> 4.6524871 | M52: ='Data Gephart'!N53/1000 -> 0.11055651 | N52: ='Data Gephart'!O53/1000 -> 0.026619691 | O52: ='Data Gephart'!L53/1000 -> 0.15571147 | T52: 0.56
A53: BF-48 | B53: Trouts | C53: Blue food | D53: Rest of World | E53: RoW | F53: ='Data Gephart'!K54/1000 -> 5.4095472 | L53: ='Data Gephart'!M54/1000 -> 3.8139923 | M53: ='Data Gephart'!N54/1000 -> 0.09888904 | N53: ='Data Gephart'!O54/1000 -> 0.023219567 | O53: ='Data Gephart'!L54/1000 -> 0.11258051
A54: BF-49 | B54: Catfishes (freshwater) | C54: Blue food | D54: Rest of World | E54: RoW | F54: ='Data Gephart'!K55/1000 -> 7.7744911 | L54: ='Data Gephart'!M55/1000 -> 10.967157 | M54: ='Data Gephart'!N55/1000 -> 0.1328817 | N54: ='Data Gephart'!O55/1000 -> 0.020816676 | O54: ='Data Gephart'!L55/1000 -> 2.0944458
A55: BF-50 | B55: Wolffish | C55: Blue food | D55: Rest of World | E55: RoW | F55: ='Data Gephart'!K56/1000 -> 20.313314 | L55: ='Data Gephart'!M56/1000 -> 0 | M55: ='Data Gephart'!N56/1000 -> 0 | N55: ='Data Gephart'!O56/1000 -> 0 | O55: ='Data Gephart'!L56/1000 -> 0
A56: BF-51 | B56: Cod | C56: Blue food | D56: Rest of World | E56: RoW | F56: ='Data Gephart'!K57/1000 -> 5.1250388 | L56: ='Data Gephart'!M57/1000 -> 0 | M56: ='Data Gephart'!N57/1000 -> 0 | N56: ='Data Gephart'!O57/1000 -> 0 | O56: ='Data Gephart'!L57/1000 -> 0
A57: BF-52 | B57: Cod liver | C57: Blue food | D57: Rest of World | E57: RoW | F57: ='Data Gephart'!K58/1000 -> 5.1250388 | L57: ='Data Gephart'!M58/1000 -> 0 | M57: ='Data Gephart'!N58/1000 -> 0 | N57: ='Data Gephart'!O58/1000 -> 0 | O57: ='Data Gephart'!L58/1000 -> 0
A58: BF-53 | B58: Cod roe | C58: Blue food | D58: Rest of World | E58: RoW | F58: ='Data Gephart'!K59/1000 -> 5.1250388 | L58: ='Data Gephart'!M59/1000 -> 0 | M58: ='Data Gephart'!N59/1000 -> 0 | N58: ='Data Gephart'!O59/1000 -> 0 | O58: ='Data Gephart'!L59/1000 -> 0
A59: BF-54 | B59: Whiting | C59: Blue food | D59: Rest of World | E59: RoW | F59: ='Data Gephart'!K60/1000 -> 5.1250388 | L59: ='Data Gephart'!M60/1000 -> 0 | M59: ='Data Gephart'!N60/1000 -> 0 | N59: ='Data Gephart'!O60/1000 -> 0 | O59: ='Data Gephart'!L60/1000 -> 0
A60: BF-55 | B60: Haddock | C60: Blue food | D60: Rest of World | E60: RoW | F60: ='Data Gephart'!K61/1000 -> 5.1250388 | L60: ='Data Gephart'!M61/1000 -> 0 | M60: ='Data Gephart'!N61/1000 -> 0 | N60: ='Data Gephart'!O61/1000 -> 0 | O60: ='Data Gephart'!L61/1000 -> 0
A61: BF-56 | B61: Lumpfish roe | C61: Blue food | D61: Rest of World | E61: RoW | F61: ='Data Gephart'!K62/1000 -> 0 | L61: ='Data Gephart'!M62/1000 -> 0 | M61: ='Data Gephart'!N62/1000 -> 0 | N61: ='Data Gephart'!O62/1000 -> 0 | O61: ='Data Gephart'!L62/1000 -> 0

Sheet Translation
A2: I dietfilerna | E2: Översatt till "vårt" EFSA-format | H2: Vad vi har miljödata för | N2: FoodEx2 Code | O2: FoodEx2 Name | P2: Taxa group (SI, Table S3) | Q2: Blue food group (SI, Table 11) | R2: Production
A3: 4418 | B3: L5 | C3: Cod liver | D3: 6.39.144.929.1532 | F3: I.07.03.002.001 | G3: Cod liver | H3: A02EL | I3: Cod liver | J3: Cods, hakes, haddocks | K3: gadiformes | L3: capture | N3: A02DE | O3: Herrings | P3: Herring, sardines, anchovies | Q3: small pelagic fishes | R3: capture
A4: 4416 | B4: L5 | C4: Alaska pollock | D4: 6.37.238.95.1530 | F4: I.07.01.017.001 | G4: Cod (Gadus morhua) | H4: A02BV | J4: Cods, hakes, haddocks | K4: gadiformes | L4: capture | N4: A02DH | O4: Sprat | P4: Herring, sardines, anchovies | Q4: small pelagic fishes | R4: capture
A5: 3872 | B5: L5 | C5: Algae and prokaryotes organisms | D5: 20.2.18.660.986 | E5: A03ST | F5: A.18.02.011 | G5: Algae formula (e.g. Spirulina, Chlorella) | H5: A03ST | K5: plants | L5: aquaculture | N5: A02DB | O5: European sardine | P5: Herring, sardines, anchovies | Q5: small pelagic fishes | R5: capture
A6: 4234 | B6: L5 | C6: Algae based formulations (e.g. Spirulina, chlorella) | D6: 16.46.256.828.1348 | E6: A03ST | F6: A.18.02.011 | G6: Algae formula (e.g. Spirulina, Chlorella) | H6: A03ST | K6: plants | L6: aquaculture | N6: A02DD | O6: Anchovies | P6: Herring, sardines, anchovies | Q6: small pelagic fishes | R6: capture
A7: 4710 | B7: L5 | C7: Amberjack | D7: 6.37.238.100.1824 | F7: A.07.01.004 | G7: Anchovy (Engraulis) | H7: A02DD | K7: small pelagic fishes | L7: capture | N7: A029M | O7: Char | P7: Trout | Q7: trout | R7: aquaculture
A8: 3546 | B8: L5 | C8: Anchovies | D8: 6.37.238.99.660 | E8: A02DD | F8: A.07.01.004 | G8: Anchovy (Engraulis) | H8: A02DD | I8: Anchovies | J8: Herring, sardines, anchovies | K8: small pelagic fishes | L8: capture | N8: A029B | O8: Smelt | P8: Salmon, trouts, smelts | Q8: salmonids | R8: capture
A9: 3966 | B9: L5 | C9: Anglerfish, monkfish and stargazers | D9: 6.37.238.462.1080 | E9: A02BJ | F9: A.07.01.029 | G9: Anglerfish and monkfish | H9: A02BJ | K9: flatfishes | L9: capture | N9: A029Q | O9: Whitefishes or coregonus | P9: Jacks, mullets, sauries | Q9: jacks, mullets, sauries | R9: capture
A10: 4871 | B10: L5 | C10: Barnacle | D10: 6.28.255.1193.1985 | E10: A02HA | F10: A.07.05.005 | G10: Clam (Mya arenaria) | H10: A02HA | K10: bivalves | L10: capture | N10: A027N | O10: Perch | P10: Redfishes, basses, congers | Q10: redfishes, basses, congers | R10: capture
A11: 4196 | B11: L5 | C11: Barracudas | D11: 6.37.238.100.1310 | H11: A02DS | K11: large pelagic fishes | L11: capture | N11: A029T | O11: Sea bass | P11: Redfishes, basses, congers | Q11: redfishes, basses, congers | R11: capture
A12: 4692 | B12: L5 | C12: Bluefish | D12: 6.37.238.100.1806 | H12: A02DD | K12: small pelagic fishes | L12: capture | N12: A02CT | O12: Mackerel | P12: Salmon, trouts, smelts | Q12: salmonids | R12: capture
A13: 3964 | B13: L5 | C13: Brill | D13: 6.37.238.98.1078 | H13: A02AT | K13: flatfishes | L13: capture | N13: A02DR | O13: Tuna and bonito (generic) | P13: Tunas, bonitos, billfish | Q13: large pelagic fishes | R13: capture
A14: 3537 | B14: L5 | C14: Carps | D14: 6.37.163.460.651 | E14: A027C | F14: A.07.01.024 | G14: Carp (Cyprinus) | H14: A027C | I14: Carps | J14: hypoph_carps | K14: silver/bighead | L14: aquaculture | N14: A02AD | O14: Mullets | P14: Jacks, mullets, sauries | Q14: jacks, mullets, sauries | R14: capture
A15: 3962 | B15: L5 | C15: Catfishes (freshwater) | D15: 6.37.163.461.1076 | H15: A027J | K15: catfish | L15: aquaculture | N15: A02CB | O15: Hakes | P15: Cods, hakes, haddocks | Q15: gadiformes | R15: capture
A16: 3945 | B16: L5 | C16: Char | D16: 6.37.124.94.1059 | E16: A029M | F16: A.07.01.007 | G16: Char (Salvelinus) | H16: A029M | I16: Char | J16: Trout | K16: trout | L16: aquaculture | N16: A02AT | O16: Flounders | P16: Flounders, halibuts, soles | Q16: flatfishes | R16: capture
A17: 4457 | B17: L5 | C17: Clams | D17: 6.73.95.962.1571 | E17: A02HA | F17: A.07.05.005 | G17: Clam (Mya arenaria) | H17: A02HA | I17: Clams | J17: Bivalves | K17: bivalves | L17: capture | N17: A02AY | O17: Halibut | P17: Flounders, halibuts, soles | Q17: flatfishes | R17: capture
A18: 4267 | B18: L5 | C18: Cockle and arkshell | D18: 6.73.95.762.1381 | E18: A02HE | F18: A.07.05.006 | G18: Cockle (Cardium edule) | H18: A02HE | I18: Cockles | J18: Bivalves | K18: bivalves | L18: capture | N18: A02BC | O18: Plaice | P18: Flounders, halibuts, soles | Q18: flatfishes | R18: capture
A19: 4087 | B19: L5 | C19: Cockles | D19: 6.73.95.762.1201 | E19: A02HE | F19: A.07.05.006 | G19: Cockle (Cardium edule) | H19: A02HE | I19: Cockles | J19: Bivalves | K19: bivalves | L19: capture | N19: A02BF | O19: Sole | P19: Flounders, halibuts, soles | Q19: flatfishes | R19: capture
A20: 3027 | B20: L5 | C20: Cod | D20: 6.37.238.95.141 | E20: A02BV | F20: I.07.01.017.001 | G20: Cod (Gadus morhua) | H20: A02BV | I20: Cod | J20: Cods, hakes, haddocks | K20: gadiformes | L20: capture | N20: A027C | O20: Carps | Q20: Comment Patrik: Carp are caught in Sweden, but farmed in other parts of the world. Low impact in Sweden, maybe use 'capture, herring'. See Hornborg et al.
A21: 4521 | B21: L5 | C21: Cod roe | D21: 6.39.145.1007.1635 | F21: I.07.03.001.001 | G21: Fish roe, Cod | H21: A02EP | I21: Cod roe | J21: Cods, hakes, haddocks | K21: gadiformes | L21: capture | N21: A027B | O21: Freshwater bream - Europe | P21: Jacks, mullets, sauries | Q21: jacks, mullets, sauries | R21: capture
A22: 4917 | B22: L5 | C22: Cod, murray | D22: 6.37.163.461.2031 | E22: A02BV | F22: I.07.01.017.001 | G22: Cod (Gadus morhua) | H22: A02BV | I22: Cod | J22: Cods, hakes, haddocks | K22: gadiformes | L22: capture | N22: A028G | O22: River eels | P22: Jacks, mullets, sauries | Q22: jacks, mullets, sauries | R22: capture
A23: 4520 | B23: L5 | C23: Cods, hakes, haddocks | D23: 6.37.238.95.1634 | E23: A02BV | F23: I.07.01.017.001 | G23: Cod (Gadus morhua) | H23: A02BV | I23: Cod | J23: Cods, hakes, haddocks | K23: gadiformes | L23: capture | N23: A02BJ | O23: Anglerfish and monkfish | P23: Flounders, halibuts, soles | Q23: flatfishes | R23: capture
A24: 4646 | B24: L5 | C24: Conger | D24: 6.37.238.462.1760 | H24: A028G | K24: jacks, mullets, sauries | L24: capture | N24: A02DJ | O24: Sharks | P24: Tunas, bonitos, billfish | Q24: large pelagic fishes | R24: capture
A25: 4183 | B25: L5 | C25: Crabs, sea-spiders | D25: 6.28.109.808.1297 | E25: A02FF | F25: A.07.04.001 | G25: Crab (Cancer spp.) | H25: A02FF | I25: Freshwater crabs | J25: Shrimp | K25: shrimp | L25: capture | N25: A02DQ | O25: Rays | P25: Tunas, bonitos, billfish | Q25: large pelagic fishes | R25: capture
A26: 3530 | B26: L5 | C26: Crustaceans | D26: 6.28.114.453.644 | G26: =skaldjur, vanligast shrimp | J26: Shrimp | K26: shrimp | L26: capture | N26: A02FA | O26: Sturgeon roe | P26: Tunas, bonitos, billfish | Q26: large pelagic fishes | R26: capture
A27: 4882 | B27: L5 | C27: Cusk-eels | D27: 6.37.238.462.1996 | H27: A028G | K27: jacks, mullets, sauries | L27: capture | N27: A02DS | O27: Bonito | P27: Tunas, bonitos, billfish | Q27: large pelagic fishes | R27: capture
A28: 3569 | B28: L5 | C28: Cuttlefish, common | D28: 6.73.370.473.683 | E28: A02JA | F28: A.07.05.003 | G28: Cuttlefish (Sepia officinalis) | H28: A02JA | I28: Cuttlefishes | J28: Squid, cuttlefishes, octopuses | K28: cephalopods | L28: capture | N28: A02DA | O28: Sardines and sardine-type fishes | P28: Herring, sardines, anchovies | Q28: small pelagic fishes | R28: capture
A29: 3797 | B29: L5 | C29: Cuttlefishes | D29: 6.73.370.473.911 | E29: A02JA | F29: A.07.05.003 | G29: Cuttlefish (Sepia officinalis) | H29: A02JA | I29: Cuttlefishes | J29: Squid, cuttlefishes, octopuses | K29: cephalopods | L29: capture | N29: A07Y0 | O29: Swordfish | P29: Tunas, bonitos, billfish | Q29: large pelagic fishes | R29: capture
A30: 3033 | B30: L5 | C30: Dab or common dab | D30: 6.37.238.98.147 | H30: A02AT | K30: flatfishes | L30: capture | N30: A02FF | O30: Freshwater crabs | P30: Shrimp | Q30: shrimp | R30: capture
A31: 4137 | B31: L5 | C31: Dentex | D31: 6.37.238.705.1251 | H31: A02DE | K31: small pelagic fishes | L31: capture | N31: A02FP | O31: Lobsters | P31: Lobster | Q31: lobster | R31: capture
A32: 4762 | B32: L5 | C32: Diadromous fish | D32: 6.37.124.1125.1876 | J32: Misc_diad | K32: misc diadromous fishes | L32: aquaculture | N32: A02FS | O32: Lobster, norway | P32: Lobster | Q32: lobster | R32: capture
A33: 4010 | B33: L5 | C33: Dulse | D33: 20.2.322.732.1124 | E33: A03ST | F33: A.18.02.011 | G33: Algae formula (e.g. Spirulina, Chlorella) | H33: A03ST | K33: plants | L33: aquaculture | N33: A02FY | O33: Prawn, giant tiger | P33: Shrimp | Q33: shrimp | R33: aquaculture
A34: 3760 | B34: L5 | C34: Edible crab | D34: 6.28.109.593.874 | E34: A02FF | F34: A.07.04.001 | G34: Crab (Cancer spp.) | H34: A02FF | I34: Freshwater crabs | J34: Shrimp | K34: shrimp | L34: capture | N34: A02GA | O34: White shrimp | P34: Shrimp | Q34: shrimp | R34: aquaculture
A35: 4916 | B35: L5 | C35: Eel, european | D35: 6.37.124.458.2030 | E35: A028G | F35: A.07.01.027 | G35: Eels (Apodes) | H35: A028G | I35: River eels | J35: Jacks, mullets, sauries | K35: jacks, mullets, sauries | L35: capture | N35: A02FV | O35: Spiny and rock lobsters | P35: Lobster | Q35: lobster | R35: capture
A36: 3778 | B36: L5 | C36: Flounders, halibuts, soles | D36: 6.37.238.98.892 | E36: A02AT | F36: A.07.01.019 | G36: Flounder (Platichthys flesus) | H36: A02AT | I36: Flounders | J36: Flounders, halibuts, soles | K36: flatfishes | L36: capture | N36: A02JH | O36: Squids | P36: Squid, cuttlefishes, octopuses | Q36: cephalopods | R36: capture
A37: 3538 | B37: L5 | C37: Freshwater bream - Europe | D37: 6.37.163.460.652 | E37: A027B | F37: A.07.01.026 | G37: Bream (Charax) | H37: A027B | I37: Freshwater bream - Europe | J37: Jacks, mullets, sauries | K37: jacks, mullets, sauries | L37: capture | N37: A02JD | O37: Octopuses | P37: Squid, cuttlefishes, octopuses | Q37: cephalopods | R37: capture
A38: 4723 | B38: L5 | C38: Freshwater crabs | D38: 6.28.162.1107.1837 | E38: A02FF | F38: A.07.04.001 | G38: Crab (Cancer spp.) | H38: A02FF | I38: Freshwater crabs | J38: Shrimp | K38: shrimp | L38: capture | N38: A02JA | O38: Cuttlefishes | P38: Squid, cuttlefishes, octopuses | Q38: cephalopods | R38: capture
A39: 3531 | B39: L5 | C39: Freshwater crayfishes | D39: 6.28.162.454.645 | E39: A02FG | F39: A.07.04.007 | G39: Crayfish (Astacus spp.) | H39: A02FG | J39: Lobster | K39: lobster | L39: capture | N39: A02HA | O39: Clams | P39: Bivalves | Q39: bivalves | R39: capture
A40: 3961 | B40: L5 | C40: Freshwater fish | D40: 6.37.163.710.1075 | J40: Trout | K40: trout | L40: aquaculture | N40: A02HE | O40: Cockles | P40: Bivalves | Q40: bivalves | R40: capture
A41: 3528 | B41: L5 | C41: Frog meat (Rana genus) | D41: 6.3.20.452.642 | E41: A02KR | F41: A.07.06.001 | G41: Frog legs (Rana spp.) | H41: ? | I41: Water snails, conches and whelks | J41: Bivalves | K41: bivalves | L41: capture | N41: A02HF | O41: Mussels | P41: Bivalves | Q41: bivalves | R41: aquaculture
...

Sheet Yields
A2: Yields and degree of wild caught and farmed
B4: Species | C4: Edible portion (kg edible per kg whole) " | D4: kg per animal (maximum weight) | E4: Yield (kg edible flesh per fish/animal)" | F4: Share import to Sweden | G4: Species farmed or wild caught (F=O/farmed, W=Fished/wild caught)
A5: BF-01 | B5: Herrings | C5: 0.522 | D5: 1.05 | E5: =D5*C5 -> 0.5481 | F5: =E5*D5 -> 0.575505 | G5: W | I5: "The total Swedish seafood consumption for 2015 is 109,000 tons of fillets and shelled seafood, corresponding to 11 kg per person or around 25 kg of whole fish per person. Of this, 60% is wild caught and 40% farmed. Around a quarter of the total volume is certified by either MSC or ASC. Almost 75% of what we eat is imported, while Swedish fishing accounts for just over 20% and Swedish aquaculture accounts for around 6%"
A6: BF-02 | B6: Herring roe | C6: 1 | D6: 1.05 | E6: =D6*C6 -> 1.05 | F6: 0 | G6: W | I6: From: Svensk konsumtion av sjömaten växande mångfald Friederike Ziegler & Kristina Bergman SP Rapport 2017:07
A7: BF-03 | B7: Sprat | C7: 0.56 | D7: 0.015 | E7: =D7*C7 -> 0.0084 | F7: 1 | G7: W
A8: BF-04 | B8: European sardine | C8: 0.478 | D8: 0.49 | E8: =D8*C8 -> 0.23422 | F8: 1 | G8: W
A9: BF-05 | B9: Anchovies | C9: 0.601 | D9: 0.049 | E9: =D9*C9 -> 0.029449 | F9: 1 | G9: W
A10: BF-06 | B10: Char | C10: 0.368 | D10: 2.5 | E10: =D10*C10 -> 0.92 | F10: 1 | G10: F
A11: BF-07 | B11: Smelt | C11: 0.368 | D11: 0.015 | E11: =D11*C11 -> 0.00552 | F11: 1 | G11: W
A12: BF-08 | B12: Whitefishes or coregonus | C12: 0.368 | D12: 2 | E12: =D12*C12 -> 0.736 | F12: 1 | G12: W
A13: BF-09 | B13: Perch | C13: 0.368 | D13: 2.7 | E13: =D13*C13 -> 0.9936 | F13: 1 | G13: W
A14: BF-10 | B14: Sea bass | C14: 0.368 | D14: =(4.9+0.267)/2 -> 2.5835 | E14: =D14*C14 -> 0.950728 | F14: 1 | G14: F
A15: BF-11 | B15: Mackerel | C15: 0.407 | D15: 3.4 | E15: =D15*C15 -> 1.3838 | F15: 0.67 | G15: W
A16: BF-12 | B16: Tuna and bonito (generic) | C16: =AVERAGEA(0.368,0.368,0.399,0.42,0.368,0.368) -> 0.38183333 | D16: 34.5 | E16: =D16*C16 -> 13.17325 | F16: 1 | G16: W
A17: BF-13 | B17: Mullets | C17: 0.5 | D17: 2 | E17: =D17*C17 -> 1 | F17: 1 | G17: W
A18: BF-14 | B18: Hakes | C18: 0.53 | D18: 3.6 | E18: =D18*C18 -> 1.908 | F18: 1 | G18: W
A19: BF-15 | B19: Flounders | C19: 0.368 | D19: 2 | E19: =D19*C19 -> 0.736 | F19: 1 | G19: W
A20: BF-16 | B20: Halibut | C20: 0.368 | D20: 15 | E20: =D20*C20 -> 5.52 | F20: 1 | G20: W
A21: BF-17 | B21: Plaice | C21: 0.368 | D21: 1.2 | E21: =D21*C21 -> 0.4416 | F21: 1 | G21: W
A22: BF-18 | B22: Sole | C22: 0.368 | D22: 1.2 | E22: =D22*C22 -> 0.4416 | F22: 1 | G22: W
A23: BF-19 | B23: Carps | C23: 0.368 | D23: 5 | E23: =D23*C23 -> 1.84 | F23: 1 | G23: F
A24: BF-20 | B24: Freshwater bream - Europe | C24: 0.368 | D24: 4 | E24: =D24*C24 -> 1.472 | F24: 1 | G24: W
A25: BF-21 | B25: River eels | C25: 0.61 | D25: =(25+0.03)/2 -> 12.515 | E25: =D25*C25 -> 7.63415 | F25: 1 | G25: W
A26: BF-22 | B26: Anglerfish and monkfish | C26: 0.72 | D26: 5 | E26: =D26*C26 -> 3.6 | F26: 1 | G26: W
A27: BF-23 | B27: Sharks (dogfish) | C27: 0.368 | D27: 4.5 | E27: =D27*C27 -> 1.656 | F27: 1 | G27: W
A28: BF-24 | B28: Rays | C28: 0.26 | D28: 100 | E28: =D28*C28 -> 26 | F28: 1 | G28: W
A29: BF-25 | B29: Sturgeon roe | C29: 0.01 | D29: 50 | E29: =D29*C29 -> 0.5 | F29: 1 | G29: W
A30: BF-26 | B30: Bonito | C30: 0.368 | D30: 34.5 | E30: =D30*C30 -> 12.696 | F30: 1 | G30: W
A31: BF-27 | B31: Sardines and sardine-type fishes | C31: 0.478 | D31: 0.49 | E31: =D31*C31 -> 0.23422 | F31: 1 | G31: W
A32: BF-28 | B32: Swordfish | C32: 0.368 | D32: 320 | E32: =D32*C32 -> 117.76 | F32: 1 | G32: W
A33: BF-29 | B33: Freshwater crabs | C33: =(0.444+0.556)/2 -> 0.5 | D33: 0.75 | E33: =D33*C33 -> 0.375 | F33: 1 | G33: W
A34: BF-30 | B34: Lobsters | C34: 0.478 | D34: 2.2 | E34: =D34*C34 -> 1.0516 | F34: 1 | G34: W
A35: BF-31 | B35: Lobster, norway | C35: 0.478 | D35: 2.2 | E35: =D35*C35 -> 1.0516 | F35: 1 | G35: W
A36: BF-32 | B36: Prawn, giant tiger | C36: 0.444 | D36: 1 | E36: =D36*C36 -> 0.444 | F36: 1 | G36: F
A37: BF-33 | B37: White shrimp | C37: 0.444 | D37: 0.0054 | E37: =D37*C37 -> 0.0023976 | F37: 0.9 | G37: W
A38: BF-34 | B38: Spiny and rock lobsters | C38: 0.478 | D38: 1.2 | E38: =D38*C38 -> 0.5736 | F38: 1 | G38: W
A39: BF-35 | B39: Freshwater crayfishes | C39: 0.478 | D39: 0.75 | E39: =D39*C39 -> 0.3585 | F39: 1 | G39: W
A40: BF-36 | B40: Squids (European squid) | C40: 0.678 | D40: 0.06 | E40: =D40*C40 -> 0.04068 | F40: 1 | G40: W
A41: BF-37 | B41: Octopuses | C41: 0.735 | D41: 15 | E41: =D41*C41 -> 11.025 | F41: 1 | G41: W
A42: BF-38 | B42: Cuttlefishes | C42: 0.735 | D42: 5 | E42: =D42*C42 -> 3.675 | F42: 1 | G42: W
...

Sheet Data Gephart
A2: Blue food (per tonne edible blue food)
A4: FoodEx2 Code | B4: FoodEx2 Name | C4: Taxa group (SI, Table S3) | D4: Blue food group (SI, Table 11) | E4: Production | F4: GHG (AR5) econ [kgCO2e] | G4: Water [m3] | H4: Land [m2] | I4: N [kgNe] | J4: P [kgPe] | K4: GHG (AR5) mass [kgCO2e] | L4: Water [m3] | M4: Land [m2] | N4: N [kgNe] | O4: P [kgPe] | Q4: Source: | R4: Gephart et al., 2021 - edible weight
A5: A02DE | B5: Herrings | C5: Herring, sardines, anchovies | D5: small pelagic fishes | E5: capture | K5: 3877.9404
A6: A02ES | B6: Herring roe | C6: Herring, sardines, anchovies | D6: small pelagic fishes | E6: capture | K6: 3877.9404 | Q6: Helped by | R6: https://www.fao.org/fishery/en/species?page=1&q=coregonus#search
A7: A02DH | B7: Sprat | C7: Herring, sardines, anchovies | D7: small pelagic fishes | E7: capture | K7: 3877.9404
A8: A02DB | B8: European sardine | C8: Herring, sardines, anchovies | D8: small pelagic fishes | E8: capture | K8: 3878
A9: A02DD | B9: Anchovies | C9: Herring, sardines, anchovies | D9: small pelagic fishes | E9: capture | K9: 3878
A10: A029M | B10: Char | C10: Trout | D10: trout | E10: aquaculture | F10: 3659.9608 | G10: 63.844502 | H10: 3008.6899 | I10: 97.537069 | J10: 23.142802 | K10: 5409.5472 | L10: 112.58051 | M10: 3813.9923 | N10: 98.88904 | O10: 23.219567
A11: A029B | B11: Smelt | C11: Salmon, trouts, smelts | D11: salmonids | E11: capture | K11: 6881.3387
A12: A029Q | B12: Whitefishes or coregonus | C12: Jacks, mullets, sauries | D12: jacks, mullets, sauries | E12: capture | K12: 9665.1743
A13: A027N | B13: Perch | C13: Redfishes, basses, congers | D13: redfishes, basses, congers | E13: capture | K13: 9914.6496
A14: A029T | B14: Sea bass | C14: Redfishes, basses, congers | D14: redfishes, basses, congers | E14: capture | K14: 9914.6496
A15: A02CT | B15: Mackerel | C15: Salmon, trouts, smelts | D15: salmonids | E15: capture | K15: 6881.3387
A16: A02DR | B16: Tuna and bonito (generic) | C16: Tunas, bonitos, billfish | D16: large pelagic fishes | E16: capture | K16: 7629.0538
A17: A02AD | B17: Mullets | C17: Jacks, mullets, sauries | D17: jacks, mullets, sauries | E17: capture | K17: 9665.1743
A18: A02CB | B18: Hakes | C18: Cods, hakes, haddocks | D18: gadiformes | E18: capture | K18: 5125.0388
A19: A02AT | B19: Flounders | C19: Flounders, halibuts, soles | D19: flatfishes | E19: capture | K19: 20313.314
A20: A02AY | B20: Halibut | C20: Flounders, halibuts, soles | D20: flatfishes | E20: capture | K20: 20313.314
A21: A02BC | B21: Plaice | C21: Flounders, halibuts, soles | D21: flatfishes | E21: capture | K21: 20313.314
A22: A02BF | B22: Sole | C22: Flounders, halibuts, soles | D22: flatfishes | E22: capture | K22: 20313.314
A23: A027C | B23: Carps, capture | D23: Comment Patrik: Carp are caught in Sweden, but farmed in other parts of the world. Low impact in Sweden, maybe use 'capture, herring'. See Hornborg et al.
B24: Carps | C24: oth_carps | D24: misc carps | E24: aquaculture | F24: 5009.0935 | G24: 3439.4581 | H24: 9526.1763 | I24: 144.57444 | J24: 20.069415 | K24: 6946.9227 | L24: 3522.7751 | M24: 11395.571 | N24: 147.79592 | O24: 20.26049
B25: Carps | C25: hypoph_carps | D25: silver/bighead | E25: aquaculture | F25: 2536.6296 | G25: 9239.0517 | H25: 7309.231 | I25: 41.58759 | J25: 6.4714976 | K25: 3510.591 | L25: 9277.2797 | M25: 8293.0994 | N25: 43.284474 | O25: 6.5628955
A26: A027B | B26: Freshwater bream - Europe | C26: Jacks, mullets, sauries | D26: jacks, mullets, sauries | E26: capture | K26: 9665.1743
A27: A028G | B27: River eels | C27: Jacks, mullets, sauries | D27: jacks, mullets, sauries | E27: capture | K27: 9665.1743
A28: A02BJ | B28: Anglerfish and monkfish | C28: Flounders, halibuts, soles | D28: flatfishes | E28: capture | K28: 20313.314
A29: A02DJ | B29: Sharks | C29: Tunas, bonitos, billfish | D29: large pelagic fishes | E29: capture | K29: 7629.0538
A30: A02DQ | B30: Rays | C30: Tunas, bonitos, billfish | D30: large pelagic fishes | E30: capture | K30: 7629.0538
A31: A02FA | B31: Sturgeon roe | C31: Tunas, bonitos, billfish | D31: large pelagic fishes | E31: capture | K31: 7629.0538
A32: A02DS | B32: Bonito | C32: Tunas, bonitos, billfish | D32: large pelagic fishes | E32: capture | K32: 7629.0538
A33: A02DA | B33: Sardines and sardine-type fishes | C33: Herring, sardines, anchovies | D33: small pelagic fishes | E33: capture | K33: 3877.9404
A34: A07Y0 | B34: Swordfish | C34: Tunas, bonitos, billfish | D34: large pelagic fishes | E34: capture | K34: 7629.0538
A35: A02FF | B35: Freshwater crabs | C35: Shrimp | D35: shrimp | E35: capture | K35: 11956.739
A36: A02FP | B36: Lobsters | C36: Lobster | D36: lobster | E36: capture | K36: 19444.952
A37: A02FS | B37: Lobster, norway | C37: Lobster | D37: lobster | E37: capture | K37: 19444.952
A38: A02FY | B38: Prawn, giant tiger | C38: Shrimp | D38: shrimp | E38: aquaculture | F38: 7775.8589 | G38: 182.32745 | H38: 12294.687 | I38: 121.65783 | J38: 23.900589 | K38: 9428.0156 | L38: 219.16533 | M38: 12960.917 | N38: 123.03703 | O38: 23.984136
A39: A02GA | B39: White shrimp | C39: Shrimp | D39: shrimp | E39: aquaculture | F39: 7775.8589 | G39: 182.32745 | H39: 12294.687 | I39: 121.65783 | J39: 23.900589 | K39: 9428.0156 | L39: 219.16533 | M39: 12960.917 | N39: 123.03703 | O39: 23.984136
A40: A02FV | B40: Spiny and rock lobsters | C40: Lobster | D40: lobster | E40: capture | K40: 19444.952
A41: A02FG | B41: Freshwater crayfishes | C41: Shrimp | D41: shrimp | E41: capture | K41: 11956.739
A42: A02JH | B42: Squids | C42: Squid, cuttlefishes, octopuses | D42: cephalopods | E42: capture | K42: 8184.9503
...

Sheet Production vs. consumption SWE
A1: Data from RISE/MFF report #14: Key species or production techniques in production (in 2020) and consumption (in 2019). Of the production (Swedish fisheries and aquaculture), only the volume estimated to go to food has been included, and only the edible part of this volume. For those species that are largely used for feed (herring and sprat), this means that the volume presented here is significantly less than Swedish landings. Seafood that is imported, processed and re-exported is also not included in the table, but only "net imports", i.e. production + imports - exports, as an estimate of consumption._x000D_
B2: Production | C2: Edible Share | D2: Volume produced (tonnes of edible part) | F2: Consumption | I2: Volume consumed (tonnes of edible part) | K2: Proportion consumed:produced
B3: Herring | C3: 0.52 | D3: 18860
B4: Rainbow1 | C4: 0.45 | D4: 3893 | F4: Rainbow trout | G4: (Salmonids) | H4: 0.45 | I4: 4098 | K4: =I4/D4 -> 1.0526586
B5: Mackerel | C5: 0.41 | D5: 3689
B6: Blue mussel1 | C6: 0.47 | D6: 1081
B7: Skarpsill | C7: 0.37 | D7: 1058
B8: Norway lobster | C8: 0.48 | D8: 837
B9: Shrimp | C9: 0.44 | D9: 517 | F9: Shrimp | G9: (Shellfish) | H9: 0.44 | I9: 15934 | K9: =I9/D9 -> 30.820116
B10: char1 | C10: 0.45 | D10: 473 | F10: Salmon1 | G10: (Salmonids) | H10: 0.45 | I10: 29870 | K10: =I10/D10 -> 63.150106
B11: Cod | C11: 0.33 | D11: 284
B12: Tilapia/Clarias1 | C12: 0.37 | D12: 38 | F12: Cod | G12: (Whitefish) | H12: 0.33 | I12: 11165 | K12: =I12/D12 -> 293.81579
B13: Sugar tongs1 | C13: 1 | D13: 50
B14: Bream | C14: 0.4 | D14: 14
B15: Seepage1 | C15: 1 | D15: 12
F16: Pollock | G16: (Whitefish) | H16: 0.39 | I16: 4895
F17: Tuna | G17: (Tuna) | H17: 0.42 | I17: 4413
F18: Other saltwater fish' | H18: not inlcuded due to non-specificity | I18: 3941
F19: Alaska pollock | G19: (Whitefish) | H19: 0.34 | I19: 3425
