Workbook
Name _Ref501010803: 'Excluded data'!$A$117
Name _Ref501632987: 'Excluded data'!$A$10
Name _Ref501704412: 'Input data processed products'!$E$28
Name _Toc505255448: 'Common input data'!$A$64
Name a_t: '[1]Base case results'!$B$2
Name a_t: '[1]Base case results'!$B$2
Name a_t: '[1]Base case results'!$B$2
Name a_t: '[1]Base case results'!$B$2
Name a_t: '[2]Base case results'!$B$2
Name a_t: '[1]Base case results'!$B$2
Name a_t: '[1]Base case results'!$B$2
Name a_t: '[1]Base case results'!$B$2
Name a_t: '[1]Base case results'!$B$2
Name a_t: '[1]Base case results'!$B$2
Name a_t: '[1]Base case results'!$B$2
Name a_t: '[1]Base case results'!$B$2
Name a_t: '[1]Base case results'!$B$2
Name a_t: '[1]Base case results'!$B$2
Name a_t: '[1]Base case results'!$B$2
Name a_t: '[1]Base case results'!$B$2
Name a_t: '[1]Base case results'!$B$2
Name a_t: '[1]Base case results'!$B$2
Name a_t: '[1]Base case results'!$B$2
Name a_t: '[1]Base case results'!$B$2
Name a_t: '[3]Base case results'!$B$2
Name aaaCH4bio: OFFSET('Summary pivot'!$H$10,,,COUNTA('Summary pivot'!$C$10:$C$200))
Name aaaCH4bioee: OFFSET('Summary pivot'!$L$10,,,COUNTA('Summary pivot'!$C$10:$C$200))
Name aaaCH4fossil: OFFSET('Summary pivot'!$G$10,,,COUNTA('Summary pivot'!$C$10:$C$200))
Name aaaCH4fossilee: OFFSET('Summary pivot'!$K$10,,,COUNTA('Summary pivot'!$C$10:$C$200))
Name aaaCO2: OFFSET('Summary pivot'!$F$10,,,COUNTA('Summary pivot'!$C$10:$C$200))
Name aaaHFC: OFFSET('Summary pivot'!$J$10,,,COUNTA('Summary pivot'!$C$10:$C$200))
Name aaaHFCee: OFFSET('Summary pivot'!$N$10,,,COUNTA('Summary pivot'!$C$10:$C$200))
Name aaaN2O: OFFSET('Summary pivot'!$I$10,,,COUNTA('Summary pivot'!$C$10:$C$200))
Name aaaN2Oee: OFFSET('Summary pivot'!$M$10,,,COUNTA('Summary pivot'!$C$10:$C$200))
Name AlaskaPollock: 'Fish and seafood'!$A$120
Name Apple: 'Fruits, berries, cocoa, coffee'!$A$9
Name AverageFishAndSeafood: 'Fish and seafood'!$A$7
Name Avocado: 'Fruits, berries, cocoa, coffee'!$A$115
Name Banana: 'Fruits, berries, cocoa, coffee'!$A$68
Name Barley: 'Grains, oil crops, sugar'!$A$34
Name Beans: 'Vegetables, roots, legumes'!$A$229
Name Beef: 'Meat and eggs'!$A$72
Name Beer: 'Processed products'!$A$106
Name BellPepper: 'Vegetables, roots, legumes'!$A$67
Name Biscuits: 'Processed products'!$A$34
Name Broccoli: 'Vegetables, roots, legumes'!$A$169
Name Buns: 'Processed products'!$A$28
Name Butter: 'Dairy products'!$A$24
Name Butter: '[4]Dairy products wo allocation'!$A$23
Name Butter: '[5]Dairy products wo allocation'!$A$23
Name Carrot: 'Vegetables, roots, legumes'!$A$122
Name Cauliflower: 'Vegetables, roots, legumes'!$A$203
Name ChickenMeat: 'Meat and eggs'!$A$35
Name Cider: 'Processed products'!$A$100
Name CO2ee: OFFSET('Summary pivot'!$E$10,,,COUNTA('Summary pivot'!$C$10:$C$200))
Name Cocoa: 'Fruits, berries, cocoa, coffee'!$A$175
Name CocoaDrinkPowder: 'Processed products'!$A$88
Name Cod: 'Fish and seafood'!$A$19
Name Coffee: 'Fruits, berries, cocoa, coffee'!$A$190
Name CommonInputData: 'Common input data'!$A$1

Sheet Guide to the material
A1: Environmental pressures of Swedish food consumption, version 1.0, April 2022 Contact details for questions on the material: Emma Moberg, IVL Svenska miljöinstitutet, Stockholm. E-mail: emma.moberg@ivl.se Elin Röös, Department of Energy and Technology, Swedish University of Agricultural Sciences, Uppsala. E-mail: elin.roos@slu.se
A2: This material presents datasets of the environmental pressures of a variety of food available on the Swedish market. The data is based on the work by Moberg et al. (2019), Moberg et al. (2020), Moberg et al. (2021) and Wood et al. (in revision). Food products are divided into food groups as follows by the Table of content. For each product, the results of the calculations of the climate impact are given for the production countries representing more than 10% of the Swedish consumption of a certain food product during a five-year period (2011 to 2015). Food imported from countries representing less than 10% of Swedish consumption are accounted for as an average of the larger producing countries if no global or regional input data is available. For all products, an average value of the climate impact is presented based on the market shares. For some cases, import data only show the country of import to Europe. By contacting with the wholesaler business, it was possible to partly trace the origin for some products, e.g. beef. For other products such as rice and avocado, an average of world production systems was accounted for. The results are divided into three parts with different system boundaries to show how the choice of system boundary affect the climate impact of foods: i) Agricultural emissions: Including only emissions from biological processes giving rise to emissions of CH4 and N2O (emission from enteric fermentation, soils and manure management) ii) The cradle-to-farm gate boundary: Including emissions from pre-farm processes, e.g. production of input materials such as fertiliser, emissions from agricultural processes and energy use on the farm iii) The full cradle-to-retail gate boundary Further, results are shown as emissions per kg of each individual greenhouse gas (CO2, CH4 and N2O, as well as HCFC-22 for the case of fish and seafood) as well as aggregated into the common unit of kg of CO2e using different climate metrics. Here, it is possible to choose between the following metrics by using the drop-down list to the right of “Choice of climate metric” placed above the “Results” cells in each results worksheet: i) GWP100 - available both with and without climate-carbon feedbacks (Myhre et al., 2013) ii) GTP100 - available both with and without climate-carbon feedbacks (Myhre et al., 2013) iii) GTP characterisation factors adjusted to limit global warming to 2°C by assuming that it is equally likely that the limit will be reached in 2050, 2075 and 2100 (Persson et al., 2015) Additionally, it is possible to choose whether or not to include emissions of CO2 from land use change and soil carbon changes in the results by using the drop-down lists to the right of “Include land use change?” and “Include soil carbon changes?” respectively, which are placed above the “Results” cells in each results worksheet. Additionally, factors for assessing soil carbon changes can be chosen in "Common input data" --> "Choose factors for soil carbon changes". Emissions of greenhouse gases arising from each production step in the production of a food product can be seen to the right of the box showing the results for different system boundaries.

Sheet Table of contents
A1: Common data | B1: Meat and eggs | C1: Dairy products | D1: Fish and seafood | E1: Grains, oil crops and sugar | F1: Vegetables, root crops and legumes | G1: Fruits, berries, cocoa and coffee | H1: Processed products
A2: Reference list | B2: Results meat and eggs | C2: Results dairy products | D2: Results fish and seafood | E2: Results grains, oil crops and sugar | F2: Results vegetables, root crops and legumes | G2: Results fruits, berries, cocoa and coffee | H2: Results processed products
A3: Common input data sheet | B3: Input data sheet | C3: Input data sheet | D3: Input data sheet | E3: Input data sheet | F3: Input data sheet | G3: Input data sheet | H3: Input data sheet
A4: Additional motivation to excluded data | B4: Products included: | C4: Products included: | D4: Products included: | E4: Products included: | F4: Products included: | G4: Products included: | H4: Products included:
A5: Maintenance of data | B5: Pork meat | C5: Raw milk | D5: Average of fish and seafood | E5: Average grains | F5: Tomato | G5: Apple | H5: Pasta
B6: Chicken meat | C6: Pasteurized milk | D6: Salmon | E6: Wheat | F6: Cucumber | G6: Pear | H6: Buns
B7: Eggs | C7: Butter | D7: Cod | E7: Rye | F7: Bell pepper | G7: Melon | H7: Biscuits
B8: Beef | C8: Yogurt | D8: Herring | E8: Barley | F8: Iceberg lettuce | G8: Banana | H8: Pastry
C9: Cream | D9: Mackerel | E9: Oats | F9: Potato | G9: Orange | H9: Rusks
C10: Hard cheese | D10: Saithe | E10: Rice | F10: Carrot | G10: Lemon | H10: Wheat bread
C11: Dessert cheese | D11: Northern Prawn | E11: Rapeseed/rapeseed oil | F11: Onion | G11: Avocado | H11: Wheat-rye bread
C12: Crème fraiche | D12: Alaska pollock | E12: Olives/Olive oil | F12: Leek | G12: Kiwifruit | H12: Crisp bread
C13: Milk powder | D13: Rainbow trout | E13: Sugar beet/sugar | F13: Broccoli | G13: Strawberry | H13: Follow-up formula
D14: Roe (from cod fish) | F14: White cabbage | G14: Raspberry | H14: Margarine
D15: Pangasius | F15: Cauliflower | G15: Cocoa/Cocoa powder/Cocoa butter | H15: Low fat margarine
D16: European plaice | F16: Peas | G16: Coffee | H16: Cocoa drink powder
D17: Hoki | F17: Beans | H17: Soda
H18: Cider (non-alcoholic)
H19: Beer (regular)
H20: Mineral water
H21: Juice of orange and apple
H22: Squash drink of strawberry and raspberry
H23: Milk chocolate
H24: Potato crisps
H25: Ice cream (dairy-based)

Sheet Results Summary
A1: Product group | B1: Food product | C1: Production country | D1: Production system | E1: Share of market | F1: Choice of climate metric | G1: kg CO2e at retail-gate per kg of product | H1: kg CO2 at retail-gate per kg of product | I1: kg CH4 fossil at retail-gate per kg of product | J1: kg CH4 bio at retail-gate per kg of product | K1: kg N2O at retail-gate per kg of product | L1: kg HCFC-22 at retail-gate per kg of product | M1: Kg CO2e from CH4 fossil | N1: Kg CO2e from CH4 bio | O1: Kg CO2e from N2O | P1: Kg CO2e from HCFC-22
A2: Fruits, berries, cocoa and coffee | B2: Apple | C2: Average | D2: Open-field | E2: ='Fruits, berries, cocoa, coffee'!C10 -> 1 | F2: ='Summary pivot'!$C$1 -> GWP100 with fb AR6 | G2: =Table1[[#This Row],[kg CO2 at retail-gate per kg of product]]+Table1[[#This Row],[Kg CO2e from CH4 fossil]]+Table1[[#This Row],[Kg CO2e from N2O]] -> 0.37887814 | H2: ='Fruits, berries, cocoa, coffee'!H11 -> 0.35933717 | I2: ='Fruits, berries, cocoa, coffee'!H12 -> 4.4897438e-05 | J2: 0 | K2: ='Fruits, berries, cocoa, coffee'!H13 -> 6.6677763e-05 | L2: 0 | M2: =Table1[[#This Row],[kg CH4 fossil at retail-gate per kg of product]]*'Summary pivot'!$D$5 -> 0.0013379436 | N2: =Table1[[#This Row],[kg CH4 bio at retail-gate per kg of product]]*'Summary pivot'!$D$4 -> 0 | O2: =Table1[[#This Row],[kg N2O at retail-gate per kg of product]]*'Summary pivot'!$D$6 -> 0.018203029 | P2: =Table1[[#This Row],[kg HCFC-22 at retail-gate per kg of product]]*'Summary pivot'!$D$7 -> 0
A3: Fruits, berries, cocoa and coffee | B3: Apple | C3: Sweden | D3: Open-field | E3: ='Fruits, berries, cocoa, coffee'!C14 -> 0.15862944 | F3: ='Summary pivot'!$C$1 -> GWP100 with fb AR6 | G3: =Table1[[#This Row],[kg CO2 at retail-gate per kg of product]]+Table1[[#This Row],[Kg CO2e from CH4 fossil]]+Table1[[#This Row],[Kg CO2e from N2O]] -> 0.15341643 | H3: ='Fruits, berries, cocoa, coffee'!H15 -> 0.1221874 | I3: ='Fruits, berries, cocoa, coffee'!H16 -> 5.2088245e-05 | J3: 0 | K3: ='Fruits, berries, cocoa, coffee'!H17 -> 0.00010870621 | L3: 0 | M3: =Table1[[#This Row],[kg CH4 fossil at retail-gate per kg of product]]*'Summary pivot'!$D$5 -> 0.0015522297 | N3: =Table1[[#This Row],[kg CH4 bio at retail-gate per kg of product]]*'Summary pivot'!$D$4 -> 0 | O3: =Table1[[#This Row],[kg N2O at retail-gate per kg of product]]*'Summary pivot'!$D$6 -> 0.029676796 | P3: =Table1[[#This Row],[kg HCFC-22 at retail-gate per kg of product]]*'Summary pivot'!$D$7 -> 0
A4: Fruits, berries, cocoa and coffee | B4: Apple | C4: Italy | D4: Open-field | E4: ='Fruits, berries, cocoa, coffee'!C18 -> 0.30710109 | F4: ='Summary pivot'!$C$1 -> GWP100 with fb AR6 | G4: =Table1[[#This Row],[kg CO2 at retail-gate per kg of product]]+Table1[[#This Row],[Kg CO2e from CH4 fossil]]+Table1[[#This Row],[Kg CO2e from N2O]] -> 0.37657963 | H4: ='Fruits, berries, cocoa, coffee'!H19 -> 0.36093237 | I4: ='Fruits, berries, cocoa, coffee'!H20 -> 2.5559701e-05 | J4: 0 | K4: ='Fruits, berries, cocoa, coffee'!H21 -> 5.4525945e-05 | L4: 0 | M4: =Table1[[#This Row],[kg CH4 fossil at retail-gate per kg of product]]*'Summary pivot'!$D$5 -> 0.00076167909 | N4: =Table1[[#This Row],[kg CH4 bio at retail-gate per kg of product]]*'Summary pivot'!$D$4 -> 0 | O4: =Table1[[#This Row],[kg N2O at retail-gate per kg of product]]*'Summary pivot'!$D$6 -> 0.014885583 | P4: =Table1[[#This Row],[kg HCFC-22 at retail-gate per kg of product]]*'Summary pivot'!$D$7 -> 0
A5: Fruits, berries, cocoa and coffee | B5: Apple | C5: Poland | D5: Open-field | E5: ='Fruits, berries, cocoa, coffee'!C22 -> 0.10348546 | F5: ='Summary pivot'!$C$1 -> GWP100 with fb AR6 | G5: =Table1[[#This Row],[kg CO2 at retail-gate per kg of product]]+Table1[[#This Row],[Kg CO2e from CH4 fossil]]+Table1[[#This Row],[Kg CO2e from N2O]] -> 0.495281 | H5: ='Fruits, berries, cocoa, coffee'!H23 -> 0.47219934 | I5: ='Fruits, berries, cocoa, coffee'!H24 -> 5.1774912e-05 | J5: 0 | K5: ='Fruits, berries, cocoa, coffee'!H25 -> 7.8896603e-05 | L5: 0 | M5: =Table1[[#This Row],[kg CH4 fossil at retail-gate per kg of product]]*'Summary pivot'!$D$5 -> 0.0015428924 | N5: =Table1[[#This Row],[kg CH4 bio at retail-gate per kg of product]]*'Summary pivot'!$D$4 -> 0 | O5: =Table1[[#This Row],[kg N2O at retail-gate per kg of product]]*'Summary pivot'!$D$6 -> 0.021538773 | P5: =Table1[[#This Row],[kg HCFC-22 at retail-gate per kg of product]]*'Summary pivot'!$D$7 -> 0
A6: Fruits, berries, cocoa and coffee | B6: Apple | C6: Rest of Europe | D6: Open-field | E6: ='Fruits, berries, cocoa, coffee'!C26 -> 0.43078401 | F6: ='Summary pivot'!$C$1 -> GWP100 with fb AR6 | G6: =Table1[[#This Row],[kg CO2 at retail-gate per kg of product]]+Table1[[#This Row],[Kg CO2e from CH4 fossil]]+Table1[[#This Row],[Kg CO2e from N2O]] -> 0.43557647 | H6: ='Fruits, berries, cocoa, coffee'!H27 -> 0.41841423 | I6: ='Fruits, berries, cocoa, coffee'!H28 -> 5.4383044e-05 | J6: 0 | K6: ='Fruits, berries, cocoa, coffee'!H29 -> 5.692906e-05 | L6: 0 | M6: =Table1[[#This Row],[kg CH4 fossil at retail-gate per kg of product]]*'Summary pivot'!$D$5 -> 0.0016206147 | N6: =Table1[[#This Row],[kg CH4 bio at retail-gate per kg of product]]*'Summary pivot'!$D$4 -> 0 | O6: =Table1[[#This Row],[kg N2O at retail-gate per kg of product]]*'Summary pivot'!$D$6 -> 0.015541633 | P6: =Table1[[#This Row],[kg HCFC-22 at retail-gate per kg of product]]*'Summary pivot'!$D$7 -> 0
A7: Fruits, berries, cocoa and coffee | B7: Pear | C7: Average | D7: Open-field | E7: ='Fruits, berries, cocoa, coffee'!C31 -> 1 | F7: ='Summary pivot'!$C$1 -> GWP100 with fb AR6 | G7: =Table1[[#This Row],[kg CO2 at retail-gate per kg of product]]+Table1[[#This Row],[Kg CO2e from CH4 fossil]]+Table1[[#This Row],[Kg CO2e from N2O]] -> 0.34540519 | H7: ='Fruits, berries, cocoa, coffee'!H32 -> 0.25374583 | I7: ='Fruits, berries, cocoa, coffee'!H33 -> 9.0304094e-05 | J7: 0 | K7: ='Fruits, berries, cocoa, coffee'!H34 -> 0.00032589118 | L7: 0 | M7: =Table1[[#This Row],[kg CH4 fossil at retail-gate per kg of product]]*'Summary pivot'!$D$5 -> 0.002691062 | N7: =Table1[[#This Row],[kg CH4 bio at retail-gate per kg of product]]*'Summary pivot'!$D$4 -> 0 | O7: =Table1[[#This Row],[kg N2O at retail-gate per kg of product]]*'Summary pivot'!$D$6 -> 0.088968292 | P7: =Table1[[#This Row],[kg HCFC-22 at retail-gate per kg of product]]*'Summary pivot'!$D$7 -> 0
A8: Fruits, berries, cocoa and coffee | B8: Pear | C8: Sweden | D8: Open-field | E8: ='Fruits, berries, cocoa, coffee'!C35 -> 0.055877298 | F8: ='Summary pivot'!$C$1 -> GWP100 with fb AR6 | G8: =Table1[[#This Row],[kg CO2 at retail-gate per kg of product]]+Table1[[#This Row],[Kg CO2e from CH4 fossil]]+Table1[[#This Row],[Kg CO2e from N2O]] -> 0.17322281 | H8: ='Fruits, berries, cocoa, coffee'!H36 -> 0.13380794 | I8: ='Fruits, berries, cocoa, coffee'!H37 -> 5.9396548e-05 | J8: 0 | K8: ='Fruits, berries, cocoa, coffee'!H38 -> 0.00013789324 | L8: 0 | M8: =Table1[[#This Row],[kg CH4 fossil at retail-gate per kg of product]]*'Summary pivot'!$D$5 -> 0.0017700171 | N8: =Table1[[#This Row],[kg CH4 bio at retail-gate per kg of product]]*'Summary pivot'!$D$4 -> 0 | O8: =Table1[[#This Row],[kg N2O at retail-gate per kg of product]]*'Summary pivot'!$D$6 -> 0.037644855 | P8: =Table1[[#This Row],[kg HCFC-22 at retail-gate per kg of product]]*'Summary pivot'!$D$7 -> 0
A9: Fruits, berries, cocoa and coffee | B9: Pear | C9: Belgium | D9: Open-field | E9: ='Fruits, berries, cocoa, coffee'!C39 -> 0.23061781 | F9: ='Summary pivot'!$C$1 -> GWP100 with fb AR6 | G9: =Table1[[#This Row],[kg CO2 at retail-gate per kg of product]]+Table1[[#This Row],[Kg CO2e from CH4 fossil]]+Table1[[#This Row],[Kg CO2e from N2O]] -> 0.19845356 | H9: ='Fruits, berries, cocoa, coffee'!H40 -> 0.18698792 | I9: ='Fruits, berries, cocoa, coffee'!H41 -> 2.4719196e-05 | J9: 0 | K9: ='Fruits, berries, cocoa, coffee'!H42 -> 3.9300404e-05 | L9: 0 | M9: =Table1[[#This Row],[kg CH4 fossil at retail-gate per kg of product]]*'Summary pivot'!$D$5 -> 0.00073663205 | N9: =Table1[[#This Row],[kg CH4 bio at retail-gate per kg of product]]*'Summary pivot'!$D$4 -> 0 | O9: =Table1[[#This Row],[kg N2O at retail-gate per kg of product]]*'Summary pivot'!$D$6 -> 0.01072901 | P9: =Table1[[#This Row],[kg HCFC-22 at retail-gate per kg of product]]*'Summary pivot'!$D$7 -> 0
A10: Fruits, berries, cocoa and coffee | B10: Pear | C10: The Nederlands | D10: Open-field | E10: ='Fruits, berries, cocoa, coffee'!C43 -> 0.48627566 | F10: ='Summary pivot'!$C$1 -> GWP100 with fb AR6 | G10: =Table1[[#This Row],[kg CO2 at retail-gate per kg of product]]+Table1[[#This Row],[Kg CO2e from CH4 fossil]]+Table1[[#This Row],[Kg CO2e from N2O]] -> 0.36238091 | H10: ='Fruits, berries, cocoa, coffee'!H44 -> 0.23008011 | I10: ='Fruits, berries, cocoa, coffee'!H45 -> 0.00010649148 | J10: 0 | K10: ='Fruits, berries, cocoa, coffee'!H46 -> 0.00047299397 | L10: 0 | M10: =Table1[[#This Row],[kg CH4 fossil at retail-gate per kg of product]]*'Summary pivot'!$D$5 -> 0.003173446 | N10: =Table1[[#This Row],[kg CH4 bio at retail-gate per kg of product]]*'Summary pivot'!$D$4 -> 0 | O10: =Table1[[#This Row],[kg N2O at retail-gate per kg of product]]*'Summary pivot'!$D$6 -> 0.12912735 | P10: =Table1[[#This Row],[kg HCFC-22 at retail-gate per kg of product]]*'Summary pivot'!$D$7 -> 0
A11: Fruits, berries, cocoa and coffee | B11: Pear | C11: Rest of Europe | D11: Open-field | E11: ='Fruits, berries, cocoa, coffee'!C47 -> 0.22722923 | F11: ='Summary pivot'!$C$1 -> GWP100 with fb AR6 | G11: =Table1[[#This Row],[kg CO2 at retail-gate per kg of product]]+Table1[[#This Row],[Kg CO2e from CH4 fossil]]+Table1[[#This Row],[Kg CO2e from N2O]] -> 0.50056069 | H11: ='Fruits, berries, cocoa, coffee'!H48 -> 0.40163805 | I11: ='Fruits, berries, cocoa, coffee'!H49 -> 0.00012982606 | J11: 0 | K11: ='Fruits, berries, cocoa, coffee'!H50 -> 0.00034818254 | L11: 0 | M11: =Table1[[#This Row],[kg CH4 fossil at retail-gate per kg of product]]*'Summary pivot'!$D$5 -> 0.0038688166 | N11: =Table1[[#This Row],[kg CH4 bio at retail-gate per kg of product]]*'Summary pivot'!$D$4 -> 0 | O11: =Table1[[#This Row],[kg N2O at retail-gate per kg of product]]*'Summary pivot'!$D$6 -> 0.095053832 | P11: =Table1[[#This Row],[kg HCFC-22 at retail-gate per kg of product]]*'Summary pivot'!$D$7 -> 0
A12: Fruits, berries, cocoa and coffee | B12: Melon | C12: Average | D12: / | E12: ='Fruits, berries, cocoa, coffee'!C52 -> 1 | F12: ='Summary pivot'!$C$1 -> GWP100 with fb AR6 | G12: =Table1[[#This Row],[kg CO2 at retail-gate per kg of product]]+Table1[[#This Row],[Kg CO2e from CH4 fossil]]+Table1[[#This Row],[Kg CO2e from N2O]] -> 1.7168736 | H12: ='Fruits, berries, cocoa, coffee'!H53 -> 1.5944747 | I12: ='Fruits, berries, cocoa, coffee'!H54 -> 0.0022401632 | J12: 0 | K12: ='Fruits, berries, cocoa, coffee'!H55 -> 0.00020381706 | L12: 0 | M12: =Table1[[#This Row],[kg CH4 fossil at retail-gate per kg of product]]*'Summary pivot'!$D$5 -> 0.066756865 | N12: =Table1[[#This Row],[kg CH4 bio at retail-gate per kg of product]]*'Summary pivot'!$D$4 -> 0 | O12: =Table1[[#This Row],[kg N2O at retail-gate per kg of product]]*'Summary pivot'!$D$6 -> 0.055642057 | P12: =Table1[[#This Row],[kg HCFC-22 at retail-gate per kg of product]]*'Summary pivot'!$D$7 -> 0
A13: Fruits, berries, cocoa and coffee | B13: Melon | C13: Sweden | D13: Greenhouse | E13: ='Fruits, berries, cocoa, coffee'!C56 -> 0.38 | F13: ='Summary pivot'!$C$1 -> GWP100 with fb AR6 | G13: =Table1[[#This Row],[kg CO2 at retail-gate per kg of product]]+Table1[[#This Row],[Kg CO2e from CH4 fossil]]+Table1[[#This Row],[Kg CO2e from N2O]] -> 3.9343248 | H13: ='Fruits, berries, cocoa, coffee'!H57 -> 3.6630031 | I13: ='Fruits, berries, cocoa, coffee'!H58 -> 0.0058171736 | J13: 0 | K13: ='Fruits, berries, cocoa, coffee'!H59 -> 0.00035886416 | L13: 0 | M13: =Table1[[#This Row],[kg CH4 fossil at retail-gate per kg of product]]*'Summary pivot'!$D$5 -> 0.17335177 | N13: =Table1[[#This Row],[kg CH4 bio at retail-gate per kg of product]]*'Summary pivot'!$D$4 -> 0 | O13: =Table1[[#This Row],[kg N2O at retail-gate per kg of product]]*'Summary pivot'!$D$6 -> 0.097969915 | P13: =Table1[[#This Row],[kg HCFC-22 at retail-gate per kg of product]]*'Summary pivot'!$D$7 -> 0
A14: Fruits, berries, cocoa and coffee | B14: Melon | C14: Spain | D14: Open-field | E14: ='Fruits, berries, cocoa, coffee'!C60 -> 0.34 | F14: ='Summary pivot'!$C$1 -> GWP100 with fb AR6 | G14: =Table1[[#This Row],[kg CO2 at retail-gate per kg of product]]+Table1[[#This Row],[Kg CO2e from CH4 fossil]]+Table1[[#This Row],[Kg CO2e from N2O]] -> 0.39609197 | H14: ='Fruits, berries, cocoa, coffee'!H61 -> 0.37069841 | I14: ='Fruits, berries, cocoa, coffee'!H62 -> 4.8969615e-05 | J14: 0 | K14: ='Fruits, berries, cocoa, coffee'!H63 -> 8.7671317e-05 | L14: 0 | M14: =Table1[[#This Row],[kg CH4 fossil at retail-gate per kg of product]]*'Summary pivot'!$D$5 -> 0.0014592945 | N14: =Table1[[#This Row],[kg CH4 bio at retail-gate per kg of product]]*'Summary pivot'!$D$4 -> 0 | O14: =Table1[[#This Row],[kg N2O at retail-gate per kg of product]]*'Summary pivot'!$D$6 -> 0.02393427 | P14: =Table1[[#This Row],[kg HCFC-22 at retail-gate per kg of product]]*'Summary pivot'!$D$7 -> 0
A15: Fruits, berries, cocoa and coffee | B15: Melon | C15: The Nederlands | D15: Open-field | E15: ='Fruits, berries, cocoa, coffee'!C64 -> 0.16 | F15: ='Summary pivot'!$C$1 -> GWP100 with fb AR6 | G15: =Table1[[#This Row],[kg CO2 at retail-gate per kg of product]]+Table1[[#This Row],[Kg CO2e from CH4 fossil]]+Table1[[#This Row],[Kg CO2e from N2O]] -> 0.2333757 | H15: ='Fruits, berries, cocoa, coffee'!H65 -> 0.19022278 | I15: ='Fruits, berries, cocoa, coffee'!H66 -> 4.3651452e-05 | J15: 0 | K15: ='Fruits, berries, cocoa, coffee'!H67 -> 0.00015330441 | L15: 0 | M15: =Table1[[#This Row],[kg CH4 fossil at retail-gate per kg of product]]*'Summary pivot'!$D$5 -> 0.0013008133 | N15: =Table1[[#This Row],[kg CH4 bio at retail-gate per kg of product]]*'Summary pivot'!$D$4 -> 0 | O15: =Table1[[#This Row],[kg N2O at retail-gate per kg of product]]*'Summary pivot'!$D$6 -> 0.041852104 | P15: =Table1[[#This Row],[kg HCFC-22 at retail-gate per kg of product]]*'Summary pivot'!$D$7 -> 0
A16: Fruits, berries, cocoa and coffee | B16: Melon | C16: Rest of Europe | D16: Open-field | E16: ='Fruits, berries, cocoa, coffee'!C68 -> 0.12 | F16: ='Summary pivot'!$C$1 -> GWP100 with fb AR6 | G16: =Table1[[#This Row],[kg CO2 at retail-gate per kg of product]]+Table1[[#This Row],[Kg CO2e from CH4 fossil]]+Table1[[#This Row],[Kg CO2e from N2O]] -> 0.41515694 | H16: ='Fruits, berries, cocoa, coffee'!H69 -> 0.38383692 | I16: ='Fruits, berries, cocoa, coffee'!H70 -> 5.0028023e-05 | J16: 0 | K16: ='Fruits, berries, cocoa, coffee'!H71 -> 0.00010926439 | L16: 0 | M16: =Table1[[#This Row],[kg CH4 fossil at retail-gate per kg of product]]*'Summary pivot'!$D$5 -> 0.0014908351 | N16: =Table1[[#This Row],[kg CH4 bio at retail-gate per kg of product]]*'Summary pivot'!$D$4 -> 0 | O16: =Table1[[#This Row],[kg N2O at retail-gate per kg of product]]*'Summary pivot'!$D$6 -> 0.029829179 | P16: =Table1[[#This Row],[kg HCFC-22 at retail-gate per kg of product]]*'Summary pivot'!$D$7 -> 0
A17: Fruits, berries, cocoa and coffee | B17: Banana | C17: Average | D17: Open-field | E17: ='Fruits, berries, cocoa, coffee'!C73 -> 1 | F17: ='Summary pivot'!$C$1 -> GWP100 with fb AR6 | G17: =Table1[[#This Row],[kg CO2 at retail-gate per kg of product]]+Table1[[#This Row],[Kg CO2e from CH4 fossil]]+Table1[[#This Row],[Kg CO2e from N2O]] -> 0.71329833 | H17: ='Fruits, berries, cocoa, coffee'!H74 -> 0.63986302 | I17: ='Fruits, berries, cocoa, coffee'!H75 -> 6.9274603e-05 | J17: 0 | K17: ='Fruits, berries, cocoa, coffee'!H76 -> 0.00026143197 | L17: 0 | M17: =Table1[[#This Row],[kg CH4 fossil at retail-gate per kg of product]]*'Summary pivot'!$D$5 -> 0.0020643832 | N17: =Table1[[#This Row],[kg CH4 bio at retail-gate per kg of product]]*'Summary pivot'!$D$4 -> 0 | O17: =Table1[[#This Row],[kg N2O at retail-gate per kg of product]]*'Summary pivot'!$D$6 -> 0.071370929 | P17: =Table1[[#This Row],[kg HCFC-22 at retail-gate per kg of product]]*'Summary pivot'!$D$7 -> 0
A18: Fruits, berries, cocoa and coffee | B18: Banana | C18: Costa Rica | D18: Open-field | E18: ='Fruits, berries, cocoa, coffee'!C77 -> 0.22683686 | F18: ='Summary pivot'!$C$1 -> GWP100 with fb AR6 | G18: =Table1[[#This Row],[kg CO2 at retail-gate per kg of product]]+Table1[[#This Row],[Kg CO2e from CH4 fossil]]+Table1[[#This Row],[Kg CO2e from N2O]] -> 0.76630946 | H18: ='Fruits, berries, cocoa, coffee'!H78 -> 0.63130343 | I18: ='Fruits, berries, cocoa, coffee'!H79 -> 0.00011879716 | J18: 0 | K18: ='Fruits, berries, cocoa, coffee'!H80 -> 0.00048156 | L18: 0 | M18: =Table1[[#This Row],[kg CH4 fossil at retail-gate per kg of product]]*'Summary pivot'!$D$5 -> 0.0035401555 | N18: =Table1[[#This Row],[kg CH4 bio at retail-gate per kg of product]]*'Summary pivot'!$D$4 -> 0 | O18: =Table1[[#This Row],[kg N2O at retail-gate per kg of product]]*'Summary pivot'!$D$6 -> 0.13146588 | P18: =Table1[[#This Row],[kg HCFC-22 at retail-gate per kg of product]]*'Summary pivot'!$D$7 -> 0
A19: Fruits, berries, cocoa and coffee | B19: Banana | C19: Ecuador | D19: Open-field | E19: ='Fruits, berries, cocoa, coffee'!C81 -> 0.21006031 | F19: ='Summary pivot'!$C$1 -> GWP100 with fb AR6 | G19: =Table1[[#This Row],[kg CO2 at retail-gate per kg of product]]+Table1[[#This Row],[Kg CO2e from CH4 fossil]]+Table1[[#This Row],[Kg CO2e from N2O]] -> 0.76542228 | H19: ='Fruits, berries, cocoa, coffee'!H82 -> 0.63357912 | I19: ='Fruits, berries, cocoa, coffee'!H83 -> 0.00011761396 | J19: 0 | K19: ='Fruits, berries, cocoa, coffee'!H84 -> 0.00047010353 | L19: 0 | M19: =Table1[[#This Row],[kg CH4 fossil at retail-gate per kg of product]]*'Summary pivot'!$D$5 -> 0.0035048961 | N19: =Table1[[#This Row],[kg CH4 bio at retail-gate per kg of product]]*'Summary pivot'!$D$4 -> 0 | O19: =Table1[[#This Row],[kg N2O at retail-gate per kg of product]]*'Summary pivot'!$D$6 -> 0.12833826 | P19: =Table1[[#This Row],[kg HCFC-22 at retail-gate per kg of product]]*'Summary pivot'!$D$7 -> 0
A20: Fruits, berries, cocoa and coffee | B20: Banana | C20: Dominican Republic | D20: Open-field | E20: ='Fruits, berries, cocoa, coffee'!C85 -> 0.18600803 | F20: ='Summary pivot'!$C$1 -> GWP100 with fb AR6 | G20: =Table1[[#This Row],[kg CO2 at retail-gate per kg of product]]+Table1[[#This Row],[Kg CO2e from CH4 fossil]]+Table1[[#This Row],[Kg CO2e from N2O]] -> 0.63586064 | H20: ='Fruits, berries, cocoa, coffee'!H86 -> 0.59565195 | I20: ='Fruits, berries, cocoa, coffee'!H87 -> 3.8784817e-05 | J20: 0 | K20: ='Fruits, berries, cocoa, coffee'!H88 -> 0.00014305092 | L20: 0 | M20: =Table1[[#This Row],[kg CH4 fossil at retail-gate per kg of product]]*'Summary pivot'!$D$5 -> 0.0011557876 | N20: =Table1[[#This Row],[kg CH4 bio at retail-gate per kg of product]]*'Summary pivot'!$D$4 -> 0 | O20: =Table1[[#This Row],[kg N2O at retail-gate per kg of product]]*'Summary pivot'!$D$6 -> 0.039052902 | P20: =Table1[[#This Row],[kg HCFC-22 at retail-gate per kg of product]]*'Summary pivot'!$D$7 -> 0
A21: Fruits, berries, cocoa and coffee | B21: Banana | C21: Rest of the world | D21: Open-field | E21: ='Fruits, berries, cocoa, coffee'!C89 -> 0.37709481 | F21: ='Summary pivot'!$C$1 -> GWP100 with fb AR6 | G21: =Table1[[#This Row],[kg CO2 at retail-gate per kg of product]]+Table1[[#This Row],[Kg CO2e from CH4 fossil]]+Table1[[#This Row],[Kg CO2e from N2O]] -> 0.69057191 | H21: ='Fruits, berries, cocoa, coffee'!H90 -> 0.6703202 | I21: ='Fruits, berries, cocoa, coffee'!H91 -> 2.7597078e-05 | J21: 0 | K21: ='Fruits, berries, cocoa, coffee'!H92 -> 7.1169652e-05 | L21: 0 | M21: =Table1[[#This Row],[kg CH4 fossil at retail-gate per kg of product]]*'Summary pivot'!$D$5 -> 0.00082239294 | N21: =Table1[[#This Row],[kg CH4 bio at retail-gate per kg of product]]*'Summary pivot'!$D$4 -> 0 | O21: =Table1[[#This Row],[kg N2O at retail-gate per kg of product]]*'Summary pivot'!$D$6 -> 0.019429315 | P21: =Table1[[#This Row],[kg HCFC-22 at retail-gate per kg of product]]*'Summary pivot'!$D$7 -> 0
A22: Fruits, berries, cocoa and coffee | B22: Orange | C22: Average | D22: Open-field | E22: ='Fruits, berries, cocoa, coffee'!C94 -> 1 | F22: ='Summary pivot'!$C$1 -> GWP100 with fb AR6 | G22: =Table1[[#This Row],[kg CO2 at retail-gate per kg of product]]+Table1[[#This Row],[Kg CO2e from CH4 fossil]]+Table1[[#This Row],[Kg CO2e from N2O]] -> 0.64669319 | H22: ='Fruits, berries, cocoa, coffee'!H95 -> 0.57932126 | I22: ='Fruits, berries, cocoa, coffee'!H96 -> 0.00010002485 | J22: 0 | K22: ='Fruits, berries, cocoa, coffee'!H97 -> 0.00023586518 | L22: 0 | M22: =Table1[[#This Row],[kg CH4 fossil at retail-gate per kg of product]]*'Summary pivot'!$D$5 -> 0.0029807406 | N22: =Table1[[#This Row],[kg CH4 bio at retail-gate per kg of product]]*'Summary pivot'!$D$4 -> 0 | O22: =Table1[[#This Row],[kg N2O at retail-gate per kg of product]]*'Summary pivot'!$D$6 -> 0.064391194 | P22: =Table1[[#This Row],[kg HCFC-22 at retail-gate per kg of product]]*'Summary pivot'!$D$7 -> 0
A23: Fruits, berries, cocoa and coffee | B23: Orange | C23: Spain | D23: Open-field | E23: ='Fruits, berries, cocoa, coffee'!C98 -> 0.44158071 | F23: ='Summary pivot'!$C$1 -> GWP100 with fb AR6 | G23: =Table1[[#This Row],[kg CO2 at retail-gate per kg of product]]+Table1[[#This Row],[Kg CO2e from CH4 fossil]]+Table1[[#This Row],[Kg CO2e from N2O]] -> 0.47169577 | H23: ='Fruits, berries, cocoa, coffee'!H99 -> 0.40302268 | I23: ='Fruits, berries, cocoa, coffee'!H100 -> 0.00011032632 | J23: 0 | K23: ='Fruits, berries, cocoa, coffee'!H101 -> 0.00023950683 | L23: 0 | M23: =Table1[[#This Row],[kg CH4 fossil at retail-gate per kg of product]]*'Summary pivot'!$D$5 -> 0.0032877244 | N23: =Table1[[#This Row],[kg CH4 bio at retail-gate per kg of product]]*'Summary pivot'!$D$4 -> 0 | O23: =Table1[[#This Row],[kg N2O at retail-gate per kg of product]]*'Summary pivot'!$D$6 -> 0.065385365 | P23: =Table1[[#This Row],[kg HCFC-22 at retail-gate per kg of product]]*'Summary pivot'!$D$7 -> 0
A24: Fruits, berries, cocoa and coffee | B24: Orange | C24: Rest of the world | D24: Open-field | E24: ='Fruits, berries, cocoa, coffee'!C102 -> 0.55841929 | F24: ='Summary pivot'!$C$1 -> GWP100 with fb AR6 | G24: =Table1[[#This Row],[kg CO2 at retail-gate per kg of product]]+Table1[[#This Row],[Kg CO2e from CH4 fossil]]+Table1[[#This Row],[Kg CO2e from N2O]] -> 0.78507574 | H24: ='Fruits, berries, cocoa, coffee'!H103 -> 0.71873272 | I24: ='Fruits, berries, cocoa, coffee'!H104 -> 9.187877e-05 | J24: 0 | K24: ='Fruits, berries, cocoa, coffee'!H105 -> 0.00023298548 | L24: 0 | M24: =Table1[[#This Row],[kg CH4 fossil at retail-gate per kg of product]]*'Summary pivot'!$D$5 -> 0.0027379874 | N24: =Table1[[#This Row],[kg CH4 bio at retail-gate per kg of product]]*'Summary pivot'!$D$4 -> 0 | O24: =Table1[[#This Row],[kg N2O at retail-gate per kg of product]]*'Summary pivot'!$D$6 -> 0.063605035 | P24: =Table1[[#This Row],[kg HCFC-22 at retail-gate per kg of product]]*'Summary pivot'!$D$7 -> 0
A25: Fruits, berries, cocoa and coffee | B25: Lemon | C25: Average | D25: Open-field | E25: ='Fruits, berries, cocoa, coffee'!C107 -> 1 | F25: ='Summary pivot'!$C$1 -> GWP100 with fb AR6 | G25: =Table1[[#This Row],[kg CO2 at retail-gate per kg of product]]+Table1[[#This Row],[Kg CO2e from CH4 fossil]]+Table1[[#This Row],[Kg CO2e from N2O]] -> 0.45593276 | H25: ='Fruits, berries, cocoa, coffee'!H108 -> 0.39359704 | I25: ='Fruits, berries, cocoa, coffee'!H109 -> 8.9226954e-05 | J25: 0 | K25: ='Fruits, berries, cocoa, coffee'!H110 -> 0.00021859619 | L25: 0 | M25: =Table1[[#This Row],[kg CH4 fossil at retail-gate per kg of product]]*'Summary pivot'!$D$5 -> 0.0026589632 | N25: =Table1[[#This Row],[kg CH4 bio at retail-gate per kg of product]]*'Summary pivot'!$D$4 -> 0 | O25: =Table1[[#This Row],[kg N2O at retail-gate per kg of product]]*'Summary pivot'!$D$6 -> 0.05967676 | P25: =Table1[[#This Row],[kg HCFC-22 at retail-gate per kg of product]]*'Summary pivot'!$D$7 -> 0
A26: Fruits, berries, cocoa and coffee | B26: Lemon | C26: Spain | D26: Open-field | E26: ='Fruits, berries, cocoa, coffee'!C111 -> 0.5618141 | F26: ='Summary pivot'!$C$1 -> GWP100 with fb AR6 | G26: =Table1[[#This Row],[kg CO2 at retail-gate per kg of product]]+Table1[[#This Row],[Kg CO2e from CH4 fossil]]+Table1[[#This Row],[Kg CO2e from N2O]] -> 0.47169577 | H26: ='Fruits, berries, cocoa, coffee'!H112 -> 0.40302268 | I26: ='Fruits, berries, cocoa, coffee'!H113 -> 0.00011032632 | J26: 0 | K26: ='Fruits, berries, cocoa, coffee'!H114 -> 0.00023950683 | L26: 0 | M26: =Table1[[#This Row],[kg CH4 fossil at retail-gate per kg of product]]*'Summary pivot'!$D$5 -> 0.0032877244 | N26: =Table1[[#This Row],[kg CH4 bio at retail-gate per kg of product]]*'Summary pivot'!$D$4 -> 0 | O26: =Table1[[#This Row],[kg N2O at retail-gate per kg of product]]*'Summary pivot'!$D$6 -> 0.065385365 | P26: =Table1[[#This Row],[kg HCFC-22 at retail-gate per kg of product]]*'Summary pivot'!$D$7 -> 0
A27: Fruits, berries, cocoa and coffee | B27: Lemon | C27: Rest of the world | D27: Open-field | E27: ='Fruits, berries, cocoa, coffee'!C115 -> 0.4381859 | F27: ='Summary pivot'!$C$1 -> GWP100 with fb AR6 | G27: =Table1[[#This Row],[kg CO2 at retail-gate per kg of product]]+Table1[[#This Row],[Kg CO2e from CH4 fossil]]+Table1[[#This Row],[Kg CO2e from N2O]] -> 0.43572243 | H27: ='Fruits, berries, cocoa, coffee'!H116 -> 0.38151208 | I27: ='Fruits, berries, cocoa, coffee'!H117 -> 6.2174685e-05 | J27: 0 | K27: ='Fruits, berries, cocoa, coffee'!H118 -> 0.00019178589 | L27: 0 | M27: =Table1[[#This Row],[kg CH4 fossil at retail-gate per kg of product]]*'Summary pivot'!$D$5 -> 0.0018528056 | N27: =Table1[[#This Row],[kg CH4 bio at retail-gate per kg of product]]*'Summary pivot'!$D$4 -> 0 | O27: =Table1[[#This Row],[kg N2O at retail-gate per kg of product]]*'Summary pivot'!$D$6 -> 0.052357549 | P27: =Table1[[#This Row],[kg HCFC-22 at retail-gate per kg of product]]*'Summary pivot'!$D$7 -> 0
A28: Fruits, berries, cocoa and coffee | B28: Avocado | C28: World average | D28: Open-field | E28: ='Fruits, berries, cocoa, coffee'!C120 -> 1 | F28: ='Summary pivot'!$C$1 -> GWP100 with fb AR6 | G28: =Table1[[#This Row],[kg CO2 at retail-gate per kg of product]]+Table1[[#This Row],[Kg CO2e from CH4 fossil]]+Table1[[#This Row],[Kg CO2e from N2O]] -> 1.064396 | H28: ='Fruits, berries, cocoa, coffee'!H121 -> 0.90762782 | I28: ='Fruits, berries, cocoa, coffee'!H122 -> 0.00020146218 | J28: 0 | K28: ='Fruits, berries, cocoa, coffee'!H123 -> 0.00055225119 | L28: 0 | M28: =Table1[[#This Row],[kg CH4 fossil at retail-gate per kg of product]]*'Summary pivot'!$D$5 -> 0.006003573 | N28: =Table1[[#This Row],[kg CH4 bio at retail-gate per kg of product]]*'Summary pivot'!$D$4 -> 0 | O28: =Table1[[#This Row],[kg N2O at retail-gate per kg of product]]*'Summary pivot'!$D$6 -> 0.15076457 | P28: =Table1[[#This Row],[kg HCFC-22 at retail-gate per kg of product]]*'Summary pivot'!$D$7 -> 0
A29: Fruits, berries, cocoa and coffee | B29: Kiwifruit | C29: Average | D29: Open-field | E29: ='Fruits, berries, cocoa, coffee'!C125 -> 1 | F29: ='Summary pivot'!$C$1 -> GWP100 with fb AR6 | G29: =Table1[[#This Row],[kg CO2 at retail-gate per kg of product]]+Table1[[#This Row],[Kg CO2e from CH4 fossil]]+Table1[[#This Row],[Kg CO2e from N2O]] -> 0.63217957 | H29: ='Fruits, berries, cocoa, coffee'!H126 -> 0.58067426 | I29: ='Fruits, berries, cocoa, coffee'!H127 -> 7.8102951e-05 | J29: 0 | K29: ='Fruits, berries, cocoa, coffee'!H128 -> 0.00018013861 | L29: 0 | M29: =Table1[[#This Row],[kg CH4 fossil at retail-gate per kg of product]]*'Summary pivot'!$D$5 -> 0.0023274679 | N29: =Table1[[#This Row],[kg CH4 bio at retail-gate per kg of product]]*'Summary pivot'!$D$4 -> 0 | O29: =Table1[[#This Row],[kg N2O at retail-gate per kg of product]]*'Summary pivot'!$D$6 -> 0.049177841 | P29: =Table1[[#This Row],[kg HCFC-22 at retail-gate per kg of product]]*'Summary pivot'!$D$7 -> 0
A30: Fruits, berries, cocoa and coffee | B30: Kiwifruit | C30: Italy | D30: Open-field | E30: ='Fruits, berries, cocoa, coffee'!C129 -> 0.49 | F30: ='Summary pivot'!$C$1 -> GWP100 with fb AR6 | G30: =Table1[[#This Row],[kg CO2 at retail-gate per kg of product]]+Table1[[#This Row],[Kg CO2e from CH4 fossil]]+Table1[[#This Row],[Kg CO2e from N2O]] -> 0.45852521 | H30: ='Fruits, berries, cocoa, coffee'!H130 -> 0.40372084 | I30: ='Fruits, berries, cocoa, coffee'!H131 -> 6.469386e-05 | J30: 0 | K30: ='Fruits, berries, cocoa, coffee'!H132 -> 0.00019368678 | L30: 0 | M30: =Table1[[#This Row],[kg CH4 fossil at retail-gate per kg of product]]*'Summary pivot'!$D$5 -> 0.001927877 | N30: =Table1[[#This Row],[kg CH4 bio at retail-gate per kg of product]]*'Summary pivot'!$D$4 -> 0 | O30: =Table1[[#This Row],[kg N2O at retail-gate per kg of product]]*'Summary pivot'!$D$6 -> 0.052876492 | P30: =Table1[[#This Row],[kg HCFC-22 at retail-gate per kg of product]]*'Summary pivot'!$D$7 -> 0
A31: Fruits, berries, cocoa and coffee | B31: Kiwifruit | C31: Rest of the world | D31: Open-field | E31: ='Fruits, berries, cocoa, coffee'!C133 -> 0.51 | F31: ='Summary pivot'!$C$1 -> GWP100 with fb AR6 | G31: =Table1[[#This Row],[kg CO2 at retail-gate per kg of product]]+Table1[[#This Row],[Kg CO2e from CH4 fossil]]+Table1[[#This Row],[Kg CO2e from N2O]] -> 0.79902396 | H31: ='Fruits, berries, cocoa, coffee'!H134 -> 0.75068834 | I31: ='Fruits, berries, cocoa, coffee'!H135 -> 9.0986194e-05 | J31: 0 | K31: ='Fruits, berries, cocoa, coffee'!H136 -> 0.00016712174 | L31: 0 | M31: =Table1[[#This Row],[kg CH4 fossil at retail-gate per kg of product]]*'Summary pivot'!$D$5 -> 0.0027113886 | N31: =Table1[[#This Row],[kg CH4 bio at retail-gate per kg of product]]*'Summary pivot'!$D$4 -> 0 | O31: =Table1[[#This Row],[kg N2O at retail-gate per kg of product]]*'Summary pivot'!$D$6 -> 0.045624236 | P31: =Table1[[#This Row],[kg HCFC-22 at retail-gate per kg of product]]*'Summary pivot'!$D$7 -> 0
A32: Fruits, berries, cocoa and coffee | B32: Strawberry | C32: Average | D32: Open-field | E32: ='Fruits, berries, cocoa, coffee'!C138 -> 1 | F32: ='Summary pivot'!$C$1 -> GWP100 with fb AR6 | G32: =Table1[[#This Row],[kg CO2 at retail-gate per kg of product]]+Table1[[#This Row],[Kg CO2e from CH4 fossil]]+Table1[[#This Row],[Kg CO2e from N2O]] -> 0.73791114 | H32: ='Fruits, berries, cocoa, coffee'!H139 -> 0.64851804 | I32: ='Fruits, berries, cocoa, coffee'!H140 -> 0.001219915 | J32: 0 | K32: ='Fruits, berries, cocoa, coffee'!H141 -> 0.00019428435 | L32: 0 | M32: =Table1[[#This Row],[kg CH4 fossil at retail-gate per kg of product]]*'Summary pivot'!$D$5 -> 0.036353468 | N32: =Table1[[#This Row],[kg CH4 bio at retail-gate per kg of product]]*'Summary pivot'!$D$4 -> 0 | O32: =Table1[[#This Row],[kg N2O at retail-gate per kg of product]]*'Summary pivot'!$D$6 -> 0.053039627 | P32: =Table1[[#This Row],[kg HCFC-22 at retail-gate per kg of product]]*'Summary pivot'!$D$7 -> 0
A33: Fruits, berries, cocoa and coffee | B33: Strawberry | C33: Sweden | D33: Open-field | E33: ='Fruits, berries, cocoa, coffee'!C142 -> 0.69 | F33: ='Summary pivot'!$C$1 -> GWP100 with fb AR6 | G33: =Table1[[#This Row],[kg CO2 at retail-gate per kg of product]]+Table1[[#This Row],[Kg CO2e from CH4 fossil]]+Table1[[#This Row],[Kg CO2e from N2O]] -> 0.42387643 | H33: ='Fruits, berries, cocoa, coffee'!H143 -> 0.36462364 | I33: ='Fruits, berries, cocoa, coffee'!H144 -> 8.7445351e-05 | J33: 0 | K33: ='Fruits, berries, cocoa, coffee'!H145 -> 0.00020749788 | L33: 0 | M33: =Table1[[#This Row],[kg CH4 fossil at retail-gate per kg of product]]*'Summary pivot'!$D$5 -> 0.0026058715 | N33: =Table1[[#This Row],[kg CH4 bio at retail-gate per kg of product]]*'Summary pivot'!$D$4 -> 0 | O33: =Table1[[#This Row],[kg N2O at retail-gate per kg of product]]*'Summary pivot'!$D$6 -> 0.056646921 | P33: =Table1[[#This Row],[kg HCFC-22 at retail-gate per kg of product]]*'Summary pivot'!$D$7 -> 0
A34: Fruits, berries, cocoa and coffee | B34: Strawberry | C34: Belgium | D34: Open-field | E34: ='Fruits, berries, cocoa, coffee'!C146 -> 0.14 | F34: ='Summary pivot'!$C$1 -> GWP100 with fb AR6 | G34: =Table1[[#This Row],[kg CO2 at retail-gate per kg of product]]+Table1[[#This Row],[Kg CO2e from CH4 fossil]]+Table1[[#This Row],[Kg CO2e from N2O]] -> 0.41939891 | H34: ='Fruits, berries, cocoa, coffee'!H147 -> 0.37682941 | I34: ='Fruits, berries, cocoa, coffee'!H148 -> 4.6622801e-05 | J34: 0 | K34: ='Fruits, berries, cocoa, coffee'!H149 -> 0.00015084298 | L34: 0 | M34: =Table1[[#This Row],[kg CH4 fossil at retail-gate per kg of product]]*'Summary pivot'!$D$5 -> 0.0013893595 | N34: =Table1[[#This Row],[kg CH4 bio at retail-gate per kg of product]]*'Summary pivot'!$D$4 -> 0 | O34: =Table1[[#This Row],[kg N2O at retail-gate per kg of product]]*'Summary pivot'!$D$6 -> 0.041180134 | P34: =Table1[[#This Row],[kg HCFC-22 at retail-gate per kg of product]]*'Summary pivot'!$D$7 -> 0
A35: Fruits, berries, cocoa and coffee | B35: Strawberry | C35: Rest of Europe | D35: Greenhouse | E35: ='Fruits, berries, cocoa, coffee'!C150 -> 0.085 | F35: ='Summary pivot'!$C$1 -> GWP100 with fb AR6 | G35: =Table1[[#This Row],[kg CO2 at retail-gate per kg of product]]+Table1[[#This Row],[Kg CO2e from CH4 fossil]]+Table1[[#This Row],[Kg CO2e from N2O]] -> 3.9582679 | H35: ='Fruits, berries, cocoa, coffee'!H151 -> 3.4901827 | I35: ='Fruits, berries, cocoa, coffee'!H152 -> 0.013490575 | J35: 0 | K35: ='Fruits, berries, cocoa, coffee'!H153 -> 0.00024200019 | L35: 0 | M35: =Table1[[#This Row],[kg CH4 fossil at retail-gate per kg of product]]*'Summary pivot'!$D$5 -> 0.40201912 | N35: =Table1[[#This Row],[kg CH4 bio at retail-gate per kg of product]]*'Summary pivot'!$D$4 -> 0 | O35: =Table1[[#This Row],[kg N2O at retail-gate per kg of product]]*'Summary pivot'!$D$6 -> 0.066066053 | P35: =Table1[[#This Row],[kg HCFC-22 at retail-gate per kg of product]]*'Summary pivot'!$D$7 -> 0
A36: Fruits, berries, cocoa and coffee | B36: Strawberry | C36: Rest of Europe | D36: Open-field | E36: ='Fruits, berries, cocoa, coffee'!C154 -> 0.085 | F36: ='Summary pivot'!$C$1 -> GWP100 with fb AR6 | G36: =Table1[[#This Row],[kg CO2 at retail-gate per kg of product]]+Table1[[#This Row],[Kg CO2e from CH4 fossil]]+Table1[[#This Row],[Kg CO2e from N2O]] -> 0.59138565 | H36: ='Fruits, berries, cocoa, coffee'!H155 -> 0.55889506 | I36: ='Fruits, berries, cocoa, coffee'!H156 -> 7.4726141e-05 | J36: 0 | K36: ='Fruits, berries, cocoa, coffee'!H157 -> 0.00011085622 | L36: 0 | M36: =Table1[[#This Row],[kg CH4 fossil at retail-gate per kg of product]]*'Summary pivot'!$D$5 -> 0.002226839 | N36: =Table1[[#This Row],[kg CH4 bio at retail-gate per kg of product]]*'Summary pivot'!$D$4 -> 0 | O36: =Table1[[#This Row],[kg N2O at retail-gate per kg of product]]*'Summary pivot'!$D$6 -> 0.030263749 | P36: =Table1[[#This Row],[kg HCFC-22 at retail-gate per kg of product]]*'Summary pivot'!$D$7 -> 0
A37: Fruits, berries, cocoa and coffee | B37: Raspberry | C37: Average | D37: Open-field | E37: ='Fruits, berries, cocoa, coffee'!C159 -> 1 | F37: ='Summary pivot'!$C$1 -> GWP100 with fb AR6 | G37: =Table1[[#This Row],[kg CO2 at retail-gate per kg of product]]+Table1[[#This Row],[Kg CO2e from CH4 fossil]]+Table1[[#This Row],[Kg CO2e from N2O]] -> 0.76684375 | H37: ='Fruits, berries, cocoa, coffee'!H160 -> 0.53776445 | I37: ='Fruits, berries, cocoa, coffee'!H161 -> 0.00020773901 | J37: 0 | K37: ='Fruits, berries, cocoa, coffee'!H162 -> 0.00081644203 | L37: 0 | M37: =Table1[[#This Row],[kg CH4 fossil at retail-gate per kg of product]]*'Summary pivot'!$D$5 -> 0.0061906224 | N37: =Table1[[#This Row],[kg CH4 bio at retail-gate per kg of product]]*'Summary pivot'!$D$4 -> 0 | O37: =Table1[[#This Row],[kg N2O at retail-gate per kg of product]]*'Summary pivot'!$D$6 -> 0.22288868 | P37: =Table1[[#This Row],[kg HCFC-22 at retail-gate per kg of product]]*'Summary pivot'!$D$7 -> 0
A38: Fruits, berries, cocoa and coffee | B38: Raspberry | C38: Sweden | D38: Open-field | E38: ='Fruits, berries, cocoa, coffee'!C163 -> 0.44 | F38: ='Summary pivot'!$C$1 -> GWP100 with fb AR6 | G38: =Table1[[#This Row],[kg CO2 at retail-gate per kg of product]]+Table1[[#This Row],[Kg CO2e from CH4 fossil]]+Table1[[#This Row],[Kg CO2e from N2O]] -> 0.88398645 | H38: ='Fruits, berries, cocoa, coffee'!H164 -> 0.54006654 | I38: ='Fruits, berries, cocoa, coffee'!H165 -> 0.00026768025 | J38: 0 | K38: ='Fruits, berries, cocoa, coffee'!H166 -> 0.0012305606 | L38: 0 | M38: =Table1[[#This Row],[kg CH4 fossil at retail-gate per kg of product]]*'Summary pivot'!$D$5 -> 0.0079768714 | N38: =Table1[[#This Row],[kg CH4 bio at retail-gate per kg of product]]*'Summary pivot'!$D$4 -> 0 | O38: =Table1[[#This Row],[kg N2O at retail-gate per kg of product]]*'Summary pivot'!$D$6 -> 0.33594304 | P38: =Table1[[#This Row],[kg HCFC-22 at retail-gate per kg of product]]*'Summary pivot'!$D$7 -> 0
A39: Fruits, berries, cocoa and coffee | B39: Raspberry | C39: Belgium | D39: Open-field | E39: ='Fruits, berries, cocoa, coffee'!C167 -> 0.15 | F39: ='Summary pivot'!$C$1 -> GWP100 with fb AR6 | G39: =Table1[[#This Row],[kg CO2 at retail-gate per kg of product]]+Table1[[#This Row],[Kg CO2e from CH4 fossil]]+Table1[[#This Row],[Kg CO2e from N2O]] -> 0.54508324 | H39: ='Fruits, berries, cocoa, coffee'!H168 -> 0.44116128 | I39: ='Fruits, berries, cocoa, coffee'!H169 -> 0.00010676808 | J39: 0 | K39: ='Fruits, berries, cocoa, coffee'!H170 -> 0.000369012 | L39: 0 | M39: =Table1[[#This Row],[kg CH4 fossil at retail-gate per kg of product]]*'Summary pivot'!$D$5 -> 0.0031816887 | N39: =Table1[[#This Row],[kg CH4 bio at retail-gate per kg of product]]*'Summary pivot'!$D$4 -> 0 | O39: =Table1[[#This Row],[kg N2O at retail-gate per kg of product]]*'Summary pivot'!$D$6 -> 0.10074028 | P39: =Table1[[#This Row],[kg HCFC-22 at retail-gate per kg of product]]*'Summary pivot'!$D$7 -> 0
A40: Fruits, berries, cocoa and coffee | B40: Raspberry | C40: The Nederlands | D40: Open-field | E40: ='Fruits, berries, cocoa, coffee'!C171 -> 0.25 | F40: ='Summary pivot'!$C$1 -> GWP100 with fb AR6 | G40: =Table1[[#This Row],[kg CO2 at retail-gate per kg of product]]+Table1[[#This Row],[Kg CO2e from CH4 fossil]]+Table1[[#This Row],[Kg CO2e from N2O]] -> 0.63772645 | H40: ='Fruits, berries, cocoa, coffee'!H172 -> 0.49086381 | I40: ='Fruits, berries, cocoa, coffee'!H173 -> 0.00015088477 | J40: 0 | K40: ='Fruits, berries, cocoa, coffee'!H174 -> 0.00052148819 | L40: 0 | M40: =Table1[[#This Row],[kg CH4 fossil at retail-gate per kg of product]]*'Summary pivot'!$D$5 -> 0.0044963662 | N40: =Table1[[#This Row],[kg CH4 bio at retail-gate per kg of product]]*'Summary pivot'!$D$4 -> 0 | O40: =Table1[[#This Row],[kg N2O at retail-gate per kg of product]]*'Summary pivot'!$D$6 -> 0.14236628 | P40: =Table1[[#This Row],[kg HCFC-22 at retail-gate per kg of product]]*'Summary pivot'!$D$7 -> 0
...

Sheet Summary pivot
C1: GWP100 with fb AR6
C2: GWP/GTP factors used:
C3: Carbon dioxide | D3: 1
C4: Methane bio | D4: =INDEX('Common input data'!A5:F15,MATCH(C1,'Common input data'!A5:A15,0),3) -> 27
C5: Methane fossil | D5: =INDEX('Common input data'!A5:F15,MATCH(C1,'Common input data'!A5:A15,0),4) -> 29.8
C6: Nitrous oxide | D6: =INDEX('Common input data'!A5:F15,MATCH(C1,'Common input data'!A5:A15,0),5) -> 273
C7: HCFC-22 | D7: =INDEX('Common input data'!A5:F15,MATCH(C1,'Common input data'!A5:A15,0),6) -> 1960
A9: Product group | B9: Food product | C9: Production country | D9: Sum of Share of market | E9: Kg CO2e at retail-gate per kg of product | F9: kg CO2 at retail-gate per kg of product | G9: kg CH4 fossil at retail-gate per kg of product | H9: kg CH4 bio at retail-gate per kg of product | I9: kg N2O at retail-gate per kg of product | J9: kg HCFC-22 at retail-gate per kg of product | K9: kg CO2e from CH4 fossil | L9: kg CO2e from CH4 bio | M9: kg CO2e from N2O | N9: kg CO2e from HCFC-22
A10: Dairy product | B10: Butter (82% fat) | C10: Average | D10: 1 | E10: 5.1928724 | F10: 2.3818856 | G10: 0.0021467841 | H10: 0.21052783 | I10: 0.010062317 | J10: 0 | K10: 0.063974167 | L10: 5.7263569 | M10: 2.7470126 | N10: 0
C11: Denmark | D11: 0 | E11: 5.0319517 | F11: 2.2212942 | G11: 0.0021408263 | H11: 0.21052783 | I11: 0.010061762 | J11: 0 | K11: 0.063796624 | L11: 5.7263569 | M11: 2.746861 | N11: 0
C12: Rest of Europe | D12: 0.16099071 | E12: 6.2979155 | F12: 3.4852133 | G12: 0.0021778334 | H12: 0.21052783 | I12: 0.010065212 | J12: 0 | K12: 0.064899436 | L12: 5.7263569 | M12: 2.7478028 | N12: 0
C13: Sweden | D13: 0.83900929 | E13: 4.9808346 | F13: 2.170177 | G13: 0.0021408263 | H13: 0.21052783 | I13: 0.010061762 | J13: 0 | K13: 0.063796624 | L13: 5.7263569 | M13: 2.746861 | N13: 0
B14: Cream (40% fat) | C14: Average | D14: 1 | E14: 2.6335681 | F14: 1.2052813 | G14: 0.0010897581 | H14: 0.10697552 | I14: 0.0051128647 | J14: 0 | K14: 0.032474793 | L14: 2.9097342 | M14: 1.3958121 | N14: 0
C15: Rest of Europe | D15: 0.1031614 | E15: 3.3041817 | F15: 1.8749631 | G15: 0.0011066227 | H15: 0.10697552 | I15: 0.0051144368 | J15: 0 | K15: 0.032977356 | L15: 2.9097342 | M15: 1.3962412 | N15: 0
C16: Sweden | D16: 0.8968386 | E16: 2.5564289 | F16: 1.1282492 | G16: 0.0010878182 | H16: 0.10697552 | I16: 0.0051126838 | J16: 0 | K16: 0.032416984 | L16: 2.9097342 | M16: 1.3957627 | N16: 0
B17: Crème fraiche (34% fat | C17: Average | D17: 1 | E17: 4.824595 | F17: 2.3490513 | G17: 0.00094692082 | H17: 0.18756023 | I17: 0.0089645623 | J17: 0 | K17: 0.02821824 | L17: 5.1016381 | M17: 2.4473255 | N17: 0
C18: Rest of Europe | D18: 0.232 | E18: 6.1169526 | F18: 3.6403309 | G18: 0.00095944186 | H18: 0.18756023 | I18: 0.0089671441 | J18: 0 | K18: 0.028591368 | L18: 5.1016381 | M18: 2.4480303 | N18: 0
C19: Sweden | D19: 0.768 | E19: 4.57839 | F19: 2.1030932 | G19: 0.00094313842 | H19: 0.18756023 | I19: 0.0089640706 | J19: 0 | K19: 0.028105525 | L19: 5.1016381 | M19: 2.4471913 | N19: 0
B20: Desert cheese (25% fat) | C20: Average | D20: 1 | E20: 3.7434617 | F20: 2.0376479 | G20: 0 | H20: 0.13072409 | I20: 0.0062484023 | J20: 0 | K20: 0 | L20: 3.5556952 | M20: 1.7058138 | N20: 0
C21: Denmark | D21: 0.16 | E21: 3.3931108 | F21: 1.6874888 | G21: 0 | H21: 0.13072409 | I21: 0.0062476996 | J21: 0 | K21: 0 | L21: 3.5556952 | M21: 1.705622 | N21: 0
C22: Rest of Europe | D22: 0.218 | E22: 4.5753323 | F22: 2.8691255 | G22: 0 | H22: 0.13072409 | I22: 0.0062498418 | J22: 0 | K22: 0 | L22: 3.5556952 | M22: 1.7062068 | N22: 0
C23: Sweden | D23: 0.512 | E23: 3.3419936 | F23: 1.6363716 | G23: 0 | H23: 0.13072409 | I23: 0.0062476996 | J23: 0 | K23: 0 | L23: 3.5556952 | M23: 1.705622 | N23: 0
C24: The Nederlands | D24: 0.11 | E24: 4.473098 | F24: 2.7668912 | G24: 0 | H24: 0.13072409 | I24: 0.0062498418 | J24: 0 | K24: 0 | L24: 3.5556952 | M24: 1.7062068 | N24: 0
B25: Hard cheese (38% fat) | C25: Average | D25: 1 | E25: 5.5188309 | F25: 2.8332125 | G25: 0.0020566939 | H25: 0.20111398 | I25: 0.0096129265 | J25: 0 | K25: 0.061289477 | L25: 5.4703003 | M25: 2.6243289 | N25: 0
C26: Denmark | D26: 0.16 | E26: 5.0543114 | F26: 2.3693336 | G26: 0.0020450983 | H26: 0.20111398 | I26: 0.0096118456 | J26: 0 | K26: 0.060943929 | L26: 5.4703003 | M26: 2.6240338 | N26: 0
C27: Rest of Europe | D27: 0.218 | E27: 6.5846081 | F27: 3.8976771 | G27: 0.0020804506 | H27: 0.20111398 | I27: 0.0096151412 | J27: 0 | K27: 0.061997429 | L27: 5.4703003 | M27: 2.6249335 | N27: 0
C28: Sweden | D28: 0.512 | E28: 5.0031942 | F28: 2.3182164 | G28: 0.0020450983 | H28: 0.20111398 | I28: 0.0096118456 | J28: 0 | K28: 0.060943929 | L28: 5.4703003 | M28: 2.6240338 | N28: 0
C29: The Nederlands | D29: 0.11 | E29: 6.4823737 | F29: 3.7954427 | G29: 0.0020804506 | H29: 0.20111398 | I29: 0.0096151412 | J29: 0 | K29: 0.061997429 | L29: 5.4703003 | M29: 2.6249335 | N29: 0
B30: Milk powder | C30: Average | D30: 1 | E30: 4.8533707 | F30: 2.3490513 | G30: 0.0019125473 | H30: 0.18756023 | I30: 0.0089645623 | J30: 0 | K30: 0.056993911 | L30: 5.1016381 | M30: 2.4473255 | N30: 0
C31: Rest of Europe | D31: 0.16 | E31: 6.1461804 | F31: 3.6403309 | G31: 0.001940242 | H31: 0.18756023 | I31: 0.0089671441 | J31: 0 | K31: 0.057819211 | L31: 5.1016381 | M31: 2.4480303 | N31: 0
C32: Sweden | D32: 0.84 | E32: 4.6071212 | F32: 2.1030932 | G32: 0.0019072722 | H32: 0.18756023 | I32: 0.0089640706 | J32: 0 | K32: 0.05683671 | L32: 5.1016381 | M32: 2.4471913 | N32: 0
B33: Pasteurized milk (3% fat) | C33: Sweden | D33: 1 | E33: 0.60534139 | F33: 0.31970546 | G33: 0.00021756365 | H33: 0.021395104 | I33: 0.0010225368 | J33: 0 | K33: 0.0064833968 | L33: 0.58194684 | M33: 0.27915254 | N33: 0
B34: Yogurt (3% fat) | C34: Average | D34: 1 | E34: 0.78441658 | F34: 0.49873244 | G34: 0.00021843618 | H34: 0.021395104 | I34: 0.0010226181 | J34: 0 | K34: 0.006509398 | L34: 0.58194684 | M34: 0.27917474 | N34: 0
C35: Rest of Europe | D35: 0.232 | E35: 1.1403155 | F35: 0.85447178 | G35: 0.00022132454 | H35: 0.021395104 | I35: 0.0010228874 | J35: 0 | K35: 0.0065954712 | L35: 0.58194684 | M35: 0.27924825 | N35: 0
C36: Sweden | D36: 0.768 | E36: 0.67690545 | F36: 0.39126951 | G36: 0.00021756365 | H36: 0.021395104 | I36: 0.0010225368 | J36: 0 | K36: 0.0064833968 | L36: 0.58194684 | M36: 0.27915254 | N36: 0

Sheet Meat and eggs
A1: Results meat and eggs | F1: Choice of climate metric: | G1: GTP100 with fb AR6
F2: Include land use change? | G2: Yes
F3: Include soil carbon changes? Go to: "Common input data" --> "Choose factors for soil carbon changes" | G3: Yes | AR3: Allocation for years | AS3: 100
E5: GHG EMISSIONS AND CLIMATE IMPACT | V5: CROPLAND USE | Z5: PASTURE USE | AD5: NITROGEN APPLICATION | AH5: PHOSPHORUS APPLICATION | AL5: FRESHWATER USE | AR5: EXTINCTION RATE | AV5: PESTICIDE USE | AZ5: AMMONIA EMISSIONS | BD5: NOx EMISSIONS
E6: Summary of results in different process steps >> | I6: Results in different process steps >> | V6: Results in different process steps >> | Z6: Results in different process steps >> | AD6: Results in different process steps >> | AH6: Results in different process steps >> | AL6: Results in different process steps >> | AR6: Results in different process steps >> | AV6: Results in different process steps >> | AZ6: Results in different process steps >> | BD6: Results in different process steps >> | BZ6: GWP/GTP factors used:
F7: RESULTS | I7: Feed production | K7: Manure management | V7: To farm-gate | W7: To retail-gate, including waste and losses | X7: At consumer, including additional waste and losses after retail-gate | Z7: To farm-gate | AA7: To retail-gate, including waste and losses | AB7: At consumer, including additional waste and losses after retail-gate | AD7: To farm-gate | AE7: To retail-gate, including waste and losses | AF7: At consumer, including additional waste and losses after retail-gate | AH7: To farm-gate | AI7: To retail-gate, including waste and losses | AJ7: At consumer, including additional waste and losses after retail-gate | AL7: Feed use | AM7: Housing and drinking water | AN7: To farm-gate | AO7: To retail-gate, including waste and losses | AP7: At consumer, including additional waste and losses after retail-gate | AR7: To farm-gate | AS7: To retail-gate, including waste and losses | AT7: At consumer, including additional waste and losses after retail-gate | AV7: To farm-gate | AW7: To retail-gate, including waste and losses | AX7: At consumer, including additional waste and losses after retail-gate | AZ7: To farm-gate | BA7: To retail-gate, including waste and losses | BB7: At consumer, including additional waste and losses after retail-gate | BD7: To retail-gate, including waste and losses | BE7: At consumer, including additional waste and losses after retail-gate | BZ7: Carbon dioxide | CA7: 1
B8: Production system | C8: Share of market | F8: Agricultural emissions only | G8: To farm-gate | H8: To retail-gate | I8: Energy use and mineral fertilizer production | J8: Soil emissions | K8: Direct emissions | L8: Indirect emissions | M8: Enteric fermentation | N8: Soil carbon emissions | O8: LUC emissions | P8: Energy use in stables | Q8: Energy use at slaughter | R8: Total after processing | S8: Packaging | T8: Transportation | V8: Per kg | W8: Per kg | X8: Per kg | Z8: Per kg | AA8: Per kg | AB8: Per kg | AD8: Per kg | AE8: Per kg | AF8: Per kg | AH8: Per kg | AI8: Per kg | AJ8: Per kg | AL8: Per kg | AM8: Per kg | AN8: Per kg | AO8: Per kg | AP8: Per kg | AR8: Per kg | AS8: Per kg | AT8: Per kg | AV8: Per kg | AW8: Per kg | AX8: Per kg | AZ8: Per kg | BA8: Per kg | BB8: Per kg | BD8: Per kg | BE8: Per kg | BZ8: Bio Methane | CA8: =INDEX('Common input data'!A5:F15,MATCH(G1,'Common input data'!A5:A15,0),3) -> 4.7
A9: PORK MEAT | F9: Per kg carcass weight | G9: Per kg carcass weight | H9: Per kg bone free weight | BZ9: Fossil methane | CA9: =INDEX('Common input data'!A5:F15,MATCH(G1,'Common input data'!A5:A15,0),4) -> 4.7
A10: Average | C10: =SUM(C15:C32) -> 1 | E10: kg CO2e | F10: =SUMPRODUCT($CA$7:$CA$10,F11:F14) -> 1.3728347 | G10: =SUMPRODUCT($CA$7:$CA$10,G11:G14) -> 2.819819 | H10: =SUMPRODUCT($CA$7:$CA$10,H11:H14) -> 5.9894862 | V10: =V15*$C$15+V20*$C$20+V25*$C$25+V30*$C$30 -> 7.6308498 | W10: =W15*$C$15+W20*$C$20+W25*$C$25+W30*$C$30 -> 8.3023646 | X10: =X15*$C$15+X20*$C$20+X25*$C$25+X30*$C$30 -> 9.2156247 | AD10: =AD15*$C$15+AD20*$C$20+AD25*$C$25+AD30*$C$30 -> 0.092264169 | AE10: =AE15*$C$15+AE20*$C$20+AE25*$C$25+AE30*$C$30 -> 0.10038342 | AF10: =AF15*$C$15+AF20*$C$20+AF25*$C$25+AF30*$C$30 -> 0.11142559 | AH10: =AH15*$C$15+AH20*$C$20+AH25*$C$25+AH30*$C$30 -> 0.0088979281 | AI10: =AI15*$C$15+AI20*$C$20+AI25*$C$25+AI30*$C$30 -> 0.0096809458 | AJ10: =AJ15*$C$15+AJ20*$C$20+AJ25*$C$25+AJ30*$C$30 -> 0.01074585 | AL10: =AL15*$C$15+AL20*$C$20+AL25*$C$25+AL30*$C$30 -> 0.0048975406 | AM10: =AM15*$C$15+AM20*$C$20+AM25*$C$25+AM30*$C$30 -> 0.19144552 | AN10: =AN15*$C$15+AN20*$C$20+AN25*$C$25+AN30*$C$30 -> 0.19634306 | AO10: =AO15*$C$15+AO20*$C$20+AO25*$C$25+AO30*$C$30 -> 0.21362125 | AP10: =AP15*$C$15+AP20*$C$20+AP25*$C$25+AP30*$C$30 -> 0.23711959 | AR10: =AR15*$C$15+AR20*$C$20+AR25*$C$25+AR30*$C$30 -> 1.7616838e-12 | AS10: =AS15*$C$15+AS20*$C$20+AS25*$C$25+AS30*$C$30 -> 1.916712e-12 | AT10: =AT15*$C$15+AT20*$C$20+AT25*$C$25+AT30*$C$30 -> 2.1275504e-12 | AV10: =AV15*$C$15+AV20*$C$20+AV25*$C$25+AV30*$C$30 -> 0.0003772961 | AW10: =AW15*$C$15+AW20*$C$20+AW25*$C$25+AW30*$C$30 -> 0.00041049816 | AX10: =AX15*$C$15+AX20*$C$20+AX25*$C$25+AX30*$C$30 -> 0.00045565295 | AY10: =AY15*$C$15+AY20*$C$20+AY25*$C$25+AY30*$C$30 -> 0 | AZ10: =AZ15*$C$15+AZ20*$C$20+AZ25*$C$25+AZ30*$C$30 -> 0.0053058423 | BA10: =BA15*$C$15+BA20*$C$20+BA25*$C$25+BA30*$C$30 -> 0.0057727564 | BB10: =BB15*$C$15+BB20*$C$20+BB25*$C$25+BB30*$C$30 -> 0.0064077596 | BD10: =BD15*$C$15+BD20*$C$20+BD25*$C$25+BD30*$C$30 -> 0.31449133 | BE10: =BE15*$C$15+BE20*$C$20+BE25*$C$25+BE30*$C$30 -> 0.34908538 | BZ10: Nitrous oxide | CA10: =INDEX('Common input data'!A5:F15,MATCH(G1,'Common input data'!A5:A15,0),5) -> 233
