Workbook
Name Ability_to_perceive_handling: #REF!
Name BGBE: #REF!
Name Boars_per_sow: #REF!
Name Bonefree_outof_CW_AT: #REF!
Name Bonefree_outof_CW_BE: #REF!
Name Bonefree_outof_CW_BG: #REF!
Name Bonefree_outof_CW_BR: #REF!
Name Bonefree_outof_CW_CY: #REF!
Name Bonefree_outof_CW_CZ: #REF!
Name Bonefree_outof_CW_DE: #REF!
Name Bonefree_outof_CW_DK: #REF!
Name Bonefree_outof_CW_EE: #REF!
Name Bonefree_outof_CW_ES: #REF!
Name Bonefree_outof_CW_FI: #REF!
Name Bonefree_outof_CW_FR: #REF!
Name Bonefree_outof_CW_GB: #REF!
Name Bonefree_outof_CW_GR: #REF!
Name Bonefree_outof_CW_HR: #REF!
Name Bonefree_outof_CW_HU: #REF!
Name Bonefree_outof_CW_IE: #REF!
Name Bonefree_outof_CW_IT: #REF!
Name Bonefree_outof_CW_LT: #REF!
Name Bonefree_outof_CW_LV: #REF!
Name Bonefree_outof_CW_MT: #REF!
Name Bonefree_outof_CW_NL: #REF!
Name Bonefree_outof_CW_PL: #REF!
Name Bonefree_outof_CW_PT: #REF!
Name Bonefree_outof_CW_RO: #REF!
Name Bonefree_outof_CW_SE: #REF!
Name Bonefree_outof_CW_SI: #REF!
Name Bonefree_outof_CW_SK: #REF!
Name Bonefree_outof_CW_TH: #REF!
Name Bonefree_outof_CW_US: #REF!
Name CF_GWP_CH4_fossil: #REF!
Name CF_GWP_N2O: #REF!
Name CY: #REF!
Name EF_ammonia_AT: #REF!
Name EF_ammonia_BE: #REF!
Name EF_ammonia_BG: #REF!
Name EF_ammonia_BR: #REF!
Name EF_ammonia_CY: #REF!
Name EF_ammonia_CZ: #REF!
Name EF_ammonia_DE: #REF!
Name EF_ammonia_DK: #REF!
Name EF_ammonia_EE: #REF!
Name EF_ammonia_ES: #REF!
Name EF_ammonia_FI: #REF!
Name EF_ammonia_FR: #REF!
Name EF_ammonia_GB: #REF!
Name EF_ammonia_GR: #REF!
Name EF_ammonia_HR: #REF!
Name EF_ammonia_HU: #REF!
Name EF_ammonia_IE: #REF!
Name EF_ammonia_IT: #REF!
Name EF_ammonia_LT: #REF!
Name EF_ammonia_LV: #REF!
Name EF_ammonia_MT: #REF!
Name EF_ammonia_NL: #REF!
Name EF_ammonia_PL: #REF!
Name EF_ammonia_PT: #REF!

Sheet README
A2: Read me
A4: File with shares of beef production from different systems.

Sheet Summary
A1: Country | B1: Country code | C1: Shares_dairy_cows | D1: Shares_suckler | E1: Shares_dairy24m | F1: Shares_dairy9m
A2: Denmark | B2: DK | C2: =Calculation!B49 -> 0.3941456 | D2: =Calculation!B48 -> 0.18670186 | E2: =Calculation!B47 -> 0.14501559 | F2: =Calculation!B46 -> 0.27413694
A3: France | B3: FR | C3: =Calculation!C49 -> 0.229849 | D3: =Calculation!C48 -> 0.43333431 | E3: =Calculation!C47 -> 0.20717345 | F3: =Calculation!C46 -> 0.12964324
A4: Germany | B4: DE | C4: =Calculation!D49 -> 0.2834736 | D4: =Calculation!D48 -> 0.19493953 | E4: =Calculation!D47 -> 0.47350634 | F4: =Calculation!D46 -> 0.048080526
A5: Greece | B5: GR | C5: =Calculation!E49 -> 0.072833518 | D5: =Calculation!E48 -> 0.48162402 | E5: =Calculation!E47 -> 0.19832567 | F5: =Calculation!E46 -> 0.2472168
A6: Hungary | B6: HU | C6: =Calculation!F49 -> 0.47440155 | D6: =Calculation!F48 -> 0.29895085 | E6: =Calculation!F47 -> 0.19118686 | F6: =Calculation!F46 -> 0.03546075
A7: Ireland | B7: IE | C7: =Calculation!G49 -> 0.1519576 | D7: =Calculation!G48 -> 0.43328958 | E7: =Calculation!G47 -> 0.40966963 | F7: =Calculation!G46 -> 0.0050831841
A8: Italy | B8: IT | C8: =Calculation!H49 -> 0.18724869 | D8: =Calculation!H48 -> 0.2051133 | E8: =Calculation!H47 -> 0.49241254 | F8: =Calculation!H46 -> 0.11522547
A9: Netherlands | B9: NL | C9: =Calculation!I49 -> 0.31416076 | D9: =Calculation!I48 -> 0.033126357 | E9: =Calculation!I47 -> 0.055646927 | F9: =Calculation!I46 -> 0.59706596
A10: Poland | B10: PL | C10: =Calculation!J49 -> 0.2760377 | D10: =Calculation!J48 -> 0.078099951 | E10: =Calculation!J47 -> 0.64138202 | F10: =Calculation!J46 -> 0.0044803313
A11: Spain | B11: ES | C11: =Calculation!K49 -> 0.060572338 | D11: =Calculation!K48 -> 0.49388292 | E11: =Calculation!K47 -> 0.15267885 | F11: =Calculation!K46 -> 0.29286589
A12: Sweden | B12: SE | C12: =Calculation!L49 -> 0.20854154 | D12: =Calculation!L48 -> 0.46763506 | E12: =Calculation!L47 -> 0.30965431 | F12: =Calculation!L46 -> 0.014169089
A13: UK | B13: GB | C13: =Calculation!M49 -> 0.13655606 | D13: =Calculation!M48 -> 0.50615022 | E13: =Calculation!M47 -> 0.34851964 | F13: =Calculation!M46 -> 0.0087740817
C15: =AVERAGE(C2:C13) -> 0.2324815 | D15: =AVERAGE(D2:D13) -> 0.31773733 | E15: =AVERAGE(E2:E13) -> 0.30209765 | F15: =AVERAGE(F2:F13) -> 0.14768352

Sheet Calculation
A2: Amount of beef produced in different systems
B4: Denmark | C4: France | D4: Germany | E4: Greece | F4: Hungary | G4: Ireland | H4: Italy | I4: Netherlands | J4: Poland | K4: Spain | L4: Sweden | M4: UK
A5: Recruitment rates
A6: Dairy cows | B6: 0.27 | C6: 0.31 | D6: 0.235 | E6: 0.1 | F6: 0.14 | G6: 0.2 | H6: 0.24 | I6: 0.27 | J6: 0.234 | K6: 0.175 | L6: 0.3 | M6: 0.214 | N6: justera dessa så mängden kött från kor stämmer (gröna celler nedan)
A7: Suckler cows | B7: 0.2 | C7: 0.19 | D7: 0.16 | E7: 0.08 | F7: 0.1 | G7: 0.1 | H7: 0.18 | I7: 0.2 | J7: 0.1 | K7: 0.1 | L7: 0.18 | M7: 0.15 | P7: Ahlgren et al 2022, Tabell U i bilaga
A8: Slaughtering weight
A9: Dairy cows | B9: 340 | C9: 340 | D9: 340 | E9: 340 | F9: 340 | G9: 340 | H9: 340 | I9: 340 | J9: 340 | K9: 340 | L9: 340 | M9: 340
A10: Suckler cows | B10: 375 | C10: 375 | D10: 375 | E10: 375 | F10: 375 | G10: 375 | H10: 375 | I10: 375 | J10: 375 | K10: 375 | L10: 375 | M10: 375 | P10: Ahlgren et al 2022, Tabell 10
A11: Young suckler animals | B11: 320 | C11: 320 | D11: 320 | E11: 320 | F11: 320 | G11: 320 | H11: 320 | I11: 320 | J11: 320 | K11: 320 | L11: 320 | M11: 320 | P11: Ahlgren et al 2022, Tabell 11
A12: Mortality
A13: Dairy cows | B13: 0.08 | C13: 0.08 | D13: 0.08 | E13: 0.08 | F13: 0.08 | G13: 0.08 | H13: 0.08 | I13: 0.08 | J13: 0.08 | K13: 0.08 | L13: 0.08 | M13: 0.08
A14: Suckler cows | B14: 0.04 | C14: 0.04 | D14: 0.04 | E14: 0.04 | F14: 0.04 | G14: 0.04 | H14: 0.04 | I14: 0.04 | J14: 0.04 | K14: 0.04 | L14: 0.04 | M14: 0.04
A15: Young suckler animals | B15: 0.04 | C15: 0.04 | D15: 0.04 | E15: 0.04 | F15: 0.04 | G15: 0.04 | H15: 0.04 | I15: 0.04 | J15: 0.04 | K15: 0.04 | L15: 0.04 | M15: 0.04
A16: Number of animals, thousands, from Eurostat
A17: Dairy cows | B17: 556 | C17: 3230 | D17: 3809 | E17: 81 | F17: 278 | G17: 1510 | H17: 1864 | I17: 1570 | J17: 2037 | K17: 810 | L17: 298 | M17: 1867 | P17: apro_mt_lscatl. 2022 (2019 for UK)
A18: Non dairy cows | B18: 70 | C18: 3790 | D18: 610 | E18: 147 | F18: 143 | G18: 862 | H18: 484 | I18: 44 | J18: 135 | K18: 2078 | L18: 198 | M18: 1470 | P18: apro_mt_lscatl. 2022 (2019 for UK)
A19: Meat produced, thousand tons, from Eurostat
A20: Bovine meat, total | B20: 119 | C20: 1361.31 | D20: 987.47 | E20: 35.53 | F20: 25.68 | G20: 621 | H20: 747.21 | I20: 422 | J20: 540.59 | K20: 731.53 | L20: 135 | M20: 914.39 | P20: apro_mt_pann. 2022 (2019 for UK)
A21: - Calf | B21: 0.14 | C21: 160.13 | D21: 44.7 | E21: 1.26 | F21: 0.23 | G21: 2.5 | H21: 78.8 | I21: 220 | J21: 1.73 | K21: 11.57 | L21: 0.4 | M21: 4.13
A22: - Young cattle | B22: 32.52 | C22: 16.53 | D22: 2.79 | E22: 7.34 | F22: 0.68 | G22: 0.66 | H22: 7.31 | I22: 32 | J22: 0.69 | K22: 202.81 | L22: 1.5 | M22: 3.9
A23: - Adult cattle | B23: 86.34 | C23: 1184.64 | D23: 939.99 | E23: 26.17 | F23: 24.77 | G23: 618 | H23: 661.1 | I23: 170 | J23: 538.17 | K23: 517.14 | L23: 133 | M23: 906.36
A24: -- Cow | B24: 51.86 | C24: 571.08 | D24: 314.89 | E24: 7.26 | F24: 17.13 | G24: 125 | H24: 171.19 | I24: 136 | J24: 154.41 | K24: 118.67 | L24: 42 | M24: 203.56
A25: -- Heifer | B25: 16.05 | C25: 218.06 | D25: 163.2 | E25: 6.6 | F25: 2.66 | G25: 181 | H25: 190.61 | I25: 3.3 | J25: 85.89 | K25: 123.45 | L25: 20.4 | M25: 257.58
A26: -- Bull | B26: 16.17 | C26: 343.42 | D26: 451.23 | E26: 12.34 | F26: 4.77 | G26: 62 | H26: 298.14 | I26: 31 | J26: 297.87 | K26: 272.25 | L26: 60 | M26: 74.34
A27: -- Bullock (stut) | B27: 2.26 | C27: 52.08 | D27: 10.67 | E27: 0.48 | F27: 0 | G27: 250 | H27: 1.16 | I27: 0 | J27: 0 | K27: 2.78 | L27: 11 | M27: 370.89
A28: Meat produced, thousand tons, calculated
A29: From dairy cows | B29: =B6*B9*B17*(1-B13)/1000 -> 46.957536 | C29: =C6*C9*C17*(1-C13)/1000 -> 313.20664 | D29: =D6*D9*D17*(1-D13)/1000 -> 279.99197 | E29: =E6*E9*E17*(1-E13)/1000 -> 2.53368 | F29: =F6*F9*F17*(1-F13)/1000 -> 12.174176 | G29: =G6*G9*G17*(1-G13)/1000 -> 94.4656 | H29: =H6*H9*H17*(1-H13)/1000 -> 139.93421 | I29: =I6*I9*I17*(1-I13)/1000 -> 132.59592 | ... M29: =M6*M9*M17*(1-M13)/1000 -> 124.97549 | N29: No of dairy cows * recruit rate * slaughtering weight * (1-mortality)
A30: From suckler cows | B30: =B7*B10*B18*(1-B14)/1000 -> 5.04 | C30: =C7*C10*C18*(1-C14)/1000 -> 259.236 | D30: =D7*D10*D18*(1-D14)/1000 -> 35.136 | E30: =E7*E10*E18*(1-E14)/1000 -> 4.2336 | F30: =F7*F10*F18*(1-F14)/1000 -> 5.148 | G30: =G7*G10*G18*(1-G14)/1000 -> 31.032 | H30: =H7*H10*H18*(1-H14)/1000 -> 31.3632 | I30: =I7*I10*I18*(1-I14)/1000 -> 3.168 | ... M30: =M7*M10*M18*(1-M14)/1000 -> 79.38 | N30: No of suckler cows * recruit rate * slaughtering weight * (1-mortality)
A31: Total from cows | B31: =SUM(B29:B30) -> 51.997536 | C31: =SUM(C29:C30) -> 572.44264 | D31: =SUM(D29:D30) -> 315.12797 | E31: =SUM(E29:E30) -> 6.76728 | F31: =SUM(F29:F30) -> 17.322176 | G31: =SUM(G29:G30) -> 125.4976 | H31: =SUM(H29:H30) -> 171.29741 | I31: =SUM(I29:I30) -> 135.76392 | ... M31: =SUM(M29:M30) -> 204.35549 | N31: Sum of the two above
A32: From young animals suckler herds | B32: =B18*B11*(1-B7)*(1-B15)/1000 -> 17.2032 | C32: =SUM(C25:C27)*(C18/SUM(C17:C18)) -> 331.25248 | D32: =D18*D11*(1-D7)*(1-D15)/1000 -> 157.40928 | E32: =SUM(E25:E27)*(E18/SUM(E17:E18)) -> 12.520789 | F32: =SUM(F25:F27)*(F18/SUM(F17:F18)) -> 2.5237292 | G32: =G18*G11*(1-G7)*(1-G15)/1000 -> 238.32576 | H32: =H18*H11*(1-H7)*(1-H15)/1000 -> 121.92154 | I32: =I18*I11*(1-I7)*(1-I15)/1000 -> 10.81344 | J32: =J18*J11*(1-J7)*(1-J15)/1000 -> 37.3248 | K32: =SUM(K25:K27)*(K18/SUM(K17:K18)) -> 286.71795 | L32: =L18*L11*(1-L7)*(1-L15)/1000 -> 49.876992 | M32: =M18*M11*(1-M7)*(1-M15)/1000 -> 383.8464 | N32: Assuming every suckler cow has one calf per year - mortality -those that go into recruitment
A33: From dairy offspring | B33: =SUM(B25:B27)-B32 -> 17.2768 | C33: =SUM(C25:C27)*(C17/SUM(C17:C18)) -> 282.30752 | D33: =SUM(D25:D27)-D32 -> 467.69072 | E33: =SUM(E25:E27)*(E17/SUM(E17:E18)) -> 6.8992105 | F33: =SUM(F25:F27)*(F17/SUM(F17:F18)) -> 4.9062708 | G33: =SUM(G25:G27)-G32 -> 254.67424 | H33: =SUM(H25:H27)-H32 -> 367.98846 | I33: =SUM(I25:I27)-I32 -> 23.48656 | J33: =SUM(J25:J27)-J32 -> 346.4352 | K33: =SUM(K25:K27)*(K17/SUM(K17:K18)) -> 111.76205 | L33: =SUM(L25:L27)-L32 -> 41.523008 | M33: =SUM(M25:M27)-M32 -> 318.9636 | N33: The rest of meat from offspring is from dairy offspring
A34: Meat produced, thousand tons, in the systems defined by us | N34: För Frankrike, Spanien, Grekland och Ungern funkar inte detta för den beräknade köttmängden blir
A35: Calves slaughtered app. 9 month | B35: =B21+B22 -> 32.66 | C35: =C21+C22 -> 176.66 | D35: =D21+D22 -> 47.49 | E35: =E21+E22 -> 8.6 | F35: =F21+F22 -> 0.91 | G35: =G21+G22 -> 3.16 | H35: =H21+H22 -> 86.11 | I35: =I21+I22 -> 252 | ... M35: =M21+M22 -> 8.03 | N35: mycket större än den verkliga, detta kan bero på handel med djur mellan länder eller att varje ko inte
A36: Meat from suckler herds (cows+offspring) | B36: =B30+B32 -> 22.2432 | C36: =C30+C32 -> 590.48848 | D36: =D30+D32 -> 192.54528 | E36: =E30+E32 -> 16.754389 | F36: =F30+F32 -> 7.6717292 | G36: =G30+G32 -> 269.35776 | H36: =H30+H32 -> 153.28474 | I36: =I30+I32 -> 13.98144 | ... M36: =M30+M32 -> 463.2264 | N36: får en kalv per år och/eller andra slaktvikter -> löser detta genom att dela det slaktade ungdjurköttet mellan
A37: Meat from dairy offspring | B37: =B33 -> 17.2768 | C37: =C33 -> 282.30752 | D37: =D33 -> 467.69072 | E37: =E33 -> 6.8992105 | F37: =F33 -> 4.9062708 | G37: =G33 -> 254.67424 | H37: =H33 -> 367.98846 | I37: =I33 -> 23.48656 | ... M37: =M33 -> 318.9636 | N37: mjölk och dikosystem baserat på antalet mjölkkor och dikor för dessa länder (gråmarkerade celler)
A38: (Dairy cows, for control) | B38: =B29 -> 46.957536 | C38: =C29 -> 313.20664 | D38: =D29 -> 279.99197 | E38: =E29 -> 2.53368 | F38: =F29 -> 12.174176 | G38: =G29 -> 94.4656 | H38: =H29 -> 139.93421 | I38: =I29 -> 132.59592 | ... M38: =M29 -> 124.97549
A39: Total | B39: =SUM(B35:B38) -> 119.13754 | C39: =SUM(C35:C38) -> 1362.6626 | D39: =SUM(D35:D38) -> 987.71797 | E39: =SUM(E35:E38) -> 34.78728 | F39: =SUM(F35:F38) -> 25.662176 | G39: =SUM(G35:G38) -> 621.6576 | H39: =SUM(H35:H38) -> 747.31741 | I39: =SUM(I35:I38) -> 422.06392 | ... M39: =SUM(M35:M38) -> 915.19549
A40: Total without dairy cows | B40: =SUM(B35:B37) -> 72.18 | C40: =SUM(C35:C37) -> 1049.456 | D40: =SUM(D35:D37) -> 707.726 | E40: =SUM(E35:E37) -> 32.2536 | F40: =SUM(F35:F37) -> 13.488 | G40: =SUM(G35:G37) -> 527.192 | H40: =SUM(H35:H37) -> 607.3832 | I40: =SUM(I35:I37) -> 289.468 | ... M40: =SUM(M35:M37) -> 790.22
A41: Shares (without dairy cows)
A42: Calves slaughtered app. 9 month | B42: =B35/B$40 -> 0.45247991 | C42: =C35/C$40 -> 0.16833483 | D42: =D35/D$40 -> 0.06710224 | E42: =E35/E$40 -> 0.2666369 | F42: =F35/F$40 -> 0.067467378 | G42: =G35/G$40 -> 0.0059940212 | H42: =H35/H$40 -> 0.14177211 | I42: =I35/I$40 -> 0.87056255 | ... M42: =M35/M$40 -> 0.010161727
...
