Workbook
Name Ability_to_perceive_handling: 'Parameters, general'!#REF!
Name AF_beef: 'Parameters, general'!#REF!
Name AF_calves: 'Parameters, general'!#REF!
Name AF_milk: 'Parameters, general'!#REF!
Name Boars_per_sow: 'Parameters, country spec'!#REF!
Name CF_GWP_CH4_biog: 'Parameters, general'!$B$25
Name CF_GWP_CH4_biogenic: 'Parameters, general'!$B$25
Name CF_GWP_CH4_fossil: 'Parameters, general'!$B$24
Name CF_GWP_N2O: 'Parameters, general'!$B$26
Name Crop_data: 'Forage crops, CF'!$A$6:$Z$80
Name Crop_data: 'Forage, input data per ha'!#REF!
Name Crop_data: 'Forage crops, footprints'!$A$6:$Z$22
Name Crop_data_codes: 'Forage crops, CF'!$A$71:$A$155
Name Crop_data_codes: 'Forage, input data per ha'!#REF!
Name Crop_data_codes: 'Forage crops, footprints'!$A$23:$A$39
Name EF_biofuel_CH4: 'Parameters, general'!$C$6
Name EF_biofuel_N2O: 'Parameters, general'!$D$6
Name EF_biofuels_CO2: 'Parameters, general'!$B$6
Name EF_capital_goods_CH4: 'Parameters, general'!$C$10
Name EF_capital_goods_CO2: 'Parameters, general'!$B$10
Name EF_capital_goods_N2O: 'Parameters, general'!$D$10
Name EF_diesel_CH4: 'Parameters, general'!$C$7
Name EF_diesel_CO2: 'Parameters, general'!$B$7
Name EF_diesel_N2O: 'Parameters, general'!$D$7
Name EF_el_CH4_DE: 'Parameters, country spec'!$D$68
Name EF_el_CH4_DK: 'Parameters, country spec'!$B$68
Name EF_el_CH4_ES: 'Parameters, country spec'!$K$68
Name EF_el_CH4_FR: 'Parameters, country spec'!$C$68
Name EF_el_CH4_GB: 'Parameters, country spec'!$M$68
Name EF_el_CH4_GR: 'Parameters, country spec'!$E$68
Name EF_el_CH4_HU: 'Parameters, country spec'!$F$68
Name EF_el_CH4_IE: 'Parameters, country spec'!$G$68
Name EF_el_CH4_IT: 'Parameters, country spec'!$H$68
Name EF_el_CH4_NL: 'Parameters, country spec'!$I$68
Name EF_el_CH4_PL: 'Parameters, country spec'!$J$68
Name EF_el_CH4_SE: 'Parameters, country spec'!$L$68
Name EF_el_CO2_DE: 'Parameters, country spec'!$D$67
Name EF_el_CO2_DK: 'Parameters, country spec'!$B$67
Name EF_el_CO2_ES: 'Parameters, country spec'!$K$67
Name EF_el_CO2_FR: 'Parameters, country spec'!$C$67
Name EF_el_CO2_GB: 'Parameters, country spec'!$M$67
Name EF_el_CO2_GR: 'Parameters, country spec'!$E$67
Name EF_el_CO2_HU: 'Parameters, country spec'!$F$67
Name EF_el_CO2_IE: 'Parameters, country spec'!$G$67
Name EF_el_CO2_IT: 'Parameters, country spec'!$H$67
Name EF_el_CO2_NL: 'Parameters, country spec'!$I$67
Name EF_el_CO2_PL: 'Parameters, country spec'!$J$67
Name EF_el_CO2_SE: 'Parameters, country spec'!$L$67
Name EF_el_N2O_DE: 'Parameters, country spec'!$D$69
Name EF_el_N2O_DK: 'Parameters, country spec'!$B$69
Name EF_el_N2O_ES: 'Parameters, country spec'!$K$69
Name EF_el_N2O_FR: 'Parameters, country spec'!$C$69
Name EF_el_N2O_GB: 'Parameters, country spec'!$M$69
Name EF_el_N2O_GR: 'Parameters, country spec'!$E$69
Name EF_el_N2O_HU: 'Parameters, country spec'!$F$69
Name EF_el_N2O_IE: 'Parameters, country spec'!$G$69
Name EF_el_N2O_IT: 'Parameters, country spec'!$H$69
Name EF_el_N2O_NL: 'Parameters, country spec'!$I$69
Name EF_el_N2O_PL: 'Parameters, country spec'!$J$69
Name EF_el_N2O_SE: 'Parameters, country spec'!$L$69

Sheet README
A2: Read me
A4: This is a file that contains the calculations of the footprints for beef from dairy calves slaughtered at 24 months.
A6: Impacts from the dairy production allocated to the calves are copied from Dairy.xlsx into the tab Footprints, mother animals | H6: Needs updating + title that should be per calf, not per kg
A17: Color codes:
B19: Results
B20: Sheets for input
B21: Intermediate calculations

Sheet Figures
A2: Figures
A4: Greenhouse gas emission for bonefree meat across countries, to farmgate, no waste
B6: Production of mineral fertilizer | C6: Production of capital goods | D6: Emissions from soil | E6: Energy use cropping | F6: Energy use for feed processing | G6: Land use change emissions | H6: Feed transports | I6: Enteric fermentation | J6: Manure management | K6: Energy use in stables | L6: Energy use for slaughter | M6: Tot
A7: Poland | B7: ='GHG detailed, results per kg'!H51 -> 3.0702722 | C7: ='GHG detailed, results per kg'!I51 -> 0.66879436 | D7: ='GHG detailed, results per kg'!J51+'GHG detailed, results per kg'!K51 -> 2.6183902 | E7: ='GHG detailed, results per kg'!L51+'GHG detailed, results per kg'!N51 -> 1.3921405 | F7: ='GHG detailed, results per kg'!O51+'GHG detailed, results per kg'!Q51 -> 1.0772879 | G7: ='GHG detailed, results per kg'!P51 -> 0.089109135 | H7: ='GHG detailed, results per kg'!R51 -> 0.12098641 | I7: ='GHG detailed, results per kg'!S51 -> 15.219337 | J7: ='GHG detailed, results per kg'!T51 -> 3.1045855 | K7: ='GHG detailed, results per kg'!W51 -> 1.7536487 | L7: ='GHG detailed, results per kg'!X51 -> 0.062562003 | M7: =SUM(B7:L7) -> 29.177114
A8: Hungary | B8: ='GHG detailed, results per kg'!H31 -> 1.3940171 | C8: ='GHG detailed, results per kg'!I31 -> 0.61010045 | D8: ='GHG detailed, results per kg'!J31+'GHG detailed, results per kg'!K31 -> 2.3067771 | E8: ='GHG detailed, results per kg'!L31+'GHG detailed, results per kg'!N31 -> 0.67851681 | F8: ='GHG detailed, results per kg'!O31+'GHG detailed, results per kg'!Q31 -> 2.4212841 | G8: ='GHG detailed, results per kg'!P31 -> 0.68504229 | H8: ='GHG detailed, results per kg'!R31 -> 0.60689028 | I8: ='GHG detailed, results per kg'!S31 -> 15.223283 | J8: ='GHG detailed, results per kg'!T31 -> 4.9976498 | K8: ='GHG detailed, results per kg'!W31 -> 1.0024766 | L8: ='GHG detailed, results per kg'!X31 -> 0.035059919 | M8: =SUM(B8:L8) -> 29.961097
A9: Italy | B9: ='GHG detailed, results per kg'!H41 -> 0.963341 | C9: ='GHG detailed, results per kg'!I41 -> 0.54631929 | D9: ='GHG detailed, results per kg'!J41+'GHG detailed, results per kg'!K41 -> 2.0040181 | E9: ='GHG detailed, results per kg'!L41+'GHG detailed, results per kg'!N41 -> 0.37373906 | F9: ='GHG detailed, results per kg'!O41+'GHG detailed, results per kg'!Q41 -> 1.4978103 | G9: ='GHG detailed, results per kg'!P41 -> 0.35073115 | H9: ='GHG detailed, results per kg'!R41 -> 0.37411654 | I9: ='GHG detailed, results per kg'!S41 -> 15.100676 | J9: ='GHG detailed, results per kg'!T41 -> 6.079777 | K9: ='GHG detailed, results per kg'!W41 -> 0.94528394 | L9: ='GHG detailed, results per kg'!X41 -> 0.032965968 | M9: =SUM(B9:L9) -> 28.268778
A10: Greece | B10: ='GHG detailed, results per kg'!H26 -> 1.9855106 | C10: ='GHG detailed, results per kg'!I26 -> 0.64087403 | D10: ='GHG detailed, results per kg'!J26+'GHG detailed, results per kg'!K26 -> 2.816655 | E10: ='GHG detailed, results per kg'!L26+'GHG detailed, results per kg'!N26 -> 0.94236473 | F10: ='GHG detailed, results per kg'!O26+'GHG detailed, results per kg'!Q26 -> 1.6243734 | G10: ='GHG detailed, results per kg'!P26 -> 0.46222465 | H10: ='GHG detailed, results per kg'!R26 -> 0.46570444 | I10: ='GHG detailed, results per kg'!S26 -> 15.137826 | J10: ='GHG detailed, results per kg'!T26 -> 3.2451259 | K10: ='GHG detailed, results per kg'!W26 -> 1.2826221 | L10: ='GHG detailed, results per kg'!X26 -> 0.04531667 | M10: =SUM(B10:L10) -> 28.648598
A11: Netherlands | B11: ='GHG detailed, results per kg'!H46 -> 2.8433188 | C11: ='GHG detailed, results per kg'!I46 -> 0.62458307 | D11: ='GHG detailed, results per kg'!J46+'GHG detailed, results per kg'!K46 -> 4.4873289 | E11: ='GHG detailed, results per kg'!L46+'GHG detailed, results per kg'!N46 -> 0.50834828 | F11: ='GHG detailed, results per kg'!O46+'GHG detailed, results per kg'!Q46 -> 1.3380371 | G11: ='GHG detailed, results per kg'!P46 -> 0.51982796 | H11: ='GHG detailed, results per kg'!R46 -> 0.46146342 | I11: ='GHG detailed, results per kg'!S46 -> 15.166478 | J11: ='GHG detailed, results per kg'!T46 -> 0.8746581 | K11: ='GHG detailed, results per kg'!W46 -> 1.0790039 | L11: ='GHG detailed, results per kg'!X46 -> 0.037861753 | M11: =SUM(B11:L11) -> 27.940909
A12: Denmark | B12: ='GHG detailed, results per kg'!H11 -> 0.50401149 | C12: ='GHG detailed, results per kg'!I11 -> 0.65831406 | D12: ='GHG detailed, results per kg'!J11+'GHG detailed, results per kg'!K11 -> 1.7142332 | E12: ='GHG detailed, results per kg'!L11+'GHG detailed, results per kg'!N11 -> 0.35724031 | F12: ='GHG detailed, results per kg'!O11+'GHG detailed, results per kg'!Q11 -> 2.0407575 | G12: ='GHG detailed, results per kg'!P11 -> 0.39669488 | H12: ='GHG detailed, results per kg'!R11 -> 0.54543796 | I12: ='GHG detailed, results per kg'!S11 -> 15.259257 | J12: ='GHG detailed, results per kg'!T11 -> 4.5107129 | K12: ='GHG detailed, results per kg'!W11 -> 0.89120028 | L12: ='GHG detailed, results per kg'!X11 -> 0.030985844 | M12: =SUM(B12:L12) -> 26.908845
A13: Sweden | B13: ='GHG detailed, results per kg'!H61 -> 1.3664806 | C13: ='GHG detailed, results per kg'!I61 -> 0.68612308 | D13: ='GHG detailed, results per kg'!J61+'GHG detailed, results per kg'!K61 -> 3.3922754 | E13: ='GHG detailed, results per kg'!L61+'GHG detailed, results per kg'!N61 -> 0.51912628 | F13: ='GHG detailed, results per kg'!O61+'GHG detailed, results per kg'!Q61 -> 1.6233062 | G13: ='GHG detailed, results per kg'!P61 -> 0.079871101 | H13: ='GHG detailed, results per kg'!R61 -> 0.28072828 | I13: ='GHG detailed, results per kg'!S61 -> 15.214983 | J13: ='GHG detailed, results per kg'!T61 -> 2.1695283 | K13: ='GHG detailed, results per kg'!W61 -> 0.44290797 | L13: ='GHG detailed, results per kg'!X61 -> 0.0016272133 | M13: =SUM(B13:L13) -> 25.776957
A14: Germany | B14: ='GHG detailed, results per kg'!H21 -> 0.78995281 | C14: ='GHG detailed, results per kg'!I21 -> 0.60441002 | D14: ='GHG detailed, results per kg'!J21+'GHG detailed, results per kg'!K21 -> 1.8927154 | E14: ='GHG detailed, results per kg'!L21+'GHG detailed, results per kg'!N21 -> 0.35593281 | F14: ='GHG detailed, results per kg'!O21+'GHG detailed, results per kg'!Q21 -> 1.7043705 | G14: ='GHG detailed, results per kg'!P21 -> 0.23591073 | H14: ='GHG detailed, results per kg'!R21 -> 0.30988502 | I14: ='GHG detailed, results per kg'!S21 -> 15.063616 | J14: ='GHG detailed, results per kg'!T21 -> 3.7995222 | K14: ='GHG detailed, results per kg'!W21 -> 1.0310344 | L14: ='GHG detailed, results per kg'!X21 -> 0.036105482 | M14: =SUM(B14:L14) -> 25.823455
A15: France | B15: ='GHG detailed, results per kg'!H16 -> 1.0745563 | C15: ='GHG detailed, results per kg'!I16 -> 0.61237884 | D15: ='GHG detailed, results per kg'!J16+'GHG detailed, results per kg'!K16 -> 2.6696469 | E15: ='GHG detailed, results per kg'!L16+'GHG detailed, results per kg'!N16 -> 0.45049177 | F15: ='GHG detailed, results per kg'!O16+'GHG detailed, results per kg'!Q16 -> 1.428531 | G15: ='GHG detailed, results per kg'!P16 -> 0.25048528 | H15: ='GHG detailed, results per kg'!R16 -> 0.35746652 | I15: ='GHG detailed, results per kg'!S16 -> 15.177842 | J15: ='GHG detailed, results per kg'!T16 -> 2.9070556 | K15: ='GHG detailed, results per kg'!W16 -> 0.44590589 | L15: ='GHG detailed, results per kg'!X16 -> 0.0016456263 | M15: =SUM(B15:L15) -> 25.376006
A16: Spain | B16: ='GHG detailed, results per kg'!H56 -> 0.56980648 | C16: ='GHG detailed, results per kg'!I56 -> 0.6206311 | D16: ='GHG detailed, results per kg'!J56+'GHG detailed, results per kg'!K56 -> 2.5611694 | E16: ='GHG detailed, results per kg'!L56+'GHG detailed, results per kg'!N56 -> 0.83056979 | F16: ='GHG detailed, results per kg'!O56+'GHG detailed, results per kg'!Q56 -> 1.1322993 | G16: ='GHG detailed, results per kg'!P56 -> 0.55896494 | H16: ='GHG detailed, results per kg'!R56 -> 0.58254605 | I16: ='GHG detailed, results per kg'!S56 -> 15.057932 | J16: ='GHG detailed, results per kg'!T56 -> 2.0788073 | K16: ='GHG detailed, results per kg'!W56 -> 0.76444523 | L16: ='GHG detailed, results per kg'!X56 -> 0.02634506 | M16: =SUM(B16:L16) -> 24.783517
A17: Ireland | B17: ='GHG detailed, results per kg'!H36 -> 1.1484849 | C17: ='GHG detailed, results per kg'!I36 -> 0.62858168 | D17: ='GHG detailed, results per kg'!J36+'GHG detailed, results per kg'!K36 -> 1.7407168 | E17: ='GHG detailed, results per kg'!L36+'GHG detailed, results per kg'!N36 -> 0.36519092 | F17: ='GHG detailed, results per kg'!O36+'GHG detailed, results per kg'!Q36 -> 0.36866263 | G17: ='GHG detailed, results per kg'!P36 -> 0.066050789 | H17: ='GHG detailed, results per kg'!R36 -> 0.065395076 | I17: ='GHG detailed, results per kg'!S36 -> 15.130733 | J17: ='GHG detailed, results per kg'!T36 -> 3.6465072 | K17: ='GHG detailed, results per kg'!W36 -> 0.91448327 | L17: ='GHG detailed, results per kg'!X36 -> 0.031838287 | M17: =SUM(B17:L17) -> 24.106645
A22: Comparison Ahlgren et al 2022
A24: Klimat | D24: Metan | E24: Gödsel | F24: Lustgas, mark | G24: Energi | H24: Övrigt | I24: Summa
A25: Köttrasstut | B25: Gns | C25: CW | D25: 5.9394412 | E25: 2.8821149 | F25: 1.8985379 | G25: 1.8519477 | H25: 0.56060773 | I25: 13.132649
C26: Benfritt | D26: =D25/0.69 -> 8.6078858 | E26: =E25/0.69 -> 4.1769781 | F26: =F25/0.69 -> 2.7515042 | G26: =G25/0.69 -> 2.6839822 | H26: =H25/0.69 -> 0.81247498 | I26: =I25/0.69 -> 19.032825
A27: Our data | D27: =I17 -> 15.130733 | E27: =J17 -> 3.6465072 | F27: =D17 -> 1.7407168 | G27: =B17+E17+F17+K17 -> 2.7968217 | H27: =C17+H17+L17 -> 0.72581504 | I27: =SUM(D27:H27) -> 24.040594
A29: Ammoniak
A30: Köttrasstut | B30: Gns | C30: =0.2/0.695 -> 0.28776978
A31: Our data | C31: ='Footprints, only calves'!R17 -> 0.13602367 | D31: Lower value explained by us using TAN for manure calculations
A33: Cropland
A34: Köttrasstut | B34: Gns | C34: 30
A35: Our data | C35: ='Footprints, only calves'!L17 -> 25.618253

Sheet Footprints, results per kg
A2: Footprints (per kg of meat) - calves + mother animal | T2: **Values inserted directly here, no formula in this excel sheet
A5: Animal products | F5: Climate | L5: Land | M5: Nitrogen | N5: Phosphorus | O5: Water | P5: Pesticides | Q5: Biodiversity | R5: Ammonia | S5: Labour | T5: Animal welfare** | U5: Use of antibiotics**
A6: Code | B6: Name | C6: Category | D6: Country | E6: Country code | F6: Carbon footprint, kg CO2e/kg | G6: Carbon dioxide, kg CO2/kg | H6: Methane, fossil, kg CH4/kg | I6: Methane, biogenic, kg CH4/kg | J6: Nitrous oxide, kg N2O/kg | K6: HFCs, kg HFCs/kg | L6: Cropland use, m2/kg | M6: New N input, kg N/kg | N6: New P input, kg P/kg | O6: Blue freshwater use, m3/kg | P6: Pesticide use, g a.i./kg | Q6: Extinction rate, E/MSY/kg | R6: Ammonia emission, kg NH3/kg | S6: Labour requirements, h/kg | T6: Animal welfare index per kg of bonefree meat | U6: Antibiotics use indicator/kg
A7: 21111.02_dc24 | B7: Bovine meat | C7: Red meat | D7: Denmark | E7: DK | F7: ='GHG detailed, results per kg'!G11 -> 26.908845 | G7: ='GHG detailed, results per kg'!G7 -> 4.1584806 | H7: ='GHG detailed, results per kg'!G8 -> 0.020876964 | I7: ='GHG detailed, results per kg'!G9 -> 0.67527936 | J7: ='GHG detailed, results per kg'!G10 -> 0.014269919 | L7: ='Footprints, only calves'!L7+Production!$B$7*'Footprints, mother animal'!L7/Production!$B$23 -> 22.105225 | M7: ='Footprints, only calves'!M7+Production!$B$7*'Footprints, mother animal'!M7/Production!$B$23 -> 0.25601315 | N7: ='Footprints, only calves'!N7+Production!$B$7*'Footprints, mother animal'!N7/Production!$B$23 -> 0.011609952 | O7: ='Footprints, only calves'!O7+Production!$B$7*'Footprints, mother animal'!O7/Production!$B$23 -> 0.2135412 | P7: ='Footprints, only calves'!P7+Production!$B$7*'Footprints, mother animal'!P7/Production!$B$23 -> 0.69193227 | Q7: ='Footprints, only calves'!Q7+Production!$B$7*'Footprints, mother animal'!Q7/Production!$B$23 -> 6.177992e-10 | R7: ='Footprints, only calves'!R7+Production!$B$7*'Footprints, mother animal'!R7/Production!$B$23 -> 0.15869624 | S7: ='Footprints, only calves'!S7+Production!$B$7*'Footprints, mother animal'!S7/Production!$B$23 -> 0 | T7: 0.32534992 | U7: 5.9802073
A8: 21111.02_dc24 | B8: Bovine meat | C8: Red meat | D8: France | E8: FR | F8: ='GHG detailed, results per kg'!G16 -> 25.376006 | G8: ='GHG detailed, results per kg'!G12 -> 3.4797961 | H8: ='GHG detailed, results per kg'!G13 -> 0.015134033 | I8: ='GHG detailed, results per kg'!G14 -> 0.60767863 | J8: ='GHG detailed, results per kg'!G15 -> 0.018453819 | L8: ='Footprints, only calves'!L8+Production!$C$7*'Footprints, mother animal'!L8/Production!$C$23 -> 20.544328 | M8: ='Footprints, only calves'!M8+Production!$C$7*'Footprints, mother animal'!M8/Production!$C$23 -> 0.30263548 | N8: ='Footprints, only calves'!N8+Production!$C$7*'Footprints, mother animal'!N8/Production!$C$23 -> 0.024382234 | O8: ='Footprints, only calves'!O8+Production!$C$7*'Footprints, mother animal'!O8/Production!$C$23 -> 0.7025304 | P8: ='Footprints, only calves'!P8+Production!$C$7*'Footprints, mother animal'!P8/Production!$C$23 -> 1.3280314 | Q8: ='Footprints, only calves'!Q8+Production!$C$7*'Footprints, mother animal'!Q8/Production!$C$23 -> 1.8609392e-09 | R8: ='Footprints, only calves'!R8+Production!$C$7*'Footprints, mother animal'!R8/Production!$C$23 -> 0.15660255 | S8: ='Footprints, only calves'!S8+Production!$C$7*'Footprints, mother animal'!S8/Production!$C$23 -> 0 | T8: 0.39946722 | U8: 8.7454742
A9: 21111.02_dc24 | B9: Bovine meat | C9: Red meat | D9: Germany | E9: DE | F9: ='GHG detailed, results per kg'!G21 -> 25.823455 | G9: ='GHG detailed, results per kg'!G17 -> 4.0175058 | H9: ='GHG detailed, results per kg'!G18 -> 0.015682521 | I9: ='GHG detailed, results per kg'!G19 -> 0.63692123 | J9: ='GHG detailed, results per kg'!G20 -> 0.015171199 | L9: ='Footprints, only calves'!L9+Production!$D$7*'Footprints, mother animal'!L9/Production!$D$23 -> 14.181147 | M9: ='Footprints, only calves'!M9+Production!$D$7*'Footprints, mother animal'!M9/Production!$D$23 -> 0.23634698 | N9: ='Footprints, only calves'!N9+Production!$D$7*'Footprints, mother animal'!N9/Production!$D$23 -> 0.011812314 | O9: ='Footprints, only calves'!O9+Production!$D$7*'Footprints, mother animal'!O9/Production!$D$23 -> 0.19062819 | P9: ='Footprints, only calves'!P9+Production!$D$7*'Footprints, mother animal'!P9/Production!$D$23 -> 0.76934035 | Q9: ='Footprints, only calves'!Q9+Production!$D$7*'Footprints, mother animal'!Q9/Production!$D$23 -> 4.8386013e-10 | R9: ='Footprints, only calves'!R9+Production!$D$7*'Footprints, mother animal'!R9/Production!$D$23 -> 0.17632361 | S9: ='Footprints, only calves'!S9+Production!$D$7*'Footprints, mother animal'!S9/Production!$D$23 -> 0 | T9: 0.45796537 | U9: 14.65228
A10: 21111.02_dc24 | B10: Bovine meat | C10: Red meat | D10: Greece | E10: GR | F10: ='GHG detailed, results per kg'!G26 -> 28.648598 | G10: ='GHG detailed, results per kg'!G22 -> 6.179929 | H10: ='GHG detailed, results per kg'!G23 -> 0.013306376 | I10: ='GHG detailed, results per kg'!G24 -> 0.60210886 | J10: ='GHG detailed, results per kg'!G25 -> 0.021301096 | L10: ='Footprints, only calves'!L10+Production!$E$7*'Footprints, mother animal'!L10/Production!$E$23 -> 32.559498 | M10: ='Footprints, only calves'!M10+Production!$E$7*'Footprints, mother animal'!M10/Production!$E$23 -> 0.47768109 | N10: ='Footprints, only calves'!N10+Production!$E$7*'Footprints, mother animal'!N10/Production!$E$23 -> 0.054031175 | O10: ='Footprints, only calves'!O10+Production!$E$7*'Footprints, mother animal'!O10/Production!$E$23 -> 1.9214941 | P10: ='Footprints, only calves'!P10+Production!$E$7*'Footprints, mother animal'!P10/Production!$E$23 -> 1.3523146 | Q10: ='Footprints, only calves'!Q10+Production!$E$7*'Footprints, mother animal'!Q10/Production!$E$23 -> 1.5414764e-08 | R10: ='Footprints, only calves'!R10+Production!$E$7*'Footprints, mother animal'!R10/Production!$E$23 -> 0.18602505 | S10: ='Footprints, only calves'!S10+Production!$E$7*'Footprints, mother animal'!S10/Production!$E$23 -> 0 | T10: 0.46223854 | U10: 28.588806
A11: 21111.02_dc24 | B11: Bovine meat | C11: Red meat | D11: Hungary | E11: HU | F11: ='GHG detailed, results per kg'!G31 -> 29.961097 | G11: ='GHG detailed, results per kg'!G27 -> 6.0834424 | H11: ='GHG detailed, results per kg'!G28 -> 0.018408951 | I11: ='GHG detailed, results per kg'!G29 -> 0.66249804 | J11: ='GHG detailed, results per kg'!G30 -> 0.019932678 | L11: ='Footprints, only calves'!L11+Production!$F$7*'Footprints, mother animal'!L11/Production!$F$23 -> 36.386013 | M11: ='Footprints, only calves'!M11+Production!$F$7*'Footprints, mother animal'!M11/Production!$F$23 -> 0.50103554 | N11: ='Footprints, only calves'!N11+Production!$F$7*'Footprints, mother animal'!N11/Production!$F$23 -> 0.043608658 | O11: ='Footprints, only calves'!O11+Production!$F$7*'Footprints, mother animal'!O11/Production!$F$23 -> 0.072651871 | P11: ='Footprints, only calves'!P11+Production!$F$7*'Footprints, mother animal'!P11/Production!$F$23 -> 1.8223897 | Q11: ='Footprints, only calves'!Q11+Production!$F$7*'Footprints, mother animal'!Q11/Production!$F$23 -> 1.1409672e-09 | R11: ='Footprints, only calves'!R11+Production!$F$7*'Footprints, mother animal'!R11/Production!$F$23 -> 0.19064653 | S11: ='Footprints, only calves'!S11+Production!$F$7*'Footprints, mother animal'!S11/Production!$F$23 -> 0 | T11: 0.48610932 | U11: 22.282123
A12: 21111.02_dc24 | B12: Bovine meat | C12: Red meat | D12: Ireland | E12: IE | F12: ='GHG detailed, results per kg'!G36 -> 24.106645 | G12: ='GHG detailed, results per kg'!G32 -> 2.9968111 | H12: ='GHG detailed, results per kg'!G33 -> 0.0048271858 | I12: ='GHG detailed, results per kg'!G34 -> 0.63163289 | J12: ='GHG detailed, results per kg'!G35 -> 0.014329288 | L12: ='Footprints, only calves'!L12+Production!$G$7*'Footprints, mother animal'!L12/Production!$G$23 -> 6.8152461 | M12: ='Footprints, only calves'!M12+Production!$G$7*'Footprints, mother animal'!M12/Production!$G$23 -> 0.35086283 | N12: ='Footprints, only calves'!N12+Production!$G$7*'Footprints, mother animal'!N12/Production!$G$23 -> 0.018066692 | O12: ='Footprints, only calves'!O12+Production!$G$7*'Footprints, mother animal'!O12/Production!$G$23 -> 0.039731243 | P12: ='Footprints, only calves'!P12+Production!$G$7*'Footprints, mother animal'!P12/Production!$G$23 -> 2.0936718 | Q12: ='Footprints, only calves'!Q12+Production!$G$7*'Footprints, mother animal'!Q12/Production!$G$23 -> 2.0749476e-10 | R12: ='Footprints, only calves'!R12+Production!$G$7*'Footprints, mother animal'!R12/Production!$G$23 -> 0.15456516 | S12: ='Footprints, only calves'!S12+Production!$G$7*'Footprints, mother animal'!S12/Production!$G$23 -> 0 | T12: 0.40565594 | U12: 9.7002402
A13: 21111.02_dc24 | B13: Bovine meat | C13: Red meat | D13: Italy | E13: IT | F13: ='GHG detailed, results per kg'!G41 -> 28.268778 | G13: ='GHG detailed, results per kg'!G37 -> 4.0900976 | H13: ='GHG detailed, results per kg'!G38 -> 0.014997212 | I13: ='GHG detailed, results per kg'!G39 -> 0.69299415 | J13: ='GHG detailed, results per kg'!G40 -> 0.018391655 | L13: ='Footprints, only calves'!L13+Production!$H$7*'Footprints, mother animal'!L13/Production!$H$23 -> 18.711976 | M13: ='Footprints, only calves'!M13+Production!$H$7*'Footprints, mother animal'!M13/Production!$H$23 -> 0.36409048 | N13: ='Footprints, only calves'!N13+Production!$H$7*'Footprints, mother animal'!N13/Production!$H$23 -> 0.021748047 | O13: ='Footprints, only calves'!O13+Production!$H$7*'Footprints, mother animal'!O13/Production!$H$23 -> 0.65224429 | P13: ='Footprints, only calves'!P13+Production!$H$7*'Footprints, mother animal'!P13/Production!$H$23 -> 1.3728683 | Q13: ='Footprints, only calves'!Q13+Production!$H$7*'Footprints, mother animal'!Q13/Production!$H$23 -> 5.9321408e-09 | R13: ='Footprints, only calves'!R13+Production!$H$7*'Footprints, mother animal'!R13/Production!$H$23 -> 0.25338963 | S13: ='Footprints, only calves'!S13+Production!$H$7*'Footprints, mother animal'!S13/Production!$H$23 -> 0 | T13: 0.55241704 | U13: 36.046526
A14: 21111.02_dc24 | B14: Bovine meat | C14: Red meat | D14: Netherlands | E14: NL | F14: ='GHG detailed, results per kg'!G46 -> 27.940909 | G14: ='GHG detailed, results per kg'!G42 -> 5.7542313 | H14: ='GHG detailed, results per kg'!G43 -> 0.014434474 | I14: ='GHG detailed, results per kg'!G44 -> 0.56172267 | J14: ='GHG detailed, results per kg'!G45 -> 0.02413926 | L14: ='Footprints, only calves'!L14+Production!$I$7*'Footprints, mother animal'!L14/Production!$I$23 -> 17.350177 | M14: ='Footprints, only calves'!M14+Production!$I$7*'Footprints, mother animal'!M14/Production!$I$23 -> 0.64282028 | N14: ='Footprints, only calves'!N14+Production!$I$7*'Footprints, mother animal'!N14/Production!$I$23 -> 0.016720367 | O14: ='Footprints, only calves'!O14+Production!$I$7*'Footprints, mother animal'!O14/Production!$I$23 -> 0.21910518 | P14: ='Footprints, only calves'!P14+Production!$I$7*'Footprints, mother animal'!P14/Production!$I$23 -> 1.6285781 | Q14: ='Footprints, only calves'!Q14+Production!$I$7*'Footprints, mother animal'!Q14/Production!$I$23 -> 8.688608e-10 | R14: ='Footprints, only calves'!R14+Production!$I$7*'Footprints, mother animal'!R14/Production!$I$23 -> 0.12617766 | S14: ='Footprints, only calves'!S14+Production!$I$7*'Footprints, mother animal'!S14/Production!$I$23 -> 0 | T14: 0.4084556 | U14: 7.3938528
A15: 21111.02_dc24 | B15: Bovine meat | C15: Red meat | D15: Poland | E15: PL | F15: ='GHG detailed, results per kg'!G51 -> 29.177114 | G15: ='GHG detailed, results per kg'!G47 -> 6.6892944 | H15: ='GHG detailed, results per kg'!G48 -> 0.011742448 | I15: ='GHG detailed, results per kg'!G49 -> 0.58237224 | J15: ='GHG detailed, results per kg'!G50 -> 0.023493934 | L15: ='Footprints, only calves'!L15+Production!$J$7*'Footprints, mother animal'!L15/Production!$J$23 -> 24.504847 | M15: ='Footprints, only calves'!M15+Production!$J$7*'Footprints, mother animal'!M15/Production!$J$23 -> 0.39005059 | N15: ='Footprints, only calves'!N15+Production!$J$7*'Footprints, mother animal'!N15/Production!$J$23 -> 0.034351107 | O15: ='Footprints, only calves'!O15+Production!$J$7*'Footprints, mother animal'!O15/Production!$J$23 -> 0.086266021 | P15: ='Footprints, only calves'!P15+Production!$J$7*'Footprints, mother animal'!P15/Production!$J$23 -> 1.8979157 | Q15: ='Footprints, only calves'!Q15+Production!$J$7*'Footprints, mother animal'!Q15/Production!$J$23 -> 8.2321652e-10 | R15: ='Footprints, only calves'!R15+Production!$J$7*'Footprints, mother animal'!R15/Production!$J$23 -> 0.20617376 | S15: ='Footprints, only calves'!S15+Production!$J$7*'Footprints, mother animal'!S15/Production!$J$23 -> 0 | T15: 0.52500985 | U15: 46.317503
A16: 21111.02_dc24 | B16: Bovine meat | C16: Red meat | D16: Spain | E16: ES | F16: ='GHG detailed, results per kg'!G56 -> 24.783517 | G16: ='GHG detailed, results per kg'!G52 -> 4.4752125 | H16: ='GHG detailed, results per kg'!G53 -> 0.0096628073 | I16: ='GHG detailed, results per kg'!G54 -> 0.58698499 | J16: ='GHG detailed, results per kg'!G55 -> 0.015281164 | L16: ='Footprints, only calves'!L16+Production!$K$7*'Footprints, mother animal'!L16/Production!$K$23 -> 26.067195 | M16: ='Footprints, only calves'!M16+Production!$K$7*'Footprints, mother animal'!M16/Production!$K$23 -> 0.42116103 | N16: ='Footprints, only calves'!N16+Production!$K$7*'Footprints, mother animal'!N16/Production!$K$23 -> 0.040764647 | O16: ='Footprints, only calves'!O16+Production!$K$7*'Footprints, mother animal'!O16/Production!$K$23 -> 1.9338384 | P16: ='Footprints, only calves'!P16+Production!$K$7*'Footprints, mother animal'!P16/Production!$K$23 -> 1.7025173 | Q16: ='Footprints, only calves'!Q16+Production!$K$7*'Footprints, mother animal'!Q16/Production!$K$23 -> 5.5044005e-09 | R16: ='Footprints, only calves'!R16+Production!$K$7*'Footprints, mother animal'!R16/Production!$K$23 -> 0.13198399 | S16: ='Footprints, only calves'!S16+Production!$K$7*'Footprints, mother animal'!S16/Production!$K$23 -> 0 | T16: 0.36675541 | U16: 23.956277
A17: 21111.02_dc24 | B17: Bovine meat | C17: Red meat | D17: Sweden | E17: SE | F17: ='GHG detailed, results per kg'!G61 -> 25.776957 | G17: ='GHG detailed, results per kg'!G57 -> 3.6648189 | H17: ='GHG detailed, results per kg'!G58 -> 0.015911472 | I17: ='GHG detailed, results per kg'!G59 -> 0.59984781 | J17: ='GHG detailed, results per kg'!G60 -> 0.019934379 | L17: ='Footprints, only calves'!L17+Production!$L$7*'Footprints, mother animal'!L17/Production!$L$23 -> 32.361607 | M17: ='Footprints, only calves'!M17+Production!$L$7*'Footprints, mother animal'!M17/Production!$L$23 -> 0.38324318 | N17: ='Footprints, only calves'!N17+Production!$L$7*'Footprints, mother animal'!N17/Production!$L$23 -> 0.022362562 | O17: ='Footprints, only calves'!O17+Production!$L$7*'Footprints, mother animal'!O17/Production!$L$23 -> 0.12925758 | P17: ='Footprints, only calves'!P17+Production!$L$7*'Footprints, mother animal'!P17/Production!$L$23 -> 1.0961478 | Q17: ='Footprints, only calves'!Q17+Production!$L$7*'Footprints, mother animal'!Q17/Production!$L$23 -> 6.3403108e-11 | R17: ='Footprints, only calves'!R17+Production!$L$7*'Footprints, mother animal'!R17/Production!$L$23 -> 0.1383655 | S17: ='Footprints, only calves'!S17+Production!$L$7*'Footprints, mother animal'!S17/Production!$L$23 -> 0 | T17: 0.34037967 | U17: 2.8978382
A18: 21111.02_dc24 | B18: Bovine meat | C18: Red meat | D18: UK | E18: GB | F18: ='GHG detailed, results per kg'!G66 -> 24.381452 | G18: ='GHG detailed, results per kg'!G62 -> 3.2154431 | H18: ='GHG detailed, results per kg'!G63 -> 0.0040192299 | I18: ='GHG detailed, results per kg'!G64 -> 0.6189979 | J18: ='GHG detailed, results per kg'!G65 -> 0.015872865 | L18: ='Footprints, only calves'!L18+Production!$M$7*'Footprints, mother animal'!L18/Production!$M$23 -> 24.671055 | M18: ='Footprints, only calves'!M18+Production!$M$7*'Footprints, mother animal'!M18/Production!$M$23 -> 0.66147609 | N18: ='Footprints, only calves'!N18+Production!$M$7*'Footprints, mother animal'!N18/Production!$M$23 -> 0.047761845 | O18: ='Footprints, only calves'!O18+Production!$M$7*'Footprints, mother animal'!O18/Production!$M$23 -> 0.091741307 | P18: ='Footprints, only calves'!P18+Production!$M$7*'Footprints, mother animal'!P18/Production!$M$23 -> 3.9596704 | Q18: ='Footprints, only calves'!Q18+Production!$M$7*'Footprints, mother animal'!Q18/Production!$M$23 -> 2.2351625e-10 | R18: ='Footprints, only calves'!R18+Production!$M$7*'Footprints, mother animal'!R18/Production!$M$23 -> 0.12122597 | S18: ='Footprints, only calves'!S18+Production!$M$7*'Footprints, mother animal'!S18/Production!$M$23 -> 0 | T18: 0.37736464 | U18: 8.1652033

Sheet GHG detailed, results per kg
A2: GHG emissions (per kg of bonefree meat) - calves + mother animal
K3: * Calculated as percentage of direct emissions due to assumption due to data limitations regarding nitrogen leaching and volatilization from soils in different regions.
S4: Animals | W4: Stables | X4: Slaughter | Z4: Control
A5: Animal products | G5: Sum | H5: Inputs | J5: Soil emissions | L5: Energy use | P5: Land use change | Q5: Feed processing | R5: Transports | AA5: Dairy cows
A6: FoodEx code | B6: FoodEx name | C6: Food Ex category (L1) | D6: Country | E6: Country code | F6: Gas | G6: GHG | H6: Production of mineral fertilizer | I6: Production of capital goods | J6: Direct emissions | K6: Indirect emissions* | L6: Diesel use field mach | M6: Energy use in greenhouses | N6: Energy use for irrigation | O6: Energy use for post-harvest proc | P6: LUC emissions | Q6: Feed processing | R6: Feed transports | S6: Enteric fermentation* | T6: Manure management - tot | U6: Manure management - direct | V6: Manure management - indirect | W6: Energy use in stables | X6: Energy use for slaughter | Z6: Total feed, excl LUC | AA6: Feed mix emissions, kg CO2E per kg feed, excl. adjustement manure
A7: A01QV | B7: Bovine muscle | C7: Meat and meat products | D7: Denmark | E7: DK | F7: CO2 | G7: =SUM(H7:X7) -> 4.1584806 | H7: ='GHG detailed, only calves'!H7+Production!$B$7*'GHG detailed, mother animal'!H7/Production!$B$23 -> 0.30911974 | I7: ='GHG detailed, only calves'!I7+Production!$B$7*'GHG detailed, mother animal'!I7/Production!$B$23 -> 0.58985082 | J7: ='GHG detailed, only calves'!J7+Production!$B$7*'GHG detailed, mother animal'!J7/Production!$B$23 -> 0 | K7: ='GHG detailed, only calves'!K7+Production!$B$7*'GHG detailed, mother animal'!K7/Production!$B$23 -> 0 | L7: ='GHG detailed, only calves'!L7+Production!$B$7*'GHG detailed, mother animal'!L7/Production!$B$23 -> 0.33300411 | M7: ='GHG detailed, only calves'!M7+Production!$B$7*'GHG detailed, mother animal'!M7/Production!$B$23 -> 0 | N7: ='GHG detailed, only calves'!N7+Production!$B$7*'GHG detailed, mother animal'!N7/Production!$B$23 -> 0.015580535 | O7: ='GHG detailed, only calves'!O7+Production!$B$7*'GHG detailed, mother animal'!O7/Production!$B$23 -> 0.075015949 | ... X7: ='GHG detailed, only calves'!X7+Production!$B$7*'GHG detailed, mother animal'!X7/Production!$B$23 -> 0.02974226
A8: A01QV | B8: Bovine muscle | C8: Meat and meat products | D8: Denmark | E8: DK | F8: CH4, fossil | G8: =SUM(H8:X8) -> 0.020876964 | H8: ='GHG detailed, only calves'!H8+Production!$B$7*'GHG detailed, mother animal'!H8/Production!$B$23 -> 0.00045988957 | I8: ='GHG detailed, only calves'!I8+Production!$B$7*'GHG detailed, mother animal'!I8/Production!$B$23 -> 0.0020776947 | J8: ='GHG detailed, only calves'!J8+Production!$B$7*'GHG detailed, mother animal'!J8/Production!$B$23 -> 0 | K8: ='GHG detailed, only calves'!K8+Production!$B$7*'GHG detailed, mother animal'!K8/Production!$B$23 -> 0 | L8: ='GHG detailed, only calves'!L8+Production!$B$7*'GHG detailed, mother animal'!L8/Production!$B$23 -> 0.00014948914 | M8: ='GHG detailed, only calves'!M8+Production!$B$7*'GHG detailed, mother animal'!M8/Production!$B$23 -> 0 | N8: ='GHG detailed, only calves'!N8+Production!$B$7*'GHG detailed, mother animal'!N8/Production!$B$23 -> 5.2410402e-05 | O8: ='GHG detailed, only calves'!O8+Production!$B$7*'GHG detailed, mother animal'!O8/Production!$B$23 -> 5.0385501e-05 | ... X8: ='GHG detailed, only calves'!X8+Production!$B$7*'GHG detailed, mother animal'!X8/Production!$B$23 -> 2.941869e-05
A9: A01QV | B9: Bovine muscle | C9: Meat and meat products | D9: Denmark | E9: DK | F9: CH4, biogenic | G9: =SUM(H9:T9) -> 0.67527936 | H9: ='GHG detailed, only calves'!H9+Production!$B$7*'GHG detailed, mother animal'!H9/Production!$B$23 -> 0 | I9: ='GHG detailed, only calves'!I9+Production!$B$7*'GHG detailed, mother animal'!I9/Production!$B$23 -> 0 | J9: ='GHG detailed, only calves'!J9+Production!$B$7*'GHG detailed, mother animal'!J9/Production!$B$23 -> 0 | K9: ='GHG detailed, only calves'!K9+Production!$B$7*'GHG detailed, mother animal'!K9/Production!$B$23 -> 0 | L9: ='GHG detailed, only calves'!L9+Production!$B$7*'GHG detailed, mother animal'!L9/Production!$B$23 -> 0 | M9: ='GHG detailed, only calves'!M9+Production!$B$7*'GHG detailed, mother animal'!M9/Production!$B$23 -> 0 | N9: ='GHG detailed, only calves'!N9+Production!$B$7*'GHG detailed, mother animal'!N9/Production!$B$23 -> 0 | O9: ='GHG detailed, only calves'!O9+Production!$B$7*'GHG detailed, mother animal'!O9/Production!$B$23 -> 0 | ... X9: ='GHG detailed, only calves'!X9+Production!$B$7*'GHG detailed, mother animal'!X9/Production!$B$23 -> 0
A10: A01QV | B10: Bovine muscle | C10: Meat and meat products | D10: Denmark | E10: DK | F10: N2O | G10: =SUM(H10:T10)+W10+X10 -> 0.014269919 | H10: ='GHG detailed, only calves'!H10+Production!$B$7*'GHG detailed, mother animal'!H10/Production!$B$23 -> 0.00066368879 | I10: ='GHG detailed, only calves'!I10+Production!$B$7*'GHG detailed, mother animal'!I10/Production!$B$23 -> 2.3985086e-05 | J10: ='GHG detailed, only calves'!J10+Production!$B$7*'GHG detailed, mother animal'!J10/Production!$B$23 -> 0.0057084022 | K10: ='GHG detailed, only calves'!K10+Production!$B$7*'GHG detailed, mother animal'!K10/Production!$B$23 -> 0.00057084022 | L10: ='GHG detailed, only calves'!L10+Production!$B$7*'GHG detailed, mother animal'!L10/Production!$B$23 -> 9.0219131e-06 | M10: ='GHG detailed, only calves'!M10+Production!$B$7*'GHG detailed, mother animal'!M10/Production!$B$23 -> 0 | N10: ='GHG detailed, only calves'!N10+Production!$B$7*'GHG detailed, mother animal'!N10/Production!$B$23 -> 6.449865e-07 | O10: ='GHG detailed, only calves'!O10+Production!$B$7*'GHG detailed, mother animal'!O10/Production!$B$23 -> 2.7576819e-06 | ... X10: ='GHG detailed, only calves'!X10+Production!$B$7*'GHG detailed, mother animal'!X10/Production!$B$23 -> 1.3439832e-06
A11: A01QV | B11: Bovine muscle | C11: Meat and meat products | D11: Denmark | E11: DK | F11: CO2e | G11: =SUM(H11:X11) -> 26.908845 | H11: =SUMPRODUCT(H7:H10,'Parameters, general'!$B$23:$B$26) -> 0.50401149 | I11: =SUMPRODUCT(I7:I10,'Parameters, general'!$B$23:$B$26) -> 0.65831406 | J11: =SUMPRODUCT(J7:J10,'Parameters, general'!$B$23:$B$26) -> 1.5583938 | K11: =SUMPRODUCT(K7:K10,'Parameters, general'!$B$23:$B$26) -> 0.15583938 | L11: =SUMPRODUCT(L7:L10,'Parameters, general'!$B$23:$B$26) -> 0.33992187 | M11: =SUMPRODUCT(M7:M10,'Parameters, general'!$B$23:$B$26) -> 0 | N11: =SUMPRODUCT(N7:N10,'Parameters, general'!$B$23:$B$26) -> 0.017318446 | O11: =SUMPRODUCT(O7:O10,'Parameters, general'!$B$23:$B$26) -> 0.077270285 | ... T11: =SUMPRODUCT(T7:T10,'Parameters, general'!$B$23:$B$26) -> 4.5107129 | W11: =SUMPRODUCT(W7:W10,'Parameters, general'!$B$23:$B$26) -> 0.89120028 | X11: =SUMPRODUCT(X7:X10,'Parameters, general'!$B$23:$B$26) -> 0.030985844 | Z11: =SUM(H11:R11) -> 6.2166893 | AA11: ='CO2 per kg feed'!F20+'CH4 per kg feed'!F20*CF_GWP_CH4_fossil+'N2O per kg feed'!F20*CF_GWP_N2O -> 0.21046383
A12: A01QV | B12: Bovine muscle | C12: Meat and meat products | D12: France | E12: FR | F12: CO2 | G12: =SUM(H12:X12) -> 3.4797961 | H12: ='GHG detailed, only calves'!H12+Production!$C$7*'GHG detailed, mother animal'!H12/Production!$C$23 -> 0.64811709 | I12: ='GHG detailed, only calves'!I12+Production!$C$7*'GHG detailed, mother animal'!I12/Production!$C$23 -> 0.54854128 | J12: ='GHG detailed, only calves'!J12+Production!$C$7*'GHG detailed, mother animal'!J12/Production!$C$23 -> 0 | K12: ='GHG detailed, only calves'!K12+Production!$C$7*'GHG detailed, mother animal'!K12/Production!$C$23 -> 0 | L12: ='GHG detailed, only calves'!L12+Production!$C$7*'GHG detailed, mother animal'!L12/Production!$C$23 -> 0.38594931 | M12: ='GHG detailed, only calves'!M12+Production!$C$7*'GHG detailed, mother animal'!M12/Production!$C$23 -> 0 | N12: ='GHG detailed, only calves'!N12+Production!$C$7*'GHG detailed, mother animal'!N12/Production!$C$23 -> 0.050827839 | O12: ='GHG detailed, only calves'!O12+Production!$C$7*'GHG detailed, mother animal'!O12/Production!$C$23 -> 0.11977034 | ... X12: ='GHG detailed, only calves'!X12+Production!$C$7*'GHG detailed, mother animal'!X12/Production!$C$23 -> 0.001571707
A13: A01QV | B13: Bovine muscle | C13: Meat and meat products | D13: France | E13: FR | F13: CH4, fossil | G13: =SUM(H13:X13) -> 0.015134033 | H13: ='GHG detailed, only calves'!H13+Production!$C$7*'GHG detailed, mother animal'!H13/Production!$C$23 -> 0.0012151736 | I13: ='GHG detailed, only calves'!I13+Production!$C$7*'GHG detailed, mother animal'!I13/Production!$C$23 -> 0.0019391319 | J13: ='GHG detailed, only calves'!J13+Production!$C$7*'GHG detailed, mother animal'!J13/Production!$C$23 -> 0 | K13: ='GHG detailed, only calves'!K13+Production!$C$7*'GHG detailed, mother animal'!K13/Production!$C$23 -> 0 | L13: ='GHG detailed, only calves'!L13+Production!$C$7*'GHG detailed, mother animal'!L13/Production!$C$23 -> 0.0001731781 | M13: ='GHG detailed, only calves'!M13+Production!$C$7*'GHG detailed, mother animal'!M13/Production!$C$23 -> 0 | N13: ='GHG detailed, only calves'!N13+Production!$C$7*'GHG detailed, mother animal'!N13/Production!$C$23 -> 0.00017062754 | O13: ='GHG detailed, only calves'!O13+Production!$C$7*'GHG detailed, mother animal'!O13/Production!$C$23 -> 6.986607e-05 | ... X13: ='GHG detailed, only calves'!X13+Production!$C$7*'GHG detailed, mother animal'!X13/Production!$C$23 -> 1.7451993e-06
A14: A01QV | B14: Bovine muscle | C14: Meat and meat products | D14: France | E14: FR | F14: CH4, biogenic | G14: =SUM(H14:T14) -> 0.60767863 | H14: ='GHG detailed, only calves'!H14+Production!$C$7*'GHG detailed, mother animal'!H14/Production!$C$23 -> 0 | I14: ='GHG detailed, only calves'!I14+Production!$C$7*'GHG detailed, mother animal'!I14/Production!$C$23 -> 0 | J14: ='GHG detailed, only calves'!J14+Production!$C$7*'GHG detailed, mother animal'!J14/Production!$C$23 -> 0 | K14: ='GHG detailed, only calves'!K14+Production!$C$7*'GHG detailed, mother animal'!K14/Production!$C$23 -> 0 | L14: ='GHG detailed, only calves'!L14+Production!$C$7*'GHG detailed, mother animal'!L14/Production!$C$23 -> 0 | M14: ='GHG detailed, only calves'!M14+Production!$C$7*'GHG detailed, mother animal'!M14/Production!$C$23 -> 0 | N14: ='GHG detailed, only calves'!N14+Production!$C$7*'GHG detailed, mother animal'!N14/Production!$C$23 -> 0 | O14: ='GHG detailed, only calves'!O14+Production!$C$7*'GHG detailed, mother animal'!O14/Production!$C$23 -> 0 | ... X14: ='GHG detailed, only calves'!X14+Production!$C$7*'GHG detailed, mother animal'!X14/Production!$C$23 -> 0
A15: A01QV | B15: Bovine muscle | C15: Meat and meat products | D15: France | E15: FR | F15: N2O | G15: =SUM(H15:T15)+W15+X15 -> 0.018453819 | H15: ='GHG detailed, only calves'!H15+Production!$C$7*'GHG detailed, mother animal'!H15/Production!$C$23 -> 0.0014294031 | I15: ='GHG detailed, only calves'!I15+Production!$C$7*'GHG detailed, mother animal'!I15/Production!$C$23 -> 2.2166393e-05 | J15: ='GHG detailed, only calves'!J15+Production!$C$7*'GHG detailed, mother animal'!J15/Production!$C$23 -> 0.008889933 | K15: ='GHG detailed, only calves'!K15+Production!$C$7*'GHG detailed, mother animal'!K15/Production!$C$23 -> 0.0008889933 | L15: ='GHG detailed, only calves'!L15+Production!$C$7*'GHG detailed, mother animal'!L15/Production!$C$23 -> 1.0607573e-05 | M15: ='GHG detailed, only calves'!M15+Production!$C$7*'GHG detailed, mother animal'!M15/Production!$C$23 -> 0 | N15: ='GHG detailed, only calves'!N15+Production!$C$7*'GHG detailed, mother animal'!N15/Production!$C$23 -> 2.100164e-06 | O15: ='GHG detailed, only calves'!O15+Production!$C$7*'GHG detailed, mother animal'!O15/Production!$C$23 -> 4.4175478e-06 | ... X15: ='GHG detailed, only calves'!X15+Production!$C$7*'GHG detailed, mother animal'!X15/Production!$C$23 -> 8.0264974e-08
A16: A01QV | B16: Bovine muscle | C16: Meat and meat products | D16: France | E16: FR | F16: CO2e | G16: =SUM(H16:X16) -> 25.376006 | H16: =SUMPRODUCT(H12:H15,'Parameters, general'!$B$23:$B$26) -> 1.0745563 | I16: =SUMPRODUCT(I12:I15,'Parameters, general'!$B$23:$B$26) -> 0.61237884 | J16: =SUMPRODUCT(J12:J15,'Parameters, general'!$B$23:$B$26) -> 2.4269517 | K16: =SUMPRODUCT(K12:K15,'Parameters, general'!$B$23:$B$26) -> 0.24269517 | L16: =SUMPRODUCT(L12:L15,'Parameters, general'!$B$23:$B$26) -> 0.39400589 | M16: =SUMPRODUCT(M12:M15,'Parameters, general'!$B$23:$B$26) -> 0 | N16: =SUMPRODUCT(N12:N15,'Parameters, general'!$B$23:$B$26) -> 0.056485885 | O16: =SUMPRODUCT(O12:O15,'Parameters, general'!$B$23:$B$26) -> 0.12305834 | ... T16: =SUMPRODUCT(T12:T15,'Parameters, general'!$B$23:$B$26) -> 2.9070556 | W16: =SUMPRODUCT(W12:W15,'Parameters, general'!$B$23:$B$26) -> 0.44590589 | X16: =SUMPRODUCT(X12:X15,'Parameters, general'!$B$23:$B$26) -> 0.0016456263 | Z16: =SUM(H16:R16) -> 6.8435566 | AA16: ='CO2 per kg feed'!F36+'CH4 per kg feed'!F36*CF_GWP_CH4_fossil+'N2O per kg feed'!F36*CF_GWP_N2O -> 0.24350291
A17: A01QV | B17: Bovine muscle | C17: Meat and meat products | D17: Germany | E17: DE | F17: CO2 | G17: =SUM(H17:X17) -> 4.0175058 | H17: ='GHG detailed, only calves'!H17+Production!$D$7*'GHG detailed, mother animal'!H17/Production!$D$23 -> 0.47677431 | I17: ='GHG detailed, only calves'!I17+Production!$D$7*'GHG detailed, mother animal'!I17/Production!$D$23 -> 0.54157731 | J17: ='GHG detailed, only calves'!J17+Production!$D$7*'GHG detailed, mother animal'!J17/Production!$D$23 -> 0 | K17: ='GHG detailed, only calves'!K17+Production!$D$7*'GHG detailed, mother animal'!K17/Production!$D$23 -> 0 | L17: ='GHG detailed, only calves'!L17+Production!$D$7*'GHG detailed, mother animal'!L17/Production!$D$23 -> 0.33324936 | M17: ='GHG detailed, only calves'!M17+Production!$D$7*'GHG detailed, mother animal'!M17/Production!$D$23 -> 0 | N17: ='GHG detailed, only calves'!N17+Production!$D$7*'GHG detailed, mother animal'!N17/Production!$D$23 -> 0.014075493 | O17: ='GHG detailed, only calves'!O17+Production!$D$7*'GHG detailed, mother animal'!O17/Production!$D$23 -> 0.059263391 | ... X17: ='GHG detailed, only calves'!X17+Production!$D$7*'GHG detailed, mother animal'!X17/Production!$D$23 -> 0.034291614
A18: A01QV | B18: Bovine muscle | C18: Meat and meat products | D18: Germany | E18: DE | F18: CH4, fossil | G18: =SUM(H18:X18) -> 0.015682521 | H18: ='GHG detailed, only calves'!H18+Production!$D$7*'GHG detailed, mother animal'!H18/Production!$D$23 -> 0.00088939653 | I18: ='GHG detailed, only calves'!I18+Production!$D$7*'GHG detailed, mother animal'!I18/Production!$D$23 -> 0.0019065272 | J18: ='GHG detailed, only calves'!J18+Production!$D$7*'GHG detailed, mother animal'!J18/Production!$D$23 -> 0 | K18: ='GHG detailed, only calves'!K18+Production!$D$7*'GHG detailed, mother animal'!K18/Production!$D$23 -> 0 | L18: ='GHG detailed, only calves'!L18+Production!$D$7*'GHG detailed, mother animal'!L18/Production!$D$23 -> 0.00015272784 | M18: ='GHG detailed, only calves'!M18+Production!$D$7*'GHG detailed, mother animal'!M18/Production!$D$23 -> 0 | N18: ='GHG detailed, only calves'!N18+Production!$D$7*'GHG detailed, mother animal'!N18/Production!$D$23 -> 4.7044461e-05 | O18: ='GHG detailed, only calves'!O18+Production!$D$7*'GHG detailed, mother animal'!O18/Production!$D$23 -> 3.9986716e-05 | ... X18: ='GHG detailed, only calves'!X18+Production!$D$7*'GHG detailed, mother animal'!X18/Production!$D$23 -> 4.7795748e-05
A19: A01QV | B19: Bovine muscle | C19: Meat and meat products | D19: Germany | E19: DE | F19: CH4, biogenic | G19: =SUM(H19:T19) -> 0.63692123 | H19: ='GHG detailed, only calves'!H19+Production!$D$7*'GHG detailed, mother animal'!H19/Production!$D$23 -> 0 | I19: ='GHG detailed, only calves'!I19+Production!$D$7*'GHG detailed, mother animal'!I19/Production!$D$23 -> 0 | J19: ='GHG detailed, only calves'!J19+Production!$D$7*'GHG detailed, mother animal'!J19/Production!$D$23 -> 0 | K19: ='GHG detailed, only calves'!K19+Production!$D$7*'GHG detailed, mother animal'!K19/Production!$D$23 -> 0 | L19: ='GHG detailed, only calves'!L19+Production!$D$7*'GHG detailed, mother animal'!L19/Production!$D$23 -> 0 | M19: ='GHG detailed, only calves'!M19+Production!$D$7*'GHG detailed, mother animal'!M19/Production!$D$23 -> 0 | N19: ='GHG detailed, only calves'!N19+Production!$D$7*'GHG detailed, mother animal'!N19/Production!$D$23 -> 0 | O19: ='GHG detailed, only calves'!O19+Production!$D$7*'GHG detailed, mother animal'!O19/Production!$D$23 -> 0 | ... X19: ='GHG detailed, only calves'!X19+Production!$D$7*'GHG detailed, mother animal'!X19/Production!$D$23 -> 0
A20: A01QV | B20: Bovine muscle | C20: Meat and meat products | D20: Germany | E20: DE | F20: N2O | G20: =SUM(H20:T20)+W20+X20 -> 0.015171199 | H20: ='GHG detailed, only calves'!H20+Production!$D$7*'GHG detailed, mother animal'!H20/Production!$D$23 -> 0.0010500897 | I20: ='GHG detailed, only calves'!I20+Production!$D$7*'GHG detailed, mother animal'!I20/Production!$D$23 -> 2.2044712e-05 | J20: ='GHG detailed, only calves'!J20+Production!$D$7*'GHG detailed, mother animal'!J20/Production!$D$23 -> 0.0063027485 | K20: ='GHG detailed, only calves'!K20+Production!$D$7*'GHG detailed, mother animal'!K20/Production!$D$23 -> 0.00063027485 | L20: ='GHG detailed, only calves'!L20+Production!$D$7*'GHG detailed, mother animal'!L20/Production!$D$23 -> 9.1453572e-06 | M20: ='GHG detailed, only calves'!M20+Production!$D$7*'GHG detailed, mother animal'!M20/Production!$D$23 -> 0 | N20: ='GHG detailed, only calves'!N20+Production!$D$7*'GHG detailed, mother animal'!N20/Production!$D$23 -> 5.7896905e-07 | O20: ='GHG detailed, only calves'!O20+Production!$D$7*'GHG detailed, mother animal'!O20/Production!$D$23 -> 2.1290793e-06 | ... X20: ='GHG detailed, only calves'!X20+Production!$D$7*'GHG detailed, mother animal'!X20/Production!$D$23 -> 1.4269408e-06
A21: A01QV | B21: Bovine muscle | C21: Meat and meat products | D21: Germany | E21: DE | F21: CO2e | G21: =SUM(H21:X21) -> 25.823455 | H21: =SUMPRODUCT(H17:H20,'Parameters, general'!$B$23:$B$26) -> 0.78995281 | I21: =SUMPRODUCT(I17:I20,'Parameters, general'!$B$23:$B$26) -> 0.60441002 | J21: =SUMPRODUCT(J17:J20,'Parameters, general'!$B$23:$B$26) -> 1.7206503 | K21: =SUMPRODUCT(K17:K20,'Parameters, general'!$B$23:$B$26) -> 0.17206503 | L21: =SUMPRODUCT(L17:L20,'Parameters, general'!$B$23:$B$26) -> 0.34029733 | M21: =SUMPRODUCT(M17:M20,'Parameters, general'!$B$23:$B$26) -> 0 | N21: =SUMPRODUCT(N17:N20,'Parameters, general'!$B$23:$B$26) -> 0.015635477 | O21: =SUMPRODUCT(O17:O20,'Parameters, general'!$B$23:$B$26) -> 0.061036234 | ... T21: =SUMPRODUCT(T17:T20,'Parameters, general'!$B$23:$B$26) -> 3.7995222 | W21: =SUMPRODUCT(W17:W20,'Parameters, general'!$B$23:$B$26) -> 1.0310344 | X21: =SUMPRODUCT(X17:X20,'Parameters, general'!$B$23:$B$26) -> 0.036105482 | Z21: =SUM(H21:R21) -> 5.8931773 | AA21: ='CO2 per kg feed'!F52+'CH4 per kg feed'!F52*CF_GWP_CH4_fossil+'N2O per kg feed'!F52*CF_GWP_N2O -> 0.23743924
A22: A01QV | B22: Bovine muscle | C22: Meat and meat products | D22: Greece | E22: GR | F22: CO2 | G22: =SUM(H22:X22) -> 6.179929 | H22: ='GHG detailed, only calves'!H22+Production!$E$7*'GHG detailed, mother animal'!H22/Production!$E$23 -> 1.1962923 | I22: ='GHG detailed, only calves'!I22+Production!$E$7*'GHG detailed, mother animal'!I22/Production!$E$23 -> 0.57340166 | J22: ='GHG detailed, only calves'!J22+Production!$E$7*'GHG detailed, mother animal'!J22/Production!$E$23 -> 0 | K22: ='GHG detailed, only calves'!K22+Production!$E$7*'GHG detailed, mother animal'!K22/Production!$E$23 -> 0 | L22: ='GHG detailed, only calves'!L22+Production!$E$7*'GHG detailed, mother animal'!L22/Production!$E$23 -> 0.77868266 | M22: ='GHG detailed, only calves'!M22+Production!$E$7*'GHG detailed, mother animal'!M22/Production!$E$23 -> 0 | N22: ='GHG detailed, only calves'!N22+Production!$E$7*'GHG detailed, mother animal'!N22/Production!$E$23 -> 0.1324875 | O22: ='GHG detailed, only calves'!O22+Production!$E$7*'GHG detailed, mother animal'!O22/Production!$E$23 -> 0.41223113 | ... X22: ='GHG detailed, only calves'!X22+Production!$E$7*'GHG detailed, mother animal'!X22/Production!$E$23 -> 0.042926284
A23: A01QV | B23: Bovine muscle | C23: Meat and meat products | D23: Greece | E23: GR | F23: CH4, fossil | G23: =SUM(H23:X23) -> 0.013306376 | H23: ='GHG detailed, only calves'!H23+Production!$E$7*'GHG detailed, mother animal'!H23/Production!$E$23 -> 0.0022597077 | I23: ='GHG detailed, only calves'!I23+Production!$E$7*'GHG detailed, mother animal'!I23/Production!$E$23 -> 0.002057485 | J23: ='GHG detailed, only calves'!J23+Production!$E$7*'GHG detailed, mother animal'!J23/Production!$E$23 -> 0 | K23: ='GHG detailed, only calves'!K23+Production!$E$7*'GHG detailed, mother animal'!K23/Production!$E$23 -> 0 | L23: ='GHG detailed, only calves'!L23+Production!$E$7*'GHG detailed, mother animal'!L23/Production!$E$23 -> 0.00035381287 | M23: ='GHG detailed, only calves'!M23+Production!$E$7*'GHG detailed, mother animal'!M23/Production!$E$23 -> 0 | N23: ='GHG detailed, only calves'!N23+Production!$E$7*'GHG detailed, mother animal'!N23/Production!$E$23 -> 0.00044896669 | O23: ='GHG detailed, only calves'!O23+Production!$E$7*'GHG detailed, mother animal'!O23/Production!$E$23 -> 0.00033747672 | ... X23: ='GHG detailed, only calves'!X23+Production!$E$7*'GHG detailed, mother animal'!X23/Production!$E$23 -> 6.6575449e-05
A24: A01QV | B24: Bovine muscle | C24: Meat and meat products | D24: Greece | E24: GR | F24: CH4, biogenic | G24: =SUM(H24:T24) -> 0.60210886 | H24: ='GHG detailed, only calves'!H24+Production!$E$7*'GHG detailed, mother animal'!H24/Production!$E$23 -> 0 | I24: ='GHG detailed, only calves'!I24+Production!$E$7*'GHG detailed, mother animal'!I24/Production!$E$23 -> 0 | J24: ='GHG detailed, only calves'!J24+Production!$E$7*'GHG detailed, mother animal'!J24/Production!$E$23 -> 0 | K24: ='GHG detailed, only calves'!K24+Production!$E$7*'GHG detailed, mother animal'!K24/Production!$E$23 -> 0 | L24: ='GHG detailed, only calves'!L24+Production!$E$7*'GHG detailed, mother animal'!L24/Production!$E$23 -> 0 | M24: ='GHG detailed, only calves'!M24+Production!$E$7*'GHG detailed, mother animal'!M24/Production!$E$23 -> 0 | N24: ='GHG detailed, only calves'!N24+Production!$E$7*'GHG detailed, mother animal'!N24/Production!$E$23 -> 0 | O24: ='GHG detailed, only calves'!O24+Production!$E$7*'GHG detailed, mother animal'!O24/Production!$E$23 -> 0 | ... X24: ='GHG detailed, only calves'!X24+Production!$E$7*'GHG detailed, mother animal'!X24/Production!$E$23 -> 0
A25: A01QV | B25: Bovine muscle | C25: Meat and meat products | D25: Greece | E25: GR | F25: N2O | G25: =SUM(H25:T25)+W25+X25 -> 0.021301096 | H25: ='GHG detailed, only calves'!H25+Production!$E$7*'GHG detailed, mother animal'!H25/Production!$E$23 -> 0.0026442454 | I25: ='GHG detailed, only calves'!I25+Production!$E$7*'GHG detailed, mother animal'!I25/Production!$E$23 -> 2.2561595e-05 | J25: ='GHG detailed, only calves'!J25+Production!$E$7*'GHG detailed, mother animal'!J25/Production!$E$23 -> 0.0093794707 | K25: ='GHG detailed, only calves'!K25+Production!$E$7*'GHG detailed, mother animal'!K25/Production!$E$23 -> 0.00093794707 | L25: ='GHG detailed, only calves'!L25+Production!$E$7*'GHG detailed, mother animal'!L25/Production!$E$23 -> 2.1112366e-05 | M25: ='GHG detailed, only calves'!M25+Production!$E$7*'GHG detailed, mother animal'!M25/Production!$E$23 -> 0 | N25: ='GHG detailed, only calves'!N25+Production!$E$7*'GHG detailed, mother animal'!N25/Production!$E$23 -> 5.5240098e-06 | O25: ='GHG detailed, only calves'!O25+Production!$E$7*'GHG detailed, mother animal'!O25/Production!$E$23 -> 1.4507165e-05 | ... X25: ='GHG detailed, only calves'!X25+Production!$E$7*'GHG detailed, mother animal'!X25/Production!$E$23 -> 1.4887804e-06
A26: A01QV | B26: Bovine muscle | C26: Meat and meat products | D26: Greece | E26: GR | F26: CO2e | G26: =SUM(H26:X26) -> 28.648598 | H26: =SUMPRODUCT(H22:H25,'Parameters, general'!$B$23:$B$26) -> 1.9855106 | I26: =SUMPRODUCT(I22:I25,'Parameters, general'!$B$23:$B$26) -> 0.64087403 | J26: =SUMPRODUCT(J22:J25,'Parameters, general'!$B$23:$B$26) -> 2.5605955 | K26: =SUMPRODUCT(K22:K25,'Parameters, general'!$B$23:$B$26) -> 0.25605955 | L26: =SUMPRODUCT(L22:L25,'Parameters, general'!$B$23:$B$26) -> 0.79498996 | M26: =SUMPRODUCT(M22:M25,'Parameters, general'!$B$23:$B$26) -> 0 | N26: =SUMPRODUCT(N22:N25,'Parameters, general'!$B$23:$B$26) -> 0.14737477 | O26: =SUMPRODUCT(O22:O25,'Parameters, general'!$B$23:$B$26) -> 0.42624839 | ... T26: =SUMPRODUCT(T22:T25,'Parameters, general'!$B$23:$B$26) -> 3.2451259 | W26: =SUMPRODUCT(W22:W25,'Parameters, general'!$B$23:$B$26) -> 1.2826221 | X26: =SUMPRODUCT(X22:X25,'Parameters, general'!$B$23:$B$26) -> 0.04531667 | Z26: =SUM(H26:R26) -> 8.9377069 | AA26: ='CO2 per kg feed'!F68+'CH4 per kg feed'!F68*CF_GWP_CH4_fossil+'N2O per kg feed'!F68*CF_GWP_N2O -> 0.35845796
A27: A01QV | B27: Bovine muscle | C27: Meat and meat products | D27: Hungary | E27: HU | F27: CO2 | G27: =SUM(H27:X27) -> 6.0834424 | H27: ='GHG detailed, only calves'!H27+Production!$F$7*'GHG detailed, mother animal'!H27/Production!$F$23 -> 0.84074066 | I27: ='GHG detailed, only calves'!I27+Production!$F$7*'GHG detailed, mother animal'!I27/Production!$F$23 -> 0.54625597 | J27: ='GHG detailed, only calves'!J27+Production!$F$7*'GHG detailed, mother animal'!J27/Production!$F$23 -> 0 | K27: ='GHG detailed, only calves'!K27+Production!$F$7*'GHG detailed, mother animal'!K27/Production!$F$23 -> 0 | L27: ='GHG detailed, only calves'!L27+Production!$F$7*'GHG detailed, mother animal'!L27/Production!$F$23 -> 0.66200433 | M27: ='GHG detailed, only calves'!M27+Production!$F$7*'GHG detailed, mother animal'!M27/Production!$F$23 -> 0 | N27: ='GHG detailed, only calves'!N27+Production!$F$7*'GHG detailed, mother animal'!N27/Production!$F$23 -> 0.0020448259 | O27: ='GHG detailed, only calves'!O27+Production!$F$7*'GHG detailed, mother animal'!O27/Production!$F$23 -> 0.23618093 | ... X27: ='GHG detailed, only calves'!X27+Production!$F$7*'GHG detailed, mother animal'!X27/Production!$F$23 -> 0.033002157
A28: A01QV | B28: Bovine muscle | C28: Meat and meat products | D28: Hungary | E28: HU | F28: CH4, fossil | G28: =SUM(H28:X28) -> 0.018408951 | H28: ='GHG detailed, only calves'!H28+Production!$F$7*'GHG detailed, mother animal'!H28/Production!$F$23 -> 0.0015828993 | I28: ='GHG detailed, only calves'!I28+Production!$F$7*'GHG detailed, mother animal'!I28/Production!$F$23 -> 0.0019422648 | J28: ='GHG detailed, only calves'!J28+Production!$F$7*'GHG detailed, mother animal'!J28/Production!$F$23 -> 0 | K28: ='GHG detailed, only calves'!K28+Production!$F$7*'GHG detailed, mother animal'!K28/Production!$F$23 -> 0 | L28: ='GHG detailed, only calves'!L28+Production!$F$7*'GHG detailed, mother animal'!L28/Production!$F$23 -> 0.00030988835 | M28: ='GHG detailed, only calves'!M28+Production!$F$7*'GHG detailed, mother animal'!M28/Production!$F$23 -> 0 | N28: ='GHG detailed, only calves'!N28+Production!$F$7*'GHG detailed, mother animal'!N28/Production!$F$23 -> 8.2646964e-06 | O28: ='GHG detailed, only calves'!O28+Production!$F$7*'GHG detailed, mother animal'!O28/Production!$F$23 -> 0.00019018833 | ... X28: ='GHG detailed, only calves'!X28+Production!$F$7*'GHG detailed, mother animal'!X28/Production!$F$23 -> 5.8419995e-05
A29: A01QV | B29: Bovine muscle | C29: Meat and meat products | D29: Hungary | E29: HU | F29: CH4, biogenic | G29: =SUM(H29:T29) -> 0.66249804 | H29: ='GHG detailed, only calves'!H29+Production!$F$7*'GHG detailed, mother animal'!H29/Production!$F$23 -> 0 | I29: ='GHG detailed, only calves'!I29+Production!$F$7*'GHG detailed, mother animal'!I29/Production!$F$23 -> 0 | J29: ='GHG detailed, only calves'!J29+Production!$F$7*'GHG detailed, mother animal'!J29/Production!$F$23 -> 0 | K29: ='GHG detailed, only calves'!K29+Production!$F$7*'GHG detailed, mother animal'!K29/Production!$F$23 -> 0 | L29: ='GHG detailed, only calves'!L29+Production!$F$7*'GHG detailed, mother animal'!L29/Production!$F$23 -> 0 | M29: ='GHG detailed, only calves'!M29+Production!$F$7*'GHG detailed, mother animal'!M29/Production!$F$23 -> 0 | N29: ='GHG detailed, only calves'!N29+Production!$F$7*'GHG detailed, mother animal'!N29/Production!$F$23 -> 0 | O29: ='GHG detailed, only calves'!O29+Production!$F$7*'GHG detailed, mother animal'!O29/Production!$F$23 -> 0 | ... X29: ='GHG detailed, only calves'!X29+Production!$F$7*'GHG detailed, mother animal'!X29/Production!$F$23 -> 0
A30: A01QV | B30: Bovine muscle | C30: Meat and meat products | D30: Hungary | E30: HU | F30: N2O | G30: =SUM(H30:T30)+W30+X30 -> 0.019932678 | H30: ='GHG detailed, only calves'!H30+Production!$F$7*'GHG detailed, mother animal'!H30/Production!$F$23 -> 0.0018538684 | I30: ='GHG detailed, only calves'!I30+Production!$F$7*'GHG detailed, mother animal'!I30/Production!$F$23 -> 2.1849811e-05 | J30: ='GHG detailed, only calves'!J30+Production!$F$7*'GHG detailed, mother animal'!J30/Production!$F$23 -> 0.0076815756 | K30: ='GHG detailed, only calves'!K30+Production!$F$7*'GHG detailed, mother animal'!K30/Production!$F$23 -> 0.00076815756 | L30: ='GHG detailed, only calves'!L30+Production!$F$7*'GHG detailed, mother animal'!L30/Production!$F$23 -> 1.8164591e-05 | M30: ='GHG detailed, only calves'!M30+Production!$F$7*'GHG detailed, mother animal'!M30/Production!$F$23 -> 0 | N30: ='GHG detailed, only calves'!N30+Production!$F$7*'GHG detailed, mother animal'!N30/Production!$F$23 -> 1.01713e-07 | O30: ='GHG detailed, only calves'!O30+Production!$F$7*'GHG detailed, mother animal'!O30/Production!$F$23 -> 8.4240407e-06 | ... X30: ='GHG detailed, only calves'!X30+Production!$F$7*'GHG detailed, mother animal'!X30/Production!$F$23 -> 1.1606078e-06
