Workbook
Name Ability_to_perceive_handling: 'Parameters, general'!#REF!
Name AF_beef: 'Parameters, general'!#REF!
Name AF_calves: 'Parameters, general'!#REF!
Name AF_milk: 'Parameters, general'!#REF!
Name Boars_per_sow: 'Parameters, country spec'!#REF!
Name CF_GWP_CH4_biog: 'Parameters, general'!$B$25
Name CF_GWP_CH4_biogenic: 'Parameters, general'!$B$25
Name CF_GWP_CH4_fossil: 'Parameters, general'!$B$24
Name CF_GWP_N2O: 'Parameters, general'!$B$26
Name Crop_data: 'Forage crops, CF'!$A$6:$Z$60
Name Crop_data: 'Forage, input data per ha'!#REF!
Name Crop_data: 'Forage crops, footprints'!$A$6:$Z$19
Name Crop_data_codes: 'Forage crops, CF'!$A$56:$A$120
Name Crop_data_codes: 'Forage, input data per ha'!#REF!
Name Crop_data_codes: 'Forage crops, footprints'!$A$20:$A$33
Name EF_biofuel_CH4: 'Parameters, general'!$C$6
Name EF_biofuel_N2O: 'Parameters, general'!$D$6
Name EF_biofuels_CO2: 'Parameters, general'!$B$6
Name EF_capital_goods_CH4: 'Parameters, general'!$C$10
Name EF_capital_goods_CO2: 'Parameters, general'!$B$10
Name EF_capital_goods_N2O: 'Parameters, general'!$D$10
Name EF_diesel_CH4: 'Parameters, general'!$C$7
Name EF_diesel_CO2: 'Parameters, general'!$B$7
Name EF_diesel_N2O: 'Parameters, general'!$D$7
Name EF_el_CH4_DE: 'Parameters, country spec'!$C$70
Name EF_el_CH4_DK: 'Parameters, country spec'!#REF!
Name EF_el_CH4_ES: 'Parameters, country spec'!$I$70
Name EF_el_CH4_FR: 'Parameters, country spec'!$B$70
Name EF_el_CH4_GB: 'Parameters, country spec'!#REF!
Name EF_el_CH4_GR: 'Parameters, country spec'!$D$70
Name EF_el_CH4_HU: 'Parameters, country spec'!$E$70
Name EF_el_CH4_IE: 'Parameters, country spec'!#REF!
Name EF_el_CH4_IT: 'Parameters, country spec'!$F$70
Name EF_el_CH4_NL: 'Parameters, country spec'!$G$70
Name EF_el_CH4_PL: 'Parameters, country spec'!$H$70
Name EF_el_CH4_SE: 'Parameters, country spec'!$J$70
Name EF_el_CO2_DE: 'Parameters, country spec'!$C$69
Name EF_el_CO2_DK: 'Parameters, country spec'!#REF!
Name EF_el_CO2_ES: 'Parameters, country spec'!$I$69
Name EF_el_CO2_FR: 'Parameters, country spec'!$B$69
Name EF_el_CO2_GB: 'Parameters, country spec'!#REF!
Name EF_el_CO2_GR: 'Parameters, country spec'!$D$69
Name EF_el_CO2_HU: 'Parameters, country spec'!$E$69
Name EF_el_CO2_IE: 'Parameters, country spec'!#REF!
Name EF_el_CO2_IT: 'Parameters, country spec'!$F$69
Name EF_el_CO2_NL: 'Parameters, country spec'!$G$69
Name EF_el_CO2_PL: 'Parameters, country spec'!$H$69
Name EF_el_CO2_SE: 'Parameters, country spec'!$J$69
Name EF_el_N2O_DE: 'Parameters, country spec'!$C$71
Name EF_el_N2O_DK: 'Parameters, country spec'!#REF!
Name EF_el_N2O_ES: 'Parameters, country spec'!$I$71
Name EF_el_N2O_FR: 'Parameters, country spec'!$B$71
Name EF_el_N2O_GB: 'Parameters, country spec'!#REF!
Name EF_el_N2O_GR: 'Parameters, country spec'!$D$71
Name EF_el_N2O_HU: 'Parameters, country spec'!$E$71
Name EF_el_N2O_IE: 'Parameters, country spec'!#REF!
Name EF_el_N2O_IT: 'Parameters, country spec'!$F$71
Name EF_el_N2O_NL: 'Parameters, country spec'!$G$71
Name EF_el_N2O_PL: 'Parameters, country spec'!$H$71
Name EF_el_N2O_SE: 'Parameters, country spec'!$J$71

Sheet README
A2: Read me
A4: This is a file that contains the calculations of the footprints for rabbit meat
A17: Color codes:
B19: Results
B20: Sheets for input
B21: Intermediate calculations

Sheet Figures
A2: Figures
A4: Greenhouse gas emission for bonefree meat across countries, to farmgate, no waste
B6: Production of mineral fertilizer | C6: Production of capital goods | D6: Emissions from soil | E6: Energy use cropping | F6: Energy use for feed processing | G6: Land use change emissions | H6: Feed transports | I6: Enteric fermentation | J6: Manure management | K6: Energy use in stables | L6: Energy use for slaughter | M6: Tot
A7: Netherlands | B7: ='GHG detailed, results per kg'!H36 -> 1.3786109 | C7: ='GHG detailed, results per kg'!I36 -> 0.2800545 | D7: ='GHG detailed, results per kg'!J36+'GHG detailed, results per kg'!K36 -> 3.7802391 | E7: ='GHG detailed, results per kg'!L36+'GHG detailed, results per kg'!N36 -> 0.28901413 | F7: ='GHG detailed, results per kg'!O36+'GHG detailed, results per kg'!Q36 -> 1.417578 | G7: ='GHG detailed, results per kg'!P36 -> 0.2695554 | H7: ='GHG detailed, results per kg'!R36 -> 0.25166401 | I7: ='GHG detailed, results per kg'!S36 -> 0.0088703821 | J7: ='GHG detailed, results per kg'!T36 -> 2.0048728 | K7: ='GHG detailed, results per kg'!W36 -> 0.36526823 | L7: ='GHG detailed, results per kg'!X36 -> 0.21851551 | M7: =SUM(B7:L7) -> 10.264243
A8: Greece | B8: ='GHG detailed, results per kg'!H21 -> 1.013219 | C8: ='GHG detailed, results per kg'!I21 -> 0.2800545 | D8: ='GHG detailed, results per kg'!J21+'GHG detailed, results per kg'!K21 -> 2.811564 | E8: ='GHG detailed, results per kg'!L21+'GHG detailed, results per kg'!N21 -> 0.53655303 | F8: ='GHG detailed, results per kg'!O21+'GHG detailed, results per kg'!Q21 -> 1.7526364 | G8: ='GHG detailed, results per kg'!P21 -> 0.2695554 | H8: ='GHG detailed, results per kg'!R21 -> 0.28775674 | I8: ='GHG detailed, results per kg'!S21 -> 0.0088703821 | J8: ='GHG detailed, results per kg'!T21 -> 1.2827539 | K8: ='GHG detailed, results per kg'!W21 -> 0.49740052 | L8: ='GHG detailed, results per kg'!X21 -> 0.27945549 | M8: =SUM(B8:L8) -> 9.0198193
A9: Poland | B9: ='GHG detailed, results per kg'!H41 -> 1.4259348 | C9: ='GHG detailed, results per kg'!I41 -> 0.29216091 | D9: ='GHG detailed, results per kg'!J41+'GHG detailed, results per kg'!K41 -> 2.7909977 | E9: ='GHG detailed, results per kg'!L41+'GHG detailed, results per kg'!N41 -> 0.64444664 | F9: ='GHG detailed, results per kg'!O41+'GHG detailed, results per kg'!Q41 -> 0.60734224 | G9: ='GHG detailed, results per kg'!P41 -> 0.036971466 | H9: ='GHG detailed, results per kg'!R41 -> 0.032589551 | I9: ='GHG detailed, results per kg'!S41 -> 0.0087708149 | J9: ='GHG detailed, results per kg'!T41 -> 1.9124623 | K9: ='GHG detailed, results per kg'!W41 -> 0.71301047 | L9: ='GHG detailed, results per kg'!X41 -> 0.4204269 | M9: =SUM(B9:L9) -> 8.8851138
A10: Italy | B10: ='GHG detailed, results per kg'!H31 -> 1.0309718 | C10: ='GHG detailed, results per kg'!I31 -> 0.28110267 | D10: ='GHG detailed, results per kg'!J31+'GHG detailed, results per kg'!K31 -> 2.8051144 | E10: ='GHG detailed, results per kg'!L31+'GHG detailed, results per kg'!N31 -> 0.38730264 | F10: ='GHG detailed, results per kg'!O31+'GHG detailed, results per kg'!Q31 -> 1.300791 | G10: ='GHG detailed, results per kg'!P31 -> 0.2695154 | H10: ='GHG detailed, results per kg'!R31 -> 0.28790061 | I10: ='GHG detailed, results per kg'!S31 -> 0.0088592076 | J10: ='GHG detailed, results per kg'!T31 -> 2.0023472 | K10: ='GHG detailed, results per kg'!W31 -> 0.31381141 | L10: ='GHG detailed, results per kg'!X31 -> 0.17849507 | M10: =SUM(B10:L10) -> 8.8662114
A11: Hungary | B11: ='GHG detailed, results per kg'!H26 -> 0.98678155 | C11: ='GHG detailed, results per kg'!I26 -> 0.2800545 | D11: ='GHG detailed, results per kg'!J26+'GHG detailed, results per kg'!K26 -> 2.7167329 | E11: ='GHG detailed, results per kg'!L26+'GHG detailed, results per kg'!N26 -> 0.36990656 | F11: ='GHG detailed, results per kg'!O26+'GHG detailed, results per kg'!Q26 -> 1.3768317 | G11: ='GHG detailed, results per kg'!P26 -> 0.2695554 | H11: ='GHG detailed, results per kg'!R26 -> 0.2385663 | I11: ='GHG detailed, results per kg'!S26 -> 0.0088703821 | J11: ='GHG detailed, results per kg'!T26 -> 2.0048728 | K11: ='GHG detailed, results per kg'!W26 -> 0.3449373 | L11: ='GHG detailed, results per kg'!X26 -> 0.19561201 | M11: =SUM(B11:L11) -> 8.7927215
A12: Germany | B12: ='GHG detailed, results per kg'!H16 -> 1.0568745 | C12: ='GHG detailed, results per kg'!I16 -> 0.28002654 | D12: ='GHG detailed, results per kg'!J16+'GHG detailed, results per kg'!K16 -> 2.8012606 | E12: ='GHG detailed, results per kg'!L16+'GHG detailed, results per kg'!N16 -> 0.2793115 | F12: ='GHG detailed, results per kg'!O16+'GHG detailed, results per kg'!Q16 -> 1.4126299 | G12: ='GHG detailed, results per kg'!P16 -> 0.2695154 | H12: ='GHG detailed, results per kg'!R16 -> 0.25162806 | I12: ='GHG detailed, results per kg'!S16 -> 0.0088592076 | J12: ='GHG detailed, results per kg'!T16 -> 1.3291598 | K12: ='GHG detailed, results per kg'!W16 -> 0.36047925 | L12: ='GHG detailed, results per kg'!X16 -> 0.20415893 | M12: =SUM(B12:L12) -> 8.2539037
A13: Spain | B13: ='GHG detailed, results per kg'!H46 -> 0.38065762 | C13: ='GHG detailed, results per kg'!I46 -> 0.28387813 | D13: ='GHG detailed, results per kg'!J46+'GHG detailed, results per kg'!K46 -> 3.1672048 | E13: ='GHG detailed, results per kg'!L46+'GHG detailed, results per kg'!N46 -> 0.46081835 | F13: ='GHG detailed, results per kg'!O46+'GHG detailed, results per kg'!Q46 -> 1.0668966 | G13: ='GHG detailed, results per kg'!P46 -> 0.27502473 | H13: ='GHG detailed, results per kg'!R46 -> 0.39276949 | I13: ='GHG detailed, results per kg'!S46 -> 0.01039839 | J13: ='GHG detailed, results per kg'!T46 -> 2.4846062 | K13: ='GHG detailed, results per kg'!W46 -> 0.19742934 | L13: ='GHG detailed, results per kg'!X46 -> 0.12437267 | M13: =SUM(B13:L13) -> 8.8440563
A14: Sweden | B14: ='GHG detailed, results per kg'!H51 -> 1.1417187 | C14: ='GHG detailed, results per kg'!I51 -> 0.37488252 | D14: ='GHG detailed, results per kg'!J51+'GHG detailed, results per kg'!K51 -> 1.8938197 | E14: ='GHG detailed, results per kg'!L51+'GHG detailed, results per kg'!N51 -> 0.40498319 | F14: ='GHG detailed, results per kg'!O51+'GHG detailed, results per kg'!Q51 -> 0.92505124 | G14: ='GHG detailed, results per kg'!P51 -> 0.32262099 | H14: ='GHG detailed, results per kg'!R51 -> 0.31609243 | I14: ='GHG detailed, results per kg'!S51 -> 0.0056941381 | J14: ='GHG detailed, results per kg'!T51 -> 2.4443686 | K14: ='GHG detailed, results per kg'!W51 -> 0.03153598 | L14: ='GHG detailed, results per kg'!X51 -> 0.043366088 | M14: =SUM(B14:L14) -> 7.9041335
A15: France | B15: ='GHG detailed, results per kg'!H11 -> 1.0635128 | C15: ='GHG detailed, results per kg'!I11 -> 0.28387813 | D15: ='GHG detailed, results per kg'!J11+'GHG detailed, results per kg'!K11 -> 2.9575837 | E15: ='GHG detailed, results per kg'!L11+'GHG detailed, results per kg'!N11 -> 0.28102947 | F15: ='GHG detailed, results per kg'!O11+'GHG detailed, results per kg'!Q11 -> 0.71005917 | G15: ='GHG detailed, results per kg'!P11 -> 0.27502473 | H15: ='GHG detailed, results per kg'!R11 -> 0.24589056 | I15: ='GHG detailed, results per kg'!S11 -> 0.01039839 | J15: ='GHG detailed, results per kg'!T11 -> 1.0740251 | K15: ='GHG detailed, results per kg'!W11 -> 0.07083852 | L15: ='GHG detailed, results per kg'!X11 -> 0.044877985 | M15: =SUM(B15:L15) -> 7.0171185
A18: Cesari et al

Sheet Footprints, results per kg
A2: Footprints (per kg of meat) | T2: **Values inserted directly here, no formula in this excel sheet
A5: Animal products | F5: Climate | L5: Land | M5: Nitrogen | N5: Phosphorus | O5: Water | P5: Pesticides | Q5: Biodiversity | R5: Ammonia | S5: Labour | T5: Animal welfare** | U5: Use of antibiotics**
A6: Code | B6: Name | C6: Category | D6: Country | E6: Country code | F6: Carbon footprint, kg CO2e/kg | G6: Carbon dioxide, kg CO2/kg | H6: Methane, fossil, kg CH4/kg | I6: Methane, biogenic, kg CH4/kg | J6: Nitrous oxide, kg N2O/kg | K6: HFCs, kg HFCs/kg | L6: Cropland use, m2/kg | M6: New N input, kg N/kg | N6: New P input, kg P/kg | O6: Blue freshwater use, m3/kg | P6: Pesticide use, g a.i./kg | Q6: Extinction rate, E/MSY/kg | R6: Ammonia emission, kg NH3/kg | S6: Labour requirements, h/kg | T6: Animal welfare index per kg of bonefree meat | U6: Antibiotics use indicator/kg
A7: 21114 | B7: Rabbit meat | C7: Red meat | D7: France | E7: FR | F7: ='GHG detailed, results per kg'!G11 -> 7.0171185 | G7: ='GHG detailed, results per kg'!G7 -> 2.3456337 | H7: ='GHG detailed, results per kg'!G8 -> 0.0055894578 | I7: ='GHG detailed, results per kg'!G9 -> 0.016603948 | J7: ='GHG detailed, results per kg'!G10 -> 0.014859386 | L7: =(Production!$B$5*'Parameters, country spec'!$B$52*'EFP per kg feed'!F20+(Production!$B$6+Production!$B$7)*'Parameters, country spec'!$B$53*'EFP per kg feed'!F21)/Production!$B$23 -> 14.898766 | M7: =(Production!$B$5*'Parameters, country spec'!$B$52*'EFP per kg feed'!G20+(Production!$B$6+Production!$B$7)*'Parameters, country spec'!$B$53*'EFP per kg feed'!G21-Excreted_N_after_losses_FR*Manure_repl_factor_FR)/Production!B23 -> 0.22204242 | N7: =(Production!$B$5*'Parameters, country spec'!$B$52*'EFP per kg feed'!H20+(Production!$B$6+Production!$B$7)*'Parameters, country spec'!$B$53*'EFP per kg feed'!H21)/Production!B23 -> 0.02009215 | O7: =(Production!$B$5*'Parameters, country spec'!$B$52*'EFP per kg feed'!I20+(Production!$B$6+Production!$B$7)*'Parameters, country spec'!$B$53*'EFP per kg feed'!I21)/Production!B23 -> 0.029030357 | P7: =(Production!$B$5*'Parameters, country spec'!$B$52*'EFP per kg feed'!J20+(Production!$B$6+Production!$B$7)*'Parameters, country spec'!$B$53*'EFP per kg feed'!J21)/Production!B23 -> 2.0218759 | Q7: =(Production!$B$5*'Parameters, country spec'!$B$52*'EFP per kg feed'!K20+(Production!$B$6+Production!$B$7)*'Parameters, country spec'!$B$53*'EFP per kg feed'!K21)/Production!B23 -> 2.4893953e-10 | R7: =(Production!$B$5*'Parameters, country spec'!$B$52*'EFP per kg feed'!L20+(Production!$B$6+Production!$B$7)*'Parameters, country spec'!$B$53*'EFP per kg feed'!L21+Manure!C156)/Production!B23 -> 0.19626361 | T7: 121.2559 | U7: 757.9411
A8: 21114 | B8: Rabbit meat | C8: Red meat | D8: Germany | E8: DE | F8: ='GHG detailed, results per kg'!G16 -> 8.2539037 | G8: ='GHG detailed, results per kg'!G12 -> 3.4261773 | H8: ='GHG detailed, results per kg'!G13 -> 0.0073404684 | I8: ='GHG detailed, results per kg'!G14 -> 0.027964304 | J8: ='GHG detailed, results per kg'!G15 -> 0.014117012 | L8: =(Production!$C$5*'Parameters, country spec'!$C$52*'EFP per kg feed'!F36+(Production!$C$6+Production!$C$7)*'Parameters, country spec'!$C$53*'EFP per kg feed'!F37)/Production!$C$23 -> 14.49535 | M8: =(Production!$C$5*'Parameters, country spec'!$C$52*'EFP per kg feed'!G36+(Production!$C$6+Production!$C$7)*'Parameters, country spec'!$C$53*'EFP per kg feed'!G37-Excreted_N_after_losses_DE*Manure_repl_factor_DE)/Production!$C$23 -> 0.22454163 | N8: =(Production!$C$5*'Parameters, country spec'!$C$52*'EFP per kg feed'!H36+(Production!$C$6+Production!$C$7)*'Parameters, country spec'!$C$53*'EFP per kg feed'!H37)/Production!$C$23 -> 0.019789972 | O8: =(Production!$C$5*'Parameters, country spec'!$C$52*'EFP per kg feed'!I36+(Production!$C$6+Production!$C$7)*'Parameters, country spec'!$C$53*'EFP per kg feed'!I37)/Production!$C$23 -> 0.010788415 | P8: =(Production!$C$5*'Parameters, country spec'!$C$52*'EFP per kg feed'!J36+(Production!$C$6+Production!$C$7)*'Parameters, country spec'!$C$53*'EFP per kg feed'!J37)/Production!$C$23 -> 1.9767378 | Q8: =(Production!$C$5*'Parameters, country spec'!$C$52*'EFP per kg feed'!K36+(Production!$C$6+Production!$C$7)*'Parameters, country spec'!$C$53*'EFP per kg feed'!K37)/Production!$C$23 -> 2.1621626e-10 | R8: =(Production!$C$5*'Parameters, country spec'!$C$52*'EFP per kg feed'!L36+(Production!$C$6+Production!$C$7)*'Parameters, country spec'!$C$53*'EFP per kg feed'!L37+Manure!E156)/Production!$C$23 -> 0.18057984 | T8: 101.88378 | U8: 1269.8643
A9: 21114 | B9: Rabbit meat | C9: Red meat | D9: Greece | E9: GR | F9: ='GHG detailed, results per kg'!G21 -> 9.0198193 | G9: ='GHG detailed, results per kg'!G17 -> 4.2036425 | H9: ='GHG detailed, results per kg'!G18 -> 0.0085784067 | I9: ='GHG detailed, results per kg'!G19 -> 0.0012544322 | J9: ='GHG detailed, results per kg'!G20 -> 0.016581211 | L9: =(Production!$D$5*'Parameters, country spec'!$D$52*'EFP per kg feed'!F52+(Production!$D$6+Production!$D$7)*'Parameters, country spec'!$D$53*'EFP per kg feed'!F53)/Production!$D$23 -> 28.746278 | M9: =(Production!$D$5*'Parameters, country spec'!$D$52*'EFP per kg feed'!G52+(Production!$D$6+Production!$D$7)*'Parameters, country spec'!$D$53*'EFP per kg feed'!G53-Excreted_N_after_losses_GR*Manure_repl_factor_GR)/Production!$D$23 -> 0.26640592 | N9: =(Production!$D$5*'Parameters, country spec'!$D$52*'EFP per kg feed'!H52+(Production!$D$6+Production!$D$7)*'Parameters, country spec'!$D$53*'EFP per kg feed'!H53)/Production!$D$23 -> 0.024037419 | O9: =(Production!$D$5*'Parameters, country spec'!$D$52*'EFP per kg feed'!I52+(Production!$D$6+Production!$D$7)*'Parameters, country spec'!$D$53*'EFP per kg feed'!I53)/Production!$D$23 -> 0.12704871 | P9: =(Production!$D$5*'Parameters, country spec'!$D$52*'EFP per kg feed'!J52+(Production!$D$6+Production!$D$7)*'Parameters, country spec'!$D$53*'EFP per kg feed'!J53)/Production!$D$23 -> 1.1644736 | Q9: =(Production!$D$5*'Parameters, country spec'!$D$52*'EFP per kg feed'!K52+(Production!$D$6+Production!$D$7)*'Parameters, country spec'!$D$53*'EFP per kg feed'!K53)/Production!$D$23 -> 1.1193561e-09 | R9: =(Production!$D$5*'Parameters, country spec'!$D$52*'EFP per kg feed'!L52+(Production!$D$6+Production!$D$7)*'Parameters, country spec'!$D$53*'EFP per kg feed'!L53+Manure!G156)/Production!$D$23 -> 0.18036992 | T9: 102.67637 | U9: 2477.6965
A10: 21114 | B10: Rabbit meat | C10: Red meat | D10: Hungary | E10: HU | F10: ='GHG detailed, results per kg'!G26 -> 8.7927215 | G10: ='GHG detailed, results per kg'!G22 -> 3.3854858 | H10: ='GHG detailed, results per kg'!G23 -> 0.007930952 | I10: ='GHG detailed, results per kg'!G24 -> 0.027999577 | J10: ='GHG detailed, results per kg'!G25 -> 0.016171812 | L10: =(Production!$E$5*'Parameters, country spec'!$E$52*'EFP per kg feed'!F68+(Production!$E$6+Production!$E$7)*'Parameters, country spec'!$E$53*'EFP per kg feed'!F69)/Production!$E$23 -> 21.111353 | M10: =(Production!$E$5*'Parameters, country spec'!$E$52*'EFP per kg feed'!G68+(Production!$E$6+Production!$E$7)*'Parameters, country spec'!$E$53*'EFP per kg feed'!G69-Excreted_N_after_losses_HU*Manure_repl_factor_HU)/Production!$E$23 -> 0.28947878 | N10: =(Production!$E$5*'Parameters, country spec'!$E$52*'EFP per kg feed'!H68+(Production!$E$6+Production!$E$7)*'Parameters, country spec'!$E$53*'EFP per kg feed'!H69)/Production!$E$23 -> 0.026366738 | O10: =(Production!$E$5*'Parameters, country spec'!$E$52*'EFP per kg feed'!I68+(Production!$E$6+Production!$E$7)*'Parameters, country spec'!$E$53*'EFP per kg feed'!I69)/Production!$E$23 -> 0.0195214 | P10: =(Production!$E$5*'Parameters, country spec'!$E$52*'EFP per kg feed'!J68+(Production!$E$6+Production!$E$7)*'Parameters, country spec'!$E$53*'EFP per kg feed'!J69)/Production!$E$23 -> 1.3864312 | Q10: =(Production!$E$5*'Parameters, country spec'!$E$52*'EFP per kg feed'!K68+(Production!$E$6+Production!$E$7)*'Parameters, country spec'!$E$53*'EFP per kg feed'!K69)/Production!$E$23 -> 3.0965469e-10 | R10: =(Production!$E$5*'Parameters, country spec'!$E$52*'EFP per kg feed'!L68+(Production!$E$6+Production!$E$7)*'Parameters, country spec'!$E$53*'EFP per kg feed'!L69+Manure!I156)/Production!$E$23 -> 0.18010799 | T10: 102.67637 | U10: 1931.1173
A11: 21114 | B11: Rabbit meat | C11: Red meat | D11: Italy | E11: IT | F11: ='GHG detailed, results per kg'!G31 -> 8.8662114 | G11: ='GHG detailed, results per kg'!G27 -> 3.3048845 | H11: ='GHG detailed, results per kg'!G28 -> 0.0096225463 | I11: ='GHG detailed, results per kg'!G29 -> 0.027964304 | J11: ='GHG detailed, results per kg'!G30 -> 0.016555087 | L11: =(Production!$F$5*'Parameters, country spec'!$F$52*'EFP per kg feed'!F84+(Production!$F$6+Production!$F$7)*'Parameters, country spec'!$F$53*'EFP per kg feed'!F85)/Production!$F$23 -> 19.821785 | M11: =(Production!$F$5*'Parameters, country spec'!$F$52*'EFP per kg feed'!G84+(Production!$F$6+Production!$F$7)*'Parameters, country spec'!$F$53*'EFP per kg feed'!G85-Excreted_N_after_losses_IT*Manure_repl_factor_IT)/Production!$F$23 -> 0.25546919 | N11: =(Production!$F$5*'Parameters, country spec'!$F$52*'EFP per kg feed'!H84+(Production!$F$6+Production!$F$7)*'Parameters, country spec'!$F$53*'EFP per kg feed'!H85)/Production!$F$23 -> 0.023006827 | O11: =(Production!$F$5*'Parameters, country spec'!$F$52*'EFP per kg feed'!I84+(Production!$F$6+Production!$F$7)*'Parameters, country spec'!$F$53*'EFP per kg feed'!I85)/Production!$F$23 -> 0.073460273 | P11: =(Production!$F$5*'Parameters, country spec'!$F$52*'EFP per kg feed'!J84+(Production!$F$6+Production!$F$7)*'Parameters, country spec'!$F$53*'EFP per kg feed'!J85)/Production!$F$23 -> 1.196096 | Q11: =(Production!$F$5*'Parameters, country spec'!$F$52*'EFP per kg feed'!K84+(Production!$F$6+Production!$F$7)*'Parameters, country spec'!$F$53*'EFP per kg feed'!K85)/Production!$F$23 -> 8.6899546e-10 | R11: =(Production!$F$5*'Parameters, country spec'!$F$52*'EFP per kg feed'!L84+(Production!$F$6+Production!$F$7)*'Parameters, country spec'!$F$53*'EFP per kg feed'!L85+Manure!K156)/Production!$F$23 -> 0.18032777 | T11: 97.593059 | U11: 3113.7036
A12: 21114 | B12: Rabbit meat | C12: Red meat | D12: Netherlands | E12: NL | F12: ='GHG detailed, results per kg'!G36 -> 10.264243 | G12: ='GHG detailed, results per kg'!G32 -> 3.6744386 | H12: ='GHG detailed, results per kg'!G33 -> 0.0071085321 | I12: ='GHG detailed, results per kg'!G34 -> 0.027999577 | J12: ='GHG detailed, results per kg'!G35 -> 0.020593339 | L12: =(Production!$G$5*'Parameters, country spec'!$G$52*'EFP per kg feed'!F100+(Production!$G$6+Production!$G$7)*'Parameters, country spec'!$G$53*'EFP per kg feed'!F101)/Production!$G$23 -> 15.90749 | M12: =(Production!$G$5*'Parameters, country spec'!$G$52*'EFP per kg feed'!G100+(Production!$G$6+Production!$G$7)*'Parameters, country spec'!$G$53*'EFP per kg feed'!G101-Excreted_N_after_losses_NL*Manure_repl_factor_NL)/Production!$G$23 -> 0.27482316 | N12: =(Production!$G$5*'Parameters, country spec'!$G$52*'EFP per kg feed'!H100+(Production!$G$6+Production!$G$7)*'Parameters, country spec'!$G$53*'EFP per kg feed'!H101)/Production!$G$23 -> 0.019416007 | O12: =(Production!$G$5*'Parameters, country spec'!$G$52*'EFP per kg feed'!I100+(Production!$G$6+Production!$G$7)*'Parameters, country spec'!$G$53*'EFP per kg feed'!I101)/Production!$G$23 -> 0.057456983 | P12: =(Production!$G$5*'Parameters, country spec'!$G$52*'EFP per kg feed'!J100+(Production!$G$6+Production!$G$7)*'Parameters, country spec'!$G$53*'EFP per kg feed'!J101)/Production!$G$23 -> 1.9808828 | Q12: =(Production!$G$5*'Parameters, country spec'!$G$52*'EFP per kg feed'!K100+(Production!$G$6+Production!$G$7)*'Parameters, country spec'!$G$53*'EFP per kg feed'!K101)/Production!$G$23 -> 2.0876014e-10 | R12: =(Production!$G$5*'Parameters, country spec'!$G$52*'EFP per kg feed'!L100+(Production!$G$6+Production!$G$7)*'Parameters, country spec'!$G$53*'EFP per kg feed'!L101+Manure!M156)/Production!$G$23 -> 0.18387731 | T12: 101.88378 | U12: 640.80058
A13: 21114 | B13: Rabbit meat | C13: Red meat | D13: Poland | E13: PL | F13: ='GHG detailed, results per kg'!G41 -> 8.8851138 | G13: ='GHG detailed, results per kg'!G37 -> 3.4984234 | H13: ='GHG detailed, results per kg'!G38 -> 0.0044924811 | I13: ='GHG detailed, results per kg'!G39 -> 0.025096163 | J13: ='GHG detailed, results per kg'!G40 -> 0.01675904 | L13: =(Production!$H$5*'Parameters, country spec'!$H$52*'EFP per kg feed'!F116+(Production!$H$6+Production!$H$7)*'Parameters, country spec'!$H$53*'EFP per kg feed'!F117)/Production!$H$23 -> 19.383332 | M13: =(Production!$H$5*'Parameters, country spec'!$H$52*'EFP per kg feed'!G116+(Production!$H$6+Production!$H$7)*'Parameters, country spec'!$H$53*'EFP per kg feed'!G117-Excreted_N_after_losses_PL*Manure_repl_factor_PL)/Production!$H$23 -> 0.23231555 | N13: =(Production!$H$5*'Parameters, country spec'!$H$52*'EFP per kg feed'!H116+(Production!$H$6+Production!$H$7)*'Parameters, country spec'!$H$53*'EFP per kg feed'!H117)/Production!$H$23 -> 0.020686904 | O13: =(Production!$H$5*'Parameters, country spec'!$H$52*'EFP per kg feed'!I116+(Production!$H$6+Production!$H$7)*'Parameters, country spec'!$H$53*'EFP per kg feed'!I117)/Production!$H$23 -> 0.013280843 | P13: =(Production!$H$5*'Parameters, country spec'!$H$52*'EFP per kg feed'!J116+(Production!$H$6+Production!$H$7)*'Parameters, country spec'!$H$53*'EFP per kg feed'!J117)/Production!$H$23 -> 1.7542435 | Q13: =(Production!$H$5*'Parameters, country spec'!$H$52*'EFP per kg feed'!K116+(Production!$H$6+Production!$H$7)*'Parameters, country spec'!$H$53*'EFP per kg feed'!K117)/Production!$H$23 -> 1.8800247e-10 | R13: =(Production!$H$5*'Parameters, country spec'!$H$52*'EFP per kg feed'!L116+(Production!$H$6+Production!$H$7)*'Parameters, country spec'!$H$53*'EFP per kg feed'!L117+Manure!O156)/Production!$H$23 -> 0.17880685 | T13: 101.6985 | U13: 4014.1836
A14: 21114 | B14: Rabbit meat | C14: Red meat | D14: Spain | E14: ES | F14: ='GHG detailed, results per kg'!G46 -> 8.8440563 | G14: ='GHG detailed, results per kg'!G42 -> 2.7795669 | H14: ='GHG detailed, results per kg'!G43 -> 0.0061204156 | I14: ='GHG detailed, results per kg'!G44 -> 0.03779962 | J14: ='GHG detailed, results per kg'!G45 -> 0.017807734 | L14: =(Production!$I$5*'Parameters, country spec'!$I$52*'EFP per kg feed'!F132+(Production!$I$6+Production!$I$7)*'Parameters, country spec'!$I$53*'EFP per kg feed'!F133)/Production!$I$23 -> 23.437522 | M14: =(Production!$I$5*'Parameters, country spec'!$I$52*'EFP per kg feed'!G132+(Production!$I$6+Production!$I$7)*'Parameters, country spec'!$I$53*'EFP per kg feed'!G133-Excreted_N_after_losses_ES*Manure_repl_factor_ES)/Production!$I$23 -> 0.26168195 | N14: =(Production!$I$5*'Parameters, country spec'!$I$52*'EFP per kg feed'!H132+(Production!$I$6+Production!$I$7)*'Parameters, country spec'!$I$53*'EFP per kg feed'!H133)/Production!$I$23 -> 0.023475304 | O14: =(Production!$I$5*'Parameters, country spec'!$I$52*'EFP per kg feed'!I132+(Production!$I$6+Production!$I$7)*'Parameters, country spec'!$I$53*'EFP per kg feed'!I133)/Production!$I$23 -> 0.33808759 | P14: =(Production!$I$5*'Parameters, country spec'!$I$52*'EFP per kg feed'!J132+(Production!$I$6+Production!$I$7)*'Parameters, country spec'!$I$53*'EFP per kg feed'!J133)/Production!$I$23 -> 1.5290634 | Q14: =(Production!$I$5*'Parameters, country spec'!$I$52*'EFP per kg feed'!K132+(Production!$I$6+Production!$I$7)*'Parameters, country spec'!$I$53*'EFP per kg feed'!K133)/Production!$I$23 -> 1.2778619e-09 | R14: =(Production!$I$5*'Parameters, country spec'!$I$52*'EFP per kg feed'!L132+(Production!$I$6+Production!$I$7)*'Parameters, country spec'!$I$53*'EFP per kg feed'!L133+Manure!Q156)/Production!$I$23 -> 0.21020262 | T14: 121.2559 | U14: 2076.2107
A15: 21114 | B15: Rabbit meat | C15: Red meat | D15: Sweden | E15: SE | F15: ='GHG detailed, results per kg'!G51 -> 7.9041335 | G15: ='GHG detailed, results per kg'!G47 -> 2.8587919 | H15: ='GHG detailed, results per kg'!G48 -> 0.0061866075 | I15: ='GHG detailed, results per kg'!G49 -> 0.033947813 | J15: ='GHG detailed, results per kg'!G50 -> 0.014448314 | L15: =(Production!$J$5*'Parameters, country spec'!$J$52*'EFP per kg feed'!F148+(Production!$J$6+Production!$J$7)*'Parameters, country spec'!$J$53*'EFP per kg feed'!F149)/Production!$J$23 -> 22.09519 | M15: =(Production!$J$5*'Parameters, country spec'!$J$52*'EFP per kg feed'!G148+(Production!$J$6+Production!$J$7)*'Parameters, country spec'!$J$53*'EFP per kg feed'!G149-Excreted_N_after_losses_SE*Manure_repl_factor_SE)/Production!$J$23 -> 0.27904073 | N15: =(Production!$J$5*'Parameters, country spec'!$J$52*'EFP per kg feed'!H148+(Production!$J$6+Production!$J$7)*'Parameters, country spec'!$J$53*'EFP per kg feed'!H149)/Production!$J$23 -> 0.020585372 | O15: =(Production!$J$5*'Parameters, country spec'!$J$52*'EFP per kg feed'!I148+(Production!$J$6+Production!$J$7)*'Parameters, country spec'!$J$53*'EFP per kg feed'!I149)/Production!$J$23 -> 0.014250394 | P15: =(Production!$J$5*'Parameters, country spec'!$J$52*'EFP per kg feed'!J148+(Production!$J$6+Production!$J$7)*'Parameters, country spec'!$J$53*'EFP per kg feed'!J149)/Production!$J$23 -> 1.3989178 | Q15: =(Production!$J$5*'Parameters, country spec'!$J$52*'EFP per kg feed'!K148+(Production!$J$6+Production!$J$7)*'Parameters, country spec'!$J$53*'EFP per kg feed'!K149)/Production!$J$23 -> 2.080784e-10 | R15: =(Production!$J$5*'Parameters, country spec'!$J$52*'EFP per kg feed'!L148+(Production!$J$6+Production!$J$7)*'Parameters, country spec'!$J$53*'EFP per kg feed'!L149+Manure!Q156)/Production!$J$23 -> 0.22138482 | T15: 41.600193 | U15: 251.14598

Sheet GHG detailed, results per kg
K1: * Calculated as percentage of direct emissions due to assumption due to data limitations regarding nitrogen leaching and volatilization from soils in different regions.
A2: GHG emissions (per kg of bonefree meat)
S4: Animals | W4: Stables | X4: Slaughter | Z4: Control
A5: Animal products | G5: Sum | H5: Inputs | J5: Soil emissions | L5: Energy use | P5: Land use change | Q5: Feed processing | R5: Transports | AA5: Dairy cows
A6: FoodEx code | B6: FoodEx name | C6: Food Ex category (L1) | D6: Country | E6: Country code | F6: Gas | G6: GHG | H6: Production of mineral fertilizer | I6: Production of capital goods | J6: Direct emissions | K6: Indirect emissions* | L6: Diesel use field mach | M6: Energy use in greenhouses | N6: Energy use for irrigation | O6: Energy use for post-harvest proc | P6: LUC emissions | Q6: Feed processing | R6: Feed transports | S6: Enteric fermentation | T6: Manure management - tot | U6: Manure management - direct | V6: Manure management - indirect | W6: Energy use in stables | X6: Energy use for slaughter | Z6: Total feed, excl LUC | AA6: Feed mix emissions, kg CO2E per kg feed, excl. adjustement manure
A7: A01RQ | B7: Rabbit meat | C7: Meat and meat products | D7: France | E7: FR | F7: CO2 | G7: =SUM(H7:X7) -> 2.3456337 | H7: =(Production!$B$5*'Parameters, country spec'!$B$52*'CO2 per kg feed'!G20+(Production!$B$6+Production!$B$7)*'Parameters, country spec'!$B$53*'CO2 per kg feed'!G21)/Production!B23 -> 0.63927309 | I7: =(Production!$B$5*'Parameters, country spec'!$B$52*'CO2 per kg feed'!H20+(Production!$B$6+Production!$B$7)*'Parameters, country spec'!$B$53*'CO2 per kg feed'!H21)/Production!B23 -> 0.25387018 | L7: =(Production!$B$5*'Parameters, country spec'!$B$52*'CO2 per kg feed'!K20+(Production!$B$6+Production!$B$7)*'Parameters, country spec'!$B$53*'CO2 per kg feed'!K21)/Production!B23 -> 0.27471693 | N7: =(Production!$B$5*'Parameters, country spec'!$B$52*'CO2 per kg feed'!M20+(Production!$B$6+Production!$B$7)*'Parameters, country spec'!$B$53*'CO2 per kg feed'!M21)/Production!B23 -> 0.0003445696 | O7: =(Production!$B$5*'Parameters, country spec'!$B$52*'CO2 per kg feed'!N20+(Production!$B$6+Production!$B$7)*'Parameters, country spec'!$B$53*'CO2 per kg feed'!N21)/Production!B23 -> 0.21688222 | P7: =(Production!$B$5*'Parameters, country spec'!$B$52*'CO2 per kg feed'!O20+(Production!$B$6+Production!$B$7)*'Parameters, country spec'!$B$53*'CO2 per kg feed'!O21)/Production!B23 -> 0.27502473 | Q7: =(Production!$B$5*'Parameters, country spec'!$B$52*'CO2 per kg feed'!P20+(Production!$B$6+Production!$B$7)*'Parameters, country spec'!$B$53*'CO2 per kg feed'!P21)/Production!B23 -> 0.34416916 | R7: =(Production!$B$5*'Parameters, country spec'!$B$52*'CO2 per kg feed'!Q20+(Production!$B$6+Production!$B$7)*'Parameters, country spec'!$B$53*'CO2 per kg feed'!Q21)/Production!B23 -> 0.23734423 | W7: ='Parameters, country spec'!B61*EF_el_CO2_FR -> 0.063363221 | X7: =Energy_slaughter_el_FR*EF_el_CO2_FR+Energy_slaughter_oil_FR*EF_oil_CO2 -> 0.040645398
A8: A01RQ | B8: Rabbit meat | C8: Meat and meat products | D8: France | E8: FR | F8: CH4, fossil | G8: =SUM(H8:X8) -> 0.0055894578 | H8: =(Production!$B$5*'Parameters, country spec'!$B$52*'CH4 per kg feed'!G20+(Production!$B$6+Production!$B$7)*'Parameters, country spec'!$B$53*'CH4 per kg feed'!G21)/Production!B23 -> 0.0012082375 | I8: =(Production!$B$5*'Parameters, country spec'!$B$52*'CH4 per kg feed'!H20+(Production!$B$6+Production!$B$7)*'Parameters, country spec'!$B$53*'CH4 per kg feed'!H21)/Production!B23 -> 0.00091648438 | L8: =(Production!$B$5*'Parameters, country spec'!$B$52*'CH4 per kg feed'!K20+(Production!$B$6+Production!$B$7)*'Parameters, country spec'!$B$53*'CH4 per kg feed'!K21)/Production!B23 -> 0.00012421389 | N8: =(Production!$B$5*'Parameters, country spec'!$B$52*'CH4 per kg feed'!M20+(Production!$B$6+Production!$B$7)*'Parameters, country spec'!$B$53*'CH4 per kg feed'!M21)/Production!B23 -> 5.2074278e-06 | O8: =(Production!$B$5*'Parameters, country spec'!$B$52*'CH4 per kg feed'!N20+(Production!$B$6+Production!$B$7)*'Parameters, country spec'!$B$53*'CH4 per kg feed'!N21)/Production!B23 -> 0.00011975109 | P8: =(Production!$B$5*'Parameters, country spec'!$B$52*'CH4 per kg feed'!O20+(Production!$B$6+Production!$B$7)*'Parameters, country spec'!$B$53*'CH4 per kg feed'!O21)/Production!B23 -> 0 | Q8: =(Production!$B$5*'Parameters, country spec'!$B$52*'CH4 per kg feed'!P20+(Production!$B$6+Production!$B$7)*'Parameters, country spec'!$B$53*'CH4 per kg feed'!P21)/Production!B23 -> 0.0027018255 | R8: =(Production!$B$5*'Parameters, country spec'!$B$52*'CH4 per kg feed'!Q20+(Production!$B$6+Production!$B$7)*'Parameters, country spec'!$B$53*'CH4 per kg feed'!Q21)/Production!B23 -> 0.00020705889 | W8: ='Parameters, country spec'!B61*EF_el_CH4_FR -> 0.00019644552 | X8: =Energy_slaughter_el_FR*EF_el_CH4_FR+Energy_slaughter_oil_FR*EF_oil_CH4 -> 0.00011023369
A9: A01RQ | B9: Rabbit meat | C9: Meat and meat products | D9: France | E9: FR | F9: CH4, biogenic | G9: =SUM(H9:T9) -> 0.016603948 | S9: =(Production!B5*'Parameters, country spec'!B57+(Production!B6+Production!B7)*'Parameters, country spec'!B57)/Production!B23 -> 0.00038512555 | T9: =SUM(U9:V9) -> 0.016218823 | U9: =Manure!C35 -> 0.016218823
A10: A01RQ | B10: Rabbit meat | C10: Meat and meat products | D10: France | E10: FR | F10: N2O | G10: =SUM(H10:T10)+W10+X10 -> 0.014859386 | H10: =(Production!$B$5*'Parameters, country spec'!$B$52*'N2O per kg feed'!G20+(Production!$B$6+Production!$B$7)*'Parameters, country spec'!$B$53*'N2O per kg feed'!G21)/Production!B23 -> 0.0014221033 | I10: =(Production!$B$5*'Parameters, country spec'!$B$52*'N2O per kg feed'!H20+(Production!$B$6+Production!$B$7)*'Parameters, country spec'!$B$53*'N2O per kg feed'!H21)/Production!B23 -> 9.8781097e-06 | J10: =(Production!$B$5*'Parameters, country spec'!$B$52*'N2O per kg feed'!I20+(Production!$B$6+Production!$B$7)*'Parameters, country spec'!$B$53*'N2O per kg feed'!I21+Manure!C150)/Production!B23 -> 0.0098487636 | K10: =J10*EF_indirect_N2O_FR -> 0.00098487636 | L10: =(Production!$B$5*'Parameters, country spec'!$B$52*'N2O per kg feed'!K20+(Production!$B$6+Production!$B$7)*'Parameters, country spec'!$B$53*'N2O per kg feed'!K21)/Production!B23 -> 7.669112e-06 | N10: =(Production!$B$5*'Parameters, country spec'!$B$52*'N2O per kg feed'!M20+(Production!$B$6+Production!$B$7)*'Parameters, country spec'!$B$53*'N2O per kg feed'!M21)/Production!B23 -> 6.4284479e-08 | O10: =(Production!$B$5*'Parameters, country spec'!$B$52*'N2O per kg feed'!N20+(Production!$B$6+Production!$B$7)*'Parameters, country spec'!$B$53*'N2O per kg feed'!N21)/Production!B23 -> 8.1190634e-06 | P10: =(Production!$B$5*'Parameters, country spec'!$B$52*'N2O per kg feed'!O20+(Production!$B$6+Production!$B$7)*'Parameters, country spec'!$B$53*'N2O per kg feed'!O21)/Production!B23 -> 0 | Q10: =(Production!$B$5*'Parameters, country spec'!$B$52*'N2O per kg feed'!P20+(Production!$B$6+Production!$B$7)*'Parameters, country spec'!$B$53*'N2O per kg feed'!P21)/Production!B23 -> 0.00022970076 | R10: =(Production!$B$5*'Parameters, country spec'!$B$52*'N2O per kg feed'!Q20+(Production!$B$6+Production!$B$7)*'Parameters, country spec'!$B$53*'N2O per kg feed'!Q21)/Production!B23 -> 8.7031844e-06 | T10: =SUM(U10:V10) -> 0.0023300985 | U10: =Manure!$C$92*44/28 -> 5.6054857e-05 | V10: =Manure!$C$157*17/14*Manure!$B$120 -> 0.0022740436 | W10: ='Parameters, country spec'!B61*EF_el_N2O_FR -> 5.9385409e-06 | X10: =Energy_slaughter_el_FR*EF_el_N2O_FR+Energy_slaughter_oil_FR*EF_oil_N2O -> 3.4711448e-06
A11: A01RQ | B11: Rabbit meat | C11: Meat and meat products | D11: France | E11: FR | F11: CO2e | G11: =SUM(H11:X11) -> 7.0171185 | H11: =SUMPRODUCT(H7:H10,'Parameters, general'!$B$23:$B$26) -> 1.0635128 | I11: =SUMPRODUCT(I7:I10,'Parameters, general'!$B$23:$B$26) -> 0.28387813 | J11: =SUMPRODUCT(J7:J10,'Parameters, general'!$B$23:$B$26) -> 2.6887125 | K11: =SUMPRODUCT(K7:K10,'Parameters, general'!$B$23:$B$26) -> 0.26887125 | L11: =SUMPRODUCT(L7:L10,'Parameters, general'!$B$23:$B$26) -> 0.28051217 | M11: =SUMPRODUCT(M7:M10,'Parameters, general'!$B$23:$B$26) -> 0 | N11: =SUMPRODUCT(N7:N10,'Parameters, general'!$B$23:$B$26) -> 0.00051730061 | O11: =SUMPRODUCT(O7:O10,'Parameters, general'!$B$23:$B$26) -> 0.22266731 | ... T11: =SUMPRODUCT(T7:T10,'Parameters, general'!$B$23:$B$26) -> 1.0740251 | W11: =SUMPRODUCT(W7:W10,'Parameters, general'!$B$23:$B$26) -> 0.07083852 | X11: =SUMPRODUCT(X7:X10,'Parameters, general'!$B$23:$B$26) -> 0.044877985 | Z11: =SUM(H11:R11) -> 5.8169785 | AA11: ='CO2 per kg feed'!F20+'CH4 per kg feed'!F20*CF_GWP_CH4_fossil+'N2O per kg feed'!F20*CF_GWP_N2O -> 0.43484316
A12: A01RQ | B12: Rabbit meat | C12: Meat and meat products | D12: Germany | E12: DE | F12: CO2 | G12: =SUM(H12:X12) -> 3.4261773 | H12: =(Production!$C$5*'Parameters, country spec'!$C$52*'CO2 per kg feed'!G36+(Production!$C$6+Production!$C$7)*'Parameters, country spec'!$C$53*'CO2 per kg feed'!G37)/Production!C23 -> 0.63533979 | I12: =(Production!$C$5*'Parameters, country spec'!$C$52*'CO2 per kg feed'!H36+(Production!$C$6+Production!$C$7)*'Parameters, country spec'!$C$53*'CO2 per kg feed'!H37)/Production!C23 -> 0.25042553 | L12: =(Production!$C$5*'Parameters, country spec'!$C$52*'CO2 per kg feed'!K36+(Production!$C$6+Production!$C$7)*'Parameters, country spec'!$C$53*'CO2 per kg feed'!K37)/Production!C23 -> 0.27300672 | N12: =(Production!$C$5*'Parameters, country spec'!$C$52*'CO2 per kg feed'!M36+(Production!$C$6+Production!$C$7)*'Parameters, country spec'!$C$53*'CO2 per kg feed'!M37)/Production!C23 -> 0.00031828528 | O12: =(Production!$C$5*'Parameters, country spec'!$C$52*'CO2 per kg feed'!N36+(Production!$C$6+Production!$C$7)*'Parameters, country spec'!$C$53*'CO2 per kg feed'!N37)/Production!C23 -> 0.2456991 | P12: =(Production!$C$5*'Parameters, country spec'!$C$52*'CO2 per kg feed'!O36+(Production!$C$6+Production!$C$7)*'Parameters, country spec'!$C$53*'CO2 per kg feed'!O37)/Production!C23 -> 0.2695154 | Q12: =(Production!$C$5*'Parameters, country spec'!$C$52*'CO2 per kg feed'!P36+(Production!$C$6+Production!$C$7)*'Parameters, country spec'!$C$53*'CO2 per kg feed'!P37)/Production!C23 -> 0.98071415 | R12: =(Production!$C$5*'Parameters, country spec'!$C$52*'CO2 per kg feed'!Q36+(Production!$C$6+Production!$C$7)*'Parameters, country spec'!$C$53*'CO2 per kg feed'!Q37)/Production!C23 -> 0.24281788 | W12: ='Parameters, country spec'!C61*EF_el_CO2_DE -> 0.33713879 | X12: =Energy_slaughter_el_DE*EF_el_CO2_DE+Energy_slaughter_oil_DE*EF_oil_CO2 -> 0.19120168
A13: A01RQ | B13: Rabbit meat | C13: Meat and meat products | D13: Germany | E13: DE | F13: CH4, fossil | G13: =SUM(H13:X13) -> 0.0073404684 | H13: =(Production!$C$5*'Parameters, country spec'!$C$52*'CH4 per kg feed'!G36+(Production!$C$6+Production!$C$7)*'Parameters, country spec'!$C$53*'CH4 per kg feed'!G37)/Production!C23 -> 0.0011997383 | I13: =(Production!$C$5*'Parameters, country spec'!$C$52*'CH4 per kg feed'!H36+(Production!$C$6+Production!$C$7)*'Parameters, country spec'!$C$53*'CH4 per kg feed'!H37)/Production!C23 -> 0.000904058 | L13: =(Production!$C$5*'Parameters, country spec'!$C$52*'CH4 per kg feed'!K36+(Production!$C$6+Production!$C$7)*'Parameters, country spec'!$C$53*'CH4 per kg feed'!K37)/Production!C23 -> 0.00012917718 | N13: =(Production!$C$5*'Parameters, country spec'!$C$52*'CH4 per kg feed'!M36+(Production!$C$6+Production!$C$7)*'Parameters, country spec'!$C$53*'CH4 per kg feed'!M37)/Production!C23 -> 1.64618e-06 | O13: =(Production!$C$5*'Parameters, country spec'!$C$52*'CH4 per kg feed'!N36+(Production!$C$6+Production!$C$7)*'Parameters, country spec'!$C$53*'CH4 per kg feed'!N37)/Production!C23 -> 0.00017475781 | P13: =(Production!$C$5*'Parameters, country spec'!$C$52*'CH4 per kg feed'!O36+(Production!$C$6+Production!$C$7)*'Parameters, country spec'!$C$53*'CH4 per kg feed'!O37)/Production!C23 -> 0 | Q13: =(Production!$C$5*'Parameters, country spec'!$C$52*'CH4 per kg feed'!P36+(Production!$C$6+Production!$C$7)*'Parameters, country spec'!$C$53*'CH4 per kg feed'!P37)/Production!C23 -> 0.0037173075 | R13: =(Production!$C$5*'Parameters, country spec'!$C$52*'CH4 per kg feed'!Q36+(Production!$C$6+Production!$C$7)*'Parameters, country spec'!$C$53*'CH4 per kg feed'!Q37)/Production!C23 -> 0.00021201845 | W13: ='Parameters, country spec'!C61*EF_el_CH4_DE -> 0.00064490945 | X13: =Energy_slaughter_el_DE*EF_el_CH4_DE+Energy_slaughter_oil_DE*EF_oil_CH4 -> 0.00035685563
A14: A01RQ | B14: Rabbit meat | C14: Meat and meat products | D14: Germany | E14: DE | F14: CH4, biogenic | G14: =SUM(H14:T14) -> 0.027964304 | S14: =(Production!C5*'Parameters, country spec'!C57+(Production!C6+Production!C7)*'Parameters, country spec'!C57)/Production!C23 -> 0.0003281188 | T14: =SUM(U14:V14) -> 0.027636186 | U14: =Manure!E35 -> 0.027636186
A15: A01RQ | B15: Rabbit meat | C15: Meat and meat products | D15: Germany | E15: DE | F15: N2O | G15: =SUM(H15:T15)+W15+X15 -> 0.014117012 | H15: =(Production!$C$5*'Parameters, country spec'!$C$52*'N2O per kg feed'!G36+(Production!$C$6+Production!$C$7)*'Parameters, country spec'!$C$53*'N2O per kg feed'!G37)/Production!C23 -> 0.0014131227 | I15: =(Production!$C$5*'Parameters, country spec'!$C$52*'N2O per kg feed'!H36+(Production!$C$6+Production!$C$7)*'Parameters, country spec'!$C$53*'N2O per kg feed'!H37)/Production!C23 -> 9.7438985e-06 | J15: =(Production!$C$5*'Parameters, country spec'!$C$52*'N2O per kg feed'!I36+(Production!$C$6+Production!$C$7)*'Parameters, country spec'!$C$53*'N2O per kg feed'!I37++Manure!E150)/Production!C23 -> 0.0093282071 | K15: =J15*EF_indirect_N2O_DE -> 0.00093282071 | L15: =(Production!$C$5*'Parameters, country spec'!$C$52*'N2O per kg feed'!K36+(Production!$C$6+Production!$C$7)*'Parameters, country spec'!$C$53*'N2O per kg feed'!K37)/Production!C23 -> 7.627923e-06 | N15: =(Production!$C$5*'Parameters, country spec'!$C$52*'N2O per kg feed'!M36+(Production!$C$6+Production!$C$7)*'Parameters, country spec'!$C$53*'N2O per kg feed'!M37)/Production!C23 -> 2.0260414e-08 | O15: =(Production!$C$5*'Parameters, country spec'!$C$52*'N2O per kg feed'!N36+(Production!$C$6+Production!$C$7)*'Parameters, country spec'!$C$53*'N2O per kg feed'!N37)/Production!C23 -> 9.1433612e-06 | P15: =(Production!$C$5*'Parameters, country spec'!$C$52*'N2O per kg feed'!O36+(Production!$C$6+Production!$C$7)*'Parameters, country spec'!$C$53*'N2O per kg feed'!O37)/Production!C23 -> 0 | Q15: =(Production!$C$5*'Parameters, country spec'!$C$52*'N2O per kg feed'!P36+(Production!$C$6+Production!$C$7)*'Parameters, country spec'!$C$53*'N2O per kg feed'!P37)/Production!C23 -> 0.00024812089 | R15: =(Production!$C$5*'Parameters, country spec'!$C$52*'N2O per kg feed'!Q36+(Production!$C$6+Production!$C$7)*'Parameters, country spec'!$C$53*'N2O per kg feed'!Q37)/Production!C23 -> 9.1283283e-06 | T15: =SUM(U15:V15) -> 0.0021354681 | U15: =Manure!$E$92*44/28 -> 5.1372662e-05 | V15: =Manure!$E$157*17/14*Manure!$D$120 -> 0.0020840955 | W15: ='Parameters, country spec'!C61*EF_el_N2O_DE -> 1.5099488e-05 | X15: =Energy_slaughter_el_DE*EF_el_N2O_DE+Energy_slaughter_oil_DE*EF_oil_N2O -> 8.5089873e-06
A16: A01RQ | B16: Rabbit meat | C16: Meat and meat products | D16: Germany | E16: DE | F16: CO2e | G16: =SUM(H16:X16) -> 8.2539037 | H16: =SUMPRODUCT(H12:H15,'Parameters, general'!$B$23:$B$26) -> 1.0568745 | I16: =SUMPRODUCT(I12:I15,'Parameters, general'!$B$23:$B$26) -> 0.28002654 | J16: =SUMPRODUCT(J12:J15,'Parameters, general'!$B$23:$B$26) -> 2.5466005 | K16: =SUMPRODUCT(K12:K15,'Parameters, general'!$B$23:$B$26) -> 0.25466005 | L16: =SUMPRODUCT(L12:L15,'Parameters, general'!$B$23:$B$26) -> 0.27893862 | M16: =SUMPRODUCT(M12:M15,'Parameters, general'!$B$23:$B$26) -> 0 | N16: =SUMPRODUCT(N12:N15,'Parameters, general'!$B$23:$B$26) -> 0.00037287254 | O16: =SUMPRODUCT(O12:O15,'Parameters, general'!$B$23:$B$26) -> 0.25340302 | ... T16: =SUMPRODUCT(T12:T15,'Parameters, general'!$B$23:$B$26) -> 1.3291598 | W16: =SUMPRODUCT(W12:W15,'Parameters, general'!$B$23:$B$26) -> 0.36047925 | X16: =SUMPRODUCT(X12:X15,'Parameters, general'!$B$23:$B$26) -> 0.20415893 | Z16: =SUM(H16:R16) -> 6.3512465 | AA16: ='CO2 per kg feed'!F36+'CH4 per kg feed'!F36*CF_GWP_CH4_fossil+'N2O per kg feed'!F36*CF_GWP_N2O -> 0.48937945
A17: A01RQ | B17: Rabbit meat | C17: Meat and meat products | D17: Greece | E17: GR | F17: CO2 | G17: =SUM(H17:X17) -> 4.2036425 | H17: =(Production!$D$5*'Parameters, country spec'!$D$52*'CO2 per kg feed'!G52+(Production!$D$6+Production!$D$7)*'Parameters, country spec'!$D$53*'CO2 per kg feed'!G53)/Production!D23 -> 0.60895208 | I17: =(Production!$D$5*'Parameters, country spec'!$D$52*'CO2 per kg feed'!H52+(Production!$D$6+Production!$D$7)*'Parameters, country spec'!$D$53*'CO2 per kg feed'!H53)/Production!D23 -> 0.25045053 | L17: =(Production!$D$5*'Parameters, country spec'!$D$52*'CO2 per kg feed'!K52+(Production!$D$6+Production!$D$7)*'Parameters, country spec'!$D$53*'CO2 per kg feed'!K53)/Production!D23 -> 0.51738875 | N17: =(Production!$D$5*'Parameters, country spec'!$D$52*'CO2 per kg feed'!M52+(Production!$D$6+Production!$D$7)*'Parameters, country spec'!$D$53*'CO2 per kg feed'!M53)/Production!D23 -> 0.0073320326 | O17: =(Production!$D$5*'Parameters, country spec'!$D$52*'CO2 per kg feed'!N52+(Production!$D$6+Production!$D$7)*'Parameters, country spec'!$D$53*'CO2 per kg feed'!N53)/Production!D23 -> 0.26407277 | P17: =(Production!$D$5*'Parameters, country spec'!$D$52*'CO2 per kg feed'!O52+(Production!$D$6+Production!$D$7)*'Parameters, country spec'!$D$53*'CO2 per kg feed'!O53)/Production!D23 -> 0.2695554 | Q17: =(Production!$D$5*'Parameters, country spec'!$D$52*'CO2 per kg feed'!P52+(Production!$D$6+Production!$D$7)*'Parameters, country spec'!$D$53*'CO2 per kg feed'!P53)/Production!D23 -> 1.2811834 | R17: =(Production!$D$5*'Parameters, country spec'!$D$52*'CO2 per kg feed'!Q52+(Production!$D$6+Production!$D$7)*'Parameters, country spec'!$D$53*'CO2 per kg feed'!Q53)/Production!D23 -> 0.27743171 | W17: ='Parameters, country spec'!D61*EF_el_CO2_GR -> 0.46549031 | X17: =Energy_slaughter_el_GR*EF_el_CO2_GR+Energy_slaughter_oil_GR*EF_oil_CO2 -> 0.26178551
A18: A01RQ | B18: Rabbit meat | C18: Meat and meat products | D18: Greece | E18: GR | F18: CH4, fossil | G18: =SUM(H18:X18) -> 0.0085784067 | H18: =(Production!$D$5*'Parameters, country spec'!$D$52*'CH4 per kg feed'!G52+(Production!$D$6+Production!$D$7)*'Parameters, country spec'!$D$53*'CH4 per kg feed'!G53)/Production!D23 -> 0.0011513669 | I18: =(Production!$D$5*'Parameters, country spec'!$D$52*'CH4 per kg feed'!H52+(Production!$D$6+Production!$D$7)*'Parameters, country spec'!$D$53*'CH4 per kg feed'!H53)/Production!D23 -> 0.00090414821 | L18: =(Production!$D$5*'Parameters, country spec'!$D$52*'CH4 per kg feed'!K52+(Production!$D$6+Production!$D$7)*'Parameters, country spec'!$D$53*'CH4 per kg feed'!K53)/Production!D23 -> 0.00024288501 | N18: =(Production!$D$5*'Parameters, country spec'!$D$52*'CH4 per kg feed'!M52+(Production!$D$6+Production!$D$7)*'Parameters, country spec'!$D$53*'CH4 per kg feed'!M53)/Production!D23 -> 2.1687265e-05 | O18: =(Production!$D$5*'Parameters, country spec'!$D$52*'CH4 per kg feed'!N52+(Production!$D$6+Production!$D$7)*'Parameters, country spec'!$D$53*'CH4 per kg feed'!N53)/Production!D23 -> 0.00021009424 | P18: =(Production!$D$5*'Parameters, country spec'!$D$52*'CH4 per kg feed'!O52+(Production!$D$6+Production!$D$7)*'Parameters, country spec'!$D$53*'CH4 per kg feed'!O53)/Production!D23 -> 0 | Q18: =(Production!$D$5*'Parameters, country spec'!$D$52*'CH4 per kg feed'!P52+(Production!$D$6+Production!$D$7)*'Parameters, country spec'!$D$53*'CH4 per kg feed'!P53)/Production!D23 -> 0.0043709632 | R18: =(Production!$D$5*'Parameters, country spec'!$D$52*'CH4 per kg feed'!Q52+(Production!$D$6+Production!$D$7)*'Parameters, country spec'!$D$53*'CH4 per kg feed'!Q53)/Production!D23 -> 0.00024282857 | W18: ='Parameters, country spec'!D61*EF_el_CH4_GR -> 0.00092406353 | X18: =Energy_slaughter_el_GR*EF_el_CH4_GR+Energy_slaughter_oil_GR*EF_oil_CH4 -> 0.00051036969
A19: A01RQ | B19: Rabbit meat | C19: Meat and meat products | D19: Greece | E19: GR | F19: CH4, biogenic | G19: =SUM(H19:T19) -> 0.0012544322 | S19: =(Production!D5*'Parameters, country spec'!D57+(Production!D6+Production!D7)*'Parameters, country spec'!D57)/Production!D23 -> 0.00032853267 | T19: =SUM(U19:V19) -> 0.0009258995 | U19: =Manure!G35 -> 0.0009258995
A20: A01RQ | B20: Rabbit meat | C20: Meat and meat products | D20: Greece | E20: GR | F20: N2O | G20: =SUM(H20:T20)+W20+X20 -> 0.016581211 | H20: =(Production!$D$5*'Parameters, country spec'!$D$52*'N2O per kg feed'!G52+(Production!$D$6+Production!$D$7)*'Parameters, country spec'!$D$53*'N2O per kg feed'!G53)/Production!D23 -> 0.0013551508 | I20: =(Production!$D$5*'Parameters, country spec'!$D$52*'N2O per kg feed'!H52+(Production!$D$6+Production!$D$7)*'Parameters, country spec'!$D$53*'N2O per kg feed'!H53)/Production!D23 -> 9.7448728e-06 | J20: =(Production!$D$5*'Parameters, country spec'!$D$52*'N2O per kg feed'!I52+(Production!$D$6+Production!$D$7)*'Parameters, country spec'!$D$53*'N2O per kg feed'!I53+Manure!G150)/Production!D23 -> 0.0093625176 | K20: =J20*EF_indirect_N2O_GR -> 0.00093625176 | L20: =(Production!$D$5*'Parameters, country spec'!$D$52*'N2O per kg feed'!K52+(Production!$D$6+Production!$D$7)*'Parameters, country spec'!$D$53*'N2O per kg feed'!K53)/Production!D23 -> 1.4194504e-05 | N20: =(Production!$D$5*'Parameters, country spec'!$D$52*'N2O per kg feed'!M52+(Production!$D$6+Production!$D$7)*'Parameters, country spec'!$D$53*'N2O per kg feed'!M53)/Production!D23 -> 2.6701162e-07 | O20: =(Production!$D$5*'Parameters, country spec'!$D$52*'N2O per kg feed'!N52+(Production!$D$6+Production!$D$7)*'Parameters, country spec'!$D$53*'N2O per kg feed'!N53)/Production!D23 -> 9.2819603e-06 | P20: =(Production!$D$5*'Parameters, country spec'!$D$52*'N2O per kg feed'!O52+(Production!$D$6+Production!$D$7)*'Parameters, country spec'!$D$53*'N2O per kg feed'!O53)/Production!D23 -> 0 | Q20: =(Production!$D$5*'Parameters, country spec'!$D$52*'N2O per kg feed'!P52+(Production!$D$6+Production!$D$7)*'Parameters, country spec'!$D$53*'N2O per kg feed'!P53)/Production!D23 -> 0.00025029554 | R20: =(Production!$D$5*'Parameters, country spec'!$D$52*'N2O per kg feed'!Q52+(Production!$D$6+Production!$D$7)*'Parameters, country spec'!$D$53*'N2O per kg feed'!Q53)/Production!D23 -> 1.1314073e-05 | T20: =SUM(U20:V20) -> 0.0046071598 | U20: =Manure!$G$92*44/28 -> 0.0025204355 | V20: =Manure!$G$157*17/14*Manure!$F$120 -> 0.0020867242 | W20: ='Parameters, country spec'!D61*EF_el_N2O_GR -> 1.6018713e-05 | X20: =Energy_slaughter_el_GR*EF_el_N2O_GR+Energy_slaughter_oil_GR*EF_oil_N2O -> 9.0144929e-06
A21: A01RQ | B21: Rabbit meat | C21: Meat and meat products | D21: Greece | E21: GR | F21: CO2e | G21: =SUM(H21:X21) -> 9.0198193 | H21: =SUMPRODUCT(H17:H20,'Parameters, general'!$B$23:$B$26) -> 1.013219 | I21: =SUMPRODUCT(I17:I20,'Parameters, general'!$B$23:$B$26) -> 0.2800545 | J21: =SUMPRODUCT(J17:J20,'Parameters, general'!$B$23:$B$26) -> 2.5559673 | K21: =SUMPRODUCT(K17:K20,'Parameters, general'!$B$23:$B$26) -> 0.25559673 | L21: =SUMPRODUCT(L17:L20,'Parameters, general'!$B$23:$B$26) -> 0.52850183 | M21: =SUMPRODUCT(M17:M20,'Parameters, general'!$B$23:$B$26) -> 0 | N21: =SUMPRODUCT(N17:N20,'Parameters, general'!$B$23:$B$26) -> 0.0080512073 | O21: =SUMPRODUCT(O17:O20,'Parameters, general'!$B$23:$B$26) -> 0.27286755 | ... T21: =SUMPRODUCT(T17:T20,'Parameters, general'!$B$23:$B$26) -> 1.2827539 | W21: =SUMPRODUCT(W17:W20,'Parameters, general'!$B$23:$B$26) -> 0.49740052 | X21: =SUMPRODUCT(X17:X20,'Parameters, general'!$B$23:$B$26) -> 0.27945549 | Z21: =SUM(H21:R21) -> 6.951339 | AA21: ='CO2 per kg feed'!F52+'CH4 per kg feed'!F52*CF_GWP_CH4_fossil+'N2O per kg feed'!F52*CF_GWP_N2O -> 0.50027097
A22: A01RQ | B22: Rabbit meat | C22: Meat and meat products | D22: Hungary | E22: HU | F22: CO2 | G22: =SUM(H22:X22) -> 3.3854858 | H22: =(Production!$E$5*'Parameters, country spec'!$E$52*'CO2 per kg feed'!G68+(Production!$E$6+Production!$E$7)*'Parameters, country spec'!$E$53*'CO2 per kg feed'!G69)/Production!E23 -> 0.59294522 | I22: =(Production!$E$5*'Parameters, country spec'!$E$52*'CO2 per kg feed'!H68+(Production!$E$6+Production!$E$7)*'Parameters, country spec'!$E$53*'CO2 per kg feed'!H69)/Production!E23 -> 0.25045053 | L22: =(Production!$E$5*'Parameters, country spec'!$E$52*'CO2 per kg feed'!K68+(Production!$E$6+Production!$E$7)*'Parameters, country spec'!$E$53*'CO2 per kg feed'!K69)/Production!E23 -> 0.3616237 | N22: =(Production!$E$5*'Parameters, country spec'!$E$52*'CO2 per kg feed'!M68+(Production!$E$6+Production!$E$7)*'Parameters, country spec'!$E$53*'CO2 per kg feed'!M69)/Production!E23 -> 0.0003346279 | O22: =(Production!$E$5*'Parameters, country spec'!$E$52*'CO2 per kg feed'!N68+(Production!$E$6+Production!$E$7)*'Parameters, country spec'!$E$53*'CO2 per kg feed'!N69)/Production!E23 -> 0.24572607 | P22: =(Production!$E$5*'Parameters, country spec'!$E$52*'CO2 per kg feed'!O68+(Production!$E$6+Production!$E$7)*'Parameters, country spec'!$E$53*'CO2 per kg feed'!O69)/Production!E23 -> 0.2695554 | Q22: =(Production!$E$5*'Parameters, country spec'!$E$52*'CO2 per kg feed'!P68+(Production!$E$6+Production!$E$7)*'Parameters, country spec'!$E$53*'CO2 per kg feed'!P69)/Production!E23 -> 0.93592491 | R22: =(Production!$E$5*'Parameters, country spec'!$E$52*'CO2 per kg feed'!Q68+(Production!$E$6+Production!$E$7)*'Parameters, country spec'!$E$53*'CO2 per kg feed'!Q69)/Production!E23 -> 0.2302928 | W22: ='Parameters, country spec'!E61*EF_el_CO2_HU -> 0.31797144 | X22: =Energy_slaughter_el_HU*EF_el_CO2_HU+Energy_slaughter_oil_HU*EF_oil_CO2 -> 0.18066106
A23: A01RQ | B23: Rabbit meat | C23: Meat and meat products | D23: Hungary | E23: HU | F23: CH4, fossil | G23: =SUM(H23:X23) -> 0.007930952 | H23: =(Production!$E$5*'Parameters, country spec'!$E$52*'CH4 per kg feed'!G68+(Production!$E$6+Production!$E$7)*'Parameters, country spec'!$E$53*'CH4 per kg feed'!G69)/Production!E23 -> 0.001122619 | I23: =(Production!$E$5*'Parameters, country spec'!$E$52*'CH4 per kg feed'!H68+(Production!$E$6+Production!$E$7)*'Parameters, country spec'!$E$53*'CH4 per kg feed'!H69)/Production!E23 -> 0.00090414821 | L23: =(Production!$E$5*'Parameters, country spec'!$E$52*'CH4 per kg feed'!K68+(Production!$E$6+Production!$E$7)*'Parameters, country spec'!$E$53*'CH4 per kg feed'!K69)/Production!E23 -> 0.00017222351 | N23: =(Production!$E$5*'Parameters, country spec'!$E$52*'CH4 per kg feed'!M68+(Production!$E$6+Production!$E$7)*'Parameters, country spec'!$E$53*'CH4 per kg feed'!M69)/Production!E23 -> 2.8489815e-06 | O23: =(Production!$E$5*'Parameters, country spec'!$E$52*'CH4 per kg feed'!N68+(Production!$E$6+Production!$E$7)*'Parameters, country spec'!$E$53*'CH4 per kg feed'!N69)/Production!E23 -> 0.00019449954 | P23: =(Production!$E$5*'Parameters, country spec'!$E$52*'CH4 per kg feed'!O68+(Production!$E$6+Production!$E$7)*'Parameters, country spec'!$E$53*'CH4 per kg feed'!O69)/Production!E23 -> 0 | Q23: =(Production!$E$5*'Parameters, country spec'!$E$52*'CH4 per kg feed'!P68+(Production!$E$6+Production!$E$7)*'Parameters, country spec'!$E$53*'CH4 per kg feed'!P69)/Production!E23 -> 0.0040872365 | R23: =(Production!$E$5*'Parameters, country spec'!$E$52*'CH4 per kg feed'!Q68+(Production!$E$6+Production!$E$7)*'Parameters, country spec'!$E$53*'CH4 per kg feed'!Q69)/Production!E23 -> 0.00020083772 | W23: ='Parameters, country spec'!E61*EF_el_CH4_HU -> 0.00080283539 | X23: =Energy_slaughter_el_HU*EF_el_CH4_HU+Energy_slaughter_oil_HU*EF_oil_CH4 -> 0.0004437032
A24: A01RQ | B24: Rabbit meat | C24: Meat and meat products | D24: Hungary | E24: HU | F24: CH4, biogenic | G24: =SUM(H24:T24) -> 0.027999577 | S24: =(Production!E5*'Parameters, country spec'!E57+(Production!E6+Production!E7)*'Parameters, country spec'!E57)/Production!E23 -> 0.00032853267 | T24: =SUM(U24:V24) -> 0.027671044 | U24: =Manure!I35 -> 0.027671044
A25: A01RQ | B25: Rabbit meat | C25: Meat and meat products | D25: Hungary | E25: HU | F25: N2O | G25: =SUM(H25:T25)+W25+X25 -> 0.016171812 | H25: =(Production!$E$5*'Parameters, country spec'!$E$52*'N2O per kg feed'!G68+(Production!$E$6+Production!$E$7)*'Parameters, country spec'!$E$53*'N2O per kg feed'!G69)/Production!E23 -> 0.0013200816 | I25: =(Production!$E$5*'Parameters, country spec'!$E$52*'N2O per kg feed'!H68+(Production!$E$6+Production!$E$7)*'Parameters, country spec'!$E$53*'N2O per kg feed'!H69)/Production!E23 -> 9.7448728e-06 | J25: =(Production!$E$5*'Parameters, country spec'!$E$52*'N2O per kg feed'!I68+(Production!$E$6+Production!$E$7)*'Parameters, country spec'!$E$53*'N2O per kg feed'!I69+Manure!I150)/Production!E23 -> 0.0090467297 | K25: =J25*EF_indirect_N2O_HU -> 0.00090467297 | L25: =(Production!$E$5*'Parameters, country spec'!$E$52*'N2O per kg feed'!K68+(Production!$E$6+Production!$E$7)*'Parameters, country spec'!$E$53*'N2O per kg feed'!K69)/Production!E23 -> 9.9688638e-06 | N25: =(Production!$E$5*'Parameters, country spec'!$E$52*'N2O per kg feed'!M68+(Production!$E$6+Production!$E$7)*'Parameters, country spec'!$E$53*'N2O per kg feed'!M69)/Production!E23 -> 3.506847e-08 | O25: =(Production!$E$5*'Parameters, country spec'!$E$52*'N2O per kg feed'!N68+(Production!$E$6+Production!$E$7)*'Parameters, country spec'!$E$53*'N2O per kg feed'!N69)/Production!E23 -> 8.6856926e-06 | P25: =(Production!$E$5*'Parameters, country spec'!$E$52*'N2O per kg feed'!O68+(Production!$E$6+Production!$E$7)*'Parameters, country spec'!$E$53*'N2O per kg feed'!O69)/Production!E23 -> 0 | Q25: =(Production!$E$5*'Parameters, country spec'!$E$52*'N2O per kg feed'!P68+(Production!$E$6+Production!$E$7)*'Parameters, country spec'!$E$53*'N2O per kg feed'!P69)/Production!E23 -> 0.00023887848 | R25: =(Production!$E$5*'Parameters, country spec'!$E$52*'N2O per kg feed'!Q68+(Production!$E$6+Production!$E$7)*'Parameters, country spec'!$E$53*'N2O per kg feed'!Q69)/Production!E23 -> 8.3829157e-06 | T25: =SUM(U25:V25) -> 0.0046071598 | U25: =Manure!$I$92*44/28 -> 0.0025204355 | V25: =Manure!$I$157*17/14*Manure!$H$120 -> 0.0020867242 | W25: ='Parameters, country spec'!E61*EF_el_N2O_HU -> 1.1140536e-05 | X25: =Energy_slaughter_el_HU*EF_el_N2O_HU+Energy_slaughter_oil_HU*EF_oil_N2O -> 6.3318568e-06
A26: A01RQ | B26: Rabbit meat | C26: Meat and meat products | D26: Hungary | E26: HU | F26: CO2e | G26: =SUM(H26:X26) -> 8.7927215 | H26: =SUMPRODUCT(H22:H25,'Parameters, general'!$B$23:$B$26) -> 0.98678155 | I26: =SUMPRODUCT(I22:I25,'Parameters, general'!$B$23:$B$26) -> 0.2800545 | J26: =SUMPRODUCT(J22:J25,'Parameters, general'!$B$23:$B$26) -> 2.4697572 | K26: =SUMPRODUCT(K22:K25,'Parameters, general'!$B$23:$B$26) -> 0.24697572 | L26: =SUMPRODUCT(L22:L25,'Parameters, general'!$B$23:$B$26) -> 0.36947746 | M26: =SUMPRODUCT(M22:M25,'Parameters, general'!$B$23:$B$26) -> 0 | N26: =SUMPRODUCT(N22:N25,'Parameters, general'!$B$23:$B$26) -> 0.00042910124 | O26: =SUMPRODUCT(O22:O25,'Parameters, general'!$B$23:$B$26) -> 0.25389335 | ... T26: =SUMPRODUCT(T22:T25,'Parameters, general'!$B$23:$B$26) -> 2.0048728 | W26: =SUMPRODUCT(W22:W25,'Parameters, general'!$B$23:$B$26) -> 0.3449373 | X26: =SUMPRODUCT(X22:X25,'Parameters, general'!$B$23:$B$26) -> 0.19561201 | Z26: =SUM(H26:R26) -> 6.238429 | AA26: ='CO2 per kg feed'!F68+'CH4 per kg feed'!F68*CF_GWP_CH4_fossil+'N2O per kg feed'!F68*CF_GWP_N2O -> 0.44231563
