Workbook
Name Ability_to_perceive_handling: 'Parameters, general'!#REF!
Name AF_beef: 'Parameters, general'!$B$39
Name AF_beef_DE: 'Parameters, country spec'!$D$98
Name AF_beef_DK: 'Parameters, country spec'!$B$98
Name AF_beef_ES: 'Parameters, country spec'!$K$98
Name AF_beef_FR: 'Parameters, country spec'!$C$98
Name AF_beef_GR: 'Parameters, country spec'!$E$98
Name AF_beef_HU: 'Parameters, country spec'!$F$98
Name AF_beef_IE: 'Parameters, country spec'!$G$98
Name AF_beef_IT: 'Parameters, country spec'!$H$98
Name AF_beef_NL: 'Parameters, country spec'!$I$98
Name AF_beef_PL: 'Parameters, country spec'!$J$98
Name AF_beef_SE: 'Parameters, country spec'!$L$98
Name AF_calves: 'Parameters, general'!$B$40
Name AF_calves_DE: 'Parameters, country spec'!$D$97
Name AF_calves_DK: 'Parameters, country spec'!$B$97
Name AF_calves_ES: 'Parameters, country spec'!$K$97
Name AF_calves_FR: 'Parameters, country spec'!$C$97
Name AF_calves_GR: 'Parameters, country spec'!$E$97
Name AF_calves_HU: 'Parameters, country spec'!$F$97
Name AF_calves_IE: 'Parameters, country spec'!$G$97
Name AF_calves_IT: 'Parameters, country spec'!$H$97
Name AF_calves_NL: 'Parameters, country spec'!$I$97
Name AF_calves_PL: 'Parameters, country spec'!$J$97
Name AF_calves_SE: 'Parameters, country spec'!$L$97
Name AF_milk: 'Parameters, general'!$B$38
Name AF_milk_DE: 'Parameters, country spec'!$D$95
Name AF_milk_DK: 'Parameters, country spec'!$B$95
Name AF_milk_ES: 'Parameters, country spec'!$K$95
Name AF_milk_FR: 'Parameters, country spec'!$C$95
Name AF_milk_GR: 'Parameters, country spec'!$E$95
Name AF_milk_HU: 'Parameters, country spec'!$F$95
Name AF_milk_IE: 'Parameters, country spec'!$G$95
Name AF_milk_IT: 'Parameters, country spec'!$H$95
Name AF_milk_NL: 'Parameters, country spec'!$I$95
Name AF_milk_PL: 'Parameters, country spec'!$J$95
Name AF_milk_SE: 'Parameters, country spec'!$L$95
Name AF_offal: 'Parameters, general'!$B$41
Name AF_offal_DE: 'Parameters, country spec'!$D$99
Name AF_offal_DK: 'Parameters, country spec'!$B$99
Name AF_offal_ES: 'Parameters, country spec'!$K$99
Name AF_offal_FR: 'Parameters, country spec'!$C$99
Name AF_offal_GR: 'Parameters, country spec'!$E$99
Name AF_offal_HU: 'Parameters, country spec'!$F$99
Name AF_offal_IE: 'Parameters, country spec'!$G$99
Name AF_offal_IT: 'Parameters, country spec'!$H$99
Name AF_offal_NL: 'Parameters, country spec'!$I$99
Name AF_offal_PL: 'Parameters, country spec'!$J$99
Name AF_offal_SE: 'Parameters, country spec'!$L$99
Name AF_tallow: 'Parameters, general'!$B$42
Name AF_tallow_DE: 'Parameters, country spec'!$D$100
Name AF_tallow_DK: 'Parameters, country spec'!$B$100
Name AF_tallow_ES: 'Parameters, country spec'!$K$100
Name AF_tallow_FR: 'Parameters, country spec'!$C$100
Name AF_tallow_GR: 'Parameters, country spec'!$E$100
Name AF_tallow_HU: 'Parameters, country spec'!$F$100
Name AF_tallow_IE: 'Parameters, country spec'!$G$100
Name AF_tallow_IT: 'Parameters, country spec'!$H$100
Name AF_tallow_NL: 'Parameters, country spec'!$I$100
Name AF_tallow_PL: 'Parameters, country spec'!$J$100

Sheet README
A2: Read me
A4: This is a file that contains…
A17: Color codes:
B19: Results
B20: Sheets for input
B21: Intermediate calculations
A26: Att göra:
A27: Landsspecifika mortality rates ska gå att få ut från nationella databaser, i varjefall för vissa länder skriver de om här: https://www.sciencedirect.com/science/article/pii/S003452881830359X
A28: Se om det går att få ut en foderstat för denna från Frankrike https://productions-animales.org/article/view/5396

Sheet Figures
A2: Figures
A4: Greenhouse gas emission for milk across countries, to farmgate, no waste
B6: Production of mineral fertilizer | C6: Production of capital goods | D6: Emissions from soil | E6: Energy use cropping | F6: Energy use for feed processing | G6: Land use change emissions | H6: Feed transports | I6: Enteric fermentation | J6: Manure management | K6: Energy use in stables | L6: Energy use for slaughter | M6: Tot
A7: Poland | B7: ='GHG det, per kg milk'!H51 -> 0.069906025 | C7: ='GHG det, per kg milk'!I51 -> 0.027634303 | D7: ='GHG det, per kg milk'!J51+'GHG det, per kg milk'!K51 -> 0.11683022 | E7: ='GHG det, per kg milk'!L51+'GHG det, per kg milk'!N51 -> 0.031273195 | F7: ='GHG det, per kg milk'!O51+'GHG det, per kg milk'!Q51 -> 0.10873971 | G7: ='GHG det, per kg milk'!P51 -> 0.025194435 | H7: ='GHG det, per kg milk'!R51 -> 0.085313302 | I7: ='GHG det, per kg milk'!S51 -> 0.50693602 | J7: ='GHG det, per kg milk'!T51 -> 0.12913323 | K7: ='GHG det, per kg milk'!W51 -> 0.24446143 | L7: ='GHG det, per kg milk'!X51 -> 0.0024083566 | M7: =SUM(B7:L7) -> 1.3478302
A8: Hungary | B8: ='GHG det, per kg milk'!H31 -> 0.037362351 | C8: ='GHG det, per kg milk'!I31 -> 0.024658947 | D8: ='GHG det, per kg milk'!J31+'GHG det, per kg milk'!K31 -> 0.11929175 | E8: ='GHG det, per kg milk'!L31+'GHG det, per kg milk'!N31 -> 0.026515746 | F8: ='GHG det, per kg milk'!O31+'GHG det, per kg milk'!Q31 -> 0.13831284 | G8: ='GHG det, per kg milk'!P31 -> 0.035692686 | H8: ='GHG det, per kg milk'!R31 -> 0.12179168 | I8: ='GHG det, per kg milk'!S31 -> 0.49842953 | J8: ='GHG det, per kg milk'!T31 -> 0.18214136 | K8: ='GHG det, per kg milk'!W31 -> 0.094434922 | L8: ='GHG det, per kg milk'!X31 -> 0.0012586525 | M8: =SUM(B8:L8) -> 1.2798905
A9: Greece | B9: ='GHG det, per kg milk'!H26 -> 0.059535004 | C9: ='GHG det, per kg milk'!I26 -> 0.026974893 | D9: ='GHG det, per kg milk'!J26+'GHG det, per kg milk'!K26 -> 0.14402825 | E9: ='GHG det, per kg milk'!L26+'GHG det, per kg milk'!N26 -> 0.036975427 | F9: ='GHG det, per kg milk'!O26+'GHG det, per kg milk'!Q26 -> 0.089626125 | G9: ='GHG det, per kg milk'!P26 -> 0.025821298 | H9: ='GHG det, per kg milk'!R26 -> 0.069336164 | I9: ='GHG det, per kg milk'!S26 -> 0.48100638 | J9: ='GHG det, per kg milk'!T26 -> 0.13093999 | K9: ='GHG det, per kg milk'!W26 -> 0.17249535 | L9: ='GHG det, per kg milk'!X26 -> 0.0016097656 | M9: =SUM(B9:L9) -> 1.2383486
A10: Italy | B10: ='GHG det, per kg milk'!H41 -> 0.021040006 | C10: ='GHG det, per kg milk'!I41 -> 0.02403901 | D10: ='GHG det, per kg milk'!J41+'GHG det, per kg milk'!K41 -> 0.076927334 | E10: ='GHG det, per kg milk'!L41+'GHG det, per kg milk'!N41 -> 0.014615583 | F10: ='GHG det, per kg milk'!O41+'GHG det, per kg milk'!Q41 -> 0.10412706 | G10: ='GHG det, per kg milk'!P41 -> 0.035542667 | H10: ='GHG det, per kg milk'!R41 -> 0.09875542 | I10: ='GHG det, per kg milk'!S41 -> 0.5390151 | J10: ='GHG det, per kg milk'!T41 -> 0.20950377 | K10: ='GHG det, per kg milk'!W41 -> 0.10725069 | L10: ='GHG det, per kg milk'!X41 -> 0.0011827381 | M10: =SUM(B10:L10) -> 1.2319994
A11: Netherlands | B11: ='GHG det, per kg milk'!H46 -> 0.062917336 | C11: ='GHG det, per kg milk'!I46 -> 0.024986364 | D11: ='GHG det, per kg milk'!J46+'GHG det, per kg milk'!K46 -> 0.15287739 | E11: ='GHG det, per kg milk'!L46+'GHG det, per kg milk'!N46 -> 0.020029052 | F11: ='GHG det, per kg milk'!O46+'GHG det, per kg milk'!Q46 -> 0.051076114 | G11: ='GHG det, per kg milk'!P46 -> 0.032935739 | H11: ='GHG det, per kg milk'!R46 -> 0.040598987 | I11: ='GHG det, per kg milk'!S46 -> 0.46360695 | J11: ='GHG det, per kg milk'!T46 -> 0.15024441 | K11: ='GHG det, per kg milk'!W46 -> 0.13851426 | L11: ='GHG det, per kg milk'!X46 -> 0.001092463 | M11: =SUM(B11:L11) -> 1.1388791
A12: Germany | B12: ='GHG det, per kg milk'!H21 -> 0.029641136 | C12: ='GHG det, per kg milk'!I21 -> 0.026414324 | D12: ='GHG det, per kg milk'!J21+'GHG det, per kg milk'!K21 -> 0.078516242 | E12: ='GHG det, per kg milk'!L21+'GHG det, per kg milk'!N21 -> 0.015267153 | F12: ='GHG det, per kg milk'!O21+'GHG det, per kg milk'!Q21 -> 0.069433961 | G12: ='GHG det, per kg milk'!P21 -> 0.019267566 | H12: ='GHG det, per kg milk'!R21 -> 0.064759272 | I12: ='GHG det, per kg milk'!S21 -> 0.49188537 | J12: ='GHG det, per kg milk'!T21 -> 0.1496272 | K12: ='GHG det, per kg milk'!W21 -> 0.10134181 | L12: ='GHG det, per kg milk'!X21 -> 0.001109468 | M12: =SUM(B12:L12) -> 1.0472635
A13: Spain | B13: ='GHG det, per kg milk'!H56 -> 0.043062056 | C13: ='GHG det, per kg milk'!I56 -> 0.025099257 | D13: ='GHG det, per kg milk'!J56+'GHG det, per kg milk'!K56 -> 0.11916955 | E13: ='GHG det, per kg milk'!L56+'GHG det, per kg milk'!N56 -> 0.032934437 | F13: ='GHG det, per kg milk'!O56+'GHG det, per kg milk'!Q56 -> 0.061858141 | G13: ='GHG det, per kg milk'!P56 -> 0.030633719 | H13: ='GHG det, per kg milk'!R56 -> 0.044707834 | I13: ='GHG det, per kg milk'!S56 -> 0.45374833 | J13: ='GHG det, per kg milk'!T56 -> 0.14199359 | K13: ='GHG det, per kg milk'!W56 -> 0.076050804 | L13: ='GHG det, per kg milk'!X56 -> 0.00078114666 | M13: =SUM(B13:L13) -> 1.0300389
A14: Denmark | B14: ='GHG det, per kg milk'!H11 -> 0.048384711 | C14: ='GHG det, per kg milk'!I11 -> 0.021363862 | D14: ='GHG det, per kg milk'!J11+'GHG det, per kg milk'!K11 -> 0.10830012 | E14: ='GHG det, per kg milk'!L11+'GHG det, per kg milk'!N11 -> 0.01518799 | F14: ='GHG det, per kg milk'!O11+'GHG det, per kg milk'!Q11 -> 0.056312459 | G14: ='GHG det, per kg milk'!P11 -> 0.013241399 | H14: ='GHG det, per kg milk'!R11 -> 0.046081858 | I14: ='GHG det, per kg milk'!S11 -> 0.47343335 | J14: ='GHG det, per kg milk'!T11 -> 0.22039861 | K14: ='GHG det, per kg milk'!W11 -> 0.0013171699 | L14: ='GHG det, per kg milk'!X11 -> 0.00090100914 | M14: =SUM(B14:L14) -> 1.0049225
A15: France | B15: ='GHG det, per kg milk'!H16 -> 0.036925368 | C15: ='GHG det, per kg milk'!I16 -> 0.027274827 | D15: ='GHG det, per kg milk'!J16+'GHG det, per kg milk'!K16 -> 0.11143153 | E15: ='GHG det, per kg milk'!L16+'GHG det, per kg milk'!N16 -> 0.018533852 | F15: ='GHG det, per kg milk'!O16+'GHG det, per kg milk'!Q16 -> 0.068647118 | G15: ='GHG det, per kg milk'!P16 -> 0.015469464 | H15: ='GHG det, per kg milk'!R16 -> 0.058586097 | I15: ='GHG det, per kg milk'!S16 -> 0.52754027 | J15: ='GHG det, per kg milk'!T16 -> 0.11656127 | K15: ='GHG det, per kg milk'!W16 -> 0.01922052 | L15: ='GHG det, per kg milk'!X16 -> 0.00050121823 | M15: =SUM(B15:L15) -> 1.0006915
A16: Sweden | B16: ='GHG det, per kg milk'!H61 -> 0.037642578 | C16: ='GHG det, per kg milk'!I61 -> 0.027315517 | D16: ='GHG det, per kg milk'!J61+'GHG det, per kg milk'!K61 -> 0.11183223 | E16: ='GHG det, per kg milk'!L61+'GHG det, per kg milk'!N61 -> 0.024549872 | F16: ='GHG det, per kg milk'!O61+'GHG det, per kg milk'!Q61 -> 0.074151556 | G16: ='GHG det, per kg milk'!P61 -> 0.022203399 | H16: ='GHG det, per kg milk'!R61 -> 0.065425242 | I16: ='GHG det, per kg milk'!S61 -> 0.49785567 | J16: ='GHG det, per kg milk'!T61 -> 0.077274085 | K16: ='GHG det, per kg milk'!W61 -> 0.012571318 | L16: ='GHG det, per kg milk'!X61 -> 0.00039628936 | M16: =SUM(B16:L16) -> 0.95121776
A17: Ireland | B17: ='GHG det, per kg milk'!H36 -> 0.025856819 | C17: ='GHG det, per kg milk'!I36 -> 0.031647246 | D17: ='GHG det, per kg milk'!J36+'GHG det, per kg milk'!K36 -> 0.11129543 | E17: ='GHG det, per kg milk'!L36+'GHG det, per kg milk'!N36 -> 0.017248603 | F17: ='GHG det, per kg milk'!O36+'GHG det, per kg milk'!Q36 -> 0.013414023 | G17: ='GHG det, per kg milk'!P36 -> 0.0026265212 | H17: ='GHG det, per kg milk'!R36 -> 0.007732808 | I17: ='GHG det, per kg milk'!S36 -> 0.55921983 | J17: ='GHG det, per kg milk'!T36 -> 0.11943507 | K17: ='GHG det, per kg milk'!W36 -> 0.049755033 | L17: ='GHG det, per kg milk'!X36 -> 0.0011919296 | M17: =SUM(B17:L17) -> 0.93942331
C19: Andel | D19: Arla
A20: Våmjäsning | B20: =I17 -> 0.55921983 | C20: =B20/SUM($B$20:$B$23) -> 0.59527992 | D20: =1.15*0.41 -> 0.4715 | E20: =41/91 -> 0.45054945
A21: Foder | B21: =SUM(B17:H17) -> 0.20982145 | C21: =B21/SUM($B$20:$B$23) -> 0.22335133 | D21: =1.15*0.33 -> 0.3795 | E21: =33/91 -> 0.36263736
A22: Gödsel | B22: =J17 -> 0.11943507 | C22: =B22/SUM($B$20:$B$23) -> 0.12713658 | D22: =1.15*0.1 -> 0.115 | E22: =10/91 -> 0.10989011 | I22: Från Elmquist et al 2015
A23: Energi | B23: =K17+L17 -> 0.050946963 | C23: =B23/SUM($B$20:$B$23) -> 0.054232168 | D23: =1.15*0.05 -> 0.0575 | E23: =7/91 -> 0.076923077 | F23: För Arla även diesel | I23: 0.17 kWh/kg mjölk -> | K23: =0.17*0.092 -> 0.01564 | L23: kg CO2e/kg mjölk
B24: =SUM(B20:B23) -> 0.93942331 | D24: =SUM(D20:D23) -> 1.0235
A26: Comparison with Moberg et al. Sweden
A27: - Lower values for feed due to lower emissions from grains (no SOC changes acccounted for here), ley approx the same
A28: - Moberg has slightly higher EF for methane for dairy cows and heifers, but that makes a small difference
A29: - Slight difference in milk yield does not explain difference in methane emissions
A30: - Here we do not account for any emissions from by-products!! Should be added
A34: https://www.arla.se/4a9c19/globalassets/om-arla/hallbarhet/klimatberakningar/climate-check-report-2022.pdf | Z34: Ranking here: | AB34: Ranking Lesshen:
Z36: Germany | AB36: Poland
Z37: Spain | AB37: Ireland
Z38: Netherlands | AB38: Hungary
Z39: Greece | AB39: Greece
Z40: Italy | AB40: Netherlands
Z41: Poland | AB41: Italy
Z42: Ireland | AB42: Spain
Z43: Denmark | AB43: Germany
Z44: Hungary | AB44: France
Z45: France | AB45: Sweden
Z46: Sweden | AB46: Denmakr
B76: Manure
B77: Comp
B78: Emissions from manure (tot) from Emmas data, Swedish milk | H78: 0.11 kg C02e / kg past. Milk. Near exclusively direct emissions
...

Sheet Footprints, per kg milk
A2: Footprints (per kg of milk)
A5: Animal products | F5: Climate | L5: Land | M5: Nitrogen | N5: Phosphorus | O5: Water | P5: Pesticides | Q5: Biodiversity | R5: Ammonia | S5: Labour | T5: Animal welfare | U5: Use of antibiotics
A6: Code | B6: Name | C6: Category | D6: Country | E6: Country code | F6: Carbon footprint, kg CO2e/kg | G6: Carbon dioxide, kg CO2/kg | H6: Methane, fossil, kg CH4/kg | I6: Methane, biogenic, kg CH4/kg | J6: Nitrous oxide, kg N2O/kg | K6: HFCs, kg HFCs/kg | L6: Cropland use, m2/kg | M6: New N input, kg N/kg | N6: New P input, kg P/kg | O6: Blue freshwater use, m3/kg | P6: Pesticide use, g a.i./kg | Q6: Extinction rate, E/MSY/kg | R6: Ammonia emission, kg NH3/kg | S6: Labour requirements, h/kg | T6: Animal welfare index per kg of milk | U6: Antibiotics use indicator/kg
A7: 02211 | B7: Raw milk of cattle | C7: Dairy | D7: Denmark | E7: DK | F7: ='GHG det, per kg milk'!G11 -> 1.0049225 | G7: ='GHG det, per kg milk'!G7 -> 0.14515622 | H7: ='GHG det, per kg milk'!G8 -> 0.00084506497 | I7: ='GHG det, per kg milk'!G9 -> 0.023283056 | J7: ='GHG det, per kg milk'!G10 -> 0.00075436221 | L7: ='Footprints, absolute'!L7/Production!$B$9*AF_milk_DK -> 0.94139375 | M7: ='Footprints, absolute'!M7/Production!$B$9*AF_milk_DK -> 0.012509012 | N7: ='Footprints, absolute'!N7/Production!$B$9*AF_milk_DK -> 0.001026969 | O7: ='Footprints, absolute'!O7/Production!$B$9*AF_milk_DK -> 0.0075354671 | P7: ='Footprints, absolute'!P7/Production!$B$9*AF_milk_DK -> 0.065874837 | Q7: ='Footprints, absolute'!Q7/Production!$B$9*AF_milk_DK -> 1.022527e-11 | R7: ='Footprints, absolute'!R7/Production!$B$9*AF_milk_DK -> 0.00047317567 | T7: ='Footprints, absolute'!T7*AF_milk_DK -> 0.0075099482 | U7: ='Footprints, absolute'!U7*AF_milk_DK -> 0.73472176
A8: 02211 | B8: Raw milk of cattle | C8: Dairy | D8: France | E8: FR | F8: ='GHG det, per kg milk'!G16 -> 1.0006915 | G8: ='GHG det, per kg milk'!G12 -> 0.18854038 | H8: ='GHG det, per kg milk'!G13 -> 0.00096964335 | I8: ='GHG det, per kg milk'!G14 -> 0.021746613 | J8: ='GHG det, per kg milk'!G15 -> 0.00071830489 | L8: ='Footprints, absolute'!L8/Production!$C$9*AF_milk_FR -> 1.0060224 | M8: ='Footprints, absolute'!M8/Production!$C$9*AF_milk_FR -> 0.014351879 | N8: ='Footprints, absolute'!N8/Production!$C$9*AF_milk_FR -> 0.0011800522 | O8: ='Footprints, absolute'!O8/Production!$C$9*AF_milk_FR -> 0.010768766 | P8: ='Footprints, absolute'!P8/Production!$C$9*AF_milk_FR -> 0.098987497 | Q8: ='Footprints, absolute'!Q8/Production!$C$9*AF_milk_FR -> 2.12412e-11 | R8: ='Footprints, absolute'!R8/Production!$C$9*AF_milk_FR -> 0.00062855267 | T8: ='Footprints, absolute'!T8*AF_milk_FR -> 0.0070291999 | U8: ='Footprints, absolute'!U8*AF_milk_FR -> 1.0217196
A9: 02211 | B9: Raw milk of cattle | C9: Dairy | D9: Germany | E9: DE | F9: ='GHG det, per kg milk'!G21 -> 1.0472635 | G9: ='GHG det, per kg milk'!G17 -> 0.26771039 | H9: ='GHG det, per kg milk'!G18 -> 0.0010654407 | I9: ='GHG det, per kg milk'!G19 -> 0.021556166 | J9: ='GHG det, per kg milk'!G20 -> 0.00060727654 | L9: ='Footprints, absolute'!L9/Production!$D$9*AF_milk_DE -> 0.60463234 | M9: ='Footprints, absolute'!M9/Production!$D$9*AF_milk_DE -> 0.010876001 | N9: ='Footprints, absolute'!N9/Production!$D$9*AF_milk_DE -> 0.00055324016 | O9: ='Footprints, absolute'!O9/Production!$D$9*AF_milk_DE -> 0.005354824 | P9: ='Footprints, absolute'!P9/Production!$D$9*AF_milk_DE -> 0.038100835 | Q9: ='Footprints, absolute'!Q9/Production!$D$9*AF_milk_DE -> 1.6922016e-11 | R9: ='Footprints, absolute'!R9/Production!$D$9*AF_milk_DE -> 0.00031554148 | T9: ='Footprints, absolute'!T9*AF_milk_DE -> 0.0085212815 | U9: ='Footprints, absolute'!U9*AF_milk_DE -> 1.7736434
A10: 02211 | B10: Raw milk of cattle | C10: Dairy | D10: Greece | E10: GR | F10: ='GHG det, per kg milk'!G26 -> 1.2383486 | G10: ='GHG det, per kg milk'!G22 -> 0.43306998 | H10: ='GHG det, per kg milk'!G23 -> 0.0010722308 | I10: ='GHG det, per kg milk'!G24 -> 0.019491261 | J10: ='GHG det, per kg milk'!G25 -> 0.00090498954 | L10: ='Footprints, absolute'!L10/Production!$E$9*AF_milk_GR -> 1.6393959 | M10: ='Footprints, absolute'!M10/Production!$E$9*AF_milk_GR -> 0.023233588 | N10: ='Footprints, absolute'!N10/Production!$E$9*AF_milk_GR -> 0.0023470076 | O10: ='Footprints, absolute'!O10/Production!$E$9*AF_milk_GR -> 0.062020177 | P10: ='Footprints, absolute'!P10/Production!$E$9*AF_milk_GR -> 0.078647889 | Q10: ='Footprints, absolute'!Q10/Production!$E$9*AF_milk_GR -> 1.007069e-10 | R10: ='Footprints, absolute'!R10/Production!$E$9*AF_milk_GR -> 0.0017051508 | T10: ='Footprints, absolute'!T10*AF_milk_GR -> 0.010888635 | U10: ='Footprints, absolute'!U10*AF_milk_GR -> 3.3993396
A11: 02211 | B11: Raw milk of cattle | C11: Dairy | D11: Hungary | E11: HU | F11: ='GHG det, per kg milk'!G31 -> 1.2798905 | G11: ='GHG det, per kg milk'!G27 -> 0.4204242 | H11: ='GHG det, per kg milk'!G28 -> 0.0012766862 | I11: ='GHG det, per kg milk'!G29 -> 0.021642644 | J11: ='GHG det, per kg milk'!G30 -> 0.00086838692 | L11: ='Footprints, absolute'!L11/Production!$F$9*AF_milk_HU -> 1.5375074 | M11: ='Footprints, absolute'!M11/Production!$F$9*AF_milk_HU -> 0.020866725 | N11: ='Footprints, absolute'!N11/Production!$F$9*AF_milk_HU -> 0.0022268577 | O11: ='Footprints, absolute'!O11/Production!$F$9*AF_milk_HU -> 0.01240925 | P11: ='Footprints, absolute'!P11/Production!$F$9*AF_milk_HU -> 0.10909139 | Q11: ='Footprints, absolute'!Q11/Production!$F$9*AF_milk_HU -> 3.2731815e-11 | R11: ='Footprints, absolute'!R11/Production!$F$9*AF_milk_HU -> 0.00075959581 | T11: ='Footprints, absolute'!T11*AF_milk_HU -> 0.011034239 | U11: ='Footprints, absolute'!U11*AF_milk_HU -> 2.626647
A12: 02211 | B12: Raw milk of cattle | C12: Dairy | D12: Ireland | E12: IE | F12: ='GHG det, per kg milk'!G36 -> 0.93942331 | G12: ='GHG det, per kg milk'!G32 -> 0.13988284 | H12: ='GHG det, per kg milk'!G33 -> 0.0001907991 | I12: ='GHG det, per kg milk'!G34 -> 0.023271936 | J12: ='GHG det, per kg milk'!G35 -> 0.00060627249 | L12: ='Footprints, absolute'!L12/Production!$G$9*AF_milk_IE -> 0.2185803 | M12: ='Footprints, absolute'!M12/Production!$G$9*AF_milk_IE -> 0.015554624 | N12: ='Footprints, absolute'!N12/Production!$G$9*AF_milk_IE -> 0.00050827234 | O12: ='Footprints, absolute'!O12/Production!$G$9*AF_milk_IE -> 0.0079779436 | P12: ='Footprints, absolute'!P12/Production!$G$9*AF_milk_IE -> 0.072418607 | Q12: ='Footprints, absolute'!Q12/Production!$G$9*AF_milk_IE -> 5.4689502e-12 | R12: ='Footprints, absolute'!R12/Production!$G$9*AF_milk_IE -> 0.000493313 | T12: ='Footprints, absolute'!T12*AF_milk_IE -> 0.0067615109 | U12: ='Footprints, absolute'!U12*AF_milk_IE -> 1.1141639
A13: 02211 | B13: Raw milk of cattle | C13: Dairy | D13: Italy | E13: IT | F13: ='GHG det, per kg milk'!G41 -> 1.2319994 | G13: ='GHG det, per kg milk'!G37 -> 0.34128923 | H13: ='GHG det, per kg milk'!G38 -> 0.0015417531 | I13: ='GHG det, per kg milk'!G39 -> 0.02471509 | J13: ='GHG det, per kg milk'!G40 -> 0.00065003108 | L13: ='Footprints, absolute'!L13/Production!$H$9*AF_milk_IT -> 1.0329893 | M13: ='Footprints, absolute'!M13/Production!$H$9*AF_milk_IT -> 0.01796752 | N13: ='Footprints, absolute'!N13/Production!$H$9*AF_milk_IT -> 0.0011284835 | O13: ='Footprints, absolute'!O13/Production!$H$9*AF_milk_IT -> 0.009957532 | P13: ='Footprints, absolute'!P13/Production!$H$9*AF_milk_IT -> 0.060147558 | Q13: ='Footprints, absolute'!Q13/Production!$H$9*AF_milk_IT -> 7.7871028e-11 | R13: ='Footprints, absolute'!R13/Production!$H$9*AF_milk_IT -> 0.00082493602 | T13: ='Footprints, absolute'!T13*AF_milk_IT -> 0.0093574918 | U13: ='Footprints, absolute'!U13*AF_milk_IT -> 4.2239832
A14: 02211 | B14: Raw milk of cattle | C14: Dairy | D14: Netherlands | E14: NL | F14: ='GHG det, per kg milk'!G46 -> 1.1388791 | G14: ='GHG det, per kg milk'!G42 -> 0.3221955 | H14: ='GHG det, per kg milk'!G43 -> 0.00083083679 | I14: ='GHG det, per kg milk'!G44 -> 0.020716865 | J14: ='GHG det, per kg milk'!G45 -> 0.00085190216 | L14: ='Footprints, absolute'!L14/Production!$I$9*AF_milk_NL -> 0.7664139 | M14: ='Footprints, absolute'!M14/Production!$I$9*AF_milk_NL -> 0.022073534 | N14: ='Footprints, absolute'!N14/Production!$I$9*AF_milk_NL -> 0.0008474029 | O14: ='Footprints, absolute'!O14/Production!$I$9*AF_milk_NL -> 0.0057908868 | P14: ='Footprints, absolute'!P14/Production!$I$9*AF_milk_NL -> 0.070270298 | Q14: ='Footprints, absolute'!Q14/Production!$I$9*AF_milk_NL -> 2.3868869e-11 | R14: ='Footprints, absolute'!R14/Production!$I$9*AF_milk_NL -> 0.00085129052 | T14: ='Footprints, absolute'!T14*AF_milk_NL -> 0.0075988152 | U14: ='Footprints, absolute'!U14*AF_milk_NL -> 0.90415105
A15: 02211 | B15: Raw milk of cattle | C15: Dairy | D15: Poland | E15: PL | F15: ='GHG det, per kg milk'!G51 -> 1.3478302 | G15: ='GHG det, per kg milk'!G47 -> 0.5419399 | H15: ='GHG det, per kg milk'!G48 -> 0.0011759614 | I15: ='GHG det, per kg milk'!G49 -> 0.020093092 | J15: ='GHG det, per kg milk'!G50 -> 0.00083638531 | L15: ='Footprints, absolute'!L15/Production!$J$9*AF_milk_PL -> 1.0326888 | M15: ='Footprints, absolute'!M15/Production!$J$9*AF_milk_PL -> 0.017150686 | N15: ='Footprints, absolute'!N15/Production!$J$9*AF_milk_PL -> 0.0016314221 | O15: ='Footprints, absolute'!O15/Production!$J$9*AF_milk_PL -> 0.0061497727 | P15: ='Footprints, absolute'!P15/Production!$J$9*AF_milk_PL -> 0.079431334 | Q15: ='Footprints, absolute'!Q15/Production!$J$9*AF_milk_PL -> 1.6328412e-11 | R15: ='Footprints, absolute'!R15/Production!$J$9*AF_milk_PL -> 0.00070469438 | T15: ='Footprints, absolute'!T15*AF_milk_PL -> 0.0088334873 | U15: ='Footprints, absolute'!U15*AF_milk_PL -> 5.4535717
A16: 02211 | B16: Raw milk of cattle | C16: Dairy | D16: Spain | E16: ES | F16: ='GHG det, per kg milk'!G56 -> 1.0300389 | G16: ='GHG det, per kg milk'!G52 -> 0.27884907 | H16: ='GHG det, per kg milk'!G53 -> 0.00077041442 | I16: ='GHG det, per kg milk'!G54 -> 0.01975947 | J16: ='GHG det, per kg milk'!G55 -> 0.00071328116 | L16: ='Footprints, absolute'!L16/Production!$K$9*AF_milk_ES -> 1.1170397 | M16: ='Footprints, absolute'!M16/Production!$K$9*AF_milk_ES -> 0.021005385 | N16: ='Footprints, absolute'!N16/Production!$K$9*AF_milk_ES -> 0.0018869003 | O16: ='Footprints, absolute'!O16/Production!$K$9*AF_milk_ES -> 0.050929775 | P16: ='Footprints, absolute'!P16/Production!$K$9*AF_milk_ES -> 0.085598272 | Q16: ='Footprints, absolute'!Q16/Production!$K$9*AF_milk_ES -> 3.2378153e-11 | R16: ='Footprints, absolute'!R16/Production!$K$9*AF_milk_ES -> 0.00065346232 | T16: ='Footprints, absolute'!T16*AF_milk_ES -> 0.01068814 | U16: ='Footprints, absolute'!U16*AF_milk_ES -> 2.9001293
A17: 02211 | B17: Raw milk of cattle | C17: Dairy | D17: Sweden | E17: SE | F17: ='GHG det, per kg milk'!G61 -> 0.95121776 | G17: ='GHG det, per kg milk'!G57 -> 0.19760179 | H17: ='GHG det, per kg milk'!G58 -> 0.0011064216 | I17: ='GHG det, per kg milk'!G59 -> 0.019524873 | J17: ='GHG det, per kg milk'!G60 -> 0.00070869247 | L17: ='Footprints, absolute'!L17/Production!$L$9*AF_milk_SE -> 1.7743078 | M17: ='Footprints, absolute'!M17/Production!$L$9*AF_milk_SE -> 0.017658262 | N17: ='Footprints, absolute'!N17/Production!$L$9*AF_milk_SE -> 0.00088651879 | O17: ='Footprints, absolute'!O17/Production!$L$9*AF_milk_SE -> 0.005574545 | P17: ='Footprints, absolute'!P17/Production!$L$9*AF_milk_SE -> 0.043670453 | Q17: ='Footprints, absolute'!Q17/Production!$L$9*AF_milk_SE -> 1.111115e-11 | R17: ='Footprints, absolute'!R17/Production!$L$9*AF_milk_SE -> 0.00051682885 | T17: ='Footprints, absolute'!T17*AF_milk_SE -> 0.0070430532 | U17: ='Footprints, absolute'!U17*AF_milk_SE -> 0.35178939

Sheet GHG det, per kg milk
K1: * Calculated as percentage of direct emissions due to assumption due to data limitations regarding nitrogen leaching and volatilization from soils in different regions.
A2: GHG emissions (per kg of milk)
S4: Animals | W4: Stables | X4: Slaughter | Z4: Control
A5: Animal products | G5: Sum | H5: Inputs | J5: Soil emissions | L5: Energy use | P5: Land use change | Q5: Feed processing | R5: Transports | AA5: Dairy cows
A6: Code | B6: Name | C6: Category | D6: Country | E6: Country code | F6: Gas | G6: GHG | H6: Production of mineral fertilizer | I6: Production of capital goods | J6: Direct emissions | K6: Indirect emissions* | L6: Diesel use field mach | M6: Energy use in greenhouses | N6: Energy use for irrigation | O6: Energy use for post-harvest proc | P6: LUC emissions | Q6: Feed processing | R6: Feed transports | S6: Enteric fermentation* | T6: Manure management - tot | U6: Manure management - direct | V6: Manure management - indirect | W6: Energy use in stables | X6: Energy use for slaughter | Z6: Total feed, excl LUC | AA6: Feed mix emissions, kg CO2E per kg feed, excl. adjustement manure
A7: 02211 | B7: Raw milk of cattle | C7: Dairy | D7: Denmark | E7: DK | F7: CO2 | G7: =SUM(H7:X7) -> 0.14515622 | H7: ='GHG detailed, absolute'!H7/Production!$B$9*AF_milk_DK -> 0.033773285 | I7: ='GHG detailed, absolute'!I7/Production!$B$9*AF_milk_DK -> 0.01914369 | L7: ='GHG detailed, absolute'!L7/Production!$B$9*AF_milk_DK -> 0.014849058 | N7: ='GHG detailed, absolute'!N7/Production!$B$9*AF_milk_DK -> 3.0598311e-05 | O7: ='GHG detailed, absolute'!O7/Production!$B$9*AF_milk_DK -> 0.0099528167 | P7: ='GHG detailed, absolute'!P7/Production!$B$9*AF_milk_DK -> 0.013241399 | Q7: ='GHG detailed, absolute'!Q7/Production!$B$9*AF_milk_DK -> 0.026663839 | R7: ='GHG detailed, absolute'!R7/Production!$B$9*AF_milk_DK -> 0.026663839 | W7: ='GHG detailed, absolute'!W7/Production!$B$9*AF_milk_DK -> 0 | X7: ='GHG detailed, absolute'!X7/Production!$B$9*AF_milk_DK -> 0.00083770114
A8: 02211 | B8: Raw milk of cattle | C8: Dairy | D8: Denmark | E8: DK | F8: CH4, fossil | G8: =SUM(H8:X8) -> 0.00084506497 | H8: ='GHG detailed, absolute'!H8/Production!$B$9*AF_milk_DK -> 3.7254045e-05 | I8: ='GHG detailed, absolute'!I8/Production!$B$9*AF_milk_DK -> 6.7357429e-05 | L8: ='GHG detailed, absolute'!L8/Production!$B$9*AF_milk_DK -> 6.5776319e-06 | N8: ='GHG detailed, absolute'!N8/Production!$B$9*AF_milk_DK -> 1.023349e-07 | O8: ='GHG detailed, absolute'!O8/Production!$B$9*AF_milk_DK -> 5.9888558e-06 | P8: ='GHG detailed, absolute'!P8/Production!$B$9*AF_milk_DK -> 0 | Q8: ='GHG detailed, absolute'!Q8/Production!$B$9*AF_milk_DK -> 0.00034653896 | R8: ='GHG detailed, absolute'!R8/Production!$B$9*AF_milk_DK -> 0.00034653896 | W8: ='GHG detailed, absolute'!W8/Production!$B$9*AF_milk_DK -> 3.2943073e-05 | X8: ='GHG detailed, absolute'!X8/Production!$B$9*AF_milk_DK -> 1.7636849e-06
A9: 02211 | B9: Raw milk of cattle | C9: Dairy | D9: Denmark | E9: DK | F9: CH4, biogenic | G9: =SUM(H9:T9) -> 0.023283056 | S9: ='GHG detailed, absolute'!S9/Production!$B$9*AF_milk_DK -> 0.017534569 | T9: ='GHG detailed, absolute'!T9/Production!$B$9*AF_milk_DK -> 0.0057484871 | U9: ='GHG detailed, absolute'!U9/Production!$B$9*AF_milk_DK -> 0.0057484871
A10: 02211 | B10: Raw milk of cattle | C10: Dairy | D10: Denmark | E10: DK | F10: N2O | G10: =SUM(H10:T10)+W10+X10 -> 0.00075436221 | H10: ='GHG detailed, absolute'!H10/Production!$B$9*AF_milk_DK -> 4.9455149e-05 | I10: ='GHG detailed, absolute'!I10/Production!$B$9*AF_milk_DK -> 7.7992812e-07 | J10: ='GHG detailed, absolute'!J10/Production!$B$9*AF_milk_DK -> 0.00036063977 | K10: ='GHG detailed, absolute'!K10/Production!$B$9*AF_milk_DK -> 3.6063977e-05 | L10: ='GHG detailed, absolute'!L10/Production!$B$9*AF_milk_DK -> 3.9899997e-07 | N10: ='GHG detailed, absolute'!N10/Production!$B$9*AF_milk_DK -> 1.2594242e-09 | O10: ='GHG detailed, absolute'!O10/Production!$B$9*AF_milk_DK -> 3.6379476e-07 | P10: ='GHG detailed, absolute'!P10/Production!$B$9*AF_milk_DK -> 0 | Q10: ='GHG detailed, absolute'!Q10/Production!$B$9*AF_milk_DK -> 3.3300947e-05 | R10: ='GHG detailed, absolute'!R10/Production!$B$9*AF_milk_DK -> 3.3300947e-05 | T10: ='GHG detailed, absolute'!T10/Production!$B$9*AF_milk_DK -> 0.00023878924 | U10: ='GHG detailed, absolute'!U10/Production!$B$9*AF_milk_DK -> 0.00014070314 | V10: ='GHG detailed, absolute'!V10/Production!$B$9*AF_milk_DK -> 9.8086102e-05 | W10: ='GHG detailed, absolute'!W10/Production!$B$9*AF_milk_DK -> 1.2288145e-06 | X10: ='GHG detailed, absolute'!X10/Production!$B$9*AF_milk_DK -> 3.9377963e-08
A11: 02211 | B11: Raw milk of cattle | C11: Dairy | D11: Denmark | E11: DK | F11: CO2e | G11: =SUM(H11:X11) -> 1.0049225 | H11: =SUMPRODUCT(H7:H10,'Parameters, general'!$B$24:$B$27) -> 0.048384711 | I11: =SUMPRODUCT(I7:I10,'Parameters, general'!$B$24:$B$27) -> 0.021363862 | J11: =SUMPRODUCT(J7:J10,'Parameters, general'!$B$24:$B$27) -> 0.098454657 | K11: =SUMPRODUCT(K7:K10,'Parameters, general'!$B$24:$B$27) -> 0.0098454657 | L11: =SUMPRODUCT(L7:L10,'Parameters, general'!$B$24:$B$27) -> 0.015153998 | M11: =SUMPRODUCT(M7:M10,'Parameters, general'!$B$24:$B$27) -> 0 | N11: =SUMPRODUCT(N7:N10,'Parameters, general'!$B$24:$B$27) -> 3.3991714e-05 | O11: =SUMPRODUCT(O7:O10,'Parameters, general'!$B$24:$B$27) -> 0.010230601 | ... T11: =SUMPRODUCT(T7:T10,'Parameters, general'!$B$24:$B$27) -> 0.22039861 | W11: =SUMPRODUCT(W7:W10,'Parameters, general'!$B$24:$B$27) -> 0.0013171699 | X11: =SUMPRODUCT(X7:X10,'Parameters, general'!$B$24:$B$27) -> 0.00090100914 | Z11: =SUM(H11:R11) -> 0.3088724 | AA11: ='CO2 per kg feed'!F20+'CH4 per kg feed'!F20*CF_GWP_CH4_fossil+'N2O per kg feed'!F20*CF_GWP_N2O -> 0.32935235
A12: 02211 | B12: Raw milk of cattle | C12: Dairy | D12: France | E12: FR | F12: CO2 | G12: =SUM(H12:X12) -> 0.18854038 | H12: ='GHG detailed, absolute'!H12/Production!$C$9*AF_milk_FR -> 0.029547524 | I12: ='GHG detailed, absolute'!I12/Production!$C$9*AF_milk_FR -> 0.024440377 | L12: ='GHG detailed, absolute'!L12/Production!$C$9*AF_milk_FR -> 0.0177722 | N12: ='GHG detailed, absolute'!N12/Production!$C$9*AF_milk_FR -> 0.00035893798 | O12: ='GHG detailed, absolute'!O12/Production!$C$9*AF_milk_FR -> 0.0097955658 | P12: ='GHG detailed, absolute'!P12/Production!$C$9*AF_milk_FR -> 0.015469464 | Q12: ='GHG detailed, absolute'!Q12/Production!$C$9*AF_milk_FR -> 0.036760688 | R12: ='GHG detailed, absolute'!R12/Production!$C$9*AF_milk_FR -> 0.036760688 | W12: ='GHG detailed, absolute'!W12/Production!$C$9*AF_milk_FR -> 0.017192258 | X12: ='GHG detailed, absolute'!X12/Production!$C$9*AF_milk_FR -> 0.00044267572
A13: 02211 | B13: Raw milk of cattle | C13: Dairy | D13: France | E13: FR | F13: CH4, fossil | G13: =SUM(H13:X13) -> 0.00096964335 | H13: ='GHG detailed, absolute'!H13/Production!$C$9*AF_milk_FR -> 1.6520272e-05 | I13: ='GHG detailed, absolute'!I13/Production!$C$9*AF_milk_FR -> 8.5993918e-05 | L13: ='GHG detailed, absolute'!L13/Production!$C$9*AF_milk_FR -> 7.8724852e-06 | N13: ='GHG detailed, absolute'!N13/Production!$C$9*AF_milk_FR -> 1.1281391e-06 | O13: ='GHG detailed, absolute'!O13/Production!$C$9*AF_milk_FR -> 5.5508611e-06 | P13: ='GHG detailed, absolute'!P13/Production!$C$9*AF_milk_FR -> 0 | Q13: ='GHG detailed, absolute'!Q13/Production!$C$9*AF_milk_FR -> 0.00039877597 | R13: ='GHG detailed, absolute'!R13/Production!$C$9*AF_milk_FR -> 0.00039877597 | W13: ='GHG detailed, absolute'!W13/Production!$C$9*AF_milk_FR -> 5.33013e-05 | X13: ='GHG detailed, absolute'!X13/Production!$C$9*AF_milk_FR -> 1.724423e-06
A14: 02211 | B14: Raw milk of cattle | C14: Dairy | D14: France | E14: FR | F14: CH4, biogenic | G14: =SUM(H14:T14) -> 0.021746613 | S14: ='GHG detailed, absolute'!S14/Production!$C$9*AF_milk_FR -> 0.019538529 | T14: ='GHG detailed, absolute'!T14/Production!$C$9*AF_milk_FR -> 0.0022080844 | U14: ='GHG detailed, absolute'!U14/Production!$C$9*AF_milk_FR -> 0.0022080844
A15: 02211 | B15: Raw milk of cattle | C15: Dairy | D15: France | E15: FR | F15: N2O | G15: =SUM(H15:T15)+W15+X15 -> 0.00071830489 | H15: ='GHG detailed, absolute'!H15/Production!$C$9*AF_milk_FR -> 2.5221759e-05 | I15: ='GHG detailed, absolute'!I15/Production!$C$9*AF_milk_FR -> 9.9571906e-07 | J15: ='GHG detailed, absolute'!J15/Production!$C$9*AF_milk_FR -> 0.00037106738 | K15: ='GHG detailed, absolute'!K15/Production!$C$9*AF_milk_FR -> 3.7106738e-05 | L15: ='GHG detailed, absolute'!L15/Production!$C$9*AF_milk_FR -> 4.7754594e-07 | N15: ='GHG detailed, absolute'!N15/Production!$C$9*AF_milk_FR -> 1.5112376e-08 | O15: ='GHG detailed, absolute'!O15/Production!$C$9*AF_milk_FR -> 3.6644464e-07 | P15: ='GHG detailed, absolute'!P15/Production!$C$9*AF_milk_FR -> 0 | Q15: ='GHG detailed, absolute'!Q15/Production!$C$9*AF_milk_FR -> 3.6417159e-05 | R15: ='GHG detailed, absolute'!R15/Production!$C$9*AF_milk_FR -> 3.6417159e-05 | T15: ='GHG detailed, absolute'!T15/Production!$C$9*AF_milk_FR -> 0.00020858237 | U15: ='GHG detailed, absolute'!U15/Production!$C$9*AF_milk_FR -> 0.00014488173 | V15: ='GHG detailed, absolute'!V15/Production!$C$9*AF_milk_FR -> 6.3700635e-05 | W15: ='GHG detailed, absolute'!W15/Production!$C$9*AF_milk_FR -> 1.6112963e-06 | X15: ='GHG detailed, absolute'!X15/Production!$C$9*AF_milk_FR -> 2.6207745e-08
A16: 02211 | B16: Raw milk of cattle | C16: Dairy | D16: France | E16: FR | F16: CO2e | G16: =SUM(H16:X16) -> 1.0006915 | H16: =SUMPRODUCT(H12:H15,'Parameters, general'!$B$24:$B$27) -> 0.036925368 | I16: =SUMPRODUCT(I12:I15,'Parameters, general'!$B$24:$B$27) -> 0.027274827 | J16: =SUMPRODUCT(J12:J15,'Parameters, general'!$B$24:$B$27) -> 0.1013014 | K16: =SUMPRODUCT(K12:K15,'Parameters, general'!$B$24:$B$27) -> 0.01013014 | L16: =SUMPRODUCT(L12:L15,'Parameters, general'!$B$24:$B$27) -> 0.01813717 | M16: =SUMPRODUCT(M12:M15,'Parameters, general'!$B$24:$B$27) -> 0 | N16: =SUMPRODUCT(N12:N15,'Parameters, general'!$B$24:$B$27) -> 0.0003966822 | O16: =SUMPRODUCT(O12:O15,'Parameters, general'!$B$24:$B$27) -> 0.010061021 | ... T16: =SUMPRODUCT(T12:T15,'Parameters, general'!$B$24:$B$27) -> 0.11656127 | W16: =SUMPRODUCT(W12:W15,'Parameters, general'!$B$24:$B$27) -> 0.01922052 | X16: =SUMPRODUCT(X12:X15,'Parameters, general'!$B$24:$B$27) -> 0.00050121823 | Z16: =SUM(H16:R16) -> 0.33686826 | AA16: ='CO2 per kg feed'!F36+'CH4 per kg feed'!F36*CF_GWP_CH4_fossil+'N2O per kg feed'!F36*CF_GWP_N2O -> 0.26766924
A17: 02211 | B17: Raw milk of cattle | C17: Dairy | D17: Germany | E17: DE | F17: CO2 | G17: =SUM(H17:X17) -> 0.26771039 | H17: ='GHG detailed, absolute'!H17/Production!$D$9*AF_milk_DE -> 0.021714728 | I17: ='GHG detailed, absolute'!I17/Production!$D$9*AF_milk_DE -> 0.023669299 | L17: ='GHG detailed, absolute'!L17/Production!$D$9*AF_milk_DE -> 0.014925582 | N17: ='GHG detailed, absolute'!N17/Production!$D$9*AF_milk_DE -> 3.1603201e-05 | O17: ='GHG detailed, absolute'!O17/Production!$D$9*AF_milk_DE -> 0.0045394945 | P17: ='GHG detailed, absolute'!P17/Production!$D$9*AF_milk_DE -> 0.019267566 | Q17: ='GHG detailed, absolute'!Q17/Production!$D$9*AF_milk_DE -> 0.04387909 | R17: ='GHG detailed, absolute'!R17/Production!$D$9*AF_milk_DE -> 0.04387909 | W17: ='GHG detailed, absolute'!W17/Production!$D$9*AF_milk_DE -> 0.09478009 | X17: ='GHG detailed, absolute'!X17/Production!$D$9*AF_milk_DE -> 0.0010238523
A18: 02211 | B18: Raw milk of cattle | C18: Dairy | D18: Germany | E18: DE | F18: CH4, fossil | G18: =SUM(H18:X18) -> 0.0010654407 | H18: ='GHG detailed, absolute'!H18/Production!$D$9*AF_milk_DE -> 2.0074241e-05 | I18: ='GHG detailed, absolute'!I18/Production!$D$9*AF_milk_DE -> 8.3280866e-05 | L18: ='GHG detailed, absolute'!L18/Production!$D$9*AF_milk_DE -> 6.6115293e-06 | N18: ='GHG detailed, absolute'!N18/Production!$D$9*AF_milk_DE -> 1.0399728e-07 | O18: ='GHG detailed, absolute'!O18/Production!$D$9*AF_milk_DE -> 3.0476256e-06 | P18: ='GHG detailed, absolute'!P18/Production!$D$9*AF_milk_DE -> 0 | Q18: ='GHG detailed, absolute'!Q18/Production!$D$9*AF_milk_DE -> 0.00038427142 | R18: ='GHG detailed, absolute'!R18/Production!$D$9*AF_milk_DE -> 0.00038427142 | W18: ='GHG detailed, absolute'!W18/Production!$D$9*AF_milk_DE -> 0.0001813039 | X18: ='GHG detailed, absolute'!X18/Production!$D$9*AF_milk_DE -> 2.4757302e-06
A19: 02211 | B19: Raw milk of cattle | C19: Dairy | D19: Germany | E19: DE | F19: CH4, biogenic | G19: =SUM(H19:T19) -> 0.021556166 | S19: ='GHG detailed, absolute'!S19/Production!$D$9*AF_milk_DE -> 0.018217977 | T19: ='GHG detailed, absolute'!T19/Production!$D$9*AF_milk_DE -> 0.0033381892 | U19: ='GHG detailed, absolute'!U19/Production!$D$9*AF_milk_DE -> 0.0033381892
A20: 02211 | B20: Raw milk of cattle | C20: Dairy | D20: Germany | E20: DE | F20: N2O | G20: =SUM(H20:T20)+W20+X20 -> 0.00060727654 | H20: ='GHG detailed, absolute'!H20/Production!$D$9*AF_milk_DE -> 2.6843206e-05 | I20: ='GHG detailed, absolute'!I20/Production!$D$9*AF_milk_DE -> 9.6430477e-07 | J20: ='GHG detailed, absolute'!J20/Production!$D$9*AF_milk_DE -> 0.00026145935 | K20: ='GHG detailed, absolute'!K20/Production!$D$9*AF_milk_DE -> 2.6145935e-05 | L20: ='GHG detailed, absolute'!L20/Production!$D$9*AF_milk_DE -> 4.0105619e-07 | N20: ='GHG detailed, absolute'!N20/Production!$D$9*AF_milk_DE -> 1.3087359e-09 | O20: ='GHG detailed, absolute'!O20/Production!$D$9*AF_milk_DE -> 1.6254878e-07 | P20: ='GHG detailed, absolute'!P20/Production!$D$9*AF_milk_DE -> 0 | Q20: ='GHG detailed, absolute'!Q20/Production!$D$9*AF_milk_DE -> 3.4538071e-05 | R20: ='GHG detailed, absolute'!R20/Production!$D$9*AF_milk_DE -> 3.4538071e-05 | T20: ='GHG detailed, absolute'!T20/Production!$D$9*AF_milk_DE -> 0.00021793439 | U20: ='GHG detailed, absolute'!U20/Production!$D$9*AF_milk_DE -> 0.0001302664 | V20: ='GHG detailed, absolute'!V20/Production!$D$9*AF_milk_DE -> 8.7667986e-05 | W20: ='GHG detailed, absolute'!W20/Production!$D$9*AF_milk_DE -> 4.2449309e-06 | X20: ='GHG detailed, absolute'!X20/Production!$D$9*AF_milk_DE -> 4.3366148e-08
A21: 02211 | B21: Raw milk of cattle | C21: Dairy | D21: Germany | E21: DE | F21: CO2e | G21: =SUM(H21:X21) -> 1.0472635 | H21: =SUMPRODUCT(H17:H20,'Parameters, general'!$B$24:$B$27) -> 0.029641136 | I21: =SUMPRODUCT(I17:I20,'Parameters, general'!$B$24:$B$27) -> 0.026414324 | J21: =SUMPRODUCT(J17:J20,'Parameters, general'!$B$24:$B$27) -> 0.071378402 | K21: =SUMPRODUCT(K17:K20,'Parameters, general'!$B$24:$B$27) -> 0.0071378402 | L21: =SUMPRODUCT(L17:L20,'Parameters, general'!$B$24:$B$27) -> 0.015232093 | M21: =SUMPRODUCT(M17:M20,'Parameters, general'!$B$24:$B$27) -> 0 | N21: =SUMPRODUCT(N17:N20,'Parameters, general'!$B$24:$B$27) -> 3.5059605e-05 | O21: =SUMPRODUCT(O17:O20,'Parameters, general'!$B$24:$B$27) -> 0.0046746896 | ... T21: =SUMPRODUCT(T17:T20,'Parameters, general'!$B$24:$B$27) -> 0.1496272 | W21: =SUMPRODUCT(W17:W20,'Parameters, general'!$B$24:$B$27) -> 0.10134181 | X21: =SUMPRODUCT(X17:X20,'Parameters, general'!$B$24:$B$27) -> 0.001109468 | Z21: =SUM(H21:R21) -> 0.30329965 | AA21: ='CO2 per kg feed'!F52+'CH4 per kg feed'!F52*CF_GWP_CH4_fossil+'N2O per kg feed'!F52*CF_GWP_N2O -> 0.25510784
A22: 02211 | B22: Raw milk of cattle | C22: Dairy | D22: Greece | E22: GR | F22: CO2 | G22: =SUM(H22:X22) -> 0.43306998 | H22: ='GHG detailed, absolute'!H22/Production!$E$9*AF_milk_GR -> 0.057680424 | I22: ='GHG detailed, absolute'!I22/Production!$E$9*AF_milk_GR -> 0.024171613 | L22: ='GHG detailed, absolute'!L22/Production!$E$9*AF_milk_GR -> 0.031904429 | N22: ='GHG detailed, absolute'!N22/Production!$E$9*AF_milk_GR -> 0.0040057675 | O22: ='GHG detailed, absolute'!O22/Production!$E$9*AF_milk_GR -> 0.019621094 | P22: ='GHG detailed, absolute'!P22/Production!$E$9*AF_milk_GR -> 0.025821298 | Q22: ='GHG detailed, absolute'!Q22/Production!$E$9*AF_milk_GR -> 0.053472638 | R22: ='GHG detailed, absolute'!R22/Production!$E$9*AF_milk_GR -> 0.053472638 | W22: ='GHG detailed, absolute'!W22/Production!$E$9*AF_milk_GR -> 0.16142909 | X22: ='GHG detailed, absolute'!X22/Production!$E$9*AF_milk_GR -> 0.0014909874
A23: 02211 | B23: Raw milk of cattle | C23: Dairy | D23: Greece | E23: GR | F23: CH4, fossil | G23: =SUM(H23:X23) -> 0.0010722308 | H23: ='GHG detailed, absolute'!H23/Production!$E$9*AF_milk_GR -> 1.2116124e-06 | I23: ='GHG detailed, absolute'!I23/Production!$E$9*AF_milk_GR -> 8.5048268e-05 | L23: ='GHG detailed, absolute'!L23/Production!$E$9*AF_milk_GR -> 1.4132586e-05 | N23: ='GHG detailed, absolute'!N23/Production!$E$9*AF_milk_GR -> 1.2197882e-05 | O23: ='GHG detailed, absolute'!O23/Production!$E$9*AF_milk_GR -> 1.6098129e-05 | P23: ='GHG detailed, absolute'!P23/Production!$E$9*AF_milk_GR -> 0 | Q23: ='GHG detailed, absolute'!Q23/Production!$E$9*AF_milk_GR -> 0.0003097814 | R23: ='GHG detailed, absolute'!R23/Production!$E$9*AF_milk_GR -> 0.0003097814 | W23: ='GHG detailed, absolute'!W23/Production!$E$9*AF_milk_GR -> 0.00032045938 | X23: ='GHG detailed, absolute'!X23/Production!$E$9*AF_milk_GR -> 3.5201736e-06
A24: 02211 | B24: Raw milk of cattle | C24: Dairy | D24: Greece | E24: GR | F24: CH4, biogenic | G24: =SUM(H24:T24) -> 0.019491261 | S24: ='GHG detailed, absolute'!S24/Production!$E$9*AF_milk_GR -> 0.017815051 | T24: ='GHG detailed, absolute'!T24/Production!$E$9*AF_milk_GR -> 0.0016762093 | U24: ='GHG detailed, absolute'!U24/Production!$E$9*AF_milk_GR -> 0.0016762093
A25: 02211 | B25: Raw milk of cattle | C25: Dairy | D25: Greece | E25: GR | F25: N2O | G25: =SUM(H25:T25)+W25+X25 -> 0.00090498954 | H25: ='GHG detailed, absolute'!H25/Production!$E$9*AF_milk_GR -> 6.6610742e-06 | I25: ='GHG detailed, absolute'!I25/Production!$E$9*AF_milk_GR -> 9.8476942e-07 | J25: ='GHG detailed, absolute'!J25/Production!$E$9*AF_milk_GR -> 0.00047961454 | K25: ='GHG detailed, absolute'!K25/Production!$E$9*AF_milk_GR -> 4.7961454e-05 | L25: ='GHG detailed, absolute'!L25/Production!$E$9*AF_milk_GR -> 8.5728444e-07 | N25: ='GHG detailed, absolute'!N25/Production!$E$9*AF_milk_GR -> 1.7049094e-07 | O25: ='GHG detailed, absolute'!O25/Production!$E$9*AF_milk_GR -> 6.9282969e-07 | P25: ='GHG detailed, absolute'!P25/Production!$E$9*AF_milk_GR -> 0 | Q25: ='GHG detailed, absolute'!Q25/Production!$E$9*AF_milk_GR -> 2.4293189e-05 | R25: ='GHG detailed, absolute'!R25/Production!$E$9*AF_milk_GR -> 2.4293189e-05 | T25: ='GHG detailed, absolute'!T25/Production!$E$9*AF_milk_GR -> 0.00031385471 | U25: ='GHG detailed, absolute'!U25/Production!$E$9*AF_milk_GR -> 0.00023593319 | V25: ='GHG detailed, absolute'!V25/Production!$E$9*AF_milk_GR -> 7.7921514e-05 | W25: ='GHG detailed, absolute'!W25/Production!$E$9*AF_milk_GR -> 5.5551883e-06 | X25: ='GHG detailed, absolute'!X25/Production!$E$9*AF_milk_GR -> 5.0831692e-08
A26: 02211 | B26: Raw milk of cattle | C26: Dairy | D26: Greece | E26: GR | F26: CO2e | G26: =SUM(H26:X26) -> 1.2383486 | H26: =SUMPRODUCT(H22:H25,'Parameters, general'!$B$24:$B$27) -> 0.059535004 | I26: =SUMPRODUCT(I22:I25,'Parameters, general'!$B$24:$B$27) -> 0.026974893 | J26: =SUMPRODUCT(J22:J25,'Parameters, general'!$B$24:$B$27) -> 0.13093477 | K26: =SUMPRODUCT(K22:K25,'Parameters, general'!$B$24:$B$27) -> 0.013093477 | L26: =SUMPRODUCT(L22:L25,'Parameters, general'!$B$24:$B$27) -> 0.032559619 | M26: =SUMPRODUCT(M22:M25,'Parameters, general'!$B$24:$B$27) -> 0 | N26: =SUMPRODUCT(N22:N25,'Parameters, general'!$B$24:$B$27) -> 0.0044158084 | O26: =SUMPRODUCT(O22:O25,'Parameters, general'!$B$24:$B$27) -> 0.020289961 | ... T26: =SUMPRODUCT(T22:T25,'Parameters, general'!$B$24:$B$27) -> 0.13093999 | W26: =SUMPRODUCT(W22:W25,'Parameters, general'!$B$24:$B$27) -> 0.17249535 | X26: =SUMPRODUCT(X22:X25,'Parameters, general'!$B$24:$B$27) -> 0.0016097656 | Z26: =SUM(H26:R26) -> 0.45229716 | AA26: ='CO2 per kg feed'!F68+'CH4 per kg feed'!F68*CF_GWP_CH4_fossil+'N2O per kg feed'!F68*CF_GWP_N2O -> 0.41434259
A27: 02211 | B27: Raw milk of cattle | C27: Dairy | D27: Hungary | E27: HU | F27: CO2 | G27: =SUM(H27:X27) -> 0.4204242 | H27: ='GHG detailed, absolute'!H27/Production!$F$9*AF_milk_HU -> 0.033344591 | I27: ='GHG detailed, absolute'!I27/Production!$F$9*AF_milk_HU -> 0.022096344 | L27: ='GHG detailed, absolute'!L27/Production!$F$9*AF_milk_HU -> 0.025864673 | N27: ='GHG detailed, absolute'!N27/Production!$F$9*AF_milk_HU -> 0.00010882727 | O27: ='GHG detailed, absolute'!O27/Production!$F$9*AF_milk_HU -> 0.015977849 | P27: ='GHG detailed, absolute'!P27/Production!$F$9*AF_milk_HU -> 0.035692686 | Q27: ='GHG detailed, absolute'!Q27/Production!$F$9*AF_milk_HU -> 0.099569605 | R27: ='GHG detailed, absolute'!R27/Production!$F$9*AF_milk_HU -> 0.099569605 | W27: ='GHG detailed, absolute'!W27/Production!$F$9*AF_milk_HU -> 0.087052366 | X27: ='GHG detailed, absolute'!X27/Production!$F$9*AF_milk_HU -> 0.0011476521
A28: 02211 | B28: Raw milk of cattle | C28: Dairy | D28: Hungary | E28: HU | F28: CH4, fossil | G28: =SUM(H28:X28) -> 0.0012766862 | H28: ='GHG detailed, absolute'!H28/Production!$F$9*AF_milk_HU -> 1.7628714e-06 | I28: ='GHG detailed, absolute'!I28/Production!$F$9*AF_milk_HU -> 7.7746396e-05 | L28: ='GHG detailed, absolute'!L28/Production!$F$9*AF_milk_HU -> 1.1457178e-05 | N28: ='GHG detailed, absolute'!N28/Production!$F$9*AF_milk_HU -> 3.2957773e-07 | O28: ='GHG detailed, absolute'!O28/Production!$F$9*AF_milk_HU -> 1.3018592e-05 | P28: ='GHG detailed, absolute'!P28/Production!$F$9*AF_milk_HU -> 0 | Q28: ='GHG detailed, absolute'!Q28/Production!$F$9*AF_milk_HU -> 0.00047460677 | R28: ='GHG detailed, absolute'!R28/Production!$F$9*AF_milk_HU -> 0.00047460677 | W28: ='GHG detailed, absolute'!W28/Production!$F$9*AF_milk_HU -> 0.00021979559 | X28: ='GHG detailed, absolute'!X28/Production!$F$9*AF_milk_HU -> 3.3624262e-06
A29: 02211 | B29: Raw milk of cattle | C29: Dairy | D29: Hungary | E29: HU | F29: CH4, biogenic | G29: =SUM(H29:T29) -> 0.021642644 | S29: ='GHG detailed, absolute'!S29/Production!$F$9*AF_milk_HU -> 0.018460353 | T29: ='GHG detailed, absolute'!T29/Production!$F$9*AF_milk_HU -> 0.0031822912 | U29: ='GHG detailed, absolute'!U29/Production!$F$9*AF_milk_HU -> 0.0031822912
A30: 02211 | B30: Raw milk of cattle | C30: Dairy | D30: Hungary | E30: HU | F30: N2O | G30: =SUM(H30:T30)+W30+X30 -> 0.00086838692 | H30: ='GHG detailed, absolute'!H30/Production!$F$9*AF_milk_HU -> 1.4524636e-05 | I30: ='GHG detailed, absolute'!I30/Production!$F$9*AF_milk_HU -> 9.0022143e-07 | J30: ='GHG detailed, absolute'!J30/Production!$F$9*AF_milk_HU -> 0.00039724193 | K30: ='GHG detailed, absolute'!K30/Production!$F$9*AF_milk_HU -> 3.9724193e-05 | L30: ='GHG detailed, absolute'!L30/Production!$F$9*AF_milk_HU -> 6.9499385e-07 | N30: ='GHG detailed, absolute'!N30/Production!$F$9*AF_milk_HU -> 4.6403099e-09 | O30: ='GHG detailed, absolute'!O30/Production!$F$9*AF_milk_HU -> 5.6905029e-07 | P30: ='GHG detailed, absolute'!P30/Production!$F$9*AF_milk_HU -> 0 | Q30: ='GHG detailed, absolute'!Q30/Production!$F$9*AF_milk_HU -> 2.9592662e-05 | R30: ='GHG detailed, absolute'!R30/Production!$F$9*AF_milk_HU -> 2.9592662e-05 | T30: ='GHG detailed, absolute'!T30/Production!$F$9*AF_milk_HU -> 0.00035245237 | U30: ='GHG detailed, absolute'!U30/Production!$F$9*AF_milk_HU -> 0.00025817282 | V30: ='GHG detailed, absolute'!V30/Production!$F$9*AF_milk_HU -> 9.4279553e-05 | W30: ='GHG detailed, absolute'!W30/Production!$F$9*AF_milk_HU -> 3.049991e-06 | X30: ='GHG detailed, absolute'!X30/Production!$F$9*AF_milk_HU -> 3.9561026e-08
A31: 02211 | B31: Raw milk of cattle | C31: Dairy | D31: Hungary | E31: HU | F31: CO2e | G31: =SUM(H31:X31) -> 1.2798905 | H31: =SUMPRODUCT(H27:H30,'Parameters, general'!$B$24:$B$27) -> 0.037362351 | I31: =SUMPRODUCT(I27:I30,'Parameters, general'!$B$24:$B$27) -> 0.024658947 | J31: =SUMPRODUCT(J27:J30,'Parameters, general'!$B$24:$B$27) -> 0.10844705 | K31: =SUMPRODUCT(K27:K30,'Parameters, general'!$B$24:$B$27) -> 0.010844705 | L31: =SUMPRODUCT(L27:L30,'Parameters, general'!$B$24:$B$27) -> 0.02639583 | M31: =SUMPRODUCT(M27:M30,'Parameters, general'!$B$24:$B$27) -> 0 | N31: =SUMPRODUCT(N27:N30,'Parameters, general'!$B$24:$B$27) -> 0.00011991549 | O31: =SUMPRODUCT(O27:O30,'Parameters, general'!$B$24:$B$27) -> 0.016521154 | ... T31: =SUMPRODUCT(T27:T30,'Parameters, general'!$B$24:$B$27) -> 0.18214136 | W31: =SUMPRODUCT(W27:W30,'Parameters, general'!$B$24:$B$27) -> 0.094434922 | X31: =SUMPRODUCT(X27:X30,'Parameters, general'!$B$24:$B$27) -> 0.0012586525 | Z31: =SUM(H31:R31) -> 0.503626 | AA31: ='CO2 per kg feed'!F84+'CH4 per kg feed'!F84*CF_GWP_CH4_fossil+'N2O per kg feed'!F84*CF_GWP_N2O -> 0.41909612
A32: 02211 | B32: Raw milk of cattle | C32: Dairy | D32: Ireland | E32: IE | F32: CO2 | G32: =SUM(H32:X32) -> 0.13988284 | H32: ='GHG detailed, absolute'!H32/Production!$G$9*AF_milk_IE -> 0.023357645 | I32: ='GHG detailed, absolute'!I32/Production!$G$9*AF_milk_IE -> 0.028358406 | L32: ='GHG detailed, absolute'!L32/Production!$G$9*AF_milk_IE -> 0.016829335 | N32: ='GHG detailed, absolute'!N32/Production!$G$9*AF_milk_IE -> 6.6962264e-05 | O32: ='GHG detailed, absolute'!O32/Production!$G$9*AF_milk_IE -> 0.0055404202 | P32: ='GHG detailed, absolute'!P32/Production!$G$9*AF_milk_IE -> 0.0026265212 | Q32: ='GHG detailed, absolute'!Q32/Production!$G$9*AF_milk_IE -> 0.0071204915 | R32: ='GHG detailed, absolute'!R32/Production!$G$9*AF_milk_IE -> 0.0071204915 | W32: ='GHG detailed, absolute'!W32/Production!$G$9*AF_milk_IE -> 0.047742952 | X32: ='GHG detailed, absolute'!X32/Production!$G$9*AF_milk_IE -> 0.0011196183
A33: 02211 | B33: Raw milk of cattle | C33: Dairy | D33: Ireland | E33: IE | F33: CH4, fossil | G33: =SUM(H33:X33) -> 0.0001907991 | H33: ='GHG detailed, absolute'!H33/Production!$G$9*AF_milk_IE -> 9.4555393e-07 | I33: ='GHG detailed, absolute'!I33/Production!$G$9*AF_milk_IE -> 9.9779578e-05 | L33: ='GHG detailed, absolute'!L33/Production!$G$9*AF_milk_IE -> 7.4548281e-06 | N33: ='GHG detailed, absolute'!N33/Production!$G$9*AF_milk_IE -> 1.9842204e-07 | O33: ='GHG detailed, absolute'!O33/Production!$G$9*AF_milk_IE -> 2.8963123e-06 | P33: ='GHG detailed, absolute'!P33/Production!$G$9*AF_milk_IE -> 0 | Q33: ='GHG detailed, absolute'!Q33/Production!$G$9*AF_milk_IE -> 1.3006337e-05 | R33: ='GHG detailed, absolute'!R33/Production!$G$9*AF_milk_IE -> 1.3006337e-05 | W33: ='GHG detailed, absolute'!W33/Production!$G$9*AF_milk_IE -> 5.1451797e-05 | X33: ='GHG detailed, absolute'!X33/Production!$G$9*AF_milk_IE -> 2.0599321e-06
A34: 02211 | B34: Raw milk of cattle | C34: Dairy | D34: Ireland | E34: IE | F34: CH4, biogenic | G34: =SUM(H34:T34) -> 0.023271936 | S34: ='GHG detailed, absolute'!S34/Production!$G$9*AF_milk_IE -> 0.020711846 | T34: ='GHG detailed, absolute'!T34/Production!$G$9*AF_milk_IE -> 0.0025600901 | U34: ='GHG detailed, absolute'!U34/Production!$G$9*AF_milk_IE -> 0.0025600901
A35: 02211 | B35: Raw milk of cattle | C35: Dairy | D35: Ireland | E35: IE | F35: N2O | G35: =SUM(H35:T35)+W35+X35 -> 0.00060627249 | H35: ='GHG detailed, absolute'!H35/Production!$G$9*AF_milk_IE -> 9.051268e-06 | I35: ='GHG detailed, absolute'!I35/Production!$G$9*AF_milk_IE -> 1.1553425e-06 | J35: ='GHG detailed, absolute'!J35/Production!$G$9*AF_milk_IE -> 0.00037061414 | K35: ='GHG detailed, absolute'!K35/Production!$G$9*AF_milk_IE -> 3.7061414e-05 | L35: ='GHG detailed, absolute'!L35/Production!$G$9*AF_milk_IE -> 4.522108e-07 | N35: ='GHG detailed, absolute'!N35/Production!$G$9*AF_milk_IE -> 2.8756737e-09 | O35: ='GHG detailed, absolute'!O35/Production!$G$9*AF_milk_IE -> 1.995777e-07 | P35: ='GHG detailed, absolute'!P35/Production!$G$9*AF_milk_IE -> 0 | Q35: ='GHG detailed, absolute'!Q35/Production!$G$9*AF_milk_IE -> 8.2317799e-07 | R35: ='GHG detailed, absolute'!R35/Production!$G$9*AF_milk_IE -> 8.2317799e-07 | T35: ='GHG detailed, absolute'!T35/Production!$G$9*AF_milk_IE -> 0.00018429537 | U35: ='GHG detailed, absolute'!U35/Production!$G$9*AF_milk_IE -> 0.00012886322 | V35: ='GHG detailed, absolute'!V35/Production!$G$9*AF_milk_IE -> 5.5432151e-05 | W35: ='GHG detailed, absolute'!W35/Production!$G$9*AF_milk_IE -> 1.753912e-06 | X35: ='GHG detailed, absolute'!X35/Production!$G$9*AF_milk_IE -> 4.0019475e-08
A36: 02211 | B36: Raw milk of cattle | C36: Dairy | D36: Ireland | E36: IE | F36: CO2e | G36: =SUM(H36:X36) -> 0.93942331 | H36: =SUMPRODUCT(H32:H35,'Parameters, general'!$B$24:$B$27) -> 0.025856819 | I36: =SUMPRODUCT(I32:I35,'Parameters, general'!$B$24:$B$27) -> 0.031647246 | J36: =SUMPRODUCT(J32:J35,'Parameters, general'!$B$24:$B$27) -> 0.10117766 | K36: =SUMPRODUCT(K32:K35,'Parameters, general'!$B$24:$B$27) -> 0.010117766 | L36: =SUMPRODUCT(L32:L35,'Parameters, general'!$B$24:$B$27) -> 0.017174943 | M36: =SUMPRODUCT(M32:M35,'Parameters, general'!$B$24:$B$27) -> 0 | N36: =SUMPRODUCT(N32:N35,'Parameters, general'!$B$24:$B$27) -> 7.36603e-05 | O36: =SUMPRODUCT(O32:O35,'Parameters, general'!$B$24:$B$27) -> 0.005681215 | ... T36: =SUMPRODUCT(T32:T35,'Parameters, general'!$B$24:$B$27) -> 0.11943507 | W36: =SUMPRODUCT(W32:W35,'Parameters, general'!$B$24:$B$27) -> 0.049755033 | X36: =SUMPRODUCT(X32:X35,'Parameters, general'!$B$24:$B$27) -> 0.0011919296 | Z36: =SUM(H36:R36) -> 0.20982145 | AA36: ='CO2 per kg feed'!F100+'CH4 per kg feed'!F100*CF_GWP_CH4_fossil+'N2O per kg feed'!F100*CF_GWP_N2O -> 0.13884603
A37: 02211 | B37: Raw milk of cattle | C37: Dairy | D37: Italy | E37: IT | F37: CO2 | G37: =SUM(H37:X37) -> 0.34128923 | H37: ='GHG detailed, absolute'!H37/Production!$H$9*AF_milk_IT -> 0.019822745 | I37: ='GHG detailed, absolute'!I37/Production!$H$9*AF_milk_IT -> 0.021540832 | L37: ='GHG detailed, absolute'!L37/Production!$H$9*AF_milk_IT -> 0.014071748 | N37: ='GHG detailed, absolute'!N37/Production!$H$9*AF_milk_IT -> 0.00023006348 | O37: ='GHG detailed, absolute'!O37/Production!$H$9*AF_milk_IT -> 0.0051846824 | P37: ='GHG detailed, absolute'!P37/Production!$H$9*AF_milk_IT -> 0.035542667 | Q37: ='GHG detailed, absolute'!Q37/Production!$H$9*AF_milk_IT -> 0.074949403 | R37: ='GHG detailed, absolute'!R37/Production!$H$9*AF_milk_IT -> 0.074949403 | W37: ='GHG detailed, absolute'!W37/Production!$H$9*AF_milk_IT -> 0.0939619 | X37: ='GHG detailed, absolute'!X37/Production!$H$9*AF_milk_IT -> 0.0010357867
A38: 02211 | B38: Raw milk of cattle | C38: Dairy | D38: Italy | E38: IT | F38: CH4, fossil | G38: =SUM(H38:X38) -> 0.0015417531 | H38: ='GHG detailed, absolute'!H38/Production!$H$9*AF_milk_IT -> 3.0269553e-06 | I38: ='GHG detailed, absolute'!I38/Production!$H$9*AF_milk_IT -> 7.5791816e-05 | L38: ='GHG detailed, absolute'!L38/Production!$H$9*AF_milk_IT -> 6.2333099e-06 | N38: ='GHG detailed, absolute'!N38/Production!$H$9*AF_milk_IT -> 7.4416453e-07 | O38: ='GHG detailed, absolute'!O38/Production!$H$9*AF_milk_IT -> 4.5275144e-06 | P38: ='GHG detailed, absolute'!P38/Production!$H$9*AF_milk_IT -> 0 | Q38: ='GHG detailed, absolute'!Q38/Production!$H$9*AF_milk_IT -> 0.00051920655 | R38: ='GHG detailed, absolute'!R38/Production!$H$9*AF_milk_IT -> 0.00051920655 | W38: ='GHG detailed, absolute'!W38/Production!$H$9*AF_milk_IT -> 0.00040847359 | X38: ='GHG detailed, absolute'!X38/Production!$H$9*AF_milk_IT -> 4.5426784e-06
A39: 02211 | B39: Raw milk of cattle | C39: Dairy | D39: Italy | E39: IT | F39: CH4, biogenic | G39: =SUM(H39:T39) -> 0.02471509 | S39: ='GHG detailed, absolute'!S39/Production!$H$9*AF_milk_IT -> 0.019963522 | T39: ='GHG detailed, absolute'!T39/Production!$H$9*AF_milk_IT -> 0.0047515677 | U39: ='GHG detailed, absolute'!U39/Production!$H$9*AF_milk_IT -> 0.0047515677
A40: 02211 | B40: Raw milk of cattle | C40: Dairy | D40: Italy | E40: IT | F40: N2O | G40: =SUM(H40:T40)+W40+X40 -> 0.00065003108 | H40: ='GHG detailed, absolute'!H40/Production!$H$9*AF_milk_IT -> 4.1284171e-06 | I40: ='GHG detailed, absolute'!I40/Production!$H$9*AF_milk_IT -> 8.7758945e-07 | J40: ='GHG detailed, absolute'!J40/Production!$H$9*AF_milk_IT -> 0.00025616828 | K40: ='GHG detailed, absolute'!K40/Production!$H$9*AF_milk_IT -> 2.5616828e-05 | L40: ='GHG detailed, absolute'!L40/Production!$H$9*AF_milk_IT -> 3.7811335e-07 | N40: ='GHG detailed, absolute'!N40/Production!$H$9*AF_milk_IT -> 9.5877063e-09 | O40: ='GHG detailed, absolute'!O40/Production!$H$9*AF_milk_IT -> 1.906293e-07 | P40: ='GHG detailed, absolute'!P40/Production!$H$9*AF_milk_IT -> 0 | Q40: ='GHG detailed, absolute'!Q40/Production!$H$9*AF_milk_IT -> 3.0526234e-05 | R40: ='GHG detailed, absolute'!R40/Production!$H$9*AF_milk_IT -> 3.0526234e-05 | T40: ='GHG detailed, absolute'!T40/Production!$H$9*AF_milk_IT -> 0.00029747782 | U40: ='GHG detailed, absolute'!U40/Production!$H$9*AF_milk_IT -> 0.00019581165 | V40: ='GHG detailed, absolute'!V40/Production!$H$9*AF_milk_IT -> 0.00010166616 | W40: ='GHG detailed, absolute'!W40/Production!$H$9*AF_milk_IT -> 4.0889399e-06 | X40: ='GHG detailed, absolute'!X40/Production!$H$9*AF_milk_IT -> 4.2415983e-08
A41: 02211 | B41: Raw milk of cattle | C41: Dairy | D41: Italy | E41: IT | F41: CO2e | G41: =SUM(H41:X41) -> 1.2319994 | H41: =SUMPRODUCT(H37:H40,'Parameters, general'!$B$24:$B$27) -> 0.021040006 | I41: =SUMPRODUCT(I37:I40,'Parameters, general'!$B$24:$B$27) -> 0.02403901 | J41: =SUMPRODUCT(J37:J40,'Parameters, general'!$B$24:$B$27) -> 0.06993394 | K41: =SUMPRODUCT(K37:K40,'Parameters, general'!$B$24:$B$27) -> 0.006993394 | L41: =SUMPRODUCT(L37:L40,'Parameters, general'!$B$24:$B$27) -> 0.014360726 | M41: =SUMPRODUCT(M37:M40,'Parameters, general'!$B$24:$B$27) -> 0 | N41: =SUMPRODUCT(N37:N40,'Parameters, general'!$B$24:$B$27) -> 0.00025485703 | O41: =SUMPRODUCT(O37:O40,'Parameters, general'!$B$24:$B$27) -> 0.0053716442 | ... T41: =SUMPRODUCT(T37:T40,'Parameters, general'!$B$24:$B$27) -> 0.20950377 | W41: =SUMPRODUCT(W37:W40,'Parameters, general'!$B$24:$B$27) -> 0.10725069 | X41: =SUMPRODUCT(X37:X40,'Parameters, general'!$B$24:$B$27) -> 0.0011827381 | Z41: =SUM(H41:R41) -> 0.37504708 | AA41: ='CO2 per kg feed'!F116+'CH4 per kg feed'!F116*CF_GWP_CH4_fossil+'N2O per kg feed'!F116*CF_GWP_N2O -> 0.2926376
...

Sheet Footprints, per kg meat
A2: Footprints (per kg of meat)
A5: Animal products | F5: Climate | L5: Land | M5: Nitrogen | N5: Phosphorus | O5: Water | P5: Pesticides | Q5: Biodiversity | R5: Ammonia | S5: Labour | T5: Animal welfare | U5: Use of antibiotics
A6: Code | B6: Name | C6: Category | D6: Country | E6: Country code | F6: Carbon footprint, kg CO2e/kg | G6: Carbon dioxide, kg CO2/kg | H6: Methane, fossil, kg CH4/kg | I6: Methane, biogenic, kg CH4/kg | J6: Nitrous oxide, kg N2O/kg | K6: HFCs, kg HFCs/kg | L6: Cropland use, m2/kg | M6: New N input, kg N/kg | N6: New P input, kg P/kg | O6: Blue freshwater use, m3/kg | P6: Pesticide use, g a.i./kg | Q6: Extinction rate, E/MSY/kg | R6: Ammonia emission, kg NH3/kg | S6: Labour requirements, h/kg | T6: Animal welfare index per kg of bonefree meat | U6: Antibiotics use indicator/kg
