Workbook
Name Ability_to_perceive_handling: 'Parameters, general'!$B$20
Name Bonefree_outof_CW_DE: 'Parameters, country spec'!$D$10
Name Bonefree_outof_CW_DK: 'Parameters, country spec'!$B$10
Name Bonefree_outof_CW_ES: 'Parameters, country spec'!$K$10
Name Bonefree_outof_CW_FR: 'Parameters, country spec'!$C$10
Name Bonefree_outof_CW_GR: 'Parameters, country spec'!$E$10
Name Bonefree_outof_CW_HU: 'Parameters, country spec'!$F$10
Name Bonefree_outof_CW_IE: 'Parameters, country spec'!$G$10
Name Bonefree_outof_CW_IT: 'Parameters, country spec'!$H$10
Name Bonefree_outof_CW_NL: 'Parameters, country spec'!$I$10
Name Bonefree_outof_CW_PL: 'Parameters, country spec'!$J$10
Name Bonefree_outof_CW_SE: 'Parameters, country spec'!$L$10
Name CF_GWP_CH4_fossil: 'Parameters, general'!$B$15
Name CF_GWP_N2O: 'Parameters, general'!$B$17
Name EF_biofuel_CH4: 'Parameters, general'!$C$7
Name EF_biofuel_N2O: 'Parameters, general'!$D$7
Name EF_biofuels_CO2: 'Parameters, general'!$B$7
Name EF_el_CH4_BR: 'Parameters, general'!$B$32
Name EF_el_CH4_DE: 'Parameters, country spec'!$D$44
Name EF_el_CH4_DK: 'Parameters, country spec'!$B$44
Name EF_el_CH4_ES: 'Parameters, country spec'!$K$44
Name EF_el_CH4_FR: 'Parameters, country spec'!$C$44
Name EF_el_CH4_GR: 'Parameters, country spec'!$E$44
Name EF_el_CH4_HU: 'Parameters, country spec'!$F$44
Name EF_el_CH4_IE: 'Parameters, country spec'!$G$44
Name EF_el_CH4_IT: 'Parameters, country spec'!$H$44
Name EF_el_CH4_NL: 'Parameters, country spec'!$I$44
Name EF_el_CH4_PL: 'Parameters, country spec'!$J$44
Name EF_el_CH4_SE: 'Parameters, country spec'!$L$44
Name EF_el_CO2_BR: 'Parameters, general'!$B$31
Name EF_el_CO2_DE: 'Parameters, country spec'!$D$43
Name EF_el_CO2_DK: 'Parameters, country spec'!$B$43
Name EF_el_CO2_ES: 'Parameters, country spec'!$K$43
Name EF_el_CO2_FR: 'Parameters, country spec'!$C$43
Name EF_el_CO2_GR: 'Parameters, country spec'!$E$43
Name EF_el_CO2_HU: 'Parameters, country spec'!$F$43
Name EF_el_CO2_IE: 'Parameters, country spec'!$G$43
Name EF_el_CO2_IT: 'Parameters, country spec'!$H$43
Name EF_el_CO2_NL: 'Parameters, country spec'!$I$43
Name EF_el_CO2_PL: 'Parameters, country spec'!$J$43
Name EF_el_CO2_SE: 'Parameters, country spec'!$L$43
Name EF_el_N2O_BR: 'Parameters, general'!$B$33
Name EF_el_N2O_DE: 'Parameters, country spec'!$D$46
Name EF_el_N2O_DK: 'Parameters, country spec'!$B$46
Name EF_el_N2O_ES: 'Parameters, country spec'!$K$46
Name EF_el_N2O_FR: 'Parameters, country spec'!$C$46
Name EF_el_N2O_GR: 'Parameters, country spec'!$E$46
Name EF_el_N2O_HU: 'Parameters, country spec'!$F$46
Name EF_el_N2O_IE: 'Parameters, country spec'!$G$46
Name EF_el_N2O_IT: 'Parameters, country spec'!$H$46
Name EF_el_N2O_NL: 'Parameters, country spec'!$I$46
Name EF_el_N2O_PL: 'Parameters, country spec'!$J$46
Name EF_el_N2O_SE: 'Parameters, country spec'!$L$46
Name EF_electricity: 'Parameters, country spec'!$L$42
Name EF_gas_CH4: 'Parameters, general'!$C$6
Name EF_gas_CO2: 'Parameters, general'!$B$6
Name EF_gas_N2O: 'Parameters, general'!$D$6
Name EF_GWP_CH4_biog: 'Parameters, general'!#REF!
Name EF_indirect_N2O_DE: 'Parameters, country spec'!$D$57
Name EF_indirect_N2O_DK: 'Parameters, country spec'!$B$57

Sheet README
A2: Read me
A4: This is a file that contains the calculations of the footprints from egg production.
E5: 1 | F5: Mj/kg
E6: =E5/3.6 -> 0.27777778
A7: Assumptions:
A8: - All hens are also eaten
A9: - Impacts are allocated equally across egg and hen meat
A17: Color codes:
B19: Results
B20: Sheets for input
B21: Intermediate calculations
B22: Figures
A26: Att göra:
A27: Fyll i olika gödselsystem från NIR-rapporterna - ev. gjort? Kolla med Ludvig
A28: Lägg in landspecifika foderstater, åtminstonde Sverige efter återkoppling med Svenska Ägg
A29: Noggrannare energiförbrukning i stallar - låg prio

Sheet Figures
A2: Figures
A4: Greenhouse gas emission for egg across countries, to farmgate
B6: Production of mineral fertilizer | C6: Production of capital goods | D6: Emissions from soil | E6: Diesel use field machinary | F6: Energy use for feed processing | G6: Land use change emissions | H6: Feed transports | I6: Enteric fermentation | J6: Manure management | K6: Energy use in stables | L6: Energy use for slaughter | M6: Tot | P6: Order this study: | R6: Order Lesschen:
A7: Poland | B7: ='GHG det, per kg egg'!H51 -> 0.19317539 | C7: ='GHG det, per kg egg'!I51 -> 0.071839061 | D7: ='GHG det, per kg egg'!J51+'GHG det, per kg egg'!K51 -> 0.49394546 | E7: ='GHG det, per kg egg'!L51 -> 0.089413877 | F7: ='GHG det, per kg egg'!O51 -> 0.12938673 | G7: ='GHG det, per kg egg'!P51 -> 0.065591671 | H7: ='GHG det, per kg egg'!R51 -> 0.014379837 | I7: ='GHG det, per kg egg'!S51 -> 0 | J7: ='GHG det, per kg egg'!T51 -> 0.054156647 | K7: ='GHG det, per kg egg'!W51 -> 0.10362621 | L7: ='GHG det, per kg egg'!X51 -> 0.33544575 | M7: =SUM(B7:L7) -> 1.5509606
A8: Netherlands | B8: ='GHG det, per kg egg'!H46 -> 0.14373342 | C8: ='GHG det, per kg egg'!I46 -> 0.068740876 | D8: ='GHG det, per kg egg'!J46+'GHG det, per kg egg'!K46 -> 0.33152278 | E8: ='GHG det, per kg egg'!L46 -> 0.06429864 | F8: ='GHG det, per kg egg'!O46 -> 0.10282131 | G8: ='GHG det, per kg egg'!P46 -> 0.052232875 | H8: ='GHG det, per kg egg'!R46 -> 0.051383575 | I8: ='GHG det, per kg egg'!S46 -> 0 | J8: ='GHG det, per kg egg'!T46 -> 0.050489022 | K8: ='GHG det, per kg egg'!W46 -> 0.053148366 | L8: ='GHG det, per kg egg'!X46 -> 0.20433446 | M8: =SUM(B8:L8) -> 1.1227053 | P8: Poland | R8: Greece
A9: Germany | B9: ='GHG det, per kg egg'!H21 -> 0.15738442 | C9: ='GHG det, per kg egg'!I21 -> 0.06902848 | D9: ='GHG det, per kg egg'!J21+'GHG det, per kg egg'!K21 -> 0.36644985 | E9: ='GHG det, per kg egg'!L21 -> 0.06272089 | F9: ='GHG det, per kg egg'!O21 -> 0.10206319 | G9: ='GHG det, per kg egg'!P21 -> 0.052704928 | H9: ='GHG det, per kg egg'!R21 -> 0.048481418 | I9: ='GHG det, per kg egg'!S21 -> 0 | J9: ='GHG det, per kg egg'!T21 -> 0.045352891 | K9: ='GHG det, per kg egg'!W21 -> 0.049559221 | L9: ='GHG det, per kg egg'!X21 -> 0.195012 | M9: =SUM(B9:L9) -> 1.1487573 | P9: Netherlands | R9: Netherlands
A10: Sweden | B10: ='GHG det, per kg egg'!H61 -> 0.18180101 | C10: ='GHG det, per kg egg'!I61 -> 0.069714784 | D10: ='GHG det, per kg egg'!J61+'GHG det, per kg egg'!K61 -> 0.44795079 | E10: ='GHG det, per kg egg'!L61 -> 0.085329483 | F10: ='GHG det, per kg egg'!O61 -> 0.083956516 | G10: ='GHG det, per kg egg'!P61 -> 0.074353186 | H10: ='GHG det, per kg egg'!R61 -> 0.026366678 | I10: ='GHG det, per kg egg'!S61 -> 0 | J10: ='GHG det, per kg egg'!T61 -> 0.05254583 | K10: ='GHG det, per kg egg'!W61 -> 0.0093610106 | L10: ='GHG det, per kg egg'!X61 -> 0.046084425 | M10: =SUM(B10:L10) -> 1.0774637 | P10: Germany | R10: Poland
A11: Denmark | B11: ='GHG det, per kg egg'!H11 -> 0.17108129 | C11: ='GHG det, per kg egg'!I11 -> 0.068319832 | D11: ='GHG det, per kg egg'!J11+'GHG det, per kg egg'!K11 -> 0.40468265 | E11: ='GHG det, per kg egg'!L11 -> 0.066030462 | F11: ='GHG det, per kg egg'!O11 -> 0.096049676 | G11: ='GHG det, per kg egg'!P11 -> 0.038249404 | H11: ='GHG det, per kg egg'!R11 -> 0.032433879 | I11: ='GHG det, per kg egg'!S11 -> 0 | J11: ='GHG det, per kg egg'!T11 -> 0.030299277 | K11: ='GHG det, per kg egg'!W11 -> 0.0097389846 | L11: ='GHG det, per kg egg'!X11 -> 0.091582817 | M11: =SUM(B11:L11) -> 1.0084683 | P11: Sweden | R11: Hungary
A12: Greece | B12: ='GHG det, per kg egg'!H26 -> 0.15871438 | C12: ='GHG det, per kg egg'!I26 -> 0.066967213 | D12: ='GHG det, per kg egg'!J26+'GHG det, per kg egg'!K26 -> 0.30572191 | E12: ='GHG det, per kg egg'!L26 -> 0.095449884 | F12: ='GHG det, per kg egg'!O26 -> 0.10401129 | G12: ='GHG det, per kg egg'!P26 -> 0.095424384 | H12: ='GHG det, per kg egg'!R26 -> 0.070067523 | I12: ='GHG det, per kg egg'!S26 -> 0 | J12: ='GHG det, per kg egg'!T26 -> 0.056401489 | K12: ='GHG det, per kg egg'!W26 -> 0.06838336 | L12: ='GHG det, per kg egg'!X26 -> 0.24390587 | M12: =SUM(B12:L12) -> 1.2650473 | P12: Denmark | R12: Ireland
A13: France | B13: ='GHG det, per kg egg'!H16 -> 0.15699805 | C13: ='GHG det, per kg egg'!I16 -> 0.068319832 | D13: ='GHG det, per kg egg'!J16+'GHG det, per kg egg'!K16 -> 0.37978256 | E13: ='GHG det, per kg egg'!L16 -> 0.065536275 | F13: ='GHG det, per kg egg'!O16 -> 0.08353621 | G13: ='GHG det, per kg egg'!P16 -> 0.037452199 | H13: ='GHG det, per kg egg'!R16 -> 0.032433879 | I13: ='GHG det, per kg egg'!S16 -> 0 | J13: ='GHG det, per kg egg'!T16 -> 0.030127457 | K13: ='GHG det, per kg egg'!W16 -> 0.0097389846 | L13: ='GHG det, per kg egg'!X16 -> 0.091582817 | M13: =SUM(B13:L13) -> 0.95550826 | P13: Greece | R13: Italy
A14: Spain | B14: ='GHG det, per kg egg'!H56 -> 0.20616949 | C14: ='GHG det, per kg egg'!I56 -> 0.070512407 | D14: ='GHG det, per kg egg'!J56+'GHG det, per kg egg'!K56 -> 0.38418544 | E14: ='GHG det, per kg egg'!L56 -> 0.10732139 | F14: ='GHG det, per kg egg'!O56 -> 0.093303903 | G14: ='GHG det, per kg egg'!P56 -> 0.070871921 | H14: ='GHG det, per kg egg'!R56 -> 0.058458755 | I14: ='GHG det, per kg egg'!S56 -> 0 | J14: ='GHG det, per kg egg'!T56 -> 0.044388544 | K14: ='GHG det, per kg egg'!W56 -> 0.029612657 | L14: ='GHG det, per kg egg'!X56 -> 0.14320275 | M14: =SUM(B14:L14) -> 1.2080273 | P14: France | R14: Germany
A15: Italy | B15: ='GHG det, per kg egg'!H41 -> 0.13100937 | C15: ='GHG det, per kg egg'!I41 -> 0.065787258 | D15: ='GHG det, per kg egg'!J41+'GHG det, per kg egg'!K41 -> 0.32874755 | E15: ='GHG det, per kg egg'!L41 -> 0.065325241 | F15: ='GHG det, per kg egg'!O41 -> 0.092453677 | G15: ='GHG det, per kg egg'!P41 -> 0.067969851 | H15: ='GHG det, per kg egg'!R41 -> 0.059190212 | I15: ='GHG det, per kg egg'!S41 -> 0 | J15: ='GHG det, per kg egg'!T41 -> 0.048798559 | K15: ='GHG det, per kg egg'!W41 -> 0.043143257 | L15: ='GHG det, per kg egg'!X41 -> 0.17834716 | M15: =SUM(B15:L15) -> 1.0807721 | P15: Spain | R15: France
A16: Hungary | B16: ='GHG det, per kg egg'!H31 -> 0.15956254 | C16: ='GHG det, per kg egg'!I31 -> 0.067789637 | D16: ='GHG det, per kg egg'!J31+'GHG det, per kg egg'!K31 -> 0.3972062 | E16: ='GHG det, per kg egg'!L31 -> 0.077263825 | F16: ='GHG det, per kg egg'!O31 -> 0.096902579 | G16: ='GHG det, per kg egg'!P31 -> 0.074700237 | H16: ='GHG det, per kg egg'!R31 -> 0.047563307 | I16: ='GHG det, per kg egg'!S31 -> 0 | J16: ='GHG det, per kg egg'!T31 -> 0.038177355 | K16: ='GHG det, per kg egg'!W31 -> 0.047422491 | L16: ='GHG det, per kg egg'!X31 -> 0.18946206 | M16: =SUM(B16:L16) -> 1.1960502 | P16: Italy | R16: Spain
A17: Ireland | B17: ='GHG det, per kg egg'!H36 -> 0.12039667 | C17: ='GHG det, per kg egg'!I36 -> 0.065670826 | D17: ='GHG det, per kg egg'!J36+'GHG det, per kg egg'!K36 -> 0.26684665 | E17: ='GHG det, per kg egg'!L36 -> 0.075167475 | F17: ='GHG det, per kg egg'!O36 -> 0.092436648 | G17: ='GHG det, per kg egg'!P36 -> 0.016189852 | H17: ='GHG det, per kg egg'!R36 -> 0.016006186 | I17: ='GHG det, per kg egg'!S36 -> 0 | J17: ='GHG det, per kg egg'!T36 -> 0.029703521 | K17: ='GHG det, per kg egg'!W36 -> 0.040838709 | L17: ='GHG det, per kg egg'!X36 -> 0.17236132 | M17: =SUM(B17:L17) -> 0.89561785 | P17: Hungary | R17: Denmark
P18: Ireland | R18: Sweden
A23: Comment:
A24: - Hungary and Italy low feed emissions because of lower N2O emission factors
A25: - Ireland has a high egg yield
A30: Water use - have not checked!!
A33: Denmark | B33: 0.34945447
A34: France | B34: 0.47801159
A35: Germany | B35: 0.35489833
A36: Greece | B36: 0.38101452
A37: Hungary | B37: 0.34634088
A38: Ireland | B38: 0.33400348
A39: Italy | B39: 0.68514744
A40: Netherlands | B40: 0.47153366
A41: Poland | B41: 0.34636616
A42: Spain | B42: 1.2637786
A43: Sweden | B43: 0.33340769

Sheet Footprints, per kg egg
A2: Footprints (per kg of egg) | M2: * Adjusted for manure
A5: Animal products | F5: Climate | L5: Land | M5: Nitrogen* | N5: Phosphorus | O5: Water | P5: Pesticides | Q5: Biodiversity | R5: Ammonia | S5: Labour | T5: Animal welfare | U5: Use of antibiotics
A6: Code | B6: Name | C6: Category | D6: Country | E6: Country code | F6: Carbon footprint, kg CO2e/kg | G6: Carbon dioxide, kg CO2/kg | H6: Methane, fossil, kg CH4/kg | I6: Methane, biogenic, kg CH4/kg | J6: Nitrous oxide, kg N2O/kg | K6: HFCs, kg HFCs/kg | L6: Cropland use, m2/kg | M6: New N input, kg N/kg | N6: New P input, kg P/kg | O6: Blue freshwater use, m3/kg | P6: Pesticide use, g a.i./kg | Q6: Extinction rate, E/MSY/kg | R6: Ammonia emission, kg NH3/kg | S6: Labour requirements, h/kg | T6: Animal welfare index per kg of egg | U6: Antibiotica use indicator
A7: 0231 | B7: Hen eggs in shell | C7: Egg | D7: Denmark | E7: DK | F7: ='GHG det, per kg egg'!G11 -> 1.0255664 | G7: ='GHG det, per kg egg'!G7 -> 0.54071427 | H7: ='GHG det, per kg egg'!G8 -> 0.00075243675 | I7: ='GHG det, per kg egg'!G9 -> 0.0011044964 | J7: ='GHG det, per kg egg'!G10 -> 0.0015846449 | L7: ='EFP per kg feed'!F28*FCR_bonefree_incl_parents_DK -> 5.616688 | M7: ='EFP per kg feed'!G28*FCR_bonefree_incl_parents_DK-Manure_repl_factor_DK*Excreted_N_after_losses_DK -> 0.063176073 | N7: ='EFP per kg feed'!H28*FCR_bonefree_incl_parents_DK -> 0.0059161783 | O7: ='EFP per kg feed'!I28*FCR_bonefree_incl_parents_DK+(Production!B5*(Water_drinking_hens_DK+Water_service_hens_DK)*365+Production!B6*(Water_drinking_recruit_DK+Water_service_recruit_DK)*365)/1000/Production!B14 -> 0.056879173 | P7: ='EFP per kg feed'!J28*FCR_bonefree_incl_parents_DK -> 0.94916172 | Q7: ='EFP per kg feed'!K28*FCR_bonefree_incl_parents_DK -> 9.690024e-11 | R7: ='EFP per kg feed'!L28*FCR_bonefree_incl_parents_DK+NH3_per_kg_DK -> 0.0029654015 | S7: ='Parameters, country spec'!#REF!*Production!C15 -> #REF! | T7: 6.7130159 | U7: 0.24294592
A8: 0231 | B8: Hen eggs in shell | C8: Egg | D8: France | E8: FR | F8: ='GHG det, per kg egg'!G16 -> 0.97468591 | G8: ='GHG det, per kg egg'!G12 -> 0.52147342 | H8: ='GHG det, per kg egg'!G13 -> 0.0007475364 | I8: ='GHG det, per kg egg'!G14 -> 0.0010990286 | J8: ='GHG det, per kg egg'!G15 -> 0.0014698247 | L8: ='EFP per kg feed'!F29*FCR_bonefree_incl_parents_FR -> 3.5335154 | M8: ='EFP per kg feed'!G29*FCR_bonefree_incl_parents_FR-Manure_repl_factor_FR*Excreted_N_after_losses_FR -> 0.047190605 | N8: ='EFP per kg feed'!H29*FCR_bonefree_incl_parents_FR -> 0.0061376396 | O8: ='EFP per kg feed'!I29*FCR_bonefree_incl_parents_FR+(Production!C5*(Water_drinking_hens_FR+Water_service_hens_FR)*365+Production!C6*(Water_drinking_recruit_FR+Water_service_recruit_FR)*365)/1000/Production!C14 -> 0.035796233 | P8: ='EFP per kg feed'!J29*FCR_bonefree_incl_parents_FR -> 0.75523228 | Q8: ='EFP per kg feed'!K29*FCR_bonefree_incl_parents_FR -> 5.3612845e-11 | R8: ='EFP per kg feed'!L29*FCR_bonefree_incl_parents_FR+NH3_per_kg_FR -> 0.0040961694 | S8: ='Parameters, country spec'!#REF!*Production!C16 -> #REF! | T8: 6.8052207 | U8: 0.35528489
A9: 0231 | B9: Hen eggs in shell | C9: Egg | D9: Germany | E9: DE | F9: ='GHG det, per kg egg'!G21 -> 1.1753967 | G9: ='GHG det, per kg egg'!G17 -> 0.70744124 | H9: ='GHG det, per kg egg'!G18 -> 0.0010247774 | I9: ='GHG det, per kg egg'!G19 -> 0.0016549103 | J9: ='GHG det, per kg egg'!G20 -> 0.0014385879 | L9: ='EFP per kg feed'!F41*FCR_bonefree_incl_parents_DE -> 3.3708652 | M9: ='EFP per kg feed'!G41*FCR_bonefree_incl_parents_DE-Manure_repl_factor_DE*Excreted_N_after_losses_DE -> 0.046972314 | N9: ='EFP per kg feed'!H41*FCR_bonefree_incl_parents_DE -> 0.0055151775 | O9: ='EFP per kg feed'!I41*FCR_bonefree_incl_parents_DE+(Production!D5*(Water_drinking_hens_DE+Water_service_hens_DE)*365+Production!D6*(Water_drinking_recruit_DE+Water_service_recruit_DE)*365)/1000/Production!D14 -> 0.011097036 | P9: ='EFP per kg feed'!J41*FCR_bonefree_incl_parents_DE -> 0.60904943 | Q9: ='EFP per kg feed'!K41*FCR_bonefree_incl_parents_DE -> 4.8671923e-11 | R9: ='EFP per kg feed'!L41*FCR_bonefree_incl_parents_DE+NH3_per_kg_DE -> 0.0034408338 | S9: ='Parameters, country spec'!#REF!*Production!D16 -> #REF! | T9: 6.9023384 | U9: 0.59524888
A10: 0231 | B10: Hen eggs in shell | C10: Egg | D10: Greece | E10: GR | F10: ='GHG det, per kg egg'!G26 -> 1.4138091 | G10: ='GHG det, per kg egg'!G22 -> 0.99482438 | H10: ='GHG det, per kg egg'!G23 -> 0.0014439606 | I10: ='GHG det, per kg egg'!G24 -> 0.0020715452 | J10: ='GHG det, per kg egg'!G25 -> 0.0011722453 | L10: ='EFP per kg feed'!F42*FCR_bonefree_incl_parents_GR -> 8.5177177 | M10: ='EFP per kg feed'!G42*FCR_bonefree_incl_parents_GR-Manure_repl_factor_GR*Excreted_N_after_losses_GR -> 0.079982431 | N10: ='EFP per kg feed'!H42*FCR_bonefree_incl_parents_GR -> 0.0059624024 | O10: ='EFP per kg feed'!I42*FCR_bonefree_incl_parents_GR+(Production!E5*(Water_drinking_hens_GR+Water_service_hens_GR)*365+Production!E6*(Water_drinking_recruit_GR+Water_service_recruit_GR)*365)/1000/Production!E14 -> 0.0084280637 | P10: ='EFP per kg feed'!J42*FCR_bonefree_incl_parents_GR -> 0.89997865 | Q10: ='EFP per kg feed'!K42*FCR_bonefree_incl_parents_GR -> 4.0102462e-10 | R10: ='EFP per kg feed'!L53*FCR_bonefree_incl_parents_GR+NH3_per_kg_GR -> 0.0059379151 | S10: ='Parameters, country spec'!#REF!*Production!E16 -> #REF! | T10: 9.9243984 | U10: 1.1614202
A11: 0231 | B11: Hen eggs in shell | C11: Egg | D11: Hungary | E11: HU | F11: ='GHG det, per kg egg'!G31 -> 1.2816417 | G11: ='GHG det, per kg egg'!G27 -> 0.78711453 | H11: ='GHG det, per kg egg'!G28 -> 0.0012309277 | I11: ='GHG det, per kg egg'!G29 -> 0.0013810301 | J11: ='GHG det, per kg egg'!G30 -> 0.0015405045 | L11: ='EFP per kg feed'!F65*FCR_bonefree_incl_parents_HU -> 4.3933215 | M11: ='EFP per kg feed'!G65*FCR_bonefree_incl_parents_HU-Manure_repl_factor_HU*Excreted_N_after_losses_HU -> 0.054141474 | N11: ='EFP per kg feed'!H65*FCR_bonefree_incl_parents_HU -> 0.010468686 | O11: ='EFP per kg feed'!I65*FCR_bonefree_incl_parents_HU+(Production!F5*(Water_drinking_hens_HU+Water_service_hens_HU)*365+Production!F6*(Water_drinking_recruit_HU+Water_service_recruit_HU)*365)/1000/Production!F14 -> 0.021804263 | P11: ='EFP per kg feed'!J65*FCR_bonefree_incl_parents_HU -> 0.51569057 | Q11: ='EFP per kg feed'!K65*FCR_bonefree_incl_parents_HU -> 7.7125061e-11 | R11: ='EFP per kg feed'!L65*FCR_bonefree_incl_parents_HU+NH3_per_kg_HU -> 0.0034455066 | S11: ='Parameters, country spec'!#REF!*Production!F16 -> #REF! | T11: 10.424279 | U11: 0.90521123
A12: 0231 | B12: Hen eggs in shell | C12: Egg | D12: Ireland | E12: IE | F12: ='GHG det, per kg egg'!G36 -> 0.9219189 | G12: ='GHG det, per kg egg'!G32 -> 0.57527213 | H12: ='GHG det, per kg egg'!G33 -> 0.0008010737 | I12: ='GHG det, per kg egg'!G34 -> 0.001080483 | J12: ='GHG det, per kg egg'!G35 -> 0.0010754642 | L12: ='EFP per kg feed'!F77*FCR_bonefree_incl_parents_IE -> 4.1427031 | M12: ='EFP per kg feed'!G77*FCR_bonefree_incl_parents_IE-Manure_repl_factor_IE*Excreted_N_after_losses_IE -> 0.057635783 | N12: ='EFP per kg feed'!H77*FCR_bonefree_incl_parents_IE -> 0.0048210898 | O12: ='EFP per kg feed'!I77*FCR_bonefree_incl_parents_IE+(Production!G5*(Water_drinking_hens_IE+Water_service_hens_IE)*365+Production!G6*(Water_drinking_recruit_IE+Water_service_recruit_IE)*365)/1000/Production!G14 -> 0.017817802 | P12: ='EFP per kg feed'!J77*FCR_bonefree_incl_parents_IE -> 0.84458898 | Q12: ='EFP per kg feed'!K77*FCR_bonefree_incl_parents_IE -> 6.663768e-11 | R12: ='EFP per kg feed'!L77*FCR_bonefree_incl_parents_IE+NH3_per_kg_IE -> 0.0023084452 | S12: ='Parameters, country spec'!#REF!*Production!G16 -> #REF! | T12: 7.3565669 | U12: 0.39407226
A13: 0231 | B13: Hen eggs in shell | C13: Egg | D13: Italy | E13: IT | F13: ='GHG det, per kg egg'!G41 -> 1.1943313 | G13: ='GHG det, per kg egg'!G37 -> 0.75633566 | H13: ='GHG det, per kg egg'!G38 -> 0.0016813686 | I13: ='GHG det, per kg egg'!G39 -> 0.0017878153 | J13: ='GHG det, per kg egg'!G40 -> 0.0012440286 | L13: ='EFP per kg feed'!F89*FCR_bonefree_incl_parents_IT -> 3.6595185 | M13: ='EFP per kg feed'!G89*FCR_bonefree_incl_parents_IT-Manure_repl_factor_IT*Excreted_N_after_losses_IT -> 0.046694889 | N13: ='EFP per kg feed'!H89*FCR_bonefree_incl_parents_IT -> 0.0076833135 | O13: ='EFP per kg feed'!I89*FCR_bonefree_incl_parents_IT+(Production!H5*(Water_drinking_hens_IT+Water_service_hens_IT)*365+Production!H6*(Water_drinking_recruit_IT+Water_service_recruit_IT)*365)/1000/Production!H14 -> 0.059517312 | P13: ='EFP per kg feed'!J89*FCR_bonefree_incl_parents_IT -> 0.46710206 | Q13: ='EFP per kg feed'!K89*FCR_bonefree_incl_parents_IT -> 1.9689925e-10 | R13: ='EFP per kg feed'!L89*FCR_bonefree_incl_parents_IT+NH3_per_kg_IT -> 0.0056661516 | S13: ='Parameters, country spec'!#REF!*Production!H16 -> #REF! | T13: 8.5079713 | U13: 1.4643901
A14: 0231 | B14: Hen eggs in shell | C14: Egg | D14: Netherlands | E14: NL | F14: ='GHG det, per kg egg'!G46 -> 1.1437212 | G14: ='GHG det, per kg egg'!G42 -> 0.70349586 | H14: ='GHG det, per kg egg'!G43 -> 0.0010587777 | I14: ='GHG det, per kg egg'!G44 -> 0.0018438079 | J14: ='GHG det, per kg egg'!G45 -> 0.001314619 | L14: ='EFP per kg feed'!F101*FCR_bonefree_incl_parents_NL -> 3.5412689 | M14: ='EFP per kg feed'!G101*FCR_bonefree_incl_parents_NL-Manure_repl_factor_NL*Excreted_N_after_losses_NL -> 0.047811607 | N14: ='EFP per kg feed'!H101*FCR_bonefree_incl_parents_NL -> 0.0061450559 | O14: ='EFP per kg feed'!I101*FCR_bonefree_incl_parents_NL+(Production!I5*(Water_drinking_hens_NL+Water_service_hens_NL)*365+Production!I6*(Water_drinking_recruit_NL+Water_service_recruit_NL)*365)/1000/Production!I14 -> 0.018275486 | P14: ='EFP per kg feed'!J101*FCR_bonefree_incl_parents_NL -> 0.48265267 | Q14: ='EFP per kg feed'!K101*FCR_bonefree_incl_parents_NL -> 5.4888891e-11 | R14: ='EFP per kg feed'!L101*FCR_bonefree_incl_parents_NL+NH3_per_kg_NL -> 0.0023889134 | S14: ='Parameters, country spec'!#REF!*Production!I16 -> #REF! | T14: 8.1386212 | U14: 0.30037527
A15: 0231 | B15: Hen eggs in shell | C15: Egg | D15: Poland | E15: PL | F15: ='GHG det, per kg egg'!G51 -> 1.5825569 | G15: ='GHG det, per kg egg'!G47 -> 0.96791835 | H15: ='GHG det, per kg egg'!G48 -> 0.0014022256 | I15: ='GHG det, per kg egg'!G49 -> 0.001975437 | J15: ='GHG det, per kg egg'!G50 -> 0.0019029867 | L15: ='EFP per kg feed'!F113*FCR_bonefree_incl_parents_PL -> 4.7509534 | M15: ='EFP per kg feed'!G113*FCR_bonefree_incl_parents_PL-Manure_repl_factor_PL*Excreted_N_after_losses_PL -> 0.058982852 | N15: ='EFP per kg feed'!H113*FCR_bonefree_incl_parents_PL -> 0.0076481331 | O15: ='EFP per kg feed'!I113*FCR_bonefree_incl_parents_PL+(Production!J5*(Water_drinking_hens_PL+Water_service_hens_PL)*365+Production!J6*(Water_drinking_recruit_PL+Water_service_recruit_PL)*365)/1000/Production!J14 -> 0.0089062694 | P15: ='EFP per kg feed'!J113*FCR_bonefree_incl_parents_PL -> 0.45792901 | Q15: ='EFP per kg feed'!K113*FCR_bonefree_incl_parents_PL -> 2.6371719e-11 | R15: ='EFP per kg feed'!L113*FCR_bonefree_incl_parents_PL+NH3_per_kg_PL -> 0.0042752691 | S15: ='Parameters, country spec'!#REF!*Production!J16 -> #REF! | T15: 9.9991269 | U15: 1.8816486
A16: 0231 | B16: Hen eggs in shell | C16: Egg | D16: Spain | E16: ES | F16: ='GHG det, per kg egg'!G56 -> 1.2511572 | G16: ='GHG det, per kg egg'!G52 -> 0.77371719 | H16: ='GHG det, per kg egg'!G53 -> 0.0010727959 | I16: ='GHG det, per kg egg'!G54 -> 0.001618406 | J16: ='GHG det, per kg egg'!G55 -> 0.0014716987 | L16: ='EFP per kg feed'!F125*FCR_bonefree_incl_parents_ES -> 5.6926673 | M16: ='EFP per kg feed'!G125*FCR_bonefree_incl_parents_ES-Manure_repl_factor_ES*Excreted_N_after_losses_ES -> 0.067539253 | N16: ='EFP per kg feed'!H125*FCR_bonefree_incl_parents_ES -> 0.0078670928 | O16: ='EFP per kg feed'!I125*FCR_bonefree_incl_parents_ES+(Production!K5*(Water_drinking_hens_ES+Water_service_hens_ES)*365+Production!K6*(Water_drinking_recruit_ES+Water_service_recruit_ES)*365)/1000/Production!K14 -> 0.2725496 | P16: ='EFP per kg feed'!J125*FCR_bonefree_incl_parents_ES -> 0.41329672 | Q16: ='EFP per kg feed'!K125*FCR_bonefree_incl_parents_ES -> 3.8029224e-10 | R16: ='EFP per kg feed'!L125*FCR_bonefree_incl_parents_ES+NH3_per_kg_ES -> 0.0066204288 | S16: ='Parameters, country spec'!#REF!*Production!K16 -> #REF! | T16: 8.8451275 | U16: 0.97322377
A17: 0231 | B17: Hen eggs in shell | C17: Egg | D17: Sweden | E17: SE | F17: ='GHG det, per kg egg'!G61 -> 1.0898619 | G17: ='GHG det, per kg egg'!G57 -> 0.54734417 | H17: ='GHG det, per kg egg'!G58 -> 0.00042443778 | I17: ='GHG det, per kg egg'!G59 -> 0.0019210431 | J17: ='GHG det, per kg egg'!G60 -> 0.0017509205 | L17: ='EFP per kg feed'!F137*FCR_bonefree_incl_parents_SE -> 4.4530699 | M17: ='EFP per kg feed'!G137*FCR_bonefree_incl_parents_SE-Manure_repl_factor_SE*Excreted_N_after_losses_SE -> 0.055344767 | N17: ='EFP per kg feed'!H137*FCR_bonefree_incl_parents_SE -> 0.0057137865 | O17: ='EFP per kg feed'!I137*FCR_bonefree_incl_parents_SE+(Production!L5*(Water_drinking_hens_SE+Water_service_hens_SE)*365+Production!L6*(Water_drinking_recruit_SE+Water_service_recruit_SE)*365)/1000/Production!L14 -> 0.0095730765 | P17: ='EFP per kg feed'!J137*FCR_bonefree_incl_parents_SE -> 0.23700609 | Q17: ='EFP per kg feed'!K137*FCR_bonefree_incl_parents_SE -> 2.2731494e-11 | R17: ='EFP per kg feed'!L137*FCR_bonefree_incl_parents_SE+NH3_per_kg_SE -> 0.0027464937 | S17: ='Parameters, country spec'!#REF!*Production!L16 -> #REF! | T17: 7.7115566 | U17: 0.11772468

Sheet GHG det, per kg egg
H1: * Production of mineral fertiliser is adjusted to account for the N supplied by manure.
A2: GHG emissions (per kg of egg) | E2: ='CH4 per kg feed'!G17*FCR_bonefree_incl_parents_DK -> 2.0698117e-05 | H2: ** Adjusted for use of manure instead of mineral fertiliser (lower emission factor for manure)
E3: ='CH4 per kg feed'!G29*FCR_bonefree_incl_parents_FR -> 2.0698117e-05 | H3: *** Calculated as percentage of direct emissions due to assumption due to data limitations regarding nitrogen leaching and volatilization from soils in different regions.
S4: Animals | W4: Stables | X4: Slaughter | Z4: Control
A5: Animal products | G5: Sum | H5: Inputs | J5: Soil emissions | L5: Energy use | P5: Land use change | Q5: Feed processing | R5: Transports
A6: FoodEx code | B6: FoodEx name | C6: Food Ex category (L1) | D6: Country | E6: Country code | F6: Gas | G6: GHG | H6: Production of mineral fertilizer* | I6: Production of capital goods | J6: Direct emissions** | K6: Indirect emissions*** | L6: Diesel use field mach | M6: Energy use in greenhouses | N6: Energy use for irrigation | O6: Energy use for post-harvest proc | P6: LUC emissions | Q6: Feed processing | R6: Feed transports | S6: Enteric fermentation* | T6: Manure management - tot | U6: Manure management - direct | V6: Manure management - indirect | W6: Energy use in stables | X6: Energy use for slaughter | Z6: Total feed, excl LUC | AA6: Feed mix emissions, kg CO2 per kg feed, excl. adjustement manure
A7: A031G | B7: Hen eggs | D7: Denmark | E7: DK | F7: CO2 | G7: =SUM(H7:X7) -> 0.54071427 | H7: ='CO2 per kg feed'!G17*FCR_bonefree_incl_parents_DK-Excreted_N_after_losses_DK*Manure_repl_factor_DK*EF_min_fert_CO2_DK -> 0.14745118 | I7: ='CO2 per kg feed'!H17*FCR_bonefree_incl_parents_DK -> 0.06121991 | J7: ='CO2 per kg feed'!I17*FCR_bonefree_incl_parents_DK -> 0 | L7: ='CO2 per kg feed'!K17*FCR_bonefree_incl_parents_DK -> 0.064701746 | N7: ='CO2 per kg feed'!M17*FCR_bonefree_incl_parents_DK -> 0.00041975752 | O7: ='CO2 per kg feed'!N17*FCR_bonefree_incl_parents_DK -> 0.093485789 | P7: ='CO2 per kg feed'!O17*FCR_bonefree_incl_parents_DK -> 0.038249404 | Q7: ='CO2 per kg feed'!P17*FCR_bonefree_incl_parents_DK -> 0.014632478 | R7: ='CO2 per kg feed'!Q17*FCR_bonefree_incl_parents_DK -> 0.031242032 | W7: {=Energy_stables_DK*(Share_heating_DK*(Share_biofuels_DK*EF_biofuels_CO2+(1-Share_biofuels_DK)*EF_oil_CO2)+(1-Share_heating_DK)*EF_el_CO2_DK)} -> 0.0087112695 | X7: =(Energy_slaughter_el_DK*EF_el_CO2_DK+Energy_slaughter_heat_DK*EF_gas_CO2)/'Parameters, country spec'!B$10 -> 0.0806007
A8: A031G | B8: Hen eggs | D8: Denmark | E8: DK | F8: CH4, fossil | G8: =SUM(H8:X8) -> 0.00075243675 | H8: ='CH4 per kg feed'!G17*FCR_bonefree_incl_parents_DK-Excreted_N_after_losses_DK*Manure_repl_factor_DK*EF_min_fert_CH4_DK -> 2.0698117e-05 | I8: ='CH4 per kg feed'!H17*FCR_bonefree_incl_parents_DK -> 0.00021540339 | L8: ='CH4 per kg feed'!K17*FCR_bonefree_incl_parents_DK -> 2.8660692e-05 | N8: ='CH4 per kg feed'!M17*FCR_bonefree_incl_parents_DK -> 1.2558276e-06 | O8: ='CH4 per kg feed'!N17*FCR_bonefree_incl_parents_DK -> 5.3375455e-05 | P8: ='CH4 per kg feed'!O17*FCR_bonefree_incl_parents_DK -> 0 | Q8: ='CH4 per kg feed'!P17*FCR_bonefree_incl_parents_DK -> 4.4091052e-05 | R8: ='CH4 per kg feed'!Q17*FCR_bonefree_incl_parents_DK -> 2.9976756e-05 | W8: {=Energy_stables_DK*(Share_heating_DK*(Share_biofuels_DK*EF_biofuel_CH4+(1-Share_biofuels_DK)*EF_oil_CH4)+(1-Share_heating_DK)*EF_el_CH4_DK)} -> 2.7007621e-05 | X8: =(Energy_slaughter_el_DK*EF_el_CH4_DK+Energy_slaughter_heat_DK*EF_gas_CH4)/'Parameters, country spec'!B$10 -> 0.00033196785
A9: A031G | B9: Hen eggs | D9: Denmark | E9: DK | F9: CH4, biogenic | G9: =SUM(H9:T9)+SUM(W9:X9) -> 0.0011044964 | T9: =SUM(U9:V9) -> 0.0011044964 | U9: =Manure!B12*Production!B16 -> 0.0011044964
A10: A031G | B10: Hen eggs | D10: Denmark | E10: DK | F10: N2O | G10: =SUM(H10:T10)+SUM(W10:X10) -> 0.0015846449 | H10: ='N2O per kg feed'!G17*FCR_bonefree_incl_parents_DK-Excreted_N_after_losses_DK*Manure_repl_factor_DK*EF_min_fert_N2O_DK -> 8.4297809e-05 | I10: ='N2O per kg feed'!H17*FCR_bonefree_incl_parents_DK -> 2.4941445e-06 | J10: ='N2O per kg feed'!I17*FCR_bonefree_incl_parents_DK-Excreted_N_after_losses_DK*Manure_repl_factor_DK*EF_N2O_diff_DK -> 0.0013475946 | K10: {=J10*EF_indirect_N2O_DK} -> 0.00013475946 | L10: ='N2O per kg feed'!K17*FCR_bonefree_incl_parents_DK -> 1.7385612e-06 | N10: ='N2O per kg feed'!M17*FCR_bonefree_incl_parents_DK -> 1.7970159e-08 | O10: ='N2O per kg feed'!N17*FCR_bonefree_incl_parents_DK -> 3.5651927e-06 | P10: ='N2O per kg feed'!O17*FCR_bonefree_incl_parents_DK -> 0 | Q10: ='N2O per kg feed'!P17*FCR_bonefree_incl_parents_DK -> 2.5260185e-06 | R10: ='N2O per kg feed'!Q17*FCR_bonefree_incl_parents_DK -> 1.0935534e-06 | T10: =SUM(U10:V10) -> 1.750453e-06 | U10: =Manure!B68*44/28 -> 4.5681971e-07 | V10: =NH3_per_kg_DK*17/14*Manure!B97 -> 1.2936333e-06 | W10: {=Energy_stables_DK*(Share_heating_DK*(Share_biofuels_DK*EF_biofuel_N2O+(1-Share_biofuels_DK)*EF_oil_N2O)+(1-Share_heating_DK)*EF_el_N2O_DK)} -> 8.1643941e-07 | X10: =(Energy_slaughter_el_DK*EF_el_N2O_DK+Energy_slaughter_heat_DK*EF_gas_N2O)/'Parameters, country spec'!B$10 -> 3.9907517e-06
A11: A031G | B11: Hen eggs | D11: Denmark | E11: DK | F11: CO2e | G11: =SUM(H11:X11) -> 1.0255664 | H11: =SUMPRODUCT(H7:H10,'Parameters, general'!$B$14:$B$17) -> 0.17108129 | I11: =SUMPRODUCT(I7:I10,'Parameters, general'!$B$14:$B$17) -> 0.068319832 | J11: =SUMPRODUCT(J7:J10,'Parameters, general'!$B$14:$B$17) -> 0.36789332 | K11: =SUMPRODUCT(K7:K10,'Parameters, general'!$B$14:$B$17) -> 0.036789332 | L11: =SUMPRODUCT(L7:L10,'Parameters, general'!$B$14:$B$17) -> 0.066030462 | M11: =SUMPRODUCT(M7:M10,'Parameters, general'!$B$14:$B$17) -> 0 | N11: =SUMPRODUCT(N7:N10,'Parameters, general'!$B$14:$B$17) -> 0.00046208704 | O11: =SUMPRODUCT(O7:O10,'Parameters, general'!$B$14:$B$17) -> 0.096049676 | ... R11: =SUMPRODUCT(R7:R10,'Parameters, general'!$B$14:$B$17) -> 0.032433879 | T11: =SUMPRODUCT(T7:T10,'Parameters, general'!$B$14:$B$17) -> 0.030299277 | W11: =SUMPRODUCT(W7:W10,'Parameters, general'!$B$14:$B$17) -> 0.0097389846 | X11: =SUMPRODUCT(X7:X10,'Parameters, general'!$B$14:$B$17) -> 0.091582817 | Z11: =SUM(H11:R11) -> 0.89394527 | AA11: ='CO2 per kg feed'!F24+'CH4 per kg feed'!F24*CF_GWP_CH4_fossil+'N2O per kg feed'!F24*CF_GWP_N2O -> 0.24668394
A12: A031G | B12: Hen eggs | D12: France | E12: FR | F12: CO2 | G12: =SUM(H12:X12) -> 0.52147342 | H12: ='CO2 per kg feed'!G29*FCR_bonefree_incl_parents_FR-Excreted_N_after_losses_FR*Manure_repl_factor_FR*EF_min_fert_CO2_FR -> 0.1396814 | I12: ='CO2 per kg feed'!H29*FCR_bonefree_incl_parents_FR -> 0.06121991 | J12: ='CO2 per kg feed'!I29*FCR_bonefree_incl_parents_FR -> 0 | L12: ='CO2 per kg feed'!K29*FCR_bonefree_incl_parents_FR -> 0.064217504 | N12: ='CO2 per kg feed'!M29*FCR_bonefree_incl_parents_FR -> 0.0023106644 | O12: ='CO2 per kg feed'!N29*FCR_bonefree_incl_parents_FR -> 0.081405268 | P12: ='CO2 per kg feed'!O29*FCR_bonefree_incl_parents_FR -> 0.037452199 | Q12: ='CO2 per kg feed'!P29*FCR_bonefree_incl_parents_FR -> 0.014632478 | R12: ='CO2 per kg feed'!Q29*FCR_bonefree_incl_parents_FR -> 0.031242032 | W12: =Energy_stables_FR*(Share_heating_FR*(Share_biofuels_FR*EF_biofuels_CO2+(1-Share_biofuels_FR)*EF_oil_CO2)+(1-Share_heating_FR)*EF_el_CO2_FR) -> 0.0087112695 | X12: =(Energy_slaughter_el_FR*EF_el_CO2_FR+Energy_slaughter_heat_FR*EF_gas_CO2)/'Parameters, country spec'!C$10 -> 0.0806007
A13: A031G | B13: Hen eggs | D13: France | E13: FR | F13: CH4, fossil | G13: =SUM(H13:X13) -> 0.0007475364 | H13: ='CH4 per kg feed'!G29*FCR_bonefree_incl_parents_FR-Excreted_N_after_losses_FR*Manure_repl_factor_FR*EF_min_fert_CH4_FR -> 2.0698117e-05 | I13: ='CH4 per kg feed'!H29*FCR_bonefree_incl_parents_FR -> 0.00021540339 | L13: ='CH4 per kg feed'!K29*FCR_bonefree_incl_parents_FR -> 2.8446189e-05 | N13: ='CH4 per kg feed'!M29*FCR_bonefree_incl_parents_FR -> 6.8423345e-06 | O13: ='CH4 per kg feed'!N29*FCR_bonefree_incl_parents_FR -> 4.31031e-05 | P13: ='CH4 per kg feed'!O29*FCR_bonefree_incl_parents_FR -> 0 | Q13: ='CH4 per kg feed'!P29*FCR_bonefree_incl_parents_FR -> 4.4091052e-05 | R13: ='CH4 per kg feed'!Q29*FCR_bonefree_incl_parents_FR -> 2.9976756e-05 | W13: =Energy_stables_FR*(Share_heating_FR*(Share_biofuels_FR*EF_biofuel_CH4+(1-Share_biofuels_FR)*EF_oil_CH4)+(1-Share_heating_FR)*EF_el_CH4_FR) -> 2.7007621e-05 | X13: =(Energy_slaughter_el_FR*EF_el_CH4_FR+Energy_slaughter_heat_FR*EF_gas_CH4)/'Parameters, country spec'!C$10 -> 0.00033196785
A14: A031G | B14: Hen eggs | D14: France | E14: FR | F14: CH4, biogenic | G14: =SUM(H14:T14)+SUM(W14:X14) -> 0.0010990286 | T14: =SUM(U14:V14) -> 0.0010990286 | U14: =Manure!C12*Production!C16 -> 0.0010990286
A15: A031G | B15: Hen eggs | D15: France | E15: FR | F15: N2O | G15: =SUM(H15:T15)+SUM(W15:X15) -> 0.0014698247 | H15: ='N2O per kg feed'!G29*FCR_bonefree_incl_parents_FR-Excreted_N_after_losses_FR*Manure_repl_factor_FR*EF_min_fert_N2O_FR -> 6.1171595e-05 | I15: ='N2O per kg feed'!H29*FCR_bonefree_incl_parents_FR -> 2.4941445e-06 | J15: ='N2O per kg feed'!I29*FCR_bonefree_incl_parents_FR-Excreted_N_after_losses_FR*Manure_repl_factor_FR*EF_N2O_diff_FR -> 0.0012646772 | K15: =J15*EF_indirect_N2O_FR -> 0.00012646772 | L15: ='N2O per kg feed'!K29*FCR_bonefree_incl_parents_FR -> 1.7255494e-06 | N15: ='N2O per kg feed'!M29*FCR_bonefree_incl_parents_FR -> 9.925234e-08 | O15: ='N2O per kg feed'!N29*FCR_bonefree_incl_parents_FR -> 3.1006201e-06 | P15: ='N2O per kg feed'!O29*FCR_bonefree_incl_parents_FR -> 0 | Q15: ='N2O per kg feed'!P29*FCR_bonefree_incl_parents_FR -> 2.5260185e-06 | R15: ='N2O per kg feed'!Q29*FCR_bonefree_incl_parents_FR -> 1.0935534e-06 | T15: =SUM(U15:V15) -> 1.6618532e-06 | U15: =Manure!C68*44/28 -> 4.3369761e-07 | V15: =NH3_per_kg_FR*17/14*Manure!C97 -> 1.2281556e-06 | W15: =Energy_stables_FR*(Share_heating_FR*(Share_biofuels_FR*EF_biofuel_N2O+(1-Share_biofuels_FR)*EF_oil_N2O)+(1-Share_heating_FR)*EF_el_N2O_FR) -> 8.1643941e-07 | X15: =(Energy_slaughter_el_FR*EF_el_N2O_FR+Energy_slaughter_heat_FR*EF_gas_N2O)/'Parameters, country spec'!C$10 -> 3.9907517e-06
A16: A031G | B16: Hen eggs | D16: France | E16: FR | F16: CO2e | G16: =SUM(H16:X16) -> 0.97468591 | H16: =SUMPRODUCT(H12:H15,'Parameters, general'!$B$14:$B$17) -> 0.15699805 | I16: =SUMPRODUCT(I12:I15,'Parameters, general'!$B$14:$B$17) -> 0.068319832 | J16: =SUMPRODUCT(J12:J15,'Parameters, general'!$B$14:$B$17) -> 0.34525687 | K16: =SUMPRODUCT(K12:K15,'Parameters, general'!$B$14:$B$17) -> 0.034525687 | L16: =SUMPRODUCT(L12:L15,'Parameters, general'!$B$14:$B$17) -> 0.065536275 | M16: =SUMPRODUCT(M12:M15,'Parameters, general'!$B$14:$B$17) -> 0 | N16: =SUMPRODUCT(N12:N15,'Parameters, general'!$B$14:$B$17) -> 0.0025416619 | O16: =SUMPRODUCT(O12:O15,'Parameters, general'!$B$14:$B$17) -> 0.08353621 | ... R16: =SUMPRODUCT(R12:R15,'Parameters, general'!$B$14:$B$17) -> 0.032433879 | T16: =SUMPRODUCT(T12:T15,'Parameters, general'!$B$14:$B$17) -> 0.030127457 | W16: =SUMPRODUCT(W12:W15,'Parameters, general'!$B$14:$B$17) -> 0.0097389846 | X16: =SUMPRODUCT(X12:X15,'Parameters, general'!$B$14:$B$17) -> 0.091582817 | Z16: =SUM(H16:R16) -> 0.84323665 | AA16: ='CO2 per kg feed'!F29+'CH4 per kg feed'!F29*CF_GWP_CH4_fossil+'N2O per kg feed'!F29*CF_GWP_N2O -> 0.34743476
A17: A031G | B17: Hen eggs | D17: Germany | E17: DE | F17: CO2 | G17: =SUM(H17:X17) -> 0.70744124 | H17: ='CO2 per kg feed'!G41*FCR_bonefree_incl_parents_DE-Excreted_N_after_losses_DE*Manure_repl_factor_DE*EF_min_fert_CO2_DE -> 0.13696325 | I17: ='CO2 per kg feed'!H41*FCR_bonefree_incl_parents_DE -> 0.061854914 | J17: ='CO2 per kg feed'!I41*FCR_bonefree_incl_parents_DE -> 0 | L17: ='CO2 per kg feed'!K41*FCR_bonefree_incl_parents_DE -> 0.061458772 | N17: ='CO2 per kg feed'!M41*FCR_bonefree_incl_parents_DE -> 0.00036241286 | O17: ='CO2 per kg feed'!N41*FCR_bonefree_incl_parents_DE -> 0.098959777 | P17: ='CO2 per kg feed'!O41*FCR_bonefree_incl_parents_DE -> 0.052704928 | Q17: ='CO2 per kg feed'!P41*FCR_bonefree_incl_parents_DE -> 0.023713405 | R17: ='CO2 per kg feed'!Q41*FCR_bonefree_incl_parents_DE -> 0.046708923 | W17: =Energy_stables_DE*(Share_heating_DE*(Share_biofuels_DE*EF_biofuels_CO2+(1-Share_biofuels_DE)*EF_oil_CO2)+(1-Share_heating_DE)*EF_el_CO2_DE) -> 0.04635034 | X17: =(Energy_slaughter_el_DE*EF_el_CO2_DE+Energy_slaughter_heat_DE*EF_gas_CO2)/'Parameters, country spec'!D$10 -> 0.17836452
A18: A031G | B18: Hen eggs | D18: Germany | E18: DE | F18: CH4, fossil | G18: =SUM(H18:X18) -> 0.0010247774 | H18: ='CH4 per kg feed'!G41*FCR_bonefree_incl_parents_DE-Excreted_N_after_losses_DE*Manure_repl_factor_DE*EF_min_fert_CH4_DE -> 2.8121109e-05 | I18: ='CH4 per kg feed'!H41*FCR_bonefree_incl_parents_DE -> 0.00021763766 | L18: ='CH4 per kg feed'!K41*FCR_bonefree_incl_parents_DE -> 2.7224164e-05 | N18: ='CH4 per kg feed'!M41*FCR_bonefree_incl_parents_DE -> 1.0925154e-06 | O18: ='CH4 per kg feed'!N41*FCR_bonefree_incl_parents_DE -> 7.034478e-05 | P18: ='CH4 per kg feed'!O41*FCR_bonefree_incl_parents_DE -> 0 | Q18: ='CH4 per kg feed'!P41*FCR_bonefree_incl_parents_DE -> 5.5027348e-05 | R18: ='CH4 per kg feed'!Q41*FCR_bonefree_incl_parents_DE -> 4.4554728e-05 | W18: =Energy_stables_DE*(Share_heating_DE*(Share_biofuels_DE*EF_biofuel_CH4+(1-Share_biofuels_DE)*EF_oil_CH4)+(1-Share_heating_DE)*EF_el_CH4_DE) -> 8.8663107e-05 | X18: =(Energy_slaughter_el_DE*EF_el_CH4_DE+Energy_slaughter_heat_DE*EF_gas_CH4)/'Parameters, country spec'!D$10 -> 0.00049211197
A19: A031G | B19: Hen eggs | D19: Germany | E19: DE | F19: CH4, biogenic | G19: =SUM(H19:T19)+SUM(W19:X19) -> 0.0016549103 | T19: =SUM(U19:V19) -> 0.0016549103 | U19: =Manure!D12*Production!D16 -> 0.0016549103
A20: A031G | B20: Hen eggs | D20: Germany | E20: DE | F20: N2O | G20: =SUM(H20:T20)+SUM(W20:X20) -> 0.0014385879 | H20: ='N2O per kg feed'!G41*FCR_bonefree_incl_parents_DE-Excreted_N_after_losses_DE*Manure_repl_factor_DE*EF_min_fert_N2O_DE -> 7.1733196e-05 | I20: ='N2O per kg feed'!H41*FCR_bonefree_incl_parents_DE -> 2.520015e-06 | J20: ='N2O per kg feed'!I41*FCR_bonefree_incl_parents_DE-Excreted_N_after_losses_DE*Manure_repl_factor_DE*EF_N2O_diff_DE -> 0.0012202792 | K20: =J20*EF_indirect_N2O_DE -> 0.00012202792 | L20: ='N2O per kg feed'!K41*FCR_bonefree_incl_parents_DE -> 1.6514212e-06 | N20: ='N2O per kg feed'!M41*FCR_bonefree_incl_parents_DE -> 1.5476563e-08 | O20: ='N2O per kg feed'!N41*FCR_bonefree_incl_parents_DE -> 3.689166e-06 | P20: ='N2O per kg feed'!O41*FCR_bonefree_incl_parents_DE -> 0 | Q20: ='N2O per kg feed'!P41*FCR_bonefree_incl_parents_DE -> 3.2489205e-06 | R20: ='N2O per kg feed'!Q41*FCR_bonefree_incl_parents_DE -> 1.6291739e-06 | T20: =SUM(U20:V20) -> 2.4553614e-06 | U20: =Manure!D68*44/28 -> 6.4078126e-07 | V20: =NH3_per_kg_DE*17/14*Manure!D97 -> 1.8145802e-06 | W20: =Energy_stables_DE*(Share_heating_DE*(Share_biofuels_DE*EF_biofuel_N2O+(1-Share_biofuels_DE)*EF_oil_N2O)+(1-Share_heating_DE)*EF_el_N2O_DE) -> 2.0759e-06 | X20: =(Energy_slaughter_el_DE*EF_el_N2O_DE+Energy_slaughter_heat_DE*EF_gas_N2O)/'Parameters, country spec'!D$10 -> 7.262078e-06
A21: A031G | B21: Hen eggs | D21: Germany | E21: DE | F21: CO2e | G21: =SUM(H21:X21) -> 1.1753967 | H21: =SUMPRODUCT(H17:H20,'Parameters, general'!$B$14:$B$17) -> 0.15738442 | I21: =SUMPRODUCT(I17:I20,'Parameters, general'!$B$14:$B$17) -> 0.06902848 | J21: =SUMPRODUCT(J17:J20,'Parameters, general'!$B$14:$B$17) -> 0.33313623 | K21: =SUMPRODUCT(K17:K20,'Parameters, general'!$B$14:$B$17) -> 0.033313623 | L21: =SUMPRODUCT(L17:L20,'Parameters, general'!$B$14:$B$17) -> 0.06272089 | M21: =SUMPRODUCT(M17:M20,'Parameters, general'!$B$14:$B$17) -> 0 | N21: =SUMPRODUCT(N17:N20,'Parameters, general'!$B$14:$B$17) -> 0.00039919492 | O21: =SUMPRODUCT(O17:O20,'Parameters, general'!$B$14:$B$17) -> 0.10206319 | ... R21: =SUMPRODUCT(R17:R20,'Parameters, general'!$B$14:$B$17) -> 0.048481418 | T21: =SUMPRODUCT(T17:T20,'Parameters, general'!$B$14:$B$17) -> 0.045352891 | W21: =SUMPRODUCT(W17:W20,'Parameters, general'!$B$14:$B$17) -> 0.049559221 | X21: =SUMPRODUCT(X17:X20,'Parameters, general'!$B$14:$B$17) -> 0.195012 | Z21: =SUM(H21:R21) -> 0.88547255 | AA21: ='CO2 per kg feed'!F41+'CH4 per kg feed'!F41*CF_GWP_CH4_fossil+'N2O per kg feed'!F41*CF_GWP_N2O -> 0.36485235
A22: A031G | B22: Hen eggs | D22: Greece | E22: GR | F22: CO2 | G22: =SUM(H22:X22) -> 0.99482438 | H22: ='CO2 per kg feed'!G53*FCR_bonefree_incl_parents_GR-Excreted_N_after_losses_GR*Manure_repl_factor_GR*EF_min_fert_CO2_GR -> 0.15251312 | I22: ='CO2 per kg feed'!H53*FCR_bonefree_incl_parents_GR -> 0.060007857 | J22: ='CO2 per kg feed'!I53*FCR_bonefree_incl_parents_GR -> 0 | L22: ='CO2 per kg feed'!K53*FCR_bonefree_incl_parents_GR -> 0.093529167 | N22: ='CO2 per kg feed'!M53*FCR_bonefree_incl_parents_GR -> 0.01703541 | O22: ='CO2 per kg feed'!N53*FCR_bonefree_incl_parents_GR -> 0.10058213 | P22: ='CO2 per kg feed'!O53*FCR_bonefree_incl_parents_GR -> 0.095424384 | Q22: ='CO2 per kg feed'!P53*FCR_bonefree_incl_parents_GR -> 0.12054472 | R22: ='CO2 per kg feed'!Q53*FCR_bonefree_incl_parents_GR -> 0.066993108 | W22: =Energy_stables_GR*(Share_heating_GR*(Share_biofuels_GR*EF_biofuels_CO2+(1-Share_biofuels_GR)*EF_oil_CO2)+(1-Share_heating_GR)*EF_el_CO2_GR) -> 0.063996298 | X22: =(Energy_slaughter_el_GR*EF_el_CO2_GR+Energy_slaughter_heat_GR*EF_gas_CO2)/'Parameters, country spec'!E$10 -> 0.22419818
A23: A031G | B23: Hen eggs | D23: Greece | E23: GR | F23: CH4, fossil | G23: =SUM(H23:X23) -> 0.0014439606 | H23: ='CH4 per kg feed'!G53*FCR_bonefree_incl_parents_GR-Excreted_N_after_losses_GR*Manure_repl_factor_GR*EF_min_fert_CH4_GR -> 7.2514506e-06 | I23: ='CH4 per kg feed'!H53*FCR_bonefree_incl_parents_GR -> 0.00021113876 | L23: ='CH4 per kg feed'!K53*FCR_bonefree_incl_parents_GR -> 4.1430267e-05 | N23: ='CH4 per kg feed'!M53*FCR_bonefree_incl_parents_GR -> 5.0349205e-05 | O23: ='CH4 per kg feed'!N53*FCR_bonefree_incl_parents_GR -> 8.2582263e-05 | P23: ='CH4 per kg feed'!O53*FCR_bonefree_incl_parents_GR -> 0 | Q23: ='CH4 per kg feed'!P53*FCR_bonefree_incl_parents_GR -> 0.00025268504 | R23: ='CH4 per kg feed'!Q53*FCR_bonefree_incl_parents_GR -> 7.9685533e-05 | W23: =Energy_stables_GR*(Share_heating_GR*(Share_biofuels_GR*EF_biofuel_CH4+(1-Share_biofuels_GR)*EF_oil_CH4)+(1-Share_heating_GR)*EF_el_CH4_GR) -> 0.00012704162 | X23: =(Energy_slaughter_el_GR*EF_el_CH4_GR+Energy_slaughter_heat_GR*EF_gas_CH4)/'Parameters, country spec'!E$10 -> 0.00059179642
A24: A031G | B24: Hen eggs | D24: Greece | E24: GR | F24: CH4, biogenic | G24: =SUM(H24:T24)+SUM(W24:X24) -> 0.0020715452 | T24: =SUM(U24:V24) -> 0.0020715452 | U24: =Manure!E12*Production!E16 -> 0.0020715452
A25: A031G | B25: Hen eggs | D25: Greece | E25: GR | F25: N2O | G25: =SUM(H25:T25)+SUM(W25:X25) -> 0.0011722453 | H25: ='N2O per kg feed'!G53*FCR_bonefree_incl_parents_GR-Excreted_N_after_losses_GR*Manure_repl_factor_GR*EF_min_fert_N2O_GR -> 2.1923679e-05 | I25: ='N2O per kg feed'!H53*FCR_bonefree_incl_parents_GR -> 2.4447645e-06 | J25: ='N2O per kg feed'!I53*FCR_bonefree_incl_parents_GR-Excreted_N_after_losses_GR*Manure_repl_factor_GR*EF_N2O_diff_GR -> 0.001018055 | K25: =J25*EF_indirect_N2O_GR -> 0.0001018055 | L25: ='N2O per kg feed'!K53*FCR_bonefree_incl_parents_GR -> 2.5131652e-06 | N25: ='N2O per kg feed'!M53*FCR_bonefree_incl_parents_GR -> 7.3218891e-07 | O25: ='N2O per kg feed'!N53*FCR_bonefree_incl_parents_GR -> 3.5465393e-06 | P25: ='N2O per kg feed'!O53*FCR_bonefree_incl_parents_GR -> 0 | Q25: ='N2O per kg feed'!P53*FCR_bonefree_incl_parents_GR -> 7.1477635e-06 | R25: ='N2O per kg feed'!Q53*FCR_bonefree_incl_parents_GR -> 2.5633189e-06 | T25: =SUM(U25:V25) -> 1.7207675e-06 | U25: =Manure!DE68*44/28 -> 0 | V25: =NH3_per_kg_GR*17/14*Manure!E97 -> 1.7207675e-06 | W25: =Energy_stables_GR*(Share_heating_GR*(Share_biofuels_GR*EF_biofuel_N2O+(1-Share_biofuels_GR)*EF_oil_N2O)+(1-Share_heating_GR)*EF_el_N2O_GR) -> 2.2022764e-06 | X25: =(Energy_slaughter_el_GR*EF_el_N2O_GR+Energy_slaughter_heat_GR*EF_gas_N2O)/'Parameters, country spec'!E$10 -> 7.5903284e-06
A26: A031G | B26: Hen eggs | D26: Greece | E26: GR | F26: CO2e | G26: =SUM(H26:X26) -> 1.4138091 | H26: =SUMPRODUCT(H22:H25,'Parameters, general'!$B$14:$B$17) -> 0.15871438 | I26: =SUMPRODUCT(I22:I25,'Parameters, general'!$B$14:$B$17) -> 0.066967213 | J26: =SUMPRODUCT(J22:J25,'Parameters, general'!$B$14:$B$17) -> 0.27792901 | K26: =SUMPRODUCT(K22:K25,'Parameters, general'!$B$14:$B$17) -> 0.027792901 | L26: =SUMPRODUCT(L22:L25,'Parameters, general'!$B$14:$B$17) -> 0.095449884 | M26: =SUMPRODUCT(M22:M25,'Parameters, general'!$B$14:$B$17) -> 0 | N26: =SUMPRODUCT(N22:N25,'Parameters, general'!$B$14:$B$17) -> 0.018735704 | O26: =SUMPRODUCT(O22:O25,'Parameters, general'!$B$14:$B$17) -> 0.10401129 | ... R26: =SUMPRODUCT(R22:R25,'Parameters, general'!$B$14:$B$17) -> 0.070067523 | T26: =SUMPRODUCT(T22:T25,'Parameters, general'!$B$14:$B$17) -> 0.056401489 | W26: =SUMPRODUCT(W22:W25,'Parameters, general'!$B$14:$B$17) -> 0.06838336 | X26: =SUMPRODUCT(X22:X25,'Parameters, general'!$B$14:$B$17) -> 0.24390587 | Z26: =SUM(H26:R26) -> 1.0451184 | AA26: ='CO2 per kg feed'!F53+'CH4 per kg feed'!F53*CF_GWP_CH4_fossil+'N2O per kg feed'!F53*CF_GWP_N2O -> 0.4304359
A27: A031G | B27: Hen eggs | D27: Hungary | E27: HU | F27: CO2 | G27: =SUM(H27:X27) -> 0.78711453 | H27: ='CO2 per kg feed'!G65*FCR_bonefree_incl_parents_HU-Excreted_N_after_losses_HU*Manure_repl_factor_HU*EF_min_fert_CO2_HU -> 0.14290016 | I27: ='CO2 per kg feed'!H65*FCR_bonefree_incl_parents_HU -> 0.060744814 | J27: ='CO2 per kg feed'!I65*FCR_bonefree_incl_parents_HU -> 0 | L27: ='CO2 per kg feed'!K65*FCR_bonefree_incl_parents_HU -> 0.075709063 | N27: ='CO2 per kg feed'!M65*FCR_bonefree_incl_parents_HU -> 0.0010556006 | O27: ='CO2 per kg feed'!N65*FCR_bonefree_incl_parents_HU -> 0.093698432 | P27: ='CO2 per kg feed'!O65*FCR_bonefree_incl_parents_HU -> 0.074700237 | Q27: ='CO2 per kg feed'!P65*FCR_bonefree_incl_parents_HU -> 0.077112975 | R27: ='CO2 per kg feed'!Q65*FCR_bonefree_incl_parents_HU -> 0.045958095 | W27: =Energy_stables_HU*(Share_heating_HU*(Share_biofuels_HU*EF_biofuels_CO2+(1-Share_biofuels_HU)*EF_oil_CO2)+(1-Share_heating_HU)*EF_el_CO2_HU) -> 0.043715185 | X27: =(Energy_slaughter_el_HU*EF_el_CO2_HU+Energy_slaughter_heat_HU*EF_gas_CO2)/'Parameters, country spec'!F$10 -> 0.17151996
A28: A031G | B28: Hen eggs | D28: Hungary | E28: HU | F28: CH4, fossil | G28: =SUM(H28:X28) -> 0.0012309277 | H28: ='CH4 per kg feed'!G65*FCR_bonefree_incl_parents_HU-Excreted_N_after_losses_HU*Manure_repl_factor_HU*EF_min_fert_CH4_HU -> 5.4485209e-06 | I28: ='CH4 per kg feed'!H65*FCR_bonefree_incl_parents_HU -> 0.00021373175 | L28: ='CH4 per kg feed'!K65*FCR_bonefree_incl_parents_HU -> 3.3536562e-05 | N28: ='CH4 per kg feed'!M65*FCR_bonefree_incl_parents_HU -> 3.1332747e-06 | O28: ='CH4 per kg feed'!N65*FCR_bonefree_incl_parents_HU -> 7.7117876e-05 | P28: ='CH4 per kg feed'!O65*FCR_bonefree_incl_parents_HU -> 0 | Q28: ='CH4 per kg feed'!P65*FCR_bonefree_incl_parents_HU -> 0.00020056528 | R28: ='CH4 per kg feed'!Q65*FCR_bonefree_incl_parents_HU -> 3.8512906e-05 | W28: =Energy_stables_HU*(Share_heating_HU*(Share_biofuels_HU*EF_biofuel_CH4+(1-Share_biofuels_HU)*EF_oil_CH4)+(1-Share_heating_HU)*EF_el_CH4_HU) -> 0.000110375 | X28: =(Energy_slaughter_el_HU*EF_el_CH4_HU+Energy_slaughter_heat_HU*EF_gas_CH4)/'Parameters, country spec'!F$10 -> 0.00054850649
A29: A031G | B29: Hen eggs | D29: Hungary | E29: HU | F29: CH4, biogenic | G29: =SUM(H29:T29)+SUM(W29:X29) -> 0.0013810301 | T29: =SUM(U29:V29) -> 0.0013810301 | U29: =Manure!F12*Production!F16 -> 0.0013810301
A30: A031G | B30: Hen eggs | D30: Hungary | E30: HU | F30: N2O | G30: =SUM(H30:T30)+SUM(W30:X30) -> 0.0015405045 | H30: ='N2O per kg feed'!G65*FCR_bonefree_incl_parents_HU-Excreted_N_after_losses_HU*Manure_repl_factor_HU*EF_min_fert_N2O_HU -> 6.0439603e-05 | I30: ='N2O per kg feed'!H65*FCR_bonefree_incl_parents_HU -> 2.4747887e-06 | J30: ='N2O per kg feed'!I65*FCR_bonefree_incl_parents_HU-Excreted_N_after_losses_HU*Manure_repl_factor_HU*EF_N2O_diff_HU -> 0.001322698 | K30: =J30*EF_indirect_N2O_HU -> 0.0001322698 | L30: ='N2O per kg feed'!K65*FCR_bonefree_incl_parents_HU -> 2.034332e-06 | N30: ='N2O per kg feed'!M65*FCR_bonefree_incl_parents_HU -> 4.5307503e-08 | O30: ='N2O per kg feed'!N65*FCR_bonefree_incl_parents_HU -> 3.318806e-06 | P30: ='N2O per kg feed'!O65*FCR_bonefree_incl_parents_HU -> 0 | Q30: ='N2O per kg feed'!P65*FCR_bonefree_incl_parents_HU -> 4.909576e-06 | R30: ='N2O per kg feed'!Q65*FCR_bonefree_incl_parents_HU -> 1.6759229e-06 | T30: =SUM(U30:V30) -> 3.2583949e-06 | U30: =Manure!F68*44/28 -> 8.5065051e-07 | V30: =NH3_per_kg_HU*17/14*Manure!F97 -> 2.4077444e-06 | W30: =Energy_stables_HU*(Share_heating_HU*(Share_biofuels_HU*EF_biofuel_N2O+(1-Share_biofuels_HU)*EF_oil_N2O)+(1-Share_heating_HU)*EF_el_N2O_HU) -> 1.5316174e-06 | X30: =(Energy_slaughter_el_HU*EF_el_N2O_HU+Energy_slaughter_heat_HU*EF_gas_N2O)/'Parameters, country spec'!F$10 -> 5.8483569e-06
A31: A031G | B31: Hen eggs | D31: Hungary | E31: HU | F31: CO2e | G31: =SUM(H31:X31) -> 1.2816417 | H31: =SUMPRODUCT(H27:H30,'Parameters, general'!$B$14:$B$17) -> 0.15956254 | I31: =SUMPRODUCT(I27:I30,'Parameters, general'!$B$14:$B$17) -> 0.067789637 | J31: =SUMPRODUCT(J27:J30,'Parameters, general'!$B$14:$B$17) -> 0.36109655 | K31: =SUMPRODUCT(K27:K30,'Parameters, general'!$B$14:$B$17) -> 0.036109655 | L31: =SUMPRODUCT(L27:L30,'Parameters, general'!$B$14:$B$17) -> 0.077263825 | M31: =SUMPRODUCT(M27:M30,'Parameters, general'!$B$14:$B$17) -> 0 | N31: =SUMPRODUCT(N27:N30,'Parameters, general'!$B$14:$B$17) -> 0.0011613411 | O31: =SUMPRODUCT(O27:O30,'Parameters, general'!$B$14:$B$17) -> 0.096902579 | ... R31: =SUMPRODUCT(R27:R30,'Parameters, general'!$B$14:$B$17) -> 0.047563307 | T31: =SUMPRODUCT(T27:T30,'Parameters, general'!$B$14:$B$17) -> 0.038177355 | W31: =SUMPRODUCT(W27:W30,'Parameters, general'!$B$14:$B$17) -> 0.047422491 | X31: =SUMPRODUCT(X27:X30,'Parameters, general'!$B$14:$B$17) -> 0.18946206 | Z31: =SUM(H31:R31) -> 1.0065798 | AA31: ='CO2 per kg feed'!F65+'CH4 per kg feed'!F65*CF_GWP_CH4_fossil+'N2O per kg feed'!F65*CF_GWP_N2O -> 0.41481926
A32: A031G | B32: Hen eggs | D32: Ireland | E32: IE | F32: CO2 | G32: =SUM(H32:X32) -> 0.57527213 | H32: ='CO2 per kg feed'!G77*FCR_bonefree_incl_parents_IE-Excreted_N_after_losses_IE*Manure_repl_factor_IE*EF_min_fert_CO2_IE -> 0.097260002 | I32: ='CO2 per kg feed'!H77*FCR_bonefree_incl_parents_IE -> 0.058846193 | J32: ='CO2 per kg feed'!I77*FCR_bonefree_incl_parents_IE -> 0 | L32: ='CO2 per kg feed'!K77*FCR_bonefree_incl_parents_IE -> 0.073654897 | N32: ='CO2 per kg feed'!M77*FCR_bonefree_incl_parents_IE -> 0.00094253352 | O32: ='CO2 per kg feed'!N77*FCR_bonefree_incl_parents_IE -> 0.090075945 | P32: ='CO2 per kg feed'!O77*FCR_bonefree_incl_parents_IE -> 0.016189852 | Q32: ='CO2 per kg feed'!P77*FCR_bonefree_incl_parents_IE -> 0.023922925 | R32: ='CO2 per kg feed'!Q77*FCR_bonefree_incl_parents_IE -> 0.015433619 | W32: =Energy_stables_IE*(Share_heating_IE*(Share_biofuels_IE*EF_biofuels_CO2+(1-Share_biofuels_IE)*EF_oil_CO2)+(1-Share_heating_IE)*EF_el_CO2_IE) -> 0.039187201 | X32: =(Energy_slaughter_el_IE*EF_el_CO2_IE+Energy_slaughter_heat_IE*EF_gas_CO2)/'Parameters, country spec'!G$10 -> 0.15975896
A33: A031G | B33: Hen eggs | D33: Ireland | E33: IE | F33: CH4, fossil | G33: =SUM(H33:X33) -> 0.0008010737 | H33: ='CH4 per kg feed'!G77*FCR_bonefree_incl_parents_IE-Excreted_N_after_losses_IE*Manure_repl_factor_IE*EF_min_fert_CH4_IE -> 5.0850672e-05 | I33: ='CH4 per kg feed'!H77*FCR_bonefree_incl_parents_IE -> 0.00020705142 | L33: ='CH4 per kg feed'!K77*FCR_bonefree_incl_parents_IE -> 3.2626636e-05 | N33: ='CH4 per kg feed'!M77*FCR_bonefree_incl_parents_IE -> 2.8260052e-06 | O33: ='CH4 per kg feed'!N77*FCR_bonefree_incl_parents_IE -> 4.9348575e-05 | P33: ='CH4 per kg feed'!O77*FCR_bonefree_incl_parents_IE -> 0 | Q33: ='CH4 per kg feed'!P77*FCR_bonefree_incl_parents_IE -> 3.0711133e-05 | R33: ='CH4 per kg feed'!Q77*FCR_bonefree_incl_parents_IE -> 1.3917707e-05 | W33: =Energy_stables_IE*(Share_heating_IE*(Share_biofuels_IE*EF_biofuel_CH4+(1-Share_biofuels_IE)*EF_oil_CH4)+(1-Share_heating_IE)*EF_el_CH4_IE) -> 4.2231405e-05 | X33: =(Energy_slaughter_el_IE*EF_el_CH4_IE+Energy_slaughter_heat_IE*EF_gas_CH4)/'Parameters, country spec'!G$10 -> 0.00037151014
A34: A031G | B34: Hen eggs | D34: Ireland | E34: IE | F34: CH4, biogenic | G34: =SUM(H34:T34)+SUM(W34:X34) -> 0.001080483 | T34: =SUM(U34:V34) -> 0.001080483 | U34: =Manure!G12*Production!G16 -> 0.001080483
A35: A031G | B35: Hen eggs | D35: Ireland | E35: IE | F35: N2O | G35: =SUM(H35:T35)+SUM(W35:X35) -> 0.0010754642 | H35: ='N2O per kg feed'!G77*FCR_bonefree_incl_parents_IE-Excreted_N_after_losses_IE*Manure_repl_factor_IE*EF_min_fert_N2O_IE -> 7.9198956e-05 | I35: ='N2O per kg feed'!H77*FCR_bonefree_incl_parents_IE -> 2.3974375e-06 | J35: ='N2O per kg feed'!I77*FCR_bonefree_incl_parents_IE-Excreted_N_after_losses_IE*Manure_repl_factor_IE*EF_N2O_diff_IE -> 0.00088860023 | K35: =J35*EF_indirect_N2O_IE -> 8.8860023e-05 | L35: ='N2O per kg feed'!K77*FCR_bonefree_incl_parents_IE -> 1.9791358e-06 | N35: ='N2O per kg feed'!M77*FCR_bonefree_incl_parents_IE -> 4.0321878e-08 | O35: ='N2O per kg feed'!N77*FCR_bonefree_incl_parents_IE -> 3.2604966e-06 | P35: ='N2O per kg feed'!O77*FCR_bonefree_incl_parents_IE -> 0 | Q35: ='N2O per kg feed'!P77*FCR_bonefree_incl_parents_IE -> 1.5574078e-06 | R35: ='N2O per kg feed'!Q77*FCR_bonefree_incl_parents_IE -> 5.7809058e-07 | T35: =SUM(U35:V35) -> 1.943144e-06 | U35: =Manure!G68*44/28 -> 5.0710671e-07 | V35: =NH3_per_kg_IE*17/14*Manure!G97 -> 1.4360373e-06 | W35: =Energy_stables_IE*(Share_heating_IE*(Share_biofuels_IE*EF_biofuel_N2O+(1-Share_biofuels_IE)*EF_oil_N2O)+(1-Share_heating_IE)*EF_el_N2O_IE) -> 1.4396031e-06 | X35: =(Energy_slaughter_el_IE*EF_el_N2O_IE+Energy_slaughter_heat_IE*EF_gas_N2O)/'Parameters, country spec'!G$10 -> 5.6093587e-06
A36: A031G | B36: Hen eggs | D36: Ireland | E36: IE | F36: CO2e | G36: =SUM(H36:X36) -> 0.9219189 | H36: =SUMPRODUCT(H32:H35,'Parameters, general'!$B$14:$B$17) -> 0.12039667 | I36: =SUMPRODUCT(I32:I35,'Parameters, general'!$B$14:$B$17) -> 0.065670826 | J36: =SUMPRODUCT(J32:J35,'Parameters, general'!$B$14:$B$17) -> 0.24258786 | K36: =SUMPRODUCT(K32:K35,'Parameters, general'!$B$14:$B$17) -> 0.024258786 | L36: =SUMPRODUCT(L32:L35,'Parameters, general'!$B$14:$B$17) -> 0.075167475 | M36: =SUMPRODUCT(M32:M35,'Parameters, general'!$B$14:$B$17) -> 0 | N36: =SUMPRODUCT(N32:N35,'Parameters, general'!$B$14:$B$17) -> 0.0010377563 | O36: =SUMPRODUCT(O32:O35,'Parameters, general'!$B$14:$B$17) -> 0.092436648 | ... R36: =SUMPRODUCT(R32:R35,'Parameters, general'!$B$14:$B$17) -> 0.016006186 | T36: =SUMPRODUCT(T32:T35,'Parameters, general'!$B$14:$B$17) -> 0.029703521 | W36: =SUMPRODUCT(W32:W35,'Parameters, general'!$B$14:$B$17) -> 0.040838709 | X36: =SUMPRODUCT(X32:X35,'Parameters, general'!$B$14:$B$17) -> 0.17236132 | Z36: =SUM(H36:R36) -> 0.67901535 | AA36: ='CO2 per kg feed'!F77+'CH4 per kg feed'!F77*CF_GWP_CH4_fossil+'N2O per kg feed'!F77*CF_GWP_N2O -> 0.27987243
A37: A031G | B37: Hen eggs | D37: Italy | E37: IT | F37: CO2 | G37: =SUM(H37:X37) -> 0.75633566 | H37: ='CO2 per kg feed'!G89*FCR_bonefree_incl_parents_IT-Excreted_N_after_losses_IT*Manure_repl_factor_IT*EF_min_fert_CO2_IT -> 0.12700223 | I37: ='CO2 per kg feed'!H89*FCR_bonefree_incl_parents_IT -> 0.058950525 | J37: ='CO2 per kg feed'!I89*FCR_bonefree_incl_parents_IT -> 0 | L37: ='CO2 per kg feed'!K89*FCR_bonefree_incl_parents_IT -> 0.064010717 | N37: ='CO2 per kg feed'!M89*FCR_bonefree_incl_parents_IT -> 0.0041265248 | O37: ='CO2 per kg feed'!N89*FCR_bonefree_incl_parents_IT -> 0.088687692 | P37: ='CO2 per kg feed'!O89*FCR_bonefree_incl_parents_IT -> 0.067969851 | Q37: ='CO2 per kg feed'!P89*FCR_bonefree_incl_parents_IT -> 0.095183555 | R37: ='CO2 per kg feed'!Q89*FCR_bonefree_incl_parents_IT -> 0.056457234 | W37: =Energy_stables_IT*(Share_heating_IT*(Share_biofuels_IT*EF_biofuels_CO2+(1-Share_biofuels_IT)*EF_oil_CO2)+(1-Share_heating_IT)*EF_el_CO2_IT) -> 0.037797633 | X37: =(Energy_slaughter_el_IT*EF_el_CO2_IT+Energy_slaughter_heat_IT*EF_gas_CO2)/'Parameters, country spec'!H$10 -> 0.1561497
A38: A031G | B38: Hen eggs | D38: Italy | E38: IT | F38: CH4, fossil | G38: =SUM(H38:X38) -> 0.0016813686 | H38: ='CH4 per kg feed'!G89*FCR_bonefree_incl_parents_IT-Excreted_N_after_losses_IT*Manure_repl_factor_IT*EF_min_fert_CH4_IT -> 7.583047e-06 | I38: ='CH4 per kg feed'!H89*FCR_bonefree_incl_parents_IT -> 0.00020741851 | L38: ='CH4 per kg feed'!K89*FCR_bonefree_incl_parents_IT -> 2.8354589e-05 | N38: ='CH4 per kg feed'!M89*FCR_bonefree_incl_parents_IT -> 1.2208098e-05 | O38: ='CH4 per kg feed'!N89*FCR_bonefree_incl_parents_IT -> 9.6405478e-05 | P38: ='CH4 per kg feed'!O89*FCR_bonefree_incl_parents_IT -> 0 | Q38: ='CH4 per kg feed'!P89*FCR_bonefree_incl_parents_IT -> 0.0004050413 | R38: ='CH4 per kg feed'!Q89*FCR_bonefree_incl_parents_IT -> 7.1432777e-05 | W38: =Energy_stables_IT*(Share_heating_IT*(Share_biofuels_IT*EF_biofuel_CH4+(1-Share_biofuels_IT)*EF_oil_CH4)+(1-Share_heating_IT)*EF_el_CH4_IT) -> 0.00016431484 | X38: =(Energy_slaughter_el_IT*EF_el_CH4_IT+Energy_slaughter_heat_IT*EF_gas_CH4)/'Parameters, country spec'!H$10 -> 0.00068860998
A39: A031G | B39: Hen eggs | D39: Italy | E39: IT | F39: CH4, biogenic | G39: =SUM(H39:T39)+SUM(W39:X39) -> 0.0017878153 | T39: =SUM(U39:V39) -> 0.0017878153 | U39: =Manure!H12*Production!H16 -> 0.0017878153
