Workbook
Name Ability_to_perceive_handling: 'Parameters, general'!$B$16
Name AF_lard: 'Parameters, general'!$B$34
Name AF_meat: 'Parameters, general'!$B$32
Name AF_offal: 'Parameters, general'!$B$33
Name Boars_per_sow: 'Parameters, country spec'!$L$19
Name Bonefree_outof_CW_DE: 'Parameters, country spec'!$D$8
Name Bonefree_outof_CW_DK: 'Parameters, country spec'!$B$8
Name Bonefree_outof_CW_ES: 'Parameters, country spec'!$K$8
Name Bonefree_outof_CW_FR: 'Parameters, country spec'!$C$8
Name Bonefree_outof_CW_GR: 'Parameters, country spec'!$E$8
Name Bonefree_outof_CW_HU: 'Parameters, country spec'!$F$8
Name Bonefree_outof_CW_IE: 'Parameters, country spec'!$G$8
Name Bonefree_outof_CW_IT: 'Parameters, country spec'!$H$8
Name Bonefree_outof_CW_NL: 'Parameters, country spec'!$I$8
Name Bonefree_outof_CW_PL: 'Parameters, country spec'!$J$8
Name Bonefree_outof_CW_SE: 'Parameters, country spec'!$L$8
Name CF_GWP_CH4_fossil: 'Parameters, general'!$B$11
Name CF_GWP_N2O: 'Parameters, general'!$B$12
Name Crop_data: #REF!
Name Crop_data_codes: #REF!
Name EF_biofuel_CH4: 'Parameters, general'!$C$7
Name EF_biofuel_N2O: 'Parameters, general'!$D$7
Name EF_biofuels_CO2: 'Parameters, general'!$B$7
Name EF_el_CH4_BR: 'Parameters, general'!$B$28
Name EF_el_CH4_DE: 'Parameters, country spec'!$D$94
Name EF_el_CH4_DK: 'Parameters, country spec'!$B$94
Name EF_el_CH4_ES: 'Parameters, country spec'!$K$94
Name EF_el_CH4_FR: 'Parameters, country spec'!$C$94
Name EF_el_CH4_GR: 'Parameters, country spec'!$E$94
Name EF_el_CH4_HU: 'Parameters, country spec'!$F$94
Name EF_el_CH4_IE: 'Parameters, country spec'!$G$94
Name EF_el_CH4_IT: 'Parameters, country spec'!$H$94
Name EF_el_CH4_NL: 'Parameters, country spec'!$I$94
Name EF_el_CH4_PL: 'Parameters, country spec'!$J$94
Name EF_el_CH4_SE: 'Parameters, country spec'!$L$94
Name EF_el_CO2_BR: 'Parameters, general'!$B$27
Name EF_el_CO2_DE: 'Parameters, country spec'!$D$93
Name EF_el_CO2_DK: 'Parameters, country spec'!$B$93
Name EF_el_CO2_ES: 'Parameters, country spec'!$K$93
Name EF_el_CO2_FR: 'Parameters, country spec'!$C$93
Name EF_el_CO2_GR: 'Parameters, country spec'!$E$93
Name EF_el_CO2_HU: 'Parameters, country spec'!$F$93
Name EF_el_CO2_IE: 'Parameters, country spec'!$G$93
Name EF_el_CO2_IT: 'Parameters, country spec'!$H$93
Name EF_el_CO2_NL: 'Parameters, country spec'!$I$93
Name EF_el_CO2_PL: 'Parameters, country spec'!$J$93
Name EF_el_CO2_SE: 'Parameters, country spec'!$L$93
Name EF_el_N2O_BR: 'Parameters, general'!$B$29
Name EF_el_N2O_DE: 'Parameters, country spec'!$D$95
Name EF_el_N2O_DK: 'Parameters, country spec'!$B$95
Name EF_el_N2O_ES: 'Parameters, country spec'!$K$95
Name EF_el_N2O_FR: 'Parameters, country spec'!$C$95
Name EF_el_N2O_GR: 'Parameters, country spec'!$E$95
Name EF_el_N2O_HU: 'Parameters, country spec'!$F$95
Name EF_el_N2O_IE: 'Parameters, country spec'!$G$95
Name EF_el_N2O_IT: 'Parameters, country spec'!$H$95
Name EF_el_N2O_NL: 'Parameters, country spec'!$I$95
Name EF_el_N2O_PL: 'Parameters, country spec'!$J$95
Name EF_el_N2O_SE: 'Parameters, country spec'!$L$95
Name EF_electricity: 'Parameters, country spec'!$L$92

Sheet INFO
A2: Info
A4: This is a file that contains the calculation of the footprints for pork.
A6: Color codes for tabs:
B8: Results
B9: Tabs for input
B10: Intermediate calculations
B11: Figures

Sheet Figures
A2: Figures
A4: Greenhouse gas emission for bonefree pig meat across countries, to farmgate including slaughter, no waste
B6: Production of mineral fertilizer | C6: Production of capital goods | D6: Emissions from soil | E6: Diesel use field machinary | F6: Energy use for feed processing | G6: Land use change emissions | H6: Feed transports | I6: Enteric fermentation | J6: Manure management | K6: Energy use in stables | L6: Energy use for slaughter | M6: Tot | P6: Order this study: | R6: Order Lesschen:
A7: Greece | B7: ='GHG det, per kg meat'!H26 -> 0.26403225 | C7: ='GHG det, per kg meat'!I26 -> 0.14884189 | D7: ='GHG det, per kg meat'!J26+'GHG det, per kg meat'!K26 -> 0.7276135 | E7: ='GHG det, per kg meat'!L26 -> 0.25704381 | F7: ='GHG det, per kg meat'!O26 -> 0.23106045 | G7: ='GHG det, per kg meat'!P26 -> 0.26289895 | H7: ='GHG det, per kg meat'!R26 -> 0.23780349 | I7: ='GHG det, per kg meat'!S26 -> 0.25045059 | J7: ='GHG det, per kg meat'!T26 -> 4.6239267 | K7: ='GHG det, per kg meat'!W26 -> 0.53247711 | L7: ='GHG det, per kg meat'!X26 -> 0.2280915 | M7: =SUM(B7:L7) -> 7.7642402 | P7: Greece | R7: Greece
A8: Spain | B8: ='GHG det, per kg meat'!H56 -> 0.48695011 | C8: ='GHG det, per kg meat'!I56 -> 0.19640662 | D8: ='GHG det, per kg meat'!J56+'GHG det, per kg meat'!K56 -> 1.0342953 | E8: ='GHG det, per kg meat'!L56 -> 0.30921964 | F8: ='GHG det, per kg meat'!O56 -> 0.26092488 | G8: ='GHG det, per kg meat'!P56 -> 0.31235344 | H8: ='GHG det, per kg meat'!R56 -> 0.26717907 | I8: ='GHG det, per kg meat'!S56 -> 0.26801741 | J8: ='GHG det, per kg meat'!T56 -> 2.2857223 | K8: ='GHG det, per kg meat'!W56 -> 0.34626109 | L8: ='GHG det, per kg meat'!X56 -> 0.15521479 | M8: =SUM(B8:L8) -> 5.9225447 | P8: Netherlands | R8: Netherlands
A9: Netherlands | B9: ='GHG det, per kg meat'!H46 -> 0.2994407 | C9: ='GHG det, per kg meat'!I46 -> 0.1584992 | D9: ='GHG det, per kg meat'!J46+'GHG det, per kg meat'!K46 -> 0.70851011 | E9: ='GHG det, per kg meat'!L46 -> 0.15278681 | F9: ='GHG det, per kg meat'!O46 -> 0.24018796 | G9: ='GHG det, per kg meat'!P46 -> 0.23884444 | H9: ='GHG det, per kg meat'!R46 -> 0.23496083 | I9: ='GHG det, per kg meat'!S46 -> 0.23365466 | J9: ='GHG det, per kg meat'!T46 -> 2.5704535 | K9: ='GHG det, per kg meat'!W46 -> 0.4170432 | L9: ='GHG det, per kg meat'!X46 -> 0.19720038 | M9: =SUM(B9:L9) -> 5.4515818 | P9: Spain | R9: Hungary
A10: Italy | B10: ='GHG det, per kg meat'!H41 -> 0.18825363 | C10: ='GHG det, per kg meat'!I41 -> 0.150954 | D10: ='GHG det, per kg meat'!J41+'GHG det, per kg meat'!K41 -> 0.65040983 | E10: ='GHG det, per kg meat'!L41 -> 0.16338125 | F10: ='GHG det, per kg meat'!O41 -> 0.21231362 | G10: ='GHG det, per kg meat'!P41 -> 0.21659937 | H10: ='GHG det, per kg meat'!R41 -> 0.19079747 | I10: ='GHG det, per kg meat'!S41 -> 0.16859734 | J10: ='GHG det, per kg meat'!T41 -> 2.6149658 | K10: ='GHG det, per kg meat'!W41 -> 0.25080031 | L10: ='GHG det, per kg meat'!X41 -> 0.17064176 | M10: =SUM(B10:L10) -> 4.9777144 | P10: Italy | R10: Germany
A11: Hungary | B11: ='GHG det, per kg meat'!H31 -> 0.32625745 | C11: ='GHG det, per kg meat'!I31 -> 0.17888643 | D11: ='GHG det, per kg meat'!J31+'GHG det, per kg meat'!K31 -> 0.94565531 | E11: ='GHG det, per kg meat'!L31 -> 0.21755927 | F11: ='GHG det, per kg meat'!O31 -> 0.25566802 | G11: ='GHG det, per kg meat'!P31 -> 0.26275644 | H11: ='GHG det, per kg meat'!R31 -> 0.18221524 | I11: ='GHG det, per kg meat'!S31 -> 0.26501291 | J11: ='GHG det, per kg meat'!T31 -> 1.4994277 | K11: ='GHG det, per kg meat'!W31 -> 0.44809451 | L11: ='GHG det, per kg meat'!X31 -> 0.189827 | M11: =SUM(B11:L11) -> 4.7713603 | P11: France | R11: Italy
A12: France | B12: ='GHG det, per kg meat'!H16 -> 0.28782489 | C12: ='GHG det, per kg meat'!I16 -> 0.15657272 | D12: ='GHG det, per kg meat'!J16+'GHG det, per kg meat'!K16 -> 0.77835376 | E12: ='GHG det, per kg meat'!L16 -> 0.16263327 | F12: ='GHG det, per kg meat'!O16 -> 0.19659118 | G12: ='GHG det, per kg meat'!P16 -> 0.13474615 | H12: ='GHG det, per kg meat'!R16 -> 0.13103508 | I12: ='GHG det, per kg meat'!S16 -> 0.25084052 | J12: ='GHG det, per kg meat'!T16 -> 2.3172073 | K12: ='GHG det, per kg meat'!W16 -> 0.21438718 | L12: ='GHG det, per kg meat'!X16 -> 0.11598068 | M12: =SUM(B12:L12) -> 4.7461728 | P12: Germany | R12: Ireland
A13: Germany | B13: ='GHG det, per kg meat'!H21 -> 0.29050923 | C13: ='GHG det, per kg meat'!I21 -> 0.16228761 | D13: ='GHG det, per kg meat'!J21+'GHG det, per kg meat'!K21 -> 0.75439311 | E13: ='GHG det, per kg meat'!L21 -> 0.15966524 | F13: ='GHG det, per kg meat'!O21 -> 0.24404753 | G13: ='GHG det, per kg meat'!P21 -> 0.21041098 | H13: ='GHG det, per kg meat'!R21 -> 0.20817156 | I13: ='GHG det, per kg meat'!S21 -> 0.23949946 | J13: ='GHG det, per kg meat'!T21 -> 1.8346236 | K13: ='GHG det, per kg meat'!W21 -> 0.40906585 | L13: ='GHG det, per kg meat'!X21 -> 0.19091243 | M13: =SUM(B13:L13) -> 4.7035866 | P13: Poland | R13: France
A14: Poland | B14: ='GHG det, per kg meat'!H51 -> 0.36093529 | C14: ='GHG det, per kg meat'!I51 -> 0.16906965 | D14: ='GHG det, per kg meat'!J51+'GHG det, per kg meat'!K51 -> 1.0128187 | E14: ='GHG det, per kg meat'!L51 -> 0.22903581 | F14: ='GHG det, per kg meat'!O51 -> 0.30134981 | G14: ='GHG det, per kg meat'!P51 -> 0.25009243 | H14: ='GHG det, per kg meat'!R51 -> 0.13959535 | I14: ='GHG det, per kg meat'!S51 -> 0.25045059 | J14: ='GHG det, per kg meat'!T51 -> 0.76988479 | K14: ='GHG det, per kg meat'!W51 -> 0.72376428 | L14: ='GHG det, per kg meat'!X51 -> 0.2954028 | M14: =SUM(B14:L14) -> 4.5023995 | P14: Hungary | R14: Spain
A15: Denmark | B15: ='GHG det, per kg meat'!H11 -> 0.43427161 | C15: ='GHG det, per kg meat'!I11 -> 0.16537335 | D15: ='GHG det, per kg meat'!J11+'GHG det, per kg meat'!K11 -> 1.1886998 | E15: ='GHG det, per kg meat'!L11 -> 0.17931545 | F15: ='GHG det, per kg meat'!O11 -> 0.23037198 | G15: ='GHG det, per kg meat'!P11 -> 0.12684281 | H15: ='GHG det, per kg meat'!R11 -> 0.089671 | I15: ='GHG det, per kg meat'!S11 -> 0.2652831 | J15: ='GHG det, per kg meat'!T11 -> 0.68350905 | K15: ='GHG det, per kg meat'!W11 -> 0.44090826 | L15: ='GHG det, per kg meat'!X11 -> 0.18384879 | M15: =SUM(B15:L15) -> 3.9880952 | P15: Ireland | R15: Poland
A16: Ireland | B16: ='GHG det, per kg meat'!H36 -> 0.22899818 | C16: ='GHG det, per kg meat'!I36 -> 0.16221982 | D16: ='GHG det, per kg meat'!J36+'GHG det, per kg meat'!K36 -> 0.63502627 | E16: ='GHG det, per kg meat'!L36 -> 0.16231703 | F16: ='GHG det, per kg meat'!O36 -> 0.22796651 | G16: ='GHG det, per kg meat'!P36 -> 0.27064906 | H16: ='GHG det, per kg meat'!R36 -> 0.24950996 | I16: ='GHG det, per kg meat'!S36 -> 0.25164592 | J16: ='GHG det, per kg meat'!T36 -> 0.60150292 | K16: ='GHG det, per kg meat'!W36 -> 0.38534626 | L16: ='GHG det, per kg meat'!X36 -> 0.17576443 | M16: =SUM(B16:L16) -> 3.3509463 | P16: Denmark | R16: Denmark
A17: Sweden | B17: ='GHG det, per kg meat'!H61 -> 0.31979967 | C17: ='GHG det, per kg meat'!I61 -> 0.16427931 | D17: ='GHG det, per kg meat'!J61+'GHG det, per kg meat'!K61 -> 0.91063587 | E17: ='GHG det, per kg meat'!L61 -> 0.22111287 | F17: ='GHG det, per kg meat'!O61 -> 0.20024963 | G17: ='GHG det, per kg meat'!P61 -> 0.20670845 | H17: ='GHG det, per kg meat'!R61 -> 0.08940978 | I17: ='GHG det, per kg meat'!S61 -> 0.24820308 | J17: ='GHG det, per kg meat'!T61 -> 0.67187739 | K17: ='GHG det, per kg meat'!W61 -> 0.1237307 | L17: ='GHG det, per kg meat'!X61 -> 0.11536068 | M17: =SUM(B17:L17) -> 3.2713674 | P17: Sweden | R17: Sweden
P20: Explanation:
P21: - We include slaugthering that gives a high value for Poland
P22: - Ireland has only liquid manure and a lower MCF
P23: - Italy has also only liquid manure but a much higher MCF
P24: - France and Greece also has very high MCF
P25: - Hungary (and Italy, Spain, Greece) has low emissions from feed because of lower N2O-factors (dry climate)
A30: Water use
A33: Denmark | B33: 0.34945447
A34: France | B34: 0.47801159
A35: Germany | B35: 0.35489833
A36: Greece | B36: 0.38101452
A37: Hungary | B37: 0.34634088
A38: Ireland | B38: 0.33400348
A39: Italy | B39: 0.68514742
A40: Netherlands | B40: 0.47153216
A41: Poland | B41: 0.34621616
A42: Spain | B42: 1.2637786
A43: Sweden | B43: 0.33340769
A52: Notes:
A53: https://www.fao.org/3/I8686EN/i8686en.pdf

Sheet Footprints, per kg meat
A2: Footprints (per kg of bonefree meat) | M2: * Adjusted for manure
A5: Animal products | F5: Climate | L5: Land | M5: Nitrogen* | N5: Phosphorus | O5: Water | P5: Pesticides | Q5: Biodiversity | R5: Ammonia | S5: Labour | T5: Animal welfare | U5: Use of antibiotics
A6: Code | B6: Name | C6: Category | D6: Country | E6: Country code | F6: Carbon footprint, kg CO2e/kg | G6: Carbon dioxide, kg CO2/kg | H6: Methane, fossil, kg CH4/kg | I6: Methane, biogenic, kg CH4/kg | J6: Nitrous oxide, kg N2O/kg | K6: HFCs, kg HFCs/kg | L6: Cropland use, m2/kg | M6: New N input, kg N/kg | N6: New P input, kg P/kg | O6: Blue freshwater use, m3/kg | P6: Pesticide use, g a.i./kg | Q6: Extinction rate, E/MSY/kg | R6: Ammonia emission, kg NH3/kg | S6: Labour requirements, h/kg | T6: Animal welfare index per kg of bonefree meat | U6: Antibiotics use indicator/kg
A7: 21113.02 | B7: Pig meat | C7: Red meat | D7: Denmark | E7: DK | F7: ='Footprints, absolute'!F7/Production!$B$25*AF_meat -> 4.4026765 | G7: ='Footprints, absolute'!G7/Production!$B$25*AF_meat -> 2.1119131 | H7: ='Footprints, absolute'!H7/Production!$B$25*AF_meat -> 0.0022862654 | I7: ='Footprints, absolute'!I7/Production!$B$25*AF_meat -> 0.024527673 | J7: ='Footprints, absolute'!J7/Production!$B$25*AF_meat -> 0.005715698 | L7: ='Footprints, absolute'!L7/Production!$B$25*AF_meat -> 10.230202 | M7: ='Footprints, absolute'!M7/Production!$B$25*AF_meat -> 0.15865471 | N7: ='Footprints, absolute'!N7/Production!$B$25*AF_meat -> 0.017887548 | O7: ='Footprints, absolute'!O7/Production!$B$25*AF_meat -> 0.19098403 | P7: ='Footprints, absolute'!P7/Production!$B$25*AF_meat -> 0.8945119 | Q7: ='Footprints, absolute'!Q7/Production!$B$25*AF_meat -> 1.434912e-10 | R7: ='Footprints, absolute'!R7/Production!$B$25*AF_meat -> 0.04635561 | T7: ='Footprints, absolute'!T7*AF_meat -> 3.1611271 | U7: ='Footprints, absolute'!U7*AF_meat -> 37.866225
A8: 21113.02 | B8: Pig meat | C8: Red meat | D8: France | E8: FR | F8: ='Footprints, absolute'!F8/Production!$C$25*AF_meat -> 4.8737277 | G8: ='Footprints, absolute'!G8/Production!$C$25*AF_meat -> 1.414803 | H8: ='Footprints, absolute'!H8/Production!$C$25*AF_meat -> 0.0018825312 | I8: ='Footprints, absolute'!I8/Production!$C$25*AF_meat -> 0.081686695 | J8: ='Footprints, absolute'!J8/Production!$C$25*AF_meat -> 0.0043856577 | L8: ='Footprints, absolute'!L8/Production!$C$25*AF_meat -> 8.8513877 | M8: ='Footprints, absolute'!M8/Production!$C$25*AF_meat -> 0.093263408 | N8: ='Footprints, absolute'!N8/Production!$C$25*AF_meat -> 0.014469558 | O8: ='Footprints, absolute'!O8/Production!$C$25*AF_meat -> 0.21413111 | P8: ='Footprints, absolute'!P8/Production!$C$25*AF_meat -> 1.7978051 | Q8: ='Footprints, absolute'!Q8/Production!$C$25*AF_meat -> 1.5377838e-10 | R8: ='Footprints, absolute'!R8/Production!$C$25*AF_meat -> 0.056795539 | T8: ='Footprints, absolute'!T8*AF_meat -> 3.0741054 | U8: ='Footprints, absolute'!U8*AF_meat -> 55.375688
A9: 21113.02 | B9: Pig meat | C9: Red meat | D9: Germany | E9: DE | F9: ='Footprints, absolute'!F9/Production!$D$25*AF_meat -> 4.945501 | G9: ='Footprints, absolute'!G9/Production!$D$25*AF_meat -> 1.9655391 | H9: ='Footprints, absolute'!H9/Production!$D$25*AF_meat -> 0.0026147826 | I9: ='Footprints, absolute'!I9/Production!$D$25*AF_meat -> 0.059801559 | J9: ='Footprints, absolute'!J9/Production!$D$25*AF_meat -> 0.0047157483 | L9: ='Footprints, absolute'!L9/Production!$D$25*AF_meat -> 8.7029379 | M9: ='Footprints, absolute'!M9/Production!$D$25*AF_meat -> 0.092355304 | N9: ='Footprints, absolute'!N9/Production!$D$25*AF_meat -> 0.01380377 | O9: ='Footprints, absolute'!O9/Production!$D$25*AF_meat -> 0.15217429 | P9: ='Footprints, absolute'!P9/Production!$D$25*AF_meat -> 1.5023837 | Q9: ='Footprints, absolute'!Q9/Production!$D$25*AF_meat -> 1.5624589e-10 | R9: ='Footprints, absolute'!R9/Production!$D$25*AF_meat -> 0.068042426 | T9: ='Footprints, absolute'!T9*AF_meat -> 2.8364476 | U9: ='Footprints, absolute'!U9*AF_meat -> 92.777142
A10: 21113.02 | B10: Pig meat | C10: Red meat | D10: Greece | E10: GR | F10: ='Footprints, absolute'!F10/Production!$E$25*AF_meat -> 8.1801525 | G10: ='Footprints, absolute'!G10/Production!$E$25*AF_meat -> 2.3970293 | H10: ='Footprints, absolute'!H10/Production!$E$25*AF_meat -> 0.004469096 | I10: ='Footprints, absolute'!I10/Production!$E$25*AF_meat -> 0.16142936 | J10: ='Footprints, absolute'!J10/Production!$E$25*AF_meat -> 0.0047302246 | L10: ='Footprints, absolute'!L10/Production!$E$25*AF_meat -> 22.418147 | M10: ='Footprints, absolute'!M10/Production!$E$25*AF_meat -> 0.17494486 | N10: ='Footprints, absolute'!N10/Production!$E$25*AF_meat -> 0.015692703 | O10: ='Footprints, absolute'!O10/Production!$E$25*AF_meat -> 0.14729084 | P10: ='Footprints, absolute'!P10/Production!$E$25*AF_meat -> 2.3686925 | Q10: ='Footprints, absolute'!Q10/Production!$E$25*AF_meat -> 1.0554739e-09 | R10: ='Footprints, absolute'!R10/Production!$E$25*AF_meat -> 0.08157204 | T10: ='Footprints, absolute'!T10*AF_meat -> 3.0310894 | U10: ='Footprints, absolute'!U10*AF_meat -> 181.02218
A11: 21113.02 | B11: Pig meat | C11: Red meat | D11: Hungary | E11: HU | F11: ='Footprints, absolute'!F11/Production!$F$25*AF_meat -> 5.038738 | G11: ='Footprints, absolute'!G11/Production!$F$25*AF_meat -> 2.1725181 | H11: ='Footprints, absolute'!H11/Production!$F$25*AF_meat -> 0.0032673695 | I11: ='Footprints, absolute'!I11/Production!$F$25*AF_meat -> 0.05143797 | J11: ='Footprints, absolute'!J11/Production!$F$25*AF_meat -> 0.0050550442 | L11: ='Footprints, absolute'!L11/Production!$F$25*AF_meat -> 12.334916 | M11: ='Footprints, absolute'!M11/Production!$F$25*AF_meat -> 0.12760238 | N11: ='Footprints, absolute'!N11/Production!$F$25*AF_meat -> 0.027001997 | O11: ='Footprints, absolute'!O11/Production!$F$25*AF_meat -> 0.22102312 | P11: ='Footprints, absolute'!P11/Production!$F$25*AF_meat -> 1.425495 | Q11: ='Footprints, absolute'!Q11/Production!$F$25*AF_meat -> 2.4125743e-10 | R11: ='Footprints, absolute'!R11/Production!$F$25*AF_meat -> 0.057342604 | T11: ='Footprints, absolute'!T11*AF_meat -> 3.084765 | U11: ='Footprints, absolute'!U11*AF_meat -> 141.08873
A12: 21113.02 | B12: Pig meat | C12: Red meat | D12: Ireland | E12: IE | F12: ='Footprints, absolute'!F12/Production!$G$25*AF_meat -> 3.5780268 | G12: ='Footprints, absolute'!G12/Production!$G$25*AF_meat -> 1.9578823 | H12: ='Footprints, absolute'!H12/Production!$G$25*AF_meat -> 0.0022856585 | I12: ='Footprints, absolute'!I12/Production!$G$25*AF_meat -> 0.020046372 | J12: ='Footprints, absolute'!J12/Production!$G$25*AF_meat -> 0.0037024902 | L12: ='Footprints, absolute'!L12/Production!$G$25*AF_meat -> 8.8395851 | M12: ='Footprints, absolute'!M12/Production!$G$25*AF_meat -> 0.094126956 | N12: ='Footprints, absolute'!N12/Production!$G$25*AF_meat -> 0.011423845 | O12: ='Footprints, absolute'!O12/Production!$G$25*AF_meat -> 0.1779392 | P12: ='Footprints, absolute'!P12/Production!$G$25*AF_meat -> 2.504436 | Q12: ='Footprints, absolute'!Q12/Production!$G$25*AF_meat -> 1.6523698e-10 | R12: ='Footprints, absolute'!R12/Production!$G$25*AF_meat -> 0.047048234 | T12: ='Footprints, absolute'!T12*AF_meat -> 2.9473275 | U12: ='Footprints, absolute'!U12*AF_meat -> 61.421195
A13: 21113.02 | B13: Pig meat | C13: Red meat | D13: Italy | E13: IT | F13: ='Footprints, absolute'!F13/Production!$H$25*AF_meat -> 5.2090412 | G13: ='Footprints, absolute'!G13/Production!$H$25*AF_meat -> 1.6397728 | H13: ='Footprints, absolute'!H13/Production!$H$25*AF_meat -> 0.0035773467 | I13: ='Footprints, absolute'!I13/Production!$H$25*AF_meat -> 0.086171059 | J13: ='Footprints, absolute'!J13/Production!$H$25*AF_meat -> 0.0041613364 | L13: ='Footprints, absolute'!L13/Production!$H$25*AF_meat -> 9.1419229 | M13: ='Footprints, absolute'!M13/Production!$H$25*AF_meat -> 0.085126775 | N13: ='Footprints, absolute'!N13/Production!$H$25*AF_meat -> 0.017674392 | O13: ='Footprints, absolute'!O13/Production!$H$25*AF_meat -> 0.21134628 | P13: ='Footprints, absolute'!P13/Production!$H$25*AF_meat -> 1.0837798 | Q13: ='Footprints, absolute'!Q13/Production!$H$25*AF_meat -> 4.9109898e-10 | R13: ='Footprints, absolute'!R13/Production!$H$25*AF_meat -> 0.072656869 | T13: ='Footprints, absolute'!T13*AF_meat -> 2.1180347 | U13: ='Footprints, absolute'!U13*AF_meat -> 228.24391
A14: 21113.02 | B14: Pig meat | C14: Red meat | D14: Netherlands | E14: NL | F14: ='Footprints, absolute'!F14/Production!$I$25*AF_meat -> 5.6722385 | G14: ='Footprints, absolute'!G14/Production!$I$25*AF_meat -> 2.0136303 | H14: ='Footprints, absolute'!H14/Production!$I$25*AF_meat -> 0.002414773 | I14: ='Footprints, absolute'!I14/Production!$I$25*AF_meat -> 0.09439492 | J14: ='Footprints, absolute'!J14/Production!$I$25*AF_meat -> 0.0038021433 | L14: ='Footprints, absolute'!L14/Production!$I$25*AF_meat -> 8.5095427 | M14: ='Footprints, absolute'!M14/Production!$I$25*AF_meat -> 0.10311409 | N14: ='Footprints, absolute'!N14/Production!$I$25*AF_meat -> 0.01503953 | O14: ='Footprints, absolute'!O14/Production!$I$25*AF_meat -> 0.15730437 | P14: ='Footprints, absolute'!P14/Production!$I$25*AF_meat -> 1.1312008 | Q14: ='Footprints, absolute'!Q14/Production!$I$25*AF_meat -> 1.6783268e-10 | R14: ='Footprints, absolute'!R14/Production!$I$25*AF_meat -> 0.038727788 | T14: ='Footprints, absolute'!T14*AF_meat -> 2.6843761 | U14: ='Footprints, absolute'!U14*AF_meat -> 46.817323
A15: 21113.02 | B15: Pig meat | C15: Red meat | D15: Poland | E15: PL | F15: ='Footprints, absolute'!F15/Production!$J$25*AF_meat -> 4.9872978 | G15: ='Footprints, absolute'!G15/Production!$J$25*AF_meat -> 2.7612647 | H15: ='Footprints, absolute'!H15/Production!$J$25*AF_meat -> 0.0042390042 | I15: ='Footprints, absolute'!I15/Production!$J$25*AF_meat -> 0.022289001 | J15: ='Footprints, absolute'!J15/Production!$J$25*AF_meat -> 0.0054868418 | L15: ='Footprints, absolute'!L15/Production!$J$25*AF_meat -> 12.334223 | M15: ='Footprints, absolute'!M15/Production!$J$25*AF_meat -> 0.1307871 | N15: ='Footprints, absolute'!N15/Production!$J$25*AF_meat -> 0.01828969 | O15: ='Footprints, absolute'!O15/Production!$J$25*AF_meat -> 0.15033469 | P15: ='Footprints, absolute'!P15/Production!$J$25*AF_meat -> 1.2140032 | Q15: ='Footprints, absolute'!Q15/Production!$J$25*AF_meat -> 1.2909467e-10 | R15: ='Footprints, absolute'!R15/Production!$J$25*AF_meat -> 0.062476997 | T15: ='Footprints, absolute'!T15*AF_meat -> 3.0310894 | U15: ='Footprints, absolute'!U15*AF_meat -> 293.27897
A16: 21113.02 | B16: Pig meat | C16: Red meat | D16: Spain | E16: ES | F16: ='Footprints, absolute'!F16/Production!$K$25*AF_meat -> 6.1566484 | G16: ='Footprints, absolute'!G16/Production!$K$25*AF_meat -> 2.4329267 | H16: ='Footprints, absolute'!H16/Production!$K$25*AF_meat -> 0.0027574215 | I16: ='Footprints, absolute'!I16/Production!$K$25*AF_meat -> 0.081742645 | J16: ='Footprints, absolute'!J16/Production!$K$25*AF_meat -> 0.0052545757 | L16: ='Footprints, absolute'!L16/Production!$K$25*AF_meat -> 16.523226 | M16: ='Footprints, absolute'!M16/Production!$K$25*AF_meat -> 0.17845514 | N16: ='Footprints, absolute'!N16/Production!$K$25*AF_meat -> 0.022286818 | O16: ='Footprints, absolute'!O16/Production!$K$25*AF_meat -> 0.85615812 | P16: ='Footprints, absolute'!P16/Production!$K$25*AF_meat -> 1.2099963 | Q16: ='Footprints, absolute'!Q16/Production!$K$25*AF_meat -> 1.0888407e-09 | R16: ='Footprints, absolute'!R16/Production!$K$25*AF_meat -> 0.061464198 | T16: ='Footprints, absolute'!T16*AF_meat -> 3.3369942 | U16: ='Footprints, absolute'!U16*AF_meat -> 151.68936
A17: 21113.02 | B17: Pig meat | C17: Red meat | D17: Sweden | E17: SE | F17: ='Footprints, absolute'!F17/Production!$L$25*AF_meat -> 3.3526786 | G17: ='Footprints, absolute'!G17/Production!$L$25*AF_meat -> 1.4164056 | H17: ='Footprints, absolute'!H17/Production!$L$25*AF_meat -> 0.0014331784 | I17: ='Footprints, absolute'!I17/Production!$L$25*AF_meat -> 0.021743008 | J17: ='Footprints, absolute'!J17/Production!$L$25*AF_meat -> 0.0047857256 | L17: ='Footprints, absolute'!L17/Production!$L$25*AF_meat -> 11.631695 | M17: ='Footprints, absolute'!M17/Production!$L$25*AF_meat -> 0.11670893 | N17: ='Footprints, absolute'!N17/Production!$L$25*AF_meat -> 0.011882518 | O17: ='Footprints, absolute'!O17/Production!$L$25*AF_meat -> 0.16153738 | P17: ='Footprints, absolute'!P17/Production!$L$25*AF_meat -> 0.71671578 | Q17: ='Footprints, absolute'!Q17/Production!$L$25*AF_meat -> 6.9517137e-11 | R17: ='Footprints, absolute'!R17/Production!$L$25*AF_meat -> 0.049169186 | T17: ='Footprints, absolute'!T17*AF_meat -> 2.3198265 | U17: ='Footprints, absolute'!U17*AF_meat -> 18.348895

Sheet GHG det, per kg meat
H1: * Production of mineral fertiliser is adjusted to account for the N supplied by manure. | S1: **** Slaughtering pigs starts emitting methane when after 4 months
A2: GHG emissions (per kg of bonefree meat) | H2: ** Adjusted for use of manure instead of mineral fertiliser (lower emission factor for manure)
H3: *** Calculated as percentage of direct emissions due to assumption due to data limitations regarding nitrogen leaching and volatilization from soils in different regions.
S4: Animals | W4: Stables | X4: Slaughter | Z4: Control
A5: Animal products | G5: Sum | H5: Inputs | J5: Soil emissions | L5: Energy use | P5: Land use change | Q5: Feed processing | R5: Transports
A6: Code | B6: Name | C6: Category | D6: Country | E6: Country code | F6: Gas | G6: GHG | H6: Production of mineral fertilizer* | I6: Production of capital goods | J6: Direct emissions** | K6: Indirect emissions*** | L6: Diesel use field mach | M6: Energy use in greenhouses | N6: Energy use for irrigation | O6: Energy use for post-harvest proc | P6: LUC emissions | Q6: Feed processing | R6: Feed transports | S6: Enteric fermentation**** | T6: Manure management - tot | U6: Manure management - direct | V6: Manure management - indirect | W6: Energy use in stables | X6: Energy use for slaughter | Z6: Total feed, excl LUC | AA6: Feed mix emissions, kg CO2 per kg feed, excl. adjustement manure
A7: 21113.02 | B7: Pig meat | C7: Red meat | D7: Denmark | E7: DK | F7: CO2 | G7: ='GHG detailed, absolute'!G7/Production!$B$25*AF_meat -> 2.1119131 | H7: ='GHG detailed, absolute'!H7/Production!$B$25*AF_meat -> 0.3665568 | I7: ='GHG detailed, absolute'!I7/Production!$B$25*AF_meat -> 0.14729378 | J7: ='GHG detailed, absolute'!J7/Production!$B$25*AF_meat -> 0 | L7: ='GHG detailed, absolute'!L7/Production!$B$25*AF_meat -> 0.17542398 | N7: ='GHG detailed, absolute'!N7/Production!$B$25*AF_meat -> 0.008617032 | O7: ='GHG detailed, absolute'!O7/Production!$B$25*AF_meat -> 0.22375284 | P7: ='GHG detailed, absolute'!P7/Production!$B$25*AF_meat -> 0.12684281 | Q7: ='GHG detailed, absolute'!Q7/Production!$B$25*AF_meat -> 0.38866494 | R7: ='GHG detailed, absolute'!R7/Production!$B$25*AF_meat -> 0.082497385 | W7: ='GHG detailed, absolute'!W7/Production!$B$25*AF_meat -> 0.42383699 | X7: ='GHG detailed, absolute'!X7/Production!$B$25*AF_meat -> 0.16842652
A8: 21113.02 | B8: Pig meat | C8: Red meat | D8: Denmark | E8: DK | F8: CH4, fossil | G8: ='GHG detailed, absolute'!G8/Production!$B$25*AF_meat -> 0.0022862654 | H8: ='GHG detailed, absolute'!H8/Production!$B$25*AF_meat -> 7.1255808e-05 | I8: ='GHG detailed, absolute'!I8/Production!$B$25*AF_meat -> 0.00054851333 | L8: ='GHG detailed, absolute'!L8/Production!$B$25*AF_meat -> 8.3939891e-05 | N8: ='GHG detailed, absolute'!N8/Production!$B$25*AF_meat -> 8.3595318e-06 | O8: ='GHG detailed, absolute'!O8/Production!$B$25*AF_meat -> 0.00013914845 | P8: ='GHG detailed, absolute'!P8/Production!$B$25*AF_meat -> 0 | Q8: ='GHG detailed, absolute'!Q8/Production!$B$25*AF_meat -> 0.00040882702 | R8: ='GHG detailed, absolute'!R8/Production!$B$25*AF_meat -> 0.00017565541 | W8: ='GHG detailed, absolute'!W8/Production!$B$25*AF_meat -> 0.00040020353 | X8: ='GHG detailed, absolute'!X8/Production!$B$25*AF_meat -> 0.0004503624
A9: 21113.02 | B9: Pig meat | C9: Red meat | D9: Denmark | E9: DK | F9: CH4, biogenic | G9: ='GHG detailed, absolute'!G9/Production!$B$25*AF_meat -> 0.024527673 | S9: ='GHG detailed, absolute'!S9/Production!$B$25*AF_meat -> 0.0098253002 | T9: ='GHG detailed, absolute'!T9/Production!$B$25*AF_meat -> 0.014702373 | U9: ='GHG detailed, absolute'!U9/Production!$B$25*AF_meat -> 0.014702373
A10: 21113.02 | B10: Pig meat | C10: Red meat | D10: Denmark | E10: DK | F10: N2O | G10: ='GHG detailed, absolute'!G10/Production!$B$25*AF_meat -> 0.005715698 | H10: ='GHG detailed, absolute'!H10/Production!$B$25*AF_meat -> 0.00024026148 | I10: ='GHG detailed, absolute'!I10/Production!$B$25*AF_meat -> 6.351207e-06 | J10: ='GHG detailed, absolute'!J10/Production!$B$25*AF_meat -> 0.0039583741 | K10: ='GHG detailed, absolute'!K10/Production!$B$25*AF_meat -> 0.00039583741 | L10: ='GHG detailed, absolute'!L10/Production!$B$25*AF_meat -> 5.0918043e-06 | N10: ='GHG detailed, absolute'!N10/Production!$B$25*AF_meat -> 1.2009365e-07 | O10: ='GHG detailed, absolute'!O10/Production!$B$25*AF_meat -> 9.056821e-06 | P10: ='GHG detailed, absolute'!P10/Production!$B$25*AF_meat -> 0 | Q10: ='GHG detailed, absolute'!Q10/Production!$B$25*AF_meat -> 1.7708541e-05 | R10: ='GHG detailed, absolute'!R10/Production!$B$25*AF_meat -> 7.1028736e-06 | T10: ='GHG detailed, absolute'!T10/Production!$B$25*AF_meat -> 0.0010496153 | U10: ='GHG detailed, absolute'!U10/Production!$B$25*AF_meat -> 0.00058923913 | V10: ='GHG detailed, absolute'!V10/Production!$B$25*AF_meat -> 0.00046037618 | W10: ='GHG detailed, absolute'!W10/Production!$B$25*AF_meat -> 1.884692e-05 | X10: ='GHG detailed, absolute'!X10/Production!$B$25*AF_meat -> 7.3313907e-06
A11: 21113.02 | B11: Pig meat | C11: Red meat | D11: Denmark | E11: DK | F11: CO2e | G11: ='GHG detailed, absolute'!G11/Production!$B$25*AF_meat -> 4.4026765 | H11: ='GHG detailed, absolute'!H11/Production!$B$25*AF_meat -> 0.43427161 | I11: ='GHG detailed, absolute'!I11/Production!$B$25*AF_meat -> 0.16537335 | J11: ='GHG detailed, absolute'!J11/Production!$B$25*AF_meat -> 1.0806361 | K11: ='GHG detailed, absolute'!K11/Production!$B$25*AF_meat -> 0.10806361 | L11: ='GHG detailed, absolute'!L11/Production!$B$25*AF_meat -> 0.17931545 | M11: ='GHG detailed, absolute'!M11/Production!$B$25*AF_meat -> 0 | N11: ='GHG detailed, absolute'!N11/Production!$B$25*AF_meat -> 0.0088989316 | ... T11: ='GHG detailed, absolute'!T11/Production!$B$25*AF_meat -> 0.68350905 | W11: ='GHG detailed, absolute'!W11/Production!$B$25*AF_meat -> 0.44090826 | X11: ='GHG detailed, absolute'!X11/Production!$B$25*AF_meat -> 0.18384879 | Z11: ='GHG detailed, absolute'!Z11/Production!$B$25*AF_meat -> 2.8291273 | AA11: ='GHG detailed, absolute'!AA11/Production!$B$25*AF_meat -> 0.00016744729
A12: 21113.02 | B12: Pig meat | C12: Red meat | D12: France | E12: FR | F12: CO2 | G12: ='GHG detailed, absolute'!G12/Production!$C$25*AF_meat -> 1.414803 | H12: ='GHG detailed, absolute'!H12/Production!$C$25*AF_meat -> 0.24574493 | I12: ='GHG detailed, absolute'!I12/Production!$C$25*AF_meat -> 0.1403014 | J12: ='GHG detailed, absolute'!J12/Production!$C$25*AF_meat -> 0 | L12: ='GHG detailed, absolute'!L12/Production!$C$25*AF_meat -> 0.15936064 | N12: ='GHG detailed, absolute'!N12/Production!$C$25*AF_meat -> 0.0053322389 | O12: ='GHG detailed, absolute'!O12/Production!$C$25*AF_meat -> 0.19152653 | P12: ='GHG detailed, absolute'!P12/Production!$C$25*AF_meat -> 0.13474615 | Q12: ='GHG detailed, absolute'!Q12/Production!$C$25*AF_meat -> 0.1080606 | R12: ='GHG detailed, absolute'!R12/Production!$C$25*AF_meat -> 0.12620713 | W12: ='GHG detailed, absolute'!W12/Production!$C$25*AF_meat -> 0.20171788 | X12: ='GHG detailed, absolute'!X12/Production!$C$25*AF_meat -> 0.1018055
A13: 21113.02 | B13: Pig meat | C13: Red meat | D13: France | E13: FR | F13: CH4, fossil | G13: ='GHG detailed, absolute'!G13/Production!$C$25*AF_meat -> 0.0018825312 | H13: ='GHG detailed, absolute'!H13/Production!$C$25*AF_meat -> 8.7504308e-05 | I13: ='GHG detailed, absolute'!I13/Production!$C$25*AF_meat -> 0.00049365307 | L13: ='GHG detailed, absolute'!L13/Production!$C$25*AF_meat -> 7.0591389e-05 | N13: ='GHG detailed, absolute'!N13/Production!$C$25*AF_meat -> 1.5820107e-05 | O13: ='GHG detailed, absolute'!O13/Production!$C$25*AF_meat -> 0.00010346486 | P13: ='GHG detailed, absolute'!P13/Production!$C$25*AF_meat -> 0 | Q13: ='GHG detailed, absolute'!Q13/Production!$C$25*AF_meat -> 0.00032385183 | R13: ='GHG detailed, absolute'!R13/Production!$C$25*AF_meat -> 0.00012093339 | W13: ='GHG detailed, absolute'!W13/Production!$C$25*AF_meat -> 0.00023048063 | X13: ='GHG detailed, absolute'!X13/Production!$C$25*AF_meat -> 0.00043623167
A14: 21113.02 | B14: Pig meat | C14: Red meat | D14: France | E14: FR | F14: CH4, biogenic | G14: ='GHG detailed, absolute'!G14/Production!$C$25*AF_meat -> 0.081686695 | S14: ='GHG detailed, absolute'!S14/Production!$C$25*AF_meat -> 0.0092903896 | T14: ='GHG detailed, absolute'!T14/Production!$C$25*AF_meat -> 0.072396306 | U14: ='GHG detailed, absolute'!U14/Production!$C$25*AF_meat -> 0.072396306
A15: 21113.02 | B15: Pig meat | C15: Red meat | D15: France | E15: FR | F15: N2O | G15: ='GHG detailed, absolute'!G15/Production!$C$25*AF_meat -> 0.0043856577 | H15: ='GHG detailed, absolute'!H15/Production!$C$25*AF_meat -> 0.00014458727 | I15: ='GHG detailed, absolute'!I15/Production!$C$25*AF_meat -> 5.7159829e-06 | J15: ='GHG detailed, absolute'!J15/Production!$C$25*AF_meat -> 0.0025919206 | K15: ='GHG detailed, absolute'!K15/Production!$C$25*AF_meat -> 0.00025919206 | L15: ='GHG detailed, absolute'!L15/Production!$C$25*AF_meat -> 4.2820825e-06 | N15: ='GHG detailed, absolute'!N15/Production!$C$25*AF_meat -> 2.2889932e-07 | O15: ='GHG detailed, absolute'!O15/Production!$C$25*AF_meat -> 7.257861e-06 | P15: ='GHG detailed, absolute'!P15/Production!$C$25*AF_meat -> 0 | Q15: ='GHG detailed, absolute'!Q15/Production!$C$25*AF_meat -> 1.4569312e-05 | R15: ='GHG detailed, absolute'!R15/Production!$C$25*AF_meat -> 4.4840184e-06 | T15: ='GHG detailed, absolute'!T15/Production!$C$25*AF_meat -> 0.0013278648 | U15: ='GHG detailed, absolute'!U15/Production!$C$25*AF_meat -> 0.00074597414 | V15: ='GHG detailed, absolute'!V15/Production!$C$25*AF_meat -> 0.00058189064 | W15: ='GHG detailed, absolute'!W15/Production!$C$25*AF_meat -> 2.1249008e-05 | X15: ='GHG detailed, absolute'!X15/Production!$C$25*AF_meat -> 4.3057634e-06
A16: 21113.02 | B16: Pig meat | C16: Red meat | D16: France | E16: FR | F16: CO2e | G16: ='GHG detailed, absolute'!G16/Production!$C$25*AF_meat -> 4.8737277 | H16: ='GHG detailed, absolute'!H16/Production!$C$25*AF_meat -> 0.28782489 | I16: ='GHG detailed, absolute'!I16/Production!$C$25*AF_meat -> 0.15657272 | J16: ='GHG detailed, absolute'!J16/Production!$C$25*AF_meat -> 0.70759433 | K16: ='GHG detailed, absolute'!K16/Production!$C$25*AF_meat -> 0.070759433 | L16: ='GHG detailed, absolute'!L16/Production!$C$25*AF_meat -> 0.16263327 | M16: ='GHG detailed, absolute'!M16/Production!$C$25*AF_meat -> 0 | N16: ='GHG detailed, absolute'!N16/Production!$C$25*AF_meat -> 0.0058661676 | ... T16: ='GHG detailed, absolute'!T16/Production!$C$25*AF_meat -> 2.3172073 | W16: ='GHG detailed, absolute'!W16/Production!$C$25*AF_meat -> 0.21438718 | X16: ='GHG detailed, absolute'!X16/Production!$C$25*AF_meat -> 0.11598068 | Z16: ='GHG detailed, absolute'!Z16/Production!$C$25*AF_meat -> 1.975312 | AA16: ='GHG detailed, absolute'!AA16/Production!$C$25*AF_meat -> 0.00012846983
A17: 21113.02 | B17: Pig meat | C17: Red meat | D17: Germany | E17: DE | F17: CO2 | G17: ='GHG detailed, absolute'!G17/Production!$D$25*AF_meat -> 1.9655391 | H17: ='GHG detailed, absolute'!H17/Production!$D$25*AF_meat -> 0.23482506 | I17: ='GHG detailed, absolute'!I17/Production!$D$25*AF_meat -> 0.14542238 | J17: ='GHG detailed, absolute'!J17/Production!$D$25*AF_meat -> 0 | L17: ='GHG detailed, absolute'!L17/Production!$D$25*AF_meat -> 0.15645233 | N17: ='GHG detailed, absolute'!N17/Production!$D$25*AF_meat -> 0.00098801319 | O17: ='GHG detailed, absolute'!O17/Production!$D$25*AF_meat -> 0.23666323 | P17: ='GHG detailed, absolute'!P17/Production!$D$25*AF_meat -> 0.21041098 | Q17: ='GHG detailed, absolute'!Q17/Production!$D$25*AF_meat -> 0.22177413 | R17: ='GHG detailed, absolute'!R17/Production!$D$25*AF_meat -> 0.2005476 | W17: ='GHG detailed, absolute'!W17/Production!$D$25*AF_meat -> 0.38577955 | X17: ='GHG detailed, absolute'!X17/Production!$D$25*AF_meat -> 0.17267577
A18: 21113.02 | B18: Pig meat | C18: Red meat | D18: Germany | E18: DE | F18: CH4, fossil | G18: ='GHG detailed, absolute'!G18/Production!$D$25*AF_meat -> 0.0026147826 | H18: ='GHG detailed, absolute'!H18/Production!$D$25*AF_meat -> 0.00012097438 | I18: ='GHG detailed, absolute'!I18/Production!$D$25*AF_meat -> 0.00051167135 | L18: ='GHG detailed, absolute'!L18/Production!$D$25*AF_meat -> 6.9303107e-05 | N18: ='GHG detailed, absolute'!N18/Production!$D$25*AF_meat -> 3.0127992e-06 | O18: ='GHG detailed, absolute'!O18/Production!$D$25*AF_meat -> 0.0001672912 | P18: ='GHG detailed, absolute'!P18/Production!$D$25*AF_meat -> 0 | Q18: ='GHG detailed, absolute'!Q18/Production!$D$25*AF_meat -> 0.0004635397 | R18: ='GHG detailed, absolute'!R18/Production!$D$25*AF_meat -> 0.00019113216 | W18: ='GHG detailed, absolute'!W18/Production!$D$25*AF_meat -> 0.00053701473 | X18: ='GHG detailed, absolute'!X18/Production!$D$25*AF_meat -> 0.00055084316
A19: 21113.02 | B19: Pig meat | C19: Red meat | D19: Germany | E19: DE | F19: CH4, biogenic | G19: ='GHG detailed, absolute'!G19/Production!$D$25*AF_meat -> 0.059801559 | S19: ='GHG detailed, absolute'!S19/Production!$D$25*AF_meat -> 0.0088703504 | T19: ='GHG detailed, absolute'!T19/Production!$D$25*AF_meat -> 0.050931209 | U19: ='GHG detailed, absolute'!U19/Production!$D$25*AF_meat -> 0.050931209
A20: 21113.02 | B20: Pig meat | C20: Red meat | D20: Germany | E20: DE | F20: N2O | G20: ='GHG detailed, absolute'!G20/Production!$D$25*AF_meat -> 0.0047157483 | H20: ='GHG detailed, absolute'!H20/Production!$D$25*AF_meat -> 0.00019076605 | I20: ='GHG detailed, absolute'!I20/Production!$D$25*AF_meat -> 5.9246156e-06 | J20: ='GHG detailed, absolute'!J20/Production!$D$25*AF_meat -> 0.0025121316 | K20: ='GHG detailed, absolute'!K20/Production!$D$25*AF_meat -> 0.00025121316 | L20: ='GHG detailed, absolute'!L20/Production!$D$25*AF_meat -> 4.2039351e-06 | N20: ='GHG detailed, absolute'!N20/Production!$D$25*AF_meat -> 4.2031436e-08 | O20: ='GHG detailed, absolute'!O20/Production!$D$25*AF_meat -> 8.7876413e-06 | P20: ='GHG detailed, absolute'!P20/Production!$D$25*AF_meat -> 0 | Q20: ='GHG detailed, absolute'!Q20/Production!$D$25*AF_meat -> 1.9184843e-05 | R20: ='GHG detailed, absolute'!R20/Production!$D$25*AF_meat -> 7.0630991e-06 | T20: ='GHG detailed, absolute'!T20/Production!$D$25*AF_meat -> 0.0016830805 | U20: ='GHG detailed, absolute'!U20/Production!$D$25*AF_meat -> 0.00094908679 | V20: ='GHG detailed, absolute'!V20/Production!$D$25*AF_meat -> 0.00073399374 | W20: ='GHG detailed, absolute'!W20/Production!$D$25*AF_meat -> 2.6678598e-05 | X20: ='GHG detailed, absolute'!X20/Production!$D$25*AF_meat -> 6.6722551e-06
A21: 21113.02 | B21: Pig meat | C21: Red meat | D21: Germany | E21: DE | F21: CO2e | G21: ='GHG detailed, absolute'!G21/Production!$D$25*AF_meat -> 4.945501 | H21: ='GHG detailed, absolute'!H21/Production!$D$25*AF_meat -> 0.29050923 | I21: ='GHG detailed, absolute'!I21/Production!$D$25*AF_meat -> 0.16228761 | J21: ='GHG detailed, absolute'!J21/Production!$D$25*AF_meat -> 0.68581192 | K21: ='GHG detailed, absolute'!K21/Production!$D$25*AF_meat -> 0.068581192 | L21: ='GHG detailed, absolute'!L21/Production!$D$25*AF_meat -> 0.15966524 | M21: ='GHG detailed, absolute'!M21/Production!$D$25*AF_meat -> 0 | N21: ='GHG detailed, absolute'!N21/Production!$D$25*AF_meat -> 0.0010892692 | ... T21: ='GHG detailed, absolute'!T21/Production!$D$25*AF_meat -> 1.8346236 | W21: ='GHG detailed, absolute'!W21/Production!$D$25*AF_meat -> 0.40906585 | X21: ='GHG detailed, absolute'!X21/Production!$D$25*AF_meat -> 0.19091243 | Z21: ='GHG detailed, absolute'!Z21/Production!$D$25*AF_meat -> 2.2713996 | AA21: ='GHG detailed, absolute'!AA21/Production!$D$25*AF_meat -> 0.00015533629
A22: 21113.02 | B22: Pig meat | C22: Red meat | D22: Greece | E22: GR | F22: CO2 | G22: ='GHG detailed, absolute'!G22/Production!$E$25*AF_meat -> 2.3970293 | H22: ='GHG detailed, absolute'!H22/Production!$E$25*AF_meat -> 0.24467766 | I22: ='GHG detailed, absolute'!I22/Production!$E$25*AF_meat -> 0.13337397 | J22: ='GHG detailed, absolute'!J22/Production!$E$25*AF_meat -> 0 | L22: ='GHG detailed, absolute'!L22/Production!$E$25*AF_meat -> 0.25187138 | N22: ='GHG detailed, absolute'!N22/Production!$E$25*AF_meat -> 0.040334553 | O22: ='GHG detailed, absolute'!O22/Production!$E$25*AF_meat -> 0.22348699 | P22: ='GHG detailed, absolute'!P22/Production!$E$25*AF_meat -> 0.26289895 | Q22: ='GHG detailed, absolute'!Q22/Production!$E$25*AF_meat -> 0.30188957 | R22: ='GHG detailed, absolute'!R22/Production!$E$25*AF_meat -> 0.22942183 | W22: ='GHG detailed, absolute'!W22/Production!$E$25*AF_meat -> 0.50158694 | X22: ='GHG detailed, absolute'!X22/Production!$E$25*AF_meat -> 0.20748746
A23: 21113.02 | B23: Pig meat | C23: Red meat | D23: Greece | E23: GR | F23: CH4, fossil | G23: ='GHG detailed, absolute'!G23/Production!$E$25*AF_meat -> 0.004469096 | H23: ='GHG detailed, absolute'!H23/Production!$E$25*AF_meat -> 4.0839367e-05 | I23: ='GHG detailed, absolute'!I23/Production!$E$25*AF_meat -> 0.00046927879 | L23: ='GHG detailed, absolute'!L23/Production!$E$25*AF_meat -> 0.00011157053 | N23: ='GHG detailed, absolute'!N23/Production!$E$25*AF_meat -> 0.00011923863 | O23: ='GHG detailed, absolute'!O23/Production!$E$25*AF_meat -> 0.00018182566 | P23: ='GHG detailed, absolute'!P23/Production!$E$25*AF_meat -> 0 | Q23: ='GHG detailed, absolute'!Q23/Production!$E$25*AF_meat -> 0.0019509194 | R23: ='GHG detailed, absolute'!R23/Production!$E$25*AF_meat -> 0.00019453739 | W23: ='GHG detailed, absolute'!W23/Production!$E$25*AF_meat -> 0.00077320446 | X23: ='GHG detailed, absolute'!X23/Production!$E$25*AF_meat -> 0.00062768171
A24: 21113.02 | B24: Pig meat | C24: Red meat | D24: Greece | E24: GR | F24: CH4, biogenic | G24: ='GHG detailed, absolute'!G24/Production!$E$25*AF_meat -> 0.16142936 | S24: ='GHG detailed, absolute'!S24/Production!$E$25*AF_meat -> 0.0092759479 | T24: ='GHG detailed, absolute'!T24/Production!$E$25*AF_meat -> 0.15215341 | U24: ='GHG detailed, absolute'!U24/Production!$E$25*AF_meat -> 0.15215341
A25: 21113.02 | B25: Pig meat | C25: Red meat | D25: Greece | E25: GR | F25: N2O | G25: ='GHG detailed, absolute'!G25/Production!$E$25*AF_meat -> 0.0047302246 | H25: ='GHG detailed, absolute'!H25/Production!$E$25*AF_meat -> 6.6438021e-05 | I25: ='GHG detailed, absolute'!I25/Production!$E$25*AF_meat -> 5.4337544e-06 | J25: ='GHG detailed, absolute'!J25/Production!$E$25*AF_meat -> 0.0024229554 | K25: ='GHG detailed, absolute'!K25/Production!$E$25*AF_meat -> 0.00024229554 | L25: ='GHG detailed, absolute'!L25/Production!$E$25*AF_meat -> 6.7678822e-06 | N25: ='GHG detailed, absolute'!N25/Production!$E$25*AF_meat -> 1.7334674e-06 | O25: ='GHG detailed, absolute'!O25/Production!$E$25*AF_meat -> 7.8939724e-06 | P25: ='GHG detailed, absolute'!P25/Production!$E$25*AF_meat -> 0 | Q25: ='GHG detailed, absolute'!Q25/Production!$E$25*AF_meat -> 4.2213073e-05 | R25: ='GHG detailed, absolute'!R25/Production!$E$25*AF_meat -> 9.4668255e-06 | T25: ='GHG detailed, absolute'!T25/Production!$E$25*AF_meat -> 0.0018893205 | U25: ='GHG detailed, absolute'!U25/Production!$E$25*AF_meat -> 0.0010627528 | V25: ='GHG detailed, absolute'!V25/Production!$E$25*AF_meat -> 0.00082656764 | W25: ='GHG detailed, absolute'!W25/Production!$E$25*AF_meat -> 2.874975e-05 | X25: ='GHG detailed, absolute'!X25/Production!$E$25*AF_meat -> 6.9564843e-06
A26: 21113.02 | B26: Pig meat | C26: Red meat | D26: Greece | E26: GR | F26: CO2e | G26: ='GHG detailed, absolute'!G26/Production!$E$25*AF_meat -> 8.1801525 | H26: ='GHG detailed, absolute'!H26/Production!$E$25*AF_meat -> 0.26403225 | I26: ='GHG detailed, absolute'!I26/Production!$E$25*AF_meat -> 0.14884189 | J26: ='GHG detailed, absolute'!J26/Production!$E$25*AF_meat -> 0.66146682 | K26: ='GHG detailed, absolute'!K26/Production!$E$25*AF_meat -> 0.066146682 | L26: ='GHG detailed, absolute'!L26/Production!$E$25*AF_meat -> 0.25704381 | M26: ='GHG detailed, absolute'!M26/Production!$E$25*AF_meat -> 0 | N26: ='GHG detailed, absolute'!N26/Production!$E$25*AF_meat -> 0.044361101 | ... T26: ='GHG detailed, absolute'!T26/Production!$E$25*AF_meat -> 4.6239267 | W26: ='GHG detailed, absolute'!W26/Production!$E$25*AF_meat -> 0.53247711 | X26: ='GHG detailed, absolute'!X26/Production!$E$25*AF_meat -> 0.2280915 | Z26: ='GHG detailed, absolute'!Z26/Production!$E$25*AF_meat -> 2.5452066 | AA26: ='GHG detailed, absolute'!AA26/Production!$E$25*AF_meat -> 0.00025659227
A27: 21113.02 | B27: Pig meat | C27: Red meat | D27: Hungary | E27: HU | F27: CO2 | G27: ='GHG detailed, absolute'!G27/Production!$F$25*AF_meat -> 2.1725181 | H27: ='GHG detailed, absolute'!H27/Production!$F$25*AF_meat -> 0.28879327 | I27: ='GHG detailed, absolute'!I27/Production!$F$25*AF_meat -> 0.16029622 | J27: ='GHG detailed, absolute'!J27/Production!$F$25*AF_meat -> 0 | L27: ='GHG detailed, absolute'!L27/Production!$F$25*AF_meat -> 0.21318138 | N27: ='GHG detailed, absolute'!N27/Production!$F$25*AF_meat -> 0.0051949282 | O27: ='GHG detailed, absolute'!O27/Production!$F$25*AF_meat -> 0.24723686 | P27: ='GHG detailed, absolute'!P27/Production!$F$25*AF_meat -> 0.26275644 | Q27: ='GHG detailed, absolute'!Q27/Production!$F$25*AF_meat -> 0.22967162 | R27: ='GHG detailed, absolute'!R27/Production!$F$25*AF_meat -> 0.17606297 | W27: ='GHG detailed, absolute'!W27/Production!$F$25*AF_meat -> 0.41898479 | X27: ='GHG detailed, absolute'!X27/Production!$F$25*AF_meat -> 0.17033962
A28: 21113.02 | B28: Pig meat | C28: Red meat | D28: Hungary | E28: HU | F28: CH4, fossil | G28: ='GHG detailed, absolute'!G28/Production!$F$25*AF_meat -> 0.0032673695 | H28: ='GHG detailed, absolute'!H28/Production!$F$25*AF_meat -> 2.4990798e-05 | I28: ='GHG detailed, absolute'!I28/Production!$F$25*AF_meat -> 0.00056400523 | L28: ='GHG detailed, absolute'!L28/Production!$F$25*AF_meat -> 9.4432162e-05 | N28: ='GHG detailed, absolute'!N28/Production!$F$25*AF_meat -> 1.5407034e-05 | O28: ='GHG detailed, absolute'!O28/Production!$F$25*AF_meat -> 0.00020260501 | P28: ='GHG detailed, absolute'!P28/Production!$F$25*AF_meat -> 0 | Q28: ='GHG detailed, absolute'!Q28/Production!$F$25*AF_meat -> 0.00088625405 | R28: ='GHG detailed, absolute'!R28/Production!$F$25*AF_meat -> 0.00014755922 | W28: ='GHG detailed, absolute'!W28/Production!$F$25*AF_meat -> 0.0007306606 | X28: ='GHG detailed, absolute'!X28/Production!$F$25*AF_meat -> 0.00060145541
A29: 21113.02 | B29: Pig meat | C29: Red meat | D29: Hungary | E29: HU | F29: CH4, biogenic | G29: ='GHG detailed, absolute'!G29/Production!$F$25*AF_meat -> 0.05143797 | S29: ='GHG detailed, absolute'!S29/Production!$F$25*AF_meat -> 0.0098152928 | T29: ='GHG detailed, absolute'!T29/Production!$F$25*AF_meat -> 0.041622677 | U29: ='GHG detailed, absolute'!U29/Production!$F$25*AF_meat -> 0.041622677
A30: 21113.02 | B30: Pig meat | C30: Red meat | D30: Hungary | E30: HU | F30: N2O | G30: ='GHG detailed, absolute'!G30/Production!$F$25*AF_meat -> 0.0050550442 | H30: ='GHG detailed, absolute'!H30/Production!$F$25*AF_meat -> 0.0001345035 | I30: ='GHG detailed, absolute'!I30/Production!$F$25*AF_meat -> 6.5305869e-06 | J30: ='GHG detailed, absolute'!J30/Production!$F$25*AF_meat -> 0.0031490353 | K30: ='GHG detailed, absolute'!K30/Production!$F$25*AF_meat -> 0.00031490353 | L30: ='GHG detailed, absolute'!L30/Production!$F$25*AF_meat -> 5.7282667e-06 | N30: ='GHG detailed, absolute'!N30/Production!$F$25*AF_meat -> 2.2303156e-07 | O30: ='GHG detailed, absolute'!O30/Production!$F$25*AF_meat -> 8.7675053e-06 | P30: ='GHG detailed, absolute'!P30/Production!$F$25*AF_meat -> 0 | Q30: ='GHG detailed, absolute'!Q30/Production!$F$25*AF_meat -> 2.044221e-05 | R30: ='GHG detailed, absolute'!R30/Production!$F$25*AF_meat -> 6.4286201e-06 | T30: ='GHG detailed, absolute'!T30/Production!$F$25*AF_meat -> 0.0013758808 | U30: ='GHG detailed, absolute'!U30/Production!$F$25*AF_meat -> 0.00077958739 | V30: ='GHG detailed, absolute'!V30/Production!$F$25*AF_meat -> 0.00059629337 | W30: ='GHG detailed, absolute'!W30/Production!$F$25*AF_meat -> 2.6871905e-05 | X30: ='GHG detailed, absolute'!X30/Production!$F$25*AF_meat -> 5.7289698e-06
A31: 21113.02 | B31: Pig meat | C31: Red meat | D31: Hungary | E31: HU | F31: CO2e | G31: ='GHG detailed, absolute'!G31/Production!$F$25*AF_meat -> 5.038738 | H31: ='GHG detailed, absolute'!H31/Production!$F$25*AF_meat -> 0.32625745 | I31: ='GHG detailed, absolute'!I31/Production!$F$25*AF_meat -> 0.17888643 | J31: ='GHG detailed, absolute'!J31/Production!$F$25*AF_meat -> 0.85968665 | K31: ='GHG detailed, absolute'!K31/Production!$F$25*AF_meat -> 0.085968665 | L31: ='GHG detailed, absolute'!L31/Production!$F$25*AF_meat -> 0.21755927 | M31: ='GHG detailed, absolute'!M31/Production!$F$25*AF_meat -> 0 | N31: ='GHG detailed, absolute'!N31/Production!$F$25*AF_meat -> 0.0057149455 | ... T31: ='GHG detailed, absolute'!T31/Production!$F$25*AF_meat -> 1.4994277 | W31: ='GHG detailed, absolute'!W31/Production!$F$25*AF_meat -> 0.44809451 | X31: ='GHG detailed, absolute'!X31/Production!$F$25*AF_meat -> 0.189827 | Z31: ='GHG detailed, absolute'!Z31/Production!$F$25*AF_meat -> 2.6363758 | AA31: ='GHG detailed, absolute'!AA31/Production!$F$25*AF_meat -> 0.00018060317
A32: 21113.02 | B32: Pig meat | C32: Red meat | D32: Ireland | E32: IE | F32: CO2 | G32: ='GHG detailed, absolute'!G32/Production!$G$25*AF_meat -> 1.9578823 | H32: ='GHG detailed, absolute'!H32/Production!$G$25*AF_meat -> 0.18458653 | I32: ='GHG detailed, absolute'!I32/Production!$G$25*AF_meat -> 0.14536164 | J32: ='GHG detailed, absolute'!J32/Production!$G$25*AF_meat -> 0 | L32: ='GHG detailed, absolute'!L32/Production!$G$25*AF_meat -> 0.15905076 | N32: ='GHG detailed, absolute'!N32/Production!$G$25*AF_meat -> 0.0024166368 | O32: ='GHG detailed, absolute'!O32/Production!$G$25*AF_meat -> 0.22214238 | P32: ='GHG detailed, absolute'!P32/Production!$G$25*AF_meat -> 0.27064906 | Q32: ='GHG detailed, absolute'!Q32/Production!$G$25*AF_meat -> 0.20352588 | R32: ='GHG detailed, absolute'!R32/Production!$G$25*AF_meat -> 0.24058459 | W32: ='GHG detailed, absolute'!W32/Production!$G$25*AF_meat -> 0.36920442 | X32: ='GHG detailed, absolute'!X32/Production!$G$25*AF_meat -> 0.16036046
A33: 21113.02 | B33: Pig meat | C33: Red meat | D33: Ireland | E33: IE | F33: CH4, fossil | G33: ='GHG detailed, absolute'!G33/Production!$G$25*AF_meat -> 0.0022856585 | H33: ='GHG detailed, absolute'!H33/Production!$G$25*AF_meat -> 9.7462666e-05 | I33: ='GHG detailed, absolute'!I33/Production!$G$25*AF_meat -> 0.00051145761 | L33: ='GHG detailed, absolute'!L33/Production!$G$25*AF_meat -> 7.0454123e-05 | N33: ='GHG detailed, absolute'!N33/Production!$G$25*AF_meat -> 7.237342e-06 | O33: ='GHG detailed, absolute'!O33/Production!$G$25*AF_meat -> 0.00012209055 | P33: ='GHG detailed, absolute'!P33/Production!$G$25*AF_meat -> 0 | Q33: ='GHG detailed, absolute'!Q33/Production!$G$25*AF_meat -> 0.00047873576 | R33: ='GHG detailed, absolute'!R33/Production!$G$25*AF_meat -> 0.00021695403 | W33: ='GHG detailed, absolute'!W33/Production!$G$25*AF_meat -> 0.00031481978 | X33: ='GHG detailed, absolute'!X33/Production!$G$25*AF_meat -> 0.00046644663
A34: 21113.02 | B34: Pig meat | C34: Red meat | D34: Ireland | E34: IE | F34: CH4, biogenic | G34: ='GHG detailed, absolute'!G34/Production!$G$25*AF_meat -> 0.020046372 | S34: ='GHG detailed, absolute'!S34/Production!$G$25*AF_meat -> 0.0093202194 | T34: ='GHG detailed, absolute'!T34/Production!$G$25*AF_meat -> 0.010726152 | U34: ='GHG detailed, absolute'!U34/Production!$G$25*AF_meat -> 0.010726152
A35: 21113.02 | B35: Pig meat | C35: Red meat | D35: Ireland | E35: IE | F35: N2O | G35: ='GHG detailed, absolute'!G35/Production!$G$25*AF_meat -> 0.0037024902 | H35: ='GHG detailed, absolute'!H35/Production!$G$25*AF_meat -> 0.00015204125 | I35: ='GHG detailed, absolute'!I35/Production!$G$25*AF_meat -> 5.9221407e-06 | J35: ='GHG detailed, absolute'!J35/Production!$G$25*AF_meat -> 0.0021146396 | K35: ='GHG detailed, absolute'!K35/Production!$G$25*AF_meat -> 0.00021146396 | L35: ='GHG detailed, absolute'!L35/Production!$G$25*AF_meat -> 4.2737559e-06 | N35: ='GHG detailed, absolute'!N35/Production!$G$25*AF_meat -> 1.0342416e-07 | O35: ='GHG detailed, absolute'!O35/Production!$G$25*AF_meat -> 8.0067233e-06 | P35: ='GHG detailed, absolute'!P35/Production!$G$25*AF_meat -> 0 | Q35: ='GHG detailed, absolute'!Q35/Production!$G$25*AF_meat -> 2.4277411e-05 | R35: ='GHG detailed, absolute'!R35/Production!$G$25*AF_meat -> 9.0114758e-06 | T35: ='GHG detailed, absolute'!T35/Production!$G$25*AF_meat -> 0.0011424791 | U35: ='GHG detailed, absolute'!U35/Production!$G$25*AF_meat -> 0.00064189648 | V35: ='GHG detailed, absolute'!V35/Production!$G$25*AF_meat -> 0.00050058266 | W35: ='GHG detailed, absolute'!W35/Production!$G$25*AF_meat -> 2.4762682e-05 | X35: ='GHG detailed, absolute'!X35/Production!$G$25*AF_meat -> 5.508647e-06
A36: 21113.02 | B36: Pig meat | C36: Red meat | D36: Ireland | E36: IE | F36: CO2e | G36: ='GHG detailed, absolute'!G36/Production!$G$25*AF_meat -> 3.5780268 | H36: ='GHG detailed, absolute'!H36/Production!$G$25*AF_meat -> 0.22899818 | I36: ='GHG detailed, absolute'!I36/Production!$G$25*AF_meat -> 0.16221982 | J36: ='GHG detailed, absolute'!J36/Production!$G$25*AF_meat -> 0.57729661 | K36: ='GHG detailed, absolute'!K36/Production!$G$25*AF_meat -> 0.057729661 | L36: ='GHG detailed, absolute'!L36/Production!$G$25*AF_meat -> 0.16231703 | M36: ='GHG detailed, absolute'!M36/Production!$G$25*AF_meat -> 0 | N36: ='GHG detailed, absolute'!N36/Production!$G$25*AF_meat -> 0.0026605444 | ... T36: ='GHG detailed, absolute'!T36/Production!$G$25*AF_meat -> 0.60150292 | W36: ='GHG detailed, absolute'!W36/Production!$G$25*AF_meat -> 0.38534626 | X36: ='GHG detailed, absolute'!X36/Production!$G$25*AF_meat -> 0.17576443 | Z36: ='GHG detailed, absolute'!Z36/Production!$G$25*AF_meat -> 2.1637673 | AA36: ='GHG detailed, absolute'!AA36/Production!$G$25*AF_meat -> 0.00017169946
A37: 21113.02 | B37: Pig meat | C37: Red meat | D37: Italy | E37: IT | F37: CO2 | G37: ='GHG detailed, absolute'!G37/Production!$H$25*AF_meat -> 1.6397728 | H37: ='GHG detailed, absolute'!H37/Production!$H$25*AF_meat -> 0.1773049 | I37: ='GHG detailed, absolute'!I37/Production!$H$25*AF_meat -> 0.13526658 | J37: ='GHG detailed, absolute'!J37/Production!$H$25*AF_meat -> 0 | L37: ='GHG detailed, absolute'!L37/Production!$H$25*AF_meat -> 0.16009357 | N37: ='GHG detailed, absolute'!N37/Production!$H$25*AF_meat -> 0.0087543777 | O37: ='GHG detailed, absolute'!O37/Production!$H$25*AF_meat -> 0.20375441 | P37: ='GHG detailed, absolute'!P37/Production!$H$25*AF_meat -> 0.21659937 | Q37: ='GHG detailed, absolute'!Q37/Production!$H$25*AF_meat -> 0.17656043 | R37: ='GHG detailed, absolute'!R37/Production!$H$25*AF_meat -> 0.18416799 | W37: ='GHG detailed, absolute'!W37/Production!$H$25*AF_meat -> 0.22791146 | X37: ='GHG detailed, absolute'!X37/Production!$H$25*AF_meat -> 0.14935971
A38: 21113.02 | B38: Pig meat | C38: Red meat | D38: Italy | E38: IT | F38: CH4, fossil | G38: ='GHG detailed, absolute'!G38/Production!$H$25*AF_meat -> 0.0035773467 | H38: ='GHG detailed, absolute'!H38/Production!$H$25*AF_meat -> 2.6979608e-05 | I38: ='GHG detailed, absolute'!I38/Production!$H$25*AF_meat -> 0.00047593797 | L38: ='GHG detailed, absolute'!L38/Production!$H$25*AF_meat -> 7.0916051e-05 | N38: ='GHG detailed, absolute'!N38/Production!$H$25*AF_meat -> 2.5920124e-05 | O38: ='GHG detailed, absolute'!O38/Production!$H$25*AF_meat -> 0.00021840279 | P38: ='GHG detailed, absolute'!P38/Production!$H$25*AF_meat -> 0 | Q38: ='GHG detailed, absolute'!Q38/Production!$H$25*AF_meat -> 0.0013212769 | R38: ='GHG detailed, absolute'!R38/Production!$H$25*AF_meat -> 0.00015631775 | W38: ='GHG detailed, absolute'!W38/Production!$H$25*AF_meat -> 0.00061863453 | X38: ='GHG detailed, absolute'!X38/Production!$H$25*AF_meat -> 0.00066296097
A39: 21113.02 | B39: Pig meat | C39: Red meat | D39: Italy | E39: IT | F39: CH4, biogenic | G39: ='GHG detailed, absolute'!G39/Production!$H$25*AF_meat -> 0.086171059 | S39: ='GHG detailed, absolute'!S39/Production!$H$25*AF_meat -> 0.0062443459 | T39: ='GHG detailed, absolute'!T39/Production!$H$25*AF_meat -> 0.079926714 | U39: ='GHG detailed, absolute'!U39/Production!$H$25*AF_meat -> 0.079926714
A40: 21113.02 | B40: Pig meat | C40: Red meat | D40: Italy | E40: IT | F40: N2O | G40: ='GHG detailed, absolute'!G40/Production!$H$25*AF_meat -> 0.0041613364 | H40: ='GHG detailed, absolute'!H40/Production!$H$25*AF_meat -> 3.7160187e-05 | I40: ='GHG detailed, absolute'!I40/Production!$H$25*AF_meat -> 5.5108607e-06 | J40: ='GHG detailed, absolute'!J40/Production!$H$25*AF_meat -> 0.0021658669 | K40: ='GHG detailed, absolute'!K40/Production!$H$25*AF_meat -> 0.00021658669 | L40: ='GHG detailed, absolute'!L40/Production!$H$25*AF_meat -> 4.3017765e-06 | N40: ='GHG detailed, absolute'!N40/Production!$H$25*AF_meat -> 3.7605131e-07 | O40: ='GHG detailed, absolute'!O40/Production!$H$25*AF_meat -> 7.5121194e-06 | P40: ='GHG detailed, absolute'!P40/Production!$H$25*AF_meat -> 0 | Q40: ='GHG detailed, absolute'!Q40/Production!$H$25*AF_meat -> 2.1109159e-05 | R40: ='GHG detailed, absolute'!R40/Production!$H$25*AF_meat -> 7.2205657e-06 | T40: ='GHG detailed, absolute'!T40/Production!$H$25*AF_meat -> 0.0016737897 | U40: ='GHG detailed, absolute'!U40/Production!$H$25*AF_meat -> 0.00094201628 | V40: ='GHG detailed, absolute'!V40/Production!$H$25*AF_meat -> 0.00073177338 | W40: ='GHG detailed, absolute'!W40/Production!$H$25*AF_meat -> 1.6313336e-05 | X40: ='GHG detailed, absolute'!X40/Production!$H$25*AF_meat -> 5.5890824e-06
...

Sheet Footprints, per kg offal
A2: Footprints (per kg of offal) | M2: * Adjusted for manure
A5: Animal products | F5: Climate | L5: Land | M5: Nitrogen* | N5: Phosphorus | O5: Water | P5: Pesticides | Q5: Biodiversity | R5: Ammonia | S5: Labour | T5: Animal welfare | U5: Use of antibiotics
A6: Code | B6: Name | C6: Category | D6: Country | E6: Country code | F6: Carbon footprint, kg CO2e/kg | G6: Carbon dioxide, kg CO2/kg | H6: Methane, fossil, kg CH4/kg | I6: Methane, biogenic, kg CH4/kg | J6: Nitrous oxide, kg N2O/kg | K6: HFCs, kg HFCs/kg | L6: Cropland use, m2/kg | M6: New N input, kg N/kg | N6: New P input, kg P/kg | O6: Blue freshwater use, m3/kg | P6: Pesticide use, g a.i./kg | Q6: Extinction rate, E/MSY/kg | R6: Ammonia emission, kg NH3/kg | S6: Labour requirements, h/kg | T6: Animal welfare index per kg of bonefree meat | U6: Antibiotics use indicator/kg
A7: 21153 | B7: Edible offal of pigs, fresh, chilled or frozen | C7: Offals | D7: Denmark | E7: DK | F7: ='Footprints, absolute'!F7/Production!$B$30*AF_offal -> 0.59931677 | G7: ='Footprints, absolute'!G7/Production!$B$30*AF_offal -> 0.28748533 | H7: ='Footprints, absolute'!H7/Production!$B$30*AF_offal -> 0.00031121914 | I7: ='Footprints, absolute'!I7/Production!$B$30*AF_offal -> 0.0033388431 | J7: ='Footprints, absolute'!J7/Production!$B$30*AF_offal -> 0.00077805255 | L7: ='Footprints, absolute'!L7/Production!$B$30*AF_offal -> 1.392592 | M7: ='Footprints, absolute'!M7/Production!$B$30*AF_offal -> 0.021596961 | N7: ='Footprints, absolute'!N7/Production!$B$30*AF_offal -> 0.0024349524 | O7: ='Footprints, absolute'!O7/Production!$B$30*AF_offal -> 0.025997807 | P7: ='Footprints, absolute'!P7/Production!$B$30*AF_offal -> 0.12176593 | Q7: ='Footprints, absolute'!Q7/Production!$B$30*AF_offal -> 1.9532819e-11 | R7: ='Footprints, absolute'!R7/Production!$B$30*AF_offal -> 0.006310183 | T7: ='Footprints, absolute'!T7*AF_offal -> 0.073696724 | U7: ='Footprints, absolute'!U7*AF_offal -> 0.8827917
