Workbook
Name CF_biog_CH4: 'CF climate'!$C$5
Name CF_fossil_CH4: 'CF climate'!$D$5
Name CF_HCFC: 'CF climate'!$F$5
Name CF_N2O: 'CF climate'!$E$5
Name CH4_bio_codes: 'Crops CH4, bio'!$A$6:$A$118
Name CH4_bio_data: 'Crops CH4, bio'!$E$6:$N$118
Name CH4_codes: 'Crops CH4, bio'!$A$6:$A$118
Name CH4_codes: 'Crops CH4, fossil'!$A$6:$A$118
Name CH4_data: 'Crops CH4, bio'!$E$6:$N$118
Name CH4_data: 'Crops CH4, fossil'!$E$6:$N$118
Name CO2_codes: 'Crops CO2'!$A$6:$A$118
Name CO2_data: 'Crops CO2'!$E$6:$N$118
Name CO2e_codes: 'Crops CO2e'!$A$6:$A$118
Name CO2e_data: 'Crops CO2e'!$E$6:$N$118
Name Crop_codes: 'Footprints, results per kg'!$A$6:$A$6
Name Crop_codes: #REF!
Name Crop_data: #REF!
Name Crop_data_codes: #REF!
Name Crops: 'Crops CH4, bio'!$B:$B
Name Crops: 'Crops CH4, fossil'!$B:$B
Name Crops: 'Crops CO2e'!$B:$B
Name Crops: 'Crops N2O'!$B:$B
Name Crops: 'Crops CO2'!$B:$B
Name EF_capital_goods_CH4: 'Emission factors'!$C$35
Name EF_capital_goods_CO2: 'Emission factors'!$B$35
Name EF_capital_goods_N2O: 'Emission factors'!$D$35
Name EF_chips_CH4: 'Emission factors'!$C$10
Name EF_chips_CO2: 'Emission factors'!$B$10
Name EF_chips_N2O: 'Emission factors'!$D$10
Name EF_diesel_CH4: 'Emission factors'!$C$13
Name EF_diesel_CO2: 'Emission factors'!$B$13
Name EF_diesel_N2O: 'Emission factors'!$D$13
Name EF_district_heating_CH4: 'Emission factors'!$C$14
Name EF_district_heating_CO2: 'Emission factors'!$B$14
Name EF_district_heating_N2O: 'Emission factors'!$D$14
Name EF_electricity_CH4: 'Emission factors'!$C$6
Name EF_electricity_CO2: 'Emission factors'!$B$6
Name EF_electricity_N2O: 'Emission factors'!$D$6
Name EF_heating_oil_CH4: 'Emission factors'!$C$7
Name EF_heating_oil_CO2: 'Emission factors'!$B$7
Name EF_heating_oil_N2O: 'Emission factors'!$D$7
Name EF_irrigation_CH4: 'Emission factors'!$C$28
Name EF_irrigation_CO2: 'Emission factors'!$B$28
Name EF_irrigation_N2O: 'Emission factors'!$D$28
Name EF_min_fert_AN_CH4: 'Emission factors'!$C$21
Name EF_min_fert_AN_CO2: 'Emission factors'!$B$21
Name EF_min_fert_AN_N2O: 'Emission factors'!$D$21
Name EF_min_fert_BAT_CH4: 'Emission factors'!$C$20
Name EF_min_fert_BAT_CO2: 'Emission factors'!$B$20
Name EF_min_fert_BAT_N2O: 'Emission factors'!$D$20
Name EF_min_fert_CH4: 'Emission factors'!$C$20
Name EF_min_fert_CO2: 'Emission factors'!$B$20
Name EF_N2O_soils_crop_res: 'Emission factors'!$B$63
Name EF_N2O_soils_indirect: 'Emission factors'!$B$64
Name EF_N2O_soils_min_fert: 'Emission factors'!$B$62
Name EF_natural_gas_CH4: 'Emission factors'!$C$8
Name EF_natural_gas_CO2: 'Emission factors'!$B$8
Name EF_natural_gas_N2O: 'Emission factors'!$D$8
Name EF_NH3: 'Emission factors'!$B$73
Name EF_other_fossil_CH4: 'Emission factors'!$C$9

Sheet README
A2: Introduction to the dataset
A4: This is a dataset that includes data on the environmental and social indicators for crops for Spain.
A6: Results are presented in the tab "Crops, results per kg"
A7: These are calculated from the input data in tab "Crops, input data per kg"

Sheet Crop Data
A1: Code | B1: Name | C1: Category | D1: Country_name | E1: Country_code | F1: Carbon_Footprint | G1: Carbon_Dioxide | H1: Methane_fossil | I1: Methane_bio | J1: Nitrous_Oxide | K1: HFC | L1: Land | M1: N_input | N1: P_input | O1: Water | P1: Pesticides | Q1: Biodiversity | R1: Ammonia | S1: Labour | T1: Animal_Welfare | U1: Antibiotics | V1: CO2e_rm_fert_prod | W1: CO2e_rm_cap_goods | X1: CO2e_rm_soils | Y1: CO2e_rm_energy | Z1: CO2e_rm_LUC | AA1: CO2e_rm_ent_ferm | AB1: CO2e_rm_manure | AC1: CO2_rm_fert_prod | AD1: CO2_rm_cap_goods | AE1: CO2_rm_energy | AF1: CO2_rm_LUC | AG1: CH4_fossil_rm_fert_prod | AH1: CH4_fossil_rm_cap_goods | AI1: CH4_fossil_rm_energy | AJ1: CH4_bio_rm_soils_dir | AK1: CH4_bio_rm_ent_ferm | AL1: CH4_bio_rm_manure | AM1: N2O_rm_fert_prod | AN1: N2O_rm_cap_goods | AO1: N2O_rm_soils | AP1: N2O_rm_energy | AQ1: N2O_rm_manure
A2: 01270 | B2: Mushrooms and truffles | C2: Mushrooms | D2: Rest of World | E2: RoW | F2: ='Footprints, results per kg'!F6 -> 2.38 | G2: ='Footprints, results per kg'!G6 -> 0 | H2: ='Footprints, results per kg'!H6 -> 0 | I2: ='Footprints, results per kg'!I6 -> 0 | J2: ='Footprints, results per kg'!J6 -> 0 | K2: ='Footprints, results per kg'!K6 -> 0 | L2: ='Footprints, results per kg'!L6 -> 0 | M2: ='Footprints, results per kg'!M6 -> 0 | ... S2: ='Footprints, results per kg'!S6 -> 0

Sheet Footprints, results per kg
A2: Footprints (per kg of crop)
A4: Crops | F4: Climate | L4: Land | M4: Nitrogen | N4: Phosphorus | O4: Water | P4: Pesticides | Q4: Biodiversity | R4: Ammonia | S4: Labour
A5: Crop code | B5: Crop | C5: Category | D5: Grown in country | E5: Share | F5: Carbon footprint, kg CO2e/kg | G5: Carbon dioxide, kg CO2/kg | H5: Methane fossil, kg CH4/kg | I5: Methane biogenic, kg CH4/kg | J5: Nitrous oxide, kg N2O/kg | K5: HFCs, kg HFCs/kg | L5: Cropland use, m2/kg | M5: New N input, kg N/kg | N5: New P input, kg P/kg | O5: Blue freshwater use, m3/kg | P5: Pesticide use, g a.i./kg | Q5: Extinction rate, E/MSY/kg | R5: Ammonia emission, kg NH3/kg | S5: Labour requirements, h/kg | U5: Source
A6: 01270 | B6: Mushrooms and truffles | C6: Mushrooms | D6: Yes | F6: 2.38 | O6: 9 | U6: Robinson et. al (2019

Sheet Crops CO2e
A2: Emissions of CO2e per kg of crop [kg CO2e per kg of crop harvested]
A4: Crops | E4: Sum | F4: Inputs | H4: Soil emissions | J4: Energy use | N4: Land use change
A5: Code | B5: Crops | C5: Categories | D5: Cultivated in country | F5: Production of mineral fertilizer | G5: Production of capital goods | H5: Direct emissions | I5: Indirect emissions | J5: Diesel use field mach | K5: Energy use in greenhouses | L5: Energy use for irrigation | M5: Energy use for post-harvest proc | N5: LUC emissions
A6: 01371 | B6: =INDEX(Crop_data,MATCH(A6,Crop_data_codes,0),2) -> #REF! | C6: =INDEX(Crop_data,MATCH(A6,Crop_data_codes,0),3) -> #REF! | D6: =INDEX(Crop_data,MATCH(A6,Crop_data_codes,0),4) -> #REF! | E6: =IF(D6="Yes", SUM(F6:N6),"") -> #REF! | F6: =IF(D6="YES",INDEX(CO2_data,MATCH(A6,CO2_codes,0),2)+INDEX(CH4_data,MATCH(A6,CH4_codes,0),2)*CF_fossil_CH4+INDEX(CH4_bio_data,MATCH(A6,CH4_bio_codes,0),2)*CF_biog_CH4+INDEX(N2O_data,MATCH(A6,N2O_codes,0),2)*CF_N2O,"") -> #REF! | G6: =IF(D6="YES",INDEX(CO2_data,MATCH(A6,CO2_codes,0),3)+INDEX(CH4_data,MATCH(A6,CH4_codes,0),3)*CF_fossil_CH4+INDEX(CH4_bio_data,MATCH(A6,CH4_bio_codes,0),3)*CF_biog_CH4+INDEX(N2O_data,MATCH(A6,N2O_codes,0),3)*CF_N2O,"") -> #REF! | H6: =IF(D6="YES",INDEX(CO2_data,MATCH(A6,CO2_codes,0),4)+INDEX(CH4_data,MATCH(A6,CH4_codes,0),4)*CF_fossil_CH4+INDEX(CH4_bio_data,MATCH(A6,CH4_bio_codes,0),4)*CF_biog_CH4+INDEX(N2O_data,MATCH(A6,N2O_codes,0),4)*CF_N2O,"") -> #REF! | I6: =IF(D6="YES",INDEX(CO2_data,MATCH(A6,CO2_codes,0),5)+INDEX(CH4_data,MATCH(A6,CH4_codes,0),5)*CF_fossil_CH4+INDEX(CH4_bio_data,MATCH(A6,CH4_bio_codes,0),5)*CF_biog_CH4+INDEX(N2O_data,MATCH(A6,N2O_codes,0),5)*CF_N2O,"") -> #REF! | J6: =IF(D6="YES",INDEX(CO2_data,MATCH(A6,CO2_codes,0),6)+INDEX(CH4_data,MATCH(A6,CH4_codes,0),6)*CF_fossil_CH4+INDEX(CH4_bio_data,MATCH(A6,CH4_bio_codes,0),6)*CF_biog_CH4+INDEX(N2O_data,MATCH(A6,N2O_codes,0),6)*CF_N2O,"") -> #REF! | K6: =IF(D6="YES",INDEX(CO2_data,MATCH(A6,CO2_codes,0),7)+INDEX(CH4_data,MATCH(A6,CH4_codes,0),7)*CF_fossil_CH4+INDEX(CH4_bio_data,MATCH(A6,CH4_bio_codes,0),7)*CF_biog_CH4+INDEX(N2O_data,MATCH(A6,N2O_codes,0),7)*CF_N2O,"") -> #REF! | L6: =IF(D6="YES",INDEX(CO2_data,MATCH(A6,CO2_codes,0),8)+INDEX(CH4_data,MATCH(A6,CH4_codes,0),8)*CF_fossil_CH4+INDEX(CH4_bio_data,MATCH(A6,CH4_bio_codes,0),8)*CF_biog_CH4+INDEX(N2O_data,MATCH(A6,N2O_codes,0),8)*CF_N2O,"") -> #REF! | M6: =IF(D6="YES",INDEX(CO2_data,MATCH(A6,CO2_codes,0),9)+INDEX(CH4_data,MATCH(A6,CH4_codes,0),9)*CF_fossil_CH4+INDEX(CH4_bio_data,MATCH(A6,CH4_bio_codes,0),9)*CF_biog_CH4+INDEX(N2O_data,MATCH(A6,N2O_codes,0),9)*CF_N2O,"") -> #REF! | N6: =IF(D6="YES",INDEX(CO2_data,MATCH(A6,CO2_codes,0),10)+INDEX(CH4_data,MATCH(A6,CH4_codes,0),10)*CF_fossil_CH4+INDEX(CH4_bio_data,MATCH(A6,CH4_bio_codes,0),10)*CF_biog_CH4+INDEX(N2O_data,MATCH(A6,N2O_codes,0),10)*CF_N2O,"") -> #REF!
A7: 01654 | B7: =INDEX(Crop_data,MATCH(A7,Crop_data_codes,0),2) -> #REF! | C7: =INDEX(Crop_data,MATCH(A7,Crop_data_codes,0),3) -> #REF! | D7: =INDEX(Crop_data,MATCH(A7,Crop_data_codes,0),4) -> #REF! | E7: =IF(D7="Yes", SUM(F7:N7),"") -> #REF! | F7: =IF(D7="YES",INDEX(CO2_data,MATCH(A7,CO2_codes,0),2)+INDEX(CH4_data,MATCH(A7,CH4_codes,0),2)*CF_fossil_CH4+INDEX(CH4_bio_data,MATCH(A7,CH4_bio_codes,0),2)*CF_biog_CH4+INDEX(N2O_data,MATCH(A7,N2O_codes,0),2)*CF_N2O,"") -> #REF! | G7: =IF(D7="YES",INDEX(CO2_data,MATCH(A7,CO2_codes,0),3)+INDEX(CH4_data,MATCH(A7,CH4_codes,0),3)*CF_fossil_CH4+INDEX(CH4_bio_data,MATCH(A7,CH4_bio_codes,0),3)*CF_biog_CH4+INDEX(N2O_data,MATCH(A7,N2O_codes,0),3)*CF_N2O,"") -> #REF! | H7: =IF(D7="YES",INDEX(CO2_data,MATCH(A7,CO2_codes,0),4)+INDEX(CH4_data,MATCH(A7,CH4_codes,0),4)*CF_fossil_CH4+INDEX(CH4_bio_data,MATCH(A7,CH4_bio_codes,0),4)*CF_biog_CH4+INDEX(N2O_data,MATCH(A7,N2O_codes,0),4)*CF_N2O,"") -> #REF! | I7: =IF(D7="YES",INDEX(CO2_data,MATCH(A7,CO2_codes,0),5)+INDEX(CH4_data,MATCH(A7,CH4_codes,0),5)*CF_fossil_CH4+INDEX(CH4_bio_data,MATCH(A7,CH4_bio_codes,0),5)*CF_biog_CH4+INDEX(N2O_data,MATCH(A7,N2O_codes,0),5)*CF_N2O,"") -> #REF! | J7: =IF(D7="YES",INDEX(CO2_data,MATCH(A7,CO2_codes,0),6)+INDEX(CH4_data,MATCH(A7,CH4_codes,0),6)*CF_fossil_CH4+INDEX(CH4_bio_data,MATCH(A7,CH4_bio_codes,0),6)*CF_biog_CH4+INDEX(N2O_data,MATCH(A7,N2O_codes,0),6)*CF_N2O,"") -> #REF! | K7: =IF(D7="YES",INDEX(CO2_data,MATCH(A7,CO2_codes,0),7)+INDEX(CH4_data,MATCH(A7,CH4_codes,0),7)*CF_fossil_CH4+INDEX(CH4_bio_data,MATCH(A7,CH4_bio_codes,0),7)*CF_biog_CH4+INDEX(N2O_data,MATCH(A7,N2O_codes,0),7)*CF_N2O,"") -> #REF! | L7: =IF(D7="YES",INDEX(CO2_data,MATCH(A7,CO2_codes,0),8)+INDEX(CH4_data,MATCH(A7,CH4_codes,0),8)*CF_fossil_CH4+INDEX(CH4_bio_data,MATCH(A7,CH4_bio_codes,0),8)*CF_biog_CH4+INDEX(N2O_data,MATCH(A7,N2O_codes,0),8)*CF_N2O,"") -> #REF! | M7: =IF(D7="YES",INDEX(CO2_data,MATCH(A7,CO2_codes,0),9)+INDEX(CH4_data,MATCH(A7,CH4_codes,0),9)*CF_fossil_CH4+INDEX(CH4_bio_data,MATCH(A7,CH4_bio_codes,0),9)*CF_biog_CH4+INDEX(N2O_data,MATCH(A7,N2O_codes,0),9)*CF_N2O,"") -> #REF! | N7: =IF(D7="YES",INDEX(CO2_data,MATCH(A7,CO2_codes,0),10)+INDEX(CH4_data,MATCH(A7,CH4_codes,0),10)*CF_fossil_CH4+INDEX(CH4_bio_data,MATCH(A7,CH4_bio_codes,0),10)*CF_biog_CH4+INDEX(N2O_data,MATCH(A7,N2O_codes,0),10)*CF_N2O,"") -> #REF!
A8: 01341 | B8: =INDEX(Crop_data,MATCH(A8,Crop_data_codes,0),2) -> #REF! | C8: =INDEX(Crop_data,MATCH(A8,Crop_data_codes,0),3) -> #REF! | D8: =INDEX(Crop_data,MATCH(A8,Crop_data_codes,0),4) -> #REF! | E8: =IF(D8="Yes", SUM(F8:N8),"") -> #REF! | F8: =IF(D8="YES",INDEX(CO2_data,MATCH(A8,CO2_codes,0),2)+INDEX(CH4_data,MATCH(A8,CH4_codes,0),2)*CF_fossil_CH4+INDEX(CH4_bio_data,MATCH(A8,CH4_bio_codes,0),2)*CF_biog_CH4+INDEX(N2O_data,MATCH(A8,N2O_codes,0),2)*CF_N2O,"") -> #REF! | G8: =IF(D8="YES",INDEX(CO2_data,MATCH(A8,CO2_codes,0),3)+INDEX(CH4_data,MATCH(A8,CH4_codes,0),3)*CF_fossil_CH4+INDEX(CH4_bio_data,MATCH(A8,CH4_bio_codes,0),3)*CF_biog_CH4+INDEX(N2O_data,MATCH(A8,N2O_codes,0),3)*CF_N2O,"") -> #REF! | H8: =IF(D8="YES",INDEX(CO2_data,MATCH(A8,CO2_codes,0),4)+INDEX(CH4_data,MATCH(A8,CH4_codes,0),4)*CF_fossil_CH4+INDEX(CH4_bio_data,MATCH(A8,CH4_bio_codes,0),4)*CF_biog_CH4+INDEX(N2O_data,MATCH(A8,N2O_codes,0),4)*CF_N2O,"") -> #REF! | I8: =IF(D8="YES",INDEX(CO2_data,MATCH(A8,CO2_codes,0),5)+INDEX(CH4_data,MATCH(A8,CH4_codes,0),5)*CF_fossil_CH4+INDEX(CH4_bio_data,MATCH(A8,CH4_bio_codes,0),5)*CF_biog_CH4+INDEX(N2O_data,MATCH(A8,N2O_codes,0),5)*CF_N2O,"") -> #REF! | J8: =IF(D8="YES",INDEX(CO2_data,MATCH(A8,CO2_codes,0),6)+INDEX(CH4_data,MATCH(A8,CH4_codes,0),6)*CF_fossil_CH4+INDEX(CH4_bio_data,MATCH(A8,CH4_bio_codes,0),6)*CF_biog_CH4+INDEX(N2O_data,MATCH(A8,N2O_codes,0),6)*CF_N2O,"") -> #REF! | K8: =IF(D8="YES",INDEX(CO2_data,MATCH(A8,CO2_codes,0),7)+INDEX(CH4_data,MATCH(A8,CH4_codes,0),7)*CF_fossil_CH4+INDEX(CH4_bio_data,MATCH(A8,CH4_bio_codes,0),7)*CF_biog_CH4+INDEX(N2O_data,MATCH(A8,N2O_codes,0),7)*CF_N2O,"") -> #REF! | L8: =IF(D8="YES",INDEX(CO2_data,MATCH(A8,CO2_codes,0),8)+INDEX(CH4_data,MATCH(A8,CH4_codes,0),8)*CF_fossil_CH4+INDEX(CH4_bio_data,MATCH(A8,CH4_bio_codes,0),8)*CF_biog_CH4+INDEX(N2O_data,MATCH(A8,N2O_codes,0),8)*CF_N2O,"") -> #REF! | M8: =IF(D8="YES",INDEX(CO2_data,MATCH(A8,CO2_codes,0),9)+INDEX(CH4_data,MATCH(A8,CH4_codes,0),9)*CF_fossil_CH4+INDEX(CH4_bio_data,MATCH(A8,CH4_bio_codes,0),9)*CF_biog_CH4+INDEX(N2O_data,MATCH(A8,N2O_codes,0),9)*CF_N2O,"") -> #REF! | N8: =IF(D8="YES",INDEX(CO2_data,MATCH(A8,CO2_codes,0),10)+INDEX(CH4_data,MATCH(A8,CH4_codes,0),10)*CF_fossil_CH4+INDEX(CH4_bio_data,MATCH(A8,CH4_bio_codes,0),10)*CF_biog_CH4+INDEX(N2O_data,MATCH(A8,N2O_codes,0),10)*CF_N2O,"") -> #REF!
A9: 01343 | B9: =INDEX(Crop_data,MATCH(A9,Crop_data_codes,0),2) -> #REF! | C9: =INDEX(Crop_data,MATCH(A9,Crop_data_codes,0),3) -> #REF! | D9: =INDEX(Crop_data,MATCH(A9,Crop_data_codes,0),4) -> #REF! | E9: =IF(D9="Yes", SUM(F9:N9),"") -> #REF! | F9: =IF(D9="YES",INDEX(CO2_data,MATCH(A9,CO2_codes,0),2)+INDEX(CH4_data,MATCH(A9,CH4_codes,0),2)*CF_fossil_CH4+INDEX(CH4_bio_data,MATCH(A9,CH4_bio_codes,0),2)*CF_biog_CH4+INDEX(N2O_data,MATCH(A9,N2O_codes,0),2)*CF_N2O,"") -> #REF! | G9: =IF(D9="YES",INDEX(CO2_data,MATCH(A9,CO2_codes,0),3)+INDEX(CH4_data,MATCH(A9,CH4_codes,0),3)*CF_fossil_CH4+INDEX(CH4_bio_data,MATCH(A9,CH4_bio_codes,0),3)*CF_biog_CH4+INDEX(N2O_data,MATCH(A9,N2O_codes,0),3)*CF_N2O,"") -> #REF! | H9: =IF(D9="YES",INDEX(CO2_data,MATCH(A9,CO2_codes,0),4)+INDEX(CH4_data,MATCH(A9,CH4_codes,0),4)*CF_fossil_CH4+INDEX(CH4_bio_data,MATCH(A9,CH4_bio_codes,0),4)*CF_biog_CH4+INDEX(N2O_data,MATCH(A9,N2O_codes,0),4)*CF_N2O,"") -> #REF! | I9: =IF(D9="YES",INDEX(CO2_data,MATCH(A9,CO2_codes,0),5)+INDEX(CH4_data,MATCH(A9,CH4_codes,0),5)*CF_fossil_CH4+INDEX(CH4_bio_data,MATCH(A9,CH4_bio_codes,0),5)*CF_biog_CH4+INDEX(N2O_data,MATCH(A9,N2O_codes,0),5)*CF_N2O,"") -> #REF! | J9: =IF(D9="YES",INDEX(CO2_data,MATCH(A9,CO2_codes,0),6)+INDEX(CH4_data,MATCH(A9,CH4_codes,0),6)*CF_fossil_CH4+INDEX(CH4_bio_data,MATCH(A9,CH4_bio_codes,0),6)*CF_biog_CH4+INDEX(N2O_data,MATCH(A9,N2O_codes,0),6)*CF_N2O,"") -> #REF! | K9: =IF(D9="YES",INDEX(CO2_data,MATCH(A9,CO2_codes,0),7)+INDEX(CH4_data,MATCH(A9,CH4_codes,0),7)*CF_fossil_CH4+INDEX(CH4_bio_data,MATCH(A9,CH4_bio_codes,0),7)*CF_biog_CH4+INDEX(N2O_data,MATCH(A9,N2O_codes,0),7)*CF_N2O,"") -> #REF! | L9: =IF(D9="YES",INDEX(CO2_data,MATCH(A9,CO2_codes,0),8)+INDEX(CH4_data,MATCH(A9,CH4_codes,0),8)*CF_fossil_CH4+INDEX(CH4_bio_data,MATCH(A9,CH4_bio_codes,0),8)*CF_biog_CH4+INDEX(N2O_data,MATCH(A9,N2O_codes,0),8)*CF_N2O,"") -> #REF! | M9: =IF(D9="YES",INDEX(CO2_data,MATCH(A9,CO2_codes,0),9)+INDEX(CH4_data,MATCH(A9,CH4_codes,0),9)*CF_fossil_CH4+INDEX(CH4_bio_data,MATCH(A9,CH4_bio_codes,0),9)*CF_biog_CH4+INDEX(N2O_data,MATCH(A9,N2O_codes,0),9)*CF_N2O,"") -> #REF! | N9: =IF(D9="YES",INDEX(CO2_data,MATCH(A9,CO2_codes,0),10)+INDEX(CH4_data,MATCH(A9,CH4_codes,0),10)*CF_fossil_CH4+INDEX(CH4_bio_data,MATCH(A9,CH4_bio_codes,0),10)*CF_biog_CH4+INDEX(N2O_data,MATCH(A9,N2O_codes,0),10)*CF_N2O,"") -> #REF!
A10: 01216 | B10: =INDEX(Crop_data,MATCH(A10,Crop_data_codes,0),2) -> #REF! | C10: =INDEX(Crop_data,MATCH(A10,Crop_data_codes,0),3) -> #REF! | D10: =INDEX(Crop_data,MATCH(A10,Crop_data_codes,0),4) -> #REF! | E10: =IF(D10="Yes", SUM(F10:N10),"") -> #REF! | F10: =IF(D10="YES",INDEX(CO2_data,MATCH(A10,CO2_codes,0),2)+INDEX(CH4_data,MATCH(A10,CH4_codes,0),2)*CF_fossil_CH4+INDEX(CH4_bio_data,MATCH(A10,CH4_bio_codes,0),2)*CF_biog_CH4+INDEX(N2O_data,MATCH(A10,N2O_codes,0),2)*CF_N2O,"") -> #REF! | G10: =IF(D10="YES",INDEX(CO2_data,MATCH(A10,CO2_codes,0),3)+INDEX(CH4_data,MATCH(A10,CH4_codes,0),3)*CF_fossil_CH4+INDEX(CH4_bio_data,MATCH(A10,CH4_bio_codes,0),3)*CF_biog_CH4+INDEX(N2O_data,MATCH(A10,N2O_codes,0),3)*CF_N2O,"") -> #REF! | H10: =IF(D10="YES",INDEX(CO2_data,MATCH(A10,CO2_codes,0),4)+INDEX(CH4_data,MATCH(A10,CH4_codes,0),4)*CF_fossil_CH4+INDEX(CH4_bio_data,MATCH(A10,CH4_bio_codes,0),4)*CF_biog_CH4+INDEX(N2O_data,MATCH(A10,N2O_codes,0),4)*CF_N2O,"") -> #REF! | I10: =IF(D10="YES",INDEX(CO2_data,MATCH(A10,CO2_codes,0),5)+INDEX(CH4_data,MATCH(A10,CH4_codes,0),5)*CF_fossil_CH4+INDEX(CH4_bio_data,MATCH(A10,CH4_bio_codes,0),5)*CF_biog_CH4+INDEX(N2O_data,MATCH(A10,N2O_codes,0),5)*CF_N2O,"") -> #REF! | J10: =IF(D10="YES",INDEX(CO2_data,MATCH(A10,CO2_codes,0),6)+INDEX(CH4_data,MATCH(A10,CH4_codes,0),6)*CF_fossil_CH4+INDEX(CH4_bio_data,MATCH(A10,CH4_bio_codes,0),6)*CF_biog_CH4+INDEX(N2O_data,MATCH(A10,N2O_codes,0),6)*CF_N2O,"") -> #REF! | K10: =IF(D10="YES",INDEX(CO2_data,MATCH(A10,CO2_codes,0),7)+INDEX(CH4_data,MATCH(A10,CH4_codes,0),7)*CF_fossil_CH4+INDEX(CH4_bio_data,MATCH(A10,CH4_bio_codes,0),7)*CF_biog_CH4+INDEX(N2O_data,MATCH(A10,N2O_codes,0),7)*CF_N2O,"") -> #REF! | L10: =IF(D10="YES",INDEX(CO2_data,MATCH(A10,CO2_codes,0),8)+INDEX(CH4_data,MATCH(A10,CH4_codes,0),8)*CF_fossil_CH4+INDEX(CH4_bio_data,MATCH(A10,CH4_bio_codes,0),8)*CF_biog_CH4+INDEX(N2O_data,MATCH(A10,N2O_codes,0),8)*CF_N2O,"") -> #REF! | M10: =IF(D10="YES",INDEX(CO2_data,MATCH(A10,CO2_codes,0),9)+INDEX(CH4_data,MATCH(A10,CH4_codes,0),9)*CF_fossil_CH4+INDEX(CH4_bio_data,MATCH(A10,CH4_bio_codes,0),9)*CF_biog_CH4+INDEX(N2O_data,MATCH(A10,N2O_codes,0),9)*CF_N2O,"") -> #REF! | N10: =IF(D10="YES",INDEX(CO2_data,MATCH(A10,CO2_codes,0),10)+INDEX(CH4_data,MATCH(A10,CH4_codes,0),10)*CF_fossil_CH4+INDEX(CH4_bio_data,MATCH(A10,CH4_bio_codes,0),10)*CF_biog_CH4+INDEX(N2O_data,MATCH(A10,N2O_codes,0),10)*CF_N2O,"") -> #REF!
A11: 01211 | B11: =INDEX(Crop_data,MATCH(A11,Crop_data_codes,0),2) -> #REF! | C11: =INDEX(Crop_data,MATCH(A11,Crop_data_codes,0),3) -> #REF! | D11: =INDEX(Crop_data,MATCH(A11,Crop_data_codes,0),4) -> #REF! | E11: =IF(D11="Yes", SUM(F11:N11),"") -> #REF! | F11: =IF(D11="YES",INDEX(CO2_data,MATCH(A11,CO2_codes,0),2)+INDEX(CH4_data,MATCH(A11,CH4_codes,0),2)*CF_fossil_CH4+INDEX(CH4_bio_data,MATCH(A11,CH4_bio_codes,0),2)*CF_biog_CH4+INDEX(N2O_data,MATCH(A11,N2O_codes,0),2)*CF_N2O,"") -> #REF! | G11: =IF(D11="YES",INDEX(CO2_data,MATCH(A11,CO2_codes,0),3)+INDEX(CH4_data,MATCH(A11,CH4_codes,0),3)*CF_fossil_CH4+INDEX(CH4_bio_data,MATCH(A11,CH4_bio_codes,0),3)*CF_biog_CH4+INDEX(N2O_data,MATCH(A11,N2O_codes,0),3)*CF_N2O,"") -> #REF! | H11: =IF(D11="YES",INDEX(CO2_data,MATCH(A11,CO2_codes,0),4)+INDEX(CH4_data,MATCH(A11,CH4_codes,0),4)*CF_fossil_CH4+INDEX(CH4_bio_data,MATCH(A11,CH4_bio_codes,0),4)*CF_biog_CH4+INDEX(N2O_data,MATCH(A11,N2O_codes,0),4)*CF_N2O,"") -> #REF! | I11: =IF(D11="YES",INDEX(CO2_data,MATCH(A11,CO2_codes,0),5)+INDEX(CH4_data,MATCH(A11,CH4_codes,0),5)*CF_fossil_CH4+INDEX(CH4_bio_data,MATCH(A11,CH4_bio_codes,0),5)*CF_biog_CH4+INDEX(N2O_data,MATCH(A11,N2O_codes,0),5)*CF_N2O,"") -> #REF! | J11: =IF(D11="YES",INDEX(CO2_data,MATCH(A11,CO2_codes,0),6)+INDEX(CH4_data,MATCH(A11,CH4_codes,0),6)*CF_fossil_CH4+INDEX(CH4_bio_data,MATCH(A11,CH4_bio_codes,0),6)*CF_biog_CH4+INDEX(N2O_data,MATCH(A11,N2O_codes,0),6)*CF_N2O,"") -> #REF! | K11: =IF(D11="YES",INDEX(CO2_data,MATCH(A11,CO2_codes,0),7)+INDEX(CH4_data,MATCH(A11,CH4_codes,0),7)*CF_fossil_CH4+INDEX(CH4_bio_data,MATCH(A11,CH4_bio_codes,0),7)*CF_biog_CH4+INDEX(N2O_data,MATCH(A11,N2O_codes,0),7)*CF_N2O,"") -> #REF! | L11: =IF(D11="YES",INDEX(CO2_data,MATCH(A11,CO2_codes,0),8)+INDEX(CH4_data,MATCH(A11,CH4_codes,0),8)*CF_fossil_CH4+INDEX(CH4_bio_data,MATCH(A11,CH4_bio_codes,0),8)*CF_biog_CH4+INDEX(N2O_data,MATCH(A11,N2O_codes,0),8)*CF_N2O,"") -> #REF! | M11: =IF(D11="YES",INDEX(CO2_data,MATCH(A11,CO2_codes,0),9)+INDEX(CH4_data,MATCH(A11,CH4_codes,0),9)*CF_fossil_CH4+INDEX(CH4_bio_data,MATCH(A11,CH4_bio_codes,0),9)*CF_biog_CH4+INDEX(N2O_data,MATCH(A11,N2O_codes,0),9)*CF_N2O,"") -> #REF! | N11: =IF(D11="YES",INDEX(CO2_data,MATCH(A11,CO2_codes,0),10)+INDEX(CH4_data,MATCH(A11,CH4_codes,0),10)*CF_fossil_CH4+INDEX(CH4_bio_data,MATCH(A11,CH4_bio_codes,0),10)*CF_biog_CH4+INDEX(N2O_data,MATCH(A11,N2O_codes,0),10)*CF_N2O,"") -> #REF!
A12: 01311 | B12: =INDEX(Crop_data,MATCH(A12,Crop_data_codes,0),2) -> #REF! | C12: =INDEX(Crop_data,MATCH(A12,Crop_data_codes,0),3) -> #REF! | D12: =INDEX(Crop_data,MATCH(A12,Crop_data_codes,0),4) -> #REF! | E12: =IF(D12="Yes", SUM(F12:N12),"") -> #REF! | F12: =IF(D12="YES",INDEX(CO2_data,MATCH(A12,CO2_codes,0),2)+INDEX(CH4_data,MATCH(A12,CH4_codes,0),2)*CF_fossil_CH4+INDEX(CH4_bio_data,MATCH(A12,CH4_bio_codes,0),2)*CF_biog_CH4+INDEX(N2O_data,MATCH(A12,N2O_codes,0),2)*CF_N2O,"") -> #REF! | G12: =IF(D12="YES",INDEX(CO2_data,MATCH(A12,CO2_codes,0),3)+INDEX(CH4_data,MATCH(A12,CH4_codes,0),3)*CF_fossil_CH4+INDEX(CH4_bio_data,MATCH(A12,CH4_bio_codes,0),3)*CF_biog_CH4+INDEX(N2O_data,MATCH(A12,N2O_codes,0),3)*CF_N2O,"") -> #REF! | H12: =IF(D12="YES",INDEX(CO2_data,MATCH(A12,CO2_codes,0),4)+INDEX(CH4_data,MATCH(A12,CH4_codes,0),4)*CF_fossil_CH4+INDEX(CH4_bio_data,MATCH(A12,CH4_bio_codes,0),4)*CF_biog_CH4+INDEX(N2O_data,MATCH(A12,N2O_codes,0),4)*CF_N2O,"") -> #REF! | I12: =IF(D12="YES",INDEX(CO2_data,MATCH(A12,CO2_codes,0),5)+INDEX(CH4_data,MATCH(A12,CH4_codes,0),5)*CF_fossil_CH4+INDEX(CH4_bio_data,MATCH(A12,CH4_bio_codes,0),5)*CF_biog_CH4+INDEX(N2O_data,MATCH(A12,N2O_codes,0),5)*CF_N2O,"") -> #REF! | J12: =IF(D12="YES",INDEX(CO2_data,MATCH(A12,CO2_codes,0),6)+INDEX(CH4_data,MATCH(A12,CH4_codes,0),6)*CF_fossil_CH4+INDEX(CH4_bio_data,MATCH(A12,CH4_bio_codes,0),6)*CF_biog_CH4+INDEX(N2O_data,MATCH(A12,N2O_codes,0),6)*CF_N2O,"") -> #REF! | K12: =IF(D12="YES",INDEX(CO2_data,MATCH(A12,CO2_codes,0),7)+INDEX(CH4_data,MATCH(A12,CH4_codes,0),7)*CF_fossil_CH4+INDEX(CH4_bio_data,MATCH(A12,CH4_bio_codes,0),7)*CF_biog_CH4+INDEX(N2O_data,MATCH(A12,N2O_codes,0),7)*CF_N2O,"") -> #REF! | L12: =IF(D12="YES",INDEX(CO2_data,MATCH(A12,CO2_codes,0),8)+INDEX(CH4_data,MATCH(A12,CH4_codes,0),8)*CF_fossil_CH4+INDEX(CH4_bio_data,MATCH(A12,CH4_bio_codes,0),8)*CF_biog_CH4+INDEX(N2O_data,MATCH(A12,N2O_codes,0),8)*CF_N2O,"") -> #REF! | M12: =IF(D12="YES",INDEX(CO2_data,MATCH(A12,CO2_codes,0),9)+INDEX(CH4_data,MATCH(A12,CH4_codes,0),9)*CF_fossil_CH4+INDEX(CH4_bio_data,MATCH(A12,CH4_bio_codes,0),9)*CF_biog_CH4+INDEX(N2O_data,MATCH(A12,N2O_codes,0),9)*CF_N2O,"") -> #REF! | N12: =IF(D12="YES",INDEX(CO2_data,MATCH(A12,CO2_codes,0),10)+INDEX(CH4_data,MATCH(A12,CH4_codes,0),10)*CF_fossil_CH4+INDEX(CH4_bio_data,MATCH(A12,CH4_bio_codes,0),10)*CF_biog_CH4+INDEX(N2O_data,MATCH(A12,N2O_codes,0),10)*CF_N2O,"") -> #REF!
A13: 01312 | B13: =INDEX(Crop_data,MATCH(A13,Crop_data_codes,0),2) -> #REF! | C13: =INDEX(Crop_data,MATCH(A13,Crop_data_codes,0),3) -> #REF! | D13: =INDEX(Crop_data,MATCH(A13,Crop_data_codes,0),4) -> #REF! | E13: =IF(D13="Yes", SUM(F13:N13),"") -> #REF! | F13: =IF(D13="YES",INDEX(CO2_data,MATCH(A13,CO2_codes,0),2)+INDEX(CH4_data,MATCH(A13,CH4_codes,0),2)*CF_fossil_CH4+INDEX(CH4_bio_data,MATCH(A13,CH4_bio_codes,0),2)*CF_biog_CH4+INDEX(N2O_data,MATCH(A13,N2O_codes,0),2)*CF_N2O,"") -> #REF! | G13: =IF(D13="YES",INDEX(CO2_data,MATCH(A13,CO2_codes,0),3)+INDEX(CH4_data,MATCH(A13,CH4_codes,0),3)*CF_fossil_CH4+INDEX(CH4_bio_data,MATCH(A13,CH4_bio_codes,0),3)*CF_biog_CH4+INDEX(N2O_data,MATCH(A13,N2O_codes,0),3)*CF_N2O,"") -> #REF! | H13: =IF(D13="YES",INDEX(CO2_data,MATCH(A13,CO2_codes,0),4)+INDEX(CH4_data,MATCH(A13,CH4_codes,0),4)*CF_fossil_CH4+INDEX(CH4_bio_data,MATCH(A13,CH4_bio_codes,0),4)*CF_biog_CH4+INDEX(N2O_data,MATCH(A13,N2O_codes,0),4)*CF_N2O,"") -> #REF! | I13: =IF(D13="YES",INDEX(CO2_data,MATCH(A13,CO2_codes,0),5)+INDEX(CH4_data,MATCH(A13,CH4_codes,0),5)*CF_fossil_CH4+INDEX(CH4_bio_data,MATCH(A13,CH4_bio_codes,0),5)*CF_biog_CH4+INDEX(N2O_data,MATCH(A13,N2O_codes,0),5)*CF_N2O,"") -> #REF! | J13: =IF(D13="YES",INDEX(CO2_data,MATCH(A13,CO2_codes,0),6)+INDEX(CH4_data,MATCH(A13,CH4_codes,0),6)*CF_fossil_CH4+INDEX(CH4_bio_data,MATCH(A13,CH4_bio_codes,0),6)*CF_biog_CH4+INDEX(N2O_data,MATCH(A13,N2O_codes,0),6)*CF_N2O,"") -> #REF! | K13: =IF(D13="YES",INDEX(CO2_data,MATCH(A13,CO2_codes,0),7)+INDEX(CH4_data,MATCH(A13,CH4_codes,0),7)*CF_fossil_CH4+INDEX(CH4_bio_data,MATCH(A13,CH4_bio_codes,0),7)*CF_biog_CH4+INDEX(N2O_data,MATCH(A13,N2O_codes,0),7)*CF_N2O,"") -> #REF! | L13: =IF(D13="YES",INDEX(CO2_data,MATCH(A13,CO2_codes,0),8)+INDEX(CH4_data,MATCH(A13,CH4_codes,0),8)*CF_fossil_CH4+INDEX(CH4_bio_data,MATCH(A13,CH4_bio_codes,0),8)*CF_biog_CH4+INDEX(N2O_data,MATCH(A13,N2O_codes,0),8)*CF_N2O,"") -> #REF! | M13: =IF(D13="YES",INDEX(CO2_data,MATCH(A13,CO2_codes,0),9)+INDEX(CH4_data,MATCH(A13,CH4_codes,0),9)*CF_fossil_CH4+INDEX(CH4_bio_data,MATCH(A13,CH4_bio_codes,0),9)*CF_biog_CH4+INDEX(N2O_data,MATCH(A13,N2O_codes,0),9)*CF_N2O,"") -> #REF! | N13: =IF(D13="YES",INDEX(CO2_data,MATCH(A13,CO2_codes,0),10)+INDEX(CH4_data,MATCH(A13,CH4_codes,0),10)*CF_fossil_CH4+INDEX(CH4_bio_data,MATCH(A13,CH4_bio_codes,0),10)*CF_biog_CH4+INDEX(N2O_data,MATCH(A13,N2O_codes,0),10)*CF_N2O,"") -> #REF!
A14: 0115 | B14: =INDEX(Crop_data,MATCH(A14,Crop_data_codes,0),2) -> #REF! | C14: =INDEX(Crop_data,MATCH(A14,Crop_data_codes,0),3) -> #REF! | D14: =INDEX(Crop_data,MATCH(A14,Crop_data_codes,0),4) -> #REF! | E14: =IF(D14="Yes", SUM(F14:N14),"") -> #REF! | F14: =IF(D14="YES",INDEX(CO2_data,MATCH(A14,CO2_codes,0),2)+INDEX(CH4_data,MATCH(A14,CH4_codes,0),2)*CF_fossil_CH4+INDEX(CH4_bio_data,MATCH(A14,CH4_bio_codes,0),2)*CF_biog_CH4+INDEX(N2O_data,MATCH(A14,N2O_codes,0),2)*CF_N2O,"") -> #REF! | G14: =IF(D14="YES",INDEX(CO2_data,MATCH(A14,CO2_codes,0),3)+INDEX(CH4_data,MATCH(A14,CH4_codes,0),3)*CF_fossil_CH4+INDEX(CH4_bio_data,MATCH(A14,CH4_bio_codes,0),3)*CF_biog_CH4+INDEX(N2O_data,MATCH(A14,N2O_codes,0),3)*CF_N2O,"") -> #REF! | H14: =IF(D14="YES",INDEX(CO2_data,MATCH(A14,CO2_codes,0),4)+INDEX(CH4_data,MATCH(A14,CH4_codes,0),4)*CF_fossil_CH4+INDEX(CH4_bio_data,MATCH(A14,CH4_bio_codes,0),4)*CF_biog_CH4+INDEX(N2O_data,MATCH(A14,N2O_codes,0),4)*CF_N2O,"") -> #REF! | I14: =IF(D14="YES",INDEX(CO2_data,MATCH(A14,CO2_codes,0),5)+INDEX(CH4_data,MATCH(A14,CH4_codes,0),5)*CF_fossil_CH4+INDEX(CH4_bio_data,MATCH(A14,CH4_bio_codes,0),5)*CF_biog_CH4+INDEX(N2O_data,MATCH(A14,N2O_codes,0),5)*CF_N2O,"") -> #REF! | J14: =IF(D14="YES",INDEX(CO2_data,MATCH(A14,CO2_codes,0),6)+INDEX(CH4_data,MATCH(A14,CH4_codes,0),6)*CF_fossil_CH4+INDEX(CH4_bio_data,MATCH(A14,CH4_bio_codes,0),6)*CF_biog_CH4+INDEX(N2O_data,MATCH(A14,N2O_codes,0),6)*CF_N2O,"") -> #REF! | K14: =IF(D14="YES",INDEX(CO2_data,MATCH(A14,CO2_codes,0),7)+INDEX(CH4_data,MATCH(A14,CH4_codes,0),7)*CF_fossil_CH4+INDEX(CH4_bio_data,MATCH(A14,CH4_bio_codes,0),7)*CF_biog_CH4+INDEX(N2O_data,MATCH(A14,N2O_codes,0),7)*CF_N2O,"") -> #REF! | L14: =IF(D14="YES",INDEX(CO2_data,MATCH(A14,CO2_codes,0),8)+INDEX(CH4_data,MATCH(A14,CH4_codes,0),8)*CF_fossil_CH4+INDEX(CH4_bio_data,MATCH(A14,CH4_bio_codes,0),8)*CF_biog_CH4+INDEX(N2O_data,MATCH(A14,N2O_codes,0),8)*CF_N2O,"") -> #REF! | M14: =IF(D14="YES",INDEX(CO2_data,MATCH(A14,CO2_codes,0),9)+INDEX(CH4_data,MATCH(A14,CH4_codes,0),9)*CF_fossil_CH4+INDEX(CH4_bio_data,MATCH(A14,CH4_bio_codes,0),9)*CF_biog_CH4+INDEX(N2O_data,MATCH(A14,N2O_codes,0),9)*CF_N2O,"") -> #REF! | N14: =IF(D14="YES",INDEX(CO2_data,MATCH(A14,CO2_codes,0),10)+INDEX(CH4_data,MATCH(A14,CH4_codes,0),10)*CF_fossil_CH4+INDEX(CH4_bio_data,MATCH(A14,CH4_bio_codes,0),10)*CF_biog_CH4+INDEX(N2O_data,MATCH(A14,N2O_codes,0),10)*CF_N2O,"") -> #REF!
A15: 0115_s | B15: =INDEX(Crop_data,MATCH(A15,Crop_data_codes,0),2) -> #REF! | C15: =INDEX(Crop_data,MATCH(A15,Crop_data_codes,0),3) -> #REF! | D15: =INDEX(Crop_data,MATCH(A15,Crop_data_codes,0),4) -> #REF! | E15: =IF(D15="Yes", SUM(F15:N15),"") -> #REF! | F15: =IF(D15="YES",INDEX(CO2_data,MATCH(A15,CO2_codes,0),2)+INDEX(CH4_data,MATCH(A15,CH4_codes,0),2)*CF_fossil_CH4+INDEX(CH4_bio_data,MATCH(A15,CH4_bio_codes,0),2)*CF_biog_CH4+INDEX(N2O_data,MATCH(A15,N2O_codes,0),2)*CF_N2O,"") -> #REF! | G15: =IF(D15="YES",INDEX(CO2_data,MATCH(A15,CO2_codes,0),3)+INDEX(CH4_data,MATCH(A15,CH4_codes,0),3)*CF_fossil_CH4+INDEX(CH4_bio_data,MATCH(A15,CH4_bio_codes,0),3)*CF_biog_CH4+INDEX(N2O_data,MATCH(A15,N2O_codes,0),3)*CF_N2O,"") -> #REF! | H15: =IF(D15="YES",INDEX(CO2_data,MATCH(A15,CO2_codes,0),4)+INDEX(CH4_data,MATCH(A15,CH4_codes,0),4)*CF_fossil_CH4+INDEX(CH4_bio_data,MATCH(A15,CH4_bio_codes,0),4)*CF_biog_CH4+INDEX(N2O_data,MATCH(A15,N2O_codes,0),4)*CF_N2O,"") -> #REF! | I15: =IF(D15="YES",INDEX(CO2_data,MATCH(A15,CO2_codes,0),5)+INDEX(CH4_data,MATCH(A15,CH4_codes,0),5)*CF_fossil_CH4+INDEX(CH4_bio_data,MATCH(A15,CH4_bio_codes,0),5)*CF_biog_CH4+INDEX(N2O_data,MATCH(A15,N2O_codes,0),5)*CF_N2O,"") -> #REF! | J15: =IF(D15="YES",INDEX(CO2_data,MATCH(A15,CO2_codes,0),6)+INDEX(CH4_data,MATCH(A15,CH4_codes,0),6)*CF_fossil_CH4+INDEX(CH4_bio_data,MATCH(A15,CH4_bio_codes,0),6)*CF_biog_CH4+INDEX(N2O_data,MATCH(A15,N2O_codes,0),6)*CF_N2O,"") -> #REF! | K15: =IF(D15="YES",INDEX(CO2_data,MATCH(A15,CO2_codes,0),7)+INDEX(CH4_data,MATCH(A15,CH4_codes,0),7)*CF_fossil_CH4+INDEX(CH4_bio_data,MATCH(A15,CH4_bio_codes,0),7)*CF_biog_CH4+INDEX(N2O_data,MATCH(A15,N2O_codes,0),7)*CF_N2O,"") -> #REF! | L15: =IF(D15="YES",INDEX(CO2_data,MATCH(A15,CO2_codes,0),8)+INDEX(CH4_data,MATCH(A15,CH4_codes,0),8)*CF_fossil_CH4+INDEX(CH4_bio_data,MATCH(A15,CH4_bio_codes,0),8)*CF_biog_CH4+INDEX(N2O_data,MATCH(A15,N2O_codes,0),8)*CF_N2O,"") -> #REF! | M15: =IF(D15="YES",INDEX(CO2_data,MATCH(A15,CO2_codes,0),9)+INDEX(CH4_data,MATCH(A15,CH4_codes,0),9)*CF_fossil_CH4+INDEX(CH4_bio_data,MATCH(A15,CH4_bio_codes,0),9)*CF_biog_CH4+INDEX(N2O_data,MATCH(A15,N2O_codes,0),9)*CF_N2O,"") -> #REF! | N15: =IF(D15="YES",INDEX(CO2_data,MATCH(A15,CO2_codes,0),10)+INDEX(CH4_data,MATCH(A15,CH4_codes,0),10)*CF_fossil_CH4+INDEX(CH4_bio_data,MATCH(A15,CH4_bio_codes,0),10)*CF_biog_CH4+INDEX(N2O_data,MATCH(A15,N2O_codes,0),10)*CF_N2O,"") -> #REF!
A16: 0115_w | B16: =INDEX(Crop_data,MATCH(A16,Crop_data_codes,0),2) -> #REF! | C16: =INDEX(Crop_data,MATCH(A16,Crop_data_codes,0),3) -> #REF! | D16: =INDEX(Crop_data,MATCH(A16,Crop_data_codes,0),4) -> #REF! | E16: =IF(D16="Yes", SUM(F16:N16),"") -> #REF! | F16: =IF(D16="YES",INDEX(CO2_data,MATCH(A16,CO2_codes,0),2)+INDEX(CH4_data,MATCH(A16,CH4_codes,0),2)*CF_fossil_CH4+INDEX(CH4_bio_data,MATCH(A16,CH4_bio_codes,0),2)*CF_biog_CH4+INDEX(N2O_data,MATCH(A16,N2O_codes,0),2)*CF_N2O,"") -> #REF! | G16: =IF(D16="YES",INDEX(CO2_data,MATCH(A16,CO2_codes,0),3)+INDEX(CH4_data,MATCH(A16,CH4_codes,0),3)*CF_fossil_CH4+INDEX(CH4_bio_data,MATCH(A16,CH4_bio_codes,0),3)*CF_biog_CH4+INDEX(N2O_data,MATCH(A16,N2O_codes,0),3)*CF_N2O,"") -> #REF! | H16: =IF(D16="YES",INDEX(CO2_data,MATCH(A16,CO2_codes,0),4)+INDEX(CH4_data,MATCH(A16,CH4_codes,0),4)*CF_fossil_CH4+INDEX(CH4_bio_data,MATCH(A16,CH4_bio_codes,0),4)*CF_biog_CH4+INDEX(N2O_data,MATCH(A16,N2O_codes,0),4)*CF_N2O,"") -> #REF! | I16: =IF(D16="YES",INDEX(CO2_data,MATCH(A16,CO2_codes,0),5)+INDEX(CH4_data,MATCH(A16,CH4_codes,0),5)*CF_fossil_CH4+INDEX(CH4_bio_data,MATCH(A16,CH4_bio_codes,0),5)*CF_biog_CH4+INDEX(N2O_data,MATCH(A16,N2O_codes,0),5)*CF_N2O,"") -> #REF! | J16: =IF(D16="YES",INDEX(CO2_data,MATCH(A16,CO2_codes,0),6)+INDEX(CH4_data,MATCH(A16,CH4_codes,0),6)*CF_fossil_CH4+INDEX(CH4_bio_data,MATCH(A16,CH4_bio_codes,0),6)*CF_biog_CH4+INDEX(N2O_data,MATCH(A16,N2O_codes,0),6)*CF_N2O,"") -> #REF! | K16: =IF(D16="YES",INDEX(CO2_data,MATCH(A16,CO2_codes,0),7)+INDEX(CH4_data,MATCH(A16,CH4_codes,0),7)*CF_fossil_CH4+INDEX(CH4_bio_data,MATCH(A16,CH4_bio_codes,0),7)*CF_biog_CH4+INDEX(N2O_data,MATCH(A16,N2O_codes,0),7)*CF_N2O,"") -> #REF! | L16: =IF(D16="YES",INDEX(CO2_data,MATCH(A16,CO2_codes,0),8)+INDEX(CH4_data,MATCH(A16,CH4_codes,0),8)*CF_fossil_CH4+INDEX(CH4_bio_data,MATCH(A16,CH4_bio_codes,0),8)*CF_biog_CH4+INDEX(N2O_data,MATCH(A16,N2O_codes,0),8)*CF_N2O,"") -> #REF! | M16: =IF(D16="YES",INDEX(CO2_data,MATCH(A16,CO2_codes,0),9)+INDEX(CH4_data,MATCH(A16,CH4_codes,0),9)*CF_fossil_CH4+INDEX(CH4_bio_data,MATCH(A16,CH4_bio_codes,0),9)*CF_biog_CH4+INDEX(N2O_data,MATCH(A16,N2O_codes,0),9)*CF_N2O,"") -> #REF! | N16: =IF(D16="YES",INDEX(CO2_data,MATCH(A16,CO2_codes,0),10)+INDEX(CH4_data,MATCH(A16,CH4_codes,0),10)*CF_fossil_CH4+INDEX(CH4_bio_data,MATCH(A16,CH4_bio_codes,0),10)*CF_biog_CH4+INDEX(N2O_data,MATCH(A16,N2O_codes,0),10)*CF_N2O,"") -> #REF!
A17: 01701 | B17: =INDEX(Crop_data,MATCH(A17,Crop_data_codes,0),2) -> #REF! | C17: =INDEX(Crop_data,MATCH(A17,Crop_data_codes,0),3) -> #REF! | D17: =INDEX(Crop_data,MATCH(A17,Crop_data_codes,0),4) -> #REF! | E17: =IF(D17="Yes", SUM(F17:N17),"") -> #REF! | F17: =IF(D17="YES",INDEX(CO2_data,MATCH(A17,CO2_codes,0),2)+INDEX(CH4_data,MATCH(A17,CH4_codes,0),2)*CF_fossil_CH4+INDEX(CH4_bio_data,MATCH(A17,CH4_bio_codes,0),2)*CF_biog_CH4+INDEX(N2O_data,MATCH(A17,N2O_codes,0),2)*CF_N2O,"") -> #REF! | G17: =IF(D17="YES",INDEX(CO2_data,MATCH(A17,CO2_codes,0),3)+INDEX(CH4_data,MATCH(A17,CH4_codes,0),3)*CF_fossil_CH4+INDEX(CH4_bio_data,MATCH(A17,CH4_bio_codes,0),3)*CF_biog_CH4+INDEX(N2O_data,MATCH(A17,N2O_codes,0),3)*CF_N2O,"") -> #REF! | H17: =IF(D17="YES",INDEX(CO2_data,MATCH(A17,CO2_codes,0),4)+INDEX(CH4_data,MATCH(A17,CH4_codes,0),4)*CF_fossil_CH4+INDEX(CH4_bio_data,MATCH(A17,CH4_bio_codes,0),4)*CF_biog_CH4+INDEX(N2O_data,MATCH(A17,N2O_codes,0),4)*CF_N2O,"") -> #REF! | I17: =IF(D17="YES",INDEX(CO2_data,MATCH(A17,CO2_codes,0),5)+INDEX(CH4_data,MATCH(A17,CH4_codes,0),5)*CF_fossil_CH4+INDEX(CH4_bio_data,MATCH(A17,CH4_bio_codes,0),5)*CF_biog_CH4+INDEX(N2O_data,MATCH(A17,N2O_codes,0),5)*CF_N2O,"") -> #REF! | J17: =IF(D17="YES",INDEX(CO2_data,MATCH(A17,CO2_codes,0),6)+INDEX(CH4_data,MATCH(A17,CH4_codes,0),6)*CF_fossil_CH4+INDEX(CH4_bio_data,MATCH(A17,CH4_bio_codes,0),6)*CF_biog_CH4+INDEX(N2O_data,MATCH(A17,N2O_codes,0),6)*CF_N2O,"") -> #REF! | K17: =IF(D17="YES",INDEX(CO2_data,MATCH(A17,CO2_codes,0),7)+INDEX(CH4_data,MATCH(A17,CH4_codes,0),7)*CF_fossil_CH4+INDEX(CH4_bio_data,MATCH(A17,CH4_bio_codes,0),7)*CF_biog_CH4+INDEX(N2O_data,MATCH(A17,N2O_codes,0),7)*CF_N2O,"") -> #REF! | L17: =IF(D17="YES",INDEX(CO2_data,MATCH(A17,CO2_codes,0),8)+INDEX(CH4_data,MATCH(A17,CH4_codes,0),8)*CF_fossil_CH4+INDEX(CH4_bio_data,MATCH(A17,CH4_bio_codes,0),8)*CF_biog_CH4+INDEX(N2O_data,MATCH(A17,N2O_codes,0),8)*CF_N2O,"") -> #REF! | M17: =IF(D17="YES",INDEX(CO2_data,MATCH(A17,CO2_codes,0),9)+INDEX(CH4_data,MATCH(A17,CH4_codes,0),9)*CF_fossil_CH4+INDEX(CH4_bio_data,MATCH(A17,CH4_bio_codes,0),9)*CF_biog_CH4+INDEX(N2O_data,MATCH(A17,N2O_codes,0),9)*CF_N2O,"") -> #REF! | N17: =IF(D17="YES",INDEX(CO2_data,MATCH(A17,CO2_codes,0),10)+INDEX(CH4_data,MATCH(A17,CH4_codes,0),10)*CF_fossil_CH4+INDEX(CH4_bio_data,MATCH(A17,CH4_bio_codes,0),10)*CF_biog_CH4+INDEX(N2O_data,MATCH(A17,N2O_codes,0),10)*CF_N2O,"") -> #REF!
... A118: 0111_w | B118: =INDEX(Crop_data,MATCH(A118,Crop_data_codes,0),2) -> #REF! | C118: =INDEX(Crop_data,MATCH(A118,Crop_data_codes,0),3) -> #REF! | D118: =INDEX(Crop_data,MATCH(A118,Crop_data_codes,0),4) -> #REF! | E118: =IF(D118="Yes", SUM(F118:N118),"") -> #REF! | F118: =IF(D118="YES",INDEX(CO2_data,MATCH(A118,CO2_codes,0),2)+INDEX(CH4_data,MATCH(A118,CH4_codes,0),2)*CF_fossil_CH4+INDEX(CH4_bio_data,MATCH(A118,CH4_bio_codes,0),2)*CF_biog_CH4+INDEX(N2O_data,MATCH(A118,N2O_codes,0),2)*CF_N2O,"") -> #REF! | G118: =IF(D118="YES",INDEX(CO2_data,MATCH(A118,CO2_codes,0),3)+INDEX(CH4_data,MATCH(A118,CH4_codes,0),3)*CF_fossil_CH4+INDEX(CH4_bio_data,MATCH(A118,CH4_bio_codes,0),3)*CF_biog_CH4+INDEX(N2O_data,MATCH(A118,N2O_codes,0),3)*CF_N2O,"") -> #REF! | H118: =IF(D118="YES",INDEX(CO2_data,MATCH(A118,CO2_codes,0),4)+INDEX(CH4_data,MATCH(A118,CH4_codes,0),4)*CF_fossil_CH4+INDEX(CH4_bio_data,MATCH(A118,CH4_bio_codes,0),4)*CF_biog_CH4+INDEX(N2O_data,MATCH(A118,N2O_codes,0),4)*CF_N2O,"") -> #REF! | I118: =IF(D118="YES",INDEX(CO2_data,MATCH(A118,CO2_codes,0),5)+INDEX(CH4_data,MATCH(A118,CH4_codes,0),5)*CF_fossil_CH4+INDEX(CH4_bio_data,MATCH(A118,CH4_bio_codes,0),5)*CF_biog_CH4+INDEX(N2O_data,MATCH(A118,N2O_codes,0),5)*CF_N2O,"") -> #REF! | J118: =IF(D118="YES",INDEX(CO2_data,MATCH(A118,CO2_codes,0),6)+INDEX(CH4_data,MATCH(A118,CH4_codes,0),6)*CF_fossil_CH4+INDEX(CH4_bio_data,MATCH(A118,CH4_bio_codes,0),6)*CF_biog_CH4+INDEX(N2O_data,MATCH(A118,N2O_codes,0),6)*CF_N2O,"") -> #REF! | K118: =IF(D118="YES",INDEX(CO2_data,MATCH(A118,CO2_codes,0),7)+INDEX(CH4_data,MATCH(A118,CH4_codes,0),7)*CF_fossil_CH4+INDEX(CH4_bio_data,MATCH(A118,CH4_bio_codes,0),7)*CF_biog_CH4+INDEX(N2O_data,MATCH(A118,N2O_codes,0),7)*CF_N2O,"") -> #REF! | L118: =IF(D118="YES",INDEX(CO2_data,MATCH(A118,CO2_codes,0),8)+INDEX(CH4_data,MATCH(A118,CH4_codes,0),8)*CF_fossil_CH4+INDEX(CH4_bio_data,MATCH(A118,CH4_bio_codes,0),8)*CF_biog_CH4+INDEX(N2O_data,MATCH(A118,N2O_codes,0),8)*CF_N2O,"") -> #REF! | M118: =IF(D118="YES",INDEX(CO2_data,MATCH(A118,CO2_codes,0),9)+INDEX(CH4_data,MATCH(A118,CH4_codes,0),9)*CF_fossil_CH4+INDEX(CH4_bio_data,MATCH(A118,CH4_bio_codes,0),9)*CF_biog_CH4+INDEX(N2O_data,MATCH(A118,N2O_codes,0),9)*CF_N2O,"") -> #REF! | N118: =IF(D118="YES",INDEX(CO2_data,MATCH(A118,CO2_codes,0),10)+INDEX(CH4_data,MATCH(A118,CH4_codes,0),10)*CF_fossil_CH4+INDEX(CH4_bio_data,MATCH(A118,CH4_bio_codes,0),10)*CF_biog_CH4+INDEX(N2O_data,MATCH(A118,N2O_codes,0),10)*CF_N2O,"") -> #REF!

Sheet Crops CO2
A2: Emissions of CO2 per kg of crop [kg CO2 per kg of crop harvested]
A4: Crops | E4: Sum | F4: Inputs | H4: Soil emissions | J4: Energy use | N4: Land use change
A5: Code | B5: Crops | C5: Categories | D5: Cultivated in country | F5: Production of mineral fertilizer | G5: Production of capital goods | H5: Direct emissions | I5: Indirect emissions | J5: Diesel use field mach | K5: Energy use in greenhouses | L5: Energy use for irrigation | M5: Energy use for post-harvest proc | N5: LUC emissions
A6: 01371 | B6: =INDEX(Crop_data,MATCH(A6,Crop_data_codes,0),2) -> #REF! | C6: =INDEX(Crop_data,MATCH(A6,Crop_data_codes,0),3) -> #REF! | D6: =INDEX(Crop_data,MATCH(A6,Crop_data_codes,0),4) -> #REF! | E6: =IF(D6="Yes", SUM(F6:N6),"") -> #REF! | F6: =IF(D6="YES",INDEX(Crop_data,MATCH(A6,Crop_data_codes,0),7)*(Frac_BAT*EF_min_fert_BAT_CO2+Frac_AN*EF_min_fert_AN_CO2)/INDEX(Crop_data,MATCH(A6,Crop_data_codes,0),6),"") -> #REF! | G6: =IF(D6="YES",EF_capital_goods_CO2,"") -> #REF! | H6: =IF(D6="Yes",INDEX(Soil_carbon_data,MATCH(C6,Soil_carbon_categories,0),2),"") -> #REF! | J6: =IF(D6="YES",INDEX(Crop_data,MATCH(A6,Crop_data_codes,0),11)*Heating_value_diesel*EF_diesel_CO2/INDEX(Crop_data,MATCH(A6,Crop_data_codes,0),6),"") -> #REF! | L6: =IF(D6="YES",INDEX(Crop_data,MATCH(A6,Crop_data_codes,0),12)*EF_irrigation_CO2/INDEX(Crop_data,MATCH(A6,Crop_data_codes,0),6),"") -> #REF! | M6: =IF(D6="Yes",INDEX(Post_harvest_energy_data,MATCH(C6,Post_harvest_energy_categories,0),2)*EF_heating_oil_CO2+INDEX(Post_harvest_energy_data,MATCH(C6,Post_harvest_energy_categories,0),3)*EF_electricity_CO2+INDEX(Post_harvest_energy_data,MATCH(C6,Post_harvest_energy_categories,0),4)*EF_chips_CO2,"") -> #REF!
A7: 01654 | B7: =INDEX(Crop_data,MATCH(A7,Crop_data_codes,0),2) -> #REF! | C7: =INDEX(Crop_data,MATCH(A7,Crop_data_codes,0),3) -> #REF! | D7: =INDEX(Crop_data,MATCH(A7,Crop_data_codes,0),4) -> #REF! | E7: =IF(D7="Yes", SUM(F7:N7),"") -> #REF! | F7: =IF(D7="YES",INDEX(Crop_data,MATCH(A7,Crop_data_codes,0),7)*(Frac_BAT*EF_min_fert_BAT_CO2+Frac_AN*EF_min_fert_AN_CO2)/INDEX(Crop_data,MATCH(A7,Crop_data_codes,0),6),"") -> #REF! | G7: =IF(D7="YES",EF_capital_goods_CO2,"") -> #REF! | H7: =IF(D7="Yes",INDEX(Soil_carbon_data,MATCH(C7,Soil_carbon_categories,0),2),"") -> #REF! | J7: =IF(D7="YES",INDEX(Crop_data,MATCH(A7,Crop_data_codes,0),11)*Heating_value_diesel*EF_diesel_CO2/INDEX(Crop_data,MATCH(A7,Crop_data_codes,0),6),"") -> #REF! | L7: =IF(D7="YES",INDEX(Crop_data,MATCH(A7,Crop_data_codes,0),12)*EF_irrigation_CO2/INDEX(Crop_data,MATCH(A7,Crop_data_codes,0),6),"") -> #REF! | M7: =IF(D7="Yes",INDEX(Post_harvest_energy_data,MATCH(C7,Post_harvest_energy_categories,0),2)*EF_heating_oil_CO2+INDEX(Post_harvest_energy_data,MATCH(C7,Post_harvest_energy_categories,0),3)*EF_electricity_CO2+INDEX(Post_harvest_energy_data,MATCH(C7,Post_harvest_energy_categories,0),4)*EF_chips_CO2,"") -> #REF!
A8: 01341 | B8: =INDEX(Crop_data,MATCH(A8,Crop_data_codes,0),2) -> #REF! | C8: =INDEX(Crop_data,MATCH(A8,Crop_data_codes,0),3) -> #REF! | D8: =INDEX(Crop_data,MATCH(A8,Crop_data_codes,0),4) -> #REF! | E8: =IF(D8="Yes", SUM(F8:N8),"") -> #REF! | F8: =IF(D8="YES",INDEX(Crop_data,MATCH(A8,Crop_data_codes,0),7)*(Frac_BAT*EF_min_fert_BAT_CO2+Frac_AN*EF_min_fert_AN_CO2)/INDEX(Crop_data,MATCH(A8,Crop_data_codes,0),6),"") -> #REF! | G8: =IF(D8="YES",EF_capital_goods_CO2,"") -> #REF! | H8: =IF(D8="Yes",INDEX(Soil_carbon_data,MATCH(C8,Soil_carbon_categories,0),2),"") -> #REF! | J8: =IF(D8="YES",INDEX(Crop_data,MATCH(A8,Crop_data_codes,0),11)*Heating_value_diesel*EF_diesel_CO2/INDEX(Crop_data,MATCH(A8,Crop_data_codes,0),6),"") -> #REF! | L8: =IF(D8="YES",INDEX(Crop_data,MATCH(A8,Crop_data_codes,0),12)*EF_irrigation_CO2/INDEX(Crop_data,MATCH(A8,Crop_data_codes,0),6),"") -> #REF! | M8: =IF(D8="Yes",INDEX(Post_harvest_energy_data,MATCH(C8,Post_harvest_energy_categories,0),2)*EF_heating_oil_CO2+INDEX(Post_harvest_energy_data,MATCH(C8,Post_harvest_energy_categories,0),3)*EF_electricity_CO2+INDEX(Post_harvest_energy_data,MATCH(C8,Post_harvest_energy_categories,0),4)*EF_chips_CO2,"") -> #REF!
A9: 01343 | B9: =INDEX(Crop_data,MATCH(A9,Crop_data_codes,0),2) -> #REF! | C9: =INDEX(Crop_data,MATCH(A9,Crop_data_codes,0),3) -> #REF! | D9: =INDEX(Crop_data,MATCH(A9,Crop_data_codes,0),4) -> #REF! | E9: =IF(D9="Yes", SUM(F9:N9),"") -> #REF! | F9: =IF(D9="YES",INDEX(Crop_data,MATCH(A9,Crop_data_codes,0),7)*(Frac_BAT*EF_min_fert_BAT_CO2+Frac_AN*EF_min_fert_AN_CO2)/INDEX(Crop_data,MATCH(A9,Crop_data_codes,0),6),"") -> #REF! | G9: =IF(D9="YES",EF_capital_goods_CO2,"") -> #REF! | H9: =IF(D9="Yes",INDEX(Soil_carbon_data,MATCH(C9,Soil_carbon_categories,0),2),"") -> #REF! | J9: =IF(D9="YES",INDEX(Crop_data,MATCH(A9,Crop_data_codes,0),11)*Heating_value_diesel*EF_diesel_CO2/INDEX(Crop_data,MATCH(A9,Crop_data_codes,0),6),"") -> #REF! | L9: =IF(D9="YES",INDEX(Crop_data,MATCH(A9,Crop_data_codes,0),12)*EF_irrigation_CO2/INDEX(Crop_data,MATCH(A9,Crop_data_codes,0),6),"") -> #REF! | M9: =IF(D9="Yes",INDEX(Post_harvest_energy_data,MATCH(C9,Post_harvest_energy_categories,0),2)*EF_heating_oil_CO2+INDEX(Post_harvest_energy_data,MATCH(C9,Post_harvest_energy_categories,0),3)*EF_electricity_CO2+INDEX(Post_harvest_energy_data,MATCH(C9,Post_harvest_energy_categories,0),4)*EF_chips_CO2,"") -> #REF!
A10: 01216 | B10: =INDEX(Crop_data,MATCH(A10,Crop_data_codes,0),2) -> #REF! | C10: =INDEX(Crop_data,MATCH(A10,Crop_data_codes,0),3) -> #REF! | D10: =INDEX(Crop_data,MATCH(A10,Crop_data_codes,0),4) -> #REF! | E10: =IF(D10="Yes", SUM(F10:N10),"") -> #REF! | F10: =IF(D10="YES",INDEX(Crop_data,MATCH(A10,Crop_data_codes,0),7)*(Frac_BAT*EF_min_fert_BAT_CO2+Frac_AN*EF_min_fert_AN_CO2)/INDEX(Crop_data,MATCH(A10,Crop_data_codes,0),6),"") -> #REF! | G10: =IF(D10="YES",EF_capital_goods_CO2,"") -> #REF! | H10: =IF(D10="Yes",INDEX(Soil_carbon_data,MATCH(C10,Soil_carbon_categories,0),2),"") -> #REF! | J10: =IF(D10="YES",INDEX(Crop_data,MATCH(A10,Crop_data_codes,0),11)*Heating_value_diesel*EF_diesel_CO2/INDEX(Crop_data,MATCH(A10,Crop_data_codes,0),6),"") -> #REF! | L10: =IF(D10="YES",INDEX(Crop_data,MATCH(A10,Crop_data_codes,0),12)*EF_irrigation_CO2/INDEX(Crop_data,MATCH(A10,Crop_data_codes,0),6),"") -> #REF! | M10: =IF(D10="Yes",INDEX(Post_harvest_energy_data,MATCH(C10,Post_harvest_energy_categories,0),2)*EF_heating_oil_CO2+INDEX(Post_harvest_energy_data,MATCH(C10,Post_harvest_energy_categories,0),3)*EF_electricity_CO2+INDEX(Post_harvest_energy_data,MATCH(C10,Post_harvest_energy_categories,0),4)*EF_chips_CO2,"") -> #REF!
A11: 01211 | B11: =INDEX(Crop_data,MATCH(A11,Crop_data_codes,0),2) -> #REF! | C11: =INDEX(Crop_data,MATCH(A11,Crop_data_codes,0),3) -> #REF! | D11: =INDEX(Crop_data,MATCH(A11,Crop_data_codes,0),4) -> #REF! | E11: =IF(D11="Yes", SUM(F11:N11),"") -> #REF! | F11: =IF(D11="YES",INDEX(Crop_data,MATCH(A11,Crop_data_codes,0),7)*(Frac_BAT*EF_min_fert_BAT_CO2+Frac_AN*EF_min_fert_AN_CO2)/INDEX(Crop_data,MATCH(A11,Crop_data_codes,0),6),"") -> #REF! | G11: =IF(D11="YES",EF_capital_goods_CO2,"") -> #REF! | H11: =IF(D11="Yes",INDEX(Soil_carbon_data,MATCH(C11,Soil_carbon_categories,0),2),"") -> #REF! | J11: =IF(D11="YES",INDEX(Crop_data,MATCH(A11,Crop_data_codes,0),11)*Heating_value_diesel*EF_diesel_CO2/INDEX(Crop_data,MATCH(A11,Crop_data_codes,0),6),"") -> #REF! | L11: =IF(D11="YES",INDEX(Crop_data,MATCH(A11,Crop_data_codes,0),12)*EF_irrigation_CO2/INDEX(Crop_data,MATCH(A11,Crop_data_codes,0),6),"") -> #REF! | M11: =IF(D11="Yes",INDEX(Post_harvest_energy_data,MATCH(C11,Post_harvest_energy_categories,0),2)*EF_heating_oil_CO2+INDEX(Post_harvest_energy_data,MATCH(C11,Post_harvest_energy_categories,0),3)*EF_electricity_CO2+INDEX(Post_harvest_energy_data,MATCH(C11,Post_harvest_energy_categories,0),4)*EF_chips_CO2,"") -> #REF!
A12: 01311 | B12: =INDEX(Crop_data,MATCH(A12,Crop_data_codes,0),2) -> #REF! | C12: =INDEX(Crop_data,MATCH(A12,Crop_data_codes,0),3) -> #REF! | D12: =INDEX(Crop_data,MATCH(A12,Crop_data_codes,0),4) -> #REF! | E12: =IF(D12="Yes", SUM(F12:N12),"") -> #REF! | F12: =IF(D12="YES",INDEX(Crop_data,MATCH(A12,Crop_data_codes,0),7)*(Frac_BAT*EF_min_fert_BAT_CO2+Frac_AN*EF_min_fert_AN_CO2)/INDEX(Crop_data,MATCH(A12,Crop_data_codes,0),6),"") -> #REF! | G12: =IF(D12="YES",EF_capital_goods_CO2,"") -> #REF! | H12: =IF(D12="Yes",INDEX(Soil_carbon_data,MATCH(C12,Soil_carbon_categories,0),2),"") -> #REF! | J12: =IF(D12="YES",INDEX(Crop_data,MATCH(A12,Crop_data_codes,0),11)*Heating_value_diesel*EF_diesel_CO2/INDEX(Crop_data,MATCH(A12,Crop_data_codes,0),6),"") -> #REF! | L12: =IF(D12="YES",INDEX(Crop_data,MATCH(A12,Crop_data_codes,0),12)*EF_irrigation_CO2/INDEX(Crop_data,MATCH(A12,Crop_data_codes,0),6),"") -> #REF! | M12: =IF(D12="Yes",INDEX(Post_harvest_energy_data,MATCH(C12,Post_harvest_energy_categories,0),2)*EF_heating_oil_CO2+INDEX(Post_harvest_energy_data,MATCH(C12,Post_harvest_energy_categories,0),3)*EF_electricity_CO2+INDEX(Post_harvest_energy_data,MATCH(C12,Post_harvest_energy_categories,0),4)*EF_chips_CO2,"") -> #REF!
A13: 01312 | B13: =INDEX(Crop_data,MATCH(A13,Crop_data_codes,0),2) -> #REF! | C13: =INDEX(Crop_data,MATCH(A13,Crop_data_codes,0),3) -> #REF! | D13: =INDEX(Crop_data,MATCH(A13,Crop_data_codes,0),4) -> #REF! | E13: =IF(D13="Yes", SUM(F13:N13),"") -> #REF! | F13: =IF(D13="YES",INDEX(Crop_data,MATCH(A13,Crop_data_codes,0),7)*(Frac_BAT*EF_min_fert_BAT_CO2+Frac_AN*EF_min_fert_AN_CO2)/INDEX(Crop_data,MATCH(A13,Crop_data_codes,0),6),"") -> #REF! | G13: =IF(D13="YES",EF_capital_goods_CO2,"") -> #REF! | H13: =IF(D13="Yes",INDEX(Soil_carbon_data,MATCH(C13,Soil_carbon_categories,0),2),"") -> #REF! | J13: =IF(D13="YES",INDEX(Crop_data,MATCH(A13,Crop_data_codes,0),11)*Heating_value_diesel*EF_diesel_CO2/INDEX(Crop_data,MATCH(A13,Crop_data_codes,0),6),"") -> #REF! | L13: =IF(D13="YES",INDEX(Crop_data,MATCH(A13,Crop_data_codes,0),12)*EF_irrigation_CO2/INDEX(Crop_data,MATCH(A13,Crop_data_codes,0),6),"") -> #REF! | M13: =IF(D13="Yes",INDEX(Post_harvest_energy_data,MATCH(C13,Post_harvest_energy_categories,0),2)*EF_heating_oil_CO2+INDEX(Post_harvest_energy_data,MATCH(C13,Post_harvest_energy_categories,0),3)*EF_electricity_CO2+INDEX(Post_harvest_energy_data,MATCH(C13,Post_harvest_energy_categories,0),4)*EF_chips_CO2,"") -> #REF!
A14: 0115 | B14: =INDEX(Crop_data,MATCH(A14,Crop_data_codes,0),2) -> #REF! | C14: =INDEX(Crop_data,MATCH(A14,Crop_data_codes,0),3) -> #REF! | D14: =INDEX(Crop_data,MATCH(A14,Crop_data_codes,0),4) -> #REF! | E14: =IF(D14="Yes", SUM(F14:N14),"") -> #REF! | F14: =IF(D14="YES",INDEX(Crop_data,MATCH(A14,Crop_data_codes,0),7)*(Frac_BAT*EF_min_fert_BAT_CO2+Frac_AN*EF_min_fert_AN_CO2)/INDEX(Crop_data,MATCH(A14,Crop_data_codes,0),6),"") -> #REF! | G14: =IF(D14="YES",EF_capital_goods_CO2,"") -> #REF! | H14: =IF(D14="Yes",INDEX(Soil_carbon_data,MATCH(C14,Soil_carbon_categories,0),2),"") -> #REF! | J14: =IF(D14="YES",INDEX(Crop_data,MATCH(A14,Crop_data_codes,0),11)*Heating_value_diesel*EF_diesel_CO2/INDEX(Crop_data,MATCH(A14,Crop_data_codes,0),6),"") -> #REF! | L14: =IF(D14="YES",INDEX(Crop_data,MATCH(A14,Crop_data_codes,0),12)*EF_irrigation_CO2/INDEX(Crop_data,MATCH(A14,Crop_data_codes,0),6),"") -> #REF! | M14: =IF(D14="Yes",INDEX(Post_harvest_energy_data,MATCH(C14,Post_harvest_energy_categories,0),2)*EF_heating_oil_CO2+INDEX(Post_harvest_energy_data,MATCH(C14,Post_harvest_energy_categories,0),3)*EF_electricity_CO2+INDEX(Post_harvest_energy_data,MATCH(C14,Post_harvest_energy_categories,0),4)*EF_chips_CO2,"") -> #REF!
A15: 0115_s | B15: =INDEX(Crop_data,MATCH(A15,Crop_data_codes,0),2) -> #REF! | C15: =INDEX(Crop_data,MATCH(A15,Crop_data_codes,0),3) -> #REF! | D15: =INDEX(Crop_data,MATCH(A15,Crop_data_codes,0),4) -> #REF! | E15: =IF(D15="Yes", SUM(F15:N15),"") -> #REF! | F15: =IF(D15="YES",INDEX(Crop_data,MATCH(A15,Crop_data_codes,0),7)*(Frac_BAT*EF_min_fert_BAT_CO2+Frac_AN*EF_min_fert_AN_CO2)/INDEX(Crop_data,MATCH(A15,Crop_data_codes,0),6),"") -> #REF! | G15: =IF(D15="YES",EF_capital_goods_CO2,"") -> #REF! | H15: =IF(D15="Yes",INDEX(Soil_carbon_data,MATCH(C15,Soil_carbon_categories,0),2),"") -> #REF! | J15: =IF(D15="YES",INDEX(Crop_data,MATCH(A15,Crop_data_codes,0),11)*Heating_value_diesel*EF_diesel_CO2/INDEX(Crop_data,MATCH(A15,Crop_data_codes,0),6),"") -> #REF! | L15: =IF(D15="YES",INDEX(Crop_data,MATCH(A15,Crop_data_codes,0),12)*EF_irrigation_CO2/INDEX(Crop_data,MATCH(A15,Crop_data_codes,0),6),"") -> #REF! | M15: =IF(D15="Yes",INDEX(Post_harvest_energy_data,MATCH(C15,Post_harvest_energy_categories,0),2)*EF_heating_oil_CO2+INDEX(Post_harvest_energy_data,MATCH(C15,Post_harvest_energy_categories,0),3)*EF_electricity_CO2+INDEX(Post_harvest_energy_data,MATCH(C15,Post_harvest_energy_categories,0),4)*EF_chips_CO2,"") -> #REF!
A16: 0115_w | B16: =INDEX(Crop_data,MATCH(A16,Crop_data_codes,0),2) -> #REF! | C16: =INDEX(Crop_data,MATCH(A16,Crop_data_codes,0),3) -> #REF! | D16: =INDEX(Crop_data,MATCH(A16,Crop_data_codes,0),4) -> #REF! | E16: =IF(D16="Yes", SUM(F16:N16),"") -> #REF! | F16: =IF(D16="YES",INDEX(Crop_data,MATCH(A16,Crop_data_codes,0),7)*(Frac_BAT*EF_min_fert_BAT_CO2+Frac_AN*EF_min_fert_AN_CO2)/INDEX(Crop_data,MATCH(A16,Crop_data_codes,0),6),"") -> #REF! | G16: =IF(D16="YES",EF_capital_goods_CO2,"") -> #REF! | H16: =IF(D16="Yes",INDEX(Soil_carbon_data,MATCH(C16,Soil_carbon_categories,0),2),"") -> #REF! | J16: =IF(D16="YES",INDEX(Crop_data,MATCH(A16,Crop_data_codes,0),11)*Heating_value_diesel*EF_diesel_CO2/INDEX(Crop_data,MATCH(A16,Crop_data_codes,0),6),"") -> #REF! | L16: =IF(D16="YES",INDEX(Crop_data,MATCH(A16,Crop_data_codes,0),12)*EF_irrigation_CO2/INDEX(Crop_data,MATCH(A16,Crop_data_codes,0),6),"") -> #REF! | M16: =IF(D16="Yes",INDEX(Post_harvest_energy_data,MATCH(C16,Post_harvest_energy_categories,0),2)*EF_heating_oil_CO2+INDEX(Post_harvest_energy_data,MATCH(C16,Post_harvest_energy_categories,0),3)*EF_electricity_CO2+INDEX(Post_harvest_energy_data,MATCH(C16,Post_harvest_energy_categories,0),4)*EF_chips_CO2,"") -> #REF!
A17: 01701 | B17: =INDEX(Crop_data,MATCH(A17,Crop_data_codes,0),2) -> #REF! | C17: =INDEX(Crop_data,MATCH(A17,Crop_data_codes,0),3) -> #REF! | D17: =INDEX(Crop_data,MATCH(A17,Crop_data_codes,0),4) -> #REF! | E17: =IF(D17="Yes", SUM(F17:N17),"") -> #REF! | F17: =IF(D17="YES",INDEX(Crop_data,MATCH(A17,Crop_data_codes,0),7)*(Frac_BAT*EF_min_fert_BAT_CO2+Frac_AN*EF_min_fert_AN_CO2)/INDEX(Crop_data,MATCH(A17,Crop_data_codes,0),6),"") -> #REF! | G17: =IF(D17="YES",EF_capital_goods_CO2,"") -> #REF! | H17: =IF(D17="Yes",INDEX(Soil_carbon_data,MATCH(C17,Soil_carbon_categories,0),2),"") -> #REF! | J17: =IF(D17="YES",INDEX(Crop_data,MATCH(A17,Crop_data_codes,0),11)*Heating_value_diesel*EF_diesel_CO2/INDEX(Crop_data,MATCH(A17,Crop_data_codes,0),6),"") -> #REF! | L17: =IF(D17="YES",INDEX(Crop_data,MATCH(A17,Crop_data_codes,0),12)*EF_irrigation_CO2/INDEX(Crop_data,MATCH(A17,Crop_data_codes,0),6),"") -> #REF! | M17: =IF(D17="Yes",INDEX(Post_harvest_energy_data,MATCH(C17,Post_harvest_energy_categories,0),2)*EF_heating_oil_CO2+INDEX(Post_harvest_energy_data,MATCH(C17,Post_harvest_energy_categories,0),3)*EF_electricity_CO2+INDEX(Post_harvest_energy_data,MATCH(C17,Post_harvest_energy_categories,0),4)*EF_chips_CO2,"") -> #REF!
... A37: 01610 | B37: =INDEX(Crop_data,MATCH(A37,Crop_data_codes,0),2) -> #REF! | C37: =INDEX(Crop_data,MATCH(A37,Crop_data_codes,0),3) -> #REF! | D37: =INDEX(Crop_data,MATCH(A37,Crop_data_codes,0),4) -> #REF! | E37: =IF(D37="Yes", SUM(F37:N37),"") -> #REF! | F37: =IF(D37="YES",INDEX(Crop_data,MATCH(A37,Crop_data_codes,0),7)*(Frac_BAT*EF_min_fert_BAT_CO2+Frac_AN*EF_min_fert_AN_CO2)/INDEX(Crop_data,MATCH(A37,Crop_data_codes,0),6),"") -> #REF! | G37: =IF(D37="YES",EF_capital_goods_CO2,"") -> #REF! | H37: =IF(D37="Yes",INDEX(Soil_carbon_data,MATCH(C37,Soil_carbon_categories,0),2),"") -> #REF! | J37: =IF(D37="YES",INDEX(Crop_data,MATCH(A37,Crop_data_codes,0),11)*Heating_value_diesel*EF_diesel_CO2/INDEX(Crop_data,MATCH(A37,Crop_data_codes,0),6),"") -> #REF! | L37: =IF(D37="YES",INDEX(Crop_data,MATCH(A37,Crop_data_codes,0),12)*EF_irrigation_CO2/INDEX(Crop_data,MATCH(A37,Crop_data_codes,0),6),"") -> #REF! | M37: =IF(D37="Yes",INDEX(Post_harvest_energy_data,MATCH(C37,Post_harvest_energy_categories,0),2)*EF_heating_oil_CO2+INDEX(Post_harvest_energy_data,MATCH(C37,Post_harvest_energy_categories,0),3)*EF_electricity_CO2+INDEX(Post_harvest_energy_data,MATCH(C37,Post_harvest_energy_categories,0),4)*EF_chips_CO2,"") -> #REF!
A38: 01232 | B38: =INDEX(Crop_data,MATCH(A38,Crop_data_codes,0),2) -> #REF! | C38: =INDEX(Crop_data,MATCH(A38,Crop_data_codes,0),3) -> #REF! | D38: =INDEX(Crop_data,MATCH(A38,Crop_data_codes,0),4) -> #REF! | E38: =IF(D38="Yes", SUM(F38:N38),"") -> #REF! | F38: =IF(D38="YES",INDEX(Crop_data,MATCH(A38,Crop_data_codes,0),7)*(Frac_BAT*EF_min_fert_BAT_CO2+Frac_AN*EF_min_fert_AN_CO2)/INDEX(Crop_data,MATCH(A38,Crop_data_codes,0),6),"") -> #REF! | G38: =IF(D38="YES",EF_capital_goods_CO2,"") -> #REF! | H38: =IF(D38="Yes",INDEX(Soil_carbon_data,MATCH(C38,Soil_carbon_categories,0),2),"") -> #REF! | J38: =IF(D38="YES",INDEX(Crop_data,MATCH(A38,Crop_data_codes,0),11)*Heating_value_diesel*EF_diesel_CO2/INDEX(Crop_data,MATCH(A38,Crop_data_codes,0),6),"") -> #REF! | K38: =Energy!B21/INDEX(Crop_data,MATCH(A38,Crop_data_codes,0),6)*INDEX(Crop_data,MATCH(A38,Crop_data_codes,0),5)/100 -> #REF! | L38: =IF(D38="YES",INDEX(Crop_data,MATCH(A38,Crop_data_codes,0),12)*EF_irrigation_CO2/INDEX(Crop_data,MATCH(A38,Crop_data_codes,0),6),"") -> #REF! | M38: =IF(D38="Yes",INDEX(Post_harvest_energy_data,MATCH(C38,Post_harvest_energy_categories,0),2)*EF_heating_oil_CO2+INDEX(Post_harvest_energy_data,MATCH(C38,Post_harvest_energy_categories,0),3)*EF_electricity_CO2+INDEX(Post_harvest_energy_data,MATCH(C38,Post_harvest_energy_categories,0),4)*EF_chips_CO2,"") -> #REF!
A39: 01232_gh | B39: =INDEX(Crop_data,MATCH(A39,Crop_data_codes,0),2) -> #REF! | C39: =INDEX(Crop_data,MATCH(A39,Crop_data_codes,0),3) -> #REF! | D39: =INDEX(Crop_data,MATCH(A39,Crop_data_codes,0),4) -> #REF! | E39: =IF(D39="Yes", SUM(F39:N39),"") -> #REF! | F39: =IF(D39="YES",INDEX(Crop_data,MATCH(A39,Crop_data_codes,0),7)*(Frac_BAT*EF_min_fert_BAT_CO2+Frac_AN*EF_min_fert_AN_CO2)/INDEX(Crop_data,MATCH(A39,Crop_data_codes,0),6),"") -> #REF! | G39: =IF(D39="YES",EF_capital_goods_CO2,"") -> #REF! | H39: =IF(D39="Yes",INDEX(Soil_carbon_data,MATCH(C39,Soil_carbon_categories,0),2),"") -> #REF! | K39: =Energy!B21/INDEX(Crop_data,MATCH(A38,Crop_data_codes,0),6) -> #REF! | L39: =IF(D39="YES",INDEX(Crop_data,MATCH(A39,Crop_data_codes,0),12)*EF_irrigation_CO2/INDEX(Crop_data,MATCH(A39,Crop_data_codes,0),6),"") -> #REF! | M39: =IF(D39="Yes",INDEX(Post_harvest_energy_data,MATCH(C39,Post_harvest_energy_categories,0),2)*EF_heating_oil_CO2+INDEX(Post_harvest_energy_data,MATCH(C39,Post_harvest_energy_categories,0),3)*EF_electricity_CO2+INDEX(Post_harvest_energy_data,MATCH(C39,Post_harvest_energy_categories,0),4)*EF_chips_CO2,"") -> #REF!
A40: 01232_of | B40: =INDEX(Crop_data,MATCH(A40,Crop_data_codes,0),2) -> #REF! | C40: =INDEX(Crop_data,MATCH(A40,Crop_data_codes,0),3) -> #REF! | D40: =INDEX(Crop_data,MATCH(A40,Crop_data_codes,0),4) -> #REF! | E40: =IF(D40="Yes", SUM(F40:N40),"") -> #REF! | F40: =IF(D40="YES",INDEX(Crop_data,MATCH(A40,Crop_data_codes,0),7)*(Frac_BAT*EF_min_fert_BAT_CO2+Frac_AN*EF_min_fert_AN_CO2)/INDEX(Crop_data,MATCH(A40,Crop_data_codes,0),6),"") -> #REF! | G40: =IF(D40="YES",EF_capital_goods_CO2,"") -> #REF! | H40: =IF(D40="Yes",INDEX(Soil_carbon_data,MATCH(C40,Soil_carbon_categories,0),2),"") -> #REF! | J40: =IF(D40="YES",INDEX(Crop_data,MATCH(A40,Crop_data_codes,0),11)*Heating_value_diesel*EF_diesel_CO2/INDEX(Crop_data,MATCH(A40,Crop_data_codes,0),6),"") -> #REF! | L40: =IF(D40="YES",INDEX(Crop_data,MATCH(A40,Crop_data_codes,0),12)*EF_irrigation_CO2/INDEX(Crop_data,MATCH(A40,Crop_data_codes,0),6),"") -> #REF! | M40: =IF(D40="Yes",INDEX(Post_harvest_energy_data,MATCH(C40,Post_harvest_energy_categories,0),2)*EF_heating_oil_CO2+INDEX(Post_harvest_energy_data,MATCH(C40,Post_harvest_energy_categories,0),3)*EF_electricity_CO2+INDEX(Post_harvest_energy_data,MATCH(C40,Post_harvest_energy_categories,0),4)*EF_chips_CO2,"") -> #REF!
A41: 01351.01 | B41: =INDEX(Crop_data,MATCH(A41,Crop_data_codes,0),2) -> #REF! | C41: =INDEX(Crop_data,MATCH(A41,Crop_data_codes,0),3) -> #REF! | D41: =INDEX(Crop_data,MATCH(A41,Crop_data_codes,0),4) -> #REF! | E41: =IF(D41="Yes", SUM(F41:N41),"") -> #REF! | F41: =IF(D41="YES",INDEX(Crop_data,MATCH(A41,Crop_data_codes,0),7)*(Frac_BAT*EF_min_fert_BAT_CO2+Frac_AN*EF_min_fert_AN_CO2)/INDEX(Crop_data,MATCH(A41,Crop_data_codes,0),6),"") -> #REF! | G41: =IF(D41="YES",EF_capital_goods_CO2,"") -> #REF! | H41: =IF(D41="Yes",INDEX(Soil_carbon_data,MATCH(C41,Soil_carbon_categories,0),2),"") -> #REF! | J41: =IF(D41="YES",INDEX(Crop_data,MATCH(A41,Crop_data_codes,0),11)*Heating_value_diesel*EF_diesel_CO2/INDEX(Crop_data,MATCH(A41,Crop_data_codes,0),6),"") -> #REF! | L41: =IF(D41="YES",INDEX(Crop_data,MATCH(A41,Crop_data_codes,0),12)*EF_irrigation_CO2/INDEX(Crop_data,MATCH(A41,Crop_data_codes,0),6),"") -> #REF! | M41: =IF(D41="Yes",INDEX(Post_harvest_energy_data,MATCH(C41,Post_harvest_energy_categories,0),2)*EF_heating_oil_CO2+INDEX(Post_harvest_energy_data,MATCH(C41,Post_harvest_energy_categories,0),3)*EF_electricity_CO2+INDEX(Post_harvest_energy_data,MATCH(C41,Post_harvest_energy_categories,0),4)*EF_chips_CO2,"") -> #REF!
A42: 01314 | B42: =INDEX(Crop_data,MATCH(A42,Crop_data_codes,0),2) -> #REF! | C42: =INDEX(Crop_data,MATCH(A42,Crop_data_codes,0),3) -> #REF! | D42: =INDEX(Crop_data,MATCH(A42,Crop_data_codes,0),4) -> #REF! | E42: =IF(D42="Yes", SUM(F42:N42),"") -> #REF! | F42: =IF(D42="YES",INDEX(Crop_data,MATCH(A42,Crop_data_codes,0),7)*(Frac_BAT*EF_min_fert_BAT_CO2+Frac_AN*EF_min_fert_AN_CO2)/INDEX(Crop_data,MATCH(A42,Crop_data_codes,0),6),"") -> #REF! | G42: =IF(D42="YES",EF_capital_goods_CO2,"") -> #REF! | H42: =IF(D42="Yes",INDEX(Soil_carbon_data,MATCH(C42,Soil_carbon_categories,0),2),"") -> #REF! | J42: =IF(D42="YES",INDEX(Crop_data,MATCH(A42,Crop_data_codes,0),11)*Heating_value_diesel*EF_diesel_CO2/INDEX(Crop_data,MATCH(A42,Crop_data_codes,0),6),"") -> #REF! | L42: =IF(D42="YES",INDEX(Crop_data,MATCH(A42,Crop_data_codes,0),12)*EF_irrigation_CO2/INDEX(Crop_data,MATCH(A42,Crop_data_codes,0),6),"") -> #REF! | M42: =IF(D42="Yes",INDEX(Post_harvest_energy_data,MATCH(C42,Post_harvest_energy_categories,0),2)*EF_heating_oil_CO2+INDEX(Post_harvest_energy_data,MATCH(C42,Post_harvest_energy_categories,0),3)*EF_electricity_CO2+INDEX(Post_harvest_energy_data,MATCH(C42,Post_harvest_energy_categories,0),4)*EF_chips_CO2,"") -> #REF!
