Workbook
Name Ability_to_perceive_handling: 'Parameters, general'!$B$19
Name Bonefree_outof_CW_AT: 'Parameters, country spec'!$B$9
Name Bonefree_outof_CW_BE: 'Parameters, country spec'!$C$9
Name Bonefree_outof_CW_BG: 'Parameters, country spec'!$D$9
Name Bonefree_outof_CW_BR: 'Parameters, country spec'!$AC$9
Name Bonefree_outof_CW_CY: 'Parameters, country spec'!$F$9
Name Bonefree_outof_CW_CZ: 'Parameters, country spec'!$G$9
Name Bonefree_outof_CW_DE: 'Parameters, country spec'!$L$9
Name Bonefree_outof_CW_DK: 'Parameters, country spec'!$H$9
Name Bonefree_outof_CW_EE: 'Parameters, country spec'!$I$9
Name Bonefree_outof_CW_ES: 'Parameters, country spec'!$Z$9
Name Bonefree_outof_CW_FI: 'Parameters, country spec'!$J$9
Name Bonefree_outof_CW_FR: 'Parameters, country spec'!$K$9
Name Bonefree_outof_CW_GB: 'Parameters, country spec'!$AB$9
Name Bonefree_outof_CW_GR: 'Parameters, country spec'!$M$9
Name Bonefree_outof_CW_HR: 'Parameters, country spec'!$E$9
Name Bonefree_outof_CW_HU: 'Parameters, country spec'!$N$9
Name Bonefree_outof_CW_IE: 'Parameters, country spec'!$O$9
Name Bonefree_outof_CW_IT: 'Parameters, country spec'!$P$9
Name Bonefree_outof_CW_LT: 'Parameters, country spec'!$R$9
Name Bonefree_outof_CW_LV: 'Parameters, country spec'!$Q$9
Name Bonefree_outof_CW_MT: 'Parameters, country spec'!$S$9
Name Bonefree_outof_CW_NL: 'Parameters, country spec'!$T$9
Name Bonefree_outof_CW_PL: 'Parameters, country spec'!$U$9
Name Bonefree_outof_CW_PT: 'Parameters, country spec'!$V$9
Name Bonefree_outof_CW_RO: 'Parameters, country spec'!$W$9
Name Bonefree_outof_CW_SE: 'Parameters, country spec'!$AA$9
Name Bonefree_outof_CW_SI: 'Parameters, country spec'!$Y$9
Name Bonefree_outof_CW_SK: 'Parameters, country spec'!$X$9
Name Bonefree_outof_CW_TH: 'Parameters, country spec'!$AD$9
Name Bonefree_outof_CW_US: 'Parameters, country spec'!$AE$9
Name CF_biog_CH4: '[1]CF climate'!$C$5
Name CF_fossil_CH4: '[1]CF climate'!$D$5
Name CF_GWP_CH4_fossil: 'Parameters, general'!$B$14
Name CF_GWP_N2O: 'Parameters, general'!$B$16
Name CF_N2O: '[1]CF climate'!$E$5
Name CH4_bio_codes: '[1]Crops CH4, bio'!$A$6:$A$118
Name CH4_bio_data: '[1]Crops CH4, bio'!$E$6:$N$118
Name CH4_codes: '[1]Crops CH4, fossil'!$A$6:$A$118
Name CH4_data: '[1]Crops CH4, fossil'!$E$6:$N$118
Name CO2_codes: '[1]Crops CO2'!$A$6:$A$118
Name CO2_data: '[1]Crops CO2'!$E$6:$N$118
Name Crop_data: '[1]Crops, input data per ha'!$A$6:$Z$118
Name Crop_data_codes: '[1]Crops, input data per ha'!$A$6:$A$118
Name CY: 'Parameters, country spec'!$F$36
Name EF_ammonia_AT: 'Parameters, country spec'!$B$42
Name EF_ammonia_BE: 'Parameters, country spec'!$C$42
Name EF_ammonia_BG: 'Parameters, country spec'!$D$42
Name EF_ammonia_BR: 'Parameters, country spec'!$AC$42
Name EF_ammonia_CY: 'Parameters, country spec'!$F$42
Name EF_ammonia_CZ: 'Parameters, country spec'!$G$42
Name EF_ammonia_DE: 'Parameters, country spec'!$L$42
Name EF_ammonia_DK: 'Parameters, country spec'!$H$42
Name EF_ammonia_EE: 'Parameters, country spec'!$I$42
Name EF_ammonia_ES: 'Parameters, country spec'!$Z$42
Name EF_ammonia_FI: 'Parameters, country spec'!$J$42
Name EF_ammonia_FR: 'Parameters, country spec'!$K$42
Name EF_ammonia_GB: 'Parameters, country spec'!$AB$42
Name EF_ammonia_GR: 'Parameters, country spec'!$M$42
Name EF_ammonia_HR: 'Parameters, country spec'!$E$42

Sheet README
A2: Read me
A4: This is a file that contains the calculations of environmental footprints, labour requirements, animal welfare and use of antibiotics for chicken production.
A7: Assumptions:
A8: - All parent animals are also eaten
A9: - Impacts are allocated equally across flesh and offals
A13: Tab color codes:
B15: Results
B16: Sheets for input
B17: Intermediate calculations
B18: Figures
A20: Att göra:
A23: Se om det går att få ut en foderstat för denna från Frankrike https://productions-animales.org/article/view/5396
A24: Gödselemissioner från NIR - är det klart? Kolla med Ludvig
A25: Justera till landsspecifik energianvändning https://www.mdpi.com/2076-3417/12/4/2142
A26: Vattenanvändning per land - OBS att detta är för anv i stallar, inte foderodlingen

Sheet Figures
A2: Figures
A4: Greenhouse gas emission for bonefree chicken meat across countries, to farmgate including slaughter, no waste
A42: Lesschen:
J45: Order in this study: | L45: Order in Lesschen:
J47: Poland | L47: Netherlands
J48: UK | L48: Greece
J49: Netherlands | L49: Poland
J50: Denmark | L50: Germany
J51: Sweden | L51: Hungary
J52: Greece | L52: Ireland
J53: Germany | L53: UK
J54: Spain | L54: Denmark
J55: Ireland | L55: Italy
J56: France | L56: France
J57: Italy | L57: Spain
J58: Hungary | L58: Sweden
B71: Production of mineral fertilizer | C71: Production of capital goods | D71: Emissions from soil | E71: Diesel use field machinary | F71: Energy use for feed processing | G71: Land use change emissions | H71: Feed transports | I71: Enteric fermentation | J71: Manure management | K71: Energy use in stables | L71: Energy use for slaughter | M71: Tot
A72: Poland | B72: ='GHG detailed, results per kg'!H106 -> 0.23803531 | C72: ='GHG detailed, results per kg'!I106 -> 0.090380114 | D72: ='GHG detailed, results per kg'!J106+'GHG detailed, results per kg'!K106 -> 0.35702712 | E72: ='GHG detailed, results per kg'!L106+'GHG detailed, results per kg'!N106 -> 0.13266084 | F72: ='GHG detailed, results per kg'!O106 -> 0.15985879 | G72: ='GHG detailed, results per kg'!P106 -> 0.10943919 | H72: ='GHG detailed, results per kg'!R106 -> 0.09632315 | I72: ='GHG detailed, results per kg'!S106 -> 0 | J72: ='GHG detailed, results per kg'!T106 -> 0.1386938 | K72: ='GHG detailed, results per kg'!W106 -> 0.15074932 | L72: ='GHG detailed, results per kg'!X106 -> 0.54600896 | M72: =SUM(B72:L72) -> 2.0191766
A73: UK | B73: ='GHG detailed, results per kg'!H141 -> 0.22131229 | C73: ='GHG detailed, results per kg'!I141 -> 0.09015126 | D73: ='GHG detailed, results per kg'!J141+'GHG detailed, results per kg'!K141 -> 0.4653007 | E73: ='GHG detailed, results per kg'!L141+'GHG detailed, results per kg'!N141 -> 0.1186624 | F73: ='GHG detailed, results per kg'!O141 -> 0.11300219 | G73: ='GHG detailed, results per kg'!P141 -> 0.19408949 | H73: ='GHG detailed, results per kg'!R141 -> 0.17830096 | I73: ='GHG detailed, results per kg'!S141 -> 0 | J73: ='GHG detailed, results per kg'!T141 -> 0.093263729 | K73: ='GHG detailed, results per kg'!W141 -> 0.094238727 | L73: ='GHG detailed, results per kg'!X141 -> 0.22309127 | M73: =SUM(B73:L73) -> 1.791413
A74: Netherlands | B74: ='GHG detailed, results per kg'!H101 -> 0.18889798 | C74: ='GHG detailed, results per kg'!I101 -> 0.088547668 | D74: ='GHG detailed, results per kg'!J101+'GHG detailed, results per kg'!K101 -> 0.38352742 | E74: ='GHG detailed, results per kg'!L101+'GHG detailed, results per kg'!N101 -> 0.098272513 | F74: ='GHG detailed, results per kg'!O101 -> 0.13182431 | G74: ='GHG detailed, results per kg'!P101 -> 0.16580919 | H74: ='GHG detailed, results per kg'!R101 -> 0.16108315 | I74: ='GHG detailed, results per kg'!S101 -> 0 | J74: ='GHG detailed, results per kg'!T101 -> 0.1510445 | K74: ='GHG detailed, results per kg'!W101 -> 0.10486037 | L74: ='GHG detailed, results per kg'!X101 -> 0.28378637 | M74: =SUM(B74:L74) -> 1.7576535
A75: Denmark | B75: ='GHG detailed, results per kg'!H41 -> 0.24971371 | C75: ='GHG detailed, results per kg'!I41 -> 0.090853563 | D75: ='GHG detailed, results per kg'!J41+'GHG detailed, results per kg'!K41 -> 0.48955719 | E75: ='GHG detailed, results per kg'!L41+'GHG detailed, results per kg'!N41 -> 0.099457169 | F75: ='GHG detailed, results per kg'!O41 -> 0.12602944 | G75: ='GHG detailed, results per kg'!P41 -> 0.11199554 | H75: ='GHG detailed, results per kg'!R41 -> 0.10108349 | I75: ='GHG detailed, results per kg'!S41 -> 0 | J75: ='GHG detailed, results per kg'!T41 -> 0.093263729 | K75: ='GHG detailed, results per kg'!W41 -> 0.092086077 | L75: ='GHG detailed, results per kg'!X41 -> 0.21079041 | M75: =SUM(B75:L75) -> 1.6648303
A76: Sweden | B76: ='GHG detailed, results per kg'!H136 -> 0.25129264 | C76: ='GHG detailed, results per kg'!I136 -> 0.092035735 | D76: ='GHG detailed, results per kg'!J136+'GHG detailed, results per kg'!K36 -> 0.48733229 | E76: ='GHG detailed, results per kg'!L136+'GHG detailed, results per kg'!N136 -> 0.11182227 | F76: ='GHG detailed, results per kg'!O136 -> 0.11472904 | G76: ='GHG detailed, results per kg'!P136 -> 0.19366753 | H76: ='GHG detailed, results per kg'!R136 -> 0.17244619 | I76: ='GHG detailed, results per kg'!S136 -> 0 | J76: ='GHG detailed, results per kg'!T136 -> 0.093263729 | K76: ='GHG detailed, results per kg'!W136 -> 0.065053683 | L76: ='GHG detailed, results per kg'!X136 -> 0.056319595 | M76: =SUM(B76:L76) -> 1.6379627
A77: Greece | B77: ='GHG detailed, results per kg'!H66 -> 0.12850413 | C77: ='GHG detailed, results per kg'!I66 -> 0.081097112 | D77: ='GHG detailed, results per kg'!J66+'GHG detailed, results per kg'!K66 -> 0.11730113 | E77: ='GHG detailed, results per kg'!L66+'GHG detailed, results per kg'!N66 -> 0.15210488 | F77: ='GHG detailed, results per kg'!O66 -> 0.12393547 | G77: ='GHG detailed, results per kg'!P66 -> 0.21074569 | H77: ='GHG detailed, results per kg'!R66 -> 0.17453023 | I77: ='GHG detailed, results per kg'!S66 -> 0 | J77: ='GHG detailed, results per kg'!T66 -> 0.14380684 | K77: ='GHG detailed, results per kg'!W66 -> 0.11871036 | L77: ='GHG detailed, results per kg'!X66 -> 0.3629292 | M77: =SUM(B77:L77) -> 1.613665
A78: Germany | B78: ='GHG detailed, results per kg'!H61 -> 0.22779948 | C78: ='GHG detailed, results per kg'!I61 -> 0.090347174 | D78: ='GHG detailed, results per kg'!J61+'GHG detailed, results per kg'!K61 -> 0.34558455 | E78: ='GHG detailed, results per kg'!L61+'GHG detailed, results per kg'!N61 -> 0.090175519 | F78: ='GHG detailed, results per kg'!O61 -> 0.13396724 | G78: ='GHG detailed, results per kg'!P61 -> 0.094471241 | H78: ='GHG detailed, results per kg'!R61 -> 0.097794323 | I78: ='GHG detailed, results per kg'!S1 -> 0 | J78: ='GHG detailed, results per kg'!T61 -> 0.16129506 | K78: ='GHG detailed, results per kg'!W61 -> 0.10159751 | L78: ='GHG detailed, results per kg'!X61 -> 0.26514147 | M78: =SUM(B78:L78) -> 1.6081736
A79: Spain | B79: ='GHG detailed, results per kg'!H131 -> 0.16629826 | C79: ='GHG detailed, results per kg'!I131 -> 0.091990033 | D79: ='GHG detailed, results per kg'!J131+'GHG detailed, results per kg'!K131 -> 0.22550367 | E79: ='GHG detailed, results per kg'!L131+'GHG detailed, results per kg'!N131 -> 0.17747389 | F79: ='GHG detailed, results per kg'!O131 -> 0.12052009 | G79: ='GHG detailed, results per kg'!P131 -> 0.17947456 | H79: ='GHG detailed, results per kg'!R131 -> 0.15094581 | I79: ='GHG detailed, results per kg'!S131 -> 0 | J79: ='GHG detailed, results per kg'!T131 -> 0.1506608 | K79: ='GHG detailed, results per kg'!W131 -> 0.083464271 | L79: ='GHG detailed, results per kg'!X131 -> 0.16152295 | M79: =SUM(B79:L79) -> 1.5078543
A80: Ireland | B80: ='GHG detailed, results per kg'!H76 -> 0.12006494 | C80: ='GHG detailed, results per kg'!I76 -> 0.069390558 | D80: ='GHG detailed, results per kg'!J76+'GHG detailed, results per kg'!K76 -> 0.29117875 | E80: ='GHG detailed, results per kg'!L76+'GHG detailed, results per kg'!N76 -> 0.075023333 | F80: ='GHG detailed, results per kg'!O76 -> 0.10049496 | G80: ='GHG detailed, results per kg'!P76 -> 0.14537906 | H80: ='GHG detailed, results per kg'!R76 -> 0.13484734 | I80: ='GHG detailed, results per kg'!S76 -> 0 | J80: ='GHG detailed, results per kg'!T76 -> 0.12361808 | K80: ='GHG detailed, results per kg'!W76 -> 0.093669772 | L80: ='GHG detailed, results per kg'!X76 -> 0.2198401 | M80: =SUM(B80:L80) -> 1.3735069
A81: France | B81: ='GHG detailed, results per kg'!H56 -> 0.25670205 | C81: ='GHG detailed, results per kg'!I56 -> 0.084528256 | D81: ='GHG detailed, results per kg'!J56+'GHG detailed, results per kg'!K56 -> 0.34183843 | E81: ='GHG detailed, results per kg'!L56+'GHG detailed, results per kg'!N56 -> 0.093381308 | F81: ='GHG detailed, results per kg'!O56 -> 0.10830226 | G81: ='GHG detailed, results per kg'!P56 -> 0.091730991 | H81: ='GHG detailed, results per kg'!R56 -> 0.096283526 | I81: ='GHG detailed, results per kg'!S56 -> 0 | J81: ='GHG detailed, results per kg'!T56 -> 0.11017856 | K81: ='GHG detailed, results per kg'!W56 -> 0.065397296 | L81: ='GHG detailed, results per kg'!X56 -> 0.058283097 | M81: =SUM(B81:L81) -> 1.3066258
A82: Italy | B82: ='GHG detailed, results per kg'!H81 -> 0.20126111 | C82: ='GHG detailed, results per kg'!I81 -> 0.083040166 | D82: ='GHG detailed, results per kg'!J81+'GHG detailed, results per kg'!K81 -> 0.13646328 | E82: ='GHG detailed, results per kg'!L81+'GHG detailed, results per kg'!N81 -> 0.11065477 | F82: ='GHG detailed, results per kg'!O81 -> 0.11751804 | G82: ='GHG detailed, results per kg'!P81 -> 0.12172101 | H82: ='GHG detailed, results per kg'!R81 -> 0.10263629 | I82: ='GHG detailed, results per kg'!S81 -> 0 | J82: ='GHG detailed, results per kg'!T81 -> 0.10084615 | K82: ='GHG detailed, results per kg'!W81 -> 0.095764816 | L82: ='GHG detailed, results per kg'!X81 -> 0.23181178 | M82: =SUM(B82:L82) -> 1.3017174
A83: Hungary | B83: ='GHG detailed, results per kg'!H71 -> 0.19919809 | C83: ='GHG detailed, results per kg'!I71 -> 0.088757377 | D83: ='GHG detailed, results per kg'!J71+'GHG detailed, results per kg'!K71 -> 0.12819491 | E83: ='GHG detailed, results per kg'!L71+'GHG detailed, results per kg'!N71 -> 0.10101657 | F83: ='GHG detailed, results per kg'!O71 -> 0.12688013 | G83: ='GHG detailed, results per kg'!P71 -> 0.10270074 | H83: ='GHG detailed, results per kg'!R71 -> 0.084100047 | I83: ='GHG detailed, results per kg'!S71 -> 0 | J83: ='GHG detailed, results per kg'!T71 -> 0.11443727 | K83: ='GHG detailed, results per kg'!W71 -> 0.099655029 | L83: ='GHG detailed, results per kg'!X71 -> 0.25404157 | M83: =SUM(B83:L83) -> 1.2989817

Sheet Footprints, results per kg
A2: Footprints (per kg of bonefree meat) | M2: * Adjusted for manure
A5: Animal products | F5: Climate | L5: Land | M5: Nitrogen* | N5: Phosphorus | O5: Water | P5: Pesticides | Q5: Biodiversity | R5: Ammonia | S5: Labour | T5: Animal welfare | U5: Use of antibiotics
A6: Code | B6: Name | C6: Category | D6: Country | E6: Country code | F6: Carbon footprint, kg CO2e/kg | G6: Carbon dioxide, kg CO2/kg | H6: Methane, fossil, kg CH4/kg | I6: Methane, biogenic, kg CH4/kg | J6: Nitrous oxide, kg N2O/kg | K6: HFCs, kg HFCs/kg | L6: Cropland use, m2/kg | M6: New N input, kg N/kg | N6: New P input, kg P/kg | O6: Blue freshwater use, m3/kg | P6: Pesticide use, g a.i./kg | Q6: Extinction rate, E/MSY/kg | R6: Ammonia emission, kg NH3/kg | S6: Labour requirements, h/kg | T6: Animal welfare index per kg of bonefree meat
A7: 21121 | B7: Chicken meat | C7: White meat | D7: Austria | E7: AT | F7: ='GHG detailed, results per kg'!G11 -> 1.5092702 | G7: ='GHG detailed, results per kg'!G7 -> 0.86319394 | H7: ='GHG detailed, results per kg'!G8 -> 0.0010944362 | I7: ='GHG detailed, results per kg'!G9 -> 0.0022013861 | J7: ='GHG detailed, results per kg'!G10 -> 0.0020293944 | L7: ='EFP per kg feed'!F17*FCR_bonefree_incl_parents_AT -> 10.389611 | M7: ='EFP per kg feed'!G17*FCR_bonefree_incl_parents_AT-Manure_repl_factor_AT*Excreted_N_after_losses_AT -> 0.051691689 | N7: ='EFP per kg feed'!H17*FCR_bonefree_incl_parents_AT -> 0.0076615155 | O7: ='EFP per kg feed'!I17*FCR_bonefree_incl_parents_AT+Water_stables_AT/Bonefree_outof_CW_AT -> 0.014439502 | P7: ='EFP per kg feed'!J17*FCR_bonefree_incl_parents_AT -> 0.16155118 | Q7: ='EFP per kg feed'!K17*FCR_bonefree_incl_parents_AT -> 2.5375629e-10 | R7: ='EFP per kg feed'!L17*FCR_bonefree_incl_parents_AT+Excreted_N_after_losses_AT -> 0.029187573 | S7: =Production!B52*Labour_per_animal_AT -> 0.16374995
A8: 21121 | B8: Chicken meat | C8: White meat | D8: Belgium | E8: BE | F8: ='GHG detailed, results per kg'!G16 -> 1.4361306 | G8: ='GHG detailed, results per kg'!G12 -> 0.88800536 | H8: ='GHG detailed, results per kg'!G13 -> 0.00092155385 | I8: ='GHG detailed, results per kg'!G14 -> 0.0022013861 | J8: ='GHG detailed, results per kg'!G15 -> 0.0016894707 | L8: ='EFP per kg feed'!F29*FCR_bonefree_incl_parents_BE -> 8.026457 | M8: ='EFP per kg feed'!G29*FCR_bonefree_incl_parents_BE-Manure_repl_factor_BE*Excreted_N_after_losses_BE -> 0.059569596 | N8: ='EFP per kg feed'!H29*FCR_bonefree_incl_parents_BE -> 0.0077825138 | O8: ='EFP per kg feed'!I29*FCR_bonefree_incl_parents_BE+Water_stables_BE/Bonefree_outof_CW_BE -> 0.015369115 | P8: ='EFP per kg feed'!J29*FCR_bonefree_incl_parents_BE -> 0.26539614 | Q8: ='EFP per kg feed'!K29*FCR_bonefree_incl_parents_BE -> 3.9941229e-10 | R8: ='EFP per kg feed'!L29*FCR_bonefree_incl_parents_BE+Excreted_N_after_losses_BE -> 0.029645549 | S8: =Production!C52*Labour_per_animal_BE -> 0.0924884
A9: 21121 | B9: Chicken meat | C9: White meat | D9: Bulgaria | E9: BG | F9: ='GHG detailed, results per kg'!G21 -> 1.4825254 | G9: ='GHG detailed, results per kg'!G17 -> 0.8860164 | H9: ='GHG detailed, results per kg'!G18 -> 0.00083549634 | I9: ='GHG detailed, results per kg'!G19 -> 0.0022013861 | J9: ='GHG detailed, results per kg'!G20 -> 0.0018760945 | L9: ='EFP per kg feed'!F41*FCR_bonefree_incl_parents_BG -> 11.873854 | M9: ='EFP per kg feed'!G41*FCR_bonefree_incl_parents_BG-Manure_repl_factor_BG*Excreted_N_after_losses_BG -> 0.037889187 | N9: ='EFP per kg feed'!H41*FCR_bonefree_incl_parents_BG -> 0.0067014532 | O9: ='EFP per kg feed'!I41*FCR_bonefree_incl_parents_BG+Water_stables_BG/Bonefree_outof_CW_BG -> 0.013771555 | P9: ='EFP per kg feed'!J41*FCR_bonefree_incl_parents_BG -> 0.086617264 | Q9: ='EFP per kg feed'!K41*FCR_bonefree_incl_parents_BG -> 1.609658e-10 | R9: ='EFP per kg feed'!L41*FCR_bonefree_incl_parents_BG+Excreted_N_after_losses_BG -> 0.028661273 | S9: =Production!D52*Labour_per_animal_BG -> 0.30930547
A10: 21121 | B10: Chicken meat | C10: White meat | D10: Croatia | E10: HR | F10: ='GHG detailed, results per kg'!G26 -> 1.6668186 | G10: ='GHG detailed, results per kg'!G22 -> 1.0832445 | H10: ='GHG detailed, results per kg'!G23 -> 0.0012461444 | I10: ='GHG detailed, results per kg'!G24 -> 0.0022013861 | J10: ='GHG detailed, results per kg'!G25 -> 0.0017838884 | L10: ='EFP per kg feed'!F53*FCR_bonefree_incl_parents_HR -> 10.818017 | M10: ='EFP per kg feed'!G53*FCR_bonefree_incl_parents_HR-Manure_repl_factor_HR*Excreted_N_after_losses_HR -> 0.050353677 | N10: ='EFP per kg feed'!H53*FCR_bonefree_incl_parents_HR -> 0.0081656824 | O10: ='EFP per kg feed'!I53*FCR_bonefree_incl_parents_HR+Water_stables_HR/Bonefree_outof_CW_HR -> 0.014594993 | P10: ='EFP per kg feed'!J53*FCR_bonefree_incl_parents_HR -> 0.17611603 | Q10: ='EFP per kg feed'!K53*FCR_bonefree_incl_parents_HR -> 3.8239745e-10 | R10: ='EFP per kg feed'!L53*FCR_bonefree_incl_parents_HR+Excreted_N_after_losses_HR -> 0.028816738 | S10: =Production!E52*Labour_per_animal_HR -> 0.34721055
A11: 21121 | B11: Chicken meat | C11: White meat | D11: Cyprus | E11: CY | F11: ='GHG detailed, results per kg'!G31 -> 2.124919 | G11: ='GHG detailed, results per kg'!G27 -> 1.4349527 | H11: ='GHG detailed, results per kg'!G28 -> 0.0022274804 | I11: ='GHG detailed, results per kg'!G29 -> 0.0022013861 | J11: ='GHG detailed, results per kg'!G30 -> 0.0020664835 | L11: ='EFP per kg feed'!F65*FCR_bonefree_incl_parents_CY -> 9.5598529 | M11: ='EFP per kg feed'!G65*FCR_bonefree_incl_parents_CY-Manure_repl_factor_CY*Excreted_N_after_losses_CY -> 0.060438069 | N11: ='EFP per kg feed'!H65*FCR_bonefree_incl_parents_CY -> 0.0084524034 | O11: ='EFP per kg feed'!I65*FCR_bonefree_incl_parents_CY+Water_stables_CY/Bonefree_outof_CW_CY -> 0.014579277 | P11: ='EFP per kg feed'!J65*FCR_bonefree_incl_parents_CY -> 0.17409708 | Q11: ='EFP per kg feed'!K65*FCR_bonefree_incl_parents_CY -> 3.8972337e-10 | R11: ='EFP per kg feed'!L65*FCR_bonefree_incl_parents_CY+Excreted_N_after_losses_CY -> 0.029038099 | S11: =Production!F52*Labour_per_animal_CY -> 0.069745351
A12: 21121 | B12: Chicken meat | C12: White meat | D12: Czechia | E12: CZ | F12: ='GHG detailed, results per kg'!G36 -> 1.784702 | G12: ='GHG detailed, results per kg'!G32 -> 1.0963773 | H12: ='GHG detailed, results per kg'!G33 -> 0.0011323232 | I12: ='GHG detailed, results per kg'!G34 -> 0.0022013861 | J12: ='GHG detailed, results per kg'!G35 -> 0.0021800147 | L12: ='EFP per kg feed'!F77*FCR_bonefree_incl_parents_CZ -> 9.1816938 | M12: ='EFP per kg feed'!G77*FCR_bonefree_incl_parents_CZ-Manure_repl_factor_CZ*Excreted_N_after_losses_CZ -> 0.056446162 | N12: ='EFP per kg feed'!H77*FCR_bonefree_incl_parents_CZ -> 0.0077073249 | O12: ='EFP per kg feed'!I77*FCR_bonefree_incl_parents_CZ+Water_stables_CZ/Bonefree_outof_CW_CZ -> 0.014247699 | P12: ='EFP per kg feed'!J77*FCR_bonefree_incl_parents_CZ -> 0.13997568 | Q12: ='EFP per kg feed'!K77*FCR_bonefree_incl_parents_CZ -> 2.2926494e-10 | R12: ='EFP per kg feed'!L77*FCR_bonefree_incl_parents_CZ+Excreted_N_after_losses_CZ -> 0.029095855 | S12: =Production!G52*Labour_per_animal_CZ -> 0.13342589
A13: 21121 | B13: Chicken meat | C13: White meat | D13: Denmark | E13: DK | F13: ='GHG detailed, results per kg'!G41 -> 1.6832501 | G13: ='GHG detailed, results per kg'!G37 -> 0.96979988 | H13: ='GHG detailed, results per kg'!G38 -> 0.0011031151 | I13: ='GHG detailed, results per kg'!G39 -> 0.0022013861 | J13: ='GHG detailed, results per kg'!G40 -> 0.0022752379 | L13: ='EFP per kg feed'!F89*FCR_bonefree_incl_parents_DK -> 5.5056842 | M13: ='EFP per kg feed'!G89*FCR_bonefree_incl_parents_DK-Manure_repl_factor_DK*Excreted_N_after_losses_DK -> 0.06802495 | N13: ='EFP per kg feed'!H89*FCR_bonefree_incl_parents_DK -> 0.009368177 | O13: ='EFP per kg feed'!I89*FCR_bonefree_incl_parents_DK+Water_stables_DK/Bonefree_outof_CW_DK -> 0.021950283 | P13: ='EFP per kg feed'!J89*FCR_bonefree_incl_parents_DK -> 0.74850462 | Q13: ='EFP per kg feed'!K89*FCR_bonefree_incl_parents_DK -> 4.6901396e-10 | R13: ='EFP per kg feed'!L89*FCR_bonefree_incl_parents_DK+Excreted_N_after_losses_DK -> 0.032019301 | S13: =Production!H52*Labour_per_animal_DK -> 0.062164334 | T13: 3.7137562 | U13: 19.4
A14: 21121 | B14: Chicken meat | C14: White meat | D14: Estonia | E14: EE | F14: ='GHG detailed, results per kg'!G46 -> 1.2398926 | G14: ='GHG detailed, results per kg'!G42 -> 0.81427153 | H14: ='GHG detailed, results per kg'!G43 -> 0.0018321997 | I14: ='GHG detailed, results per kg'!G44 -> 0.0022013861 | J14: ='GHG detailed, results per kg'!G45 -> 0.0011413336 | L14: ='EFP per kg feed'!F101*FCR_bonefree_incl_parents_EE -> 4.8277187 | M14: ='EFP per kg feed'!G101*FCR_bonefree_incl_parents_EE-Manure_repl_factor_EE*Excreted_N_after_losses_EE -> 0.029066435 | N14: ='EFP per kg feed'!H101*FCR_bonefree_incl_parents_EE -> 0.0046807495 | O14: ='EFP per kg feed'!I101*FCR_bonefree_incl_parents_EE+Water_stables_EE/Bonefree_outof_CW_EE -> 0.01386508 | P14: ='EFP per kg feed'!J101*FCR_bonefree_incl_parents_EE -> 0.098381513 | Q14: ='EFP per kg feed'!K101*FCR_bonefree_incl_parents_EE -> 1.2664368e-10 | R14: ='EFP per kg feed'!L101*FCR_bonefree_incl_parents_EE+Excreted_N_after_losses_EE -> 0.029009395 | S14: =Production!I52*Labour_per_animal_EE -> 0.068229148
A15: 21121 | B15: Chicken meat | C15: White meat | D15: Finland | E15: FI | F15: ='GHG detailed, results per kg'!G51 -> 1.5575329 | G15: ='GHG detailed, results per kg'!G47 -> 0.89988162 | H15: ='GHG detailed, results per kg'!G48 -> 0.0011415948 | I15: ='GHG detailed, results per kg'!G49 -> 0.0022013861 | J15: ='GHG detailed, results per kg'!G50 -> 0.0020666461 | L15: ='EFP per kg feed'!F113*FCR_bonefree_incl_parents_FI -> 6.2414862 | M15: ='EFP per kg feed'!G113*FCR_bonefree_incl_parents_FI-Manure_repl_factor_FI*Excreted_N_after_losses_FI -> 0.064779926 | N15: ='EFP per kg feed'!H113*FCR_bonefree_incl_parents_FI -> 0.011241359 | O15: ='EFP per kg feed'!I113*FCR_bonefree_incl_parents_FI+Water_stables_FI/Bonefree_outof_CW_FI -> 0.015227821 | P15: ='EFP per kg feed'!J113*FCR_bonefree_incl_parents_FI -> 0.25303358 | Q15: ='EFP per kg feed'!K113*FCR_bonefree_incl_parents_FI -> 2.5007746e-10 | R15: ='EFP per kg feed'!L113*FCR_bonefree_incl_parents_FI+Excreted_N_after_losses_FI -> 0.030844704 | S15: =Production!J52*Labour_per_animal_FI -> 0.089455993
A16: 21121 | B16: Chicken meat | C16: White meat | D16: France | E16: FR | F16: ='GHG detailed, results per kg'!G56 -> 1.3265143 | G16: ='GHG detailed, results per kg'!G52 -> 0.7460333 | H16: ='GHG detailed, results per kg'!G53 -> 0.0010169099 | I16: ='GHG detailed, results per kg'!G54 -> 0.0022548527 | J16: ='GHG detailed, results per kg'!G55 -> 0.0017922933 | L16: ='EFP per kg feed'!F125*FCR_bonefree_incl_parents_FR -> 4.7229561 | M16: ='EFP per kg feed'!G125*FCR_bonefree_incl_parents_FR-Manure_repl_factor_FR*Excreted_N_after_losses_FR -> 0.058493449 | N16: ='EFP per kg feed'!H125*FCR_bonefree_incl_parents_FR -> 0.010741997 | O16: ='EFP per kg feed'!I125*FCR_bonefree_incl_parents_FR+Water_stables_FR/Bonefree_outof_CW_FR -> 0.089587279 | P16: ='EFP per kg feed'!J125*FCR_bonefree_incl_parents_FR -> 0.7010948 | Q16: ='EFP per kg feed'!K125*FCR_bonefree_incl_parents_FR -> 1.3831994e-09 | R16: ='EFP per kg feed'!L125*FCR_bonefree_incl_parents_FR+Excreted_N_after_losses_FR -> 0.045473608 | S16: =Production!K52*Labour_per_animal_FR -> 0.094548198 | T16: 4.0414332 | U16: 38.1
A17: 21121 | B17: Chicken meat | C17: White meat | D17: Germany | E17: DE | F17: ='GHG detailed, results per kg'!G61 -> 1.6281702 | G17: ='GHG detailed, results per kg'!G57 -> 0.98916343 | H17: ='GHG detailed, results per kg'!G58 -> 0.0014032805 | I17: ='GHG detailed, results per kg'!G59 -> 0.0033020792 | J17: ='GHG detailed, results per kg'!G60 -> 0.0018609264 | K17: =G17+H17*29.8+I17*27+J17*273 -> 1.6281702 | L17: ='EFP per kg feed'!F137*FCR_bonefree_incl_parents_DE -> 4.7692643 | M17: ='EFP per kg feed'!G137*FCR_bonefree_incl_parents_DE-Manure_repl_factor_DE*Excreted_N_after_losses_DE -> 0.05299851 | N17: ='EFP per kg feed'!H137*FCR_bonefree_incl_parents_DE -> 0.010613089 | O17: ='EFP per kg feed'!I137*FCR_bonefree_incl_parents_DE+Water_stables_DE/Bonefree_outof_CW_DE -> 0.015870449 | P17: ='EFP per kg feed'!J137*FCR_bonefree_incl_parents_DE -> 1.2965167 | Q17: ='EFP per kg feed'!K137*FCR_bonefree_incl_parents_DE -> 3.6072017e-10 | R17: ='EFP per kg feed'!L137*FCR_bonefree_incl_parents_DE+Excreted_N_after_losses_DE -> 0.065457899 | S17: =Production!L52*Labour_per_animal_DE -> 0.10613423 | T17: 3.5910056 | U17: 50.4
A18: 21121 | B18: Chicken meat | C18: White meat | D18: Greece | E18: GR | F18: ='GHG detailed, results per kg'!G66 -> 1.6420556 | G18: ='GHG detailed, results per kg'!G62 -> 1.2701078 | H18: ='GHG detailed, results per kg'!G63 -> 0.0017458147 | I18: ='GHG detailed, results per kg'!G64 -> 0.0033020792 | J18: ='GHG detailed, results per kg'!G65 -> 0.00084529818 | L18: ='EFP per kg feed'!F138*FCR_bonefree_incl_parents_GR -> 11.530704 | M18: ='EFP per kg feed'!G138*FCR_bonefree_incl_parents_GR-Manure_repl_factor_GR*Excreted_N_after_losses_GR -> 0.045724947 | N18: ='EFP per kg feed'!H138*FCR_bonefree_incl_parents_GR -> 0.010154881 | O18: ='EFP per kg feed'!I138*FCR_bonefree_incl_parents_GR+Water_stables_GR/Bonefree_outof_CW_GR -> 0.012987013 | P18: ='EFP per kg feed'!J138*FCR_bonefree_incl_parents_GR -> 0.52412289 | Q18: ='EFP per kg feed'!K138*FCR_bonefree_incl_parents_GR -> 1.9032212e-08 | R18: ='EFP per kg feed'!L138*FCR_bonefree_incl_parents_GR+Excreted_N_after_losses_GR -> 0.050227074 | S18: =Production!M52*Labour_per_animal_GR -> 0.069745351 | T18: 4.0181974 | U18: 111.7
A19: 21121 | B19: Chicken meat | C19: White meat | D19: Hungary | E19: HU | F19: ='GHG detailed, results per kg'!G71 -> 1.3128138 | G19: ='GHG detailed, results per kg'!G67 -> 0.94482381 | H19: ='GHG detailed, results per kg'!G68 -> 0.0014900731 | I19: ='GHG detailed, results per kg'!G69 -> 0.0022013861 | J19: ='GHG detailed, results per kg'!G70 -> 0.0009675764 | L19: ='EFP per kg feed'!F161*FCR_bonefree_incl_parents_HU -> 5.4437521 | M19: ='EFP per kg feed'!G161*FCR_bonefree_incl_parents_HU-Manure_repl_factor_HU*Excreted_N_after_losses_HU -> 0.046445615 | N19: ='EFP per kg feed'!H161*FCR_bonefree_incl_parents_HU -> 0.013406362 | O19: ='EFP per kg feed'!I161*FCR_bonefree_incl_parents_HU+Water_stables_HU/Bonefree_outof_CW_HU -> 0.024492772 | P19: ='EFP per kg feed'!J161*FCR_bonefree_incl_parents_HU -> 0.48488616 | Q19: ='EFP per kg feed'!K161*FCR_bonefree_incl_parents_HU -> 3.8941156e-10 | R19: ='EFP per kg feed'!L161*FCR_bonefree_incl_parents_HU+Excreted_N_after_losses_HU -> 0.049707416 | S19: =Production!N52*Labour_per_animal_HU -> 0.30475686 | T19: 4.0175551 | U19: 102.5
A20: 21121 | B20: Chicken meat | C20: White meat | D20: Ireland | E20: IE | F20: ='GHG detailed, results per kg'!G76 -> 1.3987103 | G20: ='GHG detailed, results per kg'!G72 -> 0.90510556 | H20: ='GHG detailed, results per kg'!G73 -> 0.00092381804 | I20: ='GHG detailed, results per kg'!G74 -> 0.0023114555 | J20: ='GHG detailed, results per kg'!G75 -> 0.0014786289 | L20: ='EFP per kg feed'!F173*FCR_bonefree_incl_parents_IE -> 4.0873594 | M20: ='EFP per kg feed'!G173*FCR_bonefree_incl_parents_IE-Manure_repl_factor_IE*Excreted_N_after_losses_IE -> 0.04409976 | N20: ='EFP per kg feed'!H173*FCR_bonefree_incl_parents_IE -> 0.0078240708 | O20: ='EFP per kg feed'!I173*FCR_bonefree_incl_parents_IE+Water_stables_IE/Bonefree_outof_CW_IE -> 0.014883424 | P20: ='EFP per kg feed'!J173*FCR_bonefree_incl_parents_IE -> 0.99114394 | Q20: ='EFP per kg feed'!K173*FCR_bonefree_incl_parents_IE -> 4.4076574e-10 | R20: ='EFP per kg feed'!L173*FCR_bonefree_incl_parents_IE+Excreted_N_after_losses_IE -> 0.054695165 | S20: =Production!O52*Labour_per_animal_IE -> 0.20317124 | T20: 4.0181974 | U20: 40.6
A21: 21121 | B21: Chicken meat | C21: White meat | D21: Italy | E21: IT | F21: ='GHG detailed, results per kg'!G81 -> 1.3184303 | G21: ='GHG detailed, results per kg'!G77 -> 0.94113879 | H21: ='GHG detailed, results per kg'!G78 -> 0.0019482909 | I21: ='GHG detailed, results per kg'!G79 -> 0.0022013861 | J21: ='GHG detailed, results per kg'!G80 -> 0.00095162992 | L21: ='EFP per kg feed'!F185*FCR_bonefree_incl_parents_IT -> 5.1818383 | M21: ='EFP per kg feed'!G185*FCR_bonefree_incl_parents_IT-Manure_repl_factor_IT*Excreted_N_after_losses_IT -> 0.051948917 | N21: ='EFP per kg feed'!H185*FCR_bonefree_incl_parents_IT -> 0.012513637 | O21: ='EFP per kg feed'!I185*FCR_bonefree_incl_parents_IT+Water_stables_IT/Bonefree_outof_CW_IT -> 0.19261166 | P21: ='EFP per kg feed'!J185*FCR_bonefree_incl_parents_IT -> 0.59106668 | Q21: ='EFP per kg feed'!K185*FCR_bonefree_incl_parents_IT -> 4.9457643e-09 | R21: ='EFP per kg feed'!L185*FCR_bonefree_incl_parents_IT+Excreted_N_after_losses_IT -> 0.037695122 | S21: =Production!P52*Labour_per_animal_IT -> 0.098553213 | T21: 4.0181974 | U21: 129.1
A22: 21121 | B22: Chicken meat | C22: White meat | D22: Latvia | E22: LV | F22: ='GHG detailed, results per kg'!G86 -> 1.646143 | G22: ='GHG detailed, results per kg'!G82 -> 1.0047267 | H22: ='GHG detailed, results per kg'!G83 -> 0.0019934818 | I22: ='GHG detailed, results per kg'!G84 -> 0.0022013861 | J22: ='GHG detailed, results per kg'!G85 -> 0.0019141873 | L22: ='EFP per kg feed'!F197*FCR_bonefree_incl_parents_LV -> 7.4883007 | M22: ='EFP per kg feed'!G197*FCR_bonefree_incl_parents_LV-Manure_repl_factor_LV*Excreted_N_after_losses_LV -> 0.05584175 | N22: ='EFP per kg feed'!H197*FCR_bonefree_incl_parents_LV -> 0.0071391219 | O22: ='EFP per kg feed'!I197*FCR_bonefree_incl_parents_LV+Water_stables_LV/Bonefree_outof_CW_LV -> 0.014686065 | P22: ='EFP per kg feed'!J197*FCR_bonefree_incl_parents_LV -> 0.19032495 | Q22: ='EFP per kg feed'!K197*FCR_bonefree_incl_parents_LV -> 2.4662312e-10 | R22: ='EFP per kg feed'!L197*FCR_bonefree_incl_parents_LV+Excreted_N_after_losses_LV -> 0.029386731 | S22: =Production!Q52*Labour_per_animal_LV -> 0.22743049
A23: 21121 | B23: Chicken meat | C23: White meat | D23: Lithuania | E23: LT | F23: ='GHG detailed, results per kg'!G91 -> 1.6839321 | G23: ='GHG detailed, results per kg'!G87 -> 1.0488961 | H23: ='GHG detailed, results per kg'!G88 -> 0.0016311933 | I23: ='GHG detailed, results per kg'!G89 -> 0.0022013861 | J23: ='GHG detailed, results per kg'!G90 -> 0.001930363 | L23: ='EFP per kg feed'!F209*FCR_bonefree_incl_parents_LT -> 8.6015859 | M23: ='EFP per kg feed'!G209*FCR_bonefree_incl_parents_LT-Manure_repl_factor_LT*Excreted_N_after_losses_LT -> 0.058759057 | N23: ='EFP per kg feed'!H209*FCR_bonefree_incl_parents_LT -> 0.0072175694 | O23: ='EFP per kg feed'!I209*FCR_bonefree_incl_parents_LT+Water_stables_LT/Bonefree_outof_CW_LT -> 0.014556737 | P23: ='EFP per kg feed'!J209*FCR_bonefree_incl_parents_LT -> 0.17309923 | Q23: ='EFP per kg feed'!K209*FCR_bonefree_incl_parents_LT -> 3.2967357e-10 | R23: ='EFP per kg feed'!L209*FCR_bonefree_incl_parents_LT+Excreted_N_after_losses_LT -> 0.028907773 | S23: =Production!R52*Labour_per_animal_LT -> 0.2319791
A24: 21121 | B24: Chicken meat | C24: White meat | D24: Malta | E24: MT | F24: ='GHG detailed, results per kg'!G96 -> 1.7630951 | G24: ='GHG detailed, results per kg'!G92 -> 1.1042139 | H24: ='GHG detailed, results per kg'!G93 -> 0.0019325333 | I24: ='GHG detailed, results per kg'!G94 -> 0.0022013861 | J24: ='GHG detailed, results per kg'!G95 -> 0.001984814 | L24: ='EFP per kg feed'!F221*FCR_bonefree_incl_parents_MT -> 10.774721 | M24: ='EFP per kg feed'!G221*FCR_bonefree_incl_parents_MT-Manure_repl_factor_MT*Excreted_N_after_losses_MT -> 0.057416792 | N24: ='EFP per kg feed'!H221*FCR_bonefree_incl_parents_MT -> 0.0076342443 | O24: ='EFP per kg feed'!I221*FCR_bonefree_incl_parents_MT+Water_stables_MT/Bonefree_outof_CW_MT -> 0.014620402 | P24: ='EFP per kg feed'!J221*FCR_bonefree_incl_parents_MT -> 0.17823711 | Q24: ='EFP per kg feed'!K221*FCR_bonefree_incl_parents_MT -> 4.1304522e-10 | R24: ='EFP per kg feed'!L221*FCR_bonefree_incl_parents_MT+Excreted_N_after_losses_MT -> 0.028644145 | S24: =Production!S52*Labour_per_animal_MT -> 0.11978006
A25: 21121 | B25: Chicken meat | C25: White meat | D25: Netherlands | E25: NL | F25: ='GHG detailed, results per kg'!G101 -> 1.7895472 | G25: ='GHG detailed, results per kg'!G97 -> 1.1319672 | H25: ='GHG detailed, results per kg'!G98 -> 0.0015856929 | I25: ='GHG detailed, results per kg'!G99 -> 0.0031693198 | J25: ='GHG detailed, results per kg'!G100 -> 0.0019221784 | L25: ='EFP per kg feed'!F233*FCR_bonefree_incl_parents_NL -> 5.1252606 | M25: ='EFP per kg feed'!G233*FCR_bonefree_incl_parents_NL-Manure_repl_factor_NL*Excreted_N_after_losses_NL -> 0.061582344 | N25: ='EFP per kg feed'!H233*FCR_bonefree_incl_parents_NL -> 0.011515637 | O25: ='EFP per kg feed'!I233*FCR_bonefree_incl_parents_NL+Water_stables_NL/Bonefree_outof_CW_NL -> 0.027587863 | P25: ='EFP per kg feed'!J233*FCR_bonefree_incl_parents_NL -> 1.4322929 | Q25: ='EFP per kg feed'!K233*FCR_bonefree_incl_parents_NL -> 5.2214194e-10 | R25: ='EFP per kg feed'!L233*FCR_bonefree_incl_parents_NL+Excreted_N_after_losses_NL -> 0.059299832 | S25: =Production!T52*Labour_per_animal_NL -> 0.12736108 | T25: 3.9652974 | U25: 32.1
A26: 21121 | B26: Chicken meat | C26: White meat | D26: Poland | E26: PL | F26: ='GHG detailed, results per kg'!G106 -> 2.0362177 | G26: ='GHG detailed, results per kg'!G102 -> 1.3816965 | H26: ='GHG detailed, results per kg'!G103 -> 0.0021239649 | I26: ='GHG detailed, results per kg'!G104 -> 0.0033020792 | J26: ='GHG detailed, results per kg'!G105 -> 0.0018390874 | L26: ='EFP per kg feed'!F245*FCR_bonefree_incl_parents_PL -> 7.0510223 | M26: ='EFP per kg feed'!G245*FCR_bonefree_incl_parents_PL-Manure_repl_factor_PL*Excreted_N_after_losses_PL -> 0.055335453 | N26: ='EFP per kg feed'!H245*FCR_bonefree_incl_parents_PL -> 0.010506687 | O26: ='EFP per kg feed'!I245*FCR_bonefree_incl_parents_PL+Water_stables_PL/Bonefree_outof_CW_PL -> 0.017549218 | P26: ='EFP per kg feed'!J245*FCR_bonefree_incl_parents_PL -> 0.68914629 | Q26: ='EFP per kg feed'!K245*FCR_bonefree_incl_parents_PL -> 5.148248e-10 | R26: ='EFP per kg feed'!L245*FCR_bonefree_incl_parents_PL+Excreted_N_after_losses_PL -> 0.045305435 | S26: =Production!U52*Labour_per_animal_PL -> 0.32143509 | T26: 4.0175551 | U26: 134.7
A27: 21121 | B27: Chicken meat | C27: White meat | D27: Portugal | E27: PT | F27: ='GHG detailed, results per kg'!G111 -> 1.7759507 | G27: ='GHG detailed, results per kg'!G107 -> 1.0590786 | H27: ='GHG detailed, results per kg'!G108 -> 0.0015130992 | I27: ='GHG detailed, results per kg'!G109 -> 0.0022013861 | J27: ='GHG detailed, results per kg'!G110 -> 0.0022430198 | L27: ='EFP per kg feed'!F246*FCR_bonefree_incl_parents_PL -> 7.1460909 | M27: ='EFP per kg feed'!G246*FCR_bonefree_incl_parents_PL-Manure_repl_factor_PL*Excreted_N_after_losses_PL -> 0.04631184 | N27: ='EFP per kg feed'!H246*FCR_bonefree_incl_parents_PL -> 0.010004527 | O27: ='EFP per kg feed'!I246*FCR_bonefree_incl_parents_PL+Water_stables_PL/Bonefree_outof_CW_PL -> 0.012987013 | P27: ='EFP per kg feed'!J246*FCR_bonefree_incl_parents_PL -> 3.7159672e-07 | Q27: ='EFP per kg feed'!K246*FCR_bonefree_incl_parents_PL -> 3.057246e-15 | R27: ='EFP per kg feed'!L246*FCR_bonefree_incl_parents_PL+Excreted_N_after_losses_PL -> 0.043438013 | S27: =Production!V52*Labour_per_animal_PT -> 0.063680538
A28: 21121 | B28: Chicken meat | C28: White meat | D28: Romania | E28: RO | F28: ='GHG detailed, results per kg'!G116 -> 1.3046117 | G28: ='GHG detailed, results per kg'!G112 -> 0.79410435 | H28: ='GHG detailed, results per kg'!G113 -> 0.00076706291 | I28: ='GHG detailed, results per kg'!G114 -> 0.0022013861 | J28: ='GHG detailed, results per kg'!G115 -> 0.00156854 | L28: ='EFP per kg feed'!F269*FCR_bonefree_incl_parents_RO -> 9.5783283 | M28: ='EFP per kg feed'!G269*FCR_bonefree_incl_parents_RO-Manure_repl_factor_RO*Excreted_N_after_losses_RO -> 0.03544192 | N28: ='EFP per kg feed'!H269*FCR_bonefree_incl_parents_RO -> 0.0064312059 | O28: ='EFP per kg feed'!I269*FCR_bonefree_incl_parents_RO+Water_stables_RO/Bonefree_outof_CW_RO -> 0.013922612 | P28: ='EFP per kg feed'!J269*FCR_bonefree_incl_parents_RO -> 0.10305746 | Q28: ='EFP per kg feed'!K269*FCR_bonefree_incl_parents_RO -> 2.007644e-10 | R28: ='EFP per kg feed'!L269*FCR_bonefree_incl_parents_RO+Excreted_N_after_losses_RO -> 0.028677813 | S28: =Production!W52*Labour_per_animal_RO -> 0.42453692
A29: 21121 | B29: Chicken meat | C29: White meat | D29: Slovakia | E29: SK | F29: ='GHG detailed, results per kg'!G121 -> 1.4811818 | G29: ='GHG detailed, results per kg'!G117 -> 0.92005878 | H29: ='GHG detailed, results per kg'!G118 -> 0.0011282747 | I29: ='GHG detailed, results per kg'!G119 -> 0.0022013861 | J29: ='GHG detailed, results per kg'!G120 -> 0.0017145163 | L29: ='EFP per kg feed'!F281*FCR_bonefree_incl_parents_SK -> 10.992647 | M29: ='EFP per kg feed'!G281*FCR_bonefree_incl_parents_SK-Manure_repl_factor_SK*Excreted_N_after_losses_SK -> 0.043065464 | N29: ='EFP per kg feed'!H281*FCR_bonefree_incl_parents_SK -> 0.0070468092 | O29: ='EFP per kg feed'!I281*FCR_bonefree_incl_parents_SK+Water_stables_SK/Bonefree_outof_CW_SK -> 0.0144725 | P29: ='EFP per kg feed'!J281*FCR_bonefree_incl_parents_SK -> 0.16453258 | Q29: ='EFP per kg feed'!K281*FCR_bonefree_incl_parents_SK -> 2.8513121e-10 | R29: ='EFP per kg feed'!L281*FCR_bonefree_incl_parents_SK+Excreted_N_after_losses_SK -> 0.028895602 | S29: =Production!X52*Labour_per_animal_SK -> 0.15616894
A30: 21121 | B30: Chicken meat | C30: White meat | D30: Slovenia | E30: SI | F30: ='GHG detailed, results per kg'!G126 -> 1.3972174 | G30: ='GHG detailed, results per kg'!G122 -> 0.71718286 | H30: ='GHG detailed, results per kg'!G123 -> 0.00086241939 | I30: ='GHG detailed, results per kg'!G124 -> 0.0022013861 | J30: ='GHG detailed, results per kg'!G125 -> 0.0021791099 | L30: ='EFP per kg feed'!F293*FCR_bonefree_incl_parents_SI -> 10.59831 | M30: ='EFP per kg feed'!G293*FCR_bonefree_incl_parents_SI-Manure_repl_factor_SI*Excreted_N_after_losses_SI -> 0.041838404 | N30: ='EFP per kg feed'!H293*FCR_bonefree_incl_parents_SI -> 0.0069792426 | O30: ='EFP per kg feed'!I293*FCR_bonefree_incl_parents_SI+Water_stables_SI/Bonefree_outof_CW_SI -> 0.013512506 | P30: ='EFP per kg feed'!J293*FCR_bonefree_incl_parents_SI -> 0.059471499 | Q30: ='EFP per kg feed'!K293*FCR_bonefree_incl_parents_SI -> 5.3743107e-11 | R30: ='EFP per kg feed'!L293*FCR_bonefree_incl_parents_SI+Excreted_N_after_losses_SI -> 0.028977955 | S30: =Production!Y52*Labour_per_animal_SI -> 0.45637719
A31: 21121 | B31: Chicken meat | C31: White meat | D31: Spain | E31: ES | F31: ='GHG detailed, results per kg'!G131 -> 1.5335329 | G31: ='GHG detailed, results per kg'!G127 -> 1.0417051 | H31: ='GHG detailed, results per kg'!G128 -> 0.0015090295 | I31: ='GHG detailed, results per kg'!G129 -> 0.0029891817 | J31: ='GHG detailed, results per kg'!G130 -> 0.001341212 | L31: ='EFP per kg feed'!F305*FCR_bonefree_incl_parents_ES -> 7.5137079 | M31: ='EFP per kg feed'!G305*FCR_bonefree_incl_parents_ES-Manure_repl_factor_ES*Excreted_N_after_losses_ES -> 0.05232145 | N31: ='EFP per kg feed'!H305*FCR_bonefree_incl_parents_ES -> 0.011865135 | O31: ='EFP per kg feed'!I305*FCR_bonefree_incl_parents_ES+Water_stables_ES/Bonefree_outof_CW_ES -> 0.65893968 | P31: ='EFP per kg feed'!J305*FCR_bonefree_incl_parents_ES -> 0.52449158 | Q31: ='EFP per kg feed'!K305*FCR_bonefree_incl_parents_ES -> 1.1939788e-08 | R31: ='EFP per kg feed'!L305*FCR_bonefree_incl_parents_ES+Excreted_N_after_losses_ES -> 0.062712675 | S31: =Production!Z52*Labour_per_animal_ES -> 0.030324066 | T31: 4.0175551 | U31: 95.7
A32: 21121 | B32: Chicken meat | C32: White meat | D32: Sweden | E32: SE | F32: ='GHG detailed, results per kg'!G136 -> 1.6703778 | G32: ='GHG detailed, results per kg'!G132 -> 0.96137293 | H32: ='GHG detailed, results per kg'!G133 -> 0.00096050214 | I32: ='GHG detailed, results per kg'!G134 -> 0.0022013861 | J32: ='GHG detailed, results per kg'!G135 -> 0.002274522 | L32: ='EFP per kg feed'!F317*FCR_bonefree_incl_parents_SE -> 6.0474278 | M32: ='EFP per kg feed'!G317*FCR_bonefree_incl_parents_SE-Manure_repl_factor_SE*Excreted_N_after_losses_SE -> 0.078367539 | N32: ='EFP per kg feed'!H317*FCR_bonefree_incl_parents_SE -> 0.0091283907 | O32: ='EFP per kg feed'!I317*FCR_bonefree_incl_parents_SE+Water_stables_SE/Bonefree_outof_CW_SE -> 0.015210233 | P32: ='EFP per kg feed'!J317*FCR_bonefree_incl_parents_SE -> 0.49994899 | Q32: ='EFP per kg feed'!K317*FCR_bonefree_incl_parents_SE -> 4.6739436e-10 | R32: ='EFP per kg feed'!L317*FCR_bonefree_incl_parents_SE+Excreted_N_after_losses_SE -> 0.032095317 | S32: =Production!AA52*Labour_per_animal_SE -> 0.062164334 | T32: 3.2167138 | U32: 10.1
A33: 21121 | B33: Chicken meat | C33: White meat | D33: UK | E33: GB | F33: ='GHG detailed, results per kg'!G141 -> 1.8248724 | G33: ='GHG detailed, results per kg'!G137 -> 1.1435903 | H33: ='GHG detailed, results per kg'!G138 -> 0.0012190321 | I33: ='GHG detailed, results per kg'!G139 -> 0.0022013861 | J33: ='GHG detailed, results per kg'!G140 -> 0.002144753 | L33: ='EFP per kg feed'!F329*FCR_bonefree_incl_parents_GB -> 8.5754518 | M33: ='EFP per kg feed'!G329*FCR_bonefree_incl_parents_GB-Manure_repl_factor_GB*Excreted_N_after_losses_GB -> 0.07326634 | N33: ='EFP per kg feed'!H329*FCR_bonefree_incl_parents_GB -> 0.0089749896 | O33: ='EFP per kg feed'!I329*FCR_bonefree_incl_parents_GB+Water_stables_GB/Bonefree_outof_CW_GB -> 0.015325819 | P33: ='EFP per kg feed'!J329*FCR_bonefree_incl_parents_GB -> 0.25920829 | Q33: ='EFP per kg feed'!K329*FCR_bonefree_incl_parents_GB -> 4.4287036e-10 | R33: ='EFP per kg feed'!L329*FCR_bonefree_incl_parents_GB+Excreted_N_after_losses_GB -> 0.02958822 | S33: =Production!AB52*Labour_per_animal_GB -> 0.086423587 | U33: 29.8
A34: 21121 | B34: Chicken meat | C34: White meat | D34: Brazil | E34: BR | F34: ='GHG detailed, results per kg'!G146 -> 1.975719 | G34: ='GHG detailed, results per kg'!G142 -> 1.2972925 | H34: ='GHG detailed, results per kg'!G143 -> 0.0011640501 | I34: ='GHG detailed, results per kg'!G144 -> 0.0022013861 | J34: ='GHG detailed, results per kg'!G145 -> 0.0021402946 | L34: ='EFP per kg feed'!F341*FCR_bonefree_incl_parents_BR -> 8.5754518 | M34: ='EFP per kg feed'!G341*FCR_bonefree_incl_parents_BR-Manure_repl_factor_BR*Excreted_N_after_losses_BR -> 0.07326634 | N34: ='EFP per kg feed'!H341*FCR_bonefree_incl_parents_BR -> 0.0089749896 | O34: ='EFP per kg feed'!I341*FCR_bonefree_incl_parents_BR+Water_stables_BR/Bonefree_outof_CW_BR -> 0.015325819 | P34: ='EFP per kg feed'!J341*FCR_bonefree_incl_parents_BR -> 0.25920829 | Q34: ='EFP per kg feed'!K341*FCR_bonefree_incl_parents_BR -> 4.4287036e-10 | R34: ='EFP per kg feed'!L341*FCR_bonefree_incl_parents_BR+Excreted_N_after_losses_BR -> 0.02958822 | S34: =Production!AC52*Labour_per_animal_BR -> 0.086423587
A35: 21121 | B35: Chicken meat | C35: White meat | D35: Thailand | E35: TH | F35: ='GHG detailed, results per kg'!G151 -> 2.0457732 | G35: ='GHG detailed, results per kg'!G147 -> 1.3494256 | H35: ='GHG detailed, results per kg'!G148 -> 0.0018170867 | I35: ='GHG detailed, results per kg'!G149 -> 0.0022013861 | J35: ='GHG detailed, results per kg'!G150 -> 0.0021346555 | L35: ='EFP per kg feed'!F353*FCR_bonefree_incl_parents_TH -> 8.5754518 | M35: ='EFP per kg feed'!G353*FCR_bonefree_incl_parents_TH-Manure_repl_factor_TH*Excreted_N_after_losses_TH -> 0.07326634 | N35: ='EFP per kg feed'!H353*FCR_bonefree_incl_parents_TH -> 0.0089749896 | O35: ='EFP per kg feed'!I353*FCR_bonefree_incl_parents_TH+Water_stables_TH/Bonefree_outof_CW_TH -> 0.015325819 | P35: ='EFP per kg feed'!J353*FCR_bonefree_incl_parents_TH -> 0.25920829 | Q35: ='EFP per kg feed'!K353*FCR_bonefree_incl_parents_TH -> 4.4287036e-10 | R35: ='EFP per kg feed'!L353*FCR_bonefree_incl_parents_TH+Excreted_N_after_losses_TH -> 0.02958822 | S35: =Production!AD52*Labour_per_animal_TH -> 0.086423587
A36: 21121 | B36: Chicken meat | C36: White meat | D36: USA | E36: US | F36: ='GHG detailed, results per kg'!G156 -> 2.0214359 | G36: ='GHG detailed, results per kg'!G152 -> 1.344688 | H36: ='GHG detailed, results per kg'!G153 -> 0.0011518059 | I36: ='GHG detailed, results per kg'!G154 -> 0.0022013861 | J36: ='GHG detailed, results per kg'!G155 -> 0.0021354821 | L36: ='EFP per kg feed'!F365*FCR_bonefree_incl_parents_US -> 8.5754518 | M36: ='EFP per kg feed'!G365*FCR_bonefree_incl_parents_US-Manure_repl_factor_US*Excreted_N_after_losses_US -> 0.07326634 | N36: ='EFP per kg feed'!H365*FCR_bonefree_incl_parents_US -> 0.0089749896 | O36: ='EFP per kg feed'!I365*FCR_bonefree_incl_parents_US+Water_stables_US/Bonefree_outof_CW_US -> 0.015325819 | P36: ='EFP per kg feed'!J365*FCR_bonefree_incl_parents_US -> 0.25920829 | Q36: ='EFP per kg feed'!K365*FCR_bonefree_incl_parents_US -> 4.4287036e-10 | R36: ='EFP per kg feed'!L365*FCR_bonefree_incl_parents_US+Excreted_N_after_losses_US -> 0.02958822 | S36: =Production!AE52*Labour_per_animal_US -> 0.086423587

Sheet GHG detailed, results per kg
H1: * Production of mineral fertiliser is adjusted to account for the N supplied by manure.
A2: GHG emissions (per kg of bonefree meat) | H2: ** Adjusted for use of manure instead of mineral fertiliser (lower emission factor for manure)
H3: *** Calculated as percentage of direct emissions due to assumption due to data limitations regarding nitrogen leaching and volatilization from soils in different regions.
S4: Animals | W4: Stables | X4: Slaughter | Z4: Control
A5: Animal products | G5: Sum | H5: Inputs | J5: Soil emissions | L5: Energy use | P5: Land use change | Q5: Feed processing | R5: Transports
A6: FoodEx code | B6: FoodEx name | C6: Food Ex category (L1) | D6: Country | E6: Country code | F6: Gas | G6: GHG | H6: Production of mineral fertilizer* | I6: Production of capital goods | J6: Direct emissions** | K6: Indirect emissions*** | L6: Diesel use field mach | M6: Energy use in greenhouses | N6: Energy use for irrigation | O6: Energy use for post-harvest proc | P6: LUC emissions | Q6: Feed processing | R6: Feed transports | S6: Enteric fermentation | T6: Manure management - tot | U6: Manure management - direct | V6: Manure management - indirect | W6: Energy use in stables | X6: Energy use for slaughter | Z6: Total feed, incl LUC | AA6: Feed mix emissions, kg CO2 per kg feed, excl. adjustement manure
A7: A01SP | B7: Chicken fresh meat | C7: Meat and meat products | D7: Austria | E7: AT | F7: CO2 | G7: =SUM(H7:X7) -> 0.86319394 | H7: ='CO2 per kg feed'!G17*FCR_bonefree_incl_parents_AT-Excreted_N_after_losses_AT*Manure_repl_factor_AT*(EF_min_fert_BAT_CO2*Frac_BAT_AT+EF_min_fert_AN_CO2*Frac_AN_AT) -> 0.130835 | I7: ='CO2 per kg feed'!H17*FCR_bonefree_incl_parents_AT -> 0.075059882 | J7: ='CO2 per kg feed'!I17*FCR_bonefree_incl_parents_AT -> 0 | L7: ='CO2 per kg feed'!K17*FCR_bonefree_incl_parents_AT -> 0.097086501 | N7: ='CO2 per kg feed'!M17*FCR_bonefree_incl_parents_AT -> 0.00010897754 | O7: ='CO2 per kg feed'!N17*FCR_bonefree_incl_parents_AT -> 0.10276169 | P7: ='CO2 per kg feed'!O17*FCR_bonefree_incl_parents_AT -> 0.10488857 | Q7: ='CO2 per kg feed'!P17*FCR_bonefree_incl_parents_AT -> 0.016583652 | R7: ='CO2 per kg feed'!Q17*FCR_bonefree_incl_parents_AT -> 0.09774859 | W7: =Energy_stables_AT/Bonefree_outof_CW_AT*(Share_heating_AT*(Share_biofuels_AT*EF_biofuels_CO2+(1-Share_biofuels_AT)*EF_oil_CO2)+(1-Share_heating_AT)*EF_el_CO2_AT) -> 0.08070981 | X7: =(Energy_slaughter_el_AT*EF_el_CO2_AT+Energy_slaughter_oil_AT*EF_oil_CO2)/Bonefree_outof_CW_AT -> 0.15741128
A8: A01SP | B8: Chicken fresh meat | C8: Meat and meat products | D8: Austria | E8: AT | F8: CH4, fossil | G8: =SUM(H8:X8) -> 0.0010944362 | H8: ='CH4 per kg feed'!G17*FCR_bonefree_incl_parents_AT-Excreted_N_after_losses_AT*Manure_repl_factor_AT*(EF_min_fert_BAT_CH4*Frac_BAT_AT+EF_min_fert_AN_CH4*Frac_AN_AT) -> 0.00014314288 | I8: ='CH4 per kg feed'!H17*FCR_bonefree_incl_parents_AT -> 0.00026409958 | L8: ='CH4 per kg feed'!K17*FCR_bonefree_incl_parents_AT -> 4.3006046e-05 | N8: ='CH4 per kg feed'!M17*FCR_bonefree_incl_parents_AT -> 3.6447126e-07 | O8: ='CH4 per kg feed'!N17*FCR_bonefree_incl_parents_AT -> 4.3299836e-05 | P8: ='CH4 per kg feed'!O17*FCR_bonefree_incl_parents_AT -> 0 | Q8: ='CH4 per kg feed'!P17*FCR_bonefree_incl_parents_AT -> 5.3403781e-05 | R8: ='CH4 per kg feed'!Q17*FCR_bonefree_incl_parents_AT -> 9.0202499e-05 | W8: =Energy_stables_AT/Bonefree_outof_CW_AT*(Share_heating_AT*(Share_biofuels_AT*EF_biofuel_CH4+(1-Share_biofuels_AT)*EF_oil_CH4)+(1-Share_heating_AT)*EF_el_CH4_AT) -> 9.034409e-05 | X8: =(Energy_slaughter_el_AT*EF_el_CH4_AT+Energy_slaughter_oil_AT*EF_oil_CH4)/Bonefree_outof_CW_AT -> 0.00036657298
A9: A01SP | B9: Chicken fresh meat | C9: Meat and meat products | D9: Austria | E9: AT | F9: CH4, biogenic | G9: =SUM(H9:T9)+SUM(W9:X9) -> 0.0022013861 | T9: =SUM(U9:V9) -> 0.0022013861 | U9: =(Production!B40*(Slaughter_age_AT/365)+SUM(Production!B41:B44))*EF_CH4_manure_AT -> 0.0022013861
A10: A01SP | B10: Chicken fresh meat | C10: Meat and meat products | D10: Austria | E10: AT | F10: N2O | G10: =SUM(H10:T10)+SUM(W10:X10) -> 0.0020293944 | H10: ='N2O per kg feed'!G17*FCR_bonefree_incl_parents_AT-Excreted_N_after_losses_AT*Manure_repl_factor_AT*(EF_min_fert_BAT_N2O*Frac_BAT_AT+EF_min_fert_AN_N2O*Frac_AN_AT) -> 0.00026048804 | I10: ='N2O per kg feed'!H17*FCR_bonefree_incl_parents_AT -> 3.0579952e-06 | J10: ='N2O per kg feed'!I17*FCR_bonefree_incl_parents_AT-Excreted_N_after_losses_AT*Manure_repl_factor_AT*EF_N2O_diff_AT -> 0.0014666535 | K10: =J10*EF_indirect_N2O_AT -> 0.00014666535 | L10: ='N2O per kg feed'!K17*FCR_bonefree_incl_parents_AT -> 2.6087521e-06 | N10: ='N2O per kg feed'!M17*FCR_bonefree_incl_parents_AT -> 4.4855073e-09 | O10: ='N2O per kg feed'!N17*FCR_bonefree_incl_parents_AT -> 3.4942022e-06 | P10: ='N2O per kg feed'!O17*FCR_bonefree_incl_parents_AT -> 0 | Q10: ='N2O per kg feed'!P17*FCR_bonefree_incl_parents_AT -> 5.3557563e-06 | R10: ='N2O per kg feed'!Q17*FCR_bonefree_incl_parents_AT -> 3.4308651e-06 | T10: =SUM(U10:V10) -> 0.00012390587 | U10: =Excreted_N_per_kg_of_bonefree_meat_AT*EF_N2O_manure_direct_AT*44/28 -> 4.5919976e-05 | V10: =(Excreted_N_per_kg_of_bonefree_meat_AT-U10*28/44)*EF_ammonia_AT*EF_N2O_manure_indirect_AT*44/28 -> 7.7985895e-05 | W10: =Energy_stables_AT/Bonefree_outof_CW_AT*(Share_heating_AT*(Share_biofuels_AT*EF_biofuel_N2O+(1-Share_biofuels_AT)*EF_oil_N2O)+(1-Share_heating_AT)*EF_el_N2O_AT) -> 5.9551818e-06 | X10: =(Energy_slaughter_el_AT*EF_el_N2O_AT+Energy_slaughter_oil_AT*EF_oil_N2O)/Bonefree_outof_CW_AT -> 7.7744143e-06
A11: A01SP | B11: Chicken fresh meat | C11: Meat and meat products | D11: Austria | E11: AT | F11: CO2e | G11: =SUM(H11:X11) -> 1.5092702 | H11: =SUMPRODUCT(H7:H10,'Parameters, general'!$B$13:$B$16) -> 0.20621389 | I11: =SUMPRODUCT(I7:I10,'Parameters, general'!$B$13:$B$16) -> 0.083764882 | J11: =SUMPRODUCT(J7:J10,'Parameters, general'!$B$13:$B$16) -> 0.4003964 | K11: =SUMPRODUCT(K7:K10,'Parameters, general'!$B$13:$B$16) -> 0.04003964 | L11: =SUMPRODUCT(L7:L10,'Parameters, general'!$B$13:$B$16) -> 0.099080271 | M11: =SUMPRODUCT(M7:M10,'Parameters, general'!$B$13:$B$16) -> 0 | N11: =SUMPRODUCT(N7:N10,'Parameters, general'!$B$13:$B$16) -> 0.00012106333 | O11: =SUMPRODUCT(O7:O10,'Parameters, general'!$B$13:$B$16) -> 0.10500594 | ... T11: =SUMPRODUCT(T7:T10,'Parameters, general'!$B$13:$B$16) -> 0.093263729 | W11: =SUMPRODUCT(W7:W10,'Parameters, general'!$B$13:$B$16) -> 0.085027828 | X11: =SUMPRODUCT(X7:X10,'Parameters, general'!$B$13:$B$16) -> 0.17045757 | Z11: =SUM(H11:R11) -> 1.1605211 | AA11: ='CO2 per kg feed'!F17+'CH4 per kg feed'!F17*CF_GWP_CH4_fossil+'N2O per kg feed'!F17*CF_GWP_N2O -> 0.39397499
A12: A01SP | B12: Chicken fresh meat | C12: Meat and meat products | D12: Belgium | E12: BE | F12: CO2 | G12: =SUM(H12:X12) -> 0.88800536 | H12: ='CO2 per kg feed'!G29*FCR_bonefree_incl_parents_BE-Excreted_N_after_losses_BE*Manure_repl_factor_BE*(EF_min_fert_BAT_CO2*Frac_BAT_BE+EF_min_fert_AN_CO2*Frac_AN_BE) -> 0.1123419 | I12: ='CO2 per kg feed'!H29*FCR_bonefree_incl_parents_BE -> 0.064985012 | J12: ='CO2 per kg feed'!I29*FCR_bonefree_incl_parents_BE -> 0 | L12: ='CO2 per kg feed'!K29*FCR_bonefree_incl_parents_BE -> 0.094632861 | N12: ='CO2 per kg feed'!M29*FCR_bonefree_incl_parents_BE -> 0.0001787247 | O12: ='CO2 per kg feed'!N29*FCR_bonefree_incl_parents_BE -> 0.094131804 | P12: ='CO2 per kg feed'!O29*FCR_bonefree_incl_parents_BE -> 0.15039507 | Q12: ='CO2 per kg feed'!P29*FCR_bonefree_incl_parents_BE -> 0.024886349 | R12: ='CO2 per kg feed'!Q29*FCR_bonefree_incl_parents_BE -> 0.14346438 | W12: =Energy_stables_BE/Bonefree_outof_CW_BE*(Share_heating_BE*(Share_biofuels_BE*EF_biofuels_CO2+(1-Share_biofuels_BE)*EF_oil_CO2)+(1-Share_heating_BE)*EF_el_CO2_BE) -> 0.07547741 | X12: =(Energy_slaughter_el_BE*EF_el_CO2_BE+Energy_slaughter_oil_BE*EF_oil_CO2)/Bonefree_outof_CW_BE -> 0.12751185
A13: A01SP | B13: Chicken fresh meat | C13: Meat and meat products | D13: Belgium | E13: BE | F13: CH4, fossil | G13: =SUM(H13:X13) -> 0.00092155385 | H13: ='CH4 per kg feed'!G29*FCR_bonefree_incl_parents_BE-Excreted_N_after_losses_BE*Manure_repl_factor_BE*(EF_min_fert_BAT_CH4*Frac_BAT_BE+EF_min_fert_AN_CH4*Frac_AN_BE) -> 0.00012643274 | I13: ='CH4 per kg feed'!H29*FCR_bonefree_incl_parents_BE -> 0.00022865097 | L13: ='CH4 per kg feed'!K29*FCR_bonefree_incl_parents_BE -> 4.1919167e-05 | N13: ='CH4 per kg feed'!M29*FCR_bonefree_incl_parents_BE -> 5.9773801e-07 | O13: ='CH4 per kg feed'!N29*FCR_bonefree_incl_parents_BE -> 4.4063929e-05 | P13: ='CH4 per kg feed'!O29*FCR_bonefree_incl_parents_BE -> 0 | Q13: ='CH4 per kg feed'!P29*FCR_bonefree_incl_parents_BE -> 7.8978335e-05 | R13: ='CH4 per kg feed'!Q29*FCR_bonefree_incl_parents_BE -> 0.00013397847 | W13: =Energy_stables_BE/Bonefree_outof_CW_BE*(Share_heating_BE*(Share_biofuels_BE*EF_biofuel_CH4+(1-Share_biofuels_BE)*EF_oil_CH4)+(1-Share_heating_BE)*EF_el_CH4_BE) -> 6.2048517e-05 | X13: =(Energy_slaughter_el_BE*EF_el_CH4_BE+Energy_slaughter_oil_BE*EF_oil_CH4)/Bonefree_outof_CW_BE -> 0.00020488399
A14: A01SP | B14: Chicken fresh meat | C14: Meat and meat products | D14: Belgium | E14: BE | F14: CH4, biogenic | G14: =SUM(H14:T14)+SUM(W14:X14) -> 0.0022013861 | T14: =SUM(U14:V14) -> 0.0022013861 | U14: =(Production!C40*(Slaughter_age_BE/365)+SUM(Production!C41:C44))*EF_CH4_manure_BE -> 0.0022013861
A15: A01SP | B15: Chicken fresh meat | C15: Meat and meat products | D15: Belgium | E15: BE | F15: N2O | G15: =SUM(H15:T15)+SUM(W15:X15) -> 0.0016894707 | H15: ='N2O per kg feed'!G29*FCR_bonefree_incl_parents_BE-Excreted_N_after_losses_BE*Manure_repl_factor_BE*(EF_min_fert_BAT_N2O*Frac_BAT_BE+EF_min_fert_AN_N2O*Frac_AN_BE) -> 0.00021401142 | I15: ='N2O per kg feed'!H29*FCR_bonefree_incl_parents_BE -> 2.6475375e-06 | J15: ='N2O per kg feed'!I29*FCR_bonefree_incl_parents_BE-Excreted_N_after_losses_BE*Manure_repl_factor_BE*EF_N2O_diff_BE -> 0.0011989662 | K15: =J15*EF_indirect_N2O_BE -> 0.00011989662 | L15: ='N2O per kg feed'!K29*FCR_bonefree_incl_parents_BE -> 2.5428219e-06 | N15: ='N2O per kg feed'!M29*FCR_bonefree_incl_parents_BE -> 7.3562952e-09 | O15: ='N2O per kg feed'!N29*FCR_bonefree_incl_parents_BE -> 3.2306694e-06 | P15: ='N2O per kg feed'!O29*FCR_bonefree_incl_parents_BE -> 0 | Q15: ='N2O per kg feed'!P29*FCR_bonefree_incl_parents_BE -> 7.8850902e-06 | R15: ='N2O per kg feed'!Q29*FCR_bonefree_incl_parents_BE -> 5.0150019e-06 | T15: =SUM(U15:V15) -> 0.00012390587 | U15: =Excreted_N_per_kg_of_bonefree_meat_BE*EF_N2O_manure_direct_BE*44/28 -> 4.5919976e-05 | V15: =(Excreted_N_per_kg_of_bonefree_meat_BE-U15*28/44)*EF_ammonia_BE*EF_N2O_manure_indirect_BE*44/28 -> 7.7985895e-05 | W15: =Energy_stables_BE/Bonefree_outof_CW_BE*(Share_heating_BE*(Share_biofuels_BE*EF_biofuel_N2O+(1-Share_biofuels_BE)*EF_oil_N2O)+(1-Share_heating_BE)*EF_el_N2O_BE) -> 5.6025832e-06 | X15: =(Energy_slaughter_el_BE*EF_el_N2O_BE+Energy_slaughter_oil_BE*EF_oil_N2O)/Bonefree_outof_CW_BE -> 5.7595652e-06
A16: A01SP | B16: Chicken fresh meat | C16: Meat and meat products | D16: Belgium | E16: BE | F16: CO2e | G16: =SUM(H16:X16) -> 1.4361306 | H16: =SUMPRODUCT(H12:H15,'Parameters, general'!$B$13:$B$16) -> 0.17453471 | I16: =SUMPRODUCT(I12:I15,'Parameters, general'!$B$13:$B$16) -> 0.072521588 | J16: =SUMPRODUCT(J12:J15,'Parameters, general'!$B$13:$B$16) -> 0.32731777 | K16: =SUMPRODUCT(K12:K15,'Parameters, general'!$B$13:$B$16) -> 0.032731777 | L16: =SUMPRODUCT(L12:L15,'Parameters, general'!$B$13:$B$16) -> 0.096576243 | M16: =SUMPRODUCT(M12:M15,'Parameters, general'!$B$13:$B$16) -> 0 | N16: =SUMPRODUCT(N12:N15,'Parameters, general'!$B$13:$B$16) -> 0.00019854556 | O16: =SUMPRODUCT(O12:O15,'Parameters, general'!$B$13:$B$16) -> 0.096326882 | ... T16: =SUMPRODUCT(T12:T15,'Parameters, general'!$B$13:$B$16) -> 0.093263729 | W16: =SUMPRODUCT(W12:W15,'Parameters, general'!$B$13:$B$16) -> 0.078855961 | X16: =SUMPRODUCT(X12:X15,'Parameters, general'!$B$13:$B$16) -> 0.13518975 | Z16: =SUM(H16:R16) -> 1.1288212 | AA16: ='CO2 per kg feed'!F29+'CH4 per kg feed'!F29*CF_GWP_CH4_fossil+'N2O per kg feed'!F29*CF_GWP_N2O -> 0.38429788
