Workbook
Name Ability_to_perceive_handling: 'Parameters, general'!$B$20
Name Bonefree_outof_CW_AT: 'Parameters, country spec'!#REF!
Name Bonefree_outof_CW_BE: 'Parameters, country spec'!#REF!
Name Bonefree_outof_CW_BG: 'Parameters, country spec'!#REF!
Name Bonefree_outof_CW_BR: 'Parameters, country spec'!#REF!
Name Bonefree_outof_CW_CY: 'Parameters, country spec'!#REF!
Name Bonefree_outof_CW_CZ: 'Parameters, country spec'!#REF!
Name Bonefree_outof_CW_DE: 'Parameters, country spec'!$D$9
Name Bonefree_outof_CW_DK: 'Parameters, country spec'!$B$9
Name Bonefree_outof_CW_EE: 'Parameters, country spec'!#REF!
Name Bonefree_outof_CW_ES: 'Parameters, country spec'!$K$9
Name Bonefree_outof_CW_FI: 'Parameters, country spec'!#REF!
Name Bonefree_outof_CW_FR: 'Parameters, country spec'!$C$9
Name Bonefree_outof_CW_GB: 'Parameters, country spec'!$M$9
Name Bonefree_outof_CW_GR: 'Parameters, country spec'!$E$9
Name Bonefree_outof_CW_HR: 'Parameters, country spec'!#REF!
Name Bonefree_outof_CW_HU: 'Parameters, country spec'!$F$9
Name Bonefree_outof_CW_IE: 'Parameters, country spec'!$G$9
Name Bonefree_outof_CW_IT: 'Parameters, country spec'!$H$9
Name Bonefree_outof_CW_LT: 'Parameters, country spec'!#REF!
Name Bonefree_outof_CW_LV: 'Parameters, country spec'!#REF!
Name Bonefree_outof_CW_MT: 'Parameters, country spec'!#REF!
Name Bonefree_outof_CW_NL: 'Parameters, country spec'!$I$9
Name Bonefree_outof_CW_PL: 'Parameters, country spec'!$J$9
Name Bonefree_outof_CW_PT: 'Parameters, country spec'!#REF!
Name Bonefree_outof_CW_RO: 'Parameters, country spec'!#REF!
Name Bonefree_outof_CW_SE: 'Parameters, country spec'!$L$9
Name Bonefree_outof_CW_SI: 'Parameters, country spec'!#REF!
Name Bonefree_outof_CW_SK: 'Parameters, country spec'!#REF!
Name Bonefree_outof_CW_TH: 'Parameters, country spec'!#REF!
Name Bonefree_outof_CW_US: 'Parameters, country spec'!#REF!
Name CF_biog_CH4: '[1]CF climate'!$C$5
Name CF_fossil_CH4: '[1]CF climate'!$D$5
Name CF_GWP_CH4_fossil: 'Parameters, general'!$B$15
Name CF_GWP_N2O: 'Parameters, general'!$B$17
Name CF_N2O: '[1]CF climate'!$E$5
Name CH4_bio_codes: '[1]Crops CH4, bio'!$A$6:$A$118
Name CH4_bio_data: '[1]Crops CH4, bio'!$E$6:$N$118
Name CH4_codes: '[1]Crops CH4, fossil'!$A$6:$A$118
Name CH4_data: '[1]Crops CH4, fossil'!$E$6:$N$118
Name CO2_codes: '[1]Crops CO2'!$A$6:$A$118
Name CO2_data: '[1]Crops CO2'!$E$6:$N$118
Name Crop_data: '[1]Crops, input data per ha'!$A$6:$Z$118
Name Crop_data_codes: '[1]Crops, input data per ha'!$A$6:$A$118
Name CY: 'Parameters, country spec'!#REF!
Name EF_ammonia_AT: 'Parameters, country spec'!#REF!
Name EF_ammonia_BE: 'Parameters, country spec'!#REF!
Name EF_ammonia_BG: 'Parameters, country spec'!#REF!
Name EF_ammonia_BR: 'Parameters, country spec'!#REF!
Name EF_ammonia_CY: 'Parameters, country spec'!#REF!
Name EF_ammonia_CZ: 'Parameters, country spec'!#REF!
Name EF_ammonia_DE: 'Parameters, country spec'!$D$42
Name EF_ammonia_DK: 'Parameters, country spec'!$B$42
Name EF_ammonia_EE: 'Parameters, country spec'!#REF!
Name EF_ammonia_ES: 'Parameters, country spec'!$K$42
Name EF_ammonia_FI: 'Parameters, country spec'!#REF!
Name EF_ammonia_FR: 'Parameters, country spec'!$C$42
Name EF_ammonia_GB: 'Parameters, country spec'!$M$42
Name EF_ammonia_GR: 'Parameters, country spec'!$E$42
Name EF_ammonia_HR: 'Parameters, country spec'!#REF!

Sheet README
A2: Read me
A4: This is a file that contains the calculations of environmental footprints, labour requirements, animal welfare and use of antibiotics for chicken production.
A7: Assumptions:
A8: - All parent animals are also eaten
A9: - Impacts are allocated equally across flesh and offals
A13: Tab color codes:
B15: Results
B16: Sheets for input
B17: Intermediate calculations
B18: Figures
A20: Att göra:
A23: Se om det går att få ut en foderstat för denna från Frankrike https://productions-animales.org/article/view/5396
A24: Gödselemissioner från NIR - är det klart? Kolla med Ludvig
A25: Justera till landsspecifik energianvändning https://www.mdpi.com/2076-3417/12/4/2142
A26: Vattenanvändning per land - OBS att detta är för anv i stallar, inte foderodlingen

Sheet Figures
A2: Figures
A4: Greenhouse gas emission for bonefree chicken meat across countries, to farmgate including slaughter, no waste
A42: Lesschen:
J45: Order in this study: | L45: Order in Lesschen:
J47: Poland | L47: Netherlands
J48: UK | L48: Greece
J49: Netherlands | L49: Poland
J50: Denmark | L50: Germany
J51: Sweden | L51: Hungary
J52: Greece | L52: Ireland
J53: Germany | L53: UK
J54: Spain | L54: Denmark
J55: Ireland | L55: Italy
J56: France | L56: France
J57: Italy | L57: Spain
J58: Hungary | L58: Sweden
B71: Production of mineral fertilizer | C71: Production of capital goods | D71: Emissions from soil | E71: Diesel use field machinary | F71: Energy use for feed processing | G71: Land use change emissions | H71: Feed transports | I71: Enteric fermentation | J71: Manure management | K71: Energy use in stables | L71: Energy use for slaughter | M71: Tot
A72: Poland | B72: ='GHG detailed, results per kg'!H51 -> 0.23803531 | C72: ='GHG detailed, results per kg'!I51 -> 0.090380114 | D72: ='GHG detailed, results per kg'!J51+'GHG detailed, results per kg'!K51 -> 0.35702712 | E72: ='GHG detailed, results per kg'!L51+'GHG detailed, results per kg'!N51 -> 0.13266084 | F72: ='GHG detailed, results per kg'!O51 -> 0.15985879 | G72: ='GHG detailed, results per kg'!P51 -> 0.10943919 | H72: ='GHG detailed, results per kg'!R51 -> 0.09632315 | I72: ='GHG detailed, results per kg'!S51 -> 0 | J72: ='GHG detailed, results per kg'!T51 -> 0.1386938 | K72: ='GHG detailed, results per kg'!W51 -> 0.15074932 | L72: ='GHG detailed, results per kg'!X51 -> 0.54600896 | M72: =SUM(B72:L72) -> 2.0191766
A73: UK | B73: ='GHG detailed, results per kg'!H66 -> 0.28892789 | C73: ='GHG detailed, results per kg'!I66 -> 0.09015126 | D73: ='GHG detailed, results per kg'!J66+'GHG detailed, results per kg'!K66 -> 0.46015496 | E73: ='GHG detailed, results per kg'!L66+'GHG detailed, results per kg'!N66 -> 0.10133222 | F73: ='GHG detailed, results per kg'!O66 -> 0.12778529 | G73: ='GHG detailed, results per kg'!P66 -> 0.19408949 | H73: ='GHG detailed, results per kg'!R66 -> 0.17830096 | I73: ='GHG detailed, results per kg'!S66 -> 0 | J73: ='GHG detailed, results per kg'!T66 -> 0.093263729 | K73: ='GHG detailed, results per kg'!W66 -> 0.094238727 | L73: ='GHG detailed, results per kg'!X66 -> 0.22309127 | M73: =SUM(B73:L73) -> 1.8513358
A74: Netherlands | B74: ='GHG detailed, results per kg'!H46 -> 0.18889798 | C74: ='GHG detailed, results per kg'!I46 -> 0.088547668 | D74: ='GHG detailed, results per kg'!J46+'GHG detailed, results per kg'!K46 -> 0.38352742 | E74: ='GHG detailed, results per kg'!L46+'GHG detailed, results per kg'!N46 -> 0.098272513 | F74: ='GHG detailed, results per kg'!O46 -> 0.13182431 | G74: ='GHG detailed, results per kg'!P46 -> 0.16580919 | H74: ='GHG detailed, results per kg'!R46 -> 0.16108315 | I74: ='GHG detailed, results per kg'!S46 -> 0 | J74: ='GHG detailed, results per kg'!T46 -> 0.1510445 | K74: ='GHG detailed, results per kg'!W46 -> 0.10486037 | L74: ='GHG detailed, results per kg'!X46 -> 0.28378637 | M74: =SUM(B74:L74) -> 1.7576535
A75: Denmark | B75: ='GHG detailed, results per kg'!H11 -> 0.24971371 | C75: ='GHG detailed, results per kg'!I11 -> 0.090853563 | D75: ='GHG detailed, results per kg'!J11+'GHG detailed, results per kg'!K11 -> 0.48955719 | E75: ='GHG detailed, results per kg'!L11+'GHG detailed, results per kg'!N11 -> 0.099457169 | F75: ='GHG detailed, results per kg'!O11 -> 0.12602944 | G75: ='GHG detailed, results per kg'!P11 -> 0.11199554 | H75: ='GHG detailed, results per kg'!R11 -> 0.10108349 | I75: ='GHG detailed, results per kg'!S11 -> 0 | J75: ='GHG detailed, results per kg'!T11 -> 0.093263729 | K75: ='GHG detailed, results per kg'!W11 -> 0.092086077 | L75: ='GHG detailed, results per kg'!X11 -> 0.21079041 | M75: =SUM(B75:L75) -> 1.6648303
A76: Sweden | B76: ='GHG detailed, results per kg'!H61 -> 0.25129264 | C76: ='GHG detailed, results per kg'!I61 -> 0.092035735 | D76: ='GHG detailed, results per kg'!J61+'GHG detailed, results per kg'!#REF! -> #REF! | E76: ='GHG detailed, results per kg'!L61+'GHG detailed, results per kg'!N61 -> 0.11182227 | F76: ='GHG detailed, results per kg'!O61 -> 0.11472904 | G76: ='GHG detailed, results per kg'!P61 -> 0.19366753 | H76: ='GHG detailed, results per kg'!R61 -> 0.17244619 | I76: ='GHG detailed, results per kg'!S61 -> 0 | J76: ='GHG detailed, results per kg'!T61 -> 0.093263729 | K76: ='GHG detailed, results per kg'!W61 -> 0.065053683 | L76: ='GHG detailed, results per kg'!X61 -> 0.056319595 | M76: =SUM(B76:L76) -> #REF!
A77: Greece | B77: ='GHG detailed, results per kg'!H26 -> 0.12850413 | C77: ='GHG detailed, results per kg'!I26 -> 0.081097112 | D77: ='GHG detailed, results per kg'!J26+'GHG detailed, results per kg'!K26 -> 0.11730113 | E77: ='GHG detailed, results per kg'!L26+'GHG detailed, results per kg'!N26 -> 0.15210488 | F77: ='GHG detailed, results per kg'!O26 -> 0.12393547 | G77: ='GHG detailed, results per kg'!P26 -> 0.21074569 | H77: ='GHG detailed, results per kg'!R26 -> 0.17453023 | I77: ='GHG detailed, results per kg'!S26 -> 0 | J77: ='GHG detailed, results per kg'!T26 -> 0.14380684 | K77: ='GHG detailed, results per kg'!W26 -> 0.11871036 | L77: ='GHG detailed, results per kg'!X26 -> 0.3629292 | M77: =SUM(B77:L77) -> 1.613665
A78: Germany | B78: ='GHG detailed, results per kg'!H21 -> 0.22779948 | C78: ='GHG detailed, results per kg'!I21 -> 0.090347174 | D78: ='GHG detailed, results per kg'!J21+'GHG detailed, results per kg'!K21 -> 0.34558455 | E78: ='GHG detailed, results per kg'!L21+'GHG detailed, results per kg'!N21 -> 0.090175519 | F78: ='GHG detailed, results per kg'!O21 -> 0.13396724 | G78: ='GHG detailed, results per kg'!P21 -> 0.094471241 | H78: ='GHG detailed, results per kg'!R21 -> 0.097794323 | I78: ='GHG detailed, results per kg'!S1 -> 0 | J78: ='GHG detailed, results per kg'!T21 -> 0.16129506 | K78: ='GHG detailed, results per kg'!W21 -> 0.10159751 | L78: ='GHG detailed, results per kg'!X21 -> 0.26514147 | M78: =SUM(B78:L78) -> 1.6081736
A79: Spain | B79: ='GHG detailed, results per kg'!H56 -> 0.16629826 | C79: ='GHG detailed, results per kg'!I56 -> 0.091990033 | D79: ='GHG detailed, results per kg'!J56+'GHG detailed, results per kg'!K56 -> 0.22550367 | E79: ='GHG detailed, results per kg'!L56+'GHG detailed, results per kg'!N56 -> 0.17747389 | F79: ='GHG detailed, results per kg'!O56 -> 0.12052009 | G79: ='GHG detailed, results per kg'!P56 -> 0.17947456 | H79: ='GHG detailed, results per kg'!R56 -> 0.15094581 | I79: ='GHG detailed, results per kg'!S56 -> 0 | J79: ='GHG detailed, results per kg'!T56 -> 0.1506608 | K79: ='GHG detailed, results per kg'!W56 -> 0.083464271 | L79: ='GHG detailed, results per kg'!X56 -> 0.16152295 | M79: =SUM(B79:L79) -> 1.5078543
A80: Ireland | B80: ='GHG detailed, results per kg'!H36 -> 0.12006494 | C80: ='GHG detailed, results per kg'!I36 -> 0.069390558 | D80: ='GHG detailed, results per kg'!J36+'GHG detailed, results per kg'!K36 -> 0.29117875 | E80: ='GHG detailed, results per kg'!L36+'GHG detailed, results per kg'!N36 -> 0.075023333 | F80: ='GHG detailed, results per kg'!O36 -> 0.10049496 | G80: ='GHG detailed, results per kg'!P36 -> 0.14537906 | H80: ='GHG detailed, results per kg'!R36 -> 0.13484734 | I80: ='GHG detailed, results per kg'!S36 -> 0 | J80: ='GHG detailed, results per kg'!T36 -> 0.12361808 | K80: ='GHG detailed, results per kg'!W36 -> 0.093669772 | L80: ='GHG detailed, results per kg'!X36 -> 0.2198401 | M80: =SUM(B80:L80) -> 1.3735069
A81: France | B81: ='GHG detailed, results per kg'!H16 -> 0.25670205 | C81: ='GHG detailed, results per kg'!I16 -> 0.084528256 | D81: ='GHG detailed, results per kg'!J16+'GHG detailed, results per kg'!K16 -> 0.34183843 | E81: ='GHG detailed, results per kg'!L16+'GHG detailed, results per kg'!N16 -> 0.093381308 | F81: ='GHG detailed, results per kg'!O16 -> 0.10830226 | G81: ='GHG detailed, results per kg'!P16 -> 0.091730991 | H81: ='GHG detailed, results per kg'!R16 -> 0.096283526 | I81: ='GHG detailed, results per kg'!S16 -> 0 | J81: ='GHG detailed, results per kg'!T16 -> 0.11017856 | K81: ='GHG detailed, results per kg'!W16 -> 0.065397296 | L81: ='GHG detailed, results per kg'!X16 -> 0.058283097 | M81: =SUM(B81:L81) -> 1.3066258
A82: Italy | B82: ='GHG detailed, results per kg'!H41 -> 0.20126111 | C82: ='GHG detailed, results per kg'!I41 -> 0.083040166 | D82: ='GHG detailed, results per kg'!J41+'GHG detailed, results per kg'!K41 -> 0.13646328 | E82: ='GHG detailed, results per kg'!L41+'GHG detailed, results per kg'!N41 -> 0.11065477 | F82: ='GHG detailed, results per kg'!O41 -> 0.11751804 | G82: ='GHG detailed, results per kg'!P41 -> 0.12172101 | H82: ='GHG detailed, results per kg'!R41 -> 0.10263629 | I82: ='GHG detailed, results per kg'!S41 -> 0 | J82: ='GHG detailed, results per kg'!T41 -> 0.10084615 | K82: ='GHG detailed, results per kg'!W41 -> 0.095764816 | L82: ='GHG detailed, results per kg'!X41 -> 0.23181178 | M82: =SUM(B82:L82) -> 1.3017174
A83: Hungary | B83: ='GHG detailed, results per kg'!H31 -> 0.19919809 | C83: ='GHG detailed, results per kg'!I31 -> 0.088757377 | D83: ='GHG detailed, results per kg'!J31+'GHG detailed, results per kg'!K31 -> 0.12819491 | E83: ='GHG detailed, results per kg'!L31+'GHG detailed, results per kg'!N31 -> 0.10101657 | F83: ='GHG detailed, results per kg'!O31 -> 0.12688013 | G83: ='GHG detailed, results per kg'!P31 -> 0.10270074 | H83: ='GHG detailed, results per kg'!R31 -> 0.084100047 | I83: ='GHG detailed, results per kg'!S31 -> 0 | J83: ='GHG detailed, results per kg'!T31 -> 0.11443727 | K83: ='GHG detailed, results per kg'!W31 -> 0.099655029 | L83: ='GHG detailed, results per kg'!X31 -> 0.25404157 | M83: =SUM(B83:L83) -> 1.2989817

Sheet Footprints, results per kg
A2: Footprints (per kg of bonefree meat) | M2: * Adjusted for manure
A5: Animal products | F5: Climate | L5: Land | M5: Nitrogen* | N5: Phosphorus | O5: Water | P5: Pesticides | Q5: Biodiversity | R5: Ammonia | S5: Labour | T5: Animal welfare | U5: Use of antibiotics
A6: Code | B6: Name | C6: Category | D6: Country | E6: Country code | F6: Carbon footprint, kg CO2e/kg | G6: Carbon dioxide, kg CO2/kg | H6: Methane, fossil, kg CH4/kg | I6: Methane, biogenic, kg CH4/kg | J6: Nitrous oxide, kg N2O/kg | K6: HFCs, kg HFCs/kg | L6: Cropland use, m2/kg | M6: New N input, kg N/kg | N6: New P input, kg P/kg | O6: Blue freshwater use, m3/kg | P6: Pesticide use, g a.i./kg | Q6: Extinction rate, E/MSY/kg | R6: Ammonia emission, kg NH3/kg | S6: Labour requirements, h/kg | T6: Animal welfare index per kg of bonefree meat
A7: 21121 | B7: Chicken meat | C7: White meat | D7: Denmark | E7: DK | F7: ='GHG detailed, results per kg'!G11 -> 1.6832501 | G7: ='GHG detailed, results per kg'!G7 -> 0.96979988 | H7: ='GHG detailed, results per kg'!G8 -> 0.0011031151 | I7: ='GHG detailed, results per kg'!G9 -> 0.0022013861 | J7: ='GHG detailed, results per kg'!G10 -> 0.0022752379 | L7: ='EFP per kg feed'!F17*FCR_bonefree_incl_parents_DK -> 5.5056842 | M7: ='EFP per kg feed'!G17*FCR_bonefree_incl_parents_DK-Manure_repl_factor_DK*Excreted_N_after_losses_DK -> 0.06802495 | N7: ='EFP per kg feed'!H17*FCR_bonefree_incl_parents_DK -> 0.009368177 | O7: ='EFP per kg feed'!I17*FCR_bonefree_incl_parents_DK+Water_stables_DK/Bonefree_outof_CW_DK -> 0.021950283 | P7: ='EFP per kg feed'!J17*FCR_bonefree_incl_parents_DK -> 0.74850462 | Q7: ='EFP per kg feed'!K17*FCR_bonefree_incl_parents_DK -> 4.6901396e-10 | R7: ='EFP per kg feed'!L17*FCR_bonefree_incl_parents_DK+Excreted_N_after_losses_DK -> 0.032019301 | S7: =Production!B52*Labour_per_animal_DK -> 0.062164334 | T7: 70.37812 | U7: 19.4
A8: 21121 | B8: Chicken meat | C8: White meat | D8: France | E8: FR | F8: ='GHG detailed, results per kg'!G16 -> 1.3265143 | G8: ='GHG detailed, results per kg'!G12 -> 0.7460333 | H8: ='GHG detailed, results per kg'!G13 -> 0.0010169099 | I8: ='GHG detailed, results per kg'!G14 -> 0.0022548527 | J8: ='GHG detailed, results per kg'!G15 -> 0.0017922933 | L8: ='EFP per kg feed'!F29*FCR_bonefree_incl_parents_FR -> 4.7229561 | M8: ='EFP per kg feed'!G29*FCR_bonefree_incl_parents_FR-Manure_repl_factor_FR*Excreted_N_after_losses_FR -> 0.058493449 | N8: ='EFP per kg feed'!H29*FCR_bonefree_incl_parents_FR -> 0.010741997 | O8: ='EFP per kg feed'!I29*FCR_bonefree_incl_parents_FR+Water_stables_FR/Bonefree_outof_CW_FR -> 0.089587279 | P8: ='EFP per kg feed'!J29*FCR_bonefree_incl_parents_FR -> 0.7010948 | Q8: ='EFP per kg feed'!K29*FCR_bonefree_incl_parents_FR -> 1.3831994e-09 | R8: ='EFP per kg feed'!L29*FCR_bonefree_incl_parents_FR+Excreted_N_after_losses_FR -> 0.045473608 | S8: =Production!C52*Labour_per_animal_FR -> 0.094548198 | T8: 76.86855 | U8: 38.1
A9: 21121 | B9: Chicken meat | C9: White meat | D9: Germany | E9: DE | F9: ='GHG detailed, results per kg'!G21 -> 1.6281702 | G9: ='GHG detailed, results per kg'!G17 -> 0.98916343 | H9: ='GHG detailed, results per kg'!G18 -> 0.0014032805 | I9: ='GHG detailed, results per kg'!G19 -> 0.0033020792 | J9: ='GHG detailed, results per kg'!G20 -> 0.0018609264 | L9: ='EFP per kg feed'!F41*FCR_bonefree_incl_parents_DE -> 4.7692643 | M9: ='EFP per kg feed'!G41*FCR_bonefree_incl_parents_DE-Manure_repl_factor_DE*Excreted_N_after_losses_DE -> 0.05299851 | N9: ='EFP per kg feed'!H41*FCR_bonefree_incl_parents_DE -> 0.010613089 | O9: ='EFP per kg feed'!I41*FCR_bonefree_incl_parents_DE+Water_stables_DE/Bonefree_outof_CW_DE -> 0.015870449 | P9: ='EFP per kg feed'!J41*FCR_bonefree_incl_parents_DE -> 1.2965167 | Q9: ='EFP per kg feed'!K41*FCR_bonefree_incl_parents_DE -> 3.6072017e-10 | R9: ='EFP per kg feed'!L41*FCR_bonefree_incl_parents_DE+Excreted_N_after_losses_DE -> 0.065457899 | S9: =Production!D52*Labour_per_animal_DE -> 0.10613423 | T9: 67.939375 | U9: 50.4
A10: 21121 | B10: Chicken meat | C10: White meat | D10: Greece | E10: GR | F10: ='GHG detailed, results per kg'!G26 -> 1.6420556 | G10: ='GHG detailed, results per kg'!G22 -> 1.2701078 | H10: ='GHG detailed, results per kg'!G23 -> 0.0017458147 | I10: ='GHG detailed, results per kg'!G24 -> 0.0033020792 | J10: ='GHG detailed, results per kg'!G25 -> 0.00084529818 | L10: ='EFP per kg feed'!F42*FCR_bonefree_incl_parents_GR -> 11.530704 | M10: ='EFP per kg feed'!G42*FCR_bonefree_incl_parents_GR-Manure_repl_factor_GR*Excreted_N_after_losses_GR -> 0.045724947 | N10: ='EFP per kg feed'!H42*FCR_bonefree_incl_parents_GR -> 0.010154881 | O10: ='EFP per kg feed'!I42*FCR_bonefree_incl_parents_GR+Water_stables_GR/Bonefree_outof_CW_GR -> 0.012987013 | P10: ='EFP per kg feed'!J42*FCR_bonefree_incl_parents_GR -> 0.52412289 | Q10: ='EFP per kg feed'!K42*FCR_bonefree_incl_parents_GR -> 1.9032212e-08 | R10: ='EFP per kg feed'!L42*FCR_bonefree_incl_parents_GR+Excreted_N_after_losses_GR -> 0.050227074 | S10: =Production!E52*Labour_per_animal_GR -> 0.069745351 | T10: 76.426602 | U10: 111.7
A11: 21121 | B11: Chicken meat | C11: White meat | D11: Hungary | E11: HU | F11: ='GHG detailed, results per kg'!G31 -> 1.3128138 | G11: ='GHG detailed, results per kg'!G27 -> 0.94482381 | H11: ='GHG detailed, results per kg'!G28 -> 0.0014900731 | I11: ='GHG detailed, results per kg'!G29 -> 0.0022013861 | J11: ='GHG detailed, results per kg'!G30 -> 0.0009675764 | L11: ='EFP per kg feed'!F65*FCR_bonefree_incl_parents_HU -> 5.4437521 | M11: ='EFP per kg feed'!G65*FCR_bonefree_incl_parents_HU-Manure_repl_factor_HU*Excreted_N_after_losses_HU -> 0.046445615 | N11: ='EFP per kg feed'!H65*FCR_bonefree_incl_parents_HU -> 0.013406362 | O11: ='EFP per kg feed'!I65*FCR_bonefree_incl_parents_HU+Water_stables_HU/Bonefree_outof_CW_HU -> 0.024492772 | P11: ='EFP per kg feed'!J65*FCR_bonefree_incl_parents_HU -> 0.48488616 | Q11: ='EFP per kg feed'!K65*FCR_bonefree_incl_parents_HU -> 3.8941156e-10 | R11: ='EFP per kg feed'!L65*FCR_bonefree_incl_parents_HU+Excreted_N_after_losses_HU -> 0.049707416 | S11: =Production!F52*Labour_per_animal_HU -> 0.30475686 | T11: 76.413841 | U11: 102.5
A12: 21121 | B12: Chicken meat | C12: White meat | D12: Ireland | E12: IE | F12: ='GHG detailed, results per kg'!G36 -> 1.3987103 | G12: ='GHG detailed, results per kg'!G32 -> 0.90510556 | H12: ='GHG detailed, results per kg'!G33 -> 0.00092381804 | I12: ='GHG detailed, results per kg'!G34 -> 0.0023114555 | J12: ='GHG detailed, results per kg'!G35 -> 0.0014786289 | L12: ='EFP per kg feed'!F77*FCR_bonefree_incl_parents_IE -> 4.0873594 | M12: ='EFP per kg feed'!G77*FCR_bonefree_incl_parents_IE-Manure_repl_factor_IE*Excreted_N_after_losses_IE -> 0.04409976 | N12: ='EFP per kg feed'!H77*FCR_bonefree_incl_parents_IE -> 0.0078240708 | O12: ='EFP per kg feed'!I77*FCR_bonefree_incl_parents_IE+Water_stables_IE/Bonefree_outof_CW_IE -> 0.014883424 | P12: ='EFP per kg feed'!J77*FCR_bonefree_incl_parents_IE -> 0.99114394 | Q12: ='EFP per kg feed'!K77*FCR_bonefree_incl_parents_IE -> 4.4076574e-10 | R12: ='EFP per kg feed'!L77*FCR_bonefree_incl_parents_IE+Excreted_N_after_losses_IE -> 0.054695165 | S12: =Production!G52*Labour_per_animal_IE -> 0.20317124 | T12: 76.426602 | U12: 40.6
A13: 21121 | B13: Chicken meat | C13: White meat | D13: Italy | E13: IT | F13: ='GHG detailed, results per kg'!G41 -> 1.3184303 | G13: ='GHG detailed, results per kg'!G37 -> 0.94113879 | H13: ='GHG detailed, results per kg'!G38 -> 0.0019482909 | I13: ='GHG detailed, results per kg'!G39 -> 0.0022013861 | J13: ='GHG detailed, results per kg'!G40 -> 0.00095162992 | L13: ='EFP per kg feed'!F89*FCR_bonefree_incl_parents_IT -> 5.1818383 | M13: ='EFP per kg feed'!G89*FCR_bonefree_incl_parents_IT-Manure_repl_factor_IT*Excreted_N_after_losses_IT -> 0.051948917 | N13: ='EFP per kg feed'!H89*FCR_bonefree_incl_parents_IT -> 0.012513637 | O13: ='EFP per kg feed'!I89*FCR_bonefree_incl_parents_IT+Water_stables_IT/Bonefree_outof_CW_IT -> 0.19261166 | P13: ='EFP per kg feed'!J89*FCR_bonefree_incl_parents_IT -> 0.59106668 | Q13: ='EFP per kg feed'!K89*FCR_bonefree_incl_parents_IT -> 4.9457643e-09 | R13: ='EFP per kg feed'!L89*FCR_bonefree_incl_parents_IT+Excreted_N_after_losses_IT -> 0.037695122 | S13: =Production!H52*Labour_per_animal_IT -> 0.098553213 | T13: 76.426602 | U13: 129.1
A14: 21121 | B14: Chicken meat | C14: White meat | D14: Netherlands | E14: NL | F14: ='GHG detailed, results per kg'!G46 -> 1.7895472 | G14: ='GHG detailed, results per kg'!G42 -> 1.1319672 | H14: ='GHG detailed, results per kg'!G43 -> 0.0015856929 | I14: ='GHG detailed, results per kg'!G44 -> 0.0031693198 | J14: ='GHG detailed, results per kg'!G45 -> 0.0019221784 | L14: ='EFP per kg feed'!F101*FCR_bonefree_incl_parents_NL -> 5.1252606 | M14: ='EFP per kg feed'!G101*FCR_bonefree_incl_parents_NL-Manure_repl_factor_NL*Excreted_N_after_losses_NL -> 0.061582344 | N14: ='EFP per kg feed'!H101*FCR_bonefree_incl_parents_NL -> 0.011515637 | O14: ='EFP per kg feed'!I101*FCR_bonefree_incl_parents_NL+Water_stables_NL/Bonefree_outof_CW_NL -> 0.027587863 | P14: ='EFP per kg feed'!J101*FCR_bonefree_incl_parents_NL -> 1.4322929 | Q14: ='EFP per kg feed'!K101*FCR_bonefree_incl_parents_NL -> 5.2214194e-10 | R14: ='EFP per kg feed'!L101*FCR_bonefree_incl_parents_NL+Excreted_N_after_losses_NL -> 0.059299832 | S14: =Production!I52*Labour_per_animal_NL -> 0.12736108 | T14: 75.375612 | U14: 32.1
A15: 21121 | B15: Chicken meat | C15: White meat | D15: Poland | E15: PL | F15: ='GHG detailed, results per kg'!G51 -> 2.0362177 | G15: ='GHG detailed, results per kg'!G47 -> 1.3816965 | H15: ='GHG detailed, results per kg'!G48 -> 0.0021239649 | I15: ='GHG detailed, results per kg'!G49 -> 0.0033020792 | J15: ='GHG detailed, results per kg'!G50 -> 0.0018390874 | L15: ='EFP per kg feed'!F113*FCR_bonefree_incl_parents_PL -> 7.0510223 | M15: ='EFP per kg feed'!G113*FCR_bonefree_incl_parents_PL-Manure_repl_factor_PL*Excreted_N_after_losses_PL -> 0.055335453 | N15: ='EFP per kg feed'!H113*FCR_bonefree_incl_parents_PL -> 0.010506687 | O15: ='EFP per kg feed'!I113*FCR_bonefree_incl_parents_PL+Water_stables_PL/Bonefree_outof_CW_PL -> 0.017549218 | P15: ='EFP per kg feed'!J113*FCR_bonefree_incl_parents_PL -> 0.68914629 | Q15: ='EFP per kg feed'!K113*FCR_bonefree_incl_parents_PL -> 5.148248e-10 | R15: ='EFP per kg feed'!L113*FCR_bonefree_incl_parents_PL+Excreted_N_after_losses_PL -> 0.045305435 | S15: =Production!J52*Labour_per_animal_PL -> 0.32143509 | T15: 76.413841 | U15: 134.7
A16: 21121 | B16: Chicken meat | C16: White meat | D16: Spain | E16: ES | F16: ='GHG detailed, results per kg'!G56 -> 1.5335329 | G16: ='GHG detailed, results per kg'!G52 -> 1.0417051 | H16: ='GHG detailed, results per kg'!G53 -> 0.0015090295 | I16: ='GHG detailed, results per kg'!G54 -> 0.0029891817 | J16: ='GHG detailed, results per kg'!G55 -> 0.001341212 | L16: ='EFP per kg feed'!F125*FCR_bonefree_incl_parents_ES -> 7.5137079 | M16: ='EFP per kg feed'!G125*FCR_bonefree_incl_parents_ES-Manure_repl_factor_ES*Excreted_N_after_losses_ES -> 0.05232145 | N16: ='EFP per kg feed'!H125*FCR_bonefree_incl_parents_ES -> 0.011865135 | O16: ='EFP per kg feed'!I125*FCR_bonefree_incl_parents_ES+Water_stables_ES/Bonefree_outof_CW_ES -> 0.65893968 | P16: ='EFP per kg feed'!J125*FCR_bonefree_incl_parents_ES -> 0.52449158 | Q16: ='EFP per kg feed'!K125*FCR_bonefree_incl_parents_ES -> 1.1939788e-08 | R16: ='EFP per kg feed'!L125*FCR_bonefree_incl_parents_ES+Excreted_N_after_losses_ES -> 0.062712675 | S16: =Production!K52*Labour_per_animal_ES -> 0.030324066 | T16: 76.413841 | U16: 95.7
A17: 21121 | B17: Chicken meat | C17: White meat | D17: Sweden | E17: SE | F17: ='GHG detailed, results per kg'!G61 -> 1.6703778 | G17: ='GHG detailed, results per kg'!G57 -> 0.96137293 | H17: ='GHG detailed, results per kg'!G58 -> 0.00096050214 | I17: ='GHG detailed, results per kg'!G59 -> 0.0022013861 | J17: ='GHG detailed, results per kg'!G60 -> 0.002274522 | L17: ='EFP per kg feed'!F137*FCR_bonefree_incl_parents_SE -> 6.0474278 | M17: ='EFP per kg feed'!G137*FCR_bonefree_incl_parents_SE-Manure_repl_factor_SE*Excreted_N_after_losses_SE -> 0.078367539 | N17: ='EFP per kg feed'!H137*FCR_bonefree_incl_parents_SE -> 0.0091283907 | O17: ='EFP per kg feed'!I137*FCR_bonefree_incl_parents_SE+Water_stables_SE/Bonefree_outof_CW_SE -> 0.015210233 | P17: ='EFP per kg feed'!J137*FCR_bonefree_incl_parents_SE -> 0.49994899 | Q17: ='EFP per kg feed'!K137*FCR_bonefree_incl_parents_SE -> 4.6739436e-10 | R17: ='EFP per kg feed'!L137*FCR_bonefree_incl_parents_SE+Excreted_N_after_losses_SE -> 0.032095317 | S17: =Production!L52*Labour_per_animal_SE -> 0.062164334 | T17: 60.503138 | U17: 10.1
A18: 21121 | B18: Chicken meat | C18: White meat | D18: UK | E18: GB | F18: ='GHG detailed, results per kg'!G66 -> 1.8847952 | G18: ='GHG detailed, results per kg'!G62 -> 1.1766977 | H18: ='GHG detailed, results per kg'!G63 -> 0.001406488 | I18: ='GHG detailed, results per kg'!G64 -> 0.0022013861 | J18: ='GHG detailed, results per kg'!G65 -> 0.0022225154 | L18: ='EFP per kg feed'!F149*FCR_bonefree_incl_parents_GB -> 5.7620019 | M18: ='EFP per kg feed'!G149*FCR_bonefree_incl_parents_GB-Manure_repl_factor_GB*Excreted_N_after_losses_GB -> 0.075136044 | N18: ='EFP per kg feed'!H149*FCR_bonefree_incl_parents_GB -> 0.0092824579 | O18: ='EFP per kg feed'!I149*FCR_bonefree_incl_parents_GB+Water_stables_GB/Bonefree_outof_CW_GB -> 0.016921113 | P18: ='EFP per kg feed'!J149*FCR_bonefree_incl_parents_GB -> 1.0742659 | Q18: ='EFP per kg feed'!K149*FCR_bonefree_incl_parents_GB -> 4.1401874e-09 | R18: ='EFP per kg feed'!L149*FCR_bonefree_incl_parents_GB+Excreted_N_after_losses_GB -> 0.031976318 | S18: =Production!M52*Labour_per_animal_GB -> 0.086423587 | T18: =T12 -> 76.426602 | U18: 29.8

Sheet GHG detailed, results per kg
H1: * Production of mineral fertiliser is adjusted to account for the N supplied by manure.
A2: GHG emissions (per kg of bonefree meat) | H2: ** Adjusted for use of manure instead of mineral fertiliser (lower emission factor for manure)
H3: *** Calculated as percentage of direct emissions due to assumption due to data limitations regarding nitrogen leaching and volatilization from soils in different regions.
S4: Animals | W4: Stables | X4: Slaughter | Z4: Control
A5: Animal products | G5: Sum | H5: Inputs | J5: Soil emissions | L5: Energy use | P5: Land use change | Q5: Feed processing | R5: Transports
A6: FoodEx code | B6: FoodEx name | C6: Food Ex category (L1) | D6: Country | E6: Country code | F6: Gas | G6: GHG | H6: Production of mineral fertilizer* | I6: Production of capital goods | J6: Direct emissions** | K6: Indirect emissions*** | L6: Diesel use field mach | M6: Energy use in greenhouses | N6: Energy use for irrigation | O6: Energy use for post-harvest proc | P6: LUC emissions | Q6: Feed processing | R6: Feed transports | S6: Enteric fermentation | T6: Manure management - tot | U6: Manure management - direct | V6: Manure management - indirect | W6: Energy use in stables | X6: Energy use for slaughter | Z6: Total feed, incl LUC | AA6: Feed mix emissions, kg CO2 per kg feed, excl. adjustement manure
A7: A01SP | B7: Chicken fresh meat | C7: Meat and meat products | D7: Denmark | E7: DK | F7: CO2 | G7: =SUM(H7:X7) -> 0.96979988 | H7: ='CO2 per kg feed'!G17*FCR_bonefree_incl_parents_DK-Excreted_N_after_losses_DK*Manure_repl_factor_DK*(EF_min_fert_BAT_CO2*Frac_BAT_DK+EF_min_fert_AN_CO2*Frac_AN_DK) -> 0.1558278 | I7: ='CO2 per kg feed'!H17*FCR_bonefree_incl_parents_DK -> 0.081035416 | J7: ='CO2 per kg feed'!I17*FCR_bonefree_incl_parents_DK -> 0 | L7: ='CO2 per kg feed'!K17*FCR_bonefree_incl_parents_DK -> 0.096796332 | N7: ='CO2 per kg feed'!M17*FCR_bonefree_incl_parents_DK -> 0.00044158907 | O7: ='CO2 per kg feed'!N17*FCR_bonefree_incl_parents_DK -> 0.12254514 | P7: ='CO2 per kg feed'!O17*FCR_bonefree_incl_parents_DK -> 0.11199554 | Q7: ='CO2 per kg feed'!P17*FCR_bonefree_incl_parents_DK -> 0.015422914 | R7: ='CO2 per kg feed'!Q17*FCR_bonefree_incl_parents_DK -> 0.097552273 | W7: =Energy_stables_DK/Bonefree_outof_CW_DK*(Share_heating_DK*(Share_biofuels_DK*EF_biofuels_CO2+(1-Share_biofuels_DK)*EF_oil_CO2)+(1-Share_heating_DK)*EF_el_CO2_DK) -> 0.088165821 | X7: =(Energy_slaughter_el_DK*EF_el_CO2_DK+Energy_slaughter_oil_DK*EF_oil_CO2)/Bonefree_outof_CW_DK -> 0.20001706
A8: A01SP | B8: Chicken fresh meat | C8: Meat and meat products | D8: Denmark | E8: DK | F8: CH4, fossil | G8: =SUM(H8:X8) -> 0.0011031151 | H8: ='CH4 per kg feed'!G17*FCR_bonefree_incl_parents_DK-Excreted_N_after_losses_DK*Manure_repl_factor_DK*(EF_min_fert_BAT_CH4*Frac_BAT_DK+EF_min_fert_AN_CH4*Frac_AN_DK) -> 0.00019891544 | I8: ='CH4 per kg feed'!H17*FCR_bonefree_incl_parents_DK -> 0.00030129717 | L8: ='CH4 per kg feed'!K17*FCR_bonefree_incl_parents_DK -> 4.4219941e-05 | N8: ='CH4 per kg feed'!M17*FCR_bonefree_incl_parents_DK -> 5.060731e-06 | O8: ='CH4 per kg feed'!N17*FCR_bonefree_incl_parents_DK -> 7.3304797e-05 | P8: ='CH4 per kg feed'!O17*FCR_bonefree_incl_parents_DK -> 0 | Q8: ='CH4 per kg feed'!P17*FCR_bonefree_incl_parents_DK -> 5.2062806e-05 | R8: ='CH4 per kg feed'!Q17*FCR_bonefree_incl_parents_DK -> 8.6743813e-05 | W8: =Energy_stables_DK/Bonefree_outof_CW_DK*(Share_heating_DK*(Share_biofuels_DK*EF_biofuel_CH4+(1-Share_biofuels_DK)*EF_oil_CH4)+(1-Share_heating_DK)*EF_el_CH4_DK) -> 7.3155856e-05 | X8: =(Energy_slaughter_el_DK*EF_el_CH4_DK+Energy_slaughter_oil_DK*EF_oil_CH4)/Bonefree_outof_CW_DK -> 0.0002683545
A9: A01SP | B9: Chicken fresh meat | C9: Meat and meat products | D9: Denmark | E9: DK | F9: CH4, biogenic | G9: =SUM(H9:T9)+SUM(W9:X9) -> 0.0022013861 | T9: =SUM(U9:V9) -> 0.0022013861 | U9: =(Production!B40*(Slaughter_age_DK/365)+SUM(Production!B41:B44))*EF_CH4_manure_DK -> 0.0022013861
A10: A01SP | B10: Chicken fresh meat | C10: Meat and meat products | D10: Denmark | E10: DK | F10: N2O | G10: =SUM(H10:T10)+SUM(W10:X10) -> 0.0022752379 | H10: ='N2O per kg feed'!G17*FCR_bonefree_incl_parents_DK-Excreted_N_after_losses_DK*Manure_repl_factor_DK*(EF_min_fert_BAT_N2O*Frac_BAT_DK+EF_min_fert_AN_N2O*Frac_AN_DK) -> 0.00032219133 | I10: ='N2O per kg feed'!H17*FCR_bonefree_incl_parents_DK -> 3.0750563e-06 | J10: ='N2O per kg feed'!I17*FCR_bonefree_incl_parents_DK-Excreted_N_after_losses_DK*Manure_repl_factor_DK*EF_N2O_diff_DK -> 0.0016302271 | K10: =J10*EF_indirect_N2O_DK -> 0.00016302271 | L10: ='N2O per kg feed'!K17*FCR_bonefree_incl_parents_DK -> 2.6876141e-06 | N10: ='N2O per kg feed'!M17*FCR_bonefree_incl_parents_DK -> 6.2144098e-08 | O10: ='N2O per kg feed'!N17*FCR_bonefree_incl_parents_DK -> 4.7612337e-06 | P10: ='N2O per kg feed'!O17*FCR_bonefree_incl_parents_DK -> 0 | Q10: ='N2O per kg feed'!P17*FCR_bonefree_incl_parents_DK -> 5.2944493e-06 | R10: ='N2O per kg feed'!Q17*FCR_bonefree_incl_parents_DK -> 3.4661158e-06 | T10: =SUM(U10:V10) -> 0.00012390587 | U10: =Excreted_N_per_kg_of_bonefree_meat_DK*EF_N2O_manure_direct_DK*44/28 -> 4.5919976e-05 | V10: =(Excreted_N_per_kg_of_bonefree_meat_DK-U10*28/44)*EF_ammonia_DK*EF_N2O_manure_indirect_DK*44/28 -> 7.7985895e-05 | W10: =Energy_stables_DK/Bonefree_outof_CW_DK*(Share_heating_DK*(Share_biofuels_DK*EF_biofuel_N2O+(1-Share_biofuels_DK)*EF_oil_N2O)+(1-Share_heating_DK)*EF_el_N2O_DK) -> 6.3743986e-06 | X10: =(Energy_slaughter_el_DK*EF_el_N2O_DK+Energy_slaughter_oil_DK*EF_oil_N2O)/Bonefree_outof_CW_DK -> 1.0169939e-05
A11: A01SP | B11: Chicken fresh meat | C11: Meat and meat products | D11: Denmark | E11: DK | F11: CO2e | G11: =SUM(H11:X11) -> 1.6832501 | H11: =SUMPRODUCT(H7:H10,'Parameters, general'!$B$14:$B$17) -> 0.24971371 | I11: =SUMPRODUCT(I7:I10,'Parameters, general'!$B$14:$B$17) -> 0.090853563 | J11: =SUMPRODUCT(J7:J10,'Parameters, general'!$B$14:$B$17) -> 0.44505199 | K11: =SUMPRODUCT(K7:K10,'Parameters, general'!$B$14:$B$17) -> 0.044505199 | L11: =SUMPRODUCT(L7:L10,'Parameters, general'!$B$14:$B$17) -> 0.098847804 | M11: =SUMPRODUCT(M7:M10,'Parameters, general'!$B$14:$B$17) -> 0 | N11: =SUMPRODUCT(N7:N10,'Parameters, general'!$B$14:$B$17) -> 0.0006093642 | O11: =SUMPRODUCT(O7:O10,'Parameters, general'!$B$14:$B$17) -> 0.12602944 | ... T11: =SUMPRODUCT(T7:T10,'Parameters, general'!$B$14:$B$17) -> 0.093263729 | W11: =SUMPRODUCT(W7:W10,'Parameters, general'!$B$14:$B$17) -> 0.092086077 | X11: =SUMPRODUCT(X7:X10,'Parameters, general'!$B$14:$B$17) -> 0.21079041 | Z11: =SUM(H11:R11) -> 1.2871099 | AA11: ='CO2 per kg feed'!F17+'CH4 per kg feed'!F17*CF_GWP_CH4_fossil+'N2O per kg feed'!F17*CF_GWP_N2O -> 0.42757257
A12: A01SP | B12: Chicken fresh meat | C12: Meat and meat products | D12: France | E12: FR | F12: CO2 | G12: =SUM(H12:X12) -> 0.7460333 | H12: ='CO2 per kg feed'!G29*FCR_bonefree_incl_parents_FR-Excreted_N_after_losses_FR*Manure_repl_factor_FR*(EF_min_fert_BAT_CO2*Frac_BAT_FR+EF_min_fert_AN_CO2*Frac_AN_FR) -> 0.15744981 | I12: ='CO2 per kg feed'!H29*FCR_bonefree_incl_parents_FR -> 0.075484001 | J12: ='CO2 per kg feed'!I29*FCR_bonefree_incl_parents_FR -> 0 | L12: ='CO2 per kg feed'!K29*FCR_bonefree_incl_parents_FR -> 0.085386586 | N12: ='CO2 per kg feed'!M29*FCR_bonefree_incl_parents_FR -> 0.0055928482 | O12: ='CO2 per kg feed'!N29*FCR_bonefree_incl_parents_FR -> 0.10551287 | P12: ='CO2 per kg feed'!O29*FCR_bonefree_incl_parents_FR -> 0.091730991 | Q12: ='CO2 per kg feed'!P29*FCR_bonefree_incl_parents_FR -> 0.016937198 | R12: ='CO2 per kg feed'!Q29*FCR_bonefree_incl_parents_FR -> 0.092752331 | W12: =Energy_stables_FR/Bonefree_outof_CW_FR*(Share_heating_FR*(Share_biofuels_FR*EF_biofuels_CO2+(1-Share_biofuels_FR)*EF_oil_CO2)+(1-Share_heating_FR)*EF_el_CO2_FR) -> 0.062400427 | X12: =(Energy_slaughter_el_FR*EF_el_CO2_FR+Energy_slaughter_oil_FR*EF_oil_CO2)/Bonefree_outof_CW_FR -> 0.052786231
A13: A01SP | B13: Chicken fresh meat | C13: Meat and meat products | D13: France | E13: FR | F13: CH4, fossil | G13: =SUM(H13:X13) -> 0.0010169099 | H13: ='CH4 per kg feed'!G29*FCR_bonefree_incl_parents_FR-Excreted_N_after_losses_FR*Manure_repl_factor_FR*(EF_min_fert_BAT_CH4*Frac_BAT_FR+EF_min_fert_AN_CH4*Frac_AN_FR) -> 0.00028919545 | I13: ='CH4 per kg feed'!H29*FCR_bonefree_incl_parents_FR -> 0.00027750918 | L13: ='CH4 per kg feed'!K29*FCR_bonefree_incl_parents_FR -> 3.7833579e-05 | N13: ='CH4 per kg feed'!M29*FCR_bonefree_incl_parents_FR -> 1.9538692e-05 | O13: ='CH4 per kg feed'!N29*FCR_bonefree_incl_parents_FR -> 5.7353021e-05 | P13: ='CH4 per kg feed'!O29*FCR_bonefree_incl_parents_FR -> 0 | Q13: ='CH4 per kg feed'!P29*FCR_bonefree_incl_parents_FR -> 5.198857e-05 | R13: ='CH4 per kg feed'!Q29*FCR_bonefree_incl_parents_FR -> 8.9083902e-05 | W13: =Energy_stables_FR/Bonefree_outof_CW_FR*(Share_heating_FR*(Share_biofuels_FR*EF_biofuel_CH4+(1-Share_biofuels_FR)*EF_oil_CH4)+(1-Share_heating_FR)*EF_el_CH4_FR) -> 5.1246928e-05 | X13: =(Energy_slaughter_el_FR*EF_el_CH4_FR+Energy_slaughter_oil_FR*EF_oil_CH4)/Bonefree_outof_CW_FR -> 0.00014316063
A14: A01SP | B14: Chicken fresh meat | C14: Meat and meat products | D14: France | E14: FR | F14: CH4, biogenic | G14: =SUM(H14:T14)+SUM(W14:X14) -> 0.0022548527 | T14: =SUM(U14:V14) -> 0.0022548527 | U14: =(Production!C40*(Slaughter_age_FR/365)+SUM(Production!C41:C44))*EF_CH4_manure_FR -> 0.0022548527
A15: A01SP | B15: Chicken fresh meat | C15: Meat and meat products | D15: France | E15: FR | F15: N2O | G15: =SUM(H15:T15)+SUM(W15:X15) -> 0.0017922933 | H15: ='N2O per kg feed'!G29*FCR_bonefree_incl_parents_FR-Excreted_N_after_losses_FR*Manure_repl_factor_FR*(EF_min_fert_BAT_N2O*Frac_BAT_FR+EF_min_fert_AN_N2O*Frac_AN_FR) -> 0.00033199344 | I15: ='N2O per kg feed'!H29*FCR_bonefree_incl_parents_FR -> 2.8369277e-06 | J15: ='N2O per kg feed'!I29*FCR_bonefree_incl_parents_FR-Excreted_N_after_losses_FR*Manure_repl_factor_FR*EF_N2O_diff_FR -> 0.0011383231 | K15: =J15*EF_indirect_N2O_FR -> 0.00011383231 | L15: ='N2O per kg feed'!K29*FCR_bonefree_incl_parents_FR -> 2.294647e-06 | N15: ='N2O per kg feed'!M29*FCR_bonefree_incl_parents_FR -> 2.4080939e-07 | O15: ='N2O per kg feed'!N29*FCR_bonefree_incl_parents_FR -> 3.9570163e-06 | P15: ='N2O per kg feed'!O29*FCR_bonefree_incl_parents_FR -> 0 | Q15: ='N2O per kg feed'!P29*FCR_bonefree_incl_parents_FR -> 5.1358635e-06 | R15: ='N2O per kg feed'!Q29*FCR_bonefree_incl_parents_FR -> 3.2106037e-06 | T15: =SUM(U15:V15) -> 0.00018057705 | U15: =Excreted_N_per_kg_of_bonefree_meat_FR*EF_N2O_manure_direct_FR*44/28 -> 6.6922527e-05 | V15: =(Excreted_N_per_kg_of_bonefree_meat_FR-U15*28/44)*EF_ammonia_FR*EF_N2O_manure_indirect_FR*44/28 -> 0.00011365453 | W15: =Energy_stables_FR/Bonefree_outof_CW_FR*(Share_heating_FR*(Share_biofuels_FR*EF_biofuel_N2O+(1-Share_biofuels_FR)*EF_oil_N2O)+(1-Share_heating_FR)*EF_el_N2O_FR) -> 5.3835558e-06 | X15: =(Energy_slaughter_el_FR*EF_el_N2O_FR+Energy_slaughter_oil_FR*EF_oil_N2O)/Bonefree_outof_CW_FR -> 4.5079803e-06
A16: A01SP | B16: Chicken fresh meat | C16: Meat and meat products | D16: France | E16: FR | F16: CO2e | G16: =SUM(H16:X16) -> 1.3265143 | H16: =SUMPRODUCT(H12:H15,'Parameters, general'!$B$14:$B$17) -> 0.25670205 | I16: =SUMPRODUCT(I12:I15,'Parameters, general'!$B$14:$B$17) -> 0.084528256 | J16: =SUMPRODUCT(J12:J15,'Parameters, general'!$B$14:$B$17) -> 0.31076221 | K16: =SUMPRODUCT(K12:K15,'Parameters, general'!$B$14:$B$17) -> 0.031076221 | L16: =SUMPRODUCT(L12:L15,'Parameters, general'!$B$14:$B$17) -> 0.087140466 | M16: =SUMPRODUCT(M12:M15,'Parameters, general'!$B$14:$B$17) -> 0 | N16: =SUMPRODUCT(N12:N15,'Parameters, general'!$B$14:$B$17) -> 0.0062408422 | O16: =SUMPRODUCT(O12:O15,'Parameters, general'!$B$14:$B$17) -> 0.10830226 | ... T16: =SUMPRODUCT(T12:T15,'Parameters, general'!$B$14:$B$17) -> 0.11017856 | W16: =SUMPRODUCT(W12:W15,'Parameters, general'!$B$14:$B$17) -> 0.065397296 | X16: =SUMPRODUCT(X12:X15,'Parameters, general'!$B$14:$B$17) -> 0.058283097 | Z16: =SUM(H16:R16) -> 1.0926554 | AA16: ='CO2 per kg feed'!F29+'CH4 per kg feed'!F29*CF_GWP_CH4_fossil+'N2O per kg feed'!F29*CF_GWP_N2O -> 0.38891068
A17: A01SP | B17: Chicken fresh meat | C17: Meat and meat products | D17: Germany | E17: DE | F17: CO2 | G17: =SUM(H17:X17) -> 0.98916343 | H17: ='CO2 per kg feed'!G41*FCR_bonefree_incl_parents_DE-Excreted_N_after_losses_DE*Manure_repl_factor_DE*(EF_min_fert_BAT_CO2*Frac_BAT_DE+EF_min_fert_AN_CO2*Frac_AN_DE) -> 0.13971619 | I17: ='CO2 per kg feed'!H41*FCR_bonefree_incl_parents_DE -> 0.080675571 | J17: ='CO2 per kg feed'!I41*FCR_bonefree_incl_parents_DE -> 0 | L17: ='CO2 per kg feed'!K41*FCR_bonefree_incl_parents_DE -> 0.08679244 | N17: ='CO2 per kg feed'!M41*FCR_bonefree_incl_parents_DE -> 0.0014603878 | O17: ='CO2 per kg feed'!N41*FCR_bonefree_incl_parents_DE -> 0.12988624 | P17: ='CO2 per kg feed'!O41*FCR_bonefree_incl_parents_DE -> 0.094471241 | Q17: ='CO2 per kg feed'!P41*FCR_bonefree_incl_parents_DE -> 0.017007422 | R17: ='CO2 per kg feed'!Q41*FCR_bonefree_incl_parents_DE -> 0.094222312 | W17: =Energy_stables_DE/Bonefree_outof_CW_DE*(Share_heating_DE*(Share_biofuels_DE*EF_biofuels_CO2+(1-Share_biofuels_DE)*EF_oil_CO2)+(1-Share_heating_DE)*EF_el_CO2_DE) -> 0.096617763 | X17: =(Energy_slaughter_el_DE*EF_el_CO2_DE+Energy_slaughter_oil_DE*EF_oil_CO2)/Bonefree_outof_CW_DE -> 0.24831387
A18: A01SP | B18: Chicken fresh meat | C18: Meat and meat products | D18: Germany | E18: DE | F18: CH4, fossil | G18: =SUM(H18:X18) -> 0.0014032805 | H18: ='CH4 per kg feed'!G41*FCR_bonefree_incl_parents_DE-Excreted_N_after_losses_DE*Manure_repl_factor_DE*(EF_min_fert_BAT_CH4*Frac_BAT_DE+EF_min_fert_AN_CH4*Frac_AN_DE) -> 0.00025792928 | I18: ='CH4 per kg feed'!H41*FCR_bonefree_incl_parents_DE -> 0.00029681362 | L18: ='CH4 per kg feed'!K41*FCR_bonefree_incl_parents_DE -> 3.835387e-05 | N18: ='CH4 per kg feed'!M41*FCR_bonefree_incl_parents_DE -> 4.359498e-06 | O18: ='CH4 per kg feed'!N41*FCR_bonefree_incl_parents_DE -> 9.2562814e-05 | P18: ='CH4 per kg feed'!O41*FCR_bonefree_incl_parents_DE -> 0 | Q18: ='CH4 per kg feed'!P41*FCR_bonefree_incl_parents_DE -> 5.2595618e-05 | R18: ='CH4 per kg feed'!Q41*FCR_bonefree_incl_parents_DE -> 8.9919548e-05 | W18: =Energy_stables_DE/Bonefree_outof_CW_DE*(Share_heating_DE*(Share_biofuels_DE*EF_biofuel_CH4+(1-Share_biofuels_DE)*EF_oil_CH4)+(1-Share_heating_DE)*EF_el_CH4_DE) -> 0.00010729737 | X18: =(Energy_slaughter_el_DE*EF_el_CH4_DE+Energy_slaughter_oil_DE*EF_oil_CH4)/Bonefree_outof_CW_DE -> 0.00046344887
A19: A01SP | B19: Chicken fresh meat | C19: Meat and meat products | D19: Germany | E19: DE | F19: CH4, biogenic | G19: =SUM(H19:T19)+SUM(W19:X19) -> 0.0033020792 | T19: =SUM(U19:V19) -> 0.0033020792 | U19: =(Production!D40*(Slaughter_age_DE/365)+SUM(Production!D41:D44))*EF_CH4_manure_DE -> 0.0033020792
A20: A01SP | B20: Chicken fresh meat | C20: Meat and meat products | D20: Germany | E20: DE | F20: N2O | G20: =SUM(H20:T20)+SUM(W20:X20) -> 0.0018609264 | H20: ='N2O per kg feed'!G41*FCR_bonefree_incl_parents_DE-Excreted_N_after_losses_DE*Manure_repl_factor_DE*(EF_min_fert_BAT_N2O*Frac_BAT_DE+EF_min_fert_AN_N2O*Frac_AN_DE) -> 0.00029449449 | I20: ='N2O per kg feed'!H41*FCR_bonefree_incl_parents_DE -> 3.0276799e-06 | J20: ='N2O per kg feed'!I41*FCR_bonefree_incl_parents_DE-Excreted_N_after_losses_DE*Manure_repl_factor_DE*EF_N2O_diff_DE -> 0.0011507977 | K20: =J20*EF_indirect_N2O_DE -> 0.00011507977 | L20: ='N2O per kg feed'!K41*FCR_bonefree_incl_parents_DE -> 2.3266654e-06 | N20: ='N2O per kg feed'!M41*FCR_bonefree_incl_parents_DE -> 5.3674875e-08 | O20: ='N2O per kg feed'!N41*FCR_bonefree_incl_parents_DE -> 4.8448061e-06 | P20: ='N2O per kg feed'!O41*FCR_bonefree_incl_parents_DE -> 0 | Q20: ='N2O per kg feed'!P41*FCR_bonefree_incl_parents_DE -> 5.2083721e-06 | R20: ='N2O per kg feed'!Q41*FCR_bonefree_incl_parents_DE -> 3.2688954e-06 | T20: =SUM(U20:V20) -> 0.00026424513 | U20: =Excreted_N_per_kg_of_bonefree_meat_DE*EF_N2O_manure_direct_DE*44/28 -> 9.7930226e-05 | V20: =(Excreted_N_per_kg_of_bonefree_meat_DE-U20*28/44)*EF_ammonia_DE*EF_N2O_manure_indirect_DE*44/28 -> 0.0001663149 | W20: =Energy_stables_DE/Bonefree_outof_CW_DE*(Share_heating_DE*(Share_biofuels_DE*EF_biofuel_N2O+(1-Share_biofuels_DE)*EF_oil_N2O)+(1-Share_heating_DE)*EF_el_N2O_DE) -> 6.52852e-06 | X20: =(Energy_slaughter_el_DE*EF_el_N2O_DE+Energy_slaughter_oil_DE*EF_oil_N2O)/Bonefree_outof_CW_DE -> 1.1050633e-05
A21: A01SP | B21: Chicken fresh meat | C21: Meat and meat products | D21: Germany | E21: DE | F21: CO2e | G21: =SUM(H21:X21) -> 1.6281702 | H21: =SUMPRODUCT(H17:H20,'Parameters, general'!$B$14:$B$17) -> 0.22779948 | I21: =SUMPRODUCT(I17:I20,'Parameters, general'!$B$14:$B$17) -> 0.090347174 | J21: =SUMPRODUCT(J17:J20,'Parameters, general'!$B$14:$B$17) -> 0.31416778 | K21: =SUMPRODUCT(K17:K20,'Parameters, general'!$B$14:$B$17) -> 0.031416778 | L21: =SUMPRODUCT(L17:L20,'Parameters, general'!$B$14:$B$17) -> 0.088570565 | M21: =SUMPRODUCT(M17:M20,'Parameters, general'!$B$14:$B$17) -> 0 | N21: =SUMPRODUCT(N17:N20,'Parameters, general'!$B$14:$B$17) -> 0.0016049541 | O21: =SUMPRODUCT(O17:O20,'Parameters, general'!$B$14:$B$17) -> 0.13396724 | ... T21: =SUMPRODUCT(T17:T20,'Parameters, general'!$B$14:$B$17) -> 0.16129506 | W21: =SUMPRODUCT(W17:W20,'Parameters, general'!$B$14:$B$17) -> 0.10159751 | X21: =SUMPRODUCT(X17:X20,'Parameters, general'!$B$14:$B$17) -> 0.26514147 | Z21: =SUM(H21:R21) -> 1.1001362 | AA21: ='CO2 per kg feed'!F41+'CH4 per kg feed'!F41*CF_GWP_CH4_fossil+'N2O per kg feed'!F41*CF_GWP_N2O -> 0.42210136
A22: A01SP | B22: Chicken fresh meat | C22: Meat and meat products | D22: Greece | E22: GR | F22: CO2 | G22: =SUM(H22:X22) -> 1.2701078 | H22: ='CO2 per kg feed'!G53*FCR_bonefree_incl_parents_GR-Excreted_N_after_losses_GR*Manure_repl_factor_GR*(EF_min_fert_BAT_CO2*Frac_BAT_GR+EF_min_fert_AN_CO2*Frac_AN_GR) -> 0.07722502 | I22: ='CO2 per kg feed'!H53*FCR_bonefree_incl_parents_GR -> 0.072441039 | J22: ='CO2 per kg feed'!I53*FCR_bonefree_incl_parents_GR -> 0 | L22: ='CO2 per kg feed'!K53*FCR_bonefree_incl_parents_GR -> 0.12418653 | N22: ='CO2 per kg feed'!M53*FCR_bonefree_incl_parents_GR -> 0.022798804 | O22: ='CO2 per kg feed'!N53*FCR_bonefree_incl_parents_GR -> 0.11988509 | P22: ='CO2 per kg feed'!O53*FCR_bonefree_incl_parents_GR -> 0.21074569 | Q22: ='CO2 per kg feed'!P53*FCR_bonefree_incl_parents_GR -> 0.023400018 | R22: ='CO2 per kg feed'!Q53*FCR_bonefree_incl_parents_GR -> 0.16678491 | W22: =Energy_stables_GR/Bonefree_outof_CW_GR*(Share_heating_GR*(Share_biofuels_GR*EF_biofuels_CO2+(1-Share_biofuels_GR)*EF_oil_CO2)+(1-Share_heating_GR)*EF_el_CO2_GR) -> 0.11265954 | X22: =(Energy_slaughter_el_GR*EF_el_CO2_GR+Energy_slaughter_oil_GR*EF_oil_CO2)/Bonefree_outof_CW_GR -> 0.33998118
A23: A01SP | B23: Chicken fresh meat | C23: Meat and meat products | D23: Greece | E23: GR | F23: CH4, fossil | G23: =SUM(H23:X23) -> 0.0017458147 | H23: ='CH4 per kg feed'!G53*FCR_bonefree_incl_parents_GR-Excreted_N_after_losses_GR*Manure_repl_factor_GR*(EF_min_fert_BAT_CH4*Frac_BAT_GR+EF_min_fert_AN_CH4*Frac_AN_GR) -> 0.00015547768 | I23: ='CH4 per kg feed'!H53*FCR_bonefree_incl_parents_GR -> 0.00026535314 | L23: ='CH4 per kg feed'!K53*FCR_bonefree_incl_parents_GR -> 5.5030547e-05 | N23: ='CH4 per kg feed'!M53*FCR_bonefree_incl_parents_GR -> 7.7451555e-05 | O23: ='CH4 per kg feed'!N53*FCR_bonefree_incl_parents_GR -> 9.7128688e-05 | P23: ='CH4 per kg feed'!O53*FCR_bonefree_incl_parents_GR -> 0 | Q23: ='CH4 per kg feed'!P53*FCR_bonefree_incl_parents_GR -> 8.5763304e-05 | R23: ='CH4 per kg feed'!Q53*FCR_bonefree_incl_parents_GR -> 0.00020460508 | W23: =Energy_stables_GR/Bonefree_outof_CW_GR*(Share_heating_GR*(Share_biofuels_GR*EF_biofuel_CH4+(1-Share_biofuels_GR)*EF_oil_CH4)+(1-Share_heating_GR)*EF_el_CH4_GR) -> 0.00014218693 | X23: =(Energy_slaughter_el_GR*EF_el_CH4_GR+Energy_slaughter_oil_GR*EF_oil_CH4)/Bonefree_outof_CW_GR -> 0.00066281778
A24: A01SP | B24: Chicken fresh meat | C24: Meat and meat products | D24: Greece | E24: GR | F24: CH4, biogenic | G24: =SUM(H24:T24)+SUM(W24:X24) -> 0.0033020792 | T24: =SUM(U24:V24) -> 0.0033020792 | U24: =(Production!E40*(Slaughter_age_GR/365)+SUM(Production!E41:E44))*EF_CH4_manure_GR -> 0.0033020792
A25: A01SP | B25: Chicken fresh meat | C25: Meat and meat products | D25: Greece | E25: GR | F25: N2O | G25: =SUM(H25:T25)+SUM(W25:X25) -> 0.00084529818 | H25: ='N2O per kg feed'!G53*FCR_bonefree_incl_parents_GR-Excreted_N_after_losses_GR*Manure_repl_factor_GR*(EF_min_fert_BAT_N2O*Frac_BAT_GR+EF_min_fert_AN_N2O*Frac_AN_GR) -> 0.00017086401 | I25: ='N2O per kg feed'!H53*FCR_bonefree_incl_parents_GR -> 2.7419415e-06 | J25: ='N2O per kg feed'!I53*FCR_bonefree_incl_parents_GR-Excreted_N_after_losses_GR*Manure_repl_factor_GR*EF_N2O_diff_GR -> 0.00039061316 | K25: =J25*EF_indirect_N2O_GR -> 3.9061316e-05 | L25: ='N2O per kg feed'!K53*FCR_bonefree_incl_parents_GR -> 3.3385732e-06 | N25: ='N2O per kg feed'!M53*FCR_bonefree_incl_parents_GR -> 9.5293863e-07 | O25: ='N2O per kg feed'!N53*FCR_bonefree_incl_parents_GR -> 4.2342188e-06 | P25: ='N2O per kg feed'!O53*FCR_bonefree_incl_parents_GR -> 0 | Q25: ='N2O per kg feed'!P53*FCR_bonefree_incl_parents_GR -> 8.9188094e-06 | R25: ='N2O per kg feed'!Q53*FCR_bonefree_incl_parents_GR -> 6.0369677e-06 | T25: =SUM(U25:V25) -> 0.0002001857 | U25: =Excreted_N_per_kg_of_bonefree_meat_GR*EF_N2O_manure_direct_GR*44/28 -> 7.4189565e-05 | V25: =(Excreted_N_per_kg_of_bonefree_meat_GR-U25*28/44)*EF_ammonia_GR*EF_N2O_manure_indirect_GR*44/28 -> 0.00012599614 | W25: =Energy_stables_GR/Bonefree_outof_CW_GR*(Share_heating_GR*(Share_biofuels_GR*EF_biofuel_N2O+(1-Share_biofuels_GR)*EF_oil_N2O)+(1-Share_heating_GR)*EF_el_N2O_GR) -> 6.6434077e-06 | X25: =(Energy_slaughter_el_GR*EF_el_N2O_GR+Energy_slaughter_oil_GR*EF_oil_N2O)/Bonefree_outof_CW_GR -> 1.1707134e-05
A26: A01SP | B26: Chicken fresh meat | C26: Meat and meat products | D26: Greece | E26: GR | F26: CO2e | G26: =SUM(H26:X26) -> 1.6420556 | H26: =SUMPRODUCT(H22:H25,'Parameters, general'!$B$14:$B$17) -> 0.12850413 | I26: =SUMPRODUCT(I22:I25,'Parameters, general'!$B$14:$B$17) -> 0.081097112 | J26: =SUMPRODUCT(J22:J25,'Parameters, general'!$B$14:$B$17) -> 0.10663739 | K26: =SUMPRODUCT(K22:K25,'Parameters, general'!$B$14:$B$17) -> 0.010663739 | L26: =SUMPRODUCT(L22:L25,'Parameters, general'!$B$14:$B$17) -> 0.12673787 | M26: =SUMPRODUCT(M22:M25,'Parameters, general'!$B$14:$B$17) -> 0 | N26: =SUMPRODUCT(N22:N25,'Parameters, general'!$B$14:$B$17) -> 0.025367013 | O26: =SUMPRODUCT(O22:O25,'Parameters, general'!$B$14:$B$17) -> 0.12393547 | ... T26: =SUMPRODUCT(T22:T25,'Parameters, general'!$B$14:$B$17) -> 0.14380684 | W26: =SUMPRODUCT(W22:W25,'Parameters, general'!$B$14:$B$17) -> 0.11871036 | X26: =SUMPRODUCT(X22:X25,'Parameters, general'!$B$14:$B$17) -> 0.3629292 | Z26: =SUM(H26:R26) -> 1.0166092 | AA26: ='CO2 per kg feed'!F53+'CH4 per kg feed'!F53*CF_GWP_CH4_fossil+'N2O per kg feed'!F53*CF_GWP_N2O -> 0.37535001
A27: A01SP | B27: Chicken fresh meat | C27: Meat and meat products | D27: Hungary | E27: HU | F27: CO2 | G27: =SUM(H27:X27) -> 0.94482381 | H27: ='CO2 per kg feed'!G65*FCR_bonefree_incl_parents_HU-Excreted_N_after_losses_HU*Manure_repl_factor_HU*(EF_min_fert_BAT_CO2*Frac_BAT_HU+EF_min_fert_AN_CO2*Frac_AN_HU) -> 0.11976552 | I27: ='CO2 per kg feed'!H65*FCR_bonefree_incl_parents_HU -> 0.079244949 | J27: ='CO2 per kg feed'!I65*FCR_bonefree_incl_parents_HU -> 0 | L27: ='CO2 per kg feed'!K65*FCR_bonefree_incl_parents_HU -> 0.098241512 | N27: ='CO2 per kg feed'!M65*FCR_bonefree_incl_parents_HU -> 0.00064481961 | O27: ='CO2 per kg feed'!N65*FCR_bonefree_incl_parents_HU -> 0.12271005 | P27: ='CO2 per kg feed'!O65*FCR_bonefree_incl_parents_HU -> 0.10270074 | Q27: ='CO2 per kg feed'!P65*FCR_bonefree_incl_parents_HU -> 0.011400364 | R27: ='CO2 per kg feed'!Q65*FCR_bonefree_incl_parents_HU -> 0.081268937 | W27: =Energy_stables_HU/Bonefree_outof_CW_HU*(Share_heating_HU*(Share_biofuels_HU*EF_biofuels_CO2+(1-Share_biofuels_HU)*EF_oil_CO2)+(1-Share_heating_HU)*EF_el_CO2_HU) -> 0.094222168 | X27: =(Energy_slaughter_el_HU*EF_el_CO2_HU+Energy_slaughter_oil_HU*EF_oil_CO2)/Bonefree_outof_CW_HU -> 0.23462475
A28: A01SP | B28: Chicken fresh meat | C28: Meat and meat products | D28: Hungary | E28: HU | F28: CH4, fossil | G28: =SUM(H28:X28) -> 0.0014900731 | H28: ='CH4 per kg feed'!G65*FCR_bonefree_incl_parents_HU-Excreted_N_after_losses_HU*Manure_repl_factor_HU*(EF_min_fert_BAT_CH4*Frac_BAT_HU+EF_min_fert_AN_CH4*Frac_AN_HU) -> 0.00023789943 | I28: ='CH4 per kg feed'!H65*FCR_bonefree_incl_parents_HU -> 0.00029205691 | L28: ='CH4 per kg feed'!K65*FCR_bonefree_incl_parents_HU -> 4.3794602e-05 | N28: ='CH4 per kg feed'!M65*FCR_bonefree_incl_parents_HU -> 3.0300551e-06 | O28: ='CH4 per kg feed'!N65*FCR_bonefree_incl_parents_HU -> 0.00010017622 | P28: ='CH4 per kg feed'!O65*FCR_bonefree_incl_parents_HU -> 0 | Q28: ='CH4 per kg feed'!P65*FCR_bonefree_incl_parents_HU -> 4.1787832e-05 | R28: ='CH4 per kg feed'!Q65*FCR_bonefree_incl_parents_HU -> 6.8054673e-05 | W28: =Energy_stables_HU/Bonefree_outof_CW_HU*(Share_heating_HU*(Share_biofuels_HU*EF_biofuel_CH4+(1-Share_biofuels_HU)*EF_oil_CH4)+(1-Share_heating_HU)*EF_el_CH4_HU) -> 0.00012703545 | X28: =(Energy_slaughter_el_HU*EF_el_CH4_HU+Energy_slaughter_oil_HU*EF_oil_CH4)/Bonefree_outof_CW_HU -> 0.00057623792
A29: A01SP | B29: Chicken fresh meat | C29: Meat and meat products | D29: Hungary | E29: HU | F29: CH4, biogenic | G29: =SUM(H29:T29)+SUM(W29:X29) -> 0.0022013861 | T29: =SUM(U29:V29) -> 0.0022013861 | U29: =(Production!F40*(Slaughter_age_HU/365)+SUM(Production!F41:F44))*EF_CH4_manure_HU -> 0.0022013861
A30: A01SP | B30: Chicken fresh meat | C30: Meat and meat products | D30: Hungary | E30: HU | F30: N2O | G30: =SUM(H30:T30)+SUM(W30:X30) -> 0.0009675764 | H30: ='N2O per kg feed'!G65*FCR_bonefree_incl_parents_HU-Excreted_N_after_losses_HU*Manure_repl_factor_HU*(EF_min_fert_BAT_N2O*Frac_BAT_HU+EF_min_fert_AN_N2O*Frac_AN_HU) -> 0.0002649933 | I30: ='N2O per kg feed'!H65*FCR_bonefree_incl_parents_HU -> 2.9638561e-06 | J30: ='N2O per kg feed'!I65*FCR_bonefree_incl_parents_HU-Excreted_N_after_losses_HU*Manure_repl_factor_HU*EF_N2O_diff_HU -> 0.00042688949 | K30: =J30*EF_indirect_N2O_HU -> 4.2688949e-05 | L30: ='N2O per kg feed'!K65*FCR_bonefree_incl_parents_HU -> 2.6545386e-06 | N30: ='N2O per kg feed'!M65*FCR_bonefree_incl_parents_HU -> 3.7289025e-08 | O30: ='N2O per kg feed'!N65*FCR_bonefree_incl_parents_HU -> 4.3400032e-06 | P30: ='N2O per kg feed'!O65*FCR_bonefree_incl_parents_HU -> 0 | Q30: ='N2O per kg feed'!P65*FCR_bonefree_incl_parents_HU -> 4.345773e-06 | R30: ='N2O per kg feed'!Q65*FCR_bonefree_incl_parents_HU -> 2.9416848e-06 | T30: =SUM(U30:V30) -> 0.00020146462 | U30: =Excreted_N_per_kg_of_bonefree_meat_HU*EF_N2O_manure_direct_HU*44/28 -> 7.4663535e-05 | V30: =(Excreted_N_per_kg_of_bonefree_meat_HU-U30*28/44)*EF_ammonia_HU*EF_N2O_manure_indirect_HU*44/28 -> 0.00012680108 | W30: =Energy_stables_HU/Bonefree_outof_CW_HU*(Share_heating_HU*(Share_biofuels_HU*EF_biofuel_N2O+(1-Share_biofuels_HU)*EF_oil_N2O)+(1-Share_heating_HU)*EF_el_N2O_HU) -> 6.0337176e-06 | X30: =(Energy_slaughter_el_HU*EF_el_N2O_HU+Energy_slaughter_oil_HU*EF_oil_N2O)/Bonefree_outof_CW_HU -> 8.2231906e-06
A31: A01SP | B31: Chicken fresh meat | C31: Meat and meat products | D31: Hungary | E31: HU | F31: CO2e | G31: =SUM(H31:X31) -> 1.3128138 | H31: =SUMPRODUCT(H27:H30,'Parameters, general'!$B$14:$B$17) -> 0.19919809 | I31: =SUMPRODUCT(I27:I30,'Parameters, general'!$B$14:$B$17) -> 0.088757377 | J31: =SUMPRODUCT(J27:J30,'Parameters, general'!$B$14:$B$17) -> 0.11654083 | K31: =SUMPRODUCT(K27:K30,'Parameters, general'!$B$14:$B$17) -> 0.011654083 | L31: =SUMPRODUCT(L27:L30,'Parameters, general'!$B$14:$B$17) -> 0.10027128 | M31: =SUMPRODUCT(M27:M30,'Parameters, general'!$B$14:$B$17) -> 0 | N31: =SUMPRODUCT(N27:N30,'Parameters, general'!$B$14:$B$17) -> 0.00074529516 | O31: =SUMPRODUCT(O27:O30,'Parameters, general'!$B$14:$B$17) -> 0.12688013 | ... T31: =SUMPRODUCT(T27:T30,'Parameters, general'!$B$14:$B$17) -> 0.11443727 | W31: =SUMPRODUCT(W27:W30,'Parameters, general'!$B$14:$B$17) -> 0.099655029 | X31: =SUMPRODUCT(X27:X30,'Parameters, general'!$B$14:$B$17) -> 0.25404157 | Z31: =SUM(H31:R31) -> 0.84467991 | AA31: ='CO2 per kg feed'!F65+'CH4 per kg feed'!F65*CF_GWP_CH4_fossil+'N2O per kg feed'!F65*CF_GWP_N2O -> 0.32328911
A32: A01SP | B32: Chicken fresh meat | C32: Meat and meat products | D32: Ireland | E32: IE | F32: CO2 | G32: =SUM(H32:X32) -> 0.90510556 | H32: ='CO2 per kg feed'!G77*FCR_bonefree_incl_parents_IE-Excreted_N_after_losses_IE*Manure_repl_factor_IE*(EF_min_fert_BAT_CO2*Frac_BAT_IE+EF_min_fert_AN_CO2*Frac_AN_IE) -> 0.073870634 | I32: ='CO2 per kg feed'!H77*FCR_bonefree_incl_parents_IE -> 0.061987143 | J32: ='CO2 per kg feed'!I77*FCR_bonefree_incl_parents_IE -> 0 | L32: ='CO2 per kg feed'!K77*FCR_bonefree_incl_parents_IE -> 0.073289325 | N32: ='CO2 per kg feed'!M77*FCR_bonefree_incl_parents_IE -> 0.00019093931 | O32: ='CO2 per kg feed'!N77*FCR_bonefree_incl_parents_IE -> 0.097908903 | P32: ='CO2 per kg feed'!O77*FCR_bonefree_incl_parents_IE -> 0.14537906 | Q32: ='CO2 per kg feed'!P77*FCR_bonefree_incl_parents_IE -> 0.021179504 | R32: ='CO2 per kg feed'!Q77*FCR_bonefree_incl_parents_IE -> 0.13009148 | W32: =Energy_stables_IE/Bonefree_outof_CW_IE*(Share_heating_IE*(Share_biofuels_IE*EF_biofuels_CO2+(1-Share_biofuels_IE)*EF_oil_CO2)+(1-Share_heating_IE)*EF_el_CO2_IE) -> 0.090105819 | X32: =(Energy_slaughter_el_IE*EF_el_CO2_IE+Energy_slaughter_oil_IE*EF_oil_CO2)/Bonefree_outof_CW_IE -> 0.21110276
A33: A01SP | B33: Chicken fresh meat | C33: Meat and meat products | D33: Ireland | E33: IE | F33: CH4, fossil | G33: =SUM(H33:X33) -> 0.00092381804 | H33: ='CH4 per kg feed'!G77*FCR_bonefree_incl_parents_IE-Excreted_N_after_losses_IE*Manure_repl_factor_IE*(EF_min_fert_BAT_CH4*Frac_BAT_IE+EF_min_fert_AN_CH4*Frac_AN_IE) -> 0.00013352964 | I33: ='CH4 per kg feed'!H77*FCR_bonefree_incl_parents_IE -> 0.00022691612 | L33: ='CH4 per kg feed'!K77*FCR_bonefree_incl_parents_IE -> 3.2220328e-05 | N33: ='CH4 per kg feed'!M77*FCR_bonefree_incl_parents_IE -> 1.5062731e-06 | O33: ='CH4 per kg feed'!N77*FCR_bonefree_incl_parents_IE -> 5.4757723e-05 | P33: ='CH4 per kg feed'!O77*FCR_bonefree_incl_parents_IE -> 0 | Q33: ='CH4 per kg feed'!P77*FCR_bonefree_incl_parents_IE -> 7.0098587e-05 | R33: ='CH4 per kg feed'!Q77*FCR_bonefree_incl_parents_IE -> 0.00011745742 | W33: =Energy_stables_IE/Bonefree_outof_CW_IE*(Share_heating_IE*(Share_biofuels_IE*EF_biofuel_CH4+(1-Share_biofuels_IE)*EF_oil_CH4)+(1-Share_heating_IE)*EF_el_CH4_IE) -> 6.5086732e-05 | X33: =(Energy_slaughter_el_IE*EF_el_CH4_IE+Energy_slaughter_oil_IE*EF_oil_CH4)/Bonefree_outof_CW_IE -> 0.00022224522
A34: A01SP | B34: Chicken fresh meat | C34: Meat and meat products | D34: Ireland | E34: IE | F34: CH4, biogenic | G34: =SUM(H34:T34)+SUM(W34:X34) -> 0.0023114555 | T34: =SUM(U34:V34) -> 0.0023114555 | U34: =(Production!G40*(Slaughter_age_IE/365)+SUM(Production!G41:G44))*EF_CH4_manure_IE -> 0.0023114555
