Workbook
Name Ability_to_perceive_handling: 'Parameters, general'!$B$19
Name BGBE: 'Parameters, country spec'!#REF!
Name Boars_per_sow: 'Parameters, country spec'!$L$17
Name Bonefree_outof_CW_AT: 'Parameters, country spec'!#REF!
Name Bonefree_outof_CW_BE: 'Parameters, country spec'!#REF!
Name Bonefree_outof_CW_BG: 'Parameters, country spec'!#REF!
Name Bonefree_outof_CW_BR: 'Parameters, country spec'!#REF!
Name Bonefree_outof_CW_CY: 'Parameters, country spec'!#REF!
Name Bonefree_outof_CW_CZ: 'Parameters, country spec'!#REF!
Name Bonefree_outof_CW_DE: 'Parameters, country spec'!$D$8
Name Bonefree_outof_CW_DK: 'Parameters, country spec'!$B$8
Name Bonefree_outof_CW_EE: 'Parameters, country spec'!#REF!
Name Bonefree_outof_CW_ES: 'Parameters, country spec'!$K$8
Name Bonefree_outof_CW_FI: 'Parameters, country spec'!#REF!
Name Bonefree_outof_CW_FR: 'Parameters, country spec'!$C$8
Name Bonefree_outof_CW_GB: 'Parameters, country spec'!#REF!
Name Bonefree_outof_CW_GR: 'Parameters, country spec'!$E$8
Name Bonefree_outof_CW_HR: 'Parameters, country spec'!#REF!
Name Bonefree_outof_CW_HU: 'Parameters, country spec'!$F$8
Name Bonefree_outof_CW_IE: 'Parameters, country spec'!$G$8
Name Bonefree_outof_CW_IT: 'Parameters, country spec'!$H$8
Name Bonefree_outof_CW_LT: 'Parameters, country spec'!#REF!
Name Bonefree_outof_CW_LV: 'Parameters, country spec'!#REF!
Name Bonefree_outof_CW_MT: 'Parameters, country spec'!#REF!
Name Bonefree_outof_CW_NL: 'Parameters, country spec'!$I$8
Name Bonefree_outof_CW_PL: 'Parameters, country spec'!$J$8
Name Bonefree_outof_CW_PT: 'Parameters, country spec'!#REF!
Name Bonefree_outof_CW_RO: 'Parameters, country spec'!#REF!
Name Bonefree_outof_CW_SE: 'Parameters, country spec'!$L$8
Name Bonefree_outof_CW_SI: 'Parameters, country spec'!#REF!
Name Bonefree_outof_CW_SK: 'Parameters, country spec'!#REF!
Name Bonefree_outof_CW_TH: 'Parameters, country spec'!#REF!
Name Bonefree_outof_CW_US: 'Parameters, country spec'!#REF!
Name CF_GWP_CH4_fossil: 'Parameters, general'!$B$14
Name CF_GWP_N2O: 'Parameters, general'!$B$15
Name CY: 'Parameters, country spec'!#REF!
Name EF_ammonia_AT: Manure!#REF!
Name EF_ammonia_AT: #REF!
Name EF_ammonia_BE: Manure!#REF!
Name EF_ammonia_BE: #REF!
Name EF_ammonia_BG: Manure!#REF!
Name EF_ammonia_BG: #REF!
Name EF_ammonia_BR: Manure!#REF!
Name EF_ammonia_BR: #REF!
Name EF_ammonia_CY: Manure!#REF!
Name EF_ammonia_CY: #REF!
Name EF_ammonia_CZ: Manure!#REF!
Name EF_ammonia_CZ: #REF!
Name EF_ammonia_DE: Manure!#REF!
Name EF_ammonia_DE: #REF!
Name EF_ammonia_DK: Manure!#REF!
Name EF_ammonia_DK: #REF!
Name EF_ammonia_EE: Manure!#REF!
Name EF_ammonia_EE: #REF!
Name EF_ammonia_ES: Manure!#REF!
Name EF_ammonia_ES: #REF!
Name EF_ammonia_FI: Manure!#REF!
Name EF_ammonia_FI: #REF!
Name EF_ammonia_FR: Manure!#REF!
Name EF_ammonia_FR: #REF!

Sheet README
A2: Read me
A4: This is a file that contains…
A7: Assumptions:
A8: - All parent animals are also eaten
A9: - Impacts are allocated equally across flesh and offals
A17: Color codes:
B19: Results
B20: Sheets for input
B21: Intermediate calculations
A26: Att göra:
A27: Fyll i olika gödselsystem från NIR-rapporterna
A28: Lägg in landspecifika foderstater
A29: Energianvändning slakt

Sheet Footprints, results per kg
A2: Footprints (per kg of bonefree meat) | D2: Data from https://www.diva-portal.org/smash/get/diva2:1718732/FULLTEXT01.pdf so not calculated here | M2: * Adjusted for manure
A5: Animal products | F5: Climate | L5: Land | M5: Nitrogen* | N5: Phosphorus | O5: Water | P5: Pesticides | Q5: Biodiversity | R5: Ammonia | S5: Labour | T5: Animal welfare | U5: Use of antibiotics
A6: Code | B6: Name | C6: Category | D6: Country | E6: Country code | F6: Carbon footprint, kg CO2e/kg | G6: Carbon dioxide, kg CO2/kg | H6: Methane, fossil, kg CH4/kg | I6: Methane, biogenic, kg CH4/kg | J6: Nitrous oxide, kg N2O/kg | K6: HFCs, kg HFCs/kg | L6: Cropland use, m2/kg | M6: New N input, kg N/kg | N6: New P input, kg P/kg | O6: Blue freshwater use, m3/kg | P6: Pesticide use, g a.i./kg | Q6: Extinction rate, E/MSY/kg | R6: Ammonia emission, kg NH3/kg | S6: Labour requirements, h/kg | T6: Animal welfare index per kg of bonefree meat
A7: 21115 | B7: Sheep meat | C7: Red meat | D7: France | E7: FR | F7: 34.395484 | G7: 3.6400991 | I7: 0.68500477 | J7: 0.025051082 | L7: =25.2782591151659/0.7 -> 36.111799 | M7: =0.731629558788247/0.7 -> 1.0451851 | N7: =0.0184851691675996/0.7 -> 0.026407385 | O7: 0.322 | P7: =0.00117435421640243/0.7 -> 0.0016776489 | Q7: =1.03063593462921E-08/0.7 -> 1.472337e-08 | R7: =0.116777886949226/0.7 -> 0.16682555 | S7: ='Parameters, country spec'!$C$83/Production!$C$35 -> 0.044138136 | T7: 0.026 | U7: 38.1
A8: 21115 | B8: Sheep meat | C8: Red meat | D8: Germany | E8: DE | F8: 34.395484 | G8: 3.6400991 | I8: 0.68500477 | J8: 0.025051082 | L8: =25.2782591151659/0.7 -> 36.111799 | M8: =0.731629558788247/0.7 -> 1.0451851 | N8: =0.0184851691675996/0.7 -> 0.026407385 | O8: 0.161 | P8: =0.00117435421640243/0.7 -> 0.0016776489 | Q8: =1.95138714626237E-09/0.7 -> 2.7876959e-09 | R8: =0.116777886949226/0.7 -> 0.16682555 | S8: ='Parameters, country spec'!$D$83/Production!$D$35 -> 0.04983338 | T8: 0.018 | U8: 50.4
A9: 21115 | B9: Sheep meat | C9: Red meat | D9: Greece | E9: GR | F9: 34.395484 | G9: 3.6400991 | I9: 0.68500477 | J9: 0.025051082 | L9: =25.2782591151659/0.7 -> 36.111799 | M9: =0.731629558788247/0.7 -> 1.0451851 | N9: =0.0184851691675996/0.7 -> 0.026407385 | O9: 1.19 | P9: =0.00117435421640243/0.7 -> 0.0016776489 | Q9: =4.72214019813801E-08/0.7 -> 6.7459146e-08 | R9: =0.116777886949226/0.7 -> 0.16682555 | S9: ='Parameters, country spec'!$E$83/Production!$E$35 -> 0.03274765 | T9: 0.026 | U9: 111.7
A10: 21115 | B10: Sheep meat | C10: Red meat | D10: Hungary | E10: HU | F10: 34.395484 | G10: 3.6400991 | I10: 0.68500477 | J10: 0.025051082 | L10: =25.2782591151659/0.7 -> 36.111799 | M10: =0.731629558788247/0.7 -> 1.0451851 | N10: =0.0184851691675996/0.7 -> 0.026407385 | O10: 0.219 | P10: =0.00117435421640243/0.7 -> 0.0016776489 | Q10: =2.08599117042857E-09/0.7 -> 2.9799874e-09 | R10: =0.116777886949226/0.7 -> 0.16682555 | S10: ='Parameters, country spec'!$F$83/Production!$F$35 -> 0.14309299 | T10: 0.026 | U10: 102.5
A11: 21115 | B11: Sheep meat | C11: Red meat | D11: Ireland | E11: IE | F11: 34.395484 | G11: 3.6400991 | I11: 0.68500477 | J11: 0.025051082 | L11: =25.2782591151659/0.7 -> 36.111799 | M11: =0.731629558788247/0.7 -> 1.0451851 | N11: =0.0184851691675996/0.7 -> 0.026407385 | O11: 0.241 | P11: =0.00117435421640243/0.7 -> 0.0016776489 | Q11: =2.01045385112878E-09/0.7 -> 2.8720769e-09 | R11: =0.116777886949226/0.7 -> 0.16682555 | S11: ='Parameters, country spec'!$G$83/Production!$G$35 -> 0.095395327 | T11: 0.026 | U11: 40.6
A12: 21115 | B12: Sheep meat | C12: Red meat | D12: Italy | E12: IT | F12: 34.395484 | G12: 3.6400991 | I12: 0.68500477 | J12: 0.025051082 | L12: =25.2782591151659/0.7 -> 36.111799 | M12: =0.731629558788247/0.7 -> 1.0451851 | N12: =0.0184851691675996/0.7 -> 0.026407385 | O12: 0.512 | P12: =0.00117435421640243/0.7 -> 0.0016776489 | Q12: =3.38805721381219E-08/0.7 -> 4.8400817e-08 | R12: =0.116777886949226/0.7 -> 0.16682555 | S12: ='Parameters, country spec'!$H$83/Production!$H$35 -> 0.046273853 | T12: 0.026 | U12: 129.1
A13: 21115 | B13: Sheep meat | C13: Red meat | D13: New Zealand | E13: NZ | F13: 34.395484 | G13: 3.6400991 | I13: 0.68500477 | J13: 0.025051082 | L13: =25.2782591151659/0.7 -> 36.111799 | M13: =0.731629558788247/0.7 -> 1.0451851 | N13: =0.0184851691675996/0.7 -> 0.026407385 | O13: 0.423 | P13: =0.00117435421640243/0.7 -> 0.0016776489 | Q13: =1.73745552407811E-09/0.7 -> 2.4820793e-09 | R13: =0.116777886949226/0.7 -> 0.16682555 | S13: ='Parameters, country spec'!$I$83/Production!$I$35 -> 0.059800056 | T13: 0.018 | U13: 32.1
A14: 21115 | B14: Sheep meat | C14: Red meat | D14: Poland | E14: PL | F14: 34.395484 | G14: 3.6400991 | I14: 0.68500477 | J14: 0.025051082 | L14: =25.2782591151659/0.7 -> 36.111799 | M14: =0.731629558788247/0.7 -> 1.0451851 | N14: =0.0184851691675996/0.7 -> 0.026407385 | O14: 0.4 | P14: =0.00117435421640243/0.7 -> 0.0016776489 | Q14: =2.28129287616524E-09/0.7 -> 3.2589898e-09 | R14: =0.116777886949226/0.7 -> 0.16682555 | S14: ='Parameters, country spec'!$J$83/Production!$J$35 -> 0.15092395 | T14: 0.026 | U14: 134.7
A15: 21115 | B15: Sheep meat | C15: Red meat | D15: Spain | E15: ES | F15: 34.395484 | G15: 3.6400991 | I15: 0.68500477 | J15: 0.025051082 | L15: =25.2782591151659/0.7 -> 36.111799 | M15: =0.731629558788247/0.7 -> 1.0451851 | N15: =0.0184851691675996/0.7 -> 0.026407385 | O15: 0.949 | P15: =0.00117435421640243/0.7 -> 0.0016776489 | Q15: =5.55001978047497E-08/0.7 -> 7.9285997e-08 | R15: =0.116777886949226/0.7 -> 0.16682555 | S15: ='Parameters, country spec'!$K$83/Production!$K$35 -> 0.014238109 | T15: 0.026 | U15: 95.7
A16: 21115 | B16: Sheep meat | C16: Red meat | D16: Sweden | E16: SE | F16: 34.395484 | G16: 3.6400991 | I16: 0.68500477 | J16: 0.025051082 | L16: =25.2782591151659/0.7 -> 36.111799 | M16: =0.731629558788247/0.7 -> 1.0451851 | N16: =0.0184851691675996/0.7 -> 0.026407385 | O16: 0.172 | P16: =0.00117435421640243/0.7 -> 0.0016776489 | Q16: =1.24339395138407E-09/0.7 -> 1.7762771e-09 | R16: =0.116777886949226/0.7 -> 0.16682555 | S16: ='Parameters, country spec'!$L$83/Production!$L$35 -> 0.029188122 | T16: 0.016 | U16: 10.1
A17: 21115 | B17: Sheep meat | C17: Red meat | D17: UK | E17: GB | F17: 34.395484 | G17: 3.6400991 | I17: 0.68500477 | J17: 0.025051082 | L17: =25.2782591151659/0.7 -> 36.111799 | M17: =0.731629558788247/0.7 -> 1.0451851 | N17: =0.0184851691675996/0.7 -> 0.026407385 | O17: 0.341 | P17: =0.00117435421640243/0.7 -> 0.0016776489 | Q17: =2.24979718582115E-08/0.7 -> 3.213996e-08 | R17: =0.116777886949226/0.7 -> 0.16682555 | S17: ='Parameters, country spec'!$L$83/Production!$L$35 -> 0.029188122 | U17: 29.8

Sheet GHG detailed, results per kg
H1: * Production of mineral fertiliser is adjusted to account for the N supplied by manure.
A2: GHG emissions (per kg of milk) | D2: Not updated | H2: ** Adjusted for use of manure instead of mineral fertiliser (lower emission factor for manure)
H3: *** Calculated as percentage of direct emissions due to assumption due to data limitations regarding nitrogen leaching and volatilization from soils in different regions.
R4: Animals | V4: Stables | W4: Slaughter | Y4: Control
A5: Animal products | G5: Sum | H5: Inputs | J5: Soil emissions | L5: Energy use | P5: Land use change | Q5: Transports
A6: FoodEx code | B6: FoodEx name | C6: Food Ex category (L1) | D6: Country | E6: Country code | F6: Gas | G6: GHG | H6: Production of mineral fertilizer* | I6: Production of capital goods | J6: Direct emissions** | K6: Indirect emissions*** | L6: Diesel use field mach | M6: Energy use in greenhouses | N6: Energy use for irrigation | O6: Energy use for post-harvest proc | P6: LUC emissions | Q6: Feed transports | R6: Enteric fermentation* | S6: Manure management - tot | T6: Manure management - direct | U6: Manure management - indirect | V6: Energy use in stables | W6: Energy use for slaughter | Y6: Total feed, excl LUC | Z6: Feed mix emissions, kg CO2 per kg feed, excl. adjustement manure
A7: A01QV | B7: Bovine muscle | C7: Meat and meat products | D7: Denmark | E7: DK | F7: CO2 | G7: =SUM(H7:W7) -> 3.3278628 | H7: ='CO2 per kg feed'!G17*FCR_bonefree_incl_parents_DK-Excreted_N_after_losses_DK*Manure_repl_factor_DK*(EF_min_fert_BAT_CO2*Frac_BAT_DK+EF_min_fert_AN_CO2*Frac_AN_DK) -> 0.25774626 | I7: ='CO2 per kg feed'!H17*FCR_bonefree_incl_parents_DK -> 0.14920613 | J7: ='CO2 per kg feed'!I17*FCR_bonefree_incl_parents_DK -> 1.142928 | L7: ='CO2 per kg feed'!K17*FCR_bonefree_incl_parents_DK -> 0.21958707 | N7: ='CO2 per kg feed'!M17*FCR_bonefree_incl_parents_DK -> 0 | O7: ='CO2 per kg feed'!N17*FCR_bonefree_incl_parents_DK -> 0.1925179 | P7: ='CO2 per kg feed'!O17*FCR_bonefree_incl_parents_DK -> 0.096183216 | Q7: ='CO2 per kg feed'!P17*FCR_bonefree_incl_parents_DK -> 0.071861229 | V7: =Energy_stables_DK/Bonefree_outof_CW_DK*(Share_heating_DK*(Share_biofuels_DK*EF_biofuels_CO2+(1-Share_biofuels_DK)*EF_oil_CO2)+(1-Share_heating_DK)*EF_el_CO2_DK) -> 0.31038958 | W7: =(Energy_slaughter_el_DK*EF_el_CO2_DK+Energy_slaughter_oil_DK*EF_oil_CO2)/Bonefree_outof_CW_DK -> 0.88744346
A8: A01QV | B8: Bovine muscle | C8: Meat and meat products | D8: Denmark | E8: DK | F8: CH4 | G8: =SUM(H8:W8) -> 0.040565463 | H8: ='CH4 per kg feed'!G17*FCR_bonefree_incl_parents_DK-Excreted_N_after_losses_DK*Manure_repl_factor_DK*(EF_min_fert_BAT_CH4*Frac_BAT_DK+EF_min_fert_AN_CH4*Frac_AN_DK) -> 0.00030406944 | I8: ='CH4 per kg feed'!H17*FCR_bonefree_incl_parents_DK -> 0.00052655737 | L8: ='CH4 per kg feed'!K17*FCR_bonefree_incl_parents_DK -> 0.00010043929 | N8: ='CH4 per kg feed'!M17*FCR_bonefree_incl_parents_DK -> 0 | O8: ='CH4 per kg feed'!N17*FCR_bonefree_incl_parents_DK -> 6.9538829e-05 | P8: ='CH4 per kg feed'!O17*FCR_bonefree_incl_parents_DK -> 0 | Q8: ='CH4 per kg feed'!P17*FCR_bonefree_incl_parents_DK -> 0.0050657669 | R8: =(Production!B37+Production!B38+Production!B39*4/12)*EF_ent_ferm_DK -> 0.010683314 | S8: =SUM(T8:U8) -> 0.011236433 | T8: =Manure!E32 -> 0.011236433 | V8: =Energy_stables_DK/Bonefree_outof_CW_DK*(Share_heating_DK*(Share_biofuels_DK*EF_biofuel_CH4+(1-Share_biofuels_DK)*EF_oil_CH4)+(1-Share_heating_DK)*EF_el_CH4_DK) -> 0.00031537651 | W8: =(Energy_slaughter_el_DK*EF_el_CH4_DK+Energy_slaughter_oil_DK*EF_oil_CH4)/Bonefree_outof_CW_DK -> 0.0010275354
A9: A01QV | B9: Bovine muscle | C9: Meat and meat products | D9: Denmark | E9: DK | F9: N2O | G9: =SUM(H9:W9) -> 0.0054696458 | H9: ='N2O per kg feed'!G17*FCR_bonefree_incl_parents_DK-Excreted_N_after_losses_DK*Manure_repl_factor_DK*(EF_min_fert_BAT_N2O*Frac_BAT_DK+EF_min_fert_AN_N2O*Frac_AN_DK) -> 0.00057716801 | I9: ='N2O per kg feed'!H17*FCR_bonefree_incl_parents_DK -> 7.6689942e-05 | J9: ='N2O per kg feed'!I17*FCR_bonefree_incl_parents_DK-Excreted_N_after_losses_DK*Manure_repl_factor_DK*EF_N2O_diff_DK -> 0.0029402166 | K9: =J9*EF_indirect_N2O_DK -> 0.00029402166 | L9: ='N2O per kg feed'!K17*FCR_bonefree_incl_parents_DK -> 1.5687779e-05 | N9: ='N2O per kg feed'!M17*FCR_bonefree_incl_parents_DK -> 0 | O9: ='N2O per kg feed'!N17*FCR_bonefree_incl_parents_DK -> 1.5805256e-05 | P9: ='N2O per kg feed'!O17*FCR_bonefree_incl_parents_DK -> 0 | Q9: ='N2O per kg feed'!P17*FCR_bonefree_incl_parents_DK -> 0.00021885712 | S9: =SUM(T9:U9) -> 0.00063249264 | T9: =Manure!E88*44/28 -> 0.00010126684 | U9: =NH3_per_kg_DK*17/14*Manure!B117 -> 0.00053122581 | V9: =Energy_stables_DK/Bonefree_outof_CW_DK*(Share_heating_DK*(Share_biofuels_DK*EF_biofuel_N2O+(1-Share_biofuels_DK)*EF_oil_N2O)+(1-Share_heating_DK)*EF_el_N2O_DK) -> 2.3709428e-05 | W9: =(Energy_slaughter_el_DK*EF_el_N2O_DK+Energy_slaughter_oil_DK*EF_oil_N2O)/Bonefree_outof_CW_DK -> 4.2504703e-05
A10: A01QV | B10: Bovine muscle | C10: Meat and meat products | D10: Denmark | E10: DK | F10: CO2e | G10: =SUM(H10:W10) -> 5.5224107 | H10: =SUMPRODUCT(H7:H9,'Parameters, general'!$B$13:$B$15) -> 0.4243744 | I10: =SUMPRODUCT(I7:I9,'Parameters, general'!$B$13:$B$15) -> 0.18583389 | J10: =SUMPRODUCT(J7:J9,'Parameters, general'!$B$13:$B$15) -> 1.9456071 | K10: =SUMPRODUCT(K7:K9,'Parameters, general'!$B$13:$B$15) -> 0.080267913 | L10: =SUMPRODUCT(L7:L9,'Parameters, general'!$B$13:$B$15) -> 0.22686293 | M10: =SUMPRODUCT(M7:M9,'Parameters, general'!$B$13:$B$15) -> 0 | N10: =SUMPRODUCT(N7:N9,'Parameters, general'!$B$13:$B$15) -> 0 | O10: =SUMPRODUCT(O7:O9,'Parameters, general'!$B$13:$B$15) -> 0.19890499 | ... S10: =SUMPRODUCT(S7:S9,'Parameters, general'!$B$13:$B$15) -> 0.50751618 | V10: =SUMPRODUCT(V7:V9,'Parameters, general'!$B$13:$B$15) -> 0.32626048 | W10: =SUMPRODUCT(W7:W9,'Parameters, general'!$B$13:$B$15) -> 0.92966779 | Y10: =SUM(H10:Q10) -> 3.4406035 | Z10: ='CO2 per kg feed'!F17+'CH4 per kg feed'!F17*CF_GWP_CH4_fossil+'N2O per kg feed'!F17*CF_GWP_N2O -> 0.54104631
A11: A01QV | B11: Bovine muscle | C11: Meat and meat products | D11: France | E11: FR | F11: CO2 | G11: =SUM(H11:W11) -> 2.747787 | H11: ='CO2 per kg feed'!G29*FCR_bonefree_incl_parents_FR-Excreted_N_after_losses_FR*Manure_repl_factor_FR*(EF_min_fert_BAT_CO2*Frac_BAT_FR+EF_min_fert_AN_CO2*Frac_AN_FR) -> 0.25444396 | I11: ='CO2 per kg feed'!H29*FCR_bonefree_incl_parents_FR -> 0.15431962 | J11: ='CO2 per kg feed'!I29*FCR_bonefree_incl_parents_FR -> 1.2050269 | L11: ='CO2 per kg feed'!K29*FCR_bonefree_incl_parents_FR -> 0.23178064 | N11: ='CO2 per kg feed'!M29*FCR_bonefree_incl_parents_FR -> 0 | O11: ='CO2 per kg feed'!N29*FCR_bonefree_incl_parents_FR -> 0.19911574 | P11: ='CO2 per kg feed'!O29*FCR_bonefree_incl_parents_FR -> 0.096183216 | Q11: ='CO2 per kg feed'!P29*FCR_bonefree_incl_parents_FR -> 0.071861229 | V11: =Energy_stables_FR/Bonefree_outof_CW_FR*(Share_heating_FR*(Share_biofuels_FR*EF_biofuels_CO2+(1-Share_biofuels_FR)*EF_oil_CO2)+(1-Share_heating_FR)*EF_el_CO2_FR) -> 0.17602118 | W11: =(Energy_slaughter_el_FR*EF_el_CO2_FR+Energy_slaughter_oil_FR*EF_oil_CO2)/Bonefree_outof_CW_FR -> 0.35903452
A12: A01QV | B12: Bovine muscle | C12: Meat and meat products | D12: France | E12: FR | F12: CH4 | G12: =SUM(H12:W12) -> 0.040001887 | H12: ='CH4 per kg feed'!G29*FCR_bonefree_incl_parents_FR-Excreted_N_after_losses_FR*Manure_repl_factor_FR*(EF_min_fert_BAT_CH4*Frac_BAT_FR+EF_min_fert_AN_CH4*Frac_AN_FR) -> 0.00030406944 | I12: ='CH4 per kg feed'!H29*FCR_bonefree_incl_parents_FR -> 0.00052655737 | L12: ='CH4 per kg feed'!K29*FCR_bonefree_incl_parents_FR -> 0.00010043929 | N12: ='CH4 per kg feed'!M29*FCR_bonefree_incl_parents_FR -> 0 | O12: ='CH4 per kg feed'!N29*FCR_bonefree_incl_parents_FR -> 6.9538829e-05 | P12: ='CH4 per kg feed'!O29*FCR_bonefree_incl_parents_FR -> 0 | Q12: ='CH4 per kg feed'!P29*FCR_bonefree_incl_parents_FR -> 0.0050657669 | R12: =(Production!C37+Production!C38+Production!C39*4/12)*EF_ent_ferm_FR -> 0.010683314 | S12: =SUM(T12:U12) -> 0.011236433 | T12: =Manure!I32 -> 0.011236433 | V12: =Energy_stables_FR/Bonefree_outof_CW_FR*(Share_heating_FR*(Share_biofuels_FR*EF_biofuel_CH4+(1-Share_biofuels_FR)*EF_oil_CH4)+(1-Share_heating_FR)*EF_el_CH4_FR) -> 0.00020111986 | W12: =(Energy_slaughter_el_FR*EF_el_CH4_FR+Energy_slaughter_oil_FR*EF_oil_CH4)/Bonefree_outof_CW_FR -> 0.00057821667
A13: A01QV | B13: Bovine muscle | C13: Meat and meat products | D13: France | E13: FR | F13: N2O | G13: =SUM(H13:W13) -> 0.0054441578 | H13: ='N2O per kg feed'!G29*FCR_bonefree_incl_parents_FR-Excreted_N_after_losses_FR*Manure_repl_factor_FR*(EF_min_fert_BAT_N2O*Frac_BAT_FR+EF_min_fert_AN_N2O*Frac_AN_FR) -> 0.00057716801 | I13: ='N2O per kg feed'!H29*FCR_bonefree_incl_parents_FR -> 7.6689942e-05 | J13: ='N2O per kg feed'!I29*FCR_bonefree_incl_parents_FR-Excreted_N_after_losses_FR*Manure_repl_factor_FR*EF_N2O_diff_FR -> 0.0029402166 | K13: =J13*EF_indirect_N2O_FR -> 0.00029402166 | L13: ='N2O per kg feed'!K29*FCR_bonefree_incl_parents_FR -> 1.5687779e-05 | N13: ='N2O per kg feed'!M29*FCR_bonefree_incl_parents_FR -> 0 | O13: ='N2O per kg feed'!N29*FCR_bonefree_incl_parents_FR -> 1.5805256e-05 | P13: ='N2O per kg feed'!O29*FCR_bonefree_incl_parents_FR -> 0 | Q13: ='N2O per kg feed'!P29*FCR_bonefree_incl_parents_FR -> 0.00021885712 | S13: =SUM(T13:U13) -> 0.00063249264 | T13: =Manure!I88*44/28 -> 0.00010126684 | U13: =NH3_per_kg_FR*17/14*Manure!F117 -> 0.00053122581 | V13: =Energy_stables_FR/Bonefree_outof_CW_FR*(Share_heating_FR*(Share_biofuels_FR*EF_biofuel_N2O+(1-Share_biofuels_FR)*EF_oil_N2O)+(1-Share_heating_FR)*EF_el_N2O_FR) -> 1.8542111e-05 | W13: =(Energy_slaughter_el_FR*EF_el_N2O_FR+Energy_slaughter_oil_FR*EF_oil_N2O)/Bonefree_outof_CW_FR -> 2.218403e-05
A14: A01QV | B14: Bovine muscle | C14: Meat and meat products | D14: France | E14: FR | F14: CO2e | G14: =SUM(H14:W14) -> 4.9185821 | H14: =SUMPRODUCT(H11:H13,'Parameters, general'!$B$13:$B$15) -> 0.42107209 | I14: =SUMPRODUCT(I11:I13,'Parameters, general'!$B$13:$B$15) -> 0.19094738 | J14: =SUMPRODUCT(J11:J13,'Parameters, general'!$B$13:$B$15) -> 2.007706 | K14: =SUMPRODUCT(K11:K13,'Parameters, general'!$B$13:$B$15) -> 0.080267913 | L14: =SUMPRODUCT(L11:L13,'Parameters, general'!$B$13:$B$15) -> 0.23905649 | M14: =SUMPRODUCT(M11:M13,'Parameters, general'!$B$13:$B$15) -> 0 | N14: =SUMPRODUCT(N11:N13,'Parameters, general'!$B$13:$B$15) -> 0 | O14: =SUMPRODUCT(O11:O13,'Parameters, general'!$B$13:$B$15) -> 0.20550283 | ... S14: =SUMPRODUCT(S11:S13,'Parameters, general'!$B$13:$B$15) -> 0.50751618 | V14: =SUMPRODUCT(V11:V13,'Parameters, general'!$B$13:$B$15) -> 0.18707654 | W14: =SUMPRODUCT(W11:W13,'Parameters, general'!$B$13:$B$15) -> 0.38232161 | Y14: =SUM(H14:Q14) -> 3.523305 | Z14: ='CO2 per kg feed'!F29+'CH4 per kg feed'!F29*CF_GWP_CH4_fossil+'N2O per kg feed'!F29*CF_GWP_N2O -> 0.55339912
A15: A01QV | B15: Bovine muscle | C15: Meat and meat products | D15: Germany | E15: DE | F15: CO2 | G15: =SUM(H15:W15) -> 3.6279783 | H15: ='CO2 per kg feed'!G41*FCR_bonefree_incl_parents_DE-Excreted_N_after_losses_DE*Manure_repl_factor_DE*(EF_min_fert_BAT_CO2*Frac_BAT_DE+EF_min_fert_AN_CO2*Frac_AN_DE) -> 0.25444396 | I15: ='CO2 per kg feed'!H41*FCR_bonefree_incl_parents_DE -> 0.15431962 | J15: ='CO2 per kg feed'!I41*FCR_bonefree_incl_parents_DE -> 1.2050269 | L15: ='CO2 per kg feed'!K41*FCR_bonefree_incl_parents_DE -> 0.23178064 | N15: ='CO2 per kg feed'!M41*FCR_bonefree_incl_parents_DE -> 0 | O15: ='CO2 per kg feed'!N41*FCR_bonefree_incl_parents_DE -> 0.19911574 | P15: ='CO2 per kg feed'!O41*FCR_bonefree_incl_parents_DE -> 0.096183216 | Q15: ='CO2 per kg feed'!P41*FCR_bonefree_incl_parents_DE -> 0.071861229 | V15: =Energy_stables_DE/Bonefree_outof_CW_DE*(Share_heating_DE*(Share_biofuels_DE*EF_biofuels_CO2+(1-Share_biofuels_DE)*EF_oil_CO2)+(1-Share_heating_DE)*EF_el_CO2_DE) -> 0.35446708 | W15: =(Energy_slaughter_el_DE*EF_el_CO2_DE+Energy_slaughter_oil_DE*EF_oil_CO2)/Bonefree_outof_CW_DE -> 1.0607799
A16: A01QV | B16: Bovine muscle | C16: Meat and meat products | D16: Germany | E16: DE | F16: CH4 | G16: =SUM(H16:W16) -> 0.041443704 | H16: ='CH4 per kg feed'!G41*FCR_bonefree_incl_parents_DE-Excreted_N_after_losses_DE*Manure_repl_factor_DE*(EF_min_fert_BAT_CH4*Frac_BAT_DE+EF_min_fert_AN_CH4*Frac_AN_DE) -> 0.00030406944 | I16: ='CH4 per kg feed'!H41*FCR_bonefree_incl_parents_DE -> 0.00052655737 | L16: ='CH4 per kg feed'!K41*FCR_bonefree_incl_parents_DE -> 0.00010043929 | N16: ='CH4 per kg feed'!M41*FCR_bonefree_incl_parents_DE -> 0 | O16: ='CH4 per kg feed'!N41*FCR_bonefree_incl_parents_DE -> 6.9538829e-05 | P16: ='CH4 per kg feed'!O41*FCR_bonefree_incl_parents_DE -> 0 | Q16: ='CH4 per kg feed'!P41*FCR_bonefree_incl_parents_DE -> 0.0050657669 | R16: =(Production!D37+Production!D38+Production!D39*4/12)*EF_ent_ferm_DE -> 0.010683314 | S16: =SUM(T16:U16) -> 0.011236433 | T16: =Manure!M32 -> 0.011236433 | V16: =Energy_stables_DE/Bonefree_outof_CW_DE*(Share_heating_DE*(Share_biofuels_DE*EF_biofuel_CH4+(1-Share_biofuels_DE)*EF_oil_CH4)+(1-Share_heating_DE)*EF_el_CH4_DE) -> 0.00049342699 | W16: =(Energy_slaughter_el_DE*EF_el_CH4_DE+Energy_slaughter_oil_DE*EF_oil_CH4)/Bonefree_outof_CW_DE -> 0.0017277257
A17: A01QV | B17: Bovine muscle | C17: Meat and meat products | D17: Germany | E17: DE | F17: N2O | G17: =SUM(H17:W17) -> 0.0054736103 | H17: ='N2O per kg feed'!G41*FCR_bonefree_incl_parents_DE-Excreted_N_after_losses_DE*Manure_repl_factor_DE*(EF_min_fert_BAT_N2O*Frac_BAT_DE+EF_min_fert_AN_N2O*Frac_AN_DE) -> 0.00057716801 | I17: ='N2O per kg feed'!H41*FCR_bonefree_incl_parents_DE -> 7.6689942e-05 | J17: ='N2O per kg feed'!I41*FCR_bonefree_incl_parents_DE-Excreted_N_after_losses_DE*Manure_repl_factor_DE*EF_N2O_diff_DE -> 0.0029402166 | K17: =J17*EF_indirect_N2O_DE -> 0.00029402166 | L17: ='N2O per kg feed'!K41*FCR_bonefree_incl_parents_DE -> 1.5687779e-05 | N17: ='N2O per kg feed'!M41*FCR_bonefree_incl_parents_DE -> 0 | O17: ='N2O per kg feed'!N41*FCR_bonefree_incl_parents_DE -> 1.5805256e-05 | P17: ='N2O per kg feed'!O41*FCR_bonefree_incl_parents_DE -> 0 | Q17: ='N2O per kg feed'!P41*FCR_bonefree_incl_parents_DE -> 0.00021885712 | S17: =SUM(T17:U17) -> 0.00063249264 | T17: =Manure!M88*44/28 -> 0.00010126684 | U17: =NH3_per_kg_DE*17/14*Manure!J117 -> 0.00053122581 | V17: =Energy_stables_DE/Bonefree_outof_CW_DE*(Share_heating_DE*(Share_biofuels_DE*EF_biofuel_N2O+(1-Share_biofuels_DE)*EF_oil_N2O)+(1-Share_heating_DE)*EF_el_N2O_DE) -> 2.4513183e-05 | W17: =(Energy_slaughter_el_DE*EF_el_N2O_DE+Energy_slaughter_oil_DE*EF_oil_N2O)/Bonefree_outof_CW_DE -> 4.5665499e-05
A18: A01QV | B18: Bovine muscle | C18: Meat and meat products | D18: Germany | E18: DE | F18: CO2e | G18: =SUM(H18:W18) -> 5.8497801 | H18: =SUMPRODUCT(H15:H17,'Parameters, general'!$B$13:$B$15) -> 0.42107209 | I18: =SUMPRODUCT(I15:I17,'Parameters, general'!$B$13:$B$15) -> 0.19094738 | J18: =SUMPRODUCT(J15:J17,'Parameters, general'!$B$13:$B$15) -> 2.007706 | K18: =SUMPRODUCT(K15:K17,'Parameters, general'!$B$13:$B$15) -> 0.080267913 | L18: =SUMPRODUCT(L15:L17,'Parameters, general'!$B$13:$B$15) -> 0.23905649 | M18: =SUMPRODUCT(M15:M17,'Parameters, general'!$B$13:$B$15) -> 0 | N18: =SUMPRODUCT(N15:N17,'Parameters, general'!$B$13:$B$15) -> 0 | O18: =SUMPRODUCT(O15:O17,'Parameters, general'!$B$13:$B$15) -> 0.20550283 | ... S18: =SUMPRODUCT(S15:S17,'Parameters, general'!$B$13:$B$15) -> 0.50751618 | V18: =SUMPRODUCT(V15:V17,'Parameters, general'!$B$13:$B$15) -> 0.3758633 | W18: =SUMPRODUCT(W15:W17,'Parameters, general'!$B$13:$B$15) -> 1.1247328 | Y18: =SUM(H18:Q18) -> 3.523305 | Z18: ='CO2 per kg feed'!F41+'CH4 per kg feed'!F41*CF_GWP_CH4_fossil+'N2O per kg feed'!F41*CF_GWP_N2O -> 0.55339912
A19: A01QV | B19: Bovine muscle | C19: Meat and meat products | D19: Greece | E19: GR | F19: CO2 | G19: =SUM(H19:W19) -> 4.0406298 | H19: ='CO2 per kg feed'!G53*FCR_bonefree_incl_parents_GR-Excreted_N_after_losses_GR*Manure_repl_factor_GR*(EF_min_fert_BAT_CO2*Frac_BAT_GR+EF_min_fert_AN_CO2*Frac_AN_GR) -> 0.25444396 | I19: ='CO2 per kg feed'!H53*FCR_bonefree_incl_parents_GR -> 0.15431962 | J19: ='CO2 per kg feed'!I53*FCR_bonefree_incl_parents_GR -> 1.2050269 | L19: ='CO2 per kg feed'!K53*FCR_bonefree_incl_parents_GR -> 0.23178064 | N19: ='CO2 per kg feed'!M53*FCR_bonefree_incl_parents_GR -> 0 | O19: ='CO2 per kg feed'!N53*FCR_bonefree_incl_parents_GR -> 0.19911574 | P19: ='CO2 per kg feed'!O53*FCR_bonefree_incl_parents_GR -> 0.096183216 | Q19: ='CO2 per kg feed'!P53*FCR_bonefree_incl_parents_GR -> 0.071861229 | V19: =Energy_stables_GR/Bonefree_outof_CW_GR*(Share_heating_GR*(Share_biofuels_GR*EF_biofuels_CO2+(1-Share_biofuels_GR)*EF_oil_CO2)+(1-Share_heating_GR)*EF_el_CO2_GR) -> 0.43812613 | W19: =(Energy_slaughter_el_GR*EF_el_CO2_GR+Energy_slaughter_oil_GR*EF_oil_CO2)/Bonefree_outof_CW_GR -> 1.3897723
A20: A01QV | B20: Bovine muscle | C20: Meat and meat products | D20: Greece | E20: GR | F20: CH4 | G20: =SUM(H20:W20) -> 0.051070459 | H20: ='CH4 per kg feed'!G53*FCR_bonefree_incl_parents_GR-Excreted_N_after_losses_GR*Manure_repl_factor_GR*(EF_min_fert_BAT_CH4*Frac_BAT_GR+EF_min_fert_AN_CH4*Frac_AN_GR) -> 0.00030406944 | I20: ='CH4 per kg feed'!H53*FCR_bonefree_incl_parents_GR -> 0.00052655737 | L20: ='CH4 per kg feed'!K53*FCR_bonefree_incl_parents_GR -> 0.00010043929 | N20: ='CH4 per kg feed'!M53*FCR_bonefree_incl_parents_GR -> 0 | O20: ='CH4 per kg feed'!N53*FCR_bonefree_incl_parents_GR -> 6.9538829e-05 | P20: ='CH4 per kg feed'!O53*FCR_bonefree_incl_parents_GR -> 0 | Q20: ='CH4 per kg feed'!P53*FCR_bonefree_incl_parents_GR -> 0.013795039 | R20: =(Production!E37+Production!E38+Production!E39*4/12)*EF_ent_ferm_GR -> 0.010683314 | S20: =SUM(T20:U20) -> 0.011236433 | T20: =Manure!Q32 -> 0.011236433 | V20: =Energy_stables_GR/Bonefree_outof_CW_GR*(Share_heating_GR*(Share_biofuels_GR*EF_biofuel_CH4+(1-Share_biofuels_GR)*EF_oil_CH4)+(1-Share_heating_GR)*EF_el_CH4_GR) -> 0.00067537859 | W20: =(Energy_slaughter_el_GR*EF_el_CH4_GR+Energy_slaughter_oil_GR*EF_oil_CH4)/Bonefree_outof_CW_GR -> 0.0024432574
A21: A01QV | B21: Bovine muscle | C21: Meat and meat products | D21: Greece | E21: GR | F21: N2O | G21: =SUM(H21:W21) -> 0.0054765656 | H21: ='N2O per kg feed'!G53*FCR_bonefree_incl_parents_GR-Excreted_N_after_losses_GR*Manure_repl_factor_GR*(EF_min_fert_BAT_N2O*Frac_BAT_GR+EF_min_fert_AN_N2O*Frac_AN_GR) -> 0.00057716801 | I21: ='N2O per kg feed'!H53*FCR_bonefree_incl_parents_GR -> 7.6689942e-05 | J21: ='N2O per kg feed'!I53*FCR_bonefree_incl_parents_GR-Excreted_N_after_losses_GR*Manure_repl_factor_GR*EF_N2O_diff_GR -> 0.0029402166 | K21: =J21*EF_indirect_N2O_GR -> 0.00029402166 | L21: ='N2O per kg feed'!K53*FCR_bonefree_incl_parents_GR -> 1.5687779e-05 | N21: ='N2O per kg feed'!M53*FCR_bonefree_incl_parents_GR -> 0 | O21: ='N2O per kg feed'!N53*FCR_bonefree_incl_parents_GR -> 1.5805256e-05 | P21: ='N2O per kg feed'!O53*FCR_bonefree_incl_parents_GR -> 0 | Q21: ='N2O per kg feed'!P53*FCR_bonefree_incl_parents_GR -> 0.00021885712 | S21: =SUM(T21:U21) -> 0.00063249264 | T21: =Manure!Q88*44/28 -> 0.00010126684 | U21: =NH3_per_kg_GR*17/14*Manure!N117 -> 0.00053122581 | V21: =Energy_stables_GR/Bonefree_outof_CW_GR*(Share_heating_GR*(Share_biofuels_GR*EF_biofuel_N2O+(1-Share_biofuels_GR)*EF_oil_N2O)+(1-Share_heating_GR)*EF_el_N2O_GR) -> 2.511233e-05 | W21: =(Energy_slaughter_el_GR*EF_el_N2O_GR+Energy_slaughter_oil_GR*EF_oil_N2O)/Bonefree_outof_CW_GR -> 4.8021669e-05
A22: A01QV | B22: Bovine muscle | C22: Meat and meat products | D22: Greece | E22: GR | F22: CO2e | G22: =SUM(H22:W22) -> 6.5501157 | H22: =SUMPRODUCT(H19:H21,'Parameters, general'!$B$13:$B$15) -> 0.42107209 | I22: =SUMPRODUCT(I19:I21,'Parameters, general'!$B$13:$B$15) -> 0.19094738 | J22: =SUMPRODUCT(J19:J21,'Parameters, general'!$B$13:$B$15) -> 2.007706 | K22: =SUMPRODUCT(K19:K21,'Parameters, general'!$B$13:$B$15) -> 0.080267913 | L22: =SUMPRODUCT(L19:L21,'Parameters, general'!$B$13:$B$15) -> 0.23905649 | M22: =SUMPRODUCT(M19:M21,'Parameters, general'!$B$13:$B$15) -> 0 | N22: =SUMPRODUCT(N19:N21,'Parameters, general'!$B$13:$B$15) -> 0 | O22: =SUMPRODUCT(O19:O21,'Parameters, general'!$B$13:$B$15) -> 0.20550283 | ... S22: =SUMPRODUCT(S19:S21,'Parameters, general'!$B$13:$B$15) -> 0.50751618 | V22: =SUMPRODUCT(V19:V21,'Parameters, general'!$B$13:$B$15) -> 0.46510808 | W22: =SUMPRODUCT(W19:W21,'Parameters, general'!$B$13:$B$15) -> 1.4756913 | Y22: =SUM(H22:Q22) -> 3.7834373 | Z22: ='CO2 per kg feed'!F53+'CH4 per kg feed'!F53*CF_GWP_CH4_fossil+'N2O per kg feed'!F53*CF_GWP_N2O -> 0.59225411
A23: A01QV | B23: Bovine muscle | C23: Meat and meat products | D23: Hungary | E23: HU | F23: CO2 | G23: =SUM(H23:W23) -> 3.5663551 | H23: ='CO2 per kg feed'!G65*FCR_bonefree_incl_parents_HU-Excreted_N_after_losses_HU*Manure_repl_factor_HU*(EF_min_fert_BAT_CO2*Frac_BAT_HU+EF_min_fert_AN_CO2*Frac_AN_HU) -> 0.25444396 | I23: ='CO2 per kg feed'!H65*FCR_bonefree_incl_parents_HU -> 0.15431962 | J23: ='CO2 per kg feed'!I65*FCR_bonefree_incl_parents_HU -> 1.2050269 | L23: ='CO2 per kg feed'!K65*FCR_bonefree_incl_parents_HU -> 0.23178064 | N23: ='CO2 per kg feed'!M65*FCR_bonefree_incl_parents_HU -> 0 | O23: ='CO2 per kg feed'!N65*FCR_bonefree_incl_parents_HU -> 0.19911574 | P23: ='CO2 per kg feed'!O65*FCR_bonefree_incl_parents_HU -> 0.096183216 | Q23: ='CO2 per kg feed'!P65*FCR_bonefree_incl_parents_HU -> 0.071861229 | V23: =Energy_stables_HU/Bonefree_outof_CW_HU*(Share_heating_HU*(Share_biofuels_HU*EF_biofuels_CO2+(1-Share_biofuels_HU)*EF_oil_CO2)+(1-Share_heating_HU)*EF_el_CO2_HU) -> 0.34197387 | W23: =(Energy_slaughter_el_HU*EF_el_CO2_HU+Energy_slaughter_oil_HU*EF_oil_CO2)/Bonefree_outof_CW_HU -> 1.0116499
A24: A01QV | B24: Bovine muscle | C24: Meat and meat products | D24: Hungary | E24: HU | F24: CH4 | G24: =SUM(H24:W24) -> 0.041951437 | H24: ='CH4 per kg feed'!G65*FCR_bonefree_incl_parents_HU-Excreted_N_after_losses_HU*Manure_repl_factor_HU*(EF_min_fert_BAT_CH4*Frac_BAT_HU+EF_min_fert_AN_CH4*Frac_AN_HU) -> 0.00030406944 | I24: ='CH4 per kg feed'!H65*FCR_bonefree_incl_parents_HU -> 0.00052655737 | L24: ='CH4 per kg feed'!K65*FCR_bonefree_incl_parents_HU -> 0.00010043929 | N24: ='CH4 per kg feed'!M65*FCR_bonefree_incl_parents_HU -> 0 | O24: ='CH4 per kg feed'!N65*FCR_bonefree_incl_parents_HU -> 6.9538829e-05 | P24: ='CH4 per kg feed'!O65*FCR_bonefree_incl_parents_HU -> 0 | Q24: ='CH4 per kg feed'!P65*FCR_bonefree_incl_parents_HU -> 0.0050657669 | R24: =(Production!F37+Production!F38+Production!F39*4/12)*EF_ent_ferm_HU -> 0.010683314 | S24: =SUM(T24:U24) -> 0.011236433 | T24: =Manure!U32 -> 0.011236433 | V24: =Energy_stables_HU/Bonefree_outof_CW_HU*(Share_heating_HU*(Share_biofuels_HU*EF_biofuel_CH4+(1-Share_biofuels_HU)*EF_oil_CH4)+(1-Share_heating_HU)*EF_el_CH4_HU) -> 0.00059636254 | W24: =(Energy_slaughter_el_HU*EF_el_CH4_HU+Energy_slaughter_oil_HU*EF_oil_CH4)/Bonefree_outof_CW_HU -> 0.0021325237
A25: A01QV | B25: Bovine muscle | C25: Meat and meat products | D25: Hungary | E25: HU | F25: N2O | G25: =SUM(H25:W25) -> 0.0054608822 | H25: ='N2O per kg feed'!G65*FCR_bonefree_incl_parents_HU-Excreted_N_after_losses_HU*Manure_repl_factor_HU*(EF_min_fert_BAT_N2O*Frac_BAT_HU+EF_min_fert_AN_N2O*Frac_AN_HU) -> 0.00057716801 | I25: ='N2O per kg feed'!H65*FCR_bonefree_incl_parents_HU -> 7.6689942e-05 | J25: ='N2O per kg feed'!I65*FCR_bonefree_incl_parents_HU-Excreted_N_after_losses_HU*Manure_repl_factor_HU*EF_N2O_diff_HU -> 0.0029402166 | K25: =J25*EF_indirect_N2O_HU -> 0.00029402166 | L25: ='N2O per kg feed'!K65*FCR_bonefree_incl_parents_HU -> 1.5687779e-05 | N25: ='N2O per kg feed'!M65*FCR_bonefree_incl_parents_HU -> 0 | O25: ='N2O per kg feed'!N65*FCR_bonefree_incl_parents_HU -> 1.5805256e-05 | P25: ='N2O per kg feed'!O65*FCR_bonefree_incl_parents_HU -> 0 | Q25: ='N2O per kg feed'!P65*FCR_bonefree_incl_parents_HU -> 0.00021885712 | S25: =SUM(T25:U25) -> 0.00063249264 | T25: =Manure!U88*44/28 -> 0.00010126684 | U25: =NH3_per_kg_HU*17/14*Manure!R117 -> 0.00053122581 | V25: =Energy_stables_HU/Bonefree_outof_CW_HU*(Share_heating_HU*(Share_biofuels_HU*EF_biofuel_N2O+(1-Share_biofuels_HU)*EF_oil_N2O)+(1-Share_heating_HU)*EF_el_N2O_HU) -> 2.1932752e-05 | W25: =(Energy_slaughter_el_HU*EF_el_N2O_HU+Energy_slaughter_oil_HU*EF_oil_N2O)/Bonefree_outof_CW_HU -> 3.5517856e-05
A26: A01QV | B26: Bovine muscle | C26: Meat and meat products | D26: Hungary | E26: HU | F26: CO2e | G26: =SUM(H26:W26) -> 5.7998126 | H26: =SUMPRODUCT(H23:H25,'Parameters, general'!$B$13:$B$15) -> 0.42107209 | I26: =SUMPRODUCT(I23:I25,'Parameters, general'!$B$13:$B$15) -> 0.19094738 | J26: =SUMPRODUCT(J23:J25,'Parameters, general'!$B$13:$B$15) -> 2.007706 | K26: =SUMPRODUCT(K23:K25,'Parameters, general'!$B$13:$B$15) -> 0.080267913 | L26: =SUMPRODUCT(L23:L25,'Parameters, general'!$B$13:$B$15) -> 0.23905649 | M26: =SUMPRODUCT(M23:M25,'Parameters, general'!$B$13:$B$15) -> 0 | N26: =SUMPRODUCT(N23:N25,'Parameters, general'!$B$13:$B$15) -> 0 | O26: =SUMPRODUCT(O23:O25,'Parameters, general'!$B$13:$B$15) -> 0.20550283 | ... S26: =SUMPRODUCT(S23:S25,'Parameters, general'!$B$13:$B$15) -> 0.50751618 | V26: =SUMPRODUCT(V23:V25,'Parameters, general'!$B$13:$B$15) -> 0.36573312 | W26: =SUMPRODUCT(W23:W25,'Parameters, general'!$B$13:$B$15) -> 1.0848955 | Y26: =SUM(H26:Q26) -> 3.523305 | Z26: ='CO2 per kg feed'!F65+'CH4 per kg feed'!F65*CF_GWP_CH4_fossil+'N2O per kg feed'!F65*CF_GWP_N2O -> 0.55339912
A27: A01QV | B27: Bovine muscle | C27: Meat and meat products | D27: Ireland | E27: IE | F27: CO2 | G27: =SUM(H27:W27) -> 3.460468 | H27: ='CO2 per kg feed'!G77*FCR_bonefree_incl_parents_IE-Excreted_N_after_losses_IE*Manure_repl_factor_IE*(EF_min_fert_BAT_CO2*Frac_BAT_IE+EF_min_fert_AN_CO2*Frac_AN_IE) -> 0.25444396 | I27: ='CO2 per kg feed'!H77*FCR_bonefree_incl_parents_IE -> 0.15431962 | J27: ='CO2 per kg feed'!I77*FCR_bonefree_incl_parents_IE -> 1.2050269 | L27: ='CO2 per kg feed'!K77*FCR_bonefree_incl_parents_IE -> 0.23178064 | N27: ='CO2 per kg feed'!M77*FCR_bonefree_incl_parents_IE -> 0 | O27: ='CO2 per kg feed'!N77*FCR_bonefree_incl_parents_IE -> 0.19911574 | P27: ='CO2 per kg feed'!O77*FCR_bonefree_incl_parents_IE -> 0.096183216 | Q27: ='CO2 per kg feed'!P77*FCR_bonefree_incl_parents_IE -> 0.071861229 | V27: =Energy_stables_IE/Bonefree_outof_CW_IE*(Share_heating_IE*(Share_biofuels_IE*EF_biofuels_CO2+(1-Share_biofuels_IE)*EF_oil_CO2)+(1-Share_heating_IE)*EF_el_CO2_IE) -> 0.32050681 | W27: =(Energy_slaughter_el_IE*EF_el_CO2_IE+Energy_slaughter_oil_IE*EF_oil_CO2)/Bonefree_outof_CW_IE -> 0.92722985
A28: A01QV | B28: Bovine muscle | C28: Meat and meat products | D28: Ireland | E28: IE | F28: CH4 | G28: =SUM(H28:W28) -> 0.040357896 | H28: ='CH4 per kg feed'!G77*FCR_bonefree_incl_parents_IE-Excreted_N_after_losses_IE*Manure_repl_factor_IE*(EF_min_fert_BAT_CH4*Frac_BAT_IE+EF_min_fert_AN_CH4*Frac_AN_IE) -> 0.00030406944 | I28: ='CH4 per kg feed'!H77*FCR_bonefree_incl_parents_IE -> 0.00052655737 | L28: ='CH4 per kg feed'!K77*FCR_bonefree_incl_parents_IE -> 0.00010043929 | N28: ='CH4 per kg feed'!M77*FCR_bonefree_incl_parents_IE -> 0 | O28: ='CH4 per kg feed'!N77*FCR_bonefree_incl_parents_IE -> 6.9538829e-05 | P28: ='CH4 per kg feed'!O77*FCR_bonefree_incl_parents_IE -> 0 | Q28: ='CH4 per kg feed'!P77*FCR_bonefree_incl_parents_IE -> 0.0050657669 | R28: =(Production!G37+Production!G38+Production!G39*4/12)*EF_ent_ferm_IE -> 0.010683314 | S28: =SUM(T28:U28) -> 0.011236433 | T28: =Manure!Y32 -> 0.011236433 | V28: =Energy_stables_IE/Bonefree_outof_CW_IE*(Share_heating_IE*(Share_biofuels_IE*EF_biofuel_CH4+(1-Share_biofuels_IE)*EF_oil_CH4)+(1-Share_heating_IE)*EF_el_CH4_IE) -> 0.00027329544 | W28: =(Energy_slaughter_el_IE*EF_el_CH4_IE+Energy_slaughter_oil_IE*EF_oil_CH4)/Bonefree_outof_CW_IE -> 0.00086204992
A29: A01QV | B29: Bovine muscle | C29: Meat and meat products | D29: Ireland | E29: IE | F29: N2O | G29: =SUM(H29:W29) -> 0.0054587305 | H29: ='N2O per kg feed'!G77*FCR_bonefree_incl_parents_IE-Excreted_N_after_losses_IE*Manure_repl_factor_IE*(EF_min_fert_BAT_N2O*Frac_BAT_IE+EF_min_fert_AN_N2O*Frac_AN_IE) -> 0.00057716801 | I29: ='N2O per kg feed'!H77*FCR_bonefree_incl_parents_IE -> 7.6689942e-05 | J29: ='N2O per kg feed'!I77*FCR_bonefree_incl_parents_IE-Excreted_N_after_losses_IE*Manure_repl_factor_IE*EF_N2O_diff_IE -> 0.0029402166 | K29: =J29*EF_indirect_N2O_IE -> 0.00029402166 | L29: ='N2O per kg feed'!K77*FCR_bonefree_incl_parents_IE -> 1.5687779e-05 | N29: ='N2O per kg feed'!M77*FCR_bonefree_incl_parents_IE -> 0 | O29: ='N2O per kg feed'!N77*FCR_bonefree_incl_parents_IE -> 1.5805256e-05 | P29: ='N2O per kg feed'!O77*FCR_bonefree_incl_parents_IE -> 0 | Q29: ='N2O per kg feed'!P77*FCR_bonefree_incl_parents_IE -> 0.00021885712 | S29: =SUM(T29:U29) -> 0.00063249264 | T29: =Manure!Y88*44/28 -> 0.00010126684 | U29: =NH3_per_kg_IE*17/14*Manure!V117 -> 0.00053122581 | V29: =Energy_stables_IE/Bonefree_outof_CW_IE*(Share_heating_IE*(Share_biofuels_IE*EF_biofuel_N2O+(1-Share_biofuels_IE)*EF_oil_N2O)+(1-Share_heating_IE)*EF_el_N2O_IE) -> 2.1496515e-05 | W29: =(Energy_slaughter_el_IE*EF_el_N2O_IE+Energy_slaughter_oil_IE*EF_oil_N2O)/Bonefree_outof_CW_IE -> 3.3802335e-05
A30: A01QV | B30: Bovine muscle | C30: Meat and meat products | D30: Ireland | E30: IE | F30: CO2e | G30: =SUM(H30:W30) -> 5.6458505 | H30: =SUMPRODUCT(H27:H29,'Parameters, general'!$B$13:$B$15) -> 0.42107209 | I30: =SUMPRODUCT(I27:I29,'Parameters, general'!$B$13:$B$15) -> 0.19094738 | J30: =SUMPRODUCT(J27:J29,'Parameters, general'!$B$13:$B$15) -> 2.007706 | K30: =SUMPRODUCT(K27:K29,'Parameters, general'!$B$13:$B$15) -> 0.080267913 | L30: =SUMPRODUCT(L27:L29,'Parameters, general'!$B$13:$B$15) -> 0.23905649 | M30: =SUMPRODUCT(M27:M29,'Parameters, general'!$B$13:$B$15) -> 0 | N30: =SUMPRODUCT(N27:N29,'Parameters, general'!$B$13:$B$15) -> 0 | O30: =SUMPRODUCT(O27:O29,'Parameters, general'!$B$13:$B$15) -> 0.20550283 | ... S30: =SUMPRODUCT(S27:S29,'Parameters, general'!$B$13:$B$15) -> 0.50751618 | V30: =SUMPRODUCT(V27:V29,'Parameters, general'!$B$13:$B$15) -> 0.33451957 | W30: =SUMPRODUCT(W27:W29,'Parameters, general'!$B$13:$B$15) -> 0.96214697 | Y30: =SUM(H30:Q30) -> 3.523305 | Z30: ='CO2 per kg feed'!F77+'CH4 per kg feed'!F77*CF_GWP_CH4_fossil+'N2O per kg feed'!F77*CF_GWP_N2O -> 0.55339912
A31: A01QV | B31: Bovine muscle | C31: Meat and meat products | D31: Italy | E31: IT | F31: CO2 | G31: =SUM(H31:W31) -> 3.4279729 | H31: ='CO2 per kg feed'!G89*FCR_bonefree_incl_parents_IT-Excreted_N_after_losses_IT*Manure_repl_factor_IT*(EF_min_fert_BAT_CO2*Frac_BAT_IT+EF_min_fert_AN_CO2*Frac_AN_IT) -> 0.25444396 | I31: ='CO2 per kg feed'!H89*FCR_bonefree_incl_parents_IT -> 0.15431962 | J31: ='CO2 per kg feed'!I89*FCR_bonefree_incl_parents_IT -> 1.2050269 | L31: ='CO2 per kg feed'!K89*FCR_bonefree_incl_parents_IT -> 0.23178064 | N31: ='CO2 per kg feed'!M89*FCR_bonefree_incl_parents_IT -> 0 | O31: ='CO2 per kg feed'!N89*FCR_bonefree_incl_parents_IT -> 0.19911574 | P31: ='CO2 per kg feed'!O89*FCR_bonefree_incl_parents_IT -> 0.096183216 | Q31: ='CO2 per kg feed'!P89*FCR_bonefree_incl_parents_IT -> 0.071861229 | V31: =Energy_stables_IT/Bonefree_outof_CW_IT*(Share_heating_IT*(Share_biofuels_IT*EF_biofuels_CO2+(1-Share_biofuels_IT)*EF_oil_CO2)+(1-Share_heating_IT)*EF_el_CO2_IT) -> 0.31391891 | W31: =(Energy_slaughter_el_IT*EF_el_CO2_IT+Energy_slaughter_oil_IT*EF_oil_CO2)/Bonefree_outof_CW_IT -> 0.90132266
A32: A01QV | B32: Bovine muscle | C32: Meat and meat products | D32: Italy | E32: IT | F32: CH4 | G32: =SUM(H32:W32) -> 0.051942095 | H32: ='CH4 per kg feed'!G89*FCR_bonefree_incl_parents_IT-Excreted_N_after_losses_IT*Manure_repl_factor_IT*(EF_min_fert_BAT_CH4*Frac_BAT_IT+EF_min_fert_AN_CH4*Frac_AN_IT) -> 0.00030406944 | I32: ='CH4 per kg feed'!H89*FCR_bonefree_incl_parents_IT -> 0.00052655737 | L32: ='CH4 per kg feed'!K89*FCR_bonefree_incl_parents_IT -> 0.00010043929 | N32: ='CH4 per kg feed'!M89*FCR_bonefree_incl_parents_IT -> 0 | O32: ='CH4 per kg feed'!N89*FCR_bonefree_incl_parents_IT -> 6.9538829e-05 | P32: ='CH4 per kg feed'!O89*FCR_bonefree_incl_parents_IT -> 0 | Q32: ='CH4 per kg feed'!P89*FCR_bonefree_incl_parents_IT -> 0.013795039 | R32: =(Production!H37+Production!H38+Production!H39*4/12)*EF_ent_ferm_IT -> 0.010683314 | S32: =SUM(T32:U32) -> 0.011236433 | T32: =Manure!AC32 -> 0.011236433 | V32: =Energy_stables_IT/Bonefree_outof_CW_IT*(Share_heating_IT*(Share_biofuels_IT*EF_biofuel_CH4+(1-Share_biofuels_IT)*EF_oil_CH4)+(1-Share_heating_IT)*EF_el_CH4_IT) -> 0.00085209001 | W32: =(Energy_slaughter_el_IT*EF_el_CH4_IT+Energy_slaughter_oil_IT*EF_oil_CH4)/Bonefree_outof_CW_IT -> 0.0031381818
A33: A01QV | B33: Bovine muscle | C33: Meat and meat products | D33: Italy | E33: IT | F33: N2O | G33: =SUM(H33:W33) -> 0.00546353 | H33: ='N2O per kg feed'!G89*FCR_bonefree_incl_parents_IT-Excreted_N_after_losses_IT*Manure_repl_factor_IT*(EF_min_fert_BAT_N2O*Frac_BAT_IT+EF_min_fert_AN_N2O*Frac_AN_IT) -> 0.00057716801 | I33: ='N2O per kg feed'!H89*FCR_bonefree_incl_parents_IT -> 7.6689942e-05 | J33: ='N2O per kg feed'!I89*FCR_bonefree_incl_parents_IT-Excreted_N_after_losses_IT*Manure_repl_factor_IT*EF_N2O_diff_IT -> 0.0029402166 | K33: =J33*EF_indirect_N2O_IT -> 0.00029402166 | L33: ='N2O per kg feed'!K89*FCR_bonefree_incl_parents_IT -> 1.5687779e-05 | N33: ='N2O per kg feed'!M89*FCR_bonefree_incl_parents_IT -> 0 | O33: ='N2O per kg feed'!N89*FCR_bonefree_incl_parents_IT -> 1.5805256e-05 | P33: ='N2O per kg feed'!O89*FCR_bonefree_incl_parents_IT -> 0 | Q33: ='N2O per kg feed'!P89*FCR_bonefree_incl_parents_IT -> 0.00021885712 | S33: =SUM(T33:U33) -> 0.00063249264 | T33: =Manure!AC88*44/28 -> 0.00010126684 | U33: =NH3_per_kg_IT*17/14*Manure!Z117 -> 0.00053122581 | V33: =Energy_stables_IT/Bonefree_outof_CW_IT*(Share_heating_IT*(Share_biofuels_IT*EF_biofuel_N2O+(1-Share_biofuels_IT)*EF_oil_N2O)+(1-Share_heating_IT)*EF_el_N2O_IT) -> 2.2469536e-05 | W33: =(Energy_slaughter_el_IT*EF_el_N2O_IT+Energy_slaughter_oil_IT*EF_oil_N2O)/Bonefree_outof_CW_IT -> 3.7628778e-05
A34: A01QV | B34: Bovine muscle | C34: Meat and meat products | D34: Italy | E34: IT | F34: CO2e | G34: =SUM(H34:W34) -> 5.9598748 | H34: =SUMPRODUCT(H31:H33,'Parameters, general'!$B$13:$B$15) -> 0.42107209 | I34: =SUMPRODUCT(I31:I33,'Parameters, general'!$B$13:$B$15) -> 0.19094738 | J34: =SUMPRODUCT(J31:J33,'Parameters, general'!$B$13:$B$15) -> 2.007706 | K34: =SUMPRODUCT(K31:K33,'Parameters, general'!$B$13:$B$15) -> 0.080267913 | L34: =SUMPRODUCT(L31:L33,'Parameters, general'!$B$13:$B$15) -> 0.23905649 | M34: =SUMPRODUCT(M31:M33,'Parameters, general'!$B$13:$B$15) -> 0 | N34: =SUMPRODUCT(N31:N33,'Parameters, general'!$B$13:$B$15) -> 0 | O34: =SUMPRODUCT(O31:O33,'Parameters, general'!$B$13:$B$15) -> 0.20550283 | ... S34: =SUMPRODUCT(S31:S33,'Parameters, general'!$B$13:$B$15) -> 0.50751618 | V34: =SUMPRODUCT(V31:V33,'Parameters, general'!$B$13:$B$15) -> 0.34544537 | W34: =SUMPRODUCT(W31:W33,'Parameters, general'!$B$13:$B$15) -> 1.0051131 | Y34: =SUM(H34:Q34) -> 3.7834373 | Z34: ='CO2 per kg feed'!F89+'CH4 per kg feed'!F89*CF_GWP_CH4_fossil+'N2O per kg feed'!F89*CF_GWP_N2O -> 0.59225411
A35: A01QV | B35: Bovine muscle | C35: Meat and meat products | D35: Netherland | E35: NL | F35: CO2 | G35: =SUM(H35:W35) -> 3.7056833 | H35: ='CO2 per kg feed'!G101*FCR_bonefree_incl_parents_NL-Excreted_N_after_losses_NL*Manure_repl_factor_NL*(EF_min_fert_BAT_CO2*Frac_BAT_NL+EF_min_fert_AN_CO2*Frac_AN_NL) -> 0.25444396 | I35: ='CO2 per kg feed'!H101*FCR_bonefree_incl_parents_NL -> 0.15431962 | J35: ='CO2 per kg feed'!I101*FCR_bonefree_incl_parents_NL -> 1.2050269 | L35: ='CO2 per kg feed'!K101*FCR_bonefree_incl_parents_NL -> 0.23178064 | N35: ='CO2 per kg feed'!M101*FCR_bonefree_incl_parents_NL -> 0 | O35: ='CO2 per kg feed'!N101*FCR_bonefree_incl_parents_NL -> 0.19911574 | P35: ='CO2 per kg feed'!O101*FCR_bonefree_incl_parents_NL -> 0.096183216 | Q35: ='CO2 per kg feed'!P101*FCR_bonefree_incl_parents_NL -> 0.071861229 | V35: =Energy_stables_NL/Bonefree_outof_CW_NL*(Share_heating_NL*(Share_biofuels_NL*EF_biofuels_CO2+(1-Share_biofuels_NL)*EF_oil_CO2)+(1-Share_heating_NL)*EF_el_CO2_NL) -> 0.37022063 | W35: =(Energy_slaughter_el_NL*EF_el_CO2_NL+Energy_slaughter_oil_NL*EF_oil_CO2)/Bonefree_outof_CW_NL -> 1.1227313
A36: A01QV | B36: Bovine muscle | C36: Meat and meat products | D36: Netherland | E36: NL | F36: CH4 | G36: =SUM(H36:W36) -> 0.041670168 | H36: ='CH4 per kg feed'!G101*FCR_bonefree_incl_parents_NL-Excreted_N_after_losses_NL*Manure_repl_factor_NL*(EF_min_fert_BAT_CH4*Frac_BAT_NL+EF_min_fert_AN_CH4*Frac_AN_NL) -> 0.00030406944 | I36: ='CH4 per kg feed'!H101*FCR_bonefree_incl_parents_NL -> 0.00052655737 | L36: ='CH4 per kg feed'!K101*FCR_bonefree_incl_parents_NL -> 0.00010043929 | N36: ='CH4 per kg feed'!M101*FCR_bonefree_incl_parents_NL -> 0 | O36: ='CH4 per kg feed'!N101*FCR_bonefree_incl_parents_NL -> 6.9538829e-05 | P36: ='CH4 per kg feed'!O101*FCR_bonefree_incl_parents_NL -> 0 | Q36: ='CH4 per kg feed'!P101*FCR_bonefree_incl_parents_NL -> 0.0050657669 | R36: =(Production!I37+Production!I38+Production!I39*4/12)*EF_ent_ferm_NL -> 0.010683314 | S36: =SUM(T36:U36) -> 0.011236433 | T36: =Manure!AG32 -> 0.011236433 | V36: =Energy_stables_NL/Bonefree_outof_CW_NL*(Share_heating_NL*(Share_biofuels_NL*EF_biofuel_CH4+(1-Share_biofuels_NL)*EF_oil_CH4)+(1-Share_heating_NL)*EF_el_CH4_NL) -> 0.00053933926 | W36: =(Energy_slaughter_el_NL*EF_el_CH4_NL+Energy_slaughter_oil_NL*EF_oil_CH4)/Bonefree_outof_CW_NL -> 0.0019082775
A37: A01QV | B37: Bovine muscle | C37: Meat and meat products | D37: Netherland | E37: NL | F37: N2O | G37: =SUM(H37:W37) -> 0.0054717008 | H37: ='N2O per kg feed'!G101*FCR_bonefree_incl_parents_NL-Excreted_N_after_losses_NL*Manure_repl_factor_NL*(EF_min_fert_BAT_N2O*Frac_BAT_NL+EF_min_fert_AN_N2O*Frac_AN_NL) -> 0.00057716801 | I37: ='N2O per kg feed'!H101*FCR_bonefree_incl_parents_NL -> 7.6689942e-05 | J37: ='N2O per kg feed'!I101*FCR_bonefree_incl_parents_NL-Excreted_N_after_losses_NL*Manure_repl_factor_NL*EF_N2O_diff_NL -> 0.0029402166 | K37: =J37*EF_indirect_N2O_NL -> 0.00029402166 | L37: ='N2O per kg feed'!K101*FCR_bonefree_incl_parents_NL -> 1.5687779e-05 | N37: ='N2O per kg feed'!M101*FCR_bonefree_incl_parents_NL -> 0 | O37: ='N2O per kg feed'!N101*FCR_bonefree_incl_parents_NL -> 1.5805256e-05 | P37: ='N2O per kg feed'!O101*FCR_bonefree_incl_parents_NL -> 0 | Q37: ='N2O per kg feed'!P101*FCR_bonefree_incl_parents_NL -> 0.00021885712 | S37: =SUM(T37:U37) -> 0.00063249264 | T37: =Manure!AG88*44/28 -> 0.00010126684 | U37: =NH3_per_kg_NL*17/14*Manure!AD117 -> 0.00053122581 | V37: =Energy_stables_NL/Bonefree_outof_CW_NL*(Share_heating_NL*(Share_biofuels_NL*EF_biofuel_N2O+(1-Share_biofuels_NL)*EF_oil_N2O)+(1-Share_heating_NL)*EF_el_N2O_NL) -> 2.412605e-05 | W37: =(Energy_slaughter_el_NL*EF_el_N2O_NL+Energy_slaughter_oil_NL*EF_oil_N2O)/Bonefree_outof_CW_NL -> 4.4143083e-05
A38: A01QV | B38: Bovine muscle | C38: Meat and meat products | D38: Netherland | E38: NL | F38: CO2e | G38: =SUM(H38:W38) -> 5.9337124 | H38: =SUMPRODUCT(H35:H37,'Parameters, general'!$B$13:$B$15) -> 0.42107209 | I38: =SUMPRODUCT(I35:I37,'Parameters, general'!$B$13:$B$15) -> 0.19094738 | J38: =SUMPRODUCT(J35:J37,'Parameters, general'!$B$13:$B$15) -> 2.007706 | K38: =SUMPRODUCT(K35:K37,'Parameters, general'!$B$13:$B$15) -> 0.080267913 | L38: =SUMPRODUCT(L35:L37,'Parameters, general'!$B$13:$B$15) -> 0.23905649 | M38: =SUMPRODUCT(M35:M37,'Parameters, general'!$B$13:$B$15) -> 0 | N38: =SUMPRODUCT(N35:N37,'Parameters, general'!$B$13:$B$15) -> 0 | O38: =SUMPRODUCT(O35:O37,'Parameters, general'!$B$13:$B$15) -> 0.20550283 | ... S38: =SUMPRODUCT(S35:S37,'Parameters, general'!$B$13:$B$15) -> 0.50751618 | V38: =SUMPRODUCT(V35:V37,'Parameters, general'!$B$13:$B$15) -> 0.39287935 | W38: =SUMPRODUCT(W35:W37,'Parameters, general'!$B$13:$B$15) -> 1.1916491 | Y38: =SUM(H38:Q38) -> 3.523305 | Z38: ='CO2 per kg feed'!F101+'CH4 per kg feed'!F101*CF_GWP_CH4_fossil+'N2O per kg feed'!F101*CF_GWP_N2O -> 0.55339912
A39: A01QV | B39: Bovine muscle | C39: Meat and meat products | D39: Poland | E39: PL | F39: CO2 | G39: =SUM(H39:W39) -> 4.8251701 | H39: ='CO2 per kg feed'!G113*FCR_bonefree_incl_parents_PL-Excreted_N_after_losses_PL*Manure_repl_factor_PL*(EF_min_fert_BAT_CO2*Frac_BAT_PL+EF_min_fert_AN_CO2*Frac_AN_PL) -> 0.25444396 | I39: ='CO2 per kg feed'!H113*FCR_bonefree_incl_parents_PL -> 0.15431962 | J39: ='CO2 per kg feed'!I113*FCR_bonefree_incl_parents_PL -> 1.2050269 | L39: ='CO2 per kg feed'!K113*FCR_bonefree_incl_parents_PL -> 0.23178064 | N39: ='CO2 per kg feed'!M113*FCR_bonefree_incl_parents_PL -> 0 | O39: ='CO2 per kg feed'!N113*FCR_bonefree_incl_parents_PL -> 0.19911574 | P39: ='CO2 per kg feed'!O113*FCR_bonefree_incl_parents_PL -> 0.096183216 | Q39: ='CO2 per kg feed'!P113*FCR_bonefree_incl_parents_PL -> 0.071861229 | V39: =Energy_stables_PL/Bonefree_outof_CW_PL*(Share_heating_PL*(Share_biofuels_PL*EF_biofuels_CO2+(1-Share_biofuels_PL)*EF_oil_CO2)+(1-Share_heating_PL)*EF_el_CO2_PL) -> 0.5971802 | W39: =(Energy_slaughter_el_PL*EF_el_CO2_PL+Energy_slaughter_oil_PL*EF_oil_CO2)/Bonefree_outof_CW_PL -> 2.0152586
A40: A01QV | B40: Bovine muscle | C40: Meat and meat products | D40: Poland | E40: PL | F40: CH4 | G40: =SUM(H40:W40) -> 0.052494572 | H40: ='CH4 per kg feed'!G113*FCR_bonefree_incl_parents_PL-Excreted_N_after_losses_PL*Manure_repl_factor_PL*(EF_min_fert_BAT_CH4*Frac_BAT_PL+EF_min_fert_AN_CH4*Frac_AN_PL) -> 0.00030406944 | I40: ='CH4 per kg feed'!H113*FCR_bonefree_incl_parents_PL -> 0.00052655737 | L40: ='CH4 per kg feed'!K113*FCR_bonefree_incl_parents_PL -> 0.00010043929 | N40: ='CH4 per kg feed'!M113*FCR_bonefree_incl_parents_PL -> 0 | O40: ='CH4 per kg feed'!N113*FCR_bonefree_incl_parents_PL -> 6.9538829e-05 | P40: ='CH4 per kg feed'!O113*FCR_bonefree_incl_parents_PL -> 0 | Q40: ='CH4 per kg feed'!P113*FCR_bonefree_incl_parents_PL -> 0.013795039 | R40: =(Production!J37+Production!J38+Production!J39*4/12)*EF_ent_ferm_PL -> 0.010683314 | S40: =SUM(T40:U40) -> 0.011236433 | T40: =Manure!AK32 -> 0.011236433 | V40: =Energy_stables_PL/Bonefree_outof_CW_PL*(Share_heating_PL*(Share_biofuels_PL*EF_biofuel_CH4+(1-Share_biofuels_PL)*EF_oil_CH4)+(1-Share_heating_PL)*EF_el_CH4_PL) -> 0.00096409668 | W40: =(Energy_slaughter_el_PL*EF_el_CH4_PL+Energy_slaughter_oil_PL*EF_oil_CH4)/Bonefree_outof_CW_PL -> 0.0035786524
...

Sheet Production
A2: Production system | B2: DK | C2: FR | D2: DE | E2: GR | F2: HU | G2: IE | H2: IT | I2: NL | J2: PL | K2: ES | L2: SE | M2: GB
B3: Denmark | C3: France | D3: Germany | E3: Greece | F3: Hungary | G3: Ireland | H3: Italy | I3: Netherlands | J3: Poland | K3: Spain | L3: Sweden | M3: UK
A4: Animals in production per year (no)
A5: Sows | B5: 1 | C5: 1 | D5: 1 | E5: 1 | F5: 1 | G5: 1 | H5: 1 | I5: 1 | J5: 1 | K5: 1 | L5: 1 | M5: 1 | O5: Number of sows (any number can be used here)
A6: Recruitment sows | B6: =B5*'Parameters, country spec'!B12/100 -> 0.55 | C6: =C5*'Parameters, country spec'!C12/100 -> 0.55 | D6: =D5*'Parameters, country spec'!D12/100 -> 0.55 | E6: =E5*'Parameters, country spec'!E12/100 -> 0.55 | F6: =F5*'Parameters, country spec'!F12/100 -> 0.55 | G6: =G5*'Parameters, country spec'!G12/100 -> 0.55 | H6: =H5*'Parameters, country spec'!H12/100 -> 0.55 | I6: =I5*'Parameters, country spec'!I12/100 -> 0.55 | ... M6: =M5*'Parameters, country spec'!M12/100 -> 0.55 | O6: Number of sows * recruitment rate
A7: Boars | B7: =B5*Boars_per_sow -> 0.012143013 | C7: =C5*Boars_per_sow -> 0.012143013 | D7: =D5*Boars_per_sow -> 0.012143013 | E7: =E5*Boars_per_sow -> 0.012143013 | F7: =F5*Boars_per_sow -> 0.012143013 | G7: =G5*Boars_per_sow -> 0.012143013 | H7: =H5*Boars_per_sow -> 0.012143013 | I7: =I5*Boars_per_sow -> 0.012143013 | ... M7: =M5*Boars_per_sow -> 0.012143013
A8: Fattening pigs | B8: =B5*'Parameters, country spec'!B16-B6 -> 22 | C8: =C5*'Parameters, country spec'!C16-C6 -> 22 | D8: =D5*'Parameters, country spec'!D16-D6 -> 22 | E8: =E5*'Parameters, country spec'!E16-E6 -> 22 | F8: =F5*'Parameters, country spec'!F16-F6 -> 22 | G8: =G5*'Parameters, country spec'!G16-G6 -> 22 | H8: =H5*'Parameters, country spec'!H16-H6 -> 22 | I8: =I5*'Parameters, country spec'!I16-I6 -> 22 | ... M8: =M5*'Parameters, country spec'!M16-M6 -> 22 | O8: Number of sows * live piglets at weaning - recruitment sows
A9: Piglets | B9: =B5*'Parameters, country spec'!B16 -> 22.55 | C9: =C5*'Parameters, country spec'!C16 -> 22.55 | D9: =D5*'Parameters, country spec'!D16 -> 22.55 | E9: =E5*'Parameters, country spec'!E16 -> 22.55 | F9: =F5*'Parameters, country spec'!F16 -> 22.55 | G9: =G5*'Parameters, country spec'!G16 -> 22.55 | H9: =H5*'Parameters, country spec'!H16 -> 22.55 | I9: =I5*'Parameters, country spec'!I16 -> 22.55 | ... M9: =M5*'Parameters, country spec'!M16 -> 22.55 | O9: Number of sows * live piglets at weaning
A10: Total: | B10: =SUM(B5:B8) -> 23.562143 | C10: =SUM(C5:C8) -> 23.562143 | D10: =SUM(D5:D8) -> 23.562143 | E10: =SUM(E5:E8) -> 23.562143 | F10: =SUM(F5:F8) -> 23.562143 | G10: =SUM(G5:G8) -> 23.562143 | H10: =SUM(H5:H8) -> 23.562143 | I10: =SUM(I5:I8) -> 23.562143 | ... M10: =SUM(M5:M8) -> 23.562143
A11: Animals slaughtered per year (no)
A12: Sows | B12: =B5*'Parameters, country spec'!B12/100*(1-'Parameters, country spec'!B18/100) -> 0.53113947 | C12: =C5*'Parameters, country spec'!C12/100*(1-'Parameters, country spec'!C18/100) -> 0.53113947 | D12: =D5*'Parameters, country spec'!D12/100*(1-'Parameters, country spec'!D18/100) -> 0.53113947 | E12: =E5*'Parameters, country spec'!E12/100*(1-'Parameters, country spec'!E18/100) -> 0.53113947 | F12: =F5*'Parameters, country spec'!F12/100*(1-'Parameters, country spec'!F18/100) -> 0.53113947 | G12: =G5*'Parameters, country spec'!G12/100*(1-'Parameters, country spec'!G18/100) -> 0.53113947 | H12: =H5*'Parameters, country spec'!H12/100*(1-'Parameters, country spec'!H18/100) -> 0.53113947 | I12: =I5*'Parameters, country spec'!I12/100*(1-'Parameters, country spec'!I18/100) -> 0.53113947 | ... M12: =M5*'Parameters, country spec'!M12/100*(1-'Parameters, country spec'!M18/100) -> 0.53113947 | O12: Number of sows * recruitment rate * (1 - mortality sows)
A13: Boars | B13: =B7*(1-'Parameters, country spec'!B18/100) -> 0.011726606 | C13: =C7*(1-'Parameters, country spec'!C18/100) -> 0.011726606 | D13: =D7*(1-'Parameters, country spec'!D18/100) -> 0.011726606 | E13: =E7*(1-'Parameters, country spec'!E18/100) -> 0.011726606 | F13: =F7*(1-'Parameters, country spec'!F18/100) -> 0.011726606 | G13: =G7*(1-'Parameters, country spec'!G18/100) -> 0.011726606 | H13: =H7*(1-'Parameters, country spec'!H18/100) -> 0.011726606 | I13: =I7*(1-'Parameters, country spec'!I18/100) -> 0.011726606 | ... M13: =M7*(1-'Parameters, country spec'!M18/100) -> 0.011726606
A14: Fattening pigs | B14: =B8*(1-'Parameters, country spec'!B6/100)*(1-'Parameters, country spec'!B7/100) -> 21.497476 | C14: =C8*(1-'Parameters, country spec'!C6/100)*(1-'Parameters, country spec'!C7/100) -> 21.497476 | D14: =D8*(1-'Parameters, country spec'!D6/100)*(1-'Parameters, country spec'!D7/100) -> 21.497476 | E14: =E8*(1-'Parameters, country spec'!E6/100)*(1-'Parameters, country spec'!E7/100) -> 21.497476 | F14: =F8*(1-'Parameters, country spec'!F6/100)*(1-'Parameters, country spec'!F7/100) -> 21.497476 | G14: =G8*(1-'Parameters, country spec'!G6/100)*(1-'Parameters, country spec'!G7/100) -> 21.497476 | H14: =H8*(1-'Parameters, country spec'!H6/100)*(1-'Parameters, country spec'!H7/100) -> 21.497476 | I14: =I8*(1-'Parameters, country spec'!I6/100)*(1-'Parameters, country spec'!I7/100) -> 21.497476 | ... M14: =M8*(1-'Parameters, country spec'!M6/100)*(1-'Parameters, country spec'!M7/100) -> 21.497476 | O14: Number of slaughter pig adjusted for mortality and rejection at slaughter
A15: Total: | B15: =SUM(B12:B14) -> 22.040342 | C15: =SUM(C12:C14) -> 22.040342 | D15: =SUM(D12:D14) -> 22.040342 | E15: =SUM(E12:E14) -> 22.040342 | F15: =SUM(F12:F14) -> 22.040342 | G15: =SUM(G12:G14) -> 22.040342 | H15: =SUM(H12:H14) -> 22.040342 | I15: =SUM(I12:I14) -> 22.040342 | ... M15: =SUM(M12:M14) -> 22.040342
A16: Meat produced (kg CW)
A17: Sows | B17: =B12*'Parameters, country spec'!B10 -> 95.339535 | C17: =C12*'Parameters, country spec'!C10 -> 95.339535 | D17: =D12*'Parameters, country spec'!D10 -> 95.339535 | E17: =E12*'Parameters, country spec'!E10 -> 95.339535 | F17: =F12*'Parameters, country spec'!F10 -> 95.339535 | G17: =G12*'Parameters, country spec'!G10 -> 95.339535 | H17: =H12*'Parameters, country spec'!H10 -> 95.339535 | I17: =I12*'Parameters, country spec'!I10 -> 95.339535 | ... M17: =M12*'Parameters, country spec'!M10 -> 95.339535 | O17: Number of animals * slaughtering weight
A18: Boars | B18: =B13*'Parameters, country spec'!B9 -> 1.0741571 | C18: =C13*'Parameters, country spec'!C9 -> 1.0741571 | D18: =D13*'Parameters, country spec'!D9 -> 1.0741571 | E18: =E13*'Parameters, country spec'!E9 -> 1.0741571 | F18: =F13*'Parameters, country spec'!F9 -> 1.0741571 | G18: =G13*'Parameters, country spec'!G9 -> 1.0741571 | H18: =H13*'Parameters, country spec'!H9 -> 1.0741571 | I18: =I13*'Parameters, country spec'!I9 -> 1.0741571 | ... M18: =M13*'Parameters, country spec'!M9 -> 1.0741571
A19: Fattening pigs | B19: =B14*'Parameters, country spec'!B9 -> 1969.1688 | C19: =C14*'Parameters, country spec'!C9 -> 1969.1688 | D19: =D14*'Parameters, country spec'!D9 -> 1969.1688 | E19: =E14*'Parameters, country spec'!E9 -> 1969.1688 | F19: =F14*'Parameters, country spec'!F9 -> 1969.1688 | G19: =G14*'Parameters, country spec'!G9 -> 1969.1688 | H19: =H14*'Parameters, country spec'!H9 -> 1969.1688 | I19: =I14*'Parameters, country spec'!I9 -> 1969.1688 | ... M19: =M14*'Parameters, country spec'!M9 -> 1969.1688
A20: Total: | B20: =SUM(B17:B19) -> 2065.5825 | C20: =SUM(C17:C19) -> 2065.5825 | D20: =SUM(D17:D19) -> 2065.5825 | E20: =SUM(E17:E19) -> 2065.5825 | F20: =SUM(F17:F19) -> 2065.5825 | G20: =SUM(G17:G19) -> 2065.5825 | H20: =SUM(H17:H19) -> 2065.5825 | I20: =SUM(I17:I19) -> 2065.5825 | ... M20: =SUM(M17:M19) -> 2065.5825
A21: Meat produced (kg bonefree)
