Workbook
Name Ability_to_perceive_handling: 'Parameters, general'!#REF!
Name AF_beef: 'Parameters, general'!$B$38
Name AF_calves: 'Parameters, general'!$B$39
Name AF_milk: 'Parameters, general'!$B$37
Name Boars_per_sow: 'Parameters D24m, country spec'!#REF!
Name Boars_per_sow: 'Parameters SH, country spec'!#REF!
Name CF_GWP_CH4_biog: 'Parameters, general'!$B$25
Name CF_GWP_CH4_biogenic: 'Parameters, general'!$B$25
Name CF_GWP_CH4_fossil: 'Parameters, general'!$B$24
Name CF_GWP_N2O: 'Parameters, general'!$B$26
Name Crop_data: 'Forage crops, CF'!$A$6:$Z$80
Name Crop_data: 'Forage, input data per ha'!#REF!
Name Crop_data: 'Forage crops, footprints'!$A$6:$Z$22
Name Crop_data_codes: 'Forage crops, CF'!$A$71:$A$155
Name Crop_data_codes: 'Forage, input data per ha'!#REF!
Name Crop_data_codes: 'Forage crops, footprints'!$A$23:$A$39
Name EF_biofuel_CH4: 'Parameters, general'!$C$6
Name EF_biofuel_N2O: 'Parameters, general'!$D$6
Name EF_biofuels_CO2: 'Parameters, general'!$B$6
Name EF_capital_goods_CH4: 'Parameters, general'!$C$10
Name EF_capital_goods_CO2: 'Parameters, general'!$B$10
Name EF_capital_goods_N2O: 'Parameters, general'!$D$10
Name EF_diesel_CH4: 'Parameters, general'!$C$7
Name EF_diesel_CO2: 'Parameters, general'!$B$7
Name EF_diesel_N2O: 'Parameters, general'!$D$7
Name EF_el_CH4_DE: 'Parameters D24m, country spec'!$D$45
Name EF_el_CH4_DE: 'Parameters SH, country spec'!$D$67
Name EF_el_CH4_DK: 'Parameters D24m, country spec'!$B$45
Name EF_el_CH4_DK: 'Parameters SH, country spec'!$B$67
Name EF_el_CH4_ES: 'Parameters D24m, country spec'!$K$45
Name EF_el_CH4_ES: 'Parameters SH, country spec'!$K$67
Name EF_el_CH4_FR: 'Parameters D24m, country spec'!$C$45
Name EF_el_CH4_FR: 'Parameters SH, country spec'!$C$67
Name EF_el_CH4_GR: 'Parameters D24m, country spec'!$E$45
Name EF_el_CH4_GR: 'Parameters SH, country spec'!$E$67
Name EF_el_CH4_HU: 'Parameters D24m, country spec'!$F$45
Name EF_el_CH4_HU: 'Parameters SH, country spec'!$F$67
Name EF_el_CH4_IE: 'Parameters D24m, country spec'!$G$45
Name EF_el_CH4_IE: 'Parameters SH, country spec'!$G$67
Name EF_el_CH4_IT: 'Parameters D24m, country spec'!$H$45
Name EF_el_CH4_IT: 'Parameters SH, country spec'!$H$67
Name EF_el_CH4_NL: 'Parameters D24m, country spec'!$I$45
Name EF_el_CH4_NL: 'Parameters SH, country spec'!$I$67
Name EF_el_CH4_PL: 'Parameters D24m, country spec'!$J$45
Name EF_el_CH4_PL: 'Parameters SH, country spec'!$J$67
Name EF_el_CH4_SE: 'Parameters D24m, country spec'!$L$45
Name EF_el_CH4_SE: 'Parameters SH, country spec'!$L$67
Name EF_el_CO2_DE: 'Parameters D24m, country spec'!$D$44
Name EF_el_CO2_DE: 'Parameters SH, country spec'!$D$66
Name EF_el_CO2_DK: 'Parameters D24m, country spec'!$B$44
Name EF_el_CO2_DK: 'Parameters SH, country spec'!$B$66
Name EF_el_CO2_ES: 'Parameters D24m, country spec'!$K$44
Name EF_el_CO2_ES: 'Parameters SH, country spec'!$K$66
Name EF_el_CO2_FR: 'Parameters D24m, country spec'!$C$44
Name EF_el_CO2_FR: 'Parameters SH, country spec'!$C$66
Name EF_el_CO2_GR: 'Parameters D24m, country spec'!$E$44
Name EF_el_CO2_GR: 'Parameters SH, country spec'!$E$66
Name EF_el_CO2_HU: 'Parameters D24m, country spec'!$F$44
Name EF_el_CO2_HU: 'Parameters SH, country spec'!$F$66
Name EF_el_CO2_IE: 'Parameters D24m, country spec'!$G$44

Sheet README
A2: Read me
A4: This is a file that contains…
A7: Har räknat enligt vår metod men sen justerat foderåtgången och energianv för att siffrorna ska stämma ungefär med Arlas. Har också använt Emmas gamla allokeringsfaktor (0.93 istället för 0.87 som är den nya som Ludvig letat underlag till)
A8: https://www.arla.se/4a9c19/globalassets/om-arla/hallbarhet/klimatberakningar/climate-check-report-2022.pdf
A9: Så detta behöver tittas på igen.
A10: Har heller inte justerat för N i foderodlingen, men kanske ska det inte göras här där vi har mycket vall för vallens fixering beräknas med hänsyn tagen till gödsling - behöver tänka litet mer på detta!!!
A17: Color codes:
B19: Results
B20: Sheets for input
B21: Intermediate calculations
A26: Att göra:
A27: Se om det går att få ut en foderstat för denna från Frankrike https://productions-animales.org/article/view/5396
A28: Justera till landsspecifik energianvändning https://www.mdpi.com/2076-3417/12/4/2142
A29: Vattenanvändning per land - OBS att detta är för anv i stallar, inte foderodlingen

Sheet Figures
A2: Figures
A4: Greenhouse gas emission for bonefree meat across countries, to farmgate, no waste
B6: Production of mineral fertilizer | C6: Production of capital goods | D6: Emissions from soil | E6: Energy use cropping | F6: Energy use for feed processing | G6: Land use change emissions | H6: Feed transports | I6: Enteric fermentation | J6: Manure management | K6: Energy use in stables | L6: Energy use for slaughter | M6: Tot
A7: Poland | B7: ='GHG det D24m, results per kg'!H51 -> 0.00019236004 | C7: ='GHG det D24m, results per kg'!I51 -> 3.862496e-05 | D7: ='GHG det D24m, results per kg'!J51+'GHG det D24m, results per kg'!K51 -> 1.8555134 | E7: ='GHG det D24m, results per kg'!L51+'GHG det D24m, results per kg'!N51 -> 8.8828979e-05 | F7: ='GHG det D24m, results per kg'!O51+'GHG det D24m, results per kg'!Q51 -> 6.0736585e-05 | G7: ='GHG det D24m, results per kg'!P51 -> 0 | H7: ='GHG det D24m, results per kg'!R51 -> 0 | I7: ='GHG det D24m, results per kg'!S51 -> 17.925311 | J7: ='GHG det D24m, results per kg'!T51 -> 8.2603 | K7: ='GHG det D24m, results per kg'!W51 -> 8.8201906e-05 | L7: ='GHG det D24m, results per kg'!X51 -> 0 | M7: =SUM(B7:L7) -> 28.041593
A8: Netherlands | B8: ='GHG det D24m, results per kg'!H46 -> 0.00015316974 | C8: ='GHG det D24m, results per kg'!I46 -> 3.5544885e-05 | D8: ='GHG det D24m, results per kg'!J46+'GHG det D24m, results per kg'!K46 -> 1.8773186 | E8: ='GHG det D24m, results per kg'!L46+'GHG det D24m, results per kg'!N46 -> 2.659238e-05 | F8: ='GHG det D24m, results per kg'!O46+'GHG det D24m, results per kg'!Q46 -> 4.9333331e-05 | G8: ='GHG det D24m, results per kg'!P46 -> 2.648564e-05 | H8: ='GHG det D24m, results per kg'!R46 -> 4.2387316e-05 | I8: ='GHG det D24m, results per kg'!S46 -> 17.925311 | J8: ='GHG det D24m, results per kg'!T46 -> 3.8252729 | K8: ='GHG det D24m, results per kg'!W46 -> 4.5237464e-05 | L8: ='GHG det D24m, results per kg'!X46 -> 0 | M8: =SUM(B8:L8) -> 23.628281
A9: Hungary | B9: ='GHG det D24m, results per kg'!H31 -> 6.7798992e-05 | C9: ='GHG det D24m, results per kg'!I31 -> 3.3197388e-05 | D9: ='GHG det D24m, results per kg'!J31+'GHG det D24m, results per kg'!K31 -> 2.1258548 | E9: ='GHG det D24m, results per kg'!L31+'GHG det D24m, results per kg'!N31 -> 3.4113098e-05 | F9: ='GHG det D24m, results per kg'!O31+'GHG det D24m, results per kg'!Q31 -> 7.9145178e-05 | G9: ='GHG det D24m, results per kg'!P31 -> 3.7824017e-05 | H9: ='GHG det D24m, results per kg'!R31 -> 6.7177442e-05 | I9: ='GHG det D24m, results per kg'!S31 -> 17.925311 | J9: ='GHG det D24m, results per kg'!T31 -> 12.159007 | K9: ='GHG det D24m, results per kg'!W31 -> 4.0363861e-05 | L9: ='GHG det D24m, results per kg'!X31 -> 0 | M9: =SUM(B9:L9) -> 32.210533
A10: Greece | B10: ='GHG det D24m, results per kg'!H26 -> 0.00010611674 | C10: ='GHG det D24m, results per kg'!I26 -> 3.672199e-05 | D10: ='GHG det D24m, results per kg'!J26+'GHG det D24m, results per kg'!K26 -> 2.2980533 | E10: ='GHG det D24m, results per kg'!L26+'GHG det D24m, results per kg'!N26 -> 5.1856024e-05 | F10: ='GHG det D24m, results per kg'!O26+'GHG det D24m, results per kg'!Q26 -> 4.6890398e-05 | G10: ='GHG det D24m, results per kg'!P26 -> 2.6432019e-05 | H10: ='GHG det D24m, results per kg'!R26 -> 2.2419988e-05 | I10: ='GHG det D24m, results per kg'!S26 -> 11.950207 | J10: ='GHG det D24m, results per kg'!T26 -> 8.852268 | K10: ='GHG det D24m, results per kg'!W26 -> 5.8204796e-05 | L10: ='GHG det D24m, results per kg'!X26 -> 0 | M10: =SUM(B10:L10) -> 23.100877
A11: Denmark | B11: ='GHG det D24m, results per kg'!H11 -> 0.4036147 | C11: ='GHG det D24m, results per kg'!I11 -> 0.64420807 | D11: ='GHG det D24m, results per kg'!J11+'GHG det D24m, results per kg'!K11 -> 0.75655943 | E11: ='GHG det D24m, results per kg'!L11+'GHG det D24m, results per kg'!N11 -> 0.30554911 | F11: ='GHG det D24m, results per kg'!O11+'GHG det D24m, results per kg'!Q11 -> 1.8236672 | G11: ='GHG det D24m, results per kg'!P11 -> 0.31030816 | H11: ='GHG det D24m, results per kg'!R11 -> 1.7657977 | I11: ='GHG det D24m, results per kg'!S11 -> 11.950207 | J11: ='GHG det D24m, results per kg'!T11 -> 12.61813 | K11: ='GHG det D24m, results per kg'!W11 -> 3.3277279e-05 | L11: ='GHG det D24m, results per kg'!X11 -> 0 | M11: =SUM(B11:L11) -> 30.578076
A12: Italy | B12: ='GHG det D24m, results per kg'!H41 -> 4.395822e-05 | C12: ='GHG det D24m, results per kg'!I41 -> 3.1533416e-05 | D12: ='GHG det D24m, results per kg'!J41+'GHG det D24m, results per kg'!K41 -> 1.8591551 | E12: ='GHG det D24m, results per kg'!L41+'GHG det D24m, results per kg'!N41 -> 1.6006975e-05 | F12: ='GHG det D24m, results per kg'!O41+'GHG det D24m, results per kg'!Q41 -> 4.4572524e-05 | G12: ='GHG det D24m, results per kg'!P41 -> 1.6949289e-05 | H12: ='GHG det D24m, results per kg'!R41 -> 4.0870606e-05 | I12: ='GHG det D24m, results per kg'!S41 -> 17.925311 | J12: ='GHG det D24m, results per kg'!T41 -> 15.454116 | K12: ='GHG det D24m, results per kg'!W41 -> 3.6721572e-05 | L12: ='GHG det D24m, results per kg'!X41 -> 0 | M12: =SUM(B12:L12) -> 35.238813
A13: Germany | B13: ='GHG det D24m, results per kg'!H21 -> 4.2402988e-05 | C13: ='GHG det D24m, results per kg'!I21 -> 3.5798974e-05 | D13: ='GHG det D24m, results per kg'!J21+'GHG det D24m, results per kg'!K21 -> 1.8160986 | E13: ='GHG det D24m, results per kg'!L21+'GHG det D24m, results per kg'!N21 -> 1.8463706e-05 | F13: ='GHG det D24m, results per kg'!O21+'GHG det D24m, results per kg'!Q21 -> 7.4174057e-05 | G13: ='GHG det D24m, results per kg'!P21 -> 1.243351e-05 | H13: ='GHG det D24m, results per kg'!R21 -> 7.0866684e-05 | I13: ='GHG det D24m, results per kg'!S21 -> 11.950207 | J13: ='GHG det D24m, results per kg'!T21 -> 9.8820862 | K13: ='GHG det D24m, results per kg'!W21 -> 4.2182548e-05 | L13: ='GHG det D24m, results per kg'!X21 -> 0 | M13: =SUM(B13:L13) -> 23.648689
A14: France | B14: ='GHG det D24m, results per kg'!H16 -> 5.3389885e-05 | C14: ='GHG det D24m, results per kg'!I16 -> 3.4500625e-05 | D14: ='GHG det D24m, results per kg'!J16+'GHG det D24m, results per kg'!K16 -> 2.9876336 | E14: ='GHG det D24m, results per kg'!L16+'GHG det D24m, results per kg'!N16 -> 2.104844e-05 | F14: ='GHG det D24m, results per kg'!O16+'GHG det D24m, results per kg'!Q16 -> 7.5547199e-05 | G14: ='GHG det D24m, results per kg'!P16 -> 1.3536749e-05 | H14: ='GHG det D24m, results per kg'!R16 -> 6.9612815e-05 | I14: ='GHG det D24m, results per kg'!S16 -> 11.950207 | J14: ='GHG det D24m, results per kg'!T16 -> 7.1892402 | K14: ='GHG det D24m, results per kg'!W16 -> 8.2893794e-06 | L14: ='GHG det D24m, results per kg'!X16 -> 0 | M14: =SUM(B14:L14) -> 22.127357
A15: Ireland | B15: ='GHG det D24m, results per kg'!H36 -> 6.7760233e-05 | C15: ='GHG det D24m, results per kg'!I36 -> 3.6682197e-05 | D15: ='GHG det D24m, results per kg'!J36+'GHG det D24m, results per kg'!K36 -> 9.5007545e-05 | E15: ='GHG det D24m, results per kg'!L36+'GHG det D24m, results per kg'!N36 -> 2.08138e-05 | F15: ='GHG det D24m, results per kg'!O36+'GHG det D24m, results per kg'!Q36 -> 1.28374e-05 | G15: ='GHG det D24m, results per kg'!P36 -> 4.285782e-06 | H15: ='GHG det D24m, results per kg'!R36 -> 2.9903501e-06 | I15: ='GHG det D24m, results per kg'!S36 -> 17.925311 | J15: ='GHG det D24m, results per kg'!T36 -> 10.057514 | K15: ='GHG det D24m, results per kg'!W36 -> 3.4760046e-05 | L15: ='GHG det D24m, results per kg'!X36 -> 0 | M15: =SUM(B15:L15) -> 27.9831
A16: Spain | B16: ='GHG det D24m, results per kg'!H56 -> 2.9296861e-05 | C16: ='GHG det D24m, results per kg'!I56 -> 3.6422997e-05 | D16: ='GHG det D24m, results per kg'!J56+'GHG det D24m, results per kg'!K56 -> 3.0522077 | E16: ='GHG det D24m, results per kg'!L56+'GHG det D24m, results per kg'!N56 -> 4.5913257e-05 | F16: ='GHG det D24m, results per kg'!O56+'GHG det D24m, results per kg'!Q56 -> 3.9805576e-05 | G16: ='GHG det D24m, results per kg'!P56 -> 3.2394772e-05 | H16: ='GHG det D24m, results per kg'!R56 -> 2.0934974e-05 | I16: ='GHG det D24m, results per kg'!S56 -> 17.925311 | J16: ='GHG det D24m, results per kg'!T56 -> 5.5727209 | K16: ='GHG det D24m, results per kg'!W56 -> 2.5204943e-05 | L16: ='GHG det D24m, results per kg'!X56 -> 0 | M16: =SUM(B16:L16) -> 26.55047
A17: Sweden | B17: ='GHG det D24m, results per kg'!H61 -> 6.3671741e-05 | C17: ='GHG det D24m, results per kg'!I61 -> 7.6939164e-05 | D17: ='GHG det D24m, results per kg'!J61+'GHG det D24m, results per kg'!K61 -> 2.2613075 | E17: ='GHG det D24m, results per kg'!L61+'GHG det D24m, results per kg'!N61 -> 6.4098373e-05 | F17: ='GHG det D24m, results per kg'!O61+'GHG det D24m, results per kg'!Q61 -> 0.00016083524 | G17: ='GHG det D24m, results per kg'!P61 -> 0 | H17: ='GHG det D24m, results per kg'!R61 -> 0.00016083524 | I17: ='GHG det D24m, results per kg'!S61 -> 17.925311 | J17: ='GHG det D24m, results per kg'!T61 -> 6.9810155 | K17: ='GHG det D24m, results per kg'!W61 -> 7.9676651e-06 | L17: ='GHG det D24m, results per kg'!X61 -> 0 | M17: =SUM(B17:L17) -> 27.168169
A22: Comparison Ahlgren et al 2022
A24: Klimat | D24: Metan | E24: Gödsel | F24: Lustgas, mark | G24: Energi | H24: Övrigt | I24: Summa
A25: Köttrasstut | B25: Gns | C25: CW | D25: 13.594746 | E25: 8.2248391 | F25: 3.0881712 | G25: 2.3886298 | H25: 2.1976081 | I25: 29.493994
C26: Benfritt | D26: =D25/0.69 -> 19.702531 | E26: =E25/0.69 -> 11.920057 | F26: =F25/0.69 -> 4.4756104 | G26: =G25/0.69 -> 3.4617823 | H26: =H25/0.69 -> 3.1849393 | I26: =I25/0.69 -> 42.744919
A27: Our data | D27: =I17 -> 17.925311 | E27: =J17 -> 6.9810155 | F27: =D17 -> 2.2613075 | G27: =B17+E17+F17+K17 -> 0.00029657302 | H27: =C17+H17+L17 -> 0.0002377744 | I27: =SUM(D27:H27) -> 27.168169
A29: Ammoniak
A30: Köttrasstut | B30: Gns | C30: =0.2/0.695 -> 0.28776978
A31: Our data | C31: ='Footprints, results per kg'!R17 -> 0.20378096 | D31: Lower value explained by us using TAN for manure calculations
A33: Cropland
A34: Köttrasstut | B34: Gns | C34: 30 | D34: We use lower yields for ley | Z34: Ranking here: | AB34: Ranking Lesshen:
A35: Our data | C35: ='Footprints, results per kg'!L17 -> 40.815647
Z36: Germany | AB36: Poland
Z37: Spain | AB37: Ireland
Z38: Netherlands | AB38: Hungary
Z39: Greece | AB39: Greece
Z40: Italy | AB40: Netherlands
Z41: Poland | AB41: Italy
Z42: Ireland | AB42: Spain
Z43: Denmark | AB43: Germany
Z44: Hungary | AB44: France
Z45: France | AB45: Sweden
Z46: Sweden | AB46: Denmakr
A52: Comparison Moberg et al 2019
B54: Moberg 2019 Suckler only | C54: Moberg 2020 All beef | D54: Our data
A55: Land use | B55: =33.9/0.7 -> 48.428571 | C55: 36 | D55: ='Footprints, results per kg'!L17 -> 40.815647
A56: N input | B56: =0.99/0.7 -> 1.4142857 | C56: 1.1 | D56: ='Footprints, results per kg'!M17 -> 0.52594899
...

Sheet Footprints, results per kg
A2: Footprints (per kg of meat) | T2: **Values inserted directly here, no formula in this excel sheet
A5: Animal products | F5: Climate | L5: Land | M5: Nitrogen | N5: Phosphorus | O5: Water | P5: Pesticides | Q5: Biodiversity | R5: Ammonia | S5: Labour | T5: Animal welfare** | U5: Use of antibiotics**
A6: Code | B6: Name | C6: Category | D6: Country | E6: Country code | F6: Carbon footprint, kg CO2e/kg | G6: Carbon dioxide, kg CO2/kg | H6: Methane, fossil, kg CH4/kg | I6: Methane, biogenic, kg CH4/kg | J6: Nitrous oxide, kg N2O/kg | K6: HFCs, kg HFCs/kg | L6: Cropland use, m2/kg | M6: New N input, kg N/kg | N6: New P input, kg P/kg | O6: Blue freshwater use, m3/kg | P6: Pesticide use, g a.i./kg | Q6: Extinction rate, E/MSY/kg | R6: Ammonia emission, kg NH3/kg | S6: Labour requirements, h/kg | T6: Animal welfare index per kg of bonefree meat | U6: Antibiotics use indicator/kg
A7: 21111.02 | B7: Bovine meat | C7: Red meat | D7: Denmark | E7: DK | F7: ='GHG det D24m, results per kg'!G11 -> 30.578076 | G7: ='GHG det D24m, results per kg'!G7 -> 3.4321149 | H7: ='GHG det D24m, results per kg'!G8 -> 0.030930649 | I7: ='GHG det D24m, results per kg'!G9 -> 1.0810815 | J7: ='GHG det D24m, results per kg'!G10 -> 0.035359551 | L7: =('Production SH'!$B$5*'Parameters SH, country spec'!$B$51*'EFP per kg feed'!F20+('Production SH'!$B$6+'Production SH'!$B$7)*'Parameters SH, country spec'!$B$52*'EFP per kg feed'!F21)/'Production SH'!$B$21 -> 34.08104 | M7: =('Production SH'!$B$5*'Parameters SH, country spec'!$B$51*'EFP per kg feed'!G20+('Production SH'!$B$6+'Production SH'!$B$7)*'Parameters SH, country spec'!$B$52*'EFP per kg feed'!G21-Excreted_N_after_losses_DK*Manure_repl_factor_DK)/'Production SH'!$B$21 -> 0.39287936 | N7: =('Production SH'!$B$5*'Parameters SH, country spec'!$B$51*'EFP per kg feed'!H20+('Production SH'!$B$6+'Production SH'!$B$7)*'Parameters SH, country spec'!$B$52*'EFP per kg feed'!H21)/'Production SH'!$B$21 -> 0.015901371 | O7: =('Production SH'!$B$5*'Parameters SH, country spec'!$B$51*'EFP per kg feed'!I20+('Production SH'!$B$6+'Production SH'!$B$7)*'Parameters SH, country spec'!$B$52*'EFP per kg feed'!I21)/'Production SH'!$B$21 -> 0.0075699251 | P7: =('Production SH'!$B$5*'Parameters SH, country spec'!$B$51*'EFP per kg feed'!J20+('Production SH'!$B$6+'Production SH'!$B$7)*'Parameters SH, country spec'!$B$52*'EFP per kg feed'!J21)/'Production SH'!$B$21 -> 0.81908393 | Q7: =('Production SH'!$B$5*'Parameters SH, country spec'!$B$51*'EFP per kg feed'!K20+('Production SH'!$B$6+'Production SH'!$B$7)*'Parameters SH, country spec'!$B$52*'EFP per kg feed'!K21)/'Production SH'!$B$21 -> 2.2515202e-09 | R7: =('Production SH'!$B$5*'Parameters SH, country spec'!$B$51*'EFP per kg feed'!L20+('Production SH'!$B$6+'Production SH'!$B$7)*'Parameters SH, country spec'!$B$52*'EFP per kg feed'!L21+Manure!C159)/'Production SH'!$B$21 -> 0.21242026 | T7: 0.27753208 | U7: 16.134752
A8: 21111.02 | B8: Bovine meat | C8: Red meat | D8: France | E8: FR | F8: ='GHG det D24m, results per kg'!G16 -> 22.127357 | G8: ='GHG det D24m, results per kg'!G12 -> 0.00018768247 | H8: ='GHG det D24m, results per kg'!G13 -> 1.3119089e-06 | I8: ='GHG det D24m, results per kg'!G14 -> 0.65194238 | J8: ='GHG det D24m, results per kg'!G15 -> 0.042908155 | L8: =('Production SH'!$C$5*'Parameters SH, country spec'!$C$51*'EFP per kg feed'!F38+('Production SH'!$C$6+'Production SH'!$C$7)*'Parameters SH, country spec'!$C$52*'EFP per kg feed'!F39)/'Production SH'!$C$21 -> 31.844587 | M8: =('Production SH'!$C$5*'Parameters SH, country spec'!$C$51*'EFP per kg feed'!G38+('Production SH'!$C$6+'Production SH'!$C$7)*'Parameters SH, country spec'!$C$52*'EFP per kg feed'!G39-Excreted_N_after_losses_FR*Manure_repl_factor_FR)/'Production SH'!C21 -> 0.4844356 | N8: =('Production SH'!$C$5*'Parameters SH, country spec'!$C$51*'EFP per kg feed'!H38+('Production SH'!$C$6+'Production SH'!$C$7)*'Parameters SH, country spec'!$C$52*'EFP per kg feed'!H39)/'Production SH'!C21 -> 0.03806657 | O8: =('Production SH'!$C$5*'Parameters SH, country spec'!$C$51*'EFP per kg feed'!I38+('Production SH'!$C$6+'Production SH'!$C$7)*'Parameters SH, country spec'!$C$52*'EFP per kg feed'!I39)/'Production SH'!C21 -> 0.32179062 | P8: =('Production SH'!$C$5*'Parameters SH, country spec'!$C$51*'EFP per kg feed'!J38+('Production SH'!$C$6+'Production SH'!$C$7)*'Parameters SH, country spec'!$C$52*'EFP per kg feed'!J39)/'Production SH'!C21 -> 1.7710491 | Q8: =('Production SH'!$C$5*'Parameters SH, country spec'!$C$51*'EFP per kg feed'!K38+('Production SH'!$C$6+'Production SH'!$C$7)*'Parameters SH, country spec'!$C$52*'EFP per kg feed'!K39)/'Production SH'!C21 -> 1.4163738e-08 | R8: =('Production SH'!$C$5*'Parameters SH, country spec'!$C$51*'EFP per kg feed'!L38+('Production SH'!$C$6+'Production SH'!$C$7)*'Parameters SH, country spec'!$C$52*'EFP per kg feed'!L39+Manure!E159)/'Production SH'!C21 -> 0.21144096 | T8: 0.2641407 | U8: 31.990695
A9: 21111.02 | B9: Bovine meat | C9: Red meat | D9: Germany | E9: DE | F9: ='GHG det D24m, results per kg'!G21 -> 23.648689 | G9: ='GHG det D24m, results per kg'!G17 -> 0.00020927458 | H9: ='GHG det D24m, results per kg'!G18 -> 1.3756598e-06 | I9: ='GHG det D24m, results per kg'!G19 -> 0.85358322 | J9: ='GHG det D24m, results per kg'!G20 -> 0.038402115 | L9: =('Production SH'!$D$5*'Parameters SH, country spec'!$D$51*'EFP per kg feed'!F56+('Production SH'!$D$6+'Production SH'!$D$7)*'Parameters SH, country spec'!$D$52*'EFP per kg feed'!F57)/'Production SH'!$D$21 -> 23.347185 | M9: =('Production SH'!$D$5*'Parameters SH, country spec'!$D$51*'EFP per kg feed'!G56+('Production SH'!$D$6+'Production SH'!$D$7)*'Parameters SH, country spec'!$D$52*'EFP per kg feed'!G57-Excreted_N_after_losses_DE*Manure_repl_factor_DE)/'Production SH'!$D$21 -> 0.39972859 | N9: =('Production SH'!$D$5*'Parameters SH, country spec'!$D$51*'EFP per kg feed'!H56+('Production SH'!$D$6+'Production SH'!$D$7)*'Parameters SH, country spec'!$D$52*'EFP per kg feed'!H57)/'Production SH'!$D$21 -> 0.019914925 | O9: =('Production SH'!$D$5*'Parameters SH, country spec'!$D$51*'EFP per kg feed'!I56+('Production SH'!$D$6+'Production SH'!$D$7)*'Parameters SH, country spec'!$D$52*'EFP per kg feed'!I57)/'Production SH'!$D$21 -> 0.01057813 | P9: =('Production SH'!$D$5*'Parameters SH, country spec'!$D$51*'EFP per kg feed'!J56+('Production SH'!$D$6+'Production SH'!$D$7)*'Parameters SH, country spec'!$D$52*'EFP per kg feed'!J57)/'Production SH'!$D$21 -> 1.0667984 | Q9: =('Production SH'!$D$5*'Parameters SH, country spec'!$D$51*'EFP per kg feed'!K56+('Production SH'!$D$6+'Production SH'!$D$7)*'Parameters SH, country spec'!$D$52*'EFP per kg feed'!K57)/'Production SH'!$D$21 -> 2.1447671e-09 | R9: =('Production SH'!$D$5*'Parameters SH, country spec'!$D$51*'EFP per kg feed'!L56+('Production SH'!$D$6+'Production SH'!$D$7)*'Parameters SH, country spec'!$D$52*'EFP per kg feed'!L57+Manure!G159)/'Production SH'!$D$21 -> 0.23798811 | T9: 0.29846858 | U9: 42.008022
A10: 21111.02 | B10: Bovine meat | C10: Red meat | D10: Greece | E10: GR | F10: ='GHG det D24m, results per kg'!G26 -> 23.100877 | G10: ='GHG det D24m, results per kg'!G22 -> 0.00027776225 | H10: ='GHG det D24m, results per kg'!G23 -> 7.4082387e-07 | I10: ='GHG det D24m, results per kg'!G24 -> 0.68873345 | J10: ='GHG det D24m, results per kg'!G25 -> 0.048926895 | L10: =('Production SH'!$E$5*'Parameters SH, country spec'!$E$51*'EFP per kg feed'!F74+('Production SH'!$E$6+'Production SH'!$E$7)*'Parameters SH, country spec'!$E$52*'EFP per kg feed'!F75)/'Production SH'!$E$21 -> 50.543518 | M10: =('Production SH'!$E$5*'Parameters SH, country spec'!$E$51*'EFP per kg feed'!G74+('Production SH'!$E$6+'Production SH'!$E$7)*'Parameters SH, country spec'!$E$52*'EFP per kg feed'!G75-Excreted_N_after_losses_GR*Manure_repl_factor_GR)/'Production SH'!$E$21 -> 0.7703812 | N10: =('Production SH'!$E$5*'Parameters SH, country spec'!$E$51*'EFP per kg feed'!H74+('Production SH'!$E$6+'Production SH'!$E$7)*'Parameters SH, country spec'!$E$52*'EFP per kg feed'!H75)/'Production SH'!$E$21 -> 0.086791142 | O10: =('Production SH'!$E$5*'Parameters SH, country spec'!$E$51*'EFP per kg feed'!I74+('Production SH'!$E$6+'Production SH'!$E$7)*'Parameters SH, country spec'!$E$52*'EFP per kg feed'!I75)/'Production SH'!$E$21 -> 3.5421374 | P10: =('Production SH'!$E$5*'Parameters SH, country spec'!$E$51*'EFP per kg feed'!J74+('Production SH'!$E$6+'Production SH'!$E$7)*'Parameters SH, country spec'!$E$52*'EFP per kg feed'!J75)/'Production SH'!$E$21 -> 2.1588876 | Q10: =('Production SH'!$E$5*'Parameters SH, country spec'!$E$51*'EFP per kg feed'!K74+('Production SH'!$E$6+'Production SH'!$E$7)*'Parameters SH, country spec'!$E$52*'EFP per kg feed'!K75)/'Production SH'!$E$21 -> 1.8194035e-07 | R10: =('Production SH'!$E$5*'Parameters SH, country spec'!$E$51*'EFP per kg feed'!L74+('Production SH'!$E$6+'Production SH'!$E$7)*'Parameters SH, country spec'!$E$52*'EFP per kg feed'!L75+Manure!I159)/'Production SH'!$E$21 -> 0.25261273 | T10: 0.3029637 | U10: 93.603378
A11: 21111.02 | B11: Bovine meat | C11: Red meat | D11: Hungary | E11: HU | F11: ='GHG det D24m, results per kg'!G31 -> 32.210533 | G11: ='GHG det D24m, results per kg'!G27 -> 0.00026618239 | H11: ='GHG det D24m, results per kg'!G28 -> 1.3488347e-06 | I11: ='GHG det D24m, results per kg'!G29 -> 1.1150113 | J11: ='GHG det D24m, results per kg'!G30 -> 0.052248825 | L11: =('Production SH'!$F$5*'Parameters SH, country spec'!$F$51*'EFP per kg feed'!F92+('Production SH'!$F$6+'Production SH'!$F$7)*'Parameters SH, country spec'!$F$52*'EFP per kg feed'!F93)/'Production SH'!$F$21 -> 56.245852 | M11: =('Production SH'!$F$5*'Parameters SH, country spec'!$F$51*'EFP per kg feed'!G92+('Production SH'!$F$6+'Production SH'!$F$7)*'Parameters SH, country spec'!$F$52*'EFP per kg feed'!G93-Excreted_N_after_losses_HU*Manure_repl_factor_HU)/'Production SH'!$F$21 -> 0.78493395 | N11: =('Production SH'!$F$5*'Parameters SH, country spec'!$F$51*'EFP per kg feed'!H92+('Production SH'!$F$6+'Production SH'!$F$7)*'Parameters SH, country spec'!$F$52*'EFP per kg feed'!H93)/'Production SH'!$F$21 -> 0.063892939 | O11: =('Production SH'!$F$5*'Parameters SH, country spec'!$F$51*'EFP per kg feed'!I92+('Production SH'!$F$6+'Production SH'!$F$7)*'Parameters SH, country spec'!$F$52*'EFP per kg feed'!I93)/'Production SH'!$F$21 -> 0.10215178 | P11: =('Production SH'!$F$5*'Parameters SH, country spec'!$F$51*'EFP per kg feed'!J92+('Production SH'!$F$6+'Production SH'!$F$7)*'Parameters SH, country spec'!$F$52*'EFP per kg feed'!J93)/'Production SH'!$F$21 -> 2.5117464 | Q11: =('Production SH'!$F$5*'Parameters SH, country spec'!$F$51*'EFP per kg feed'!K92+('Production SH'!$F$6+'Production SH'!$F$7)*'Parameters SH, country spec'!$F$52*'EFP per kg feed'!K93)/'Production SH'!$F$21 -> 4.619002e-09 | R11: =('Production SH'!$F$5*'Parameters SH, country spec'!$F$51*'EFP per kg feed'!L92+('Production SH'!$F$6+'Production SH'!$F$7)*'Parameters SH, country spec'!$F$52*'EFP per kg feed'!L93+Manure!K159)/'Production SH'!$F$21 -> 0.2560465 | T11: 0.32014997 | U11: 86.193346
A12: 21111.02 | B12: Bovine meat | C12: Red meat | D12: Ireland | E12: IE | F12: ='GHG det D24m, results per kg'!G36 -> 27.9831 | G12: ='GHG det D24m, results per kg'!G32 -> 0.00014497157 | H12: ='GHG det D24m, results per kg'!G33 -> 2.831295e-07 | I12: ='GHG det D24m, results per kg'!G34 -> 1.0769229 | J12: ='GHG det D24m, results per kg'!G35 -> 0.032833487 | L12: =('Production SH'!$G$5*'Parameters SH, country spec'!$G$51*'EFP per kg feed'!F110+('Production SH'!$G$6+'Production SH'!$G$7)*'Parameters SH, country spec'!$G$52*'EFP per kg feed'!F111)/'Production SH'!$G$21 -> 12.175918 | M12: =('Production SH'!$G$5*'Parameters SH, country spec'!$G$51*'EFP per kg feed'!G110+('Production SH'!$G$6+'Production SH'!$G$7)*'Parameters SH, country spec'!$G$52*'EFP per kg feed'!G111-Excreted_N_after_losses_IE*Manure_repl_factor_IE)/'Production SH'!$G$21 -> 0.59205666 | N12: =('Production SH'!$G$5*'Parameters SH, country spec'!$G$51*'EFP per kg feed'!H110+('Production SH'!$G$6+'Production SH'!$G$7)*'Parameters SH, country spec'!$G$52*'EFP per kg feed'!H111)/'Production SH'!$G$21 -> 0.03635779 | O12: =('Production SH'!$G$5*'Parameters SH, country spec'!$G$51*'EFP per kg feed'!I110+('Production SH'!$G$6+'Production SH'!$G$7)*'Parameters SH, country spec'!$G$52*'EFP per kg feed'!I111)/'Production SH'!$G$21 -> 0.0020039052 | P12: =('Production SH'!$G$5*'Parameters SH, country spec'!$G$51*'EFP per kg feed'!J110+('Production SH'!$G$6+'Production SH'!$G$7)*'Parameters SH, country spec'!$G$52*'EFP per kg feed'!J111)/'Production SH'!$G$21 -> 3.1877282 | Q12: =('Production SH'!$G$5*'Parameters SH, country spec'!$G$51*'EFP per kg feed'!K110+('Production SH'!$G$6+'Production SH'!$G$7)*'Parameters SH, country spec'!$G$52*'EFP per kg feed'!K111)/'Production SH'!$G$21 -> 1.4763208e-09 | R12: =('Production SH'!$G$5*'Parameters SH, country spec'!$G$51*'EFP per kg feed'!L110+('Production SH'!$G$6+'Production SH'!$G$7)*'Parameters SH, country spec'!$G$52*'EFP per kg feed'!L111+Manure!M159)/'Production SH'!$G$21 -> 0.21090107 | T12: 0.27007153 | U12: 33.680254
A13: 21111.02 | B13: Bovine meat | C13: Red meat | D13: Italy | E13: IT | F13: ='GHG det D24m, results per kg'!G41 -> 35.238813 | G13: ='GHG det D24m, results per kg'!G37 -> 0.00016863493 | H13: ='GHG det D24m, results per kg'!G38 -> 9.4642631e-07 | I13: ='GHG det D24m, results per kg'!G39 -> 1.3328476 | J13: ='GHG det D24m, results per kg'!G40 -> 0.053867572 | L13: =('Production SH'!$H$5*'Parameters SH, country spec'!$H$51*'EFP per kg feed'!F128+('Production SH'!$H$6+'Production SH'!$H$7)*'Parameters SH, country spec'!$H$52*'EFP per kg feed'!F129)/'Production SH'!$H$21 -> 27.739742 | M13: =('Production SH'!$H$5*'Parameters SH, country spec'!$H$51*'EFP per kg feed'!G128+('Production SH'!$H$6+'Production SH'!$H$7)*'Parameters SH, country spec'!$H$52*'EFP per kg feed'!G129-Excreted_N_after_losses_IT*Manure_repl_factor_IT)/'Production SH'!$H$21 -> 0.56074497 | N13: =('Production SH'!$H$5*'Parameters SH, country spec'!$H$51*'EFP per kg feed'!H128+('Production SH'!$H$6+'Production SH'!$H$7)*'Parameters SH, country spec'!$H$52*'EFP per kg feed'!H129)/'Production SH'!$H$21 -> 0.034194009 | O13: =('Production SH'!$H$5*'Parameters SH, country spec'!$H$51*'EFP per kg feed'!I128+('Production SH'!$H$6+'Production SH'!$H$7)*'Parameters SH, country spec'!$H$52*'EFP per kg feed'!I129)/'Production SH'!$H$21 -> 0.35701409 | P13: =('Production SH'!$H$5*'Parameters SH, country spec'!$H$51*'EFP per kg feed'!J128+('Production SH'!$H$6+'Production SH'!$H$7)*'Parameters SH, country spec'!$H$52*'EFP per kg feed'!J129)/'Production SH'!$H$21 -> 1.9859225 | Q13: =('Production SH'!$H$5*'Parameters SH, country spec'!$H$51*'EFP per kg feed'!K128+('Production SH'!$H$6+'Production SH'!$H$7)*'Parameters SH, country spec'!$H$52*'EFP per kg feed'!K129)/'Production SH'!$H$21 -> 5.7557651e-08 | R13: =('Production SH'!$H$5*'Parameters SH, country spec'!$H$51*'EFP per kg feed'!L128+('Production SH'!$H$6+'Production SH'!$H$7)*'Parameters SH, country spec'!$H$52*'EFP per kg feed'!L129+Manure!O159)/'Production SH'!$H$21 -> 0.33933506 | T13: 0.36127105 | U13: 108.95768
A14: 21111.02 | B14: Bovine meat | C14: Red meat | D14: Netherlands | E14: NL | F14: ='GHG det D24m, results per kg'!G46 -> 23.628281 | G14: ='GHG det D24m, results per kg'!G42 -> 0.00027509986 | H14: ='GHG det D24m, results per kg'!G43 -> 1.0181103e-06 | I14: ='GHG det D24m, results per kg'!G44 -> 0.77875629 | J14: ='GHG det D24m, results per kg'!G45 -> 0.023541498 | L14: =('Production SH'!$I$5*'Parameters SH, country spec'!$I$51*'EFP per kg feed'!F146+('Production SH'!$I$6+'Production SH'!$I$7)*'Parameters SH, country spec'!$I$52*'EFP per kg feed'!F147)/'Production SH'!$I$21 -> 27.008546 | M14: =('Production SH'!$I$5*'Parameters SH, country spec'!$I$51*'EFP per kg feed'!G146+('Production SH'!$I$6+'Production SH'!$I$7)*'Parameters SH, country spec'!$I$52*'EFP per kg feed'!G147-Excreted_N_after_losses_NL*Manure_repl_factor_NL)/'Production SH'!$I$21 -> 1.0370691 | N14: =('Production SH'!$I$5*'Parameters SH, country spec'!$I$51*'EFP per kg feed'!H146+('Production SH'!$I$6+'Production SH'!$I$7)*'Parameters SH, country spec'!$I$52*'EFP per kg feed'!H147)/'Production SH'!$I$21 -> 0.025728359 | O14: =('Production SH'!$I$5*'Parameters SH, country spec'!$I$51*'EFP per kg feed'!I146+('Production SH'!$I$6+'Production SH'!$I$7)*'Parameters SH, country spec'!$I$52*'EFP per kg feed'!I147)/'Production SH'!$I$21 -> 0.048615606 | P14: =('Production SH'!$I$5*'Parameters SH, country spec'!$I$51*'EFP per kg feed'!J146+('Production SH'!$I$6+'Production SH'!$I$7)*'Parameters SH, country spec'!$I$52*'EFP per kg feed'!J147)/'Production SH'!$I$21 -> 2.1230752 | Q14: =('Production SH'!$I$5*'Parameters SH, country spec'!$I$51*'EFP per kg feed'!K146+('Production SH'!$I$6+'Production SH'!$I$7)*'Parameters SH, country spec'!$I$52*'EFP per kg feed'!K147)/'Production SH'!$I$21 -> 3.6414625e-09 | R14: =('Production SH'!$I$5*'Parameters SH, country spec'!$I$51*'EFP per kg feed'!L146+('Production SH'!$I$6+'Production SH'!$I$7)*'Parameters SH, country spec'!$I$52*'EFP per kg feed'!L147+Manure!Q159)/'Production SH'!$I$21 -> 0.17542994 | T14: 0.26899769 | U14: 26.725346
A15: 21111.02 | B15: Bovine meat | C15: Red meat | D15: Poland | E15: PL | F15: ='GHG det D24m, results per kg'!G51 -> 28.041593 | G15: ='GHG det D24m, results per kg'!G47 -> 0.00037922767 | H15: ='GHG det D24m, results per kg'!G48 -> 5.9893187e-07 | I15: ='GHG det D24m, results per kg'!G49 -> 0.77490451 | J15: ='GHG det D24m, results per kg'!G50 -> 0.056333606 | L15: =('Production SH'!$J$5*'Parameters SH, country spec'!$J$51*'EFP per kg feed'!F164+('Production SH'!$J$6+'Production SH'!$J$7)*'Parameters SH, country spec'!$J$52*'EFP per kg feed'!F165)/'Production SH'!$J$21 -> 37.80427 | M15: =('Production SH'!$J$5*'Parameters SH, country spec'!$J$51*'EFP per kg feed'!G164+('Production SH'!$J$6+'Production SH'!$J$7)*'Parameters SH, country spec'!$J$52*'EFP per kg feed'!G165-Excreted_N_after_losses_PL*Manure_repl_factor_PL)/'Production SH'!$J$21 -> 0.62792157 | N15: =('Production SH'!$J$5*'Parameters SH, country spec'!$J$51*'EFP per kg feed'!H164+('Production SH'!$J$6+'Production SH'!$J$7)*'Parameters SH, country spec'!$J$52*'EFP per kg feed'!H165)/'Production SH'!$J$21 -> 0.053780363 | O15: =('Production SH'!$J$5*'Parameters SH, country spec'!$J$51*'EFP per kg feed'!I164+('Production SH'!$J$6+'Production SH'!$J$7)*'Parameters SH, country spec'!$J$52*'EFP per kg feed'!I165)/'Production SH'!$J$21 -> 0.021845591 | P15: =('Production SH'!$J$5*'Parameters SH, country spec'!$J$51*'EFP per kg feed'!J164+('Production SH'!$J$6+'Production SH'!$J$7)*'Parameters SH, country spec'!$J$52*'EFP per kg feed'!J165)/'Production SH'!$J$21 -> 2.7832697 | Q15: =('Production SH'!$J$5*'Parameters SH, country spec'!$J$51*'EFP per kg feed'!K164+('Production SH'!$J$6+'Production SH'!$J$7)*'Parameters SH, country spec'!$J$52*'EFP per kg feed'!K165)/'Production SH'!$J$21 -> 4.3043857e-09 | R15: =('Production SH'!$J$5*'Parameters SH, country spec'!$J$51*'EFP per kg feed'!L164+('Production SH'!$J$6+'Production SH'!$J$7)*'Parameters SH, country spec'!$J$52*'EFP per kg feed'!L165+Manure!S159)/'Production SH'!$J$21 -> 0.27758662 | T15: 0.34954097 | U15: 112.12533
A16: 21111.02 | B16: Bovine meat | C16: Red meat | D16: Spain | E16: ES | F16: ='GHG det D24m, results per kg'!G56 -> 26.55047 | G16: ='GHG det D24m, results per kg'!G52 -> 0.0001934549 | H16: ='GHG det D24m, results per kg'!G53 -> 5.6882721e-07 | I16: ='GHG det D24m, results per kg'!G54 -> 0.82853498 | J16: ='GHG det D24m, results per kg'!G55 -> 0.035723575 | L16: =('Production SH'!$K$5*'Parameters SH, country spec'!$K$51*'EFP per kg feed'!F182+('Production SH'!$K$6+'Production SH'!$K$7)*'Parameters SH, country spec'!$K$52*'EFP per kg feed'!F183)/'Production SH'!$K$21 -> 43.259834 | M16: =('Production SH'!$K$5*'Parameters SH, country spec'!$K$51*'EFP per kg feed'!G182+('Production SH'!$K$6+'Production SH'!$K$7)*'Parameters SH, country spec'!$K$52*'EFP per kg feed'!G183-Excreted_N_after_losses_ES*Manure_repl_factor_ES)/'Production SH'!$K$21 -> 0.6986156 | N16: =('Production SH'!$K$5*'Parameters SH, country spec'!$K$51*'EFP per kg feed'!H182+('Production SH'!$K$6+'Production SH'!$K$7)*'Parameters SH, country spec'!$K$52*'EFP per kg feed'!H183)/'Production SH'!$K$21 -> 0.06674488 | O16: =('Production SH'!$K$5*'Parameters SH, country spec'!$K$51*'EFP per kg feed'!I182+('Production SH'!$K$6+'Production SH'!$K$7)*'Parameters SH, country spec'!$K$52*'EFP per kg feed'!I183)/'Production SH'!$K$21 -> 3.8598342 | P16: =('Production SH'!$K$5*'Parameters SH, country spec'!$K$51*'EFP per kg feed'!J182+('Production SH'!$K$6+'Production SH'!$K$7)*'Parameters SH, country spec'!$K$52*'EFP per kg feed'!J183)/'Production SH'!$K$21 -> 2.6239911 | Q16: =('Production SH'!$K$5*'Parameters SH, country spec'!$K$51*'EFP per kg feed'!K182+('Production SH'!$K$6+'Production SH'!$K$7)*'Parameters SH, country spec'!$K$52*'EFP per kg feed'!K183)/'Production SH'!$K$21 -> 1.6644677e-07 | R16: =('Production SH'!$K$5*'Parameters SH, country spec'!$K$51*'EFP per kg feed'!L182+('Production SH'!$K$6+'Production SH'!$K$7)*'Parameters SH, country spec'!$K$52*'EFP per kg feed'!L183+Manure!U159)/'Production SH'!$K$21 -> 0.1814084 | T16: 0.24385273 | U16: 80.477964
A17: 21111.02 | B17: Bovine meat | C17: Red meat | D17: Sweden | E17: SE | F17: ='GHG det D24m, results per kg'!G61 -> 27.168169 | G17: ='GHG det D24m, results per kg'!G57 -> 0.00035361786 | H17: ='GHG det D24m, results per kg'!G58 -> 2.9149912e-06 | I17: ='GHG det D24m, results per kg'!G59 -> 0.8894799 | J17: ='GHG det D24m, results per kg'!G60 -> 0.037116433 | L17: =('Production SH'!$L$5*'Parameters SH, country spec'!$L$51*'EFP per kg feed'!F200+('Production SH'!$L$6+'Production SH'!$L$7)*'Parameters SH, country spec'!$L$52*'EFP per kg feed'!F201)/'Production SH'!$L$21 -> 40.815647 | M17: =('Production SH'!$L$5*'Parameters SH, country spec'!$L$51*'EFP per kg feed'!G200+('Production SH'!$L$6+'Production SH'!$L$7)*'Parameters SH, country spec'!$L$52*'EFP per kg feed'!G201-Excreted_N_after_losses_SE*Manure_repl_factor_SE)/'Production SH'!$L$21 -> 0.52594899 | N17: =('Production SH'!$L$5*'Parameters SH, country spec'!$L$51*'EFP per kg feed'!H200+('Production SH'!$L$6+'Production SH'!$L$7)*'Parameters SH, country spec'!$L$52*'EFP per kg feed'!H201)/'Production SH'!$L$21 -> 0.0060849689 | O17: =('Production SH'!$L$5*'Parameters SH, country spec'!$L$51*'EFP per kg feed'!I200+('Production SH'!$L$6+'Production SH'!$L$7)*'Parameters SH, country spec'!$L$52*'EFP per kg feed'!I201)/'Production SH'!$L$21 -> 0 | P17: =('Production SH'!$L$5*'Parameters SH, country spec'!$L$51*'EFP per kg feed'!J200+('Production SH'!$L$6+'Production SH'!$L$7)*'Parameters SH, country spec'!$L$52*'EFP per kg feed'!J201)/'Production SH'!$L$21 -> 0.017649507 | Q17: =('Production SH'!$L$5*'Parameters SH, country spec'!$L$51*'EFP per kg feed'!K200+('Production SH'!$L$6+'Production SH'!$L$7)*'Parameters SH, country spec'!$L$52*'EFP per kg feed'!K201)/'Production SH'!$L$21 -> -4.3908668e-09 | R17: =('Production SH'!$L$5*'Parameters SH, country spec'!$L$51*'EFP per kg feed'!L200+('Production SH'!$L$6+'Production SH'!$L$7)*'Parameters SH, country spec'!$L$52*'EFP per kg feed'!L201+Manure!W159)/'Production SH'!$L$21 -> 0.20378096 | T17: 0.22443653 | U17: 8.3075734
A18: 21111.02 | B18: Bovine meat | C18: Red meat | D18: UK | E18: GB | F18: ='GHG det D24m, results per kg'!G66 -> 24.906652 | G18: ='GHG det D24m, results per kg'!G58 -> 2.9149912e-06 | H18: ='GHG det D24m, results per kg'!G59 -> 0.8894799 | I18: ='GHG det D24m, results per kg'!G60 -> 0.037116433 | J18: ='GHG det D24m, results per kg'!G61 -> 27.168169 | L18: =('Production SH'!$M$5*'Parameters SH, country spec'!$M$51*'EFP per kg feed'!F218+('Production SH'!$M$6+'Production SH'!$M$7)*'Parameters SH, country spec'!$M$52*'EFP per kg feed'!F219)/'Production SH'!$M$21 -> 21.159436 | M18: {=('Production SH'!$M$5*'Parameters SH, country spec'!$M$51*'EFP per kg feed'!G218+('Production SH'!$M$6+'Production SH'!$M$7)*'Parameters SH, country spec'!$M$52*'EFP per kg feed'!G219-Excreted_N_after_losses_GB*Manure_repl_factor_GB)/'Production SH'!$M$21} -> 0.85821459 | N18: =('Production SH'!$M$5*'Parameters SH, country spec'!$M$51*'EFP per kg feed'!H218+('Production SH'!$M$6+'Production SH'!$M$7)*'Parameters SH, country spec'!$M$52*'EFP per kg feed'!H219)/'Production SH'!$M$21 -> 0.048203506 | O18: =('Production SH'!$M$5*'Parameters SH, country spec'!$M$51*'EFP per kg feed'!I218+('Production SH'!$M$6+'Production SH'!$M$7)*'Parameters SH, country spec'!$M$52*'EFP per kg feed'!I219)/'Production SH'!$M$21 -> 0.01379048 | P18: =('Production SH'!$M$5*'Parameters SH, country spec'!$M$51*'EFP per kg feed'!J218+('Production SH'!$M$6+'Production SH'!$M$7)*'Parameters SH, country spec'!$M$52*'EFP per kg feed'!J219)/'Production SH'!$M$21 -> 0.63437034 | Q18: =('Production SH'!$M$5*'Parameters SH, country spec'!$M$51*'EFP per kg feed'!K218+('Production SH'!$M$6+'Production SH'!$M$7)*'Parameters SH, country spec'!$M$52*'EFP per kg feed'!K219)/'Production SH'!$M$21 -> 3.8526631e-09 | R18: =('Production SH'!$M$5*'Parameters SH, country spec'!$M$51*'EFP per kg feed'!L218+('Production SH'!$M$6+'Production SH'!$M$7)*'Parameters SH, country spec'!$M$52*'EFP per kg feed'!L219+Manure!Y159)/'Production SH'!$M$21 -> 0.20496686 | T18: 0.25133442 | U18: 24.672883

Sheet Footprints D24, results per kg
A2: Footprints for dairy calves slaughtered at 24 months (per kg of meat) | T2: **Values inserted directly here, no formula in this excel sheet
A5: Animal products | F5: Climate | L5: Land | M5: Nitrogen | N5: Phosphorus | O5: Water | P5: Pesticides | Q5: Biodiversity | R5: Ammonia | S5: Labour | T5: Animal welfare** | U5: Use of antibiotics**
A6: Code | B6: Name | C6: Category | D6: Country | E6: Country code | F6: Carbon footprint, kg CO2e/kg | G6: Carbon dioxide, kg CO2/kg | H6: Methane, fossil, kg CH4/kg | I6: Methane, biogenic, kg CH4/kg | J6: Nitrous oxide, kg N2O/kg | K6: HFCs, kg HFCs/kg | L6: Cropland use, m2/kg | M6: New N input, kg N/kg | N6: New P input, kg P/kg | O6: Blue freshwater use, m3/kg | P6: Pesticide use, g a.i./kg | Q6: Extinction rate, E/MSY/kg | R6: Ammonia emission, kg NH3/kg | S6: Labour requirements, h/kg | T6: Animal welfare index per kg of bonefree meat | U6: Antibiotics use indicator/kg
A7: 21111.02 | B7: Bovine meat | C7: Red meat | D7: Denmark | E7: DK | F7: ='GHG det D24m, results per kg'!G11 -> 30.578076 | G7: ='GHG det D24m, results per kg'!G7 -> 3.4321149 | H7: ='GHG det D24m, results per kg'!G8 -> 0.030930649 | I7: ='GHG det D24m, results per kg'!G9 -> 1.0810815 | J7: ='GHG det D24m, results per kg'!G10 -> 0.035359551 | L7: ='Production D24m'!$B$5*'Parameters D24m, country spec'!$B$30*'EFP per kg feed'!F22/'Production D24m'!$B$15 -> 20.891547 | M7: =('Production D24m'!$B$5*'Parameters D24m, country spec'!$B$30*'EFP per kg feed'!G22-Excreted_N_after_losses_DK*Manure_repl_factor_DK)/'Production D24m'!$B$15 -> 0.24083926 | N7: =('Production D24m'!$B$5*'Parameters D24m, country spec'!$B$30*'EFP per kg feed'!H20+('Production D24m'!$B$6+'Production D24m'!$B$7)*'Parameters D24m, country spec'!$B$52*'EFP per kg feed'!H15)/'Production D24m'!$B$15 -> 0.0097709129 | O7: =('Production D24m'!$B$5*'Parameters D24m, country spec'!$B$30*'EFP per kg feed'!I20+('Production D24m'!$B$6+'Production D24m'!$B$7)*'Parameters D24m, country spec'!$B$52*'EFP per kg feed'!I15)/'Production D24m'!$B$15 -> 0.0046386269 | P7: =('Production D24m'!$B$5*'Parameters D24m, country spec'!$B$30*'EFP per kg feed'!J20+('Production D24m'!$B$6+'Production D24m'!$B$7)*'Parameters D24m, country spec'!$B$52*'EFP per kg feed'!J15)/'Production D24m'!$B$15 -> 0.50544185 | Q7: =('Production D24m'!$B$5*'Parameters D24m, country spec'!$B$30*'EFP per kg feed'!K20+('Production D24m'!$B$6+'Production D24m'!$B$7)*'Parameters D24m, country spec'!$B$52*'EFP per kg feed'!K15)/'Production D24m'!$B$15 -> 1.3801937e-09 | R7: =('Production D24m'!$B$5*'Parameters D24m, country spec'!$B$30*'EFP per kg feed'!L20+('Production D24m'!$B$6+'Production D24m'!$B$7)*'Parameters D24m, country spec'!$B$52*'EFP per kg feed'!L15+Manure!C159)/'Production D24m'!$B$15 -> 0.40318891 | T7: 0.20061451 | U7: 16.134752
A8: 21111.02 | B8: Bovine meat | C8: Red meat | D8: France | E8: FR | F8: ='GHG det D24m, results per kg'!G16 -> 22.127357 | G8: ='GHG det D24m, results per kg'!G12 -> 0.00018768247 | H8: ='GHG det D24m, results per kg'!G13 -> 1.3119089e-06 | I8: ='GHG det D24m, results per kg'!G14 -> 0.65194238 | J8: ='GHG det D24m, results per kg'!G15 -> 0.042908155 | L8: ='Production D24m'!$C$5*'Parameters D24m, country spec'!$C$30*'EFP per kg feed'!F40/'Production D24m'!$C$15 -> 19.531817 | M8: =('Production D24m'!$C$5*'Parameters D24m, country spec'!$C$30*'EFP per kg feed'!G40-Excreted_N_after_losses_FR*Manure_repl_factor_FR)/'Production D24m'!C15 -> 0.29707665 | N8: =('Production D24m'!$C$5*'Parameters D24m, country spec'!$C$30*'EFP per kg feed'!H38+('Production D24m'!$C$6+'Production D24m'!$C$7)*'Parameters D24m, country spec'!$C$52*'EFP per kg feed'!H39)/'Production D24m'!C15 -> 0.023367526 | O8: =('Production D24m'!$C$5*'Parameters D24m, country spec'!$C$30*'EFP per kg feed'!I38+('Production D24m'!$C$6+'Production D24m'!$C$7)*'Parameters D24m, country spec'!$C$52*'EFP per kg feed'!I39)/'Production D24m'!C15 -> 0.19719658 | P8: =('Production D24m'!$C$5*'Parameters D24m, country spec'!$C$30*'EFP per kg feed'!J38+('Production D24m'!$C$6+'Production D24m'!$C$7)*'Parameters D24m, country spec'!$C$52*'EFP per kg feed'!J39)/'Production D24m'!C15 -> 1.0898592 | Q8: =('Production D24m'!$C$5*'Parameters D24m, country spec'!$C$30*'EFP per kg feed'!K38+('Production D24m'!$C$6+'Production D24m'!$C$7)*'Parameters D24m, country spec'!$C$52*'EFP per kg feed'!K39)/'Production D24m'!C15 -> 8.6850259e-09 | R8: =('Production D24m'!$C$5*'Parameters D24m, country spec'!$C$30*'EFP per kg feed'!L38+('Production D24m'!$C$6+'Production D24m'!$C$7)*'Parameters D24m, country spec'!$C$52*'EFP per kg feed'!L39+Manure!E159)/'Production D24m'!C15 -> 0.39048552 | T8: 0.24631609 | U8: 31.990695
A9: 21111.02 | B9: Bovine meat | C9: Red meat | D9: Germany | E9: DE | F9: ='GHG det D24m, results per kg'!G21 -> 23.648689 | G9: ='GHG det D24m, results per kg'!G17 -> 0.00020927458 | H9: ='GHG det D24m, results per kg'!G18 -> 1.3756598e-06 | I9: ='GHG det D24m, results per kg'!G19 -> 0.85358322 | J9: ='GHG det D24m, results per kg'!G20 -> 0.038402115 | L9: ='Production D24m'!$D$5*'Parameters D24m, country spec'!$D$30*'EFP per kg feed'!F58/'Production D24m'!$D$15 -> 14.305134 | M9: =('Production D24m'!$D$5*'Parameters D24m, country spec'!$D$30*'EFP per kg feed'!G58-Excreted_N_after_losses_DE*Manure_repl_factor_DE)/'Production D24m'!$D$15 -> 0.24490856 | N9: =('Production D24m'!$D$5*'Parameters D24m, country spec'!$D$30*'EFP per kg feed'!H56+('Production D24m'!$D$6+'Production D24m'!$D$7)*'Parameters D24m, country spec'!$D$52*'EFP per kg feed'!H57)/'Production D24m'!$D$15 -> 0.012206474 | O9: =('Production D24m'!$D$5*'Parameters D24m, country spec'!$D$30*'EFP per kg feed'!I56+('Production D24m'!$D$6+'Production D24m'!$D$7)*'Parameters D24m, country spec'!$D$52*'EFP per kg feed'!I57)/'Production D24m'!$D$15 -> 0.0064803323 | P9: =('Production D24m'!$D$5*'Parameters D24m, country spec'!$D$30*'EFP per kg feed'!J56+('Production D24m'!$D$6+'Production D24m'!$D$7)*'Parameters D24m, country spec'!$D$52*'EFP per kg feed'!J57)/'Production D24m'!$D$15 -> 0.65416487 | Q9: =('Production D24m'!$D$5*'Parameters D24m, country spec'!$D$30*'EFP per kg feed'!K56+('Production D24m'!$D$6+'Production D24m'!$D$7)*'Parameters D24m, country spec'!$D$52*'EFP per kg feed'!K57)/'Production D24m'!$D$15 -> 1.3140219e-09 | R9: =('Production D24m'!$D$5*'Parameters D24m, country spec'!$D$30*'EFP per kg feed'!L56+('Production D24m'!$D$6+'Production D24m'!$D$7)*'Parameters D24m, country spec'!$D$52*'EFP per kg feed'!L57+Manure!G159)/'Production D24m'!$D$15 -> 0.4472852 | T9: 0.28238673 | U9: 42.008022
A10: 21111.02 | B10: Bovine meat | C10: Red meat | D10: Greece | E10: GR | F10: ='GHG det D24m, results per kg'!G26 -> 23.100877 | G10: ='GHG det D24m, results per kg'!G22 -> 0.00027776225 | H10: ='GHG det D24m, results per kg'!G23 -> 7.4082387e-07 | I10: ='GHG det D24m, results per kg'!G24 -> 0.68873345 | J10: ='GHG det D24m, results per kg'!G25 -> 0.048926895 | L10: ='Production D24m'!$E$5*'Parameters D24m, country spec'!$E$30*'EFP per kg feed'!F76/'Production D24m'!$E$15 -> 31.330595 | M10: =('Production D24m'!$E$5*'Parameters D24m, country spec'!$E$30*'EFP per kg feed'!G76-Excreted_N_after_losses_GR*Manure_repl_factor_GR)/'Production D24m'!$E$15 -> 0.47411983 | N10: =('Production D24m'!$E$5*'Parameters D24m, country spec'!$E$30*'EFP per kg feed'!H74+('Production D24m'!$E$6+'Production D24m'!$E$7)*'Parameters D24m, country spec'!$E$52*'EFP per kg feed'!H75)/'Production D24m'!$E$15 -> 0.053494248 | O10: =('Production D24m'!$E$5*'Parameters D24m, country spec'!$E$30*'EFP per kg feed'!I74+('Production D24m'!$E$6+'Production D24m'!$E$7)*'Parameters D24m, country spec'!$E$52*'EFP per kg feed'!I75)/'Production D24m'!$E$15 -> 2.1699703 | P10: =('Production D24m'!$E$5*'Parameters D24m, country spec'!$E$30*'EFP per kg feed'!J74+('Production D24m'!$E$6+'Production D24m'!$E$7)*'Parameters D24m, country spec'!$E$52*'EFP per kg feed'!J75)/'Production D24m'!$E$15 -> 1.3393228 | Q10: =('Production D24m'!$E$5*'Parameters D24m, country spec'!$E$30*'EFP per kg feed'!K74+('Production D24m'!$E$6+'Production D24m'!$E$7)*'Parameters D24m, country spec'!$E$52*'EFP per kg feed'!K75)/'Production D24m'!$E$15 -> 1.1206794e-07 | R10: =('Production D24m'!$E$5*'Parameters D24m, country spec'!$E$30*'EFP per kg feed'!L74+('Production D24m'!$E$6+'Production D24m'!$E$7)*'Parameters D24m, country spec'!$E$52*'EFP per kg feed'!L75+Manure!I159)/'Production D24m'!$E$15 -> 0.45175604 | T10: 0.28502161 | U10: 93.603378
A11: 21111.02 | B11: Bovine meat | C11: Red meat | D11: Hungary | E11: HU | F11: ='GHG det D24m, results per kg'!G31 -> 32.210533 | G11: ='GHG det D24m, results per kg'!G27 -> 0.00026618239 | H11: ='GHG det D24m, results per kg'!G28 -> 1.3488347e-06 | I11: ='GHG det D24m, results per kg'!G29 -> 1.1150113 | J11: ='GHG det D24m, results per kg'!G30 -> 0.052248825 | L11: ='Production D24m'!$F$5*'Parameters D24m, country spec'!$F$30*'EFP per kg feed'!F94/'Production D24m'!$F$15 -> 34.49397 | M11: =('Production D24m'!$F$5*'Parameters D24m, country spec'!$F$30*'EFP per kg feed'!G94-Excreted_N_after_losses_HU*Manure_repl_factor_HU)/'Production D24m'!$F$15 -> 0.48128611 | N11: =('Production D24m'!$F$5*'Parameters D24m, country spec'!$F$30*'EFP per kg feed'!H92+('Production D24m'!$F$6+'Production D24m'!$F$7)*'Parameters D24m, country spec'!$F$52*'EFP per kg feed'!H93)/'Production D24m'!$F$15 -> 0.039208352 | O11: =('Production D24m'!$F$5*'Parameters D24m, country spec'!$F$30*'EFP per kg feed'!I92+('Production D24m'!$F$6+'Production D24m'!$F$7)*'Parameters D24m, country spec'!$F$52*'EFP per kg feed'!I93)/'Production D24m'!$F$15 -> 0.062602246 | P11: =('Production D24m'!$F$5*'Parameters D24m, country spec'!$F$30*'EFP per kg feed'!J92+('Production D24m'!$F$6+'Production D24m'!$F$7)*'Parameters D24m, country spec'!$F$52*'EFP per kg feed'!J93)/'Production D24m'!$F$15 -> 1.5419545 | Q11: =('Production D24m'!$F$5*'Parameters D24m, country spec'!$F$30*'EFP per kg feed'!K92+('Production D24m'!$F$6+'Production D24m'!$F$7)*'Parameters D24m, country spec'!$F$52*'EFP per kg feed'!K93)/'Production D24m'!$F$15 -> 2.8311531e-09 | R11: =('Production D24m'!$F$5*'Parameters D24m, country spec'!$F$30*'EFP per kg feed'!L92+('Production D24m'!$F$6+'Production D24m'!$F$7)*'Parameters D24m, country spec'!$F$52*'EFP per kg feed'!L93+Manure!K159)/'Production D24m'!$F$15 -> 0.47099095 | T11: 0.29974061 | U11: 86.193346
A12: 21111.02 | B12: Bovine meat | C12: Red meat | D12: Ireland | E12: IE | F12: ='GHG det D24m, results per kg'!G36 -> 27.9831 | G12: ='GHG det D24m, results per kg'!G32 -> 0.00014497157 | H12: ='GHG det D24m, results per kg'!G33 -> 2.831295e-07 | I12: ='GHG det D24m, results per kg'!G34 -> 1.0769229 | J12: ='GHG det D24m, results per kg'!G35 -> 0.032833487 | L12: ='Production D24m'!$G$5*'Parameters D24m, country spec'!$G$30*'EFP per kg feed'!F112/'Production D24m'!$G$15 -> 7.656915 | M12: =('Production D24m'!$G$5*'Parameters D24m, country spec'!$G$30*'EFP per kg feed'!G112-Excreted_N_after_losses_IE*Manure_repl_factor_IE)/'Production D24m'!$G$15 -> 0.36585952 | N12: =('Production D24m'!$G$5*'Parameters D24m, country spec'!$G$30*'EFP per kg feed'!H110+('Production D24m'!$G$6+'Production D24m'!$G$7)*'Parameters D24m, country spec'!$G$52*'EFP per kg feed'!H111)/'Production D24m'!$G$15 -> 0.022742313 | O12: =('Production D24m'!$G$5*'Parameters D24m, country spec'!$G$30*'EFP per kg feed'!I110+('Production D24m'!$G$6+'Production D24m'!$G$7)*'Parameters D24m, country spec'!$G$52*'EFP per kg feed'!I111)/'Production D24m'!$G$15 -> 0.0012276245 | P12: =('Production D24m'!$G$5*'Parameters D24m, country spec'!$G$30*'EFP per kg feed'!J110+('Production D24m'!$G$6+'Production D24m'!$G$7)*'Parameters D24m, country spec'!$G$52*'EFP per kg feed'!J111)/'Production D24m'!$G$15 -> 2.0163882 | Q12: =('Production D24m'!$G$5*'Parameters D24m, country spec'!$G$30*'EFP per kg feed'!K110+('Production D24m'!$G$6+'Production D24m'!$G$7)*'Parameters D24m, country spec'!$G$52*'EFP per kg feed'!K111)/'Production D24m'!$G$15 -> 9.1145201e-10 | R12: =('Production D24m'!$G$5*'Parameters D24m, country spec'!$G$30*'EFP per kg feed'!L110+('Production D24m'!$G$6+'Production D24m'!$G$7)*'Parameters D24m, country spec'!$G$52*'EFP per kg feed'!L111+Manure!M159)/'Production D24m'!$G$15 -> 0.38375593 | T12: 0.25013213 | U12: 33.680254
A13: 21111.02 | B13: Bovine meat | C13: Red meat | D13: Italy | E13: IT | F13: ='GHG det D24m, results per kg'!G41 -> 35.238813 | G13: ='GHG det D24m, results per kg'!G37 -> 0.00016863493 | H13: ='GHG det D24m, results per kg'!G38 -> 9.4642631e-07 | I13: ='GHG det D24m, results per kg'!G39 -> 1.3328476 | J13: ='GHG det D24m, results per kg'!G40 -> 0.053867572 | L13: ='Production D24m'!$H$5*'Parameters D24m, country spec'!$H$30*'EFP per kg feed'!F130/'Production D24m'!$H$15 -> 17.004109 | M13: =('Production D24m'!$H$5*'Parameters D24m, country spec'!$H$30*'EFP per kg feed'!G130-Excreted_N_after_losses_IT*Manure_repl_factor_IT)/'Production D24m'!$H$15 -> 0.34359988 | N13: =('Production D24m'!$H$5*'Parameters D24m, country spec'!$H$30*'EFP per kg feed'!H128+('Production D24m'!$H$6+'Production D24m'!$H$7)*'Parameters D24m, country spec'!$H$52*'EFP per kg feed'!H129)/'Production D24m'!$H$15 -> 0.0209623 | O13: =('Production D24m'!$H$5*'Parameters D24m, country spec'!$H$30*'EFP per kg feed'!I128+('Production D24m'!$H$6+'Production D24m'!$H$7)*'Parameters D24m, country spec'!$H$52*'EFP per kg feed'!I129)/'Production D24m'!$H$15 -> 0.21871256 | P13: =('Production D24m'!$H$5*'Parameters D24m, country spec'!$H$30*'EFP per kg feed'!J128+('Production D24m'!$H$6+'Production D24m'!$H$7)*'Parameters D24m, country spec'!$H$52*'EFP per kg feed'!J129)/'Production D24m'!$H$15 -> 1.2173564 | Q13: =('Production D24m'!$H$5*'Parameters D24m, country spec'!$H$30*'EFP per kg feed'!K128+('Production D24m'!$H$6+'Production D24m'!$H$7)*'Parameters D24m, country spec'!$H$52*'EFP per kg feed'!K129)/'Production D24m'!$H$15 -> 3.5274026e-08 | R13: =('Production D24m'!$H$5*'Parameters D24m, country spec'!$H$30*'EFP per kg feed'!L128+('Production D24m'!$H$6+'Production D24m'!$H$7)*'Parameters D24m, country spec'!$H$52*'EFP per kg feed'!L129+Manure!O159)/'Production D24m'!$H$15 -> 0.63878408 | T13: 0.34062672 | U13: 108.95768
A14: 21111.02 | B14: Bovine meat | C14: Red meat | D14: Netherlands | E14: NL | F14: ='GHG det D24m, results per kg'!G46 -> 23.628281 | G14: ='GHG det D24m, results per kg'!G42 -> 0.00027509986 | H14: ='GHG det D24m, results per kg'!G43 -> 1.0181103e-06 | I14: ='GHG det D24m, results per kg'!G44 -> 0.77875629 | J14: ='GHG det D24m, results per kg'!G45 -> 0.023541498 | L14: ='Production D24m'!$I$5*'Parameters D24m, country spec'!$I$30*'EFP per kg feed'!F148/'Production D24m'!$I$15 -> 16.553538 | M14: =('Production D24m'!$I$5*'Parameters D24m, country spec'!$I$30*'EFP per kg feed'!G148-Excreted_N_after_losses_NL*Manure_repl_factor_NL)/'Production D24m'!$I$15 -> 0.63541183 | N14: =('Production D24m'!$I$5*'Parameters D24m, country spec'!$I$30*'EFP per kg feed'!H146+('Production D24m'!$I$6+'Production D24m'!$I$7)*'Parameters D24m, country spec'!$I$52*'EFP per kg feed'!H147)/'Production D24m'!$I$15 -> 0.015779781 | O14: =('Production D24m'!$I$5*'Parameters D24m, country spec'!$I$30*'EFP per kg feed'!I146+('Production D24m'!$I$6+'Production D24m'!$I$7)*'Parameters D24m, country spec'!$I$52*'EFP per kg feed'!I147)/'Production D24m'!$I$15 -> 0.029782701 | P14: =('Production D24m'!$I$5*'Parameters D24m, country spec'!$I$30*'EFP per kg feed'!J146+('Production D24m'!$I$6+'Production D24m'!$I$7)*'Parameters D24m, country spec'!$I$52*'EFP per kg feed'!J147)/'Production D24m'!$I$15 -> 1.3024475 | Q14: =('Production D24m'!$I$5*'Parameters D24m, country spec'!$I$30*'EFP per kg feed'!K146+('Production D24m'!$I$6+'Production D24m'!$I$7)*'Parameters D24m, country spec'!$I$52*'EFP per kg feed'!K147)/'Production D24m'!$I$15 -> 2.2310377e-09 | R14: =('Production D24m'!$I$5*'Parameters D24m, country spec'!$I$30*'EFP per kg feed'!L146+('Production D24m'!$I$6+'Production D24m'!$I$7)*'Parameters D24m, country spec'!$I$52*'EFP per kg feed'!L147+Manure!Q159)/'Production D24m'!$I$15 -> 0.28446922 | T14: 0.25185843 | U14: 26.725346
A15: 21111.02 | B15: Bovine meat | C15: Red meat | D15: Poland | E15: PL | F15: ='GHG det D24m, results per kg'!G51 -> 28.041593 | G15: ='GHG det D24m, results per kg'!G47 -> 0.00037922767 | H15: ='GHG det D24m, results per kg'!G48 -> 5.9893187e-07 | I15: ='GHG det D24m, results per kg'!G49 -> 0.77490451 | J15: ='GHG det D24m, results per kg'!G50 -> 0.056333606 | L15: ='Production D24m'!$J$5*'Parameters D24m, country spec'!$J$30*'EFP per kg feed'!F166/'Production D24m'!$J$15 -> 23.219235 | M15: =('Production D24m'!$J$5*'Parameters D24m, country spec'!$J$30*'EFP per kg feed'!G166-Excreted_N_after_losses_PL*Manure_repl_factor_PL)/'Production D24m'!$J$15 -> 0.38513846 | N15: =('Production D24m'!$J$5*'Parameters D24m, country spec'!$J$30*'EFP per kg feed'!H164+('Production D24m'!$J$6+'Production D24m'!$J$7)*'Parameters D24m, country spec'!$J$52*'EFP per kg feed'!H165)/'Production D24m'!$J$15 -> 0.033018412 | O15: =('Production D24m'!$J$5*'Parameters D24m, country spec'!$J$30*'EFP per kg feed'!I164+('Production D24m'!$J$6+'Production D24m'!$J$7)*'Parameters D24m, country spec'!$J$52*'EFP per kg feed'!I165)/'Production D24m'!$J$15 -> 0.01338296 | P15: =('Production D24m'!$J$5*'Parameters D24m, country spec'!$J$30*'EFP per kg feed'!J164+('Production D24m'!$J$6+'Production D24m'!$J$7)*'Parameters D24m, country spec'!$J$52*'EFP per kg feed'!J165)/'Production D24m'!$J$15 -> 1.7103953 | Q15: =('Production D24m'!$J$5*'Parameters D24m, country spec'!$J$30*'EFP per kg feed'!K164+('Production D24m'!$J$6+'Production D24m'!$J$7)*'Parameters D24m, country spec'!$J$52*'EFP per kg feed'!K165)/'Production D24m'!$J$15 -> 2.6397112e-09 | R15: =('Production D24m'!$J$5*'Parameters D24m, country spec'!$J$30*'EFP per kg feed'!L164+('Production D24m'!$J$6+'Production D24m'!$J$7)*'Parameters D24m, country spec'!$J$52*'EFP per kg feed'!L165+Manure!S159)/'Production D24m'!$J$15 -> 0.51561735 | T15: 0.32372712 | U15: 112.12533
