Workbook
Name Ability_to_perceive_handling: 'Parameters, general'!$B$19
Name Boars_per_sow: 'Parameters, country spec'!$L$17
Name Bonefree_outof_CW_DE: 'Parameters, country spec'!$D$8
Name Bonefree_outof_CW_DK: 'Parameters, country spec'!$B$8
Name Bonefree_outof_CW_ES: 'Parameters, country spec'!$K$8
Name Bonefree_outof_CW_FR: 'Parameters, country spec'!$C$8
Name Bonefree_outof_CW_GR: 'Parameters, country spec'!$E$8
Name Bonefree_outof_CW_HU: 'Parameters, country spec'!$F$8
Name Bonefree_outof_CW_IE: 'Parameters, country spec'!$G$8
Name Bonefree_outof_CW_IT: 'Parameters, country spec'!$H$8
Name Bonefree_outof_CW_NL: 'Parameters, country spec'!$I$8
Name Bonefree_outof_CW_PL: 'Parameters, country spec'!$J$8
Name Bonefree_outof_CW_SE: 'Parameters, country spec'!$L$8
Name CF_GWP_CH4_fossil: 'Parameters, general'!$B$14
Name CF_GWP_N2O: 'Parameters, general'!$B$15
Name Crop_data: #REF!
Name Crop_data_codes: #REF!
Name EF_biofuel_CH4: 'Parameters, general'!$C$6
Name EF_biofuel_N2O: 'Parameters, general'!$D$6
Name EF_biofuels_CO2: 'Parameters, general'!$B$6
Name EF_el_CH4_BR: 'Parameters, general'!$B$31
Name EF_el_CH4_DE: 'Parameters, country spec'!$D$91
Name EF_el_CH4_DK: 'Parameters, country spec'!$B$91
Name EF_el_CH4_ES: 'Parameters, country spec'!$K$91
Name EF_el_CH4_FR: 'Parameters, country spec'!$C$91
Name EF_el_CH4_GR: 'Parameters, country spec'!$E$91
Name EF_el_CH4_HU: 'Parameters, country spec'!$F$91
Name EF_el_CH4_IE: 'Parameters, country spec'!$G$91
Name EF_el_CH4_IT: 'Parameters, country spec'!$H$91
Name EF_el_CH4_NL: 'Parameters, country spec'!$I$91
Name EF_el_CH4_PL: 'Parameters, country spec'!$J$91
Name EF_el_CH4_SE: 'Parameters, country spec'!$L$91
Name EF_el_CO2_BR: 'Parameters, general'!$B$30
Name EF_el_CO2_DE: 'Parameters, country spec'!$D$90
Name EF_el_CO2_DK: 'Parameters, country spec'!$B$90
Name EF_el_CO2_ES: 'Parameters, country spec'!$K$90
Name EF_el_CO2_FR: 'Parameters, country spec'!$C$90
Name EF_el_CO2_GR: 'Parameters, country spec'!$E$90
Name EF_el_CO2_HU: 'Parameters, country spec'!$F$90
Name EF_el_CO2_IE: 'Parameters, country spec'!$G$90
Name EF_el_CO2_IT: 'Parameters, country spec'!$H$90
Name EF_el_CO2_NL: 'Parameters, country spec'!$I$90
Name EF_el_CO2_PL: 'Parameters, country spec'!$J$90
Name EF_el_CO2_SE: 'Parameters, country spec'!$L$90
Name EF_el_N2O_BR: 'Parameters, general'!$B$32
Name EF_el_N2O_DE: 'Parameters, country spec'!$D$92
Name EF_el_N2O_DK: 'Parameters, country spec'!$B$92
Name EF_el_N2O_ES: 'Parameters, country spec'!$K$92
Name EF_el_N2O_FR: 'Parameters, country spec'!$C$92
Name EF_el_N2O_GR: 'Parameters, country spec'!$E$92
Name EF_el_N2O_HU: 'Parameters, country spec'!$F$92
Name EF_el_N2O_IE: 'Parameters, country spec'!$G$92
Name EF_el_N2O_IT: 'Parameters, country spec'!$H$92
Name EF_el_N2O_NL: 'Parameters, country spec'!$I$92
Name EF_el_N2O_PL: 'Parameters, country spec'!$J$92
Name EF_el_N2O_SE: 'Parameters, country spec'!$L$92
Name EF_electricity: 'Parameters, country spec'!$L$89
Name EF_ent_ferm_DE: 'Parameters, country spec'!$D$75
Name EF_ent_ferm_DK: 'Parameters, country spec'!$B$75
Name EF_ent_ferm_ES: 'Parameters, country spec'!$K$75

Sheet README
A2: Read me
A4: This is a file that contains the calculation of the footprints for pork.
A7: Assumptions:
A17: Color codes:
B19: Results
B20: Sheets for input
B21: Intermediate calculations
B22: Figures
A26: Att göra:
A27: Se om det går att få ut en foderstat för denna från Frankrike https://productions-animales.org/article/view/5396
A28: Vattenanvändning per land - OBS att detta är för anv i stallar, inte foderodlingen
A29: Energianvändning slakt

Sheet Figures
A2: Figures
A4: Greenhouse gas emission for bonefree pig meat across countries, to farmgate including slaughter, no waste
B6: Production of mineral fertilizer | C6: Production of capital goods | D6: Emissions from soil | E6: Diesel use field machinary | F6: Energy use for feed processing | G6: Land use change emissions | H6: Feed transports | I6: Enteric fermentation | J6: Manure management | K6: Energy use in stables | L6: Energy use for slaughter | M6: Tot | P6: Order this study: | R6: Order Lesschen:
A7: Greece | B7: ='GHG detailed, results per kg'!H26 -> 0.47251514 | C7: ='GHG detailed, results per kg'!I26 -> 0.16944313 | D7: ='GHG detailed, results per kg'!J26+'GHG detailed, results per kg'!K26 -> 0.33311674 | E7: ='GHG detailed, results per kg'!L26 -> 0.25618232 | F7: ='GHG detailed, results per kg'!O26 -> 0.26086377 | G7: ='GHG detailed, results per kg'!P26 -> 0.33414898 | H7: ='GHG detailed, results per kg'!R26 -> 0.2736595 | I7: ='GHG detailed, results per kg'!S26 -> 0.28281134 | J7: ='GHG detailed, results per kg'!T26 -> 4.519341 | K7: ='GHG detailed, results per kg'!W26 -> 0.4718823 | L7: ='GHG detailed, results per kg'!X26 -> 1.0878299 | M7: =SUM(B7:L7) -> 8.4617941 | P7: Greece | R7: Greece
A8: Netherlands | B8: ='GHG detailed, results per kg'!H46 -> 0.62875327 | C8: ='GHG detailed, results per kg'!I46 -> 0.16927802 | D8: ='GHG detailed, results per kg'!J46+'GHG detailed, results per kg'!K46 -> 0.90812542 | E8: ='GHG detailed, results per kg'!L46 -> 0.16834636 | F8: ='GHG detailed, results per kg'!O46 -> 0.25792267 | G8: ='GHG detailed, results per kg'!P46 -> 0.31906063 | H8: ='GHG detailed, results per kg'!R46 -> 0.31252893 | I8: ='GHG detailed, results per kg'!S46 -> 0.2784287 | J8: ='GHG detailed, results per kg'!T46 -> 2.8051529 | K8: ='GHG detailed, results per kg'!W46 -> 0.39632618 | L8: ='GHG detailed, results per kg'!X46 -> 0.88125366 | M8: =SUM(B8:L8) -> 7.1251767 | P8: Netherlands | R8: Netherlands
A9: Italy | B9: ='GHG detailed, results per kg'!H41 -> 0.45474959 | C9: ='GHG detailed, results per kg'!I41 -> 0.17024308 | D9: ='GHG detailed, results per kg'!J41+'GHG detailed, results per kg'!K41 -> 0.30297199 | E9: ='GHG detailed, results per kg'!L41 -> 0.19600926 | F9: ='GHG detailed, results per kg'!O41 -> 0.24040521 | G9: ='GHG detailed, results per kg'!P41 -> 0.30478852 | H9: ='GHG detailed, results per kg'!R41 -> 0.25183137 | I9: ='GHG detailed, results per kg'!S41 -> 0.22438023 | J9: ='GHG detailed, results per kg'!T41 -> 2.9613334 | K9: ='GHG detailed, results per kg'!W41 -> 0.27218938 | L9: ='GHG detailed, results per kg'!X41 -> 0.74559117 | M9: =SUM(B9:L9) -> 6.1244932 | P9: Italy | R9: Hungary
A10: Germany | B10: ='GHG detailed, results per kg'!H21 -> 0.69169579 | C10: ='GHG detailed, results per kg'!I21 -> 0.17524774 | D10: ='GHG detailed, results per kg'!J21+'GHG detailed, results per kg'!K21 -> 0.78474991 | E10: ='GHG detailed, results per kg'!L21 -> 0.18168065 | F10: ='GHG detailed, results per kg'!O21 -> 0.26390751 | G10: ='GHG detailed, results per kg'!P21 -> 0.27126559 | H10: ='GHG detailed, results per kg'!R21 -> 0.28080752 | I10: ='GHG detailed, results per kg'!S21 -> 0.28163007 | J10: ='GHG detailed, results per kg'!T21 -> 1.7740007 | K10: ='GHG detailed, results per kg'!W21 -> 0.38055696 | L10: ='GHG detailed, results per kg'!X21 -> 0.8325873 | M10: =SUM(B10:L10) -> 5.9181298 | P10: Germany | R10: Germany
A11: Poland | B11: ='GHG detailed, results per kg'!H51 -> 0.62159823 | C11: ='GHG detailed, results per kg'!I51 -> 0.17858133 | D11: ='GHG detailed, results per kg'!J51+'GHG detailed, results per kg'!K51 -> 0.78077975 | E11: ='GHG detailed, results per kg'!L51 -> 0.26451266 | F11: ='GHG detailed, results per kg'!O51 -> 0.31791723 | G11: ='GHG detailed, results per kg'!P51 -> 0.2263666 | H11: ='GHG detailed, results per kg'!R51 -> 0.1986762 | I11: ='GHG detailed, results per kg'!S51 -> 0.28281134 | J11: ='GHG detailed, results per kg'!T51 -> 0.65329288 | K11: ='GHG detailed, results per kg'!W51 -> 0.64140137 | L11: ='GHG detailed, results per kg'!X51 -> 1.5656991 | M11: =SUM(B11:L11) -> 5.7316367 | P11: Poland | R11: Italy
A12: Spain | B12: ='GHG detailed, results per kg'!H56 -> 0.62609366 | C12: ='GHG detailed, results per kg'!I56 -> 0.18926471 | D12: ='GHG detailed, results per kg'!J56+'GHG detailed, results per kg'!K56 -> 0.41729961 | E12: ='GHG detailed, results per kg'!L56 -> 0.2870132 | F12: ='GHG detailed, results per kg'!O56 -> 0.24904614 | G12: ='GHG detailed, results per kg'!P56 -> 0.35911706 | H12: ='GHG detailed, results per kg'!R56 -> 0.30245702 | I12: ='GHG detailed, results per kg'!S56 -> 0.2904089 | J12: ='GHG detailed, results per kg'!T56 -> 2.180305 | K12: ='GHG detailed, results per kg'!W56 -> 0.28940494 | L12: ='GHG detailed, results per kg'!X56 -> 0.56212541 | M12: =SUM(B12:L12) -> 5.7525356 | P12: Spain | R12: Ireland
A13: France | B13: ='GHG detailed, results per kg'!H16 -> 0.63737686 | C13: ='GHG detailed, results per kg'!I16 -> 0.16715521 | D13: ='GHG detailed, results per kg'!J16+'GHG detailed, results per kg'!K16 -> 0.73893686 | E13: ='GHG detailed, results per kg'!L16 -> 0.17216528 | F13: ='GHG detailed, results per kg'!O16 -> 0.21375332 | G13: ='GHG detailed, results per kg'!P16 -> 0.17506262 | H13: ='GHG detailed, results per kg'!R16 -> 0.18375083 | I13: ='GHG detailed, results per kg'!S16 -> 0.28463898 | J13: ='GHG detailed, results per kg'!T16 -> 2.3100127 | K13: ='GHG detailed, results per kg'!W16 -> 0.19135994 | L13: ='GHG detailed, results per kg'!X16 -> 0.29265189 | M13: =SUM(B13:L13) -> 5.3668645 | P13: France | R13: France
A14: Hungary | B14: ='GHG detailed, results per kg'!H31 -> 0.51241987 | C14: ='GHG detailed, results per kg'!I31 -> 0.16925719 | D14: ='GHG detailed, results per kg'!J31+'GHG detailed, results per kg'!K31 -> 0.31985717 | E14: ='GHG detailed, results per kg'!L31 -> 0.20121631 | F14: ='GHG detailed, results per kg'!O31 -> 0.2416202 | G14: ='GHG detailed, results per kg'!P31 -> 0.27301429 | H14: ='GHG detailed, results per kg'!R31 -> 0.22356718 | I14: ='GHG detailed, results per kg'!S31 -> 0.28136403 | J14: ='GHG detailed, results per kg'!T31 -> 1.3757456 | K14: ='GHG detailed, results per kg'!W31 -> 0.37143362 | L14: ='GHG detailed, results per kg'!X31 -> 0.80361469 | M14: =SUM(B14:L14) -> 4.7731102 | P14: Hungary | R14: Spain
A15: Ireland | B15: ='GHG detailed, results per kg'!H36 -> 0.50221124 | C15: ='GHG detailed, results per kg'!I36 -> 0.15797579 | D15: ='GHG detailed, results per kg'!J36+'GHG detailed, results per kg'!K36 -> 0.71205058 | E15: ='GHG detailed, results per kg'!L36 -> 0.16440476 | F15: ='GHG detailed, results per kg'!O36 -> 0.22842459 | G15: ='GHG detailed, results per kg'!P36 -> 0.28758245 | H15: ='GHG detailed, results per kg'!R36 -> 0.26674907 | I15: ='GHG detailed, results per kg'!S36 -> 0.28139873 | J15: ='GHG detailed, results per kg'!T36 -> 0.62232911 | K15: ='GHG detailed, results per kg'!W36 -> 0.33760762 | L15: ='GHG detailed, results per kg'!X36 -> 0.71434306 | M15: =SUM(B15:L15) -> 4.275077 | P15: Ireland | R15: Poland
A16: Denmark | B16: ='GHG detailed, results per kg'!H11 -> 0.46723394 | C16: ='GHG detailed, results per kg'!I11 -> 0.16000251 | D16: ='GHG detailed, results per kg'!J11+'GHG detailed, results per kg'!K11 -> 0.95769224 | E16: ='GHG detailed, results per kg'!L11 -> 0.17201428 | F16: ='GHG detailed, results per kg'!O11 -> 0.21941667 | G16: ='GHG detailed, results per kg'!P11 -> 0.076417363 | H16: ='GHG detailed, results per kg'!R11 -> 0.080333613 | I16: ='GHG detailed, results per kg'!S11 -> 0.28131564 | J16: ='GHG detailed, results per kg'!T11 -> 0.66756856 | K16: ='GHG detailed, results per kg'!W11 -> 0.33407853 | L16: ='GHG detailed, results per kg'!X11 -> 0.69072184 | M16: =SUM(B16:L16) -> 4.1067952 | P16: Denmark | R16: Denmark
A17: Sweden | B17: ='GHG detailed, results per kg'!H61 -> 0.44049117 | C17: ='GHG detailed, results per kg'!I61 -> 0.16629496 | D17: ='GHG detailed, results per kg'!J61+'GHG detailed, results per kg'!K61 -> 0.90657945 | E17: ='GHG detailed, results per kg'!L61 -> 0.22864813 | F17: ='GHG detailed, results per kg'!O61 -> 0.20368254 | G17: ='GHG detailed, results per kg'!P61 -> 0.079221403 | H17: ='GHG detailed, results per kg'!R61 -> 0.077443604 | I17: ='GHG detailed, results per kg'!S61 -> 0.28143916 | J17: ='GHG detailed, results per kg'!T61 -> 0.68869363 | K17: ='GHG detailed, results per kg'!W61 -> 0.10956747 | L17: ='GHG detailed, results per kg'!X61 -> 0.28752682 | M17: =SUM(B17:L17) -> 3.4695883 | P17: Sweden | R17: Sweden
P20: Explanation:
P21: - We include slaugthering that gives a high value for Poland
P22: - Ireland has only liquid manure and a low MCF
P23: - Italy has also only liquid manure but a much higher MCF
P24: - France and Greece also has very high MCF
P25: - Hungary (and Italy, Spain, Greece) has low emissions from feed because of lower N2O-factors (dry climate)
A30: Water use
A33: Denmark | B33: 0.34945447
A34: France | B34: 0.47801159
A35: Germany | B35: 0.35489833
A36: Greece | B36: 0.38101452
A37: Hungary | B37: 0.34634088
A38: Ireland | B38: 0.33400348
A39: Italy | B39: 0.68514742
A40: Netherlands | B40: 0.47153216
A41: Poland | B41: 0.34621616
A42: Spain | B42: 1.2637786
A43: Sweden | B43: 0.33340769

Sheet Footprints, results per kg
A2: Footprints (per kg of bonefree meat) | M2: * Adjusted for manure | T2: **Values inserted directly here, no formula in this excel sheet
A5: Animal products | F5: Climate | L5: Land | M5: Nitrogen* | N5: Phosphorus | O5: Water | P5: Pesticides | Q5: Biodiversity | R5: Ammonia | S5: Labour | T5: Animal welfare** | U5: Use of antibiotics**
A6: Code | B6: Name | C6: Category | D6: Country | E6: Country code | F6: Carbon footprint, kg CO2e/kg | G6: Carbon dioxide, kg CO2/kg | H6: Methane, fossil, kg CH4/kg | I6: Methane, biogenic, kg CH4/kg | J6: Nitrous oxide, kg N2O/kg | K6: HFCs, kg HFCs/kg | L6: Cropland use, m2/kg | M6: New N input, kg N/kg | N6: New P input, kg P/kg | O6: Blue freshwater use, m3/kg | P6: Pesticide use, g a.i./kg | Q6: Extinction rate, E/MSY/kg | R6: Ammonia emission, kg NH3/kg | S6: Labour requirements, h/kg | T6: Animal welfare index per kg of bonefree meat | U6: Antibiotics use indicator/kg
A7: 21113.02 | B7: Pig meat | C7: Red meat | D7: Denmark | E7: DK | F7: ='GHG detailed, results per kg'!G11 -> 4.1300466 | G7: ='GHG detailed, results per kg'!G7 -> 1.9362934 | H7: ='GHG detailed, results per kg'!G8 -> 0.0026107373 | I7: ='GHG detailed, results per kg'!G9 -> 0.024715653 | J7: ='GHG detailed, results per kg'!G10 -> 0.0053063391 | L7: ='EFP per kg feed'!F17*FCR_bonefree_incl_parents_DK -> 10.292151 | M7: ='EFP per kg feed'!G17*FCR_bonefree_incl_parents_DK-Manure_repl_factor_DK*Excreted_N_after_losses_DK -> 0.13997193 | N7: ='EFP per kg feed'!H17*FCR_bonefree_incl_parents_DK -> 0.017708872 | O7: ='EFP per kg feed'!I17*FCR_bonefree_incl_parents_DK+'Parameters, country spec'!B113 -> 0.24003053 | P7: ='EFP per kg feed'!J17*FCR_bonefree_incl_parents_DK -> 1.4400172 | Q7: ='EFP per kg feed'!K17*FCR_bonefree_incl_parents_DK -> 9.2742555e-10 | R7: ='EFP per kg feed'!L17*FCR_bonefree_incl_parents_DK+NH3_per_kg_DK -> 0.044219552 | S7: ='Parameters, country spec'!$B$116/Production!$B$35 -> 0.027003692 | T7: 3.7603025 | U7: 38.723404
A8: 21113.02 | B8: Pig meat | C8: Red meat | D8: France | E8: FR | F8: ='GHG detailed, results per kg'!G16 -> 5.4172082 | G8: ='GHG detailed, results per kg'!G12 -> 1.7668012 | H8: ='GHG detailed, results per kg'!G13 -> 0.0023924705 | I8: ='GHG detailed, results per kg'!G14 -> 0.08527464 | J8: ='GHG detailed, results per kg'!G15 -> 0.0046765426 | L8: ='EFP per kg feed'!F29*FCR_bonefree_incl_parents_FR -> 9.3271779 | M8: ='EFP per kg feed'!G29*FCR_bonefree_incl_parents_FR-Manure_repl_factor_FR*Excreted_N_after_losses_FR -> 0.1357343 | N8: ='EFP per kg feed'!H29*FCR_bonefree_incl_parents_FR -> 0.021163373 | O8: ='EFP per kg feed'!I29*FCR_bonefree_incl_parents_FR+'Parameters, country spec'!C113 -> 0.37568772 | P8: ='EFP per kg feed'!J29*FCR_bonefree_incl_parents_FR -> 1.3872171 | Q8: ='EFP per kg feed'!K29*FCR_bonefree_incl_parents_FR -> 2.7407511e-09 | R8: ='EFP per kg feed'!L29*FCR_bonefree_incl_parents_FR+NH3_per_kg_FR -> 0.046048212 | S8: ='Parameters, country spec'!$C$116/Production!$C$35 -> 0.041914964 | T8: 3.8528814 | U8: 76.777668
A9: 21113.02 | B9: Pig meat | C9: Red meat | D9: Germany | E9: DE | F9: ='GHG detailed, results per kg'!G21 -> 5.9785746 | G9: ='GHG detailed, results per kg'!G17 -> 2.753196 | H9: ='GHG detailed, results per kg'!G18 -> 0.0037839547 | I9: ='GHG detailed, results per kg'!G19 -> 0.06492593 | J9: ='GHG detailed, results per kg'!G20 -> 0.0049802809 | L9: ='EFP per kg feed'!F41*FCR_bonefree_incl_parents_DE -> 9.8994309 | M9: ='EFP per kg feed'!G41*FCR_bonefree_incl_parents_DE-Manure_repl_factor_DE*Excreted_N_after_losses_DE -> 0.15793644 | N9: ='EFP per kg feed'!H41*FCR_bonefree_incl_parents_DE -> 0.021644677 | O9: ='EFP per kg feed'!I41*FCR_bonefree_incl_parents_DE+'Parameters, country spec'!D113 -> 0.22815637 | P9: ='EFP per kg feed'!J41*FCR_bonefree_incl_parents_DE -> 2.5181391 | Q9: ='EFP per kg feed'!K41*FCR_bonefree_incl_parents_DE -> 9.0048737e-10 | R9: ='EFP per kg feed'!L41*FCR_bonefree_incl_parents_DE+NH3_per_kg_DE -> 0.047846814 | S9: ='Parameters, country spec'!$D$116/Production!$D$35 -> 0.046802605 | T9: 3.6585123 | U9: 100.81925
A10: 21113.02 | B10: Pig meat | C10: Red meat | D10: Greece | E10: GR | F10: ='GHG detailed, results per kg'!G26 -> 8.5748605 | G10: ='GHG detailed, results per kg'!G22 -> 3.1066523 | H10: ='GHG detailed, results per kg'!G23 -> 0.0044234429 | I10: ='GHG detailed, results per kg'!G24 -> 0.16655426 | J10: ='GHG detailed, results per kg'!G25 -> 0.003074816 | L10: ='EFP per kg feed'!F42*FCR_bonefree_incl_parents_GR -> 23.067975 | M10: ='EFP per kg feed'!G42*FCR_bonefree_incl_parents_GR-Manure_repl_factor_GR*Excreted_N_after_losses_GR -> 0.11690421 | N10: ='EFP per kg feed'!H42*FCR_bonefree_incl_parents_GR -> 0.020315546 | O10: ='EFP per kg feed'!I42*FCR_bonefree_incl_parents_GR+'Parameters, country spec'!E113 -> 0.22214015 | P10: ='EFP per kg feed'!J42*FCR_bonefree_incl_parents_GR -> 1.0485443 | Q10: ='EFP per kg feed'!K42*FCR_bonefree_incl_parents_GR -> 3.8075265e-08 | R10: ='EFP per kg feed'!L53*FCR_bonefree_incl_parents_GR+NH3_per_kg_GR -> 0.045717758 | S10: ='Parameters, country spec'!$E$116/Production!$E$35 -> 0.030958065 | T10: 3.778257 | U10: 224.64811
A11: 21113.02 | B11: Pig meat | C11: Red meat | D11: Hungary | E11: HU | F11: ='GHG detailed, results per kg'!G31 -> 4.8295218 | G11: ='GHG detailed, results per kg'!G27 -> 2.5269021 | H11: ='GHG detailed, results per kg'!G28 -> 0.0038934293 | I11: ='GHG detailed, results per kg'!G29 -> 0.050732608 | J11: ='GHG detailed, results per kg'!G30 -> 0.0029919966 | L11: ='EFP per kg feed'!F65*FCR_bonefree_incl_parents_HU -> 10.993961 | M11: ='EFP per kg feed'!G65*FCR_bonefree_incl_parents_HU-Manure_repl_factor_HU*Excreted_N_after_losses_HU -> 0.12227569 | N11: ='EFP per kg feed'!H65*FCR_bonefree_incl_parents_HU -> 0.025164882 | O11: ='EFP per kg feed'!I65*FCR_bonefree_incl_parents_HU+'Parameters, country spec'!F113 -> 0.24979118 | P11: ='EFP per kg feed'!J65*FCR_bonefree_incl_parents_HU -> 1.0177608 | Q11: ='EFP per kg feed'!K65*FCR_bonefree_incl_parents_HU -> 9.0646474e-10 | R11: ='EFP per kg feed'!L65*FCR_bonefree_incl_parents_HU+NH3_per_kg_HU -> 0.04325173 | S11: ='Parameters, country spec'!$F$116/Production!$F$35 -> 0.1336662 | T11: 3.6643868 | U11: 206.86403
A12: 21113.02 | B12: Pig meat | C12: Red meat | D12: Ireland | E12: IE | F12: ='GHG detailed, results per kg'!G36 -> 4.3323515 | G12: ='GHG detailed, results per kg'!G32 -> 2.436667 | H12: ='GHG detailed, results per kg'!G33 -> 0.0025653582 | I12: ='GHG detailed, results per kg'!G34 -> 0.021317295 | J12: ='GHG detailed, results per kg'!G35 -> 0.0045555674 | L12: ='EFP per kg feed'!F77*FCR_bonefree_incl_parents_IE -> 8.9675416 | M12: ='EFP per kg feed'!G77*FCR_bonefree_incl_parents_IE-Manure_repl_factor_IE*Excreted_N_after_losses_IE -> 0.12916069 | N12: ='EFP per kg feed'!H77*FCR_bonefree_incl_parents_IE -> 0.01919283 | O12: ='EFP per kg feed'!I77*FCR_bonefree_incl_parents_IE++'Parameters, country spec'!G113 -> 0.22479402 | P12: ='EFP per kg feed'!J77*FCR_bonefree_incl_parents_IE -> 2.0647553 | Q12: ='EFP per kg feed'!K77*FCR_bonefree_incl_parents_IE -> 9.0353146e-10 | R12: ='EFP per kg feed'!L77*FCR_bonefree_incl_parents_IE+NH3_per_kg_IE -> 0.049815548 | S12: ='Parameters, country spec'!$G$116/Production!$G$35 -> 0.089758069 | T12: 3.6547805 | U12: 80.832611
A13: 21113.02 | B13: Pig meat | C13: Red meat | D13: Italy | E13: IT | F13: ='GHG detailed, results per kg'!G41 -> 6.2138803 | G13: ='GHG detailed, results per kg'!G37 -> 2.3937768 | H13: ='GHG detailed, results per kg'!G38 -> 0.0047976361 | I13: ='GHG detailed, results per kg'!G39 -> 0.10354346 | J13: ='GHG detailed, results per kg'!G40 -> 0.0032287936 | L13: ='EFP per kg feed'!F89*FCR_bonefree_incl_parents_IT -> 10.675796 | M13: ='EFP per kg feed'!G89*FCR_bonefree_incl_parents_IT-Manure_repl_factor_IT*Excreted_N_after_losses_IT -> 0.11921154 | N13: ='EFP per kg feed'!H89*FCR_bonefree_incl_parents_IT -> 0.02575419 | O13: ='EFP per kg feed'!I89*FCR_bonefree_incl_parents_IT+'Parameters, country spec'!H113 -> 0.53893006 | P13: ='EFP per kg feed'!J89*FCR_bonefree_incl_parents_IT -> 1.2218157 | Q13: ='EFP per kg feed'!K89*FCR_bonefree_incl_parents_IT -> 9.8384666e-09 | R13: ='EFP per kg feed'!L89*FCR_bonefree_incl_parents_IT+NH3_per_kg_IT -> 0.057088518 | S13: ='Parameters, country spec'!$H$116/Production!$H$35 -> 0.035525752 | T13: 2.9314832 | U13: 261.49844
A14: 21113.02 | B14: Pig meat | C14: Red meat | D14: Netherlands | E14: NL | F14: ='GHG detailed, results per kg'!G46 -> 7.1941901 | G14: ='GHG detailed, results per kg'!G42 -> 2.8350652 | H14: ='GHG detailed, results per kg'!G43 -> 0.0039348221 | I14: ='GHG detailed, results per kg'!G44 -> 0.10377627 | J14: ='GHG detailed, results per kg'!G45 -> 0.0052743879 | L14: ='EFP per kg feed'!F101*FCR_bonefree_incl_parents_NL -> 9.2562815 | M14: ='EFP per kg feed'!G101*FCR_bonefree_incl_parents_NL-Manure_repl_factor_NL*Excreted_N_after_losses_NL -> 0.15319968 | N14: ='EFP per kg feed'!H101*FCR_bonefree_incl_parents_NL -> 0.022927931 | O14: ='EFP per kg feed'!I101*FCR_bonefree_incl_parents_NL+'Parameters, country spec'!I113 -> 0.25167754 | P14: ='EFP per kg feed'!J101*FCR_bonefree_incl_parents_NL -> 2.8406012 | Q14: ='EFP per kg feed'!K101*FCR_bonefree_incl_parents_NL -> 9.1344276e-10 | R14: ='EFP per kg feed'!L101*FCR_bonefree_incl_parents_NL+NH3_per_kg_NL -> 0.044542832 | S14: ='Parameters, country spec'!$I$116/Production!$I$35 -> 0.055045243 | T14: 3.521251 | U14: 64.140831
A15: 21113.02 | B15: Pig meat | C15: Red meat | D15: Poland | E15: PL | F15: ='GHG detailed, results per kg'!G51 -> 5.7877933 | G15: ='GHG detailed, results per kg'!G47 -> 3.6556618 | H15: ='GHG detailed, results per kg'!G48 -> 0.0055545778 | I15: ='GHG detailed, results per kg'!G49 -> 0.023823352 | J15: ='GHG detailed, results per kg'!G50 -> 0.0048475259 | L15: ='EFP per kg feed'!F113*FCR_bonefree_incl_parents_PL -> 14.194057 | M15: ='EFP per kg feed'!G113*FCR_bonefree_incl_parents_PL-Manure_repl_factor_PL*Excreted_N_after_losses_PL -> 0.13680097 | N15: ='EFP per kg feed'!H113*FCR_bonefree_incl_parents_PL -> 0.020929677 | O15: ='EFP per kg feed'!I113*FCR_bonefree_incl_parents_PL+'Parameters, country spec'!J113 -> 0.23125061 | P15: ='EFP per kg feed'!J113*FCR_bonefree_incl_parents_PL -> 1.4081601 | Q15: ='EFP per kg feed'!K113*FCR_bonefree_incl_parents_PL -> 1.0564905e-09 | R15: ='EFP per kg feed'!L113*FCR_bonefree_incl_parents_PL+NH3_per_kg_PL -> 0.044434048 | S15: ='Parameters, country spec'!$J$116/Production!$J$35 -> 0.1426763 | T15: 3.778257 | U15: 269.1008
A16: 21113.02 | B16: Pig meat | C16: Red meat | D16: Spain | E16: ES | F16: ='GHG detailed, results per kg'!G56 -> 5.8912845 | G16: ='GHG detailed, results per kg'!G52 -> 2.6323885 | H16: ='GHG detailed, results per kg'!G53 -> 0.0039492799 | I16: ='GHG detailed, results per kg'!G54 -> 0.080767748 | J16: ='GHG detailed, results per kg'!G55 -> 0.0035182355 | L16: ='EFP per kg feed'!F125*FCR_bonefree_incl_parents_ES -> 15.509038 | M16: ='EFP per kg feed'!G125*FCR_bonefree_incl_parents_ES-Manure_repl_factor_ES*Excreted_N_after_losses_ES -> 0.15207823 | N16: ='EFP per kg feed'!H125*FCR_bonefree_incl_parents_ES -> 0.024494507 | O16: ='EFP per kg feed'!I125*FCR_bonefree_incl_parents_ES+'Parameters, country spec'!K113 -> 1.5700251 | P16: ='EFP per kg feed'!J125*FCR_bonefree_incl_parents_ES -> 1.0778178 | Q16: ='EFP per kg feed'!K125*FCR_bonefree_incl_parents_ES -> 2.4797385e-08 | R16: ='EFP per kg feed'!L125*FCR_bonefree_incl_parents_ES+NH3_per_kg_ES -> 0.043977855 | S16: ='Parameters, country spec'!$K$116/Production!$K$35 -> 0.014011909 | T16: 3.9766059 | U16: 193.14711
A17: 21113.02 | B17: Pig meat | C17: Red meat | D17: Sweden | E17: SE | F17: ='GHG detailed, results per kg'!G61 -> 3.519973 | G17: ='GHG detailed, results per kg'!G57 -> 1.4275402 | H17: ='GHG detailed, results per kg'!G58 -> 0.0014265311 | I17: ='GHG detailed, results per kg'!G59 -> 0.023288092 | J17: ='GHG detailed, results per kg'!G60 -> 0.0052056544 | L17: ='EFP per kg feed'!F137*FCR_bonefree_incl_parents_SE -> 12.340046 | M17: ='EFP per kg feed'!G137*FCR_bonefree_incl_parents_SE-Manure_repl_factor_SE*Excreted_N_after_losses_SE -> 0.10985702 | N17: ='EFP per kg feed'!H137*FCR_bonefree_incl_parents_SE -> 0.012766316 | O17: ='EFP per kg feed'!I137*FCR_bonefree_incl_parents_SE+'Parameters, country spec'!L113 -> 0.22203965 | P17: ='EFP per kg feed'!J137*FCR_bonefree_incl_parents_SE -> 0.823873 | Q17: ='EFP per kg feed'!K137*FCR_bonefree_incl_parents_SE -> 3.3035686e-10 | R17: ='EFP per kg feed'!L137*FCR_bonefree_incl_parents_SE+NH3_per_kg_SE -> 0.051449771 | S17: ='Parameters, country spec'!$L$116/Production!$L$35 -> 0.027680337 | T17: 2.8930739 | U17: 19.938176

Sheet GHG detailed, results per kg
H1: * Production of mineral fertiliser is adjusted to account for the N supplied by manure. | S1: **** Slaughtering pigs starts emitting methane when after 4 months
A2: GHG emissions (per kg of bonefree meat) | H2: ** Adjusted for use of manure instead of mineral fertiliser (lower emission factor for manure)
H3: *** Calculated as percentage of direct emissions due to assumption due to data limitations regarding nitrogen leaching and volatilization from soils in different regions.
S4: Animals | W4: Stables | X4: Slaughter | Z4: Control
A5: Animal products | G5: Sum | H5: Inputs | J5: Soil emissions | L5: Energy use | P5: Land use change | Q5: Feed processing | R5: Transports
A6: FoodEx code | B6: FoodEx name | C6: Food Ex category (L1) | D6: Country | E6: Country code | F6: Gas | G6: GHG | H6: Production of mineral fertilizer* | I6: Production of capital goods | J6: Direct emissions** | K6: Indirect emissions*** | L6: Diesel use field mach | M6: Energy use in greenhouses | N6: Energy use for irrigation | O6: Energy use for post-harvest proc | P6: LUC emissions | Q6: Feed processing | R6: Feed transports | S6: Enteric fermentation**** | T6: Manure management - tot | U6: Manure management - direct | V6: Manure management - indirect | W6: Energy use in stables | X6: Energy use for slaughter | Z6: Total feed, excl LUC | AA6: Feed mix emissions, kg CO2 per kg feed, excl. adjustement manure
A7: A01RG | B7: Pig muscle | C7: Meat and meat products | D7: Denmark | E7: DK | F7: CO2 | G7: =SUM(H7:X7) -> 1.9362934 | H7: ='CO2 per kg feed'!G17*FCR_bonefree_incl_parents_DK-Excreted_N_after_losses_DK*Manure_repl_factor_DK*(EF_min_fert_BAT_CO2*Frac_BAT_DK+EF_min_fert_AN_CO2*Frac_AN_DK) -> 0.27181653 | I7: ='CO2 per kg feed'!H17*FCR_bonefree_incl_parents_DK -> 0.14151905 | J7: ='CO2 per kg feed'!I17*FCR_bonefree_incl_parents_DK -> 0 | L7: ='CO2 per kg feed'!K17*FCR_bonefree_incl_parents_DK -> 0.16817242 | N7: ='CO2 per kg feed'!M17*FCR_bonefree_incl_parents_DK -> 0.0036101429 | O7: ='CO2 per kg feed'!N17*FCR_bonefree_incl_parents_DK -> 0.21284364 | P7: ='CO2 per kg feed'!O17*FCR_bonefree_incl_parents_DK -> 0.076417363 | Q7: ='CO2 per kg feed'!P17*FCR_bonefree_incl_parents_DK -> 0.012352194 | R7: ='CO2 per kg feed'!Q17*FCR_bonefree_incl_parents_DK -> 0.072021636 | W7: =Energy_stables_DK/Bonefree_outof_CW_DK*(Share_heating_DK*(Share_biofuels_DK*EF_biofuels_CO2+(1-Share_biofuels_DK)*EF_oil_CO2)+(1-Share_heating_DK)*EF_el_CO2_DK) -> 0.31782732 | X7: =(Energy_slaughter_el_DK*EF_el_CO2_DK+Energy_slaughter_oil_DK*EF_oil_CO2)/Bonefree_outof_CW_DK -> 0.65971313
A8: A01RG | B8: Pig muscle | C8: Meat and meat products | D8: Denmark | E8: DK | F8: CH4, fossil | G8: =SUM(H8:X8) -> 0.0026107373 | H8: ='CH4 per kg feed'!G17*FCR_bonefree_incl_parents_DK-Excreted_N_after_losses_DK*Manure_repl_factor_DK*(EF_min_fert_BAT_CH4*Frac_BAT_DK+EF_min_fert_AN_CH4*Frac_AN_DK) -> 0.00041279655 | I8: ='CH4 per kg feed'!H17*FCR_bonefree_incl_parents_DK -> 0.00056712168 | L8: ='CH4 per kg feed'!K17*FCR_bonefree_incl_parents_DK -> 8.2813454e-05 | N8: ='CH4 per kg feed'!M17*FCR_bonefree_incl_parents_DK -> 7.0862217e-06 | O8: ='CH4 per kg feed'!N17*FCR_bonefree_incl_parents_DK -> 0.00013852463 | P8: ='CH4 per kg feed'!O17*FCR_bonefree_incl_parents_DK -> 0 | Q8: ='CH4 per kg feed'!P17*FCR_bonefree_incl_parents_DK -> 0.00012254842 | R8: ='CH4 per kg feed'!Q17*FCR_bonefree_incl_parents_DK -> 0.00020418257 | W8: =Energy_stables_DK/Bonefree_outof_CW_DK*(Share_heating_DK*(Share_biofuels_DK*EF_biofuel_CH4+(1-Share_biofuels_DK)*EF_oil_CH4)+(1-Share_heating_DK)*EF_el_CH4_DK) -> 0.00032293375 | X8: =(Energy_slaughter_el_DK*EF_el_CH4_DK+Energy_slaughter_oil_DK*EF_oil_CH4)/Bonefree_outof_CW_DK -> 0.00075273006
A9: A01RG | B9: Pig muscle | C9: Meat and meat products | D9: Denmark | E9: DK | F9: CH4, biogenic | G9: =SUM(H9:T9)+SUM(W9:X9) -> 0.024715653 | S9: =(Production!B37+Production!B38+Production!B39*4/12)*EF_ent_ferm_DK -> 0.010419098 | T9: =SUM(U9:V9) -> 0.014296555 | U9: =Manure!E32 -> 0.014296555
A10: A01RG | B10: Pig muscle | C10: Meat and meat products | D10: Denmark | E10: DK | F10: N2O | G10: =SUM(H10:T10)+SUM(W10:X10) -> 0.0053063391 | H10: ='N2O per kg feed'!G17*FCR_bonefree_incl_parents_DK-Excreted_N_after_losses_DK*Manure_repl_factor_DK*(EF_min_fert_BAT_N2O*Frac_BAT_DK+EF_min_fert_AN_N2O*Frac_AN_DK) -> 0.00067075482 | I10: ='N2O per kg feed'!H17*FCR_bonefree_incl_parents_DK -> 5.7993945e-06 | J10: ='N2O per kg feed'!I17*FCR_bonefree_incl_parents_DK-Excreted_N_after_losses_DK*Manure_repl_factor_DK*EF_N2O_diff_DK -> 0.0031891183 | K10: =J10*EF_indirect_N2O_DK -> 0.00031891183 | L10: ='N2O per kg feed'!K17*FCR_bonefree_incl_parents_DK -> 5.0330577e-06 | N10: ='N2O per kg feed'!M17*FCR_bonefree_incl_parents_DK -> 8.6959133e-08 | O10: ='N2O per kg feed'!N17*FCR_bonefree_incl_parents_DK -> 8.9560319e-06 | P10: ='N2O per kg feed'!O17*FCR_bonefree_incl_parents_DK -> 0 | Q10: ='N2O per kg feed'!P17*FCR_bonefree_incl_parents_DK -> 1.2462379e-05 | R10: ='N2O per kg feed'!Q17*FCR_bonefree_incl_parents_DK -> 8.1587425e-06 | T10: =SUM(U10:V10) -> 0.0010313611 | U10: =Manure!E88*44/28 -> 0.00058398406 | V10: =NH3_per_kg_DK*17/14*Manure!B117 -> 0.00044737702 | W10: =Energy_stables_DK/Bonefree_outof_CW_DK*(Share_heating_DK*(Share_biofuels_DK*EF_biofuel_N2O+(1-Share_biofuels_DK)*EF_oil_N2O)+(1-Share_heating_DK)*EF_el_N2O_DK) -> 2.4277567e-05 | X10: =(Energy_slaughter_el_DK*EF_el_N2O_DK+Energy_slaughter_oil_DK*EF_oil_N2O)/Bonefree_outof_CW_DK -> 3.1418859e-05
A11: A01RG | B11: Pig muscle | C11: Meat and meat products | D11: Denmark | E11: DK | F11: CO2e | G11: =SUM(H11:X11) -> 4.1300466 | H11: =SUMPRODUCT(H7:H10,'Parameters, general'!$B$13:$B$16) -> 0.46723394 | I11: =SUMPRODUCT(I7:I10,'Parameters, general'!$B$13:$B$16) -> 0.16000251 | J11: =SUMPRODUCT(J7:J10,'Parameters, general'!$B$13:$B$16) -> 0.87062931 | K11: =SUMPRODUCT(K7:K10,'Parameters, general'!$B$13:$B$16) -> 0.087062931 | L11: =SUMPRODUCT(L7:L10,'Parameters, general'!$B$13:$B$16) -> 0.17201428 | M11: =SUMPRODUCT(M7:M10,'Parameters, general'!$B$13:$B$16) -> 0 | N11: =SUMPRODUCT(N7:N10,'Parameters, general'!$B$13:$B$16) -> 0.0038450521 | O11: =SUMPRODUCT(O7:O10,'Parameters, general'!$B$13:$B$16) -> 0.21941667 | ... T11: =SUMPRODUCT(T7:T10,'Parameters, general'!$B$13:$B$16) -> 0.66756856 | W11: =SUMPRODUCT(W7:W10,'Parameters, general'!$B$13:$B$16) -> 0.33407853 | X11: =SUMPRODUCT(X7:X10,'Parameters, general'!$B$13:$B$16) -> 0.69072184 | Z11: =SUM(H11:R11) -> 2.156362 | AA11: ='CO2 per kg feed'!F17+'CH4 per kg feed'!F17*CF_GWP_CH4_fossil+'N2O per kg feed'!F17*CF_GWP_N2O -> 0.26512851
A12: A01RG | B12: Pig muscle | C12: Meat and meat products | D12: France | E12: FR | F12: CO2 | G12: =SUM(H12:X12) -> 1.7668012 | H12: ='CO2 per kg feed'!G29*FCR_bonefree_incl_parents_FR-Excreted_N_after_losses_FR*Manure_repl_factor_FR*(EF_min_fert_BAT_CO2*Frac_BAT_FR+EF_min_fert_AN_CO2*Frac_AN_FR) -> 0.38961477 | I12: ='CO2 per kg feed'!H29*FCR_bonefree_incl_parents_FR -> 0.14926785 | J12: ='CO2 per kg feed'!I29*FCR_bonefree_incl_parents_FR -> 0 | L12: ='CO2 per kg feed'!K29*FCR_bonefree_incl_parents_FR -> 0.16870009 | N12: ='CO2 per kg feed'!M29*FCR_bonefree_incl_parents_FR -> 0.011101444 | O12: ='CO2 per kg feed'!N29*FCR_bonefree_incl_parents_FR -> 0.20825195 | P12: ='CO2 per kg feed'!O29*FCR_bonefree_incl_parents_FR -> 0.17506262 | Q12: ='CO2 per kg feed'!P29*FCR_bonefree_incl_parents_FR -> 0.032323539 | R12: ='CO2 per kg feed'!Q29*FCR_bonefree_incl_parents_FR -> 0.17701178 | W12: =Energy_stables_FR/Bonefree_outof_CW_FR*(Share_heating_FR*(Share_biofuels_FR*EF_biofuels_CO2+(1-Share_biofuels_FR)*EF_oil_CO2)+(1-Share_heating_FR)*EF_el_CO2_FR) -> 0.18005144 | X12: =(Energy_slaughter_el_FR*EF_el_CO2_FR+Energy_slaughter_oil_FR*EF_oil_CO2)/Bonefree_outof_CW_FR -> 0.27541572
A13: A01RG | B13: Pig muscle | C13: Meat and meat products | D13: France | E13: FR | F13: CH4, fossil | G13: =SUM(H13:X13) -> 0.0023924705 | H13: ='CH4 per kg feed'!G29*FCR_bonefree_incl_parents_FR-Excreted_N_after_losses_FR*Manure_repl_factor_FR*(EF_min_fert_BAT_CH4*Frac_BAT_FR+EF_min_fert_AN_CH4*Frac_AN_FR) -> 0.00071612041 | I13: ='CH4 per kg feed'!H29*FCR_bonefree_incl_parents_FR -> 0.00054887303 | L13: ='CH4 per kg feed'!K29*FCR_bonefree_incl_parents_FR -> 7.4749117e-05 | N13: ='CH4 per kg feed'!M29*FCR_bonefree_incl_parents_FR -> 3.8784024e-05 | O13: ='CH4 per kg feed'!N29*FCR_bonefree_incl_parents_FR -> 0.00011303871 | P13: ='CH4 per kg feed'!O29*FCR_bonefree_incl_parents_FR -> 0 | Q13: ='CH4 per kg feed'!P29*FCR_bonefree_incl_parents_FR -> 9.9216797e-05 | R13: ='CH4 per kg feed'!Q29*FCR_bonefree_incl_parents_FR -> 0.00017001082 | W13: =Energy_stables_FR/Bonefree_outof_CW_FR*(Share_heating_FR*(Share_biofuels_FR*EF_biofuel_CH4+(1-Share_biofuels_FR)*EF_oil_CH4)+(1-Share_heating_FR)*EF_el_CH4_FR) -> 0.0002057248 | X13: =(Energy_slaughter_el_FR*EF_el_CH4_FR+Energy_slaughter_oil_FR*EF_oil_CH4)/Bonefree_outof_CW_FR -> 0.00042595283
A14: A01RG | B14: Pig muscle | C14: Meat and meat products | D14: France | E14: FR | F14: CH4, biogenic | G14: =SUM(H14:T14)+SUM(W14:X14) -> 0.08527464 | S14: =(Production!C37+Production!C38+Production!C39*4/12)*EF_ent_ferm_FR -> 0.010542184 | T14: =SUM(U14:V14) -> 0.074732455 | U14: =Manure!I32 -> 0.074732455
A15: A01RG | B15: Pig muscle | C15: Meat and meat products | D15: France | E15: FR | F15: N2O | G15: =SUM(H15:T15)+SUM(W15:X15) -> 0.0046765426 | H15: ='N2O per kg feed'!G29*FCR_bonefree_incl_parents_FR-Excreted_N_after_losses_FR*Manure_repl_factor_FR*(EF_min_fert_BAT_N2O*Frac_BAT_FR+EF_min_fert_AN_N2O*Frac_AN_FR) -> 0.00082938353 | I15: ='N2O per kg feed'!H29*FCR_bonefree_incl_parents_FR -> 5.6078562e-06 | J15: ='N2O per kg feed'!I29*FCR_bonefree_incl_parents_FR-Excreted_N_after_losses_FR*Manure_repl_factor_FR*EF_N2O_diff_FR -> 0.0024606622 | K15: =J15*EF_indirect_N2O_FR -> 0.00024606622 | L15: ='N2O per kg feed'!K29*FCR_bonefree_incl_parents_FR -> 4.5335959e-06 | N15: ='N2O per kg feed'!M29*FCR_bonefree_incl_parents_FR -> 4.7800269e-07 | O15: ='N2O per kg feed'!N29*FCR_bonefree_incl_parents_FR -> 7.8125207e-06 | P15: ='N2O per kg feed'!O29*FCR_bonefree_incl_parents_FR -> 0 | Q15: ='N2O per kg feed'!P29*FCR_bonefree_incl_parents_FR -> 9.8014607e-06 | R15: ='N2O per kg feed'!Q29*FCR_bonefree_incl_parents_FR -> 6.1272279e-06 | T15: =SUM(U15:V15) -> 0.0010704631 | U15: =Manure!I88*44/28 -> 0.00060595133 | V15: =NH3_per_kg_FR*17/14*Manure!F117 -> 0.00046451175 | W15: =Energy_stables_FR/Bonefree_outof_CW_FR*(Share_heating_FR*(Share_biofuels_FR*EF_biofuel_N2O+(1-Share_biofuels_FR)*EF_oil_N2O)+(1-Share_heating_FR)*EF_el_N2O_FR) -> 1.896666e-05 | X15: =(Energy_slaughter_el_FR*EF_el_N2O_FR+Energy_slaughter_oil_FR*EF_oil_N2O)/Bonefree_outof_CW_FR -> 1.6640187e-05
A16: A01RG | B16: Pig muscle | C16: Meat and meat products | D16: France | E16: FR | F16: CO2e | G16: =SUM(H16:X16) -> 5.4172082 | H16: =SUMPRODUCT(H12:H15,'Parameters, general'!$B$13:$B$16) -> 0.63737686 | I16: =SUMPRODUCT(I12:I15,'Parameters, general'!$B$13:$B$16) -> 0.16715521 | J16: =SUMPRODUCT(J12:J15,'Parameters, general'!$B$13:$B$16) -> 0.67176079 | K16: =SUMPRODUCT(K12:K15,'Parameters, general'!$B$13:$B$16) -> 0.067176079 | L16: =SUMPRODUCT(L12:L15,'Parameters, general'!$B$13:$B$16) -> 0.17216528 | M16: =SUMPRODUCT(M12:M15,'Parameters, general'!$B$13:$B$16) -> 0 | N16: =SUMPRODUCT(N12:N15,'Parameters, general'!$B$13:$B$16) -> 0.012387703 | O16: =SUMPRODUCT(O12:O15,'Parameters, general'!$B$13:$B$16) -> 0.21375332 | ... T16: =SUMPRODUCT(T12:T15,'Parameters, general'!$B$13:$B$16) -> 2.3100127 | W16: =SUMPRODUCT(W12:W15,'Parameters, general'!$B$13:$B$16) -> 0.19135994 | X16: =SUMPRODUCT(X12:X15,'Parameters, general'!$B$13:$B$16) -> 0.29265189 | Z16: =SUM(H16:R16) -> 2.3385447 | AA16: ='CO2 per kg feed'!F29+'CH4 per kg feed'!F29*CF_GWP_CH4_fossil+'N2O per kg feed'!F29*CF_GWP_N2O -> 0.23844379
A17: A01RG | B17: Pig muscle | C17: Meat and meat products | D17: Germany | E17: DE | F17: CO2 | G17: =SUM(H17:X17) -> 2.753196 | H17: ='CO2 per kg feed'!G41*FCR_bonefree_incl_parents_DE-Excreted_N_after_losses_DE*Manure_repl_factor_DE*(EF_min_fert_BAT_CO2*Frac_BAT_DE+EF_min_fert_AN_CO2*Frac_AN_DE) -> 0.42465813 | I17: ='CO2 per kg feed'!H41*FCR_bonefree_incl_parents_DE -> 0.15652587 | J17: ='CO2 per kg feed'!I41*FCR_bonefree_incl_parents_DE -> 0 | L17: ='CO2 per kg feed'!K41*FCR_bonefree_incl_parents_DE -> 0.17803232 | N17: ='CO2 per kg feed'!M41*FCR_bonefree_incl_parents_DE -> 0.0027525334 | O17: ='CO2 per kg feed'!N41*FCR_bonefree_incl_parents_DE -> 0.25590588 | P17: ='CO2 per kg feed'!O41*FCR_bonefree_incl_parents_DE -> 0.27126559 | Q17: ='CO2 per kg feed'!P41*FCR_bonefree_incl_parents_DE -> 0.048835268 | R17: ='CO2 per kg feed'!Q41*FCR_bonefree_incl_parents_DE -> 0.27055082 | W17: =Energy_stables_DE/Bonefree_outof_CW_DE*(Share_heating_DE*(Share_biofuels_DE*EF_biofuels_CO2+(1-Share_biofuels_DE)*EF_oil_CO2)+(1-Share_heating_DE)*EF_el_CO2_DE) -> 0.35889355 | X17: =(Energy_slaughter_el_DE*EF_el_CO2_DE+Energy_slaughter_oil_DE*EF_oil_CO2)/Bonefree_outof_CW_DE -> 0.785776
A18: A01RG | B18: Pig muscle | C18: Meat and meat products | D18: Germany | E18: DE | F18: CH4, fossil | G18: =SUM(H18:X18) -> 0.0037839547 | H18: ='CH4 per kg feed'!G41*FCR_bonefree_incl_parents_DE-Excreted_N_after_losses_DE*Manure_repl_factor_DE*(EF_min_fert_BAT_CH4*Frac_BAT_DE+EF_min_fert_AN_CH4*Frac_AN_DE) -> 0.00077073451 | I18: ='CH4 per kg feed'!H41*FCR_bonefree_incl_parents_DE -> 0.0005741135 | L18: ='CH4 per kg feed'!K41*FCR_bonefree_incl_parents_DE -> 7.8694054e-05 | N18: ='CH4 per kg feed'!M41*FCR_bonefree_incl_parents_DE -> 8.2546755e-06 | O18: ='CH4 per kg feed'!N41*FCR_bonefree_incl_parents_DE -> 0.00018139038 | P18: ='CH4 per kg feed'!O41*FCR_bonefree_incl_parents_DE -> 0 | Q18: ='CH4 per kg feed'!P41*FCR_bonefree_incl_parents_DE -> 0.00015102354 | R18: ='CH4 per kg feed'!Q41*FCR_bonefree_incl_parents_DE -> 0.00025819582 | W18: =Energy_stables_DE/Bonefree_outof_CW_DE*(Share_heating_DE*(Share_biofuels_DE*EF_biofuel_CH4+(1-Share_biofuels_DE)*EF_oil_CH4)+(1-Share_heating_DE)*EF_el_CH4_DE) -> 0.00049958875 | X18: =(Energy_slaughter_el_DE*EF_el_CH4_DE+Energy_slaughter_oil_DE*EF_oil_CH4)/Bonefree_outof_CW_DE -> 0.0012619594
A19: A01RG | B19: Pig muscle | C19: Meat and meat products | D19: Germany | E19: DE | F19: CH4, biogenic | G19: =SUM(H19:T19)+SUM(W19:X19) -> 0.06492593 | S19: =(Production!D37+Production!D38+Production!D39*4/12)*EF_ent_ferm_DE -> 0.010430743 | T19: =SUM(U19:V19) -> 0.054495187 | U19: =Manure!M32 -> 0.054495187
A20: A01RG | B20: Pig muscle | C20: Meat and meat products | D20: Germany | E20: DE | F20: N2O | G20: =SUM(H20:T20)+SUM(W20:X20) -> 0.0049802809 | H20: ='N2O per kg feed'!G41*FCR_bonefree_incl_parents_DE-Excreted_N_after_losses_DE*Manure_repl_factor_DE*(EF_min_fert_BAT_N2O*Frac_BAT_DE+EF_min_fert_AN_N2O*Frac_AN_DE) -> 0.00089402844 | I20: ='N2O per kg feed'!H41*FCR_bonefree_incl_parents_DE -> 5.909493e-06 | J20: ='N2O per kg feed'!I41*FCR_bonefree_incl_parents_DE-Excreted_N_after_losses_DE*Manure_repl_factor_DE*EF_N2O_diff_DE -> 0.0026132198 | K20: =J20*EF_indirect_N2O_DE -> 0.00026132198 | L20: ='N2O per kg feed'!K41*FCR_bonefree_incl_parents_DE -> 4.7737941e-06 | N20: ='N2O per kg feed'!M41*FCR_bonefree_incl_parents_DE -> 1.0163094e-07 | O20: ='N2O per kg feed'!N41*FCR_bonefree_incl_parents_DE -> 9.5098752e-06 | P20: ='N2O per kg feed'!O41*FCR_bonefree_incl_parents_DE -> 0 | Q20: ='N2O per kg feed'!P41*FCR_bonefree_incl_parents_DE -> 1.4955368e-05 | R20: ='N2O per kg feed'!Q41*FCR_bonefree_incl_parents_DE -> 9.3863364e-06 | T20: =SUM(U20:V20) -> 0.0011085372 | U20: =Manure!M88*44/28 -> 0.00063087096 | V20: =NH3_per_kg_DE*17/14*Manure!J117 -> 0.00047766628 | W20: =Energy_stables_DE/Bonefree_outof_CW_DE*(Share_heating_DE*(Share_biofuels_DE*EF_biofuel_N2O+(1-Share_biofuels_DE)*EF_oil_N2O)+(1-Share_heating_DE)*EF_el_N2O_DE) -> 2.4819295e-05 | X20: =(Energy_slaughter_el_DE*EF_el_N2O_DE+Energy_slaughter_oil_DE*EF_oil_N2O)/Bonefree_outof_CW_DE -> 3.3717619e-05
A21: A01RG | B21: Pig muscle | C21: Meat and meat products | D21: Germany | E21: DE | F21: CO2e | G21: =SUM(H21:X21) -> 5.9785746 | H21: =SUMPRODUCT(H17:H20,'Parameters, general'!$B$13:$B$16) -> 0.69169579 | I21: =SUMPRODUCT(I17:I20,'Parameters, general'!$B$13:$B$16) -> 0.17524774 | J21: =SUMPRODUCT(J17:J20,'Parameters, general'!$B$13:$B$16) -> 0.71340901 | K21: =SUMPRODUCT(K17:K20,'Parameters, general'!$B$13:$B$16) -> 0.071340901 | L21: =SUMPRODUCT(L17:L20,'Parameters, general'!$B$13:$B$16) -> 0.18168065 | M21: =SUMPRODUCT(M17:M20,'Parameters, general'!$B$13:$B$16) -> 0 | N21: =SUMPRODUCT(N17:N20,'Parameters, general'!$B$13:$B$16) -> 0.003026268 | O21: =SUMPRODUCT(O17:O20,'Parameters, general'!$B$13:$B$16) -> 0.26390751 | ... T21: =SUMPRODUCT(T17:T20,'Parameters, general'!$B$13:$B$16) -> 1.7740007 | W21: =SUMPRODUCT(W17:W20,'Parameters, general'!$B$13:$B$16) -> 0.38055696 | X21: =SUMPRODUCT(X17:X20,'Parameters, general'!$B$13:$B$16) -> 0.8325873 | Z21: =SUM(H21:R21) -> 2.7097996 | AA21: ='CO2 per kg feed'!F41+'CH4 per kg feed'!F41*CF_GWP_CH4_fossil+'N2O per kg feed'!F41*CF_GWP_N2O -> 0.28130744
A22: A01RG | B22: Pig muscle | C22: Meat and meat products | D22: Greece | E22: GR | F22: CO2 | G22: =SUM(H22:X22) -> 3.1066523 | H22: ='CO2 per kg feed'!G53*FCR_bonefree_incl_parents_GR-Excreted_N_after_losses_GR*Manure_repl_factor_GR*(EF_min_fert_BAT_CO2*Frac_BAT_GR+EF_min_fert_AN_CO2*Frac_AN_GR) -> 0.28443233 | I22: ='CO2 per kg feed'!H53*FCR_bonefree_incl_parents_GR -> 0.1513267 | J22: ='CO2 per kg feed'!I53*FCR_bonefree_incl_parents_GR -> 0 | L22: ='CO2 per kg feed'!K53*FCR_bonefree_incl_parents_GR -> 0.25102497 | N22: ='CO2 per kg feed'!M53*FCR_bonefree_incl_parents_GR -> 0.05101316 | O22: ='CO2 per kg feed'!N53*FCR_bonefree_incl_parents_GR -> 0.25231868 | P22: ='CO2 per kg feed'!O53*FCR_bonefree_incl_parents_GR -> 0.33414898 | Q22: ='CO2 per kg feed'!P53*FCR_bonefree_incl_parents_GR -> 0.048390137 | R22: ='CO2 per kg feed'!Q53*FCR_bonefree_incl_parents_GR -> 0.26444673 | W22: =Energy_stables_GR/Bonefree_outof_CW_GR*(Share_heating_GR*(Share_biofuels_GR*EF_biofuels_CO2+(1-Share_biofuels_GR)*EF_oil_CO2)+(1-Share_heating_GR)*EF_el_CO2_GR) -> 0.44450736 | X22: =(Energy_slaughter_el_GR*EF_el_CO2_GR+Energy_slaughter_oil_GR*EF_oil_CO2)/Bonefree_outof_CW_GR -> 1.0250432
A23: A01RG | B23: Pig muscle | C23: Meat and meat products | D23: Greece | E23: GR | F23: CH4, fossil | G23: =SUM(H23:X23) -> 0.0044234429 | H23: ='CH4 per kg feed'!G53*FCR_bonefree_incl_parents_GR-Excreted_N_after_losses_GR*Manure_repl_factor_GR*(EF_min_fert_BAT_CH4*Frac_BAT_GR+EF_min_fert_AN_CH4*Frac_AN_GR) -> 0.00055277388 | I23: ='CH4 per kg feed'!H53*FCR_bonefree_incl_parents_GR -> 0.00055571876 | L23: ='CH4 per kg feed'!K53*FCR_bonefree_incl_parents_GR -> 0.0001112407 | N23: ='CH4 per kg feed'!M53*FCR_bonefree_incl_parents_GR -> 0.00017341679 | O23: ='CH4 per kg feed'!N53*FCR_bonefree_incl_parents_GR -> 0.00020528473 | P23: ='CH4 per kg feed'!O53*FCR_bonefree_incl_parents_GR -> 0 | Q23: ='CH4 per kg feed'!P53*FCR_bonefree_incl_parents_GR -> 0.00013598248 | R23: ='CH4 per kg feed'!Q53*FCR_bonefree_incl_parents_GR -> 0.00022146412 | W23: =Energy_stables_GR/Bonefree_outof_CW_GR*(Share_heating_GR*(Share_biofuels_GR*EF_biofuel_CH4+(1-Share_biofuels_GR)*EF_oil_CH4)+(1-Share_heating_GR)*EF_el_CH4_GR) -> 0.00068521536 | X23: =(Energy_slaughter_el_GR*EF_el_CH4_GR+Energy_slaughter_oil_GR*EF_oil_CH4)/Bonefree_outof_CW_GR -> 0.0017823461
A24: A01RG | B24: Pig muscle | C24: Meat and meat products | D24: Greece | E24: GR | F24: CH4, biogenic | G24: =SUM(H24:T24)+SUM(W24:X24) -> 0.16655426 | S24: =(Production!E37+Production!E38+Production!E39*4/12)*EF_ent_ferm_GR -> 0.010474494 | T24: =SUM(U24:V24) -> 0.15607976 | U24: =Manure!Q32 -> 0.15607976
A25: A01RG | B25: Pig muscle | C25: Meat and meat products | D25: Greece | E25: GR | F25: N2O | G25: =SUM(H25:T25)+SUM(W25:X25) -> 0.003074816 | H25: ='N2O per kg feed'!G53*FCR_bonefree_incl_parents_GR-Excreted_N_after_losses_GR*Manure_repl_factor_GR*(EF_min_fert_BAT_N2O*Frac_BAT_GR+EF_min_fert_AN_N2O*Frac_AN_GR) -> 0.0006286086 | I25: ='N2O per kg feed'!H53*FCR_bonefree_incl_parents_GR -> 5.6997022e-06 | J25: ='N2O per kg feed'!I53*FCR_bonefree_incl_parents_GR-Excreted_N_after_losses_GR*Manure_repl_factor_GR*EF_N2O_diff_GR -> 0.0011092799 | K25: =J25*EF_indirect_N2O_GR -> 0.00011092799 | L25: ='N2O per kg feed'!K53*FCR_bonefree_incl_parents_GR -> 6.7486538e-06 | N25: ='N2O per kg feed'!M53*FCR_bonefree_incl_parents_GR -> 2.1336225e-06 | O25: ='N2O per kg feed'!N53*FCR_bonefree_incl_parents_GR -> 8.8923391e-06 | P25: ='N2O per kg feed'!O53*FCR_bonefree_incl_parents_GR -> 0 | Q25: ='N2O per kg feed'!P53*FCR_bonefree_incl_parents_GR -> 1.4141267e-05 | R25: ='N2O per kg feed'!Q53*FCR_bonefree_incl_parents_GR -> 9.5719474e-06 | T25: =SUM(U25:V25) -> 0.0011179027 | U25: =Manure!Q88*44/28 -> 0.0006327308 | V25: =NH3_per_kg_GR*17/14*Manure!N117 -> 0.00048517188 | W25: =Energy_stables_GR/Bonefree_outof_CW_GR*(Share_heating_GR*(Share_biofuels_GR*EF_biofuel_N2O+(1-Share_biofuels_GR)*EF_oil_N2O)+(1-Share_heating_GR)*EF_el_N2O_GR) -> 2.5478087e-05 | X25: =(Energy_slaughter_el_GR*EF_el_N2O_GR+Energy_slaughter_oil_GR*EF_oil_N2O)/Bonefree_outof_CW_GR -> 3.5431198e-05
A26: A01RG | B26: Pig muscle | C26: Meat and meat products | D26: Greece | E26: GR | F26: CO2e | G26: =SUM(H26:X26) -> 8.5748605 | H26: =SUMPRODUCT(H22:H25,'Parameters, general'!$B$13:$B$16) -> 0.47251514 | I26: =SUMPRODUCT(I22:I25,'Parameters, general'!$B$13:$B$16) -> 0.16944313 | J26: =SUMPRODUCT(J22:J25,'Parameters, general'!$B$13:$B$16) -> 0.3028334 | K26: =SUMPRODUCT(K22:K25,'Parameters, general'!$B$13:$B$16) -> 0.03028334 | L26: =SUMPRODUCT(L22:L25,'Parameters, general'!$B$13:$B$16) -> 0.25618232 | M26: =SUMPRODUCT(M22:M25,'Parameters, general'!$B$13:$B$16) -> 0 | N26: =SUMPRODUCT(N22:N25,'Parameters, general'!$B$13:$B$16) -> 0.056763459 | O26: =SUMPRODUCT(O22:O25,'Parameters, general'!$B$13:$B$16) -> 0.26086377 | ... T26: =SUMPRODUCT(T22:T25,'Parameters, general'!$B$13:$B$16) -> 4.519341 | W26: =SUMPRODUCT(W22:W25,'Parameters, general'!$B$13:$B$16) -> 0.4718823 | X26: =SUMPRODUCT(X22:X25,'Parameters, general'!$B$13:$B$16) -> 1.0878299 | Z26: =SUM(H26:R26) -> 2.212996 | AA26: ='CO2 per kg feed'!F53+'CH4 per kg feed'!F53*CF_GWP_CH4_fossil+'N2O per kg feed'!F53*CF_GWP_N2O -> 0.27899023
A27: A01RG | B27: Pig muscle | C27: Meat and meat products | D27: Hungary | E27: HU | F27: CO2 | G27: =SUM(H27:X27) -> 2.5269021 | H27: ='CO2 per kg feed'!G65*FCR_bonefree_incl_parents_HU-Excreted_N_after_losses_HU*Manure_repl_factor_HU*(EF_min_fert_BAT_CO2*Frac_BAT_HU+EF_min_fert_AN_CO2*Frac_AN_HU) -> 0.30879912 | I27: ='CO2 per kg feed'!H65*FCR_bonefree_incl_parents_HU -> 0.15114165 | J27: ='CO2 per kg feed'!I65*FCR_bonefree_incl_parents_HU -> 0 | L27: ='CO2 per kg feed'!K65*FCR_bonefree_incl_parents_HU -> 0.19714607 | N27: ='CO2 per kg feed'!M65*FCR_bonefree_incl_parents_HU -> 0.001660166 | O27: ='CO2 per kg feed'!N65*FCR_bonefree_incl_parents_HU -> 0.23369737 | P27: ='CO2 per kg feed'!O65*FCR_bonefree_incl_parents_HU -> 0.27301429 | Q27: ='CO2 per kg feed'!P65*FCR_bonefree_incl_parents_HU -> 0.048053247 | R27: ='CO2 per kg feed'!Q65*FCR_bonefree_incl_parents_HU -> 0.2160411 | W27: =Energy_stables_HU/Bonefree_outof_CW_HU*(Share_heating_HU*(Share_biofuels_HU*EF_biofuels_CO2+(1-Share_biofuels_HU)*EF_oil_CO2)+(1-Share_heating_HU)*EF_el_CO2_HU) -> 0.34730405 | X27: =(Energy_slaughter_el_HU*EF_el_CO2_HU+Energy_slaughter_oil_HU*EF_oil_CO2)/Bonefree_outof_CW_HU -> 0.75004508
A28: A01RG | B28: Pig muscle | C28: Meat and meat products | D28: Hungary | E28: HU | F28: CH4, fossil | G28: =SUM(H28:X28) -> 0.0038934293 | H28: ='CH4 per kg feed'!G65*FCR_bonefree_incl_parents_HU-Excreted_N_after_losses_HU*Manure_repl_factor_HU*(EF_min_fert_BAT_CH4*Frac_BAT_HU+EF_min_fert_AN_CH4*Frac_AN_HU) -> 0.00059859355 | I28: ='CH4 per kg feed'!H65*FCR_bonefree_incl_parents_HU -> 0.00055591248 | L28: ='CH4 per kg feed'!K65*FCR_bonefree_incl_parents_HU -> 8.7816704e-05 | N28: ='CH4 per kg feed'!M65*FCR_bonefree_incl_parents_HU -> 7.0558672e-06 | O28: ='CH4 per kg feed'!N65*FCR_bonefree_incl_parents_HU -> 0.00019003544 | P28: ='CH4 per kg feed'!O65*FCR_bonefree_incl_parents_HU -> 0 | Q28: ='CH4 per kg feed'!P65*FCR_bonefree_incl_parents_HU -> 0.00011108659 | R28: ='CH4 per kg feed'!Q65*FCR_bonefree_incl_parents_HU -> 0.00018091299 | W28: =Energy_stables_HU/Bonefree_outof_CW_HU*(Share_heating_HU*(Share_biofuels_HU*EF_biofuel_CH4+(1-Share_biofuels_HU)*EF_oil_CH4)+(1-Share_heating_HU)*EF_el_CH4_HU) -> 0.00060565775 | X28: =(Energy_slaughter_el_HU*EF_el_CH4_HU+Energy_slaughter_oil_HU*EF_oil_CH4)/Bonefree_outof_CW_HU -> 0.001556358
A29: A01RG | B29: Pig muscle | C29: Meat and meat products | D29: Hungary | E29: HU | F29: CH4, biogenic | G29: =SUM(H29:T29)+SUM(W29:X29) -> 0.050732608 | S29: =(Production!F37+Production!F38+Production!F39*4/12)*EF_ent_ferm_HU -> 0.01042089 | T29: =SUM(U29:V29) -> 0.040311717 | U29: =Manure!U32 -> 0.040311717
A30: A01RG | B30: Pig muscle | C30: Meat and meat products | D30: Hungary | E30: HU | F30: N2O | G30: =SUM(H30:T30)+SUM(W30:X30) -> 0.0029919966 | H30: ='N2O per kg feed'!G65*FCR_bonefree_incl_parents_HU-Excreted_N_after_losses_HU*Manure_repl_factor_HU*(EF_min_fert_BAT_N2O*Frac_BAT_HU+EF_min_fert_AN_N2O*Frac_AN_HU) -> 0.00068052256 | I30: ='N2O per kg feed'!H65*FCR_bonefree_incl_parents_HU -> 5.6752671e-06 | J30: ='N2O per kg feed'!I65*FCR_bonefree_incl_parents_HU-Excreted_N_after_losses_HU*Manure_repl_factor_HU*EF_N2O_diff_HU -> 0.0010651254 | K30: =J30*EF_indirect_N2O_HU -> 0.00010651254 | L30: ='N2O per kg feed'!K65*FCR_bonefree_incl_parents_HU -> 5.3234561e-06 | N30: ='N2O per kg feed'!M65*FCR_bonefree_incl_parents_HU -> 8.6829175e-08 | O30: ='N2O per kg feed'!N65*FCR_bonefree_incl_parents_HU -> 8.2775736e-06 | P30: ='N2O per kg feed'!O65*FCR_bonefree_incl_parents_HU -> 0 | Q30: ='N2O per kg feed'!P65*FCR_bonefree_incl_parents_HU -> 1.1552576e-05 | R30: ='N2O per kg feed'!Q65*FCR_bonefree_incl_parents_HU -> 7.8200215e-06 | T30: =SUM(U30:V30) -> 0.0010524882 | U30: =Manure!U88*44/28 -> 0.00060005404 | V30: =NH3_per_kg_HU*17/14*Manure!R117 -> 0.00045243411 | W30: =Energy_stables_HU/Bonefree_outof_CW_HU*(Share_heating_HU*(Share_biofuels_HU*EF_biofuel_N2O+(1-Share_biofuels_HU)*EF_oil_N2O)+(1-Share_heating_HU)*EF_el_N2O_HU) -> 2.2274607e-05 | X30: =(Energy_slaughter_el_HU*EF_el_N2O_HU+Energy_slaughter_oil_HU*EF_oil_N2O)/Bonefree_outof_CW_HU -> 2.6337516e-05
A31: A01RG | B31: Pig muscle | C31: Meat and meat products | D31: Hungary | E31: HU | F31: CO2e | G31: =SUM(H31:X31) -> 4.8295218 | H31: =SUMPRODUCT(H27:H30,'Parameters, general'!$B$13:$B$16) -> 0.51241987 | I31: =SUMPRODUCT(I27:I30,'Parameters, general'!$B$13:$B$16) -> 0.16925719 | J31: =SUMPRODUCT(J27:J30,'Parameters, general'!$B$13:$B$16) -> 0.29077925 | K31: =SUMPRODUCT(K27:K30,'Parameters, general'!$B$13:$B$16) -> 0.029077925 | L31: =SUMPRODUCT(L27:L30,'Parameters, general'!$B$13:$B$16) -> 0.20121631 | M31: =SUMPRODUCT(M27:M30,'Parameters, general'!$B$13:$B$16) -> 0 | N31: =SUMPRODUCT(N27:N30,'Parameters, general'!$B$13:$B$16) -> 0.0018941353 | O31: =SUMPRODUCT(O27:O30,'Parameters, general'!$B$13:$B$16) -> 0.2416202 | ... T31: =SUMPRODUCT(T27:T30,'Parameters, general'!$B$13:$B$16) -> 1.3757456 | W31: =SUMPRODUCT(W27:W30,'Parameters, general'!$B$13:$B$16) -> 0.37143362 | X31: =SUMPRODUCT(X27:X30,'Parameters, general'!$B$13:$B$16) -> 0.80361469 | Z31: =SUM(H31:R31) -> 1.9973638 | AA31: ='CO2 per kg feed'!F65+'CH4 per kg feed'!F65*CF_GWP_CH4_fossil+'N2O per kg feed'!F65*CF_GWP_N2O -> 0.24541708
A32: A01RG | B32: Pig muscle | C32: Meat and meat products | D32: Ireland | E32: IE | F32: CO2 | G32: =SUM(H32:X32) -> 2.436667 | H32: ='CO2 per kg feed'!G77*FCR_bonefree_incl_parents_IE-Excreted_N_after_losses_IE*Manure_repl_factor_IE*(EF_min_fert_BAT_CO2*Frac_BAT_IE+EF_min_fert_AN_CO2*Frac_AN_IE) -> 0.30586025 | I32: ='CO2 per kg feed'!H77*FCR_bonefree_incl_parents_IE -> 0.14110337 | J32: ='CO2 per kg feed'!I77*FCR_bonefree_incl_parents_IE -> 0 | L32: ='CO2 per kg feed'!K77*FCR_bonefree_incl_parents_IE -> 0.16111532 | N32: ='CO2 per kg feed'!M77*FCR_bonefree_incl_parents_IE -> 0.00037380048 | O32: ='CO2 per kg feed'!N77*FCR_bonefree_incl_parents_IE -> 0.22234584 | P32: ='CO2 per kg feed'!O77*FCR_bonefree_incl_parents_IE -> 0.28758245 | Q32: ='CO2 per kg feed'!P77*FCR_bonefree_incl_parents_IE -> 0.048830488 | R32: ='CO2 per kg feed'!Q77*FCR_bonefree_incl_parents_IE -> 0.25734124 | W32: =Energy_stables_IE/Bonefree_outof_CW_IE*(Share_heating_IE*(Share_biofuels_IE*EF_biofuels_CO2+(1-Share_biofuels_IE)*EF_oil_CO2)+(1-Share_heating_IE)*EF_el_CO2_IE) -> 0.32346551 | X32: =(Energy_slaughter_el_IE*EF_el_CO2_IE+Energy_slaughter_oil_IE*EF_oil_CO2)/Bonefree_outof_CW_IE -> 0.68864869
A33: A01RG | B33: Pig muscle | C33: Meat and meat products | D33: Ireland | E33: IE | F33: CH4, fossil | G33: =SUM(H33:X33) -> 0.0025653582 | H33: ='CH4 per kg feed'!G77*FCR_bonefree_incl_parents_IE-Excreted_N_after_losses_IE*Manure_repl_factor_IE*(EF_min_fert_BAT_CH4*Frac_BAT_IE+EF_min_fert_AN_CH4*Frac_AN_IE) -> 0.00056310898 | I33: ='CH4 per kg feed'!H77*FCR_bonefree_incl_parents_IE -> 0.00051734967 | L33: ='CH4 per kg feed'!K77*FCR_bonefree_incl_parents_IE -> 7.0984951e-05 | N33: ='CH4 per kg feed'!M77*FCR_bonefree_incl_parents_IE -> 3.3249726e-06 | O33: ='CH4 per kg feed'!N77*FCR_bonefree_incl_parents_IE -> 0.00013137928 | P33: ='CH4 per kg feed'!O77*FCR_bonefree_incl_parents_IE -> 0 | Q33: ='CH4 per kg feed'!P77*FCR_bonefree_incl_parents_IE -> 0.00013866594 | R33: ='CH4 per kg feed'!Q77*FCR_bonefree_incl_parents_IE -> 0.0002323491 | W33: =Energy_stables_IE/Bonefree_outof_CW_IE*(Share_heating_IE*(Share_biofuels_IE*EF_biofuel_CH4+(1-Share_biofuels_IE)*EF_oil_CH4)+(1-Share_heating_IE)*EF_el_CH4_IE) -> 0.00027581831 | X33: =(Energy_slaughter_el_IE*EF_el_CH4_IE+Energy_slaughter_oil_IE*EF_oil_CH4)/Bonefree_outof_CW_IE -> 0.00063237701
A34: A01RG | B34: Pig muscle | C34: Meat and meat products | D34: Ireland | E34: IE | F34: CH4, biogenic | G34: =SUM(H34:T34)+SUM(W34:X34) -> 0.021317295 | S34: =(Production!G37+Production!G38+Production!G39*4/12)*EF_ent_ferm_IE -> 0.010422175 | T34: =SUM(U34:V34) -> 0.010895119 | U34: =Manure!Y32 -> 0.010895119
A35: A01RG | B35: Pig muscle | C35: Meat and meat products | D35: Ireland | E35: IE | F35: N2O | G35: =SUM(H35:T35)+SUM(W35:X35) -> 0.0045555674 | H35: ='N2O per kg feed'!G77*FCR_bonefree_incl_parents_IE-Excreted_N_after_losses_IE*Manure_repl_factor_IE*(EF_min_fert_BAT_N2O*Frac_BAT_IE+EF_min_fert_AN_N2O*Frac_AN_IE) -> 0.00065776683 | I35: ='N2O per kg feed'!H77*FCR_bonefree_incl_parents_IE -> 5.3311583e-06 | J35: ='N2O per kg feed'!I77*FCR_bonefree_incl_parents_IE-Excreted_N_after_losses_IE*Manure_repl_factor_IE*EF_N2O_diff_IE -> 0.0023711308 | K35: =J35*EF_indirect_N2O_IE -> 0.00023711308 | L35: ='N2O per kg feed'!K77*FCR_bonefree_incl_parents_IE -> 4.3006753e-06 | N35: ='N2O per kg feed'!M77*FCR_bonefree_incl_parents_IE -> 4.0901244e-08 | O35: ='N2O per kg feed'!N77*FCR_bonefree_incl_parents_IE -> 7.9254346e-06 | P35: ='N2O per kg feed'!O77*FCR_bonefree_incl_parents_IE -> 0 | Q35: ='N2O per kg feed'!P77*FCR_bonefree_incl_parents_IE -> 1.4020964e-05 | R35: ='N2O per kg feed'!Q77*FCR_bonefree_incl_parents_IE -> 9.0982905e-06 | T35: =SUM(U35:V35) -> 0.0012020545 | U35: =Manure!Y88*44/28 -> 0.00067715213 | V35: =NH3_per_kg_IE*17/14*Manure!V117 -> 0.00052490238 | W35: =Energy_stables_IE/Bonefree_outof_CW_IE*(Share_heating_IE*(Share_biofuels_IE*EF_biofuel_N2O+(1-Share_biofuels_IE)*EF_oil_N2O)+(1-Share_heating_IE)*EF_el_N2O_IE) -> 2.1694955e-05 | X35: =(Energy_slaughter_el_IE*EF_el_N2O_IE+Energy_slaughter_oil_IE*EF_oil_N2O)/Bonefree_outof_CW_IE -> 2.5089864e-05
A36: A01RG | B36: Pig muscle | C36: Meat and meat products | D36: Ireland | E36: IE | F36: CO2e | G36: =SUM(H36:X36) -> 4.3323515 | H36: =SUMPRODUCT(H32:H35,'Parameters, general'!$B$13:$B$16) -> 0.50221124 | I36: =SUMPRODUCT(I32:I35,'Parameters, general'!$B$13:$B$16) -> 0.15797579 | J36: =SUMPRODUCT(J32:J35,'Parameters, general'!$B$13:$B$16) -> 0.64731871 | K36: =SUMPRODUCT(K32:K35,'Parameters, general'!$B$13:$B$16) -> 0.064731871 | L36: =SUMPRODUCT(L32:L35,'Parameters, general'!$B$13:$B$16) -> 0.16440476 | M36: =SUMPRODUCT(M32:M35,'Parameters, general'!$B$13:$B$16) -> 0 | N36: =SUMPRODUCT(N32:N35,'Parameters, general'!$B$13:$B$16) -> 0.0004840507 | O36: =SUMPRODUCT(O32:O35,'Parameters, general'!$B$13:$B$16) -> 0.22842459 | ... T36: =SUMPRODUCT(T32:T35,'Parameters, general'!$B$13:$B$16) -> 0.62232911 | W36: =SUMPRODUCT(W32:W35,'Parameters, general'!$B$13:$B$16) -> 0.33760762 | X36: =SUMPRODUCT(X32:X35,'Parameters, general'!$B$13:$B$16) -> 0.71434306 | Z36: =SUM(H36:R36) -> 2.376673 | AA36: ='CO2 per kg feed'!F77+'CH4 per kg feed'!F77*CF_GWP_CH4_fossil+'N2O per kg feed'!F77*CF_GWP_N2O -> 0.25094543
A37: A01RG | B37: Pig muscle | C37: Meat and meat products | D37: Italy | E37: IT | F37: CO2 | G37: =SUM(H37:X37) -> 2.3937768 | H37: ='CO2 per kg feed'!G89*FCR_bonefree_incl_parents_IT-Excreted_N_after_losses_IT*Manure_repl_factor_IT*(EF_min_fert_BAT_CO2*Frac_BAT_IT+EF_min_fert_AN_CO2*Frac_AN_IT) -> 0.27436389 | I37: ='CO2 per kg feed'!H89*FCR_bonefree_incl_parents_IT -> 0.15203452 | J37: ='CO2 per kg feed'!I89*FCR_bonefree_incl_parents_IT -> 0 | L37: ='CO2 per kg feed'!K89*FCR_bonefree_incl_parents_IT -> 0.19206923 | N37: ='CO2 per kg feed'!M89*FCR_bonefree_incl_parents_IT -> 0.028000415 | O37: ='CO2 per kg feed'!N89*FCR_bonefree_incl_parents_IT -> 0.23088524 | P37: ='CO2 per kg feed'!O89*FCR_bonefree_incl_parents_IT -> 0.30478852 | Q37: ='CO2 per kg feed'!P89*FCR_bonefree_incl_parents_IT -> 0.051156321 | R37: ='CO2 per kg feed'!Q89*FCR_bonefree_incl_parents_IT -> 0.24332307 | W37: =Energy_stables_IT/Bonefree_outof_CW_IT*(Share_heating_IT*(Share_biofuels_IT*EF_biofuels_CO2+(1-Share_biofuels_IT)*EF_oil_CO2)+(1-Share_heating_IT)*EF_el_CO2_IT) -> 0.24734849 | X37: =(Energy_slaughter_el_IT*EF_el_CO2_IT+Energy_slaughter_oil_IT*EF_oil_CO2)/Bonefree_outof_CW_IT -> 0.6698071
