Workbook

Sheet AW and CC calc
A2: Animal welfare and climate change calculations
A4: Animal welfare | U4: Antibiotics | AE4: Climate change
B5: Baseline | J5: Scenarios
B6: Ireland, cons | C6: Ireland, AW | D6: Italy, cons | E6: Italy, AW | F6: Poland, cons | G6: Poland, AW | H6: Europe, cons | I6: Europe, AW, Utopia | J6: Italy, beef->rabbit, cons | K6: Italy, beef->rabbit, AW | L6: Ireland, beef->chicken | M6: Ireland, beef->chicken | N6: Ireland, beef->mussels | O6: Ireland, beef->mussels | W6: Ireland | X6: Italy | Y6: Poland | Z6: Europe Utopia | AA6: Italy, beef->rabbit | AB6: Ireland, beef->chicken | AC6: Ireland, beef->mussels | AG6: Ireland | AH6: Italy | AI6: Poland | AJ6: Europe Utopia | AK6: Italy, beef->rabbit | AL6: Ireland, beef->chicken | AM6: Ireland, beef->mussels
A7: Aquatic Animals, Others | B7: ='Summary consumption'!F5*C55 -> 0.0038605714 | C7: =B7*'Footprints Ireland'!X5 -> 0 | D7: ='Summary consumption'!G5*C55 -> 0.0057908571 | E7: =D7*'Footprints Italy'!X5 -> 0 | F7: ='Summary consumption'!H5*C55 -> 0.0028954286 | G7: =F7*'Footprints Poland'!X5 -> 0 | H7: 0.026 | I7: =H7*'Footprints Utopia'!E5 -> 0 | J7: =D7 -> 0.0057908571 | K7: =J7*'Footprints Italy'!X5 -> 0 | L7: =B7 -> 0.0038605714 | M7: =L7*'Footprints Ireland'!X5 -> 0 | N7: =B7 -> 0.0038605714 | O7: =N7*'Footprints Ireland'!X5 -> 0 | U7: Aquatic Animals, Others | W7: =B7*'Footprints Ireland'!Y5 -> 0 | X7: =D7*'Footprints Italy'!Y5 -> 0 | Y7: =F7*'Footprints Poland'!Y5 -> 0 | Z7: =H7*'Footprints Utopia'!F5 -> 0 | AA7: =J7*'Footprints Italy'!Y5 -> 0 | AB7: =L7*'Footprints Ireland'!Y5 -> 0 | AC7: =N7*'Footprints Ireland'!Y5 -> 0 | AE7: Aquatic Animals, Others | AG7: =B7*'Footprints Ireland'!G5 -> 0 | AH7: =D7*'Footprints Italy'!G5 -> 0 | AI7: =F7*'Footprints Poland'!G5 -> 0 | AJ7: =H7*'Footprints Utopia'!D5 -> 0.0754 | AK7: =J7*'Footprints Italy'!G5 -> 0 | AL7: =L7*'Footprints Ireland'!G5 -> 0 | AM7: =N7*'Footprints Ireland'!G5 -> 0
A8: Bovine Meat | B8: ='Summary consumption'!F6 -> 20.612 | C8: =B8*'Footprints Ireland'!X6 -> 5.6770882 | D8: ='Summary consumption'!G6*C43 -> 11.56063 | E8: =D8*'Footprints Italy'!X6 -> 4.0245936 | F8: ='Summary consumption'!H6*C43 -> 0.72558 | G8: =F8*'Footprints Poland'!X6 -> 0.21471473 | H8: 14.14 | I8: =H8*'Footprints Utopia'!E6 -> 0.0052649922 | J8: =D8/2 -> 5.780315 | K8: =J8*'Footprints Italy'!X6 -> 2.0122968 | L8: =B8/2 -> 10.306 | M8: =L8*'Footprints Ireland'!X6 -> 2.8385441 | N8: =B8/2 -> 10.306 | O8: =N8*'Footprints Ireland'!X6 -> 2.8385441 | U8: Bovine Meat | W8: =B8*'Footprints Ireland'!Y6 -> 727.40401 | X8: =D8*'Footprints Italy'!Y6 -> 1038.2305 | Y8: =F8*'Footprints Poland'!Y6 -> 38.400504 | Z8: =H8*'Footprints Utopia'!F6 -> 28.816831 | AA8: =J8*'Footprints Italy'!Y6 -> 519.11524 | AB8: =L8*'Footprints Ireland'!Y6 -> 363.70201 | AC8: =N8*'Footprints Ireland'!Y6 -> 363.70201 | AE8: Bovine Meat | AG8: =B8*'Footprints Ireland'!G6 -> 663.85058 | AH8: =D8*'Footprints Italy'!G6 -> 364.42737 | AI8: =F8*'Footprints Poland'!G6 -> 22.703265 | AJ8: =H8*'Footprints Utopia'!D6 -> 41.006 | AK8: =J8*'Footprints Italy'!G6 -> 182.21368 | AL8: =L8*'Footprints Ireland'!G6 -> 331.92529 | AM8: =N8*'Footprints Ireland'!G6 -> 331.92529
A9: Butter, Ghee | B9: ='Summary consumption'!F7 -> 1.912 | C9: =B9*'Footprints Ireland'!X7 -> 0.10924779 | D9: ='Summary consumption'!G7 -> 2.464 | E9: =D9*'Footprints Italy'!X7 -> 0.17426361 | F9: ='Summary consumption'!H7 -> 4.514 | G9: =F9*'Footprints Poland'!X7 -> 0.30536402 | H9: 3.648 | I9: =H9*'Footprints Utopia'!E7 -> 0.0002439311 | J9: =D9 -> 2.464 | K9: =J9*'Footprints Italy'!X7 -> 0.17426361 | L9: =B9 -> 1.912 | M9: =L9*'Footprints Ireland'!X7 -> 0.10924779 | N9: =B9 -> 1.912 | O9: =N9*'Footprints Ireland'!X7 -> 0.10924779 | U9: Butter, Ghee | W9: =B9*'Footprints Ireland'!Y7 -> 49.509209 | X9: =D9*'Footprints Italy'!Y7 -> 145.79552 | Y9: =F9*'Footprints Poland'!Y7 -> 180.79658 | Z9: =H9*'Footprints Utopia'!F7 -> 4.205583 | AA9: =J9*'Footprints Italy'!Y7 -> 145.79552 | AB9: =L9*'Footprints Ireland'!Y7 -> 49.509209 | AC9: =N9*'Footprints Ireland'!Y7 -> 49.509209 | AE9: Butter, Ghee | AG9: =B9*'Footprints Ireland'!G7 -> 12.779021 | AH9: =D9*'Footprints Italy'!G7 -> 20.027201 | AI9: =F9*'Footprints Poland'!G7 -> 34.438395 | AJ9: =H9*'Footprints Utopia'!D7 -> 10.5792 | AK9: =J9*'Footprints Italy'!G7 -> 20.027201 | AL9: =L9*'Footprints Ireland'!G7 -> 12.779021 | AM9: =N9*'Footprints Ireland'!G7 -> 12.779021
A10: Cephalopods | B10: ='Summary consumption'!F8*C48 -> 0.1617 | C10: =B10*'Footprints Ireland'!X8 -> 0.09985474 | D10: ='Summary consumption'!G8*C48 -> 2.8371 | E10: =D10*'Footprints Italy'!X8 -> 1.7519968 | F10: ='Summary consumption'!H8*C48 -> 0.02499 | G10: =F10*'Footprints Poland'!X8 -> 0.015432096 | H10: 0.946 | I10: =H10*'Footprints Utopia'!E8 -> 0.0057210389 | J10: =D10 -> 2.8371 | K10: =J10*'Footprints Italy'!X8 -> 1.7519968 | L10: =B10 -> 0.1617 | M10: =L10*'Footprints Ireland'!X8 -> 0.09985474 | N10: =B10 -> 0.1617 | O10: =N10*'Footprints Ireland'!X8 -> 0.09985474 | U10: Cephalopods | W10: =B10*'Footprints Ireland'!Y8 -> 0 | X10: =D10*'Footprints Italy'!Y8 -> 0 | Y10: =F10*'Footprints Poland'!Y8 -> 0 | Z10: =H10*'Footprints Utopia'!F8 -> 0 | AA10: =J10*'Footprints Italy'!Y8 -> 0 | AB10: =L10*'Footprints Ireland'!Y8 -> 0 | AC10: =N10*'Footprints Ireland'!Y8 -> 0 | AE10: Cephalopods | AG10: =B10*'Footprints Ireland'!G8 -> 1.7323526 | AH10: =D10*'Footprints Italy'!G8 -> 30.394913 | AI10: =F10*'Footprints Poland'!G8 -> 0.26772721 | AJ10: =H10*'Footprints Utopia'!D8 -> 2.7434 | AK10: =J10*'Footprints Italy'!G8 -> 30.394913 | AL10: =L10*'Footprints Ireland'!G8 -> 1.7323526 | AM10: =N10*'Footprints Ireland'!G8 -> 1.7323526
A11: Cream | B11: ='Summary consumption'!F9 -> 2.318 | C11: =B11*'Footprints Ireland'!X9 -> 0.06719269 | D11: ='Summary consumption'!G9 -> 4.146 | E11: =D11*'Footprints Italy'!X9 -> 0.14875758 | F11: ='Summary consumption'!H9 -> 6.626 | G11: =F11*'Footprints Poland'!X9 -> 0.22740058 | H11: 3.652 | I11: =H11*'Footprints Utopia'!E9 -> 0.00012451303 | J11: =D11 -> 4.146 | K11: =J11*'Footprints Italy'!X9 -> 0.14875758 | L11: =B11 -> 2.318 | M11: =L11*'Footprints Ireland'!X9 -> 0.06719269 | N11: =B11 -> 2.318 | O11: =N11*'Footprints Ireland'!X9 -> 0.06719269 | U11: Cream | W11: =B11*'Footprints Ireland'!Y9 -> 30.450565 | X11: =D11*'Footprints Italy'!Y9 -> 124.45622 | Y11: =F11*'Footprints Poland'!Y9 -> 134.63684 | Z11: =H11*'Footprints Utopia'!F9 -> 2.1467124 | AA11: =J11*'Footprints Italy'!Y9 -> 124.45622 | AB11: =L11*'Footprints Ireland'!Y9 -> 30.450565 | AC11: =N11*'Footprints Ireland'!Y9 -> 30.450565 | AE11: Cream | AG11: =B11*'Footprints Ireland'!G9 -> 7.610807 | AH11: =D11*'Footprints Italy'!G9 -> 16.712944 | AI11: =F11*'Footprints Poland'!G9 -> 24.58315 | AJ11: =H11*'Footprints Utopia'!D9 -> 10.5908 | AK11: =J11*'Footprints Italy'!G9 -> 16.712944 | AL11: =L11*'Footprints Ireland'!G9 -> 7.610807 | AM11: =N11*'Footprints Ireland'!G9 -> 7.610807
A12: Crustaceans | B12: ='Summary consumption'!F10*C49 -> 0.337 | C12: =B12*'Footprints Ireland'!X10 -> 5.2784981 | D12: ='Summary consumption'!G10*C49 -> 1.136 | E12: =D12*'Footprints Italy'!X10 -> 17.793394 | F12: ='Summary consumption'!H10*C49 -> 0.119 | G12: =F12*'Footprints Poland'!X10 -> 1.8639207 | H12: 1.798 | I12: =H12*'Footprints Utopia'!E10 -> 0.19549831 | J12: =D12 -> 1.136 | K12: =J12*'Footprints Italy'!X10 -> 17.793394 | L12: =B12 -> 0.337 | M12: =L12*'Footprints Ireland'!X10 -> 5.2784981 | N12: =B12 -> 0.337 | O12: =N12*'Footprints Ireland'!X10 -> 5.2784981 | U12: Crustaceans | W12: =B12*'Footprints Ireland'!Y10 -> 0 | X12: =D12*'Footprints Italy'!Y10 -> 0 | Y12: =F12*'Footprints Poland'!Y10 -> 0 | Z12: =H12*'Footprints Utopia'!F10 -> 0 | AA12: =J12*'Footprints Italy'!Y10 -> 0 | AB12: =L12*'Footprints Ireland'!Y10 -> 0 | AC12: =N12*'Footprints Ireland'!Y10 -> 0 | AE12: Crustaceans | AG12: =B12*'Footprints Ireland'!G10 -> 5.2118808 | AH12: =D12*'Footprints Italy'!G10 -> 17.568832 | AI12: =F12*'Footprints Poland'!G10 -> 1.8403971 | AJ12: =H12*'Footprints Utopia'!D10 -> 5.2142 | AK12: =J12*'Footprints Italy'!G10 -> 17.568832 | AL12: =L12*'Footprints Ireland'!G10 -> 5.2118808 | AM12: =N12*'Footprints Ireland'!G10 -> 5.2118808
A13: Demersal Fish | B13: ='Summary consumption'!F11*C50 -> 5.038432 | C13: =B13*'Footprints Ireland'!X11 -> 81.247341 | D13: ='Summary consumption'!G11*C50 -> 4.228684 | E13: =D13*'Footprints Italy'!X11 -> 68.189733 | F13: ='Summary consumption'!H11*C50 -> 2.450924 | G13: =F13*'Footprints Poland'!X11 -> 39.522427 | H13: 7.208 | I13: =H13*'Footprints Utopia'!E11 -> 0.11261053 | J13: =D13 -> 4.228684 | K13: =J13*'Footprints Italy'!X11 -> 68.189733 | L13: =B13 -> 5.038432 | M13: =L13*'Footprints Ireland'!X11 -> 81.247341 | N13: =B13 -> 5.038432 | O13: =N13*'Footprints Ireland'!X11 -> 81.247341 | U13: Demersal Fish | W13: =B13*'Footprints Ireland'!Y11 -> 0 | X13: =D13*'Footprints Italy'!Y11 -> 0 | Y13: =F13*'Footprints Poland'!Y11 -> 0 | Z13: =H13*'Footprints Utopia'!F11 -> 23.858714 | AA13: =J13*'Footprints Italy'!Y11 -> 0 | AB13: =L13*'Footprints Ireland'!Y11 -> 0 | AC13: =N13*'Footprints Ireland'!Y11 -> 0 | AE13: Demersal Fish | AG13: =B13*'Footprints Ireland'!G11 -> 34.267931 | AH13: =D13*'Footprints Italy'!G11 -> 28.760585 | AI13: =F13*'Footprints Poland'!G11 -> 16.66949 | AJ13: =H13*'Footprints Utopia'!D11 -> 20.9032 | AK13: =J13*'Footprints Italy'!G11 -> 28.760585 | AL13: =L13*'Footprints Ireland'!G11 -> 34.267931 | AM13: =N13*'Footprints Ireland'!G11 -> 34.267931
A14: Eggs | B14: ='Summary consumption'!F12 -> 11.692 | C14: =B14*'Footprints Ireland'!X12 -> 94.217209 | D14: ='Summary consumption'!G12 -> 11.608 | E14: =D14*'Footprints Italy'!X12 -> 108.70738 | F14: ='Summary consumption'!H12 -> 8.364 | G14: =F14*'Footprints Poland'!X12 -> 78.970126 | H14: 13.814 | I14: =H14*'Footprints Utopia'!E12 -> 0.070211075 | J14: =D14 -> 11.608 | K14: =J14*'Footprints Italy'!X12 -> 108.70738 | L14: =B14 -> 11.692 | M14: =L14*'Footprints Ireland'!X12 -> 94.217209 | N14: =B14 -> 11.692 | O14: =N14*'Footprints Ireland'!X12 -> 94.217209 | U14: Eggs | W14: =B14*'Footprints Ireland'!Y12 -> 6.6744591 | X14: =D14*'Footprints Italy'!Y12 -> 20.173327 | Y14: =F14*'Footprints Poland'!Y12 -> 9.2353146 | Z14: =H14*'Footprints Utopia'!F12 -> 0.38294895 | AA14: =J14*'Footprints Italy'!Y12 -> 20.173327 | AB14: =L14*'Footprints Ireland'!Y12 -> 6.6744591 | AC14: =N14*'Footprints Ireland'!Y12 -> 6.6744591 | AE14: Eggs | AG14: =B14*'Footprints Ireland'!G12 -> 11.84787 | AH14: =D14*'Footprints Italy'!G12 -> 12.245558 | AI14: =F14*'Footprints Poland'!G12 -> 9.6963713 | AJ14: =H14*'Footprints Utopia'!D12 -> 40.0606 | AK14: =J14*'Footprints Italy'!G12 -> 12.245558 | AL14: =L14*'Footprints Ireland'!G12 -> 11.84787 | AM14: =N14*'Footprints Ireland'!G12 -> 11.84787
A15: Fats, Animals, Raw | B15: ='Summary consumption'!F13 -> 4.192 | C15: =B15*'Footprints Ireland'!X13 -> 0 | D15: ='Summary consumption'!G13 -> 1.52 | E15: =D15*'Footprints Italy'!X13 -> 0 | F15: ='Summary consumption'!H13 -> 2.08 | G15: =F15*'Footprints Poland'!X13 -> 0 | H15: 2.188 | I15: =H15*'Footprints Utopia'!E13 -> 0 | J15: =D15 -> 1.52 | K15: =J15*'Footprints Italy'!X13 -> 0 | L15: =B15 -> 4.192 | M15: =L15*'Footprints Ireland'!X13 -> 0 | N15: =B15 -> 4.192 | O15: =N15*'Footprints Ireland'!X13 -> 0 | U15: Fats, Animals, Raw | W15: =B15*'Footprints Ireland'!Y13 -> 0 | X15: =D15*'Footprints Italy'!Y13 -> 0 | Y15: =F15*'Footprints Poland'!Y13 -> 0 | Z15: =H15*'Footprints Utopia'!F13 -> 0 | AA15: =J15*'Footprints Italy'!Y13 -> 0 | AB15: =L15*'Footprints Ireland'!Y13 -> 0 | AC15: =N15*'Footprints Ireland'!Y13 -> 0 | AE15: Fats, Animals, Raw | AG15: =B15*'Footprints Ireland'!G13 -> 0 | AH15: =D15*'Footprints Italy'!G13 -> 0 | AI15: =F15*'Footprints Poland'!G13 -> 0 | AJ15: =H15*'Footprints Utopia'!D13 -> 0 | AK15: =J15*'Footprints Italy'!G13 -> 0 | AL15: =L15*'Footprints Ireland'!G13 -> 0 | AM15: =N15*'Footprints Ireland'!G13 -> 0
A16: Fish, Body Oil | B16: ='Summary consumption'!F14 -> 0 | C16: =B16*'Footprints Ireland'!X14 -> 0 | D16: ='Summary consumption'!G14 -> 0 | E16: =D16*'Footprints Italy'!X14 -> 0 | F16: ='Summary consumption'!H14 -> 0 | G16: =F16*'Footprints Poland'!X14 -> 0 | H16: 0.068 | I16: =H16*'Footprints Utopia'!E14 -> 0 | J16: =D16 -> 0 | K16: =J16*'Footprints Italy'!X14 -> 0 | L16: =B16 -> 0 | M16: =L16*'Footprints Ireland'!X14 -> 0 | N16: =B16 -> 0 | O16: =N16*'Footprints Ireland'!X14 -> 0 | U16: Fish, Body Oil | W16: =B16*'Footprints Ireland'!Y14 -> 0 | X16: =D16*'Footprints Italy'!Y14 -> 0 | Y16: =F16*'Footprints Poland'!Y14 -> 0 | Z16: =H16*'Footprints Utopia'!F14 -> 0 | AA16: =J16*'Footprints Italy'!Y14 -> 0 | AB16: =L16*'Footprints Ireland'!Y14 -> 0 | AC16: =N16*'Footprints Ireland'!Y14 -> 0 | AE16: Fish, Body Oil | AG16: =B16*'Footprints Ireland'!G14 -> 0 | AH16: =D16*'Footprints Italy'!G14 -> 0 | AI16: =F16*'Footprints Poland'!G14 -> 0 | AJ16: =H16*'Footprints Utopia'!D14 -> 0 | AK16: =J16*'Footprints Italy'!G14 -> 0 | AL16: =L16*'Footprints Ireland'!G14 -> 0 | AM16: =N16*'Footprints Ireland'!G14 -> 0
A17: Fish, Liver Oil | B17: ='Summary consumption'!F15 -> 0.032 | C17: =B17*'Footprints Ireland'!X15 -> 0 | D17: ='Summary consumption'!G15 -> 0 | E17: =D17*'Footprints Italy'!X15 -> 0 | F17: ='Summary consumption'!H15 -> 0.008 | G17: =F17*'Footprints Poland'!X15 -> 0 | H17: 0.008 | I17: =H17*'Footprints Utopia'!E15 -> 0 | J17: =D17 -> 0 | K17: =J17*'Footprints Italy'!X15 -> 0 | L17: =B17 -> 0.032 | M17: =L17*'Footprints Ireland'!X15 -> 0 | N17: =B17 -> 0.032 | O17: =N17*'Footprints Ireland'!X15 -> 0 | U17: Fish, Liver Oil | W17: =B17*'Footprints Ireland'!Y15 -> 0 | X17: =D17*'Footprints Italy'!Y15 -> 0 | Y17: =F17*'Footprints Poland'!Y15 -> 0 | Z17: =H17*'Footprints Utopia'!F15 -> 0 | AA17: =J17*'Footprints Italy'!Y15 -> 0 | AB17: =L17*'Footprints Ireland'!Y15 -> 0 | AC17: =N17*'Footprints Ireland'!Y15 -> 0 | AE17: Fish, Liver Oil | AG17: =B17*'Footprints Ireland'!G15 -> 0 | AH17: =D17*'Footprints Italy'!G15 -> 0 | AI17: =F17*'Footprints Poland'!G15 -> 0 | AJ17: =H17*'Footprints Utopia'!D15 -> 0 | AK17: =J17*'Footprints Italy'!G15 -> 0 | AL17: =L17*'Footprints Ireland'!G15 -> 0 | AM17: =N17*'Footprints Ireland'!G15 -> 0
A18: Freshwater Fish | B18: ='Summary consumption'!F16*C51 -> 1.10704 | C18: =B18*'Footprints Ireland'!X16 -> 6.544304 | D18: ='Summary consumption'!G16*C51 -> 1.40896 | E18: =D18*'Footprints Italy'!X16 -> 8.3291142 | F18: ='Summary consumption'!H16*C51 -> 0.37814 | G18: =F18*'Footprints Poland'!X16 -> 2.2353873 | H18: 4.13 | I18: =H18*'Footprints Utopia'!E16 -> 0.16651086 | J18: =D18 -> 1.40896 | K18: =J18*'Footprints Italy'!X16 -> 8.3291142 | L18: =B18 -> 1.10704 | M18: =L18*'Footprints Ireland'!X16 -> 6.544304 | N18: =B18 -> 1.10704 | O18: =N18*'Footprints Ireland'!X16 -> 6.544304 | U18: Freshwater Fish | W18: =B18*'Footprints Ireland'!Y16 -> 0 | X18: =D18*'Footprints Italy'!Y16 -> 0 | Y18: =F18*'Footprints Poland'!Y16 -> 0 | Z18: =H18*'Footprints Utopia'!F16 -> 0 | AA18: =J18*'Footprints Italy'!Y16 -> 0 | AB18: =L18*'Footprints Ireland'!Y16 -> 0 | AC18: =N18*'Footprints Ireland'!Y16 -> 0 | AE18: Freshwater Fish | AG18: =B18*'Footprints Ireland'!G16 -> 14.243324 | AH18: =D18*'Footprints Italy'!G16 -> 18.127867 | AI18: =F18*'Footprints Poland'!G16 -> 4.8651997 | AJ18: =H18*'Footprints Utopia'!D16 -> 11.977 | AK18: =J18*'Footprints Italy'!G16 -> 18.127867 | AL18: =L18*'Footprints Ireland'!G16 -> 14.243324 | AM18: =N18*'Footprints Ireland'!G16 -> 14.243324
A19: Marine Fish, Other | B19: ='Summary consumption'!F17*C52 -> 0.003912 | C19: =B19*'Footprints Ireland'!X17 -> 0.014096879 | D19: ='Summary consumption'!G17*C52 -> 0.479872 | E19: =D19*'Footprints Italy'!X17 -> 1.7292172 | F19: ='Summary consumption'!H17*C52 -> 0 | G19: =F19*'Footprints Poland'!X17 -> 0 | H19: 0.39 | I19: =H19*'Footprints Utopia'!E17 -> 0.0094342713 | J19: =D19 -> 0.479872 | K19: =J19*'Footprints Italy'!X17 -> 1.7292172 | L19: =B19 -> 0.003912 | M19: =L19*'Footprints Ireland'!X17 -> 0.014096879 | N19: =B19 -> 0.003912 | O19: =N19*'Footprints Ireland'!X17 -> 0.014096879 | U19: Marine Fish, Other | W19: =B19*'Footprints Ireland'!Y17 -> 0 | X19: =D19*'Footprints Italy'!Y17 -> 0 | Y19: =F19*'Footprints Poland'!Y17 -> 0 | Z19: =H19*'Footprints Utopia'!F17 -> 0 | AA19: =J19*'Footprints Italy'!Y17 -> 0 | AB19: =L19*'Footprints Ireland'!Y17 -> 0 | AC19: =N19*'Footprints Ireland'!Y17 -> 0 | AE19: Marine Fish, Other | AG19: =B19*'Footprints Ireland'!G17 -> 0.026725271 | AH19: =D19*'Footprints Italy'!G17 -> 3.2782999 | AI19: =F19*'Footprints Poland'!G17 -> 0 | AJ19: =H19*'Footprints Utopia'!D17 -> 1.131 | AK19: =J19*'Footprints Italy'!G17 -> 3.2782999 | AL19: =L19*'Footprints Ireland'!G17 -> 0.026725271 | AM19: =N19*'Footprints Ireland'!G17 -> 0.026725271
A20: Meat, Other | B20: ='Summary consumption'!F18*C46 -> 0.69459 | C20: =B20*'Footprints Ireland'!X18 -> 0 | D20: ='Summary consumption'!G18*C46 -> 0.93023 | E20: =D20*'Footprints Italy'!X18 -> 0 | F20: ='Summary consumption'!H18*C46 -> 0.06987 | G20: =F20*'Footprints Poland'!X18 -> 0 | H20: 1.534 | I20: =H20*'Footprints Utopia'!E18 -> 0 | J20: =D20 -> 0.93023 | K20: =J20*'Footprints Italy'!X18 -> 0 | L20: =B20 -> 0.69459 | M20: =L20*'Footprints Ireland'!X18 -> 0 | N20: =B20 -> 0.69459 | O20: =N20*'Footprints Ireland'!X18 -> 0 | U20: Meat, Other | W20: =B20*'Footprints Ireland'!Y18 -> 0 | X20: =D20*'Footprints Italy'!Y18 -> 0 | Y20: =F20*'Footprints Poland'!Y18 -> 0 | Z20: =H20*'Footprints Utopia'!F18 -> 0 | AA20: =J20*'Footprints Italy'!Y18 -> 0 | AB20: =L20*'Footprints Ireland'!Y18 -> 0 | AC20: =N20*'Footprints Ireland'!Y18 -> 0 | AE20: Meat, Other | AG20: =B20*'Footprints Ireland'!G18 -> 0 | AH20: =D20*'Footprints Italy'!G18 -> 0 | AI20: =F20*'Footprints Poland'!G18 -> 0 | AJ20: =H20*'Footprints Utopia'!D18 -> 0 | AK20: =J20*'Footprints Italy'!G18 -> 0 | AL20: =L20*'Footprints Ireland'!G18 -> 0 | AM20: =N20*'Footprints Ireland'!G18 -> 0
A21: Milk - Excluding Butter | B21: ='Summary consumption'!F19 -> 288.688 | C21: =B21*'Footprints Ireland'!X19 -> 2.88688 | D21: ='Summary consumption'!G19 -> 217.016 | E21: =D21*'Footprints Italy'!X19 -> 2.17016 | F21: ='Summary consumption'!H19 -> 174.926 | G21: =F21*'Footprints Poland'!X19 -> 1.74926 | H21: 191.998 | I21: =H21*'Footprints Utopia'!E19 -> 0.0017189802 | J21: =D21 -> 217.016 | K21: =J21*'Footprints Italy'!X19 -> 2.17016 | L21: =B21 -> 288.688 | M21: =L21*'Footprints Ireland'!X19 -> 2.88688 | N21: =B21 -> 288.688 | O21: =N21*'Footprints Ireland'!X19 -> 2.88688 | U21: Milk - Excluding Butter | W21: =B21*'Footprints Ireland'!Y19 -> 995.86573 | X21: =D21*'Footprints Italy'!Y19 -> 1710.6816 | Y21: =F21*'Footprints Poland'!Y19 -> 933.37676 | Z21: =H21*'Footprints Utopia'!F19 -> 29.636705 | AA21: =J21*'Footprints Italy'!Y19 -> 1710.6816 | AB21: =L21*'Footprints Ireland'!Y19 -> 995.86573 | AC21: =N21*'Footprints Ireland'!Y19 -> 995.86573 | AE21: Milk - Excluding Butter | AG21: =B21*'Footprints Ireland'!G19 -> 270.27745 | AH21: =D21*'Footprints Italy'!G19 -> 245.88847 | AI21: =F21*'Footprints Poland'!G19 -> 185.56146 | AJ21: =H21*'Footprints Utopia'!D19 -> 55.67942 | AK21: =J21*'Footprints Italy'!G19 -> 245.88847 | AL21: =L21*'Footprints Ireland'!G19 -> 270.27745 | AM21: =N21*'Footprints Ireland'!G19 -> 270.27745
A22: Molluscs, Other | B22: ='Summary consumption'!F20*C53 -> 0.35343 | C22: =B22*'Footprints Ireland'!X20 -> 4.8112669 | D22: ='Summary consumption'!G20*C53 -> 1.95811 | E22: =D22*'Footprints Italy'!X20 -> 26.655886 | F22: ='Summary consumption'!H20*C53 -> 0.09009 | G22: =F22*'Footprints Poland'!X20 -> 1.2264014 | H22: 1.854 | I22: =H22*'Footprints Utopia'!E20 -> 1.9415912 | J22: =D22 -> 1.95811 | K22: =J22*'Footprints Italy'!X20 -> 26.655886 | L22: =B22 -> 0.35343 | M22: =L22*'Footprints Ireland'!X20 -> 4.8112669 | N22: =B22 -> 0.35343 | O22: =N22*'Footprints Ireland'!X20 -> 4.8112669 | U22: Molluscs, Other | W22: =B22*'Footprints Ireland'!Y20 -> 0 | X22: =D22*'Footprints Italy'!Y20 -> 0 | Y22: =F22*'Footprints Poland'!Y20 -> 0 | Z22: =H22*'Footprints Utopia'!F20 -> 0 | AA22: =J22*'Footprints Italy'!Y20 -> 0 | AB22: =L22*'Footprints Ireland'!Y20 -> 0 | AC22: =N22*'Footprints Ireland'!Y20 -> 0 | AE22: Molluscs, Other | AG22: =B22*'Footprints Ireland'!G20 -> 5.2335641 | AH22: =D22*'Footprints Italy'!G20 -> 28.995542 | AI22: =F22*'Footprints Poland'!G20 -> 1.3340458 | AJ22: =H22*'Footprints Utopia'!D20 -> 5.3766 | AK22: =J22*'Footprints Italy'!G20 -> 28.995542 | AL22: =L22*'Footprints Ireland'!G20 -> 5.2335641 | AM22: =N22*'Footprints Ireland'!G20 -> 5.2335641
A23: Mutton & Goat Meat | B23: ='Summary consumption'!F21*C43 -> 2.34771 | C23: =B23*'Footprints Ireland'!X21 -> 7.825369 | D23: ='Summary consumption'!G21*C43 -> 0.58797 | E23: =D23*'Footprints Italy'!X21 -> 2.1009148 | F23: ='Summary consumption'!H21*C43 -> 0.02224 | G23: =F23*'Footprints Poland'!X21 -> 0.083172698 | H23: 1.684 | I23: =H23*'Footprints Utopia'!E21 -> 0.086112534 | J23: =D23 -> 0.58797 | K23: =J23*'Footprints Italy'!X21 -> 2.1009148 | L23: =B23 -> 2.34771 | M23: =L23*'Footprints Ireland'!X21 -> 7.825369 | N23: =B23 -> 2.34771 | O23: =N23*'Footprints Ireland'!X21 -> 7.825369 | U23: Mutton & Goat Meat | W23: =B23*'Footprints Ireland'!Y21 -> 81.483977 | X23: =D23*'Footprints Italy'!Y21 -> 53.615387 | Y23: =F23*'Footprints Poland'!Y21 -> 1.2610532 | Z23: =H23*'Footprints Utopia'!F21 -> 4.1183205 | AA23: =J23*'Footprints Italy'!Y21 -> 53.615387 | AB23: =L23*'Footprints Ireland'!Y21 -> 81.483977 | AC23: =N23*'Footprints Ireland'!Y21 -> 81.483977 | AE23: Mutton & Goat Meat | AG23: =B23*'Footprints Ireland'!G21 -> 89.33542 | AH23: =D23*'Footprints Italy'!G21 -> 21.195804 | AI23: =F23*'Footprints Poland'!G21 -> 0.84437201 | AJ23: =H23*'Footprints Utopia'!D21 -> 4.8836 | AK23: =J23*'Footprints Italy'!G21 -> 21.195804 | AL23: =L23*'Footprints Ireland'!G21 -> 89.33542 | AM23: =N23*'Footprints Ireland'!G21 -> 89.33542
A24: Offals, Edible | B24: ='Summary consumption'!F22 -> 2.642 | C24: =B24*'Footprints Ireland'!X22 -> 8.8062942 | D24: ='Summary consumption'!G22 -> 2.542 | E24: =D24*'Footprints Italy'!X22 -> 9.0829897 | F24: ='Summary consumption'!H22 -> 1.06 | G24: =F24*'Footprints Poland'!X22 -> 3.9641663 | H24: 3.286 | I24: =H24*'Footprints Utopia'!E22 -> 0.0065255123 | J24: =D24 -> 2.542 | K24: =J24*'Footprints Italy'!X22 -> 9.0829897 | L24: =B24 -> 2.642 | M24: =L24*'Footprints Ireland'!X22 -> 8.8062942 | N24: =B24 -> 2.642 | O24: =N24*'Footprints Ireland'!X22 -> 8.8062942 | U24: Offals, Edible | W24: =B24*'Footprints Ireland'!Y22 -> 91.698152 | X24: =D24*'Footprints Italy'!Y22 -> 231.79807 | Y24: =F24*'Footprints Poland'!Y22 -> 60.104156 | Z24: =H24*'Footprints Utopia'!F22 -> 16.07221 | AA24: =J24*'Footprints Italy'!Y22 -> 231.79807 | AB24: =L24*'Footprints Ireland'!Y22 -> 91.698152 | AC24: =N24*'Footprints Ireland'!Y22 -> 91.698152 | AE24: Offals, Edible | AG24: =B24*'Footprints Ireland'!G22 -> 100.53379 | AH24: =D24*'Footprints Italy'!G22 -> 91.636875 | AI24: =F24*'Footprints Poland'!G22 -> 40.244349 | AJ24: =H24*'Footprints Utopia'!D22 -> 9.5294 | AK24: =J24*'Footprints Italy'!G22 -> 91.636875 | AL24: =L24*'Footprints Ireland'!G22 -> 100.53379 | AM24: =N24*'Footprints Ireland'!G22 -> 100.53379
A25: Pelagic Fish | B25: ='Summary consumption'!F23*C54 -> 3.38104 | C25: =B25*'Footprints Ireland'!X23 -> 36.232829 | D25: ='Summary consumption'!G23*C54 -> 2.74976 | E25: =D25*'Footprints Italy'!X23 -> 29.467733 | F25: ='Summary consumption'!H23*C54 -> 2.82048 | G25: =F25*'Footprints Poland'!X23 -> 30.225602 | H25: 5.332 | I25: =H25*'Footprints Utopia'!E23 -> 0.38627848 | J25: =D25 -> 2.74976 | K25: =J25*'Footprints Italy'!X23 -> 29.467733 | L25: =B25 -> 3.38104 | M25: =L25*'Footprints Ireland'!X23 -> 36.232829 | N25: =B25 -> 3.38104 | O25: =N25*'Footprints Ireland'!X23 -> 36.232829 | U25: Pelagic Fish | W25: =B25*'Footprints Ireland'!Y23 -> 0 | X25: =D25*'Footprints Italy'!Y23 -> 0 | Y25: =F25*'Footprints Poland'!Y23 -> 0 | Z25: =H25*'Footprints Utopia'!F23 -> 0 | AA25: =J25*'Footprints Italy'!Y23 -> 0 | AB25: =L25*'Footprints Ireland'!Y23 -> 0 | AC25: =N25*'Footprints Ireland'!Y23 -> 0 | AE25: Pelagic Fish | AG25: =B25*'Footprints Ireland'!G23 -> 17.785524 | AH25: =D25*'Footprints Italy'!G23 -> 14.464757 | AI25: =F25*'Footprints Poland'!G23 -> 14.83677 | AJ25: =H25*'Footprints Utopia'!D23 -> 15.4628 | AK25: =J25*'Footprints Italy'!G23 -> 14.464757 | AL25: =L25*'Footprints Ireland'!G23 -> 17.785524 | AM25: =N25*'Footprints Ireland'!G23 -> 17.785524
A26: Pigmeat | B26: ='Summary consumption'!F24*C44 -> 17.14304 | C26: =B26*'Footprints Ireland'!X24 -> 77.772887 | D26: ='Summary consumption'!G24*C44 -> 21.8241 | E26: =D26*'Footprints Italy'!X24 -> 87.472926 | F26: ='Summary consumption'!H24*C44 -> 32.47124 | G26: =F26*'Footprints Poland'!X24 -> 145.32505 | H26: 34.834 | I26: =H26*'Footprints Utopia'!E24 -> 0.069175196 | J26: =D26 -> 21.8241 | K26: =J26*'Footprints Italy'!X24 -> 87.472926 | L26: =B26 -> 17.14304 | M26: =L26*'Footprints Ireland'!X24 -> 77.772887 | N26: =B26 -> 17.14304 | O26: =N26*'Footprints Ireland'!X24 -> 77.772887 | U26: Pigmeat | W26: =B26*'Footprints Ireland'!Y24 -> 1864.9513 | X26: =D26*'Footprints Italy'!Y24 -> 5512.3751 | Y26: =F26*'Footprints Poland'!Y24 -> 5200.0706 | Z26: =H26*'Footprints Utopia'!F24 -> 170.37717 | AA26: =J26*'Footprints Italy'!Y24 -> 5512.3751 | AB26: =L26*'Footprints Ireland'!Y24 -> 1864.9513 | AC26: =N26*'Footprints Ireland'!Y24 -> 1864.9513 | AE26: Pigmeat | AG26: =B26*'Footprints Ireland'!G24 -> 104.11141 | AH26: =D26*'Footprints Italy'!G24 -> 168.59508 | AI26: =F26*'Footprints Poland'!G24 -> 232.12157 | AJ26: =H26*'Footprints Utopia'!D24 -> 101.0186 | AK26: =J26*'Footprints Italy'!G24 -> 168.59508 | AL26: =L26*'Footprints Ireland'!G24 -> 104.11141 | AM26: =N26*'Footprints Ireland'!G24 -> 104.11141
A27: Poultry Meat | B27: ='Summary consumption'!F25*C45 -> 20.33878 | C27: =B27*'Footprints Ireland'!X25 -> 1909.0576 | D27: ='Summary consumption'!G25*C45 -> 15.30452 | E27: =D27*'Footprints Italy'!X25 -> 1447.1691 | F27: ='Summary consumption'!H25*C45 -> 24.10562 | G27: =F27*'Footprints Poland'!X25 -> 2208.7765 | H27: 25.53 | I27: =H27*'Footprints Utopia'!E25 -> 1.3054947 | J27: =D27 -> 15.30452 | K27: =J27*'Footprints Italy'!X25 -> 1447.1691 | L27: =B27+L8 -> 30.64478 | M27: =L27*'Footprints Ireland'!X25 -> 2876.4091 | N27: =B27 -> 20.33878 | O27: =N27*'Footprints Ireland'!X25 -> 1909.0576 | U27: Poultry Meat | W27: =B27*'Footprints Ireland'!Y25 -> 1069.4821 | X27: =D27*'Footprints Italy'!Y25 -> 2350.3431 | Y27: =F27*'Footprints Poland'!Y25 -> 1974.9534 | Z27: =H27*'Footprints Utopia'!F25 -> 62.435108 | AA27: =J27*'Footprints Italy'!Y25 -> 2350.3431 | AB27: =L27*'Footprints Ireland'!Y25 -> 1611.4066 | AC27: =N27*'Footprints Ireland'!Y25 -> 1069.4821 | AE27: Poultry Meat | AG27: =B27*'Footprints Ireland'!G25 -> 44.272059 | AH27: =D27*'Footprints Italy'!G25 -> 28.2975 | AI27: =F27*'Footprints Poland'!G25 -> 52.006043 | AJ27: =H27*'Footprints Utopia'!D25 -> 74.037 | AK27: =J27*'Footprints Italy'!G25 -> 28.2975 | AL27: =L27*'Footprints Ireland'!G25 -> 66.705452 | AM27: =N27*'Footprints Ireland'!G25 -> 44.272059
A28: Rabbit | I28: =H28*'Footprints Utopia'!E26 -> 0 | J28: =J8 -> 5.780315 | K28: =J28*C67 -> 399.41977 | N28: =B28 -> 0 | U28: Rabbit | Z28: =H28*'Footprints Utopia'!F26 -> 0 | AA28: =J28*3399.5 -> 19650.181 | AE28: Rabbit | AJ28: =H28*'Footprints Utopia'!D26 -> 0 | AK28: =J28*3 -> 17.340945 | AM28: =N28*'Footprints Ireland'!G26 -> 0
A29: Mussels | I29: =H29*'Footprints Utopia'!E27 -> 0 | N29: =N8 -> 10.306 | O29: =N29*55.33/10 -> 57.023098 | U29: Mussels | Z29: =H29*'Footprints Utopia'!F27 -> 0 | AE29: Mussels | AJ29: =H29*'Footprints Utopia'!D27 -> 0 | AM29: =N29*1.41 -> 14.53146
A30: Sum AW | C30: =SUM(C7:C29) -> 2240.648 | E30: =SUM(E7:E29) -> 1814.9681 | G30: =SUM(G7:G29) -> 2514.7049 | I30: =SUM(I7:I29) -> 4.362516 | U30: Sum | W30: =SUM(W7:W29) -> 4917.5196 | X30: =SUM(X7:X29) -> 11187.469 | Y30: =SUM(Y7:Y29) -> 8532.8352 | Z30: =SUM(Z7:Z29) -> 342.0503 | AE30: Sum | AG30: =SUM(AG7:AG29) -> 1383.1197 | AH30: =SUM(AH7:AH29) -> 1110.6176 | AI30: =SUM(AI7:AI29) -> 642.01261 | AJ30: =SUM(AJ7:AJ29) -> 410.26822
C31: Ireland | E31: Italy | G31: Poland | K31: Italy, beef->rabbit | M31: Ireland, beef->chicken | O31: Ireland, beef->mussels | W31: Ireland | X31: Italy | Y31: Poland | AA31: Italy, beef->rabbit | AB31: Ireland, beef->chicken | AC31: Ireland, beef->mussels | AG31: Ireland | AH31: Italy | AI31: Poland | AK31: Italy, beef->rabbit | AL31: Ireland, beef->chicken | AM31: Ireland, beef->mussels
A32: Ruminant meat | C32: =C8+C23 -> 13.502457 | E32: =E8+E23 -> 6.1255085 | G32: =G8+G23 -> 0.29788743 | K32: =K8+K23 -> 4.1132116 | M32: =M8+M23 -> 10.663913 | O32: =O8+O23 -> 10.663913 | U32: Ruminant meat | W32: =W8+W23 -> 808.88799 | X32: =X8+X23 -> 1091.8459 | Y32: =Y8+Y23 -> 39.661558 | AA32: =AA8+AA23 -> 572.73063 | AB32: =AB8+AB23 -> 445.18598 | AC32: =AC8+AC23 -> 445.18598 | AE32: Ruminant meat | AG32: =AG8+AG23 -> 753.186 | AH32: =AH8+AH23 -> 385.62317 | AI32: =AI8+AI23 -> 23.547637 | AK32: =AK8+AK23 -> 203.40949 | AL32: =AL8+AL23 -> 421.26071 | AM32: =AM8+AM23 -> 421.26071
A33: Pigmeat | C33: =C26 -> 77.772887 | E33: =E26 -> 87.472926 | G33: =G26 -> 145.32505 | K33: =K26 -> 87.472926 | M33: =M26 -> 77.772887 | O33: =O26 -> 77.772887 | U33: Pigmeat | W33: =W26 -> 1864.9513 | X33: =X26 -> 5512.3751 | Y33: =Y26 -> 5200.0706 | AA33: =AA26 -> 5512.3751 | AB33: =AB26 -> 1864.9513 | AC33: =AC26 -> 1864.9513 | AE33: Pigmeat | AG33: =AG26 -> 104.11141 | AH33: =AH26 -> 168.59508 | AI33: =AI26 -> 232.12157 | AK33: =AK26 -> 168.59508 | AL33: =AL26 -> 104.11141 | AM33: =AM26 -> 104.11141
A34: Poultry meat | C34: =C27 -> 1909.0576 | E34: =E27 -> 1447.1691 | G34: =G27 -> 2208.7765 | K34: =K27 -> 1447.1691 | M34: =M27 -> 2876.4091 | O34: =O27 -> 1909.0576 | U34: Poultry meat | W34: =W27 -> 1069.4821 | X34: =X27 -> 2350.3431 | Y34: =Y27 -> 1974.9534 | AA34: =AA27 -> 2350.3431 | AB34: =AB27 -> 1611.4066 | AC34: =AC27 -> 1069.4821 | AE34: Poultry meat | AG34: =AG27 -> 44.272059 | AH34: =AH27 -> 28.2975 | AI34: =AI27 -> 52.006043 | AK34: =AK27 -> 28.2975 | AL34: =AL27 -> 66.705452 | AM34: =AM27 -> 44.272059
A35: Egg | C35: =C14 -> 94.217209 | E35: =E14 -> 108.70738 | G35: =G14 -> 78.970126 | K35: =K14 -> 108.70738 | M35: =M14 -> 94.217209 | O35: =O14 -> 94.217209 | U35: Egg | W35: =W14 -> 6.6744591 | X35: =X14 -> 20.173327 | Y35: =Y14 -> 9.2353146 | AA35: =AA14 -> 20.173327 | AB35: =AB14 -> 6.6744591 | AC35: =AC14 -> 6.6744591 | AE35: Egg | AG35: =AG14 -> 11.84787 | AH35: =AH14 -> 12.245558 | AI35: =AI14 -> 9.6963713 | AK35: =AK14 -> 12.245558 | AL35: =AL14 -> 11.84787 | AM35: =AM14 -> 11.84787
A36: Dairy | C36: =C11+C21+C9 -> 3.0633205 | E36: =E11+E21+E9 -> 2.4931812 | G36: =G11+G21+G9 -> 2.2820246 | K36: =K11+K21+K9 -> 2.4931812 | M36: =M11+M21+M9 -> 3.0633205 | O36: =O11+O21+O9 -> 3.0633205 | U36: Dairy | W36: =W11+W21+W9 -> 1075.8255 | X36: =X11+X21+X9 -> 1980.9333 | Y36: =Y11+Y21+Y9 -> 1248.8102 | AA36: =AA11+AA21+AA9 -> 1980.9333 | AB36: =AB11+AB21+AB9 -> 1075.8255 | AC36: =AC11+AC21+AC9 -> 1075.8255 | AE36: Dairy | AG36: =AG11+AG21+AG9 -> 290.66728 | AH36: =AH11+AH21+AH9 -> 282.62862 | AI36: =AI11+AI21+AI9 -> 244.583 | AK36: =AK11+AK21+AK9 -> 282.62862 | AL36: =AL11+AL21+AL9 -> 290.66728 | AM36: =AM11+AM21+AM9 -> 290.66728
A37: Blue food | C37: =C10+C12+C13+C18+C25 -> 129.40283 | E37: =E10+E12+E13+E18+E25 -> 125.53197 | G37: =G10+G12+G13+G18+G25 -> 73.862769 | K37: =K10+K12+K13+K18+K25 -> 125.53197 | M37: =M10+M12+M13+M18+M25 -> 129.40283 | O37: =O10+O12+O13+O18+O25 -> 129.40283 | U37: Blue food | W37: =W10+W12+W13+W18+W25 -> 0 | X37: =X10+X12+X13+X18+X25 -> 0 | Y37: =Y10+Y12+Y13+Y18+Y25 -> 0 | AA37: =AA10+AA12+AA13+AA18+AA25 -> 0 | AB37: =AB10+AB12+AB13+AB18+AB25 -> 0 | AC37: =AC10+AC12+AC13+AC18+AC25 -> 0 | AE37: Blue food | AG37: =AG10+AG12+AG13+AG18+AG25 -> 73.241012 | AH37: =AH10+AH12+AH13+AH18+AH25 -> 109.31695 | AI37: =AI10+AI12+AI13+AI18+AI25 -> 38.479585 | AK37: =AK10+AK12+AK13+AK18+AK25 -> 109.31695 | AL37: =AL10+AL12+AL13+AL18+AL25 -> 73.241012 | AM37: =AM10+AM12+AM13+AM18+AM25 -> 73.241012
A38: Rabbit | K38: =K28 -> 399.41977 | U38: Rabbit | AA38: =AA28 -> 19650.181 | AB38: =AB28 -> 0 | AE38: Rabbit | AK38: =AK28 -> 17.340945 | AL38: =AL28 -> 0
A39: Mussels | O39: =O29 -> 57.023098 | U39: Mussels | AC39: =AC29 -> 0 | AE39: Mussels | AM39: =AM29 -> 14.53146
A41: Conversion to bonefree meat-fish | U41: Summa | W41: =SUM(W32:W39) -> 4825.8214 | X41: =SUM(X32:X39) -> 10955.671 | Y41: =SUM(Y32:Y39) -> 8472.7311 | AA41: =SUM(AA32:AA39) -> 30086.736 | AB41: =SUM(AB32:AB39) -> 5004.0439 | AC41: =SUM(AC32:AC39) -> 4462.1194 | AE41: Summa | AG41: =SUM(AG32:AG39) -> 1277.3256 | AH41: =SUM(AH32:AH39) -> 986.70688 | AI41: =SUM(AI32:AI39) -> 600.43422 | AK41: =SUM(AK32:AK39) -> 821.83414 | AL41: =SUM(AL32:AL39) -> 967.83373 | AM41: =SUM(AM32:AM39) -> 959.9318
C42: CW->bonefree
A43: Ruminant | C43: 0.695
...

Sheet Summary consumption
A2: Summary consumption
B4: France | C4: Germany | D4: Greece | E4: Hungary | F4: Ireland | G4: Italy | H4: Polen | I4: Spain | J4: Sweden | K4: Europé | M4: We pick Ireland, Italy and Poland because they have similar total consumption but
A5: Aquatic Animals, Others | B5: 0.014 | C5: 0.012 | D5: 0.01 | E5: 0.004 | F5: 0.008 | G5: 0.012 | H5: 0.006 | I5: 0.028 | J5: 0.002 | K5: 0.026
A6: Bovine Meat | B6: 23.334 | C6: 14.622 | D6: 14.944 | E6: 5.79 | F6: 20.612 | G6: 16.634 | H6: 1.044 | I6: 12.662 | J6: 22.202 | K6: 14.14 | M6: =F4 -> Ireland | N6: =G4 -> Italy | O6: =H4 -> Polen | P6: Europe
A7: Butter, Ghee | B7: 7.948 | C7: 6.036 | D7: 1.026 | E7: 1.35 | F7: 1.912 | G7: 2.464 | H7: 4.514 | I7: 1.298 | J7: 5.336 | K7: 3.648 | L7: =A27 -> Total ruminant meat | M7: =F27 -> 23.99 | N7: =G27 -> 17.48 | O7: =H27 -> 1.076 | P7: =K27 -> 15.824
A8: Cephalopods | B8: 0.892 | C8: 0.256 | D8: 3.436 | E8: 0.044 | F8: 0.22 | G8: 3.86 | H8: 0.034 | I8: 3.134 | J8: 0.072 | K8: 0.946 | L8: =A28 -> Pigmeat | M8: =F28 -> 29.056 | N8: =G28 -> 36.99 | O8: =H28 -> 55.036 | P8: =K28 -> 34.834
A9: Cream | B9: 6.348 | C9: 6.342 | D9: 2.482 | E9: 4.506 | F9: 2.318 | G9: 4.146 | H9: 6.626 | I9: 1.386 | J9: 9.598 | K9: 3.652 | L9: =A29 -> Total poultry meat | M9: =F29 -> 26.414 | N9: =G29 -> 19.876 | O9: =H29 -> 31.306 | P9: =K29 -> 25.53
A10: Crustaceans | B10: 3.608 | C10: 0.916 | D10: 1.672 | E10: 0.164 | F10: 0.674 | G10: 2.272 | H10: 0.238 | I10: 3.366 | J10: 7.418 | K10: 1.798 | L10: =A30 -> Total blue food | M10: =F30 -> 20.622 | N10: =G30 -> 29.6 | O10: =H30 -> 11.48 | P10: =K30 -> 21.684
A11: Demersal Fish | B11: 12.324 | C11: 4.012 | D11: 6.876 | E11: 1.372 | F11: 9.296 | G11: 7.802 | H11: 4.522 | I11: 12.972 | J11: 8.452 | K11: 7.208
A12: Eggs | B12: 13.258 | C12: 15.856 | D12: 9.036 | E12: 13.99 | F12: 11.692 | G12: 11.608 | H12: 8.364 | I12: 15.008 | J12: 13.664 | K12: 13.814
A13: Fats, Animals, Raw | B13: 3.008 | C13: 0.618 | D13: 1.072 | E13: 4.336 | F13: 4.192 | G13: 1.52 | H13: 2.08 | I13: 1.52 | J13: 1.862 | K13: 2.188
A14: Fish, Body Oil | B14: 0.286 | C14: 0 | J14: 0
A15: Fish, Liver Oil | B15: 0.052 | E15: 0 | F15: 0.032 | G15: 0 | H15: 0.008
A16: Freshwater Fish | B16: 4.268 | C16: 4.612 | D16: 2.326 | E16: 3.04 | F16: 2.992 | G16: 3.808 | H16: 1.022 | I16: 2.904 | J16: 8.304 | K16: 4.13
A17: Marine Fish, Other | B17: 0.122 | C17: 0.366 | D17: 0.822 | E17: 0.19 | F17: 0.012 | G17: 1.472 | H17: 0 | I17: 0.67 | J17: 0.64 | K17: 0.39
A18: Meat, Other | B18: 1.052 | C18: 1.282 | D18: 1.94 | E18: 0.298 | F18: 1.014 | G18: 1.358 | H18: 0.102 | I18: 1.556 | J18: 0.476 | K18: 1.534
A19: Milk - Excluding Butter | B19: 231.362 | C19: 195.944 | D19: 243.11 | E19: 177.054 | F19: 288.688 | G19: 217.016 | H19: 174.926 | I19: 164.73 | J19: 202.312 | K19: 191.998
A20: Molluscs, Other | B20: 5.634 | C20: 0.346 | D20: 0.806 | E20: 0.122 | F20: 0.918 | G20: 5.086 | H20: 0.234 | I20: 6.078 | J20: 0.804 | K20: 1.854
A21: Mutton & Goat Meat | B21: 2.672 | C21: 0.828 | D21: 7.456 | E21: 0.126 | F21: 3.378 | G21: 0.846 | H21: 0.032 | I21: 1.964 | J21: 1.282 | K21: 1.684
A22: Offals, Edible | B22: 5.756 | C22: 1.704 | D22: 3.116 | E22: 0.352 | F22: 2.642 | G22: 2.542 | H22: 1.06 | I22: 3.67 | J22: 4.388 | K22: 3.286
A23: Pelagic Fish | B23: 7.424 | C23: 2.534 | D23: 4.76 | E23: 1.392 | F23: 6.502 | G23: 5.288 | H23: 5.424 | I23: 11.662 | J23: 6.078 | K23: 5.332
A24: Pigmeat | B24: 33.536 | C24: 44.864 | D24: 27.42 | E24: 50.54 | F24: 29.056 | G24: 36.99 | H24: 55.036 | I24: 54.184 | J24: 29.318 | K24: 34.834
A25: Poultry Meat | B25: 26.43 | C25: 17.878 | D25: 23.502 | E25: 26.438 | F25: 26.414 | G25: 19.876 | H25: 31.306 | I25: 32.056 | J25: 16.058 | K25: 25.53 | L25: Kyckling alldeles för lågt för Sverige
A27: Total ruminant meat | B27: =B6+B21 -> 26.006 | C27: =C6+C21 -> 15.45 | D27: =D6+D21 -> 22.4 | E27: =E6+E21 -> 5.916 | F27: =F6+F21 -> 23.99 | G27: =G6+G21 -> 17.48 | H27: =H6+H21 -> 1.076 | I27: =I6+I21 -> 14.626 | ... K27: =K6+K21 -> 15.824
A28: Pigmeat | B28: =B24 -> 33.536 | C28: =C24 -> 44.864 | D28: =D24 -> 27.42 | E28: =E24 -> 50.54 | F28: =F24 -> 29.056 | G28: =G24 -> 36.99 | H28: =H24 -> 55.036 | I28: =I24 -> 54.184 | ... K28: =K24 -> 34.834
A29: Total poultry meat | B29: =B25 -> 26.43 | C29: =C25 -> 17.878 | D29: =D25 -> 23.502 | E29: =E25 -> 26.438 | F29: =F25 -> 26.414 | G29: =G25 -> 19.876 | H29: =H25 -> 31.306 | I29: =I25 -> 32.056 | ... K29: =K25 -> 25.53
A30: Total blue food | B30: =B5+B8+B10+B11+B16+B17+B20+B23 -> 34.286 | C30: =C5+C8+C10+C11+C16+C17+C20+C23 -> 13.054 | D30: =D5+D8+D10+D11+D16+D17+D20+D23 -> 20.708 | E30: =E5+E8+E10+E11+E16+E17+E20+E23 -> 6.328 | F30: =F5+F8+F10+F11+F16+F17+F20+F23 -> 20.622 | G30: =G5+G8+G10+G11+G16+G17+G20+G23 -> 29.6 | H30: =H5+H8+H10+H11+H16+H17+H20+H23 -> 11.48 | I30: =I5+I8+I10+I11+I16+I17+I20+I23 -> 40.814 | ... K30: =K5+K8+K10+K11+K16+K17+K20+K23 -> 21.684
A31: Total milk | B31: =B19 -> 231.362 | C31: =C19 -> 195.944 | D31: =D19 -> 243.11 | E31: =E19 -> 177.054 | F31: =F19 -> 288.688 | G31: =G19 -> 217.016 | H31: =H19 -> 174.926 | I31: =I19 -> 164.73 | ... K31: =K19 -> 191.998
A32: Butter | B32: =B7 -> 7.948 | C32: =C7 -> 6.036 | D32: =D7 -> 1.026 | E32: =E7 -> 1.35 | F32: =F7 -> 1.912 | G32: =G7 -> 2.464 | H32: =H7 -> 4.514 | I32: =I7 -> 1.298 | ... K32: =K7 -> 3.648
A33: Cream | B33: =B9 -> 6.348 | C33: =C9 -> 6.342 | D33: =D9 -> 2.482 | E33: =E9 -> 4.506 | F33: =F9 -> 2.318 | G33: =G9 -> 4.146 | H33: =H9 -> 6.626 | I33: =I9 -> 1.386 | ... K33: =K9 -> 3.652
A35: Total meat and seafood | B35: =SUM(B27:B30) -> 120.258 | C35: =SUM(C27:C30) -> 91.246 | D35: =SUM(D27:D30) -> 94.03 | E35: =SUM(E27:E30) -> 89.222 | F35: =SUM(F27:F30) -> 100.082 | G35: =SUM(G27:G30) -> 103.946 | H35: =SUM(H27:H30) -> 98.898 | I35: =SUM(I27:I30) -> 141.68 | ... K35: =SUM(K27:K30) -> 97.872

Sheet Footprints Ireland
A2: Footprints Ireland
A4: FAOSTAT name | B4: Code | C4: Name | D4: L1 Category | E4: L2 Category | F4: Amount (g) | G4: Carbon footprint, total (kg CO2e) | H4: Carbon dioxide, total (kg CO2) | I4: Methane, fossil, total (kg CH4) | J4: Methane, biogenic, total (kg CH4) | K4: Nitrous oxide, total (kg N2O) | L4: Carbon footprint, primary production (kg CO2e) | M4: Carbon dioxide, primary production (kg CO2) | N4: Methane, fossil, primary production (kg CH4) | O4: Methane, biogenic, primary production (kg CH4) | P4: Nitrous oxide, primary production (kg N2O) | Q4: Cropland (m2*year/kg) | R4: New N input (kg N/kg) | S4: New P input (kg P/kg) | T4: Water (m3/kg) | U4: Pesticides (g a.i/kg) | V4: Biodiversity (E/MSY/kg) | W4: Ammonia (kg NH3/kg) | X4: Animal welfare (index) | Y4: Antibiotics (index) | Z4: Mineral fertiliser production (kg CO2e) | AA4: Capital goods (kg CO2e) | AB4: Soil emissions (kg CO2e) | AC4: Energy primary production (kg CO2e) | AD4: Land use change (kg CO2e) | AE4: Enteric fermentation (kg CO2e) | AF4: Manure management (kg CO2e) | AG4: Mineral fertiliser production (kg CO2) | AH4: Capital goods (kg CO2) | AI4: Energy primary production (kg CO2) | AJ4: Land use change (kg CO2) | AK4: Mineral fertiliser production (kg CH4, fossil) | AL4: Capital goods (kg CH4, fossil) | AM4: Energy primary production (kg CH4, fossil) | AN4: Soil emissions (kg CH4, biogenic) | AO4: Enteric fermentation (kg CH4, biogenic) | AP4: Manure management (kg CH4, biogenic) | AQ4: Mineral fertiliser production (kg N2O) | AR4: Capital goods (kg N2O) | AS4: Soil emissions (kg N2O) | AT4: Energy primary production (kg N2O) | AU4: Manure management (kg N2O) | AV4: Processing (kg CO2e) | AW4: Processing (kg CO2) | AX4: Processing (kg CH4, fossil) | AY4: Processing (kg N2O) | AZ4: Packaging (kg CO2e) | BA4: Packaging (kg CO2) | BB4: Packaging (kg CH4, fossil) | BC4: Packaging (kg CH4, biogenic) | BD4: Packaging (kg N2O) | BE4: Transports (kg CO2e) | BF4: Transports (kg CO2) | BG4: Transports (kg CH4, fossil) | BH4: Transports (kg N2O) | BI4: Processes | BJ4: Packaging | BK4: RPCs with missing data
A5: Aquatic Animals, Others
A6: Bovine Meat | B6: =A30 -> A.06.01.001 | C6: =B30 -> Beef meat (Bos spp.) | D6: =C30 -> Meat and meat products (including edible offal) | E6: =D30 -> Livestock meat | F6: =E30 -> 1000 | G6: =F30 -> 32.206995 | H6: =G30 -> 4.410635 | I6: =H30 -> 0.017237923 | ... BI6: =BH30 -> 0
A7: Butter, Ghee | B7: =A43 -> A.11.01.001 | C7: =B43 -> Butter | D7: =C43 -> Animal and vegetable fats and oils | E7: =D43 -> Animal fat | F7: =E43 -> 1000 | G7: =F43 -> 6.6835883 | H7: =G43 -> 1.6048179 | I7: =H43 -> 0.0032420391 | ... BI7: =BH43 -> F28.A07MH$F28.A0EKQ | BJ7: P8
A8: Cephalopods | B8: =A38 -> A.07.05.002 | C8: =B38 -> Octopus (Octopus vulgaris) | D8: =C38 -> Fish and other seafood (including amphibians, reptiles, snails and insects) | E8: =D38 -> Water molluscs | F8: =E38 -> 1000 | G8: =F38 -> 10.713374 | H8: =G38 -> 10.684911 | I8: =H38 -> 0.00075647881 | ... BI8: =BH38 -> 0
A9: Cream | B9: =A41 -> A.08.05.001.004 | C9: =B41 -> Cream 40 % fat | D9: =C41 -> Milk and dairy products | E9: =D41 -> Cream and cream products | F9: =E41 -> 1000 | G9: =F41 -> 3.2833507 | H9: =G41 -> 0.70438017 | I9: =H41 -> 0.0017307003 | ... BI9: =BH41 -> F28.A0EKQ | BJ9: P8
A10: Crustaceans | B10: =A37 -> A.07.04.001 | C10: =B37 -> Crab (Cancer spp.) | D10: =C37 -> Fish and other seafood (including amphibians, reptiles, snails and insects) | E10: =D37 -> Crustaceans | F10: =E37 -> 1000 | G10: =F37 -> 15.465522 | H10: =G37 -> 15.437059 | I10: =H37 -> 0.00075647881 | ... BI10: =BH37 -> 0
A11: Demersal Fish | B11: =A44 -> I.07.01.006.001 | C11: =B44 -> Salmon (Salmo salar) | D11: =C44 -> Fish and other seafood (including amphibians, reptiles, snails and insects) | E11: =D44 -> Fish meat | F11: =E44 -> 1000 | G11: =F44 -> 6.8013086 | H11: =G44 -> 4.1060372 | I11: =H44 -> 0.0015624228 | ... BI11: =BH44 -> 0
A12: Eggs | B12: =A42 -> A.09.01.001 | C12: =B42 -> Whole egg, chicken | D12: =C42 -> Eggs and egg products | E12: =D42 -> Eggs, fresh | F12: =E42 -> 1000 | G12: =F42 -> 1.0133314 | H12: =G42 -> 0.5406539 | I12: =H42 -> 0.00083036359 | ... BI12: =BH42 -> 0
A13: Fats, Animals, Raw
A14: Fish, Body Oil
A15: Fish, Liver Oil
A16: Freshwater Fish | B16: =A36 -> A.07.01.010 | C16: =B36 -> Perch (Perca) | D16: =C36 -> Fish and other seafood (including amphibians, reptiles, snails and insects) | E16: =D36 -> Fish meat | F16: =E36 -> 1000 | G16: =F36 -> 12.866133 | H16: =G36 -> 12.83403 | I16: =H36 -> 0.00091150614 | ... BI16: =BH36 -> 0
A17: Marine Fish, Other | B17: =A45 -> I.07.01.017.001 | C17: =B45 -> Cod (Gadus morhua) | D17: =C45 -> Fish and other seafood (including amphibians, reptiles, snails and insects) | E17: =D45 -> Fish meat | F17: =E45 -> 1000 | G17: =F45 -> 6.8316131 | H17: =G45 -> 6.7995096 | I17: =H45 -> 0.00091150614 | ... BI17: =BH45 -> 0
A18: Meat, Other
A19: Milk - Excluding Butter | B19: =A40 -> A.08.01.001.003 | C19: =B40 -> Cow milk, 1 - 2.9% fat (semi-skimmed milk) | D19: =C40 -> Milk and dairy products | E19: =D40 -> Liquid milk | F19: =E40 -> 1000 | G19: =F40 -> 0.93622683 | H19: =G40 -> 0.24907387 | I19: =H40 -> 0.00071973274 | ... W19: =V40 -> 0.00044995703 | X19: 0.01 | Y19: =X40 -> 3.4496263 | Z19: =Y40 -> 0.043307417 | AA19: =Z40 -> 0.025700729 | AB19: =AA40 -> 0.091697788 | AC19: =AB40 -> 0.10171305 | AD19: =AC40 -> 0.0058640772 | AE19: =AD40 -> 0.44921423 | AF19: =AE40 -> 0.10163688 | ... BI19: =BH40 -> F28.A0EKQ
A20: Molluscs, Other | B20: =A39 -> A.07.06.004 | C20: =B39 -> Snail (Helix sp.) | D20: =C39 -> Fish and other seafood (including amphibians, reptiles, snails and insects) | E20: =D39 -> Amphibians, reptiles, snails, insects | F20: =E39 -> 1000 | G20: =F39 -> 14.807923 | H20: =G39 -> 14.755509 | I20: =H39 -> 0.0015985799 | ... BI20: =BH39 -> 0
A21: Mutton & Goat Meat | B21: =A32 -> A.06.01.004 | C21: =B32 -> Mutton / lamb meat (Ovis aries) | D21: =C32 -> Meat and meat products (including edible offal) | E21: =D32 -> Livestock meat | F21: =E32 -> 1000 | G21: =F32 -> 38.052153 | H21: =G32 -> 10.458713 | I21: =H32 -> 0.014943693 | ... BI21: =BH32 -> 0
A22: Offals, Edible | B22: =A32 -> A.06.01.004 | C22: =B32 -> Mutton / lamb meat (Ovis aries) | D22: =C32 -> Meat and meat products (including edible offal) | E22: =D32 -> Livestock meat | F22: =E32 -> 1000 | G22: =F32 -> 38.052153 | H22: =G32 -> 10.458713 | I22: =H32 -> 0.014943693 | ... BI22: =BH32 -> 0
A23: Pelagic Fish | B23: =A35 -> A.07.01.001 | C23: =B35 -> Herring (Clupea) | D23: =C35 -> Fish and other seafood (including amphibians, reptiles, snails and insects) | E23: =D35 -> Fish meat | F23: =E35 -> 1000 | G23: =F35 -> 5.2603706 | H23: =G35 -> 5.228267 | I23: =H35 -> 0.00091150614 | ... BI23: =BH35 -> 0
A24: Pigmeat | B24: =A31 -> A.06.01.003 | C24: =B31 -> Pork / piglet meat (Sus scrofa) | D24: =C31 -> Meat and meat products (including edible offal) | E24: =D31 -> Livestock meat | F24: =E31 -> 1000 | G24: =F31 -> 6.0731006 | H24: =G31 -> 3.1971474 | I24: =H31 -> 0.004842494 | ... BI24: =BH31 -> 0
A25: Poultry Meat | B25: =A33 -> A.06.02.001 | C25: =B33 -> Chicken meat (Gallus domesticus) | D25: =C33 -> Meat and meat products (including edible offal) | E25: =D33 -> Poultry | F25: =E33 -> 1000 | G25: =F33 -> 2.1767313 | H25: =G33 -> 1.4314112 | I25: =H33 -> 0.0028260232 | ... BI25: =BH33 -> 0
A27: Footprint data extract generated with R-script (Extract_Data_To_AW_Paper.r), in folder WP3/R-scripts
A29: Code | B29: Name | C29: L1 Category | D29: L2 Category | E29: Amount (g) | F29: Carbon footprint, total (kg CO2e) | G29: Carbon dioxide, total (kg CO2) | H29: Methane, fossil, total (kg CH4) | I29: Methane, biogenic, total (kg CH4) | J29: Nitrous oxide, total (kg N2O) | K29: Carbon footprint, primary production (kg CO2e) | L29: Carbon dioxide, primary production (kg CO2) | M29: Methane, fossil, primary production (kg CH4) | N29: Methane, biogenic, primary production (kg CH4) | O29: Nitrous oxide, primary production (kg N2O) | P29: Cropland (m2*year/kg) | Q29: New N input (kg N/kg) | R29: New P input (kg P/kg) | S29: Water (m3/kg) | T29: Pesticides (g a.i/kg) | U29: Biodiversity (E/MSY/kg) | V29: Ammonia (kg NH3/kg) | W29: Animal welfare (index) | X29: Antibiotics (index) | Y29: Mineral fertiliser production (kg CO2e) | Z29: Capital goods (kg CO2e) | AA29: Soil emissions (kg CO2e) | AB29: Energy primary production (kg CO2e) | AC29: Land use change (kg CO2e) | AD29: Enteric fermentation (kg CO2e) | AE29: Manure management (kg CO2e) | AF29: Mineral fertiliser production (kg CO2) | AG29: Capital goods (kg CO2) | AH29: Energy primary production (kg CO2) | AI29: Land use change (kg CO2) | AJ29: Mineral fertiliser production (kg CH4, fossil) | AK29: Capital goods (kg CH4, fossil) | AL29: Energy primary production (kg CH4, fossil) | AM29: Soil emissions (kg CH4, biogenic) | AN29: Enteric fermentation (kg CH4, biogenic) | AO29: Manure management (kg CH4, biogenic) | AP29: Mineral fertiliser production (kg N2O) | AQ29: Capital goods (kg N2O) | AR29: Soil emissions (kg N2O) | AS29: Energy primary production (kg N2O) | AT29: Manure management (kg N2O) | AU29: Processing (kg CO2e) | AV29: Processing (kg CO2) | AW29: Processing (kg CH4, fossil) | AX29: Processing (kg N2O) | AY29: Packaging (kg CO2e) | AZ29: Packaging (kg CO2) | BA29: Packaging (kg CH4, fossil) | BB29: Packaging (kg CH4, biogenic) | BC29: Packaging (kg N2O) | BD29: Transports (kg CO2e) | BE29: Transports (kg CO2) | BF29: Transports (kg CH4, fossil) | BG29: Transports (kg N2O) | BH29: Processes | BI29: Packaging | BJ29: RPCs with missing data
A30: A.06.01.001 | B30: Beef meat (Bos spp.) | C30: Meat and meat products (including edible offal) | D30: Livestock meat | E30: 1000 | F30: 32.206995 | G30: 4.410635 | H30: 0.017237923 | I30: 0.88236579 | J30: 0.37556379 | K30: 32.031496 | L30: 4.2750391 | M30: 0.015933175 | N30: 0.88233991 | O30: 0.37556261 | P30: 11.266101 | Q30: 0.61223699 | R30: 0.03296691 | S30: 0.15851119 | T30: 2.7641862 | U30: 1.7034276e-11 | V30: 0.19957244 | W30: 0.27542637 | X30: 35.290317 | Y30: 2.1156923 | Z30: 0.9809255 | AA30: 3.0250944 | AB30: 2.1686886 | AC30: 0.10917954 | AD30: 18.939896 | AE30: 4.6920193 | AF30: 1.2625351 | AG30: 0.87335265 | AH30: 2.1103794 | AI30: 0.1090651 | AJ30: 0.0023088199 | AK30: 0.0031068478 | AL30: 0.17475801 | AM30: 0 | AN30: 0.70147764 | AO30: 0.094827603 | AP30: 0.0028730931 | AQ30: 5.4903956e-05 | AR30: 0.011080932 | AS30: 0.17348979 | AT30: 0.0078083298 | AU30: 0 | AV30: 0 | AW30: 0 | AX30: 0 | AY30: 0.16715055 | AZ30: 0.12759129 | BA30: 0.0012976377 | BB30: 2.5882108e-05 | BC30: 6.9902061e-07 | BD30: 0.0083482584 | BE30: 0.0080046431 | BF30: 7.1101341e-06 | BG30: 4.8253969e-07 | BI30: P9
A31: A.06.01.003 | B31: Pork / piglet meat (Sus scrofa) | C31: Meat and meat products (including edible offal) | D31: Livestock meat | E31: 1000 | F31: 6.0731006 | G31: 3.1971474 | H31: 0.004842494 | I31: 0.04332819 | J31: 0.005720827 | K31: 5.8746021 | L31: 3.039487 | M31: 0.003518158 | N31: 0.043302308 | O31: 0.0057183578 | P31: 11.864226 | Q31: 0.16578859 | R31: 0.024553422 | S31: 0.33963843 | T31: 2.4988705 | U31: 2.5600226e-11 | V31: 0.060527168 | W31: 4.5367033 | X31: 108.78767 | Y31: 0.65441266 | Z31: 0.20064505 | AA31: 0.89977455 | AB31: 2.2152901 | AC31: 0.33922634 | AD31: 0.34869832 | AE31: 1.216555 | AF31: 0.39794344 | AG31: 0.17911858 | AH31: 2.1446261 | AI31: 0.33922634 | AJ31: 0.00072547659 | AK31: 0.00066010678 | AL31: 0.3862387 | AM31: 0 | AN31: 0.012914752 | AO31: 0.030387555 | AP31: 0.00086025647 | AQ31: 6.7959137e-06 | AR31: 0.0032958775 | AS31: 0.38464028 | AT31: 0.0014508829 | AU31: 0 | AV31: 0 | AW31: 0 | AX31: 0 | AY31: 0.16715055 | AZ31: 0.12759129 | BA31: 0.0012976377 | BB31: 2.5882108e-05 | BC31: 6.9902061e-07 | BD31: 0.031348031 | BE31: 0.030069185 | BF31: 2.6698193e-05 | BG31: 1.7701125e-06 | BI31: P9
A32: A.06.01.004 | B32: Mutton / lamb meat (Ovis aries) | C32: Meat and meat products (including edible offal) | D32: Livestock meat | E32: 1000 | F32: 38.052153 | G32: 10.458713 | H32: 0.014943693 | I32: 0.74117892 | J32: 0.026140247 | K32: 37.864804 | L32: 10.311722 | M32: 0.013628758 | N32: 0.74115303 | O32: 0.026138509 | P32: 35.751742 | Q32: 1.1330792 | R32: 0.072685633 | S32: 0.029381089 | T32: 5.3639774 | U32: 1.665869e-10 | V32: 0.097788157 | W32: 3.3331924 | X32: 34.707855 | Y32: 2.9517104 | Z32: 1.4907828 | AA32: 5.6992805 | AB32: 5.2503648 | AC32: 2.2402275 | AD32: 19.35645 | AE32: 0.87598813 | AF32: 1.7592823 | AG32: 1.3270916 | AH32: 5.1693238 | AI32: 2.2402275 | AJ32: 0.0033567523 | AK32: 0.0047311093 | AL32: 2.4231303 | AM32: 0 | AN32: 0.71690556 | AO32: 0.024247471 | AP32: 0.0040014536 | AQ32: 8.3165383e-05 | AR32: 0.020876485 | AS32: 2.4214081 | AT32: 0.0008106462 | AU32: 0 | AV32: 0 | AW32: 0 | AX32: 0 | AY32: 0.16715055 | AZ32: 0.12759129 | BA32: 0.0012976377 | BB32: 2.5882108e-05 | BC32: 6.9902061e-07 | BD32: 0.020198299 | BE32: 0.019399258 | BF32: 1.7296977e-05 | BG32: 1.0387961e-06 | BI32: P9
A33: A.06.02.001 | B33: Chicken meat (Gallus domesticus) | C33: Meat and meat products (including edible offal) | D33: Poultry | E33: 1000 | F33: 2.1767313 | G33: 1.4314112 | H33: 0.0028260232 | I33: 0.0030931211 | J33: 0.0021157155 | K33: 1.946649 | L33: 1.2433856 | M33: 0.0014744348 | N33: 0.003067239 | O33: 0.0021117575 | P33: 5.9975926 | Q33: 0.067260372 | R33: 0.011266125 | S33: 0.03756542 | T33: 1.2840998 | U33: 2.0203713e-11 | V33: 0.062300454 | W33: 93.862938 | X33: 52.583396 | Y33: 0.21985329 | Z33: 0.097897829 | AA33: 0.41822996 | AB33: 0.86810731 | AC33: 0.19087504 | AD33: 0 | AE33: 0.1516856 | AF33: 0.13494031 | AG33: 0.086771204 | AH33: 0.8422405 | AI33: 0.1907775 | AJ33: 0.00025529289 | AK33: 0.00034279307 | AL33: 0.21148642 | AM33: 0 | AN33: 0 | AO33: 0.003067239 | AP33: 0.00028316944 | AQ33: 3.3384291e-06 | AR33: 0.0015319779 | AS33: 0.21087848 | AT33: 0.00025227159 | AU33: 0 | AV33: 0 | AW33: 0 | AX33: 0 | AY33: 0.16715055 | AZ33: 0.12759129 | BA33: 0.0012976377 | BB33: 2.5882108e-05 | BC33: 6.9902061e-07 | BD33: 0.062931742 | BE33: 0.060434313 | BF33: 5.3950683e-05 | BG33: 3.258969e-06 | BI33: P9
A34: A.06.06.003 | B34: Pork liver | C34: Meat and meat products (including edible offal) | D34: Edible offal, farmed animals | E34: 1000 | F34: 6.0731006 | G34: 3.1971474 | H34: 0.004842494 | I34: 0.04332819 | J34: 0.005720827 | K34: 5.8746021 | L34: 3.039487 | M34: 0.003518158 | N34: 0.043302308 | O34: 0.0057183578 | P34: 11.864226 | Q34: 0.16578859 | R34: 0.024553422 | S34: 0.33963843 | T34: 2.4988705 | U34: 2.5600226e-11 | V34: 0.060527168 | W34: 4.5367033 | X34: 108.78767 | Y34: 0.65441266 | Z34: 0.20064505 | AA34: 0.89977455 | AB34: 2.2152901 | AC34: 0.33922634 | AD34: 0.34869832 | AE34: 1.216555 | AF34: 0.39794344 | AG34: 0.17911858 | AH34: 2.1446261 | AI34: 0.33922634 | AJ34: 0.00072547659 | AK34: 0.00066010678 | AL34: 0.3862387 | AM34: 0 | AN34: 0.012914752 | AO34: 0.030387555 | AP34: 0.00086025647 | AQ34: 6.7959137e-06 | AR34: 0.0032958775 | AS34: 0.38464028 | AT34: 0.0014508829 | AU34: 0 | AV34: 0 | AW34: 0 | AX34: 0 | AY34: 0.16715055 | AZ34: 0.12759129 | BA34: 0.0012976377 | BB34: 2.5882108e-05 | BC34: 6.9902061e-07 | BD34: 0.031348031 | BE34: 0.030069185 | BF34: 2.6698193e-05 | BG34: 1.7701125e-06 | BI34: P9
A35: A.07.01.001 | B35: Herring (Clupea) | C35: Fish and other seafood (including amphibians, reptiles, snails and insects) | D35: Fish meat | E35: 1000 | F35: 5.2603706 | G35: 5.228267 | H35: 0.00091150614 | I35: 1.8453188e-05 | J35: 1.6272774e-05 | K35: 4.8858897 | L35: 4.8858897 | M35: 0 | N35: 0 | O35: 0 | P35: 0 | Q35: 0 | R35: 0 | S35: 0 | T35: 0 | U35: 0 | V35: 0 | W35: 10.716475 | X35: 0 | Y35: 0 | Z35: 0 | AA35: 0 | AB35: 4.8858897 | AC35: 0 | AD35: 0 | AE35: 0 | AF35: 0 | AG35: 0 | AH35: 4.8858897 | AI35: 0 | AJ35: 0 | AK35: 0 | AL35: 0 | AM35: 0 | AN35: 0 | AO35: 0 | AP35: 0 | AQ35: 0 | AR35: 0 | AS35: 0 | AT35: 0 | AU35: 0 | AV35: 0 | AW35: 0 | AX35: 0 | AY35: 0.10602834 | AZ35: 0.084605512 | BA35: 0.00068186277 | BB35: 1.8453188e-05 | BC35: 2.2164258e-06 | BD35: 0.26845257 | BE35: 0.25777181 | BF35: 0.00022964337 | BG35: 1.4056349e-05 | BI35: P1
A36: A.07.01.010 | B36: Perch (Perca) | C36: Fish and other seafood (including amphibians, reptiles, snails and insects) | D36: Fish meat | E36: 1000 | F36: 12.866133 | G36: 12.83403 | H36: 0.00091150614 | I36: 1.8453188e-05 | J36: 1.6272774e-05 | K36: 12.491652 | L36: 12.491652 | M36: 0 | N36: 0 | O36: 0 | P36: 0 | Q36: 0 | R36: 0 | S36: 0 | T36: 0 | U36: 0 | V36: 0 | W36: 5.9115335 | X36: 0 | Y36: 0 | Z36: 0 | AA36: 0 | AB36: 12.491652 | AC36: 0 | AD36: 0 | AE36: 0 | AF36: 0 | AG36: 0 | AH36: 12.491652 | AI36: 0 | AJ36: 0 | AK36: 0 | AL36: 0 | AM36: 0 | AN36: 0 | AO36: 0 | AP36: 0 | AQ36: 0 | AR36: 0 | AS36: 0 | AT36: 0 | AU36: 0 | AV36: 0 | AW36: 0 | AX36: 0 | AY36: 0.10602834 | AZ36: 0.084605512 | BA36: 0.00068186277 | BB36: 1.8453188e-05 | BC36: 2.2164258e-06 | BD36: 0.26845257 | BE36: 0.25777181 | BF36: 0.00022964337 | BG36: 1.4056349e-05 | BI36: P1
A37: A.07.04.001 | B37: Crab (Cancer spp.) | C37: Fish and other seafood (including amphibians, reptiles, snails and insects) | D37: Crustaceans | E37: 1000 | F37: 15.465522 | G37: 15.437059 | H37: 0.00075647881 | I37: 1.4206898e-05 | J37: 2.0278824e-05 | K37: 15.06452 | L37: 15.06452 | M37: 0 | N37: 0 | O37: 0 | P37: 0 | Q37: 0 | R37: 0 | S37: 0 | T37: 0 | U37: 0 | V37: 0 | W37: 15.663199 | X37: 0 | Y37: 0 | Z37: 0 | AA37: 0 | AB37: 15.06452 | AC37: 0 | AD37: 0 | AE37: 0 | AF37: 0 | AG37: 0 | AH37: 15.06452 | AI37: 0 | AJ37: 0 | AK37: 0 | AL37: 0 | AM37: 0 | AN37: 0 | AO37: 0 | AP37: 0 | AQ37: 0 | AR37: 0 | AS37: 0 | AT37: 0 | AU37: 0 | AV37: 0 | AW37: 0 | AX37: 0 | AY37: 0.13254929 | AZ37: 0.11476727 | BA37: 0.00052683544 | BB37: 1.4206898e-05 | BC37: 6.2224755e-06 | BD37: 0.26845257 | BE37: 0.25777181 | BF37: 0.00022964337 | BG37: 1.4056349e-05 | BI37: P2
A38: A.07.05.002 | B38: Octopus (Octopus vulgaris) | C38: Fish and other seafood (including amphibians, reptiles, snails and insects) | D38: Water molluscs | E38: 1000 | F38: 10.713374 | G38: 10.684911 | H38: 0.00075647881 | I38: 1.4206898e-05 | J38: 2.0278824e-05 | K38: 10.312372 | L38: 10.312372 | M38: 0 | N38: 0 | O38: 0 | P38: 0 | Q38: 0 | R38: 0 | S38: 0 | T38: 0 | U38: 0 | V38: 0 | W38: 0.61753086 | X38: 0 | Y38: 0 | Z38: 0 | AA38: 0 | AB38: 10.312372 | AC38: 0 | AD38: 0 | AE38: 0 | AF38: 0 | AG38: 0 | AH38: 10.312372 | AI38: 0 | AJ38: 0 | AK38: 0 | AL38: 0 | AM38: 0 | AN38: 0 | AO38: 0 | AP38: 0 | AQ38: 0 | AR38: 0 | AS38: 0 | AT38: 0 | AU38: 0 | AV38: 0 | AW38: 0 | AX38: 0 | AY38: 0.13254929 | AZ38: 0.11476727 | BA38: 0.00052683544 | BB38: 1.4206898e-05 | BC38: 6.2224755e-06 | BD38: 0.26845257 | BE38: 0.25777181 | BF38: 0.00022964337 | BG38: 1.4056349e-05 | BI38: P2
A39: A.07.06.004 | B39: Snail (Helix sp.) | C39: Fish and other seafood (including amphibians, reptiles, snails and insects) | D39: Amphibians, reptiles, snails, insects | E39: 1000 | F39: 14.807923 | G39: 14.755509 | H39: 0.0015985799 | I39: 2.7304202e-05 | J39: 1.4793777e-05 | K39: 14.363136 | L39: 14.363136 | M39: 0 | N39: 0 | O39: 0 | P39: 0 | Q39: 0 | R39: 0 | S39: 0 | T39: 0 | U39: 0 | V39: 0 | W39: 13.613069 | X39: 0 | Y39: 0 | Z39: 0 | AA39: 0 | AB39: 14.363136 | AC39: 0 | AD39: 0 | AE39: 0 | AF39: 0 | AG39: 0 | AH39: 14.363136 | AI39: 0 | AJ39: 0 | AK39: 0 | AL39: 0 | AM39: 0 | AN39: 0 | AO39: 0 | AP39: 0 | AQ39: 0 | AR39: 0 | AS39: 0 | AT39: 0 | AU39: 0 | AV39: 0 | AW39: 0 | AX39: 0 | AY39: 0.17633464 | AZ39: 0.1346018 | BA39: 0.0013689365 | BB39: 2.7304202e-05 | BC39: 7.3742834e-07 | BD39: 0.26845257 | BE39: 0.25777181 | BF39: 0.00022964337 | BG39: 1.4056349e-05 | BI39: P9
A40: A.08.01.001.003 | B40: Cow milk, 1 - 2.9% fat (semi-skimmed milk) | C40: Milk and dairy products | D40: Liquid milk | E40: 1000 | F40: 0.93622683 | G40: 0.24907387 | H40: 0.00071973274 | I40: 0.021057291 | J40: 0.00072818658 | K40: 0.81913416 | L40: 0.14611722 | M40: 0.00034578576 | N40: 0.02101148 | O40: 0.00072175618 | P40: 0.3189013 | Q40: 0.014236271 | R40: 0.00071951754 | S40: 0.0025379295 | T40: 0.050403581 | U40: 1.0807305e-12 | V40: 0.00044995703 | W40: 0.007611999 | X40: 3.4496263 | Y40: 0.043307417 | Z40: 0.025700729 | AA40: 0.091697788 | AB40: 0.10171305 | AC40: 0.0058640772 | AD40: 0.44921423 | AE40: 0.10163688 | AF40: 0.026101648 | AG40: 0.023019625 | AH40: 0.09830121 | AI40: 0.0058640772 | AJ40: 4.8327884e-05 | AK40: 8.1466036e-05 | AL40: 0.017147989 | AM40: 0 | AN40: 0.016637564 | AO40: 0.0021869581 | AP40: 5.7749443e-05 | AQ40: 9.2826317e-07 | AR40: 0.00033588933 | AS40: 0.017062635 | AT40: 0.00015600369 | AU40: 0.011033314 | AV40: 0.010587129 | AW40: 1.1409576e-05 | AX40: 3.8893475e-07 | AY40: 0.08935693 | AZ40: 0.076347166 | BA40: 0.00034830651 | BB40: 4.5811123e-05 | BC40: 5.1037732e-06 | BD40: 0.016702422 | BE40: 0.016022351 | BF40: 1.4230894e-05 | BG40: 9.3769484e-07 | BH40: F28.A0EKQ | BI40: P8
