Workbook
Name CF_biog_CH4: #REF!
Name CF_fossil_CH4: #REF!
Name CF_HCFC: #REF!
Name CF_N2O: #REF!
Name CH4_bio_codes: #REF!
Name CH4_bio_data: #REF!
Name CH4_codes: #REF!
Name CH4_data: #REF!
Name CO2_codes: #REF!
Name CO2_data: #REF!
Name CO2e_codes: #REF!
Name CO2e_data: #REF!
Name Crop_codes: Argentina!$A$6:$A$118
Name Crop_codes: Defaults!$A$6:$A$118
Name Crop_codes: Sweden!$A$6:$A$118
Name Crop_codes: #REF!
Name Crop_data: Argentina!$A$6:$J$118
Name Crop_data: Defaults!$A$6:$G$118
Name Crop_data: Sweden!$A$6:$J$118
Name Crop_data: #REF!
Name Crop_data_codes: Argentina!$A$6:$A$118
Name Crop_data_codes: Defaults!$A$6:$A$118
Name Crop_data_codes: Sweden!$A$6:$A$118
Name Crop_data_codes: #REF!
Name Crops: #REF!
Name EF_capital_goods_CH4: #REF!
Name EF_capital_goods_CO2: #REF!
Name EF_capital_goods_N2O: #REF!
Name EF_chips_CH4: #REF!
Name EF_chips_CO2: #REF!
Name EF_chips_N2O: #REF!
Name EF_diesel_CH4: #REF!
Name EF_diesel_CO2: #REF!
Name EF_diesel_N2O: #REF!
Name EF_district_heating_CH4: #REF!
Name EF_district_heating_CO2: #REF!
Name EF_district_heating_N2O: #REF!
Name EF_electricity_CH4: #REF!
Name EF_electricity_CO2: #REF!
Name EF_electricity_N2O: #REF!
Name EF_heating_oil_CH4: #REF!
Name EF_heating_oil_CO2: #REF!
Name EF_heating_oil_N2O: #REF!
Name EF_irrigation_CH4: #REF!
Name EF_irrigation_CO2: #REF!
Name EF_irrigation_N2O: #REF!
Name EF_min_fert_AN_CH4: #REF!
Name EF_min_fert_AN_CO2: #REF!
Name EF_min_fert_AN_N2O: #REF!
Name EF_min_fert_BAT_CH4: #REF!
Name EF_min_fert_BAT_CO2: #REF!
Name EF_min_fert_BAT_N2O: #REF!
Name EF_min_fert_CH4: #REF!
Name EF_min_fert_CO2: #REF!
Name EF_N2O_soils_crop_res: #REF!
Name EF_N2O_soils_indirect: #REF!
Name EF_N2O_soils_min_fert: #REF!
Name EF_natural_gas_CH4: #REF!
Name EF_natural_gas_CO2: #REF!
Name EF_natural_gas_N2O: #REF!

Sheet README
A2: Introduction to the dataset
A4: This is a dataset that includes input data for calculating the environmental footprints.
A6: Fertilisers

Sheet Diesel
A2: Diesel use per hectare and country | D2: Ha en defaultkolumn som används om inget annat anges, problemet är för kvävet som vi vill skala mot skörden som vi inte har här
A4: Crops
A5: Crop code | B5: Crop | C5: Category | D5: Default | E5: AR | F5: AU | G5: AT | H5: BE | I5: BO | J5: BR | K5: BG
A6: =Defaults!A6 -> 01371 | B6: =Defaults!B6 -> Almonds, in shell | C6: =Defaults!C6 -> Nuts
A7: =Defaults!A7 -> 01654 | B7: =Defaults!B7 -> Anise, badian, coriander, cumin, caraway, fennel and juniper berries, raw | C7: =Defaults!C7 -> Vegetables
A8: =Defaults!A8 -> 01341 | B8: =Defaults!B8 -> Apples | C8: =Defaults!C8 -> Fruits | D8: 450
A9: =Defaults!A9 -> 01343 | B9: =Defaults!B9 -> Apricots | C9: =Defaults!C9 -> Fruits
A10: =Defaults!A10 -> 01216 | B10: =Defaults!B10 -> Artichokes | C10: =Defaults!C10 -> Vegetables
A11: =Defaults!A11 -> 01211 | B11: =Defaults!B11 -> Asparagus | C11: =Defaults!C11 -> Vegetables | D11: 140
A12: =Defaults!A12 -> 01311 | B12: =Defaults!B12 -> Avocados | C12: =Defaults!C12 -> Vegetables
A13: =Defaults!A13 -> 01312 | B13: =Defaults!B13 -> Bananas | C13: =Defaults!C13 -> Fruits
A14: =Defaults!A14 -> 0115 | B14: =Defaults!B14 -> Barley, average | C14: =Defaults!C14 -> Cereals, incl feed | D14: 69.7
A15: =Defaults!A15 -> 0115_s | B15: =Defaults!B15 -> Barley, spring | C15: =Defaults!C15 -> Cereals | D15: 70
A16: =Defaults!A16 -> 0115_w | B16: =Defaults!B16 -> Barley, winter | C16: =Defaults!C16 -> Cereals | D16: 66.7
A17: =Defaults!A17 -> 01701 | B17: =Defaults!B17 -> Beans, dry | C17: =Defaults!C17 -> Pulses | D17: 65
A18: =Defaults!A18 -> 01355.01 | B18: =Defaults!B18 -> Blueberries | C18: =Defaults!C18 -> Berries
A19: =Defaults!A19 -> 01377 | B19: =Defaults!B19 -> Brazil nuts, in shell | C19: =Defaults!C19 -> Nuts
A20: =Defaults!A20 -> 01702 | B20: =Defaults!B20 -> Broad beans and horse beans, dry | C20: =Defaults!C20 -> Pulses, incl feed | D20: 63.2
A21: =Defaults!A21 -> 01243 | B21: =Defaults!B21 -> Broad beans and horse beans, green | C21: =Defaults!C21 -> Vegetables
A22: =Defaults!A22 -> 01213_b | B22: =Defaults!B22 -> Broccoli | C22: =Defaults!C22 -> Vegetables | D22: 140
A23: =Defaults!A23 -> 01192 | B23: =Defaults!B23 -> Buckwheat | C23: =Defaults!C23 -> Seeds
A24: =Defaults!A24 -> 01212 | B24: =Defaults!B24 -> Cabbages | C24: =Defaults!C24 -> Vegetables | D24: 140
A25: =Defaults!A25 -> 01229 | B25: =Defaults!B25 -> Cantaloupes and other melons | C25: =Defaults!C25 -> Fruits
A26: =Defaults!A26 -> 01251 | B26: =Defaults!B26 -> Carrots and turnips | C26: =Defaults!C26 -> Vegetables | D26: 140
A27: =Defaults!A27 -> 01372 | B27: =Defaults!B27 -> Cashew nuts, in shell | C27: =Defaults!C27 -> Nuts
A28: =Defaults!A28 -> 01213_cf | B28: =Defaults!B28 -> Cauliflowers | C28: =Defaults!C28 -> Vegetables | D28: 140
A29: =Defaults!A29 -> 01213 | B29: =Defaults!B29 -> Cauliflowers and broccoli, average | C29: =Defaults!C29 -> Vegetables | D29: 140
A30: =Defaults!A30 -> 01199.90 | B30: =Defaults!B30 -> Cereals n.e.c. | C30: =Defaults!C30 -> Cereals
A31: =Defaults!A31 -> 01344.02 | B31: =Defaults!B31 -> Cherries | C31: =Defaults!C31 -> Berries
A32: =Defaults!A32 -> 01373 | B32: =Defaults!B32 -> Chestnuts, in shell | C32: =Defaults!C32 -> Nuts
A33: =Defaults!A33 -> 01703 | B33: =Defaults!B33 -> Chick peas, dry | C33: =Defaults!C33 -> Pulses
A34: =Defaults!A34 -> 01231 | B34: =Defaults!B34 -> Chillies and peppers, green (Capsicum spp. and Pimenta spp.), raw | C34: =Defaults!C34 -> Spices
A35: =Defaults!A35 -> 01640 | B35: =Defaults!B35 -> Cocoa beans | C35: =Defaults!C35 -> Stimulants
A36: =Defaults!A36 -> 01460 | B36: =Defaults!B36 -> Coconut, in shell | C36: =Defaults!C36 -> Nuts
A37: =Defaults!A37 -> 01610 | B37: =Defaults!B37 -> Coffee, green | C37: =Defaults!C37 -> Stimulants
A38: =Defaults!A38 -> 01232 | B38: =Defaults!B38 -> Cucumbers and gherkins, averrage | C38: =Defaults!C38 -> Vegetables | D38: 7
A39: =Defaults!A39 -> 01232_gh | B39: =Defaults!B39 -> Cucumbers and gherkins, greenhouse | C39: =Defaults!C39 -> Vegetables | D39: 0
A40: =Defaults!A40 -> 01232_of | B40: =Defaults!B40 -> Cucumbers and gherkins, openfield | C40: =Defaults!C40 -> Vegetables | D40: 140
A41: =Defaults!A41 -> 01351.01 | B41: =Defaults!B41 -> Currants | C41: =Defaults!C41 -> Berries | D41: 300
A42: =Defaults!A42 -> 01314 | B42: =Defaults!B42 -> Dates | C42: =Defaults!C42 -> Fruits
...

Sheet Argentina
A2: Inputs per hectare, Argentina
A4: Crops | F4: Nutrient inputs | I4: Energy | J4: Pesticides | K4: Nutrient inputs | N4: Energy | O4: Pesticides
A5: Crop code | B5: Crop | C5: Category | D5: Grown in country | E5: Share | F5: Min N fertiliser, kg N/ha | G5: N fixation, kg N/ha | H5: Min P fertiliser, kg P/ha | I5: Diesel use, l/ha | J5: Pesticide use, kg a.i./ha | K5: Mineral N fertiliser, kg N/ha | L5: N fixation, kg N/ha | M5: Min P fertilier, kg P/ha | N5: Diesel use, l/ha | O5: Pesticide use, kg a.i./ha
A6: =Defaults!A6 -> 01371 | B6: =Defaults!B6 -> Almonds, in shell | C6: =Defaults!C6 -> Nuts | D6: No
A7: =Defaults!A7 -> 01654 | B7: =Defaults!B7 -> Anise, badian, coriander, cumin, caraway, fennel and juniper berries, raw | C7: =Defaults!C7 -> Vegetables | D7: No
A8: =Defaults!A8 -> 01341 | B8: =Defaults!B8 -> Apples | C8: =Defaults!C8 -> Fruits | D8: Yes | I8: =Defaults!F8 -> 450 | J8: 10.56 | K8: SBA, 2004 | M8: SBA, 2004
A9: =Defaults!A9 -> 01343 | B9: =Defaults!B9 -> Apricots | C9: =Defaults!C9 -> Fruits | D9: No
A10: =Defaults!A10 -> 01216 | B10: =Defaults!B10 -> Artichokes | C10: =Defaults!C10 -> Vegetables | D10: No
A11: =Defaults!A11 -> 01211 | B11: =Defaults!B11 -> Asparagus | C11: =Defaults!C11 -> Vegetables | D11: No | K11: Jensen, 2013 | M11: Jensen, 2013
A12: =Defaults!A12 -> 01311 | B12: =Defaults!B12 -> Avocados | C12: =Defaults!C12 -> Vegetables | D12: No
A13: =Defaults!A13 -> 01312 | B13: =Defaults!B13 -> Bananas | C13: =Defaults!C13 -> Fruits | D13: No
A14: =Defaults!A14 -> 0115 | B14: =Defaults!B14 -> Barley, average | C14: =Defaults!C14 -> Cereals, incl feed | D14: No
A15: =Defaults!A15 -> 0115_s | B15: =Defaults!B15 -> Barley, spring | C15: =Defaults!C15 -> Cereals | D15: No | K15: SS, 2020 | M15: SS, 2020
A16: =Defaults!A16 -> 0115_w | B16: =Defaults!B16 -> Barley, winter | C16: =Defaults!C16 -> Cereals | D16: No | K16: SS, 2020 | M16: SS, 2020
A17: =Defaults!A17 -> 01701 | B17: =Defaults!B17 -> Beans, dry | C17: =Defaults!C17 -> Pulses | D17: Yes | I17: =Defaults!F17 -> 65 | J17: =Defaults!G17 -> 1.1 | K17: Tidåker et al., 2021 | M17: Tidåker et al, 2021
A18: =Defaults!A18 -> 01355.01 | B18: =Defaults!B18 -> Blueberries | C18: =Defaults!C18 -> Berries | D18: No
A19: =Defaults!A19 -> 01377 | B19: =Defaults!B19 -> Brazil nuts, in shell | C19: =Defaults!C19 -> Nuts | D19: No
A20: =Defaults!A20 -> 01702 | B20: =Defaults!B20 -> Broad beans and horse beans, dry | C20: =Defaults!C20 -> Pulses, incl feed | D20: No | I20: =Defaults!F20 -> 63.2 | J20: =Defaults!G20 -> 0.61 | K20: SS, 2020 | M20: SS 2020
A21: =Defaults!A21 -> 01243 | B21: =Defaults!B21 -> Broad beans and horse beans, green | C21: =Defaults!C21 -> Vegetables | D21: No
A22: =Defaults!A22 -> 01213_b | B22: =Defaults!B22 -> Broccoli | C22: =Defaults!C22 -> Vegetables | D22: No | I22: =Defaults!F22 -> 140 | J22: =Defaults!G22 -> 1.65 | K22: Marmolin & Björkholm, n.d., Björkholm, A-M., pers. comm. (2019) | M22: Marmolin & Björkholm, n.d., Björkholm, A-M., pers. comm. (2019)
A23: =Defaults!A23 -> 01192 | B23: =Defaults!B23 -> Buckwheat | C23: =Defaults!C23 -> Seeds | D23: No
A24: =Defaults!A24 -> 01212 | B24: =Defaults!B24 -> Cabbages | C24: =Defaults!C24 -> Vegetables | D24: No | I24: =Defaults!F24 -> 140 | J24: =Defaults!G24 -> 1.65 | K24: Marmolin & Björkholm, n.d., Björkholm, A-M., pers. comm. (2019) | M24: Marmolin & Björkholm, n.d., Björkholm, A-M., pers. comm. (2019)
A25: =Defaults!A25 -> 01229 | B25: =Defaults!B25 -> Cantaloupes and other melons | C25: =Defaults!C25 -> Fruits | D25: No
A26: =Defaults!A26 -> 01251 | B26: =Defaults!B26 -> Carrots and turnips | C26: =Defaults!C26 -> Vegetables | D26: No | I26: =Defaults!F26 -> 140 | J26: =Defaults!G26 -> 2.23 | K26: Marmolin & Björkholm, n.d. | M26: Marmolin & Björkholm, n.d.
A27: =Defaults!A27 -> 01372 | B27: =Defaults!B27 -> Cashew nuts, in shell | C27: =Defaults!C27 -> Nuts | D27: No
A28: =Defaults!A28 -> 01213_cf | B28: =Defaults!B28 -> Cauliflowers | C28: =Defaults!C28 -> Vegetables | D28: No | I28: =Defaults!F28 -> 140 | J28: =Defaults!G28 -> 1.65 | K28: Marmolin & Björkholm, n.d., Björkholm, A-M., pers. comm. (2019) | M28: Marmolin & Björkholm, n.d., Björkholm, A-M., pers. comm. (2019)
A29: =Defaults!A29 -> 01213 | B29: =Defaults!B29 -> Cauliflowers and broccoli, average | C29: =Defaults!C29 -> Vegetables | D29: No | I29: =Defaults!F29 -> 140 | J29: =Defaults!G29 -> 1.65
A30: =Defaults!A30 -> 01199.90 | B30: =Defaults!B30 -> Cereals n.e.c. | C30: =Defaults!C30 -> Cereals | D30: No
A31: =Defaults!A31 -> 01344.02 | B31: =Defaults!B31 -> Cherries | C31: =Defaults!C31 -> Berries | D31: No
A32: =Defaults!A32 -> 01373 | B32: =Defaults!B32 -> Chestnuts, in shell | C32: =Defaults!C32 -> Nuts | D32: No
A33: =Defaults!A33 -> 01703 | B33: =Defaults!B33 -> Chick peas, dry | C33: =Defaults!C33 -> Pulses | D33: Yes
A34: =Defaults!A34 -> 01231 | B34: =Defaults!B34 -> Chillies and peppers, green (Capsicum spp. and Pimenta spp.), raw | C34: =Defaults!C34 -> Spices | D34: No
A35: =Defaults!A35 -> 01640 | B35: =Defaults!B35 -> Cocoa beans | C35: =Defaults!C35 -> Stimulants | D35: No
A36: =Defaults!A36 -> 01460 | B36: =Defaults!B36 -> Coconut, in shell | C36: =Defaults!C36 -> Nuts | D36: No
A37: =Defaults!A37 -> 01610 | B37: =Defaults!B37 -> Coffee, green | C37: =Defaults!C37 -> Stimulants | D37: No
A38: =Defaults!A38 -> 01232 | B38: =Defaults!B38 -> Cucumbers and gherkins, averrage | C38: =Defaults!C38 -> Vegetables | D38: No | I38: =Defaults!F38 -> 7 | J38: =Defaults!G38 -> 1.65
A39: =Defaults!A39 -> 01232_gh | B39: =Defaults!B39 -> Cucumbers and gherkins, greenhouse | C39: =Defaults!C39 -> Vegetables | D39: No | I39: =Defaults!F39 -> 0 | J39: =Defaults!G39 -> 1.65 | K39: Davis et al. 2011 | M39: Davis et al. (2011)
A40: =Defaults!A40 -> 01232_of | B40: =Defaults!B40 -> Cucumbers and gherkins, openfield | C40: =Defaults!C40 -> Vegetables | D40: No | I40: =Defaults!F40 -> 140 | J40: =Defaults!G40 -> 1.65 | K40: Marmolin & Björkholm, n.d., Björkholm, A-M., pers. comm. (2019) | M40: Marmolin & Björkholm, n.d., Björkholm, A-M., pers. comm. (2019)
A41: =Defaults!A41 -> 01351.01 | B41: =Defaults!B41 -> Currants | C41: =Defaults!C41 -> Berries | D41: No | I41: =Defaults!F41 -> 300 | J41: =Defaults!G41 -> 2.25 | K41: SBA, undated. | M41: SBA, undated.
A42: =Defaults!A42 -> 01314 | B42: =Defaults!B42 -> Dates | C42: =Defaults!C42 -> Fruits | D42: No
...

Sheet Pesticides
A2: Pesticides per hectare and country
A4: Crops
A5: Crop code | B5: Crop | C5: Category | D5: Default | E5: AR | F5: AU | G5: AT | H5: BE | I5: BO | J5: BR | K5: BG
A6: =Defaults!A6 -> 01371 | B6: =Defaults!B6 -> Almonds, in shell | C6: =Defaults!C6 -> Nuts
A7: =Defaults!A7 -> 01654 | B7: =Defaults!B7 -> Anise, badian, coriander, cumin, caraway, fennel and juniper berries, raw | C7: =Defaults!C7 -> Vegetables
A8: =Defaults!A8 -> 01341 | B8: =Defaults!B8 -> Apples | C8: =Defaults!C8 -> Fruits
A9: =Defaults!A9 -> 01343 | B9: =Defaults!B9 -> Apricots | C9: =Defaults!C9 -> Fruits
A10: =Defaults!A10 -> 01216 | B10: =Defaults!B10 -> Artichokes | C10: =Defaults!C10 -> Vegetables
A11: =Defaults!A11 -> 01211 | B11: =Defaults!B11 -> Asparagus | C11: =Defaults!C11 -> Vegetables
A12: =Defaults!A12 -> 01311 | B12: =Defaults!B12 -> Avocados | C12: =Defaults!C12 -> Vegetables
A13: =Defaults!A13 -> 01312 | B13: =Defaults!B13 -> Bananas | C13: =Defaults!C13 -> Fruits
A14: =Defaults!A14 -> 0115 | B14: =Defaults!B14 -> Barley, average | C14: =Defaults!C14 -> Cereals, incl feed
A15: =Defaults!A15 -> 0115_s | B15: =Defaults!B15 -> Barley, spring | C15: =Defaults!C15 -> Cereals
A16: =Defaults!A16 -> 0115_w | B16: =Defaults!B16 -> Barley, winter | C16: =Defaults!C16 -> Cereals
A17: =Defaults!A17 -> 01701 | B17: =Defaults!B17 -> Beans, dry | C17: =Defaults!C17 -> Pulses
... A118: =Defaults!A118 -> 0111_w | B118: =Defaults!B118 -> Wheat, winter | C118: =Defaults!C118 -> Cereals

Sheet Pesticides sources
A2: Pesticides per hectare and country
A4: Crops
A5: Crop code | B5: Crop | C5: Category | D5: AR | E5: AU | F5: AT | G5: BE | H5: BO | I5: BR | J5: BG
A6: =Defaults!A6 -> 01371 | B6: =Defaults!B6 -> Almonds, in shell | C6: =Defaults!C6 -> Nuts
A7: =Defaults!A7 -> 01654 | B7: =Defaults!B7 -> Anise, badian, coriander, cumin, caraway, fennel and juniper berries, raw | C7: =Defaults!C7 -> Vegetables
A8: =Defaults!A8 -> 01341 | B8: =Defaults!B8 -> Apples | C8: =Defaults!C8 -> Fruits
A9: =Defaults!A9 -> 01343 | B9: =Defaults!B9 -> Apricots | C9: =Defaults!C9 -> Fruits
A10: =Defaults!A10 -> 01216 | B10: =Defaults!B10 -> Artichokes | C10: =Defaults!C10 -> Vegetables
A11: =Defaults!A11 -> 01211 | B11: =Defaults!B11 -> Asparagus | C11: =Defaults!C11 -> Vegetables
A12: =Defaults!A12 -> 01311 | B12: =Defaults!B12 -> Avocados | C12: =Defaults!C12 -> Vegetables
A13: =Defaults!A13 -> 01312 | B13: =Defaults!B13 -> Bananas | C13: =Defaults!C13 -> Fruits
A14: =Defaults!A14 -> 0115 | B14: =Defaults!B14 -> Barley, average | C14: =Defaults!C14 -> Cereals, incl feed
A15: =Defaults!A15 -> 0115_s | B15: =Defaults!B15 -> Barley, spring | C15: =Defaults!C15 -> Cereals
A16: =Defaults!A16 -> 0115_w | B16: =Defaults!B16 -> Barley, winter | C16: =Defaults!C16 -> Cereals
A17: =Defaults!A17 -> 01701 | B17: =Defaults!B17 -> Beans, dry | C17: =Defaults!C17 -> Pulses
... A118: =Defaults!A118 -> 0111_w | B118: =Defaults!B118 -> Wheat, winter | C118: =Defaults!C118 -> Cereals

Sheet Sweden
A2: Inputs per hectare, Sweden
A4: Crops | F4: Nutrient inputs | I4: Energy | J4: Pesticides | K4: Nutrient inputs | N4: Energy | O4: Pesticides
A5: Crop code | B5: Crop | C5: Category | D5: Grown in country | E5: Share | F5: Min N fertiliser, kg N/ha | G5: N fixation, kg N/ha | H5: Min P fertiliser, kg P/ha | I5: Diesel use, l/ha | J5: Pesticide use, kg a.i./ha | K5: Mineral N fertiliser, kg N/ha | L5: N fixation, kg N/ha | M5: Min P fertilier, kg P/ha | N5: Diesel use, l/ha | O5: Pesticide use, kg a.i./ha
A6: =Defaults!A6 -> 01371 | B6: =Defaults!B6 -> Almonds, in shell | C6: =Defaults!C6 -> Nuts | D6: =IF(ISBLANK(F6),"No","Yes") -> No
A7: =Defaults!A7 -> 01654 | B7: =Defaults!B7 -> Anise, badian, coriander, cumin, caraway, fennel and juniper berries, raw | C7: =Defaults!C7 -> Vegetables | D7: =IF(ISBLANK(F7),"No","Yes") -> No
A8: =Defaults!A8 -> 01341 | B8: =Defaults!B8 -> Apples | C8: =Defaults!C8 -> Fruits | D8: =IF(ISBLANK(F8),"No","Yes") -> Yes | F8: 41.000997 | H8: 6.0001459 | I8: =Defaults!F8 -> 450 | J8: =Defaults!G8 -> 5.97 | K8: SBA, 2004 | M8: SBA, 2004
A9: =Defaults!A9 -> 01343 | B9: =Defaults!B9 -> Apricots | C9: =Defaults!C9 -> Fruits | D9: =IF(ISBLANK(F9),"No","Yes") -> No
A10: =Defaults!A10 -> 01216 | B10: =Defaults!B10 -> Artichokes | C10: =Defaults!C10 -> Vegetables | D10: =IF(ISBLANK(F10),"No","Yes") -> No
A11: =Defaults!A11 -> 01211 | B11: =Defaults!B11 -> Asparagus | C11: =Defaults!C11 -> Vegetables | D11: =IF(ISBLANK(F11),"No","Yes") -> Yes | F11: 20 | H11: 4 | I11: =Defaults!F11 -> 140 | J11: =Defaults!G11 -> 1.65 | K11: Jensen, 2013 | M11: Jensen, 2013
A12: =Defaults!A12 -> 01311 | B12: =Defaults!B12 -> Avocados | C12: =Defaults!C12 -> Vegetables | D12: =IF(ISBLANK(F12),"No","Yes") -> No
A13: =Defaults!A13 -> 01312 | B13: =Defaults!B13 -> Bananas | C13: =Defaults!C13 -> Fruits | D13: =IF(ISBLANK(F13),"No","Yes") -> No
A14: =Defaults!A14 -> 0115 | B14: =Defaults!B14 -> Barley, average | C14: =Defaults!C14 -> Cereals, incl feed | D14: =IF(ISBLANK(F14),"No","Yes") -> Yes | F14: 94 | H14: 7 | I14: =Defaults!F14 -> 69.7 | J14: =Defaults!G14 -> 0.52
A15: =Defaults!A15 -> 0115_s | B15: =Defaults!B15 -> Barley, spring | C15: =Defaults!C15 -> Cereals | D15: =IF(ISBLANK(F15),"No","Yes") -> Yes | E15: =Defaults!D15 -> 90 | F15: 90 | H15: 7 | I15: =Defaults!F15 -> 70 | J15: =Defaults!G15 -> 0.47 | K15: SS, 2020 | M15: SS, 2020
A16: =Defaults!A16 -> 0115_w | B16: =Defaults!B16 -> Barley, winter | C16: =Defaults!C16 -> Cereals | D16: =IF(ISBLANK(F16),"No","Yes") -> Yes | E16: =Defaults!D16 -> 10 | F16: 126 | H16: 8 | I16: =Defaults!F16 -> 66.7 | J16: 1 | K16: SS, 2020 | M16: SS, 2020
A17: =Defaults!A17 -> 01701 | B17: =Defaults!B17 -> Beans, dry | C17: =Defaults!C17 -> Pulses | D17: =IF(ISBLANK(F17),"No","Yes") -> Yes | F17: 30 | G17: =Defaults!E17 -> 25 | H17: 10 | I17: =Defaults!F17 -> 65 | J17: =Defaults!G17 -> 1.1 | K17: Tidåker et al., 2021 | M17: Tidåker et al, 2021
A18: =Defaults!A18 -> 01355.01 | B18: =Defaults!B18 -> Blueberries | C18: =Defaults!C18 -> Berries | D18: =IF(ISBLANK(F18),"No","Yes") -> No
A19: =Defaults!A19 -> 01377 | B19: =Defaults!B19 -> Brazil nuts, in shell | C19: =Defaults!C19 -> Nuts | D19: =IF(ISBLANK(F19),"No","Yes") -> No
A20: =Defaults!A20 -> 01702 | B20: =Defaults!B20 -> Broad beans and horse beans, dry | C20: =Defaults!C20 -> Pulses, incl feed | D20: =IF(ISBLANK(F20),"No","Yes") -> Yes | F20: 2 | G20: =Defaults!E20 -> 24 | H20: 4 | I20: =Defaults!F20 -> 63.2 | J20: =Defaults!G20 -> 0.61 | K20: SS, 2020 | M20: SS 2020
A21: =Defaults!A21 -> 01243 | B21: =Defaults!B21 -> Broad beans and horse beans, green | C21: =Defaults!C21 -> Vegetables | D21: =IF(ISBLANK(F21),"No","Yes") -> No
A22: =Defaults!A22 -> 01213_b | B22: =Defaults!B22 -> Broccoli | C22: =Defaults!C22 -> Vegetables | D22: =IF(ISBLANK(F22),"No","Yes") -> Yes | E22: =Defaults!D22 -> 40 | F22: 150 | H22: 22.944752 | I22: =Defaults!F22 -> 140 | J22: =Defaults!G22 -> 1.65 | K22: Marmolin & Björkholm, n.d., Björkholm, A-M., pers. comm. (2019) | M22: Marmolin & Björkholm, n.d., Björkholm, A-M., pers. comm. (2019)
A23: =Defaults!A23 -> 01192 | B23: =Defaults!B23 -> Buckwheat | C23: =Defaults!C23 -> Seeds | D23: =IF(ISBLANK(F23),"No","Yes") -> No
A24: =Defaults!A24 -> 01212 | B24: =Defaults!B24 -> Cabbages | C24: =Defaults!C24 -> Vegetables | D24: =IF(ISBLANK(F24),"No","Yes") -> Yes | F24: 200.00036 | H24: 16.000029 | I24: =Defaults!F24 -> 140 | J24: =Defaults!G24 -> 1.65 | K24: Marmolin & Björkholm, n.d., Björkholm, A-M., pers. comm. (2019) | M24: Marmolin & Björkholm, n.d., Björkholm, A-M., pers. comm. (2019)
A25: =Defaults!A25 -> 01229 | B25: =Defaults!B25 -> Cantaloupes and other melons | C25: =Defaults!C25 -> Fruits | D25: =IF(ISBLANK(F25),"No","Yes") -> No
A26: =Defaults!A26 -> 01251 | B26: =Defaults!B26 -> Carrots and turnips | C26: =Defaults!C26 -> Vegetables | D26: =IF(ISBLANK(F26),"No","Yes") -> Yes | F26: 83 | H26: 29.746 | I26: =Defaults!F26 -> 140 | J26: =Defaults!G26 -> 2.23 | K26: Marmolin & Björkholm, n.d. | M26: Marmolin & Björkholm, n.d.
A27: =Defaults!A27 -> 01372 | B27: =Defaults!B27 -> Cashew nuts, in shell | C27: =Defaults!C27 -> Nuts | D27: =IF(ISBLANK(F27),"No","Yes") -> No
A28: =Defaults!A28 -> 01213_cf | B28: =Defaults!B28 -> Cauliflowers | C28: =Defaults!C28 -> Vegetables | D28: =IF(ISBLANK(F28),"No","Yes") -> Yes | E28: =Defaults!D28 -> 60 | F28: 220 | H28: 21.384 | I28: =Defaults!F28 -> 140 | J28: =Defaults!G28 -> 1.65 | K28: Marmolin & Björkholm, n.d., Björkholm, A-M., pers. comm. (2019) | M28: Marmolin & Björkholm, n.d., Björkholm, A-M., pers. comm. (2019)
A29: =Defaults!A29 -> 01213 | B29: =Defaults!B29 -> Cauliflowers and broccoli, average | C29: =Defaults!C29 -> Vegetables | D29: =IF(ISBLANK(F29),"No","Yes") -> Yes | F29: 192 | H29: 22 | I29: =Defaults!F29 -> 140 | J29: =Defaults!G29 -> 1.65
A30: =Defaults!A30 -> 01199.90 | B30: =Defaults!B30 -> Cereals n.e.c. | C30: =Defaults!C30 -> Cereals | D30: =IF(ISBLANK(F30),"No","Yes") -> No
A31: =Defaults!A31 -> 01344.02 | B31: =Defaults!B31 -> Cherries | C31: =Defaults!C31 -> Berries | D31: =IF(ISBLANK(F31),"No","Yes") -> No
A32: =Defaults!A32 -> 01373 | B32: =Defaults!B32 -> Chestnuts, in shell | C32: =Defaults!C32 -> Nuts | D32: =IF(ISBLANK(F32),"No","Yes") -> No
A33: =Defaults!A33 -> 01703 | B33: =Defaults!B33 -> Chick peas, dry | C33: =Defaults!C33 -> Pulses | D33: =IF(ISBLANK(F33),"No","Yes") -> No
A34: =Defaults!A34 -> 01231 | B34: =Defaults!B34 -> Chillies and peppers, green (Capsicum spp. and Pimenta spp.), raw | C34: =Defaults!C34 -> Spices | D34: =IF(ISBLANK(F34),"No","Yes") -> No
A35: =Defaults!A35 -> 01640 | B35: =Defaults!B35 -> Cocoa beans | C35: =Defaults!C35 -> Stimulants | D35: =IF(ISBLANK(F35),"No","Yes") -> No
A36: =Defaults!A36 -> 01460 | B36: =Defaults!B36 -> Coconut, in shell | C36: =Defaults!C36 -> Nuts | D36: =IF(ISBLANK(F36),"No","Yes") -> No
A37: =Defaults!A37 -> 01610 | B37: =Defaults!B37 -> Coffee, green | C37: =Defaults!C37 -> Stimulants | D37: =IF(ISBLANK(F37),"No","Yes") -> No
A38: =Defaults!A38 -> 01232 | B38: =Defaults!B38 -> Cucumbers and gherkins, averrage | C38: =Defaults!C38 -> Vegetables | D38: =IF(ISBLANK(F38),"No","Yes") -> Yes | E38: =Defaults!D38 -> 0 | F38: 1385.8545 | H38: 7 | I38: =Defaults!F38 -> 7 | J38: =Defaults!G38 -> 1.65
A39: =Defaults!A39 -> 01232_gh | B39: =Defaults!B39 -> Cucumbers and gherkins, greenhouse | C39: =Defaults!C39 -> Vegetables | D39: =IF(ISBLANK(F39),"No","Yes") -> Yes | E39: =Defaults!D39 -> 95 | F39: 1451.4258 | H39: 703.7216 | I39: =Defaults!F39 -> 0 | J39: =Defaults!G39 -> 1.65 | K39: Davis et al. 2011 | M39: Davis et al. (2011)
A40: =Defaults!A40 -> 01232_of | B40: =Defaults!B40 -> Cucumbers and gherkins, openfield | C40: =Defaults!C40 -> Vegetables | D40: =IF(ISBLANK(F40),"No","Yes") -> Yes | E40: =Defaults!D40 -> 5 | F40: 140 | H40: 36.184615 | I40: =Defaults!F40 -> 140 | J40: =Defaults!G40 -> 1.65 | K40: Marmolin & Björkholm, n.d., Björkholm, A-M., pers. comm. (2019) | M40: Marmolin & Björkholm, n.d., Björkholm, A-M., pers. comm. (2019)
A41: =Defaults!A41 -> 01351.01 | B41: =Defaults!B41 -> Currants | C41: =Defaults!C41 -> Berries | D41: =IF(ISBLANK(F41),"No","Yes") -> Yes | F41: 32 | H41: 20 | I41: =Defaults!F41 -> 300 | J41: =Defaults!G41 -> 2.25 | K41: SBA, undated. | M41: SBA, undated.
A42: =Defaults!A42 -> 01314 | B42: =Defaults!B42 -> Dates | C42: =Defaults!C42 -> Fruits | D42: =IF(ISBLANK(F42),"No","Yes") -> No
...

Sheet Defaults
A2: Default inputs per hectare
A4: Crops | E4: Nitrogen fixation | F4: Energy | G4: Pesticides | H4: Nitrogen fixation | I4: Energy | J4: Pesticides
A5: Crop code | B5: Crop | C5: Category | D5: Share | E5: N fixation, kg N/ha | F5: Diesel use, l/ha | G5: Pesticide use, kg a.i./ha | H5: N fixation, kg N/ha | I5: Diesel use, l/ha | J5: Pesticide use, kg a.i./ha
A6: 01371 | B6: Almonds, in shell | C6: Nuts
A7: 01654 | B7: Anise, badian, coriander, cumin, caraway, fennel and juniper berries, raw | C7: Vegetables
A8: 01341 | B8: Apples | C8: Fruits | F8: 450 | G8: 5.97 | I8: SBA, 2011 | J8: SS, 2022
A9: 01343 | B9: Apricots | C9: Fruits
A10: 01216 | B10: Artichokes | C10: Vegetables
A11: 01211 | B11: Asparagus | C11: Vegetables | F11: 140 | G11: 1.65 | I11: Baky et al., 2010, average for vegetables | J11: SS, 2022. Avg for vegetables
A12: 01311 | B12: Avocados | C12: Vegetables
A13: 01312 | B13: Bananas | C13: Fruits
A14: 0115 | B14: Barley, average | C14: Cereals, incl feed | F14: 69.7 | G14: 0.52
A15: 0115_s | B15: Barley, spring | C15: Cereals | D15: 90 | F15: 70 | G15: 0.47 | I15: Baky et al., 2010 | J15: SS, 2022
A16: 0115_w | B16: Barley, winter | C16: Cereals | D16: 10 | F16: 66.7 | G16: 1 | I16: Baky et al., 2010 | J16: SS, 2022
A17: 01701 | B17: Beans, dry | C17: Pulses | E17: 25 | F17: 65 | G17: 1.1 | H17: Tidåker et al., 2021 | I17: Tidåker et al, 2021, common bean conv | J17: Tidåker et al, 2021
A18: 01355.01 | B18: Blueberries | C18: Berries
A19: 01377 | B19: Brazil nuts, in shell | C19: Nuts
A20: 01702 | B20: Broad beans and horse beans, dry | C20: Pulses, incl feed | E20: 24 | F20: 63.2 | G20: 0.61 | H20: Lassaletta et al., 2014 | I20: Baky et al., 2010 | J20: SS, 2022
A21: 01243 | B21: Broad beans and horse beans, green | C21: Vegetables
A22: 01213_b | B22: Broccoli | C22: Vegetables | D22: 40 | F22: 140 | G22: 1.65 | I22: Baky et al., 2010 | J22: SS, 2022. Avg for vegetables
A23: 01192 | B23: Buckwheat | C23: Seeds
A24: 01212 | B24: Cabbages | C24: Vegetables | F24: 140 | G24: 1.65 | I24: Baky et al., 2010 | J24: SS, 2022. Avg for vegetables
A25: 01229 | B25: Cantaloupes and other melons | C25: Fruits
A26: 01251 | B26: Carrots and turnips | C26: Vegetables | F26: 140 | G26: 2.23 | I26: Baky et al., 2010 | J26: SS, 2022
A27: 01372 | B27: Cashew nuts, in shell | C27: Nuts
A28: 01213_cf | B28: Cauliflowers | C28: Vegetables | D28: 60 | F28: 140 | G28: 1.65 | I28: Baky et al., 2010 | J28: SS, 2022. Avg for vegetables
A29: 01213 | B29: Cauliflowers and broccoli, average | C29: Vegetables | F29: 140 | G29: 1.65
A30: 01199.90 | B30: Cereals n.e.c. | C30: Cereals
A31: 01344.02 | B31: Cherries | C31: Berries
A32: 01373 | B32: Chestnuts, in shell | C32: Nuts
A33: 01703 | B33: Chick peas, dry | C33: Pulses
A34: 01231 | B34: Chillies and peppers, green (Capsicum spp. and Pimenta spp.), raw | C34: Spices
A35: 01640 | B35: Cocoa beans | C35: Stimulants
A36: 01460 | B36: Coconut, in shell | C36: Nuts
A37: 01610 | B37: Coffee, green | C37: Stimulants
A38: 01232 | B38: Cucumbers and gherkins, averrage | C38: Vegetables | F38: 7 | G38: 1.65
A39: 01232_gh | B39: Cucumbers and gherkins, greenhouse | C39: Vegetables | D39: 95 | F39: 0 | G39: 1.65 | J39: SS, 2022. Avg for vegetables
A40: 01232_of | B40: Cucumbers and gherkins, openfield | C40: Vegetables | D40: 5 | F40: 140 | G40: 1.65 | I40: Baky et al., 2010, average for vegetables | J40: SS, 2022. Avg for vegetables
A41: 01351.01 | B41: Currants | C41: Berries | F41: 300 | G41: 2.25 | I41: Baky et al., 2010, average for berries | J41: SS, 2022. Strawberry
A42: 01314 | B42: Dates | C42: Fruits
...

Sheet Reference list
A2: Reference list
A4: Baky, A., Sundberg, M., Brown, N. 2010. Kartläggning av jordbrukets energianvändning. Ett projekt utfört på uppdrag av Jordbruksverket. JTI – Institutet för jordbruks- och miljöteknik, Uppsala, Sweden.
A5: Berglund, M., Cederberg, C., Clason, C., Henriksson, M., Törner, L. 2009. Jordbrukets klimatpåverkan – underlag för att beräkna växthusgasutsläpp på gårdsnivå och nulägesanalyser av exempelgårdar. Delrapport i JoKer-proJeKtet, Hushållningssällskapet Halland, Sweden.
A6: Chaudhary, A., Brooks, T.M. 2018. Land use intensity-specific global characterization factors to assess product biodiversity footprints. Environmental Science Technology 52, 5094–5104.
A7: Davis, J. Wallman, M., Sund, V., Emanuelsson, A., Cederberg, C., Sonesson, U. 2011. Emissions of greenhouse gases from production of horticultural products: analysis of 17 products cultivated in Sweden, SIK Institutet för livsmedel och bioteknik, Gothenburg, Sweden.
A8: Ecoinvent centre. 2023. Ecoinvent Database Version 3.9.1. Dübendorf, Switzerland: Swiss Centre for Life Cycle Inventories.
A9: Edström, M., Pettersson, O., Nilsson, L., Hörndahl, T. 2005. Jordbrukssektorns energianvändning. JTI-rapport Lantbruk & Industri 342. JTI – Institutet för jordbruks- och miljöteknik, Uppsala, Sweden. | R9: SS. 2020. Gödselmedel i jordbruket 2018/19. Mineral- och stallgödsel till olika grödor samt hantering och lagring av stallgödsel. Use of fertilisers and animal manure in agriculture in 2018/19. MI 30 SM 2002. Statistics Sweden, Örebro, Sweden.
A10: EU. 2023. Eurostat Statistical Database. European Union.
A11: FAO. 2023. FAOSTAT Statistical Database. Food and Agricultural Organization of the United Nations.
A12: Flysjö, A., Cederberg, C., Strid, I. 2008. LCA-databas för konventionella fodermedel: miljöpåverkan i samband med produktion, SIK Institutet för livsmedel och bioteknik, Gothenburg, Sweden.
A13: Frischknecht, R., Althaus, H.-J., Bauer, C., Doka, G., Heck, T., Jungbluth, N., Kellenberger, D., Nemecek, T. 2007. The environmental relevance of capital goods in life cycle assessments of products and services. International Journal of Life Cycle Assessment 12, 7-17.
A14: Hutchings, N., Webb, J., Amon, B., Dämmgen, U., Van Der Hoek, K., Steinbrecher, R., Dore, C., Wiltshire, J., Sánchez Jiménez, B., Haenel, H.-D., Röseman, C., Misselbrook, T., Hayashi, K., Freibauer, Annette, Cellier, P., Butterbach-Bahl, K., Sutton, M., Skiba, U., Kroeze, C., … Mikkelsen, M. H. (2019). 3D Crop production and agricultural soils. In EMEP/EEA air pollutant emission inventory guidebook 2019. Publications Office of the European Union.
A15: IPCC. 2006. IPCC Guidelines for National Greenhouse Gas Inventories. Volume 4. Agriculture, Forestry and Other Land Use. The Intergovernmental Panel of Climate Change. Geneva, Switzerland.
A16: IPCC. 2019. 2019 Refinement to the 2006 IPCC Guidelines for National Greenhouse Gas Inventories. The Intergovernmental Panel of Climate Change. Geneva, Switzerland.
A17: IPCC. 2021. Climate change 2021: The physical science basis. Contribution of working group I to the sixth assessment report. Cambridge University Press.
A18: Jensen, K. 2013.Ekologisk odling av sparris. Länsstyrelsen i Västra Götalands Län. https://www.yumpu.com/sv/document/read/19707719/ekologisk-odling-av-sparris-lansstyrelserna
A19: Karlsson-Potter, H. 2023. N-use in the Mistra Food Future model. Unpublised data.
A20: Lassaletta, L.; Billen, G.; Grizzetti, B.; Anglade, J.; Garnier, J. 2014. 50 year trends in nitrogen use efficiency of world cropping systems: The relationship between yield and nitrogen input to cropland. Environmental Research Letters 9, 105011. | R20: SBA. 2011. Ekonomi i bärodling. Kalkyler för jordgubbar och hallon. Jordbruksinformation 13 – 2011. Swedish Board of Agriculture, Jönköping, Sweden.
A21: Marmolin, C., Björkholm, A.-M. n.d. Växtnäringsrekommendationer till frilandsgrönsaker. En sammanställning av rekommendationer som ges i Sverige, Norge, Finland, Tyskland, Holland och UK. Hushållningssällskapet Skaraborg och Kristianstad, Sweden.
A22: Mekonnen, M., Hoekstra, A. 2011. National water footprint accounts: The green, blue and grey water footprint of production and consumption. Volume 2: Appendices. https://core.ac.uk/download/pdf/323867109.pdf | R22: SS. 2022. Växtskyddsmedel i jord- och trädgårdsbruket 2021 Användning i grödor. Plant protection products in agriculture and horticulture. Use in crops. MI 31 SM 2202. Statistics Sweden, Örebro, Sweden
A23: Muller, A., Schader, C., Scialabba, N., Bruggemann, J., Isensee, A., Erb, K-H., Smith, P., Klocke, P, Leiber, F., Stolze, M., Niggli, U. 2017. Strategies for feed the world sustainably with organic agriculture. Nature Communications 8, 1290.
A24: Nilsson, T. 2011. Gödsling av hallon. LTJ-fakultetens faktablad. Fakta från Tillväxt Trädgård, nr 8. Fakulteten för landskapsplanering, trädgårds- och jordbruksvetenskap 2011. Swedish University of Agricultural Sciences, Alnarp, Sweden.
A25: NIR. 2020. Swedish National Inventory Report. Swedish Environmental Protection Agency, Stockholm, Sweden.
A26: Röös, E., Karlsson, H. 2013. Effect of eating seasonal on the carbon footprint of Swedish vegetable consumption. Journal of Cleaner Production 59, 63-72.
A27: SBA 2004. Gödslings- och kalkningsråd för fruktodling 2004. Jordbruksinformation 5 – 2004. Swedish Board of Agriculture, Jönköping, Sweden.
A28: SBA. 2010. Energikartläggning av de areella näringarna. Regeringsuppdrag Jo 2009/1596. Rapport 2010:16. Swedish Board of Agriculture. Jönköping, Sweden.
A29: SBA. 2022. Energianvändning i växthus 2020. Tomat, gurka och prydnadsväxter. Swedish Board of Agriculture, Jönköping, Sweden.
A30: SBA. 2023. Trädgårdsproduktion 2022. The 2022 Horticultural Census. JO0607. Swedish Board of Agriculture.
A31: SBA. 2013. Kalkyler för svarta vinbär. Swedish Board of Agriculture. Undated. https://www2.jordbruksverket.se/webdav/files/SJV/trycksaker/Pdf_ovrigt/ovr291_4.pdf
A32: SS. 2020. Gödselmedel i jordbruket. Statistics Sweden. https://www.scb.se/contentassets/e6fdbf100cab433798eeae49cc857632/mi1001_2018b19_sm_mi30sm2002.pdf
A33: SS. 2022. https://www.scb.se/contentassets/6e042f0902bb449fb15edc4c1eb8e22c/mi0502_2021i20_br_mi31br2202.pdf
A34: Swedish Agency for Public Management. 2010. Effekter på priset för handelsgödsel när skatten på kväve i handelsgödsel avskaffas. Stockholm, Sweden.
... A42: Björkholm, A-M. 2019. Rådgivning grönsaker, bär och frukt, växtodling/Advisor vegetables, berries and fruits, plant production. Hushållningssällskapet.
