Workbook

Sheet Scherer
A1: Animal welfare index | H1: Blue number are inputed here | K1: Black are calculated
B2: DK | C2: FR | D2: DE | E2: GR | F2: HU | G2: IE | H2: IT | I2: NL | J2: PL | K2: ES | L2: SE | M2: UK | N2: NZ | O2: Utopia | P2: Dystopia | Q2: Assumptions and comments: | R2: Source: | S2: fem kalvar per ko (livstidsproduktion) räknat från Gård&Djurhälsan, 2023 men det ska väl användas för beef parent cow
A3: beef suckler tot welfare index | B3: =B13+B4 -> 0.29560176 | C3: =C13+C4 -> 0.28068068 | D3: =D13+D4 -> 0.31780714 | E3: =E13+E4 -> 0.32250669 | F3: =F13+F4 -> 0.34083494 | G3: =G13+G4 -> 0.28690759 | H3: =H13+H4 -> 0.3851282 | I3: =I13+I4 -> 0.28596768 | ... M3: =M13+M4 -> 0.26681701 | O3: =O13+O4 -> 0.00033131845 | P3: =P13+P4 -> 1.6565922 | S3: Per suckler herd per yr??? | T3: No of animals | U3: Slaughtering weight | V3: Meat produced (bonefree weight)
A4: welfare index beef parent | B4: =B7*B6*B5*100 -> 0.028314795 | C4: =C7*C6*C5*100 -> 0.034639607 | D4: =D7*D6*D5*100 -> 0.032896857 | E4: =E7*E6*E5*100 -> 0.034757096 | F4: =F7*F6*F5*100 -> 0.03722436 | G4: =G7*G6*G5*100 -> 0.036754405 | H4: =H7*H6*H5*100 -> 0.037459338 | I4: =I7*I6*I5*100 -> 0.033954256 | ... M4: =M7*M6*M5*100 -> 0.035462029 | O4: =O7*O6*O5*100 -> 5.8744388e-05 | P4: =P7*P6*P5*100 -> 0.29372194 | S4: Suckler cows | T4: 1 | U4: 400 | V4: =T4*U4*0.7 -> 280 | W4: =T4/V6 -> 0.00066445183
A5: beef parent level | B5: =(2*(B8+B9+B11))+B10 -> 0.482 | C5: =(2*(C8+C9+C11))+C10 -> 0.58966667 | D5: =(2*(D8+D9+D11))+D10 -> 0.56 | E5: =(2*(E8+E9+E11))+E10 -> 0.59166667 | F5: =(2*(F8+F9+F11))+F10 -> 0.63366667 | G5: =(2*(G8+G9+G11))+G10 -> 0.62566667 | H5: =(2*(H8+H9+H11))+H10 -> 0.63766667 | I5: =(2*(I8+I9+I11))+I10 -> 0.578 | ... M5: =(2*(M8+M9+M11))+M10 -> 0.60366667 | O5: =(2*(O8+O9+O11))+O10 -> 0.001 | P5: =(2*(P8+P9+P11))+P10 -> 5 | S5: Young animals | T5: 5 | U5: 350 | V5: =T5*U5*0.7 -> 1225 | W5: =T5/V6 -> 0.0033222591
A6: beef parent ability | B6: =Ability!$B$5 -> 0.88410303 | C6: =Ability!$B$5 -> 0.88410303 | D6: =Ability!$B$5 -> 0.88410303 | E6: =Ability!$B$5 -> 0.88410303 | F6: =Ability!$B$5 -> 0.88410303 | G6: =Ability!$B$5 -> 0.88410303 | H6: =Ability!$B$5 -> 0.88410303 | I6: =Ability!$B$5 -> 0.88410303 | ... M6: =Ability!$B$5 -> 0.88410303 | O6: =Ability!$B$5 -> 0.88410303 | P6: =Ability!$B$5 -> 0.88410303 | Q6: Value for ruminats | S6: Sum meat | V6: =V4+V5 -> 1505 | W6: kg meat
A7: beef parent no per kg meat | B7: =$W$4 -> 0.00066445183 | C7: =$W$4 -> 0.00066445183 | D7: =$W$4 -> 0.00066445183 | E7: =$W$4 -> 0.00066445183 | F7: =$W$4 -> 0.00066445183 | G7: =$W$4 -> 0.00066445183 | H7: =$W$4 -> 0.00066445183 | I7: =$W$4 -> 0.00066445183 | ... M7: =$W$4 -> 0.00066445183 | O7: =$W$4 -> 0.00066445183 | P7: =$W$4 -> 0.00066445183 | Q7: Lotta - dödlighet dikor 2% i Ahlgren et al - ANVÄNDA???? | R7: Vi kan ta ett värde mittemellan de två referenserna. Men jag förstår inte var Ahlgren har fått 2% ifrån (otydlig hänvisning)
A8: beef parent mortality | B8: 0.03 | C8: 0.03 | D8: 0.03 | E8: 0.03 | F8: 0.03 | G8: 0.03 | H8: 0.03 | I8: 0.03 | J8: 0.03 | K8: 0.03 | L8: 0.03 | M8: 0.03 | O8: 0 | P8: 0.5 | Q8: Assumed 3% based on Ahlgren et al, 2022 (2%) and 60% of dairy cow mortality, based on Thomson et al, 2020 (4%) | R8: Assumption
A9: beef parent disease | B9: 0.04 | C9: 0.04 | D9: 0.04 | E9: 0.04 | F9: 0.04 | G9: 0.04 | H9: 0.04 | I9: 0.04 | J9: 0.04 | K9: 0.04 | L9: 0.04 | M9: 0.04 | O9: 0 | P9: 0.5 | Q9: No data found; assumed 25% of dairy cow disease | R9: Assumption | S9: Saknar källa. Mastit hos dikor 1,5% (Andersson, 2028) och 7,9% på mjölkkor (Växa 2023b) Gammal anonym källa säger 2% (slutrapport SLF troligen fr 2005)
A10: beef parent slaughter | B10: =Slaughtering!$C$6 -> 0.25 | C10: =Slaughtering!$E$6 -> 0.34166667 | D10: =Slaughtering!$G$6 -> 0.25 | E10: =Slaughtering!$I$6 -> 0.34166667 | F10: =Slaughtering!$K$6 -> 0.34166667 | G10: =Slaughtering!$M$6 -> 0.34166667 | H10: =Slaughtering!$O$6 -> 0.34166667 | I10: =Slaughtering!$Q$6 -> 0.25 | J10: =Slaughtering!$S$6 -> 0.34166667 | K10: =Slaughtering!$U$6 -> 0.34166667 | L10: =Slaughtering!$W$6 -> 0.25 | M10: =Slaughtering!$Y$6 -> 0.34166667 | O10: 0.001 | P10: 1 | R10: Tab "Slaughtering" | S10: Från Ahlgren et al (2022):
A11: beef parent space | B11: 0.046 | C11: 0.054 | D11: 0.085 | E11: 0.055 | F11: 0.076 | G11: 0.072 | H11: 0.078 | I11: 0.094 | J11: 0.122 | K11: 0.053 | L11: 0.072 | M11: 0.061 | O11: 0 | P11: 1 | Q11: Assuming all animals on pasture during the grazing season and free-range indoor during the stable season
B12: =B16*((2-6/(365*24))*B14+6/(365*24))*B15 -> 0.0053459203
A13: welfare index beef calves 24m suckler syst | B13: =B16*B15*B14*100 -> 0.26728696 | C13: =C16*C15*C14*100 -> 0.24604108 | D13: =D16*D15*D14*100 -> 0.28491028 | E13: =E16*E15*E14*100 -> 0.28774959 | F13: =F16*F15*F14*100 -> 0.30361058 | G13: =G16*G15*G14*100 -> 0.25015318 | H13: =H16*H15*H14*100 -> 0.34766887 | I13: =I16*I15*I14*100 -> 0.25201342 | ... M13: =M16*M15*M14*100 -> 0.23135498 | O13: =O16*O15*O14*100 -> 0.00027257406 | P13: =P16*P15*P14*100 -> 1.3628703
A14: beef calves 24m level | B14: =(2*(B17+B18+B20))+B19 -> 0.91 | C14: =(2*(C17+C18+C20))+C19 -> 0.83766667 | D14: =(2*(D17+D18+D20))+D19 -> 0.97 | E14: =(2*(E17+E18+E20))+E19 -> 0.97966667 | F14: =(2*(F17+F18+F20))+F19 -> 1.0336667 | G14: =(2*(G17+G18+G20))+G19 -> 0.85166667 | H14: =(2*(H17+H18+H20))+H19 -> 1.1836667 | I14: =(2*(I17+I18+I20))+I19 -> 0.858 | ... M14: =(2*(M17+M18+M20))+M19 -> 0.78766667 | O14: =(2*(O17+O18+O20))+O19 -> 0.001 | P14: =(2*(P17+P18+P20))+P19 -> 5
A15: beef calves 24m ability | B15: =Ability!$B$5 -> 0.88410303 | C15: =Ability!$B$5 -> 0.88410303 | D15: =Ability!$B$5 -> 0.88410303 | E15: =Ability!$B$5 -> 0.88410303 | F15: =Ability!$B$5 -> 0.88410303 | G15: =Ability!$B$5 -> 0.88410303 | H15: =Ability!$B$5 -> 0.88410303 | I15: =Ability!$B$5 -> 0.88410303 | ... M15: =Ability!$B$5 -> 0.88410303 | O15: =Ability!$B$6 -> 0.82044792 | P15: =Ability!$B$6 -> 0.82044792
A16: beef calves 24m no per kg meat | B16: =$W$5 -> 0.0033222591 | C16: =$W$5 -> 0.0033222591 | D16: =$W$5 -> 0.0033222591 | E16: =$W$5 -> 0.0033222591 | F16: =$W$5 -> 0.0033222591 | G16: =$W$5 -> 0.0033222591 | H16: =$W$5 -> 0.0033222591 | I16: =$W$5 -> 0.0033222591 | ... M16: =$W$5 -> 0.0033222591 | O16: =$W$5 -> 0.0033222591 | P16: =$W$5 -> 0.0033222591
A17: beef calves 24m mortality | B17: 0.042 | C17: 0.042 | D17: 0.042 | E17: 0.042 | F17: 0.042 | G17: 0.042 | H17: 0.042 | I17: 0.042 | J17: 0.042 | K17: 0.042 | L17: 0.042 | M17: 0.042 | O17: 0 | P17: 0.5 | Q17: Mortality of live born from birth to slaughter. Based on combination of Swedish data. Most calves die first week and in UK 4.4% of suckler calves died from day 1 to day 21 (AHDP, 2021) | R17: Jordbruksverket 2012; 2022;2023; | S17: 2,7+1,5=4,2. Kombination av Jordbruksverket 2023 (4,7 tot vid 6 mån) och Jordbruksverket 2022 (2,7 dikokalv och 6,0 mjölkkokalv, tot 4,7 vid 6 mån) och Jordbruksverket 2012 (1,5% under 6-24 mån, tabell 2.14)
A18: beef calves 24m disease | B18: 0.05 | C18: 0.05 | D18: 0.05 | E18: 0.05 | F18: 0.05 | G18: 0.05 | H18: 0.05 | I18: 0.05 | J18: 0.05 | K18: 0.05 | L18: 0.05 | M18: 0.05 | O18: 0 | P18: 0.5 | Q18: Lower disease and injury risk for beef than dairy calves, and for calves raised to 18m than for veal calves (Mandel et al, 2022). Assumed value set to 50% of the value for young dairy calves. | R18: Jordbruksverket 2012; 2022; 2023; Mandel et al, 2022
A19: beef calves 24m slaughter | B19: =Slaughtering!$C$6 -> 0.25 | C19: =Slaughtering!$E$6 -> 0.34166667 | D19: =Slaughtering!$G$6 -> 0.25 | E19: =Slaughtering!$I$6 -> 0.34166667 | F19: =Slaughtering!$K$6 -> 0.34166667 | G19: =Slaughtering!$M$6 -> 0.34166667 | H19: =Slaughtering!$O$6 -> 0.34166667 | I19: =Slaughtering!$Q$6 -> 0.25 | J19: =Slaughtering!$S$6 -> 0.34166667 | K19: =Slaughtering!$U$6 -> 0.34166667 | L19: =Slaughtering!$W$6 -> 0.25 | M19: =Slaughtering!$Y$6 -> 0.34166667 | O19: 0.001 | P19: 1 | R19: Tab "Slaughtering"
A20: beef calves 24m space | B20: 0.238 | C20: 0.156 | D20: 0.268 | E20: 0.227 | F20: 0.254 | G20: 0.163 | H20: 0.329 | I20: 0.212 | J20: 0.298 | K20: 0.119 | L20: 0.135 | M20: 0.131 | O20: 0 | P20: 1
A21: dairy calf 9m tot welfare index | B21: =B24*B23*B22*100 -> 0.3859387 | C21: =C24*C23*C22*100 -> 0.49604281 | D21: =D24*D23*D22*100 -> 0.45091818 | E21: =E24*E23*E22*100 -> 0.49604281 | F21: =F24*F23*F22*100 -> 0.49604281 | G21: =G24*G23*G22*100 -> 0.49604281 | H21: =H24*H23*H22*100 -> 0.49604281 | I21: =I24*I23*I22*100 -> 0.45091818 | ... M21: =M24*M23*M22*100 -> 0.46749122 | O21: =O24*O23*O22*100 -> 0.00049226875 | P21: =P24*P23*P22*100 -> 2.4613438 | Q21: Parent (cow) is not included; all welfare isssues are allocated to the dairy production
A22: dairy calf 9m level | B22: =(2*(B25+B26+B28))+B27 -> 0.784 | C22: =(2*(C25+C26+C28))+C27 -> 1.0076667 | D22: =(2*(D25+D26+D28))+D27 -> 0.916 | E22: =(2*(E25+E26+E28))+E27 -> 1.0076667 | F22: =(2*(F25+F26+F28))+F27 -> 1.0076667 | G22: =(2*(G25+G26+G28))+G27 -> 1.0076667 | H22: =(2*(H25+H26+H28))+H27 -> 1.0076667 | I22: =(2*(I25+I26+I28))+I27 -> 0.916 | ... M22: =(2*(M25+M26+M28))+M27 -> 0.94966667 | O22: =(2*(O25+O26+O28))+O27 -> 0.001 | P22: =(2*(P25+P26+P28))+P27 -> 5
A23: dairy calf 9m ability | B23: =Ability!$B$6 -> 0.82044792 | C23: =Ability!$B$6 -> 0.82044792 | D23: =Ability!$B$6 -> 0.82044792 | E23: =Ability!$B$6 -> 0.82044792 | F23: =Ability!$B$6 -> 0.82044792 | G23: =Ability!$B$6 -> 0.82044792 | H23: =Ability!$B$6 -> 0.82044792 | I23: =Ability!$B$6 -> 0.82044792 | ... M23: =Ability!$B$6 -> 0.82044792 | O23: =Ability!$B$6 -> 0.82044792 | P23: =Ability!$B$6 -> 0.82044792 | Q23: Var kommer slaktvikten nedan ifrån?
A24: dairy calf 9m no per kg meat | B24: 0.006 | C24: 0.006 | D24: 0.006 | E24: 0.006 | F24: 0.006 | G24: 0.006 | H24: 0.006 | I24: 0.006 | J24: 0.006 | K24: 0.006 | L24: 0.006 | M24: 0.006 | O24: 0.006 | P24: 0.006 | Q24: Här ska vi ha 1/(slaktvikt (240 kg)*0.7), vi antar bara mjölkras och all impact för moderdjuren hamnar för mjölken
A25: dairy calf 9m mortality | B25: 0.065 | C25: 0.065 | D25: 0.065 | E25: 0.065 | F25: 0.065 | G25: 0.065 | H25: 0.065 | I25: 0.065 | J25: 0.065 | K25: 0.065 | L25: 0.065 | M25: 0.065 | O25: 0 | P25: 0.5 | Q25: Mortality of liveborn from birth to slaughter. Based on combination of Swedish data | R25: Jordbruksverket 2012; 2022; 2023; | S25: Kombination av Jordbruksverket 2023 (4,7 tot vid 6 mån) och Jordbruksverket 2022 (2,7 dikokalv och 6,0 mjölkkokalv, tot 4,7 vid 6 mån) och Jordbruksverket 2012 (0,5% under 6-9 mån, tabell 2.14)
A26: dairy calf 9m disease | B26: 0.1 | C26: 0.1 | D26: 0.1 | E26: 0.1 | F26: 0.1 | G26: 0.1 | H26: 0.1 | I26: 0.1 | J26: 0.1 | K26: 0.1 | L26: 0.1 | M26: 0.1 | O26: 0 | P26: 0.5 | Q26: Data are scarce. 10% is an assumed value within a range from 4% (0-15m, calculated from Jordbruksverket, 2023b) to 23% (0-3m, Svensson et al, 2003). | R26: Jordbruksverket 2023b, Svensson et al, 2003
A27: dairy calf 9m slaughter | B27: =Slaughtering!$C$6 -> 0.25 | C27: =Slaughtering!$E$6 -> 0.34166667 | D27: =Slaughtering!$G$6 -> 0.25 | E27: =Slaughtering!$I$6 -> 0.34166667 | F27: =Slaughtering!$K$6 -> 0.34166667 | G27: =Slaughtering!$M$6 -> 0.34166667 | H27: =Slaughtering!$O$6 -> 0.34166667 | I27: =Slaughtering!$Q$6 -> 0.25 | J27: =Slaughtering!$S$6 -> 0.34166667 | K27: =Slaughtering!$U$6 -> 0.34166667 | L27: =Slaughtering!$W$6 -> 0.25 | M27: =Slaughtering!$Y$6 -> 0.34166667 | O27: 0.001 | P27: 1 | R27: Tab "Slaughtering"
A28: dairy calf 9m space | B28: 0.102 | C28: 0.168 | D28: 0.168 | E28: 0.168 | F28: 0.168 | G28: 0.168 | H28: 0.168 | I28: 0.168 | J28: 0.168 | K28: 0.168 | L28: 0.163 | M28: 0.139 | O28: 0 | P28: 1 | Q28: Assuming all animals indoors all year
A29: dairy calf 24m tot welfare index | B29: =B32*B31*B30*100 -> 0.20061451 | C29: =C32*C31*C30*100 -> 0.24631609 | D29: =D32*D31*D30*100 -> 0.28238673 | E29: =E32*E31*E30*100 -> 0.28502161 | F29: =F32*F31*F30*100 -> 0.29974061 | G29: =G32*G31*G30*100 -> 0.25013213 | H29: =H32*H31*H30*100 -> 0.34062672 | I29: =I32*I31*I30*100 -> 0.25185843 | ... M29: =M32*M31*M30*100 -> 0.23268739 | O29: =O32*O31*O30*100 -> 0.00027257406 | P29: =P32*P31*P30*100 -> 1.3628703 | Q29: Parent (cow) is not included; all welfare isssues are allocated to the dairy production
A30: dairy calves 24m level | B30: =(2*(B33+B34+B36))+B35 -> 0.736 | C30: =(2*(C33+C34+C36))+C35 -> 0.90366667 | D30: =(2*(D33+D34+D36))+D35 -> 1.036 | E30: =(2*(E33+E34+E36))+E35 -> 1.0456667 | F30: =(2*(F33+F34+F36))+F35 -> 1.0996667 | G30: =(2*(G33+G34+G36))+G35 -> 0.91766667 | H30: =(2*(H33+H34+H36))+H35 -> 1.2496667 | I30: =(2*(I33+I34+I36))+I35 -> 0.924 | ... M30: =(2*(M33+M34+M36))+M35 -> 0.85366667 | O30: =(2*(O33+O34+O36))+O35 -> 0.001 | P30: =(2*(P33+P34+P36))+P35 -> 5
A31: dairy calves 24m ability | B31: =Ability!$B$6 -> 0.82044792 | C31: =Ability!$B$6 -> 0.82044792 | D31: =Ability!$B$6 -> 0.82044792 | E31: =Ability!$B$6 -> 0.82044792 | F31: =Ability!$B$6 -> 0.82044792 | G31: =Ability!$B$6 -> 0.82044792 | H31: =Ability!$B$6 -> 0.82044792 | I31: =Ability!$B$6 -> 0.82044792 | ... M31: =Ability!$B$6 -> 0.82044792 | O31: =Ability!$B$6 -> 0.82044792 | P31: =Ability!$B$6 -> 0.82044792 | Q31: Är rad 33 rätt? Det är inte 1/slaktvikt utan tagit från tabellen ovan, men borde det inte vara samma sak här som för 9m??
A32: dairy calves 24m no per kg meat | B32: =$W$5 -> 0.0033222591 | C32: =$W$5 -> 0.0033222591 | D32: =$W$5 -> 0.0033222591 | E32: =$W$5 -> 0.0033222591 | F32: =$W$5 -> 0.0033222591 | G32: =$W$5 -> 0.0033222591 | H32: =$W$5 -> 0.0033222591 | I32: =$W$5 -> 0.0033222591 | ... M32: =$W$5 -> 0.0033222591 | O32: =$W$5 -> 0.0033222591 | P32: =$W$5 -> 0.0033222591 | Q32: Här ska vi ha 1/(slaktvikt*0.7), vi antar bara mjölkras och all impact för moderdjuren hamnar för mjölken
A33: dairy calves 24m mortality | B33: 0.075 | C33: 0.075 | D33: 0.075 | E33: 0.075 | F33: 0.075 | G33: 0.075 | H33: 0.075 | I33: 0.075 | J33: 0.075 | K33: 0.075 | L33: 0.075 | M33: 0.075 | O33: 0 | P33: 0.5 | Q33: Mortality of liveborn from birth to slaughter. Based on combination of Swedish data | R33: Jordbruksverket 2012; 2022; 2023; | S33: Kombination av Jordbruksverket 2023 (4,7 tot vid 6 mån) och Jordbruksverket 2022 (2,7 dikokalv och 6,0 mjölkkokalv, tot 4,7 vid 6 mån) och Jordbruksverket 2012 (1,5% under 6-24 mån, tabell 2.14)
A34: dairy calves 24m disease | B34: 0.05 | C34: 0.05 | D34: 0.05 | E34: 0.05 | F34: 0.05 | G34: 0.05 | H34: 0.05 | I34: 0.05 | J34: 0.05 | K34: 0.05 | L34: 0.05 | M34: 0.05 | O34: 0 | P34: 0.5 | Q34: Lower disease and injury risk for beef than dairy calves, and for calves raised to 18m than for veal calves (Mandel et al, 2022). Assumed value set to 50% of the value for young dairy calves. | R34: Jordbruksverket 2023b, Svensson et al, 2003
A35: dairy calves 24m slaughter | B35: =Slaughtering!$C$6 -> 0.25 | C35: =Slaughtering!$E$6 -> 0.34166667 | D35: =Slaughtering!$G$6 -> 0.25 | E35: =Slaughtering!$I$6 -> 0.34166667 | F35: =Slaughtering!$K$6 -> 0.34166667 | G35: =Slaughtering!$M$6 -> 0.34166667 | H35: =Slaughtering!$O$6 -> 0.34166667 | I35: =Slaughtering!$Q$6 -> 0.25 | J35: =Slaughtering!$S$6 -> 0.34166667 | K35: =Slaughtering!$U$6 -> 0.34166667 | L35: =Slaughtering!$W$6 -> 0.25 | M35: =Slaughtering!$Y$6 -> 0.34166667 | O35: 0.001 | P35: 1 | R35: Tab "Slaughtering"
A36: dairy calves 24m space | B36: 0.118 | C36: 0.156 | D36: 0.268 | E36: 0.227 | F36: 0.254 | G36: 0.163 | H36: 0.329 | I36: 0.212 | J36: 0.298 | K36: 0.119 | L36: 0.135 | M36: 0.131 | O36: 0 | P36: 1
A37: dairy cow welfare index | B37: =B40*B39*B38*100 -> 0.0085404353 | C37: =C40*C39*C38*100 -> 0.0083960318 | D37: =D40*D39*D38*100 -> 0.0098489078 | E37: =E40*E39*E38*100 -> 0.012851911 | F37: =F40*F39*F38*100 -> 0.013134824 | G37: =G40*G39*G38*100 -> 0.0082192112 | H37: =H40*H39*H38*100 -> 0.011189797 | I37: =I40*I39*I38*100 -> 0.0086818918 | ... L37: =L40*L39*L38*100 -> 0.0080983838 | O37: =O40*O39*O38*100 -> 8.8410303e-06 | P37: =P40*P39*P38*100 -> 0.044205152 | Q37: Dairy cow space includes the cow's whole life. Disease and mortality in % affected cows per year. | R37: kan inte sudda här? | S37: Vad menas med detta? Förenklat genom att inte ha med en beräkning för kvigan. Sjukdom o dödlighet gäller vuxna kor per år
A38: dairy cow level | B38: =(2*(B41+B42+B44))+B43 -> 0.966 | C38: =(2*(C41+C42+C44))+C43 -> 0.94966667 | D38: =(2*(D41+D42+D44))+D43 -> 1.114 | E38: =(2*(E41+E42+E44))+E43 -> 1.4536667 | F38: =(2*(F41+F42+F44))+F43 -> 1.4856667 | G38: =(2*(G41+G42+G44))+G43 -> 0.92966667 | H38: =(2*(H41+H42+H44))+H43 -> 1.2656667 | I38: =(2*(I41+I42+I44))+I43 -> 0.982 | ... L38: =(2*(L41+L42+L44))+L43 -> 0.916 | O38: =(2*(O41+O42+O44))+O43 -> 0.001 | P38: =(2*(P41+P42+P44))+P43 -> 5
A39: dairy cow ability | B39: =Ability!$B$5 -> 0.88410303 | C39: =Ability!$B$5 -> 0.88410303 | D39: =Ability!$B$5 -> 0.88410303 | E39: =Ability!$B$5 -> 0.88410303 | F39: =Ability!$B$5 -> 0.88410303 | G39: =Ability!$B$5 -> 0.88410303 | H39: =Ability!$B$5 -> 0.88410303 | I39: =Ability!$B$5 -> 0.88410303 | ... L39: =Ability!$B$5 -> 0.88410303 | O39: =Ability!$B$5 -> 0.88410303 | P39: =Ability!$B$5 -> 0.88410303 | S39: See också Ingrids artikel: | T39: https://www.frontiersin.org/articles/10.3389/fsufs.2023.1171865/full
A40: dairy cows no per kg milk | B40: 0.0001 | C40: 0.0001 | D40: 0.0001 | E40: 0.0001 | F40: 0.0001 | G40: 0.0001 | H40: 0.0001 | I40: 0.0001 | J40: 0.0001 | K40: 0.0001 | L40: 0.0001 | O40: 0.0001 | P40: 0.0001 | Q40: 1/life time milk production, but here adjusted to 0.0001 | R40: Comes from Dairy.xlsx, tab Parameters, country specific
...

Sheet Diagram
A2: Diagrams
B4: DK | C4: FR | D4: DE | E4: GR | F4: HU | G4: IE | H4: IT | I4: NL | J4: PL | K4: ES | L4: SE | O4: High | P4: Average | Q4: Low
A5: Meat from suckler herds | B5: ='Animal welfare index'!B3 -> 0.29560176 | C5: ='Animal welfare index'!C3 -> 0.28068068 | D5: ='Animal welfare index'!D3 -> 0.31780714 | E5: ='Animal welfare index'!E3 -> 0.32250669 | F5: ='Animal welfare index'!F3 -> 0.34083494 | G5: ='Animal welfare index'!G3 -> 0.28690759 | H5: ='Animal welfare index'!H3 -> 0.3851282 | I5: ='Animal welfare index'!I3 -> 0.28596768 | ... L5: ='Animal welfare index'!L3 -> 0.23814975 | N5: Meat from suckler herds | O5: =MAX(B5:L5) -> 0.3851282 | P5: =AVERAGE(B5:L5) -> 0.30768174 | Q5: =MIN(B5:L5) -> 0.23814975
A6: Meat from dairy calves 9m | B6: ='Animal welfare index'!B20 -> 0.3859387 | C6: ='Animal welfare index'!C20 -> 0.49604281 | D6: ='Animal welfare index'!D20 -> 0.45091818 | E6: ='Animal welfare index'!E20 -> 0.49604281 | F6: ='Animal welfare index'!F20 -> 0.49604281 | G6: ='Animal welfare index'!G20 -> 0.49604281 | H6: ='Animal welfare index'!H20 -> 0.49604281 | I6: ='Animal welfare index'!I20 -> 0.45091818 | ... L6: ='Animal welfare index'!L20 -> 0.44599549 | N6: Meat from dairy calves 9m | O6: =MAX(B6:L6) -> 0.49604281 | P6: =AVERAGE(B6:L6) -> 0.47327911 | Q6: =MIN(B6:L6) -> 0.3859387
A7: Meat from dairy calves 24m | B7: ='Animal welfare index'!B28 -> 0.20061451 | C7: ='Animal welfare index'!C28 -> 0.24631609 | D7: ='Animal welfare index'!D28 -> 0.28238673 | E7: ='Animal welfare index'!E28 -> 0.28502161 | F7: ='Animal welfare index'!F28 -> 0.29974061 | G7: ='Animal welfare index'!G28 -> 0.25013213 | H7: ='Animal welfare index'!H28 -> 0.34062672 | I7: ='Animal welfare index'!I28 -> 0.25185843 | ... L7: ='Animal welfare index'!L28 -> 0.20988203 | N7: Meat from dairy calves 24m | O7: =MAX(B7:L7) -> 0.34062672 | P7: =AVERAGE(B7:L7) -> 0.26513196 | Q7: =MIN(B7:L7) -> 0.20061451
A8: Milk | B8: ='Animal welfare index'!B36 -> 0.0085404353 | C8: ='Animal welfare index'!C36 -> 0.0083960318 | D8: ='Animal welfare index'!D36 -> 0.0098489078 | E8: ='Animal welfare index'!E36 -> 0.012851911 | F8: ='Animal welfare index'!F36 -> 0.013134824 | G8: ='Animal welfare index'!G36 -> 0.0082192112 | H8: ='Animal welfare index'!H36 -> 0.011189797 | I8: ='Animal welfare index'!I36 -> 0.0086818918 | ... L8: ='Animal welfare index'!L36 -> 0.0080983838
A9: Egg | B9: ='Animal welfare index'!B44 -> 6.7125008 | C9: ='Animal welfare index'!C44 -> 6.8052207 | D9: ='Animal welfare index'!D44 -> 6.9023384 | E9: ='Animal welfare index'!E44 -> 9.9274162 | F9: ='Animal welfare index'!F44 -> 10.427297 | G9: ='Animal welfare index'!G44 -> 7.3563894 | H9: ='Animal welfare index'!H44 -> 8.5092139 | I9: ='Animal welfare index'!I44 -> 8.1405739 | ... L9: ='Animal welfare index'!L44 -> 7.7135093 | N9: Egg | O9: =MAX(B9:L9) -> 10.427297 | P9: =AVERAGE(B9:L9) -> 8.3038422 | Q9: =MIN(B9:L9) -> 6.7125008
A10: Chicken | B10: ='Animal welfare index'!B61 -> 70.37812 | C10: ='Animal welfare index'!C61 -> 76.86855 | D10: ='Animal welfare index'!D61 -> 67.939375 | E10: ='Animal welfare index'!E61 -> 76.426602 | F10: ='Animal welfare index'!F61 -> 76.413841 | G10: ='Animal welfare index'!G61 -> 76.426602 | H10: ='Animal welfare index'!H61 -> 76.426602 | I10: ='Animal welfare index'!I61 -> 75.375612 | ... L10: ='Animal welfare index'!L61 -> 60.503138 | N10: Chicken | O10: =MAX(B10:L10) -> 76.86855 | P10: =AVERAGE(B10:L10) -> 73.598738 | Q10: =MIN(B10:L10) -> 60.503138
A11: Pig | B11: ='Animal welfare index'!B78 -> 3.7603025 | C11: ='Animal welfare index'!C78 -> 3.8528814 | D11: ='Animal welfare index'!D78 -> 3.6585123 | E11: ='Animal welfare index'!E78 -> 3.778257 | F11: ='Animal welfare index'!F78 -> 3.6643868 | G11: ='Animal welfare index'!G78 -> 3.6547805 | H11: ='Animal welfare index'!H78 -> 2.9314832 | I11: ='Animal welfare index'!I78 -> 3.521251 | ... L11: ='Animal welfare index'!L78 -> 2.8930739 | N11: Pig | O11: =MAX(B11:L11) -> 3.9766059 | P11: =AVERAGE(B11:L11) -> 3.5881628 | Q11: =MIN(B11:L11) -> 2.8930739
A12: Sheep | B12: ='Animal welfare index'!B95 -> 3.0059866 | C12: ='Animal welfare index'!C95 -> 3.2933591 | D12: ='Animal welfare index'!D95 -> 3.4800641 | E12: ='Animal welfare index'!E95 -> 2.8533373 | F12: ='Animal welfare index'!F95 -> 199.07249 | G12: ='Animal welfare index'!G95 -> 2.6711696 | H12: ='Animal welfare index'!H95 -> 2.8706657 | I12: ='Animal welfare index'!I95 -> 2.5248576 | ... L12: ='Animal welfare index'!L95 -> 2.8547625 | N12: Sheep | O12: =MAX(B12:L12) -> 199.07249 | P12: =AVERAGE(B12:L12) -> 20.949008 | Q12: =MIN(B12:L12) -> 2.5248576
A13: Rabbit | C13: ='Animal welfare index'!C112 -> 72.655755 | F13: ='Animal welfare index'!F112 -> 72.655755 | H13: ='Animal welfare index'!H112 -> 69.058707 | K13: ='Animal welfare index'!K112 -> 72.864618 | N13: Rabbit | O13: =MAX(B13:L13) -> 72.864618 | P13: =AVERAGE(B13:L13) -> 71.808709 | Q13: =MIN(B13:L13) -> 69.058707
A14: Salmon | B14: ='Animal welfare index'!B120 -> 10.939089 | C14: ='Animal welfare index'!C120 -> 10.939089 | D14: ='Animal welfare index'!D120 -> 10.939089 | E14: ='Animal welfare index'!E120 -> 10.939089 | F14: ='Animal welfare index'!F120 -> 10.939089 | G14: ='Animal welfare index'!G120 -> 10.939089 | H14: ='Animal welfare index'!H120 -> 10.939089 | I14: ='Animal welfare index'!I120 -> 10.939089 | ... L14: ='Animal welfare index'!L120 -> 10.939089 | N14: Salmon | O14: =MAX(B14:L14) -> 10.939089 | P14: =AVERAGE(B14:L14) -> 10.939089 | Q14: =MIN(B14:L14) -> 10.939089
A15: Meal worm | B15: ='Animal welfare index'!B160 -> 0.27459417 | C15: ='Animal welfare index'!C160 -> 0.27459417 | D15: ='Animal welfare index'!D160 -> 0.27459417 | E15: ='Animal welfare index'!E160 -> 0.27459417 | F15: ='Animal welfare index'!F160 -> 0.27459417 | G15: ='Animal welfare index'!G160 -> 0.27459417 | H15: ='Animal welfare index'!H160 -> 0.27459417 | I15: ='Animal welfare index'!I160 -> 0.27459417 | ... L15: ='Animal welfare index'!L160 -> 0.27459417
A16: Shrimp | B16: ='Animal welfare index'!B184 -> 7.6084608 | C16: ='Animal welfare index'!C184 -> 7.6084608 | D16: ='Animal welfare index'!D184 -> 7.6084608 | E16: ='Animal welfare index'!E184 -> 7.6084608 | F16: ='Animal welfare index'!F184 -> 7.6084608 | G16: ='Animal welfare index'!G184 -> 7.6084608 | H16: ='Animal welfare index'!H184 -> 7.6084608 | I16: ='Animal welfare index'!I184 -> 7.6084608 | ... L16: ='Animal welfare index'!L184 -> 7.6084608
M17: COMPARISON ACROSS ANIMAL SPECIES BASED ON DENMARK | X17: En sån här tabell skulle kunna vara användbar för att diskutera vad skillnaderna mellan djurslagen beror på eg
A18: Det är inte så stora skillnader mellan länder så det är värt att rita dem i ett diagram så här, bättre visa för ett land, eller bättre i tabell? -> | O18: Production animal | S18: Parent animal | X18: Chicken much higher index because high no of animal per kg of meat and high value for level due to limited space and high disease rate. Parent animals contribute 10%...
A19: Bättre att ha i tabell? Och diskutera intressanta skillnader tex ungern högre för får än gris | N19: Overall index | O19: Index | P19: Level | Q19: Ability | R19: No of animal | S19: Index | T19: Level | U19: Ability | V19: No of animal | X19: Interesting that the parent animal contributes more than per kg of meat from beef.
M20: Meat from suckler herds | N20: {=Animal welfare [1]index!B5} -> #NAME? | P20: ='Animal welfare index'!B13 -> 0.91 | Q20: ='Animal welfare index'!B14 -> 0.88410303 | R20: ='Animal welfare index'!B15 -> 0.0033222591 | S20: ='Animal welfare index'!B4 -> 0.028314795
M21: Meat from dairy calves 9m
M22: Meat from dairy calves 24m
M23: Egg
M24: Chicken | N24: ='Animal welfare index'!B61 -> 70.37812 | P24: ='Animal welfare index'!B63 -> 1.7066667 | Q24: ='Animal welfare index'!B64 -> 0.54320828 | R24: ='Animal welfare index'!B65 -> 0.75216903 | S24: ='Animal welfare index'!B70 -> 0.64637505
M25: Pig
M26: Sheep
M27: Rabbit
M28: Salmon
M29: Wild ruminants
M30: Wild boar
M31: Wild rabbit

Sheet Denmark
A3: COMPARISON ACROSS ANIMAL SPECIES BASED ON DENMARK
C4: Production animal | G4: Parent animal, or other involved animals
B5: Overall index | C5: Index | D5: Level | E5: Ability | F5: No of animals | G5: Index | H5: Level | I5: Ability | J5: No of animal
A6: Meat from suckler herds | B6: ='Animal welfare index'!B3 -> 0.29560176 | C6: ='Animal welfare index'!B12 -> 0.26728696 | D6: ='Animal welfare index'!B13 -> 0.91 | E6: ='Animal welfare index'!B14 -> 0.88410303 | F6: ='Animal welfare index'!B15 -> 0.0033222591 | G6: ='Animal welfare index'!B4 -> 0.028314795 | H6: ='Animal welfare index'!B5 -> 0.482 | I6: ='Animal welfare index'!B6 -> 0.88410303 | J6: ='Animal welfare index'!B7 -> 0.00066445183
A7: Meat from dairy calves 9m | B7: ='Animal welfare index'!B20 -> 0.3859387 | C7: ='Animal welfare index'!B20 -> 0.3859387 | D7: ='Animal welfare index'!B21 -> 0.784 | E7: ='Animal welfare index'!B22 -> 0.82044792 | F7: ='Animal welfare index'!B23 -> 0.006
A8: Meat from dairy calves 24m | B8: ='Animal welfare index'!B28 -> 0.20061451 | C8: ='Animal welfare index'!B28 -> 0.20061451 | D8: ='Animal welfare index'!B29 -> 0.736 | E8: ='Animal welfare index'!B30 -> 0.82044792 | F8: ='Animal welfare index'!B31 -> 0.0033222591
A9: Milk from dairy cows | B9: ='Animal welfare index'!B36 -> 0.0085404353 | C9: ='Animal welfare index'!B36 -> 0.0085404353 | D9: ='Animal welfare index'!B37 -> 0.966 | E9: ='Animal welfare index'!B38 -> 0.88410303 | F9: ='Animal welfare index'!B39 -> 0.0001 | G9: *
A10: Egg | B10: ='Animal welfare index'!B44 -> 6.7125008 | C10: ='Animal welfare index'!B53 -> 6.7027372 | D10: ='Animal welfare index'!B54 -> 2.082 | E10: ='Animal welfare index'!B55 -> 0.58534078 | F10: ='Animal welfare index'!B56 -> 0.055 | G10: ='Animal welfare index'!B45 -> 0.0097635475 | H10: ='Animal welfare index'!B46 -> 0.0069444444 | I10: ='Animal welfare index'!B47 -> 0.25562743 | J10: ='Animal welfare index'!B48 -> 0.055
A11: Chicken meat | B11: ='Animal welfare index'!B61 -> 70.37812 | C11: ='Animal welfare index'!B62 -> 69.731745 | D11: ='Animal welfare index'!B63 -> 1.7066667 | E11: ='Animal welfare index'!B64 -> 0.54320828 | F11: ='Animal welfare index'!B65 -> 0.75216903 | G11: ='Animal welfare index'!B70 -> 0.64637505 | H11: ='Animal welfare index'!B71 -> 2.026 | I11: ='Animal welfare index'!B72 -> 0.58534078 | J11: ='Animal welfare index'!B73 -> 0.0054505002
A12: Pig meat | B12: ='Animal welfare index'!B78 -> 3.7603025 | C12: ='Animal welfare index'!B79 -> 3.6384965 | D12: ='Animal welfare index'!B80 -> 2.276 | E12: ='Animal welfare index'!B81 -> 0.87981166 | F12: ='Animal welfare index'!B82 -> 0.018170212 | G12: ='Animal welfare index'!B87 -> 0.12180592 | H12: ='Animal welfare index'!B88 -> 1.456 | I12: ='Animal welfare index'!B89 -> 0.94805646 | J12: ='Animal welfare index'!B90 -> 0.0008824149
A13: Lamb meat | B13: ='Animal welfare index'!B95 -> 3.0059866 | C13: ='Animal welfare index'!B96 -> 2.5269796 | D13: ='Animal welfare index'!B97 -> 0.77 | E13: ='Animal welfare index'!B98 -> 0.82044792 | F13: ='Animal welfare index'!B99 -> 0.04 | G13: ='Animal welfare index'!B104 -> 0.47900702 | H13: ='Animal welfare index'!B105 -> 0.774 | I13: ='Animal welfare index'!B106 -> 0.88410303 | J13: ='Animal welfare index'!B107 -> 0.007
A14: Rabbit meat | B14: ='Animal welfare index'!B112 -> 72.094906 | C14: ='Animal welfare index'!B112 -> 72.094906 | D14: ='Animal welfare index'!B113 -> 1.444 | E14: ='Animal welfare index'!B114 -> 0.67196797 | F14: ='Animal welfare index'!B115 -> 0.743
A15: Salmon | B15: ='Animal welfare index'!B120 -> 10.939089 | C15: ='Animal welfare index'!B120 -> 10.939089 | D15: ='Animal welfare index'!B121 -> 0.88033333 | E15: ='Animal welfare index'!B122 -> 0.30307199 | F15: ='Animal welfare index'!B123 -> 0.4100041
A16: Wild fish | B16: ='Animal welfare index'!B128 -> 1.8647869 | C16: ='Animal welfare index'!B128 -> 1.8647869 | D16: ='Animal welfare index'!B129 -> 0.14583333 | E16: ='Animal welfare index'!B130 -> 0.31967775 | F16: ='Animal welfare index'!B131 -> 0.4
A17: Meat from wild ruminants | B17: ='Animal welfare index'!B136 -> 0.0044035906 | C17: ='Animal welfare index'!B136 -> 0.0044035906 | D17: ='Animal welfare index'!B137 -> 0.00069444444 | E17: ='Animal welfare index'!B138 -> 0.93252506 | F17: ='Animal welfare index'!B139 -> 0.068
A18: Wildboar meat | B18: ='Animal welfare index'!B144 -> 0.0022222222 | C18: ='Animal welfare index'!B144 -> 0.0022222222 | D18: ='Animal welfare index'!B145 -> 0.00069444444 | E18: ='Animal welfare index'!B146 -> 1 | F18: ='Animal welfare index'!B147 -> 0.032
A19: Wild rabbit meat | B19: ='Animal welfare index'!B152 -> 0.031305654 | C19: ='Animal welfare index'!B152 -> 0.031305654 | D19: ='Animal welfare index'!B153 -> 0.00069444444 | E19: ='Animal welfare index'!B154 -> 0.70880726 | F19: ='Animal welfare index'!B155 -> 0.636
A20: Mealworm | B20: ='Animal welfare index'!B160 -> 0.27459417 | C20: ='Animal welfare index'!B160 -> 0.27459417 | D20: ='Animal welfare index'!B161 -> 0.00069444444 | E20: ='Animal welfare index'!B162 -> 0.039541561 | F20: ='Animal welfare index'!B163 -> 100 | G20: *
A21: Honey from bees | B21: ='Animal welfare index'!B168 -> 0.3698657 | C21: ='Animal welfare index'!C168 -> 0.3698657 | D21: ='Animal welfare index'!B169 -> 0.00034722222 | E21: ='Animal welfare index'!B170 -> 0.088767767 | F21: ='Animal welfare index'!B171 -> 120 | G21: *
A22: Mussels | B22: ='Animal welfare index'!B176 -> 5.5325568 | C22: ='Animal welfare index'!B176 -> 5.5325568 | D22: ='Animal welfare index'!B177 -> 0.083333333 | E22: ='Animal welfare index'!B178 -> 0.049917806 | F22: ='Animal welfare index'!B179 -> 13.3 | G22: *
A23: Shrimps | B23: ='Animal welfare index'!B184 -> 7.6084608 | C23: ='Animal welfare index'!B184 -> 7.6084608 | D23: ='Animal welfare index'!B185 -> 0.041666667 | E23: ='Animal welfare index'!B186 -> 0.14608245 | F23: ='Animal welfare index'!B187 -> 12.5 | G23: *
A24: Wild octapus | B24: ='Animal welfare index'!B192 -> 0.70248667 | C24: ='Animal welfare index'!B192 -> 0.70248667 | D24: ='Animal welfare index'!B193 -> 0.14583333 | E24: ='Animal welfare index'!B194 -> 0.37054242 | F24: ='Animal welfare index'!B195 -> 0.13
A25: Horse meat | B25: ='Animal welfare index'!B200 -> 0.34637965 | C25: ='Animal welfare index'!B200 -> 0.34637965 | D25: ='Animal welfare index'!B201 -> 0.788 | E25: ='Animal welfare index'!B202 -> 0.87913616 | F25: ='Animal welfare index'!B203 -> 0.005

Sheet README
A2: Read me
A4: This file contains the calculations of the Animal Welfare Index.
A6: The index is calculated by multiplying:
A8: Ability | B8: A number between 0-1
A9: Level | B9: A number between 0.001-5 representing the
A10: No of animals | B10: No of animals needed to produce 1 kg of meat/fish/seafood/milk/egg
B11: This is "cut off" in both ends
B12: It can not be lower that 0.0001, otherwise the level and ability of dairy cows and some parents animals would not matter at all
B13: And for "small animals" (shrimp and mussels) it is divided by 10 not to get very high numbers for these
A14: And then multiplying by 100 to get a convenient no

Sheet Animal welfare index
A1: Animal welfare index | H1: Blue number are inputed here | K1: Black are calculated
B2: DK | C2: FR | D2: DE | E2: GR | F2: HU | G2: IE | H2: IT | I2: NL | J2: PL | K2: ES | L2: SE | M2: UK | N2: NZ | O2: Utopia | P2: Dystopia | Q2: Assumptions and comments: | R2: Source: | S2: fem kalvar per ko (livstidsproduktion) räknat från Gård&Djurhälsan, 2023 men det ska väl användas för beef parent cow
A3: beef suckler tot welfare index | B3: =B12+B4 -> 0.29560176 | C3: =C12+C4 -> 0.28068068 | D3: =D12+D4 -> 0.31780714 | E3: =E12+E4 -> 0.32250669 | F3: =F12+F4 -> 0.34083494 | G3: =G12+G4 -> 0.28690759 | H3: =H12+H4 -> 0.3851282 | I3: =I12+I4 -> 0.28596768 | ... M3: =M12+M4 -> 0.26681701 | O3: =O12+O4 -> 0.00033131845 | P3: =P12+P4 -> 1.6565922 | S3: Per suckler herd per yr??? | T3: No of animals | U3: Slaughtering weight | V3: Meat produced (bonefree weight)
A4: welfare index beef parent | B4: =B7*B6*B5*100 -> 0.028314795 | C4: =C7*C6*C5*100 -> 0.034639607 | D4: =D7*D6*D5*100 -> 0.032896857 | E4: =E7*E6*E5*100 -> 0.034757096 | F4: =F7*F6*F5*100 -> 0.03722436 | G4: =G7*G6*G5*100 -> 0.036754405 | H4: =H7*H6*H5*100 -> 0.037459338 | I4: =I7*I6*I5*100 -> 0.033954256 | ... M4: =M7*M6*M5*100 -> 0.035462029 | O4: =O7*O6*O5*100 -> 5.8744388e-05 | P4: =P7*P6*P5*100 -> 0.29372194 | S4: Suckler cows | T4: 1 | U4: 400 | V4: =T4*U4*0.7 -> 280 | W4: =T4/V6 -> 0.00066445183
A5: beef parent level | B5: =(2*(B8+B9+B11))+B10 -> 0.482 | C5: =(2*(C8+C9+C11))+C10 -> 0.58966667 | D5: =(2*(D8+D9+D11))+D10 -> 0.56 | E5: =(2*(E8+E9+E11))+E10 -> 0.59166667 | F5: =(2*(F8+F9+F11))+F10 -> 0.63366667 | G5: =(2*(G8+G9+G11))+G10 -> 0.62566667 | H5: =(2*(H8+H9+H11))+H10 -> 0.63766667 | I5: =(2*(I8+I9+I11))+I10 -> 0.578 | ... M5: =(2*(M8+M9+M11))+M10 -> 0.60366667 | O5: =(2*(O8+O9+O11))+O10 -> 0.001 | P5: =(2*(P8+P9+P11))+P10 -> 5 | S5: Young animals | T5: 5 | U5: 350 | V5: =T5*U5*0.7 -> 1225 | W5: =T5/V6 -> 0.0033222591
A6: beef parent ability | B6: =Ability!$B$5 -> 0.88410303 | C6: =Ability!$B$5 -> 0.88410303 | D6: =Ability!$B$5 -> 0.88410303 | E6: =Ability!$B$5 -> 0.88410303 | F6: =Ability!$B$5 -> 0.88410303 | G6: =Ability!$B$5 -> 0.88410303 | H6: =Ability!$B$5 -> 0.88410303 | I6: =Ability!$B$5 -> 0.88410303 | ... M6: =Ability!$B$5 -> 0.88410303 | O6: =Ability!$B$5 -> 0.88410303 | P6: =Ability!$B$5 -> 0.88410303 | Q6: Value for ruminats | S6: Sum meat | V6: =V4+V5 -> 1505 | W6: kg meat
A7: beef parent no per kg meat | B7: =$W$4 -> 0.00066445183 | C7: =$W$4 -> 0.00066445183 | D7: =$W$4 -> 0.00066445183 | E7: =$W$4 -> 0.00066445183 | F7: =$W$4 -> 0.00066445183 | G7: =$W$4 -> 0.00066445183 | H7: =$W$4 -> 0.00066445183 | I7: =$W$4 -> 0.00066445183 | ... M7: =$W$4 -> 0.00066445183 | O7: =$W$4 -> 0.00066445183 | P7: =$W$4 -> 0.00066445183 | Q7: Lotta - dödlighet dikor 2% i Ahlgren et al - ANVÄNDA???? | R7: Vi kan ta ett värde mittemellan de två referenserna. Men jag förstår inte var Ahlgren har fått 2% ifrån (otydlig hänvisning)
A8: beef parent mortality | B8: 0.03 | C8: 0.03 | D8: 0.03 | E8: 0.03 | F8: 0.03 | G8: 0.03 | H8: 0.03 | I8: 0.03 | J8: 0.03 | K8: 0.03 | L8: 0.03 | M8: 0.03 | O8: 0 | P8: 0.5 | Q8: Assumed 3% based on Ahlgren et al, 2022 (2%) and 60% of dairy cow mortality, based on Thomson et al, 2020 (4%) | R8: Assumption
A9: beef parent disease | B9: 0.04 | C9: 0.04 | D9: 0.04 | E9: 0.04 | F9: 0.04 | G9: 0.04 | H9: 0.04 | I9: 0.04 | J9: 0.04 | K9: 0.04 | L9: 0.04 | M9: 0.04 | O9: 0 | P9: 0.5 | Q9: No data found; assumed 25% of dairy cow disease | R9: Assumption | S9: Saknar källa. Mastit hos dikor 1,5% (Andersson, 2028) och 7,9% på mjölkkor (Växa 2023b) Gammal anonym källa säger 2% (slutrapport SLF troligen fr 2005)
A10: beef parent slaughter | B10: =Slaughtering!$C$6 -> 0.25 | C10: =Slaughtering!$E$6 -> 0.34166667 | D10: =Slaughtering!$G$6 -> 0.25 | E10: =Slaughtering!$I$6 -> 0.34166667 | F10: =Slaughtering!$K$6 -> 0.34166667 | G10: =Slaughtering!$M$6 -> 0.34166667 | H10: =Slaughtering!$O$6 -> 0.34166667 | I10: =Slaughtering!$Q$6 -> 0.25 | J10: =Slaughtering!$S$6 -> 0.34166667 | K10: =Slaughtering!$U$6 -> 0.34166667 | L10: =Slaughtering!$W$6 -> 0.25 | M10: =Slaughtering!$Y$6 -> 0.34166667 | O10: 0.001 | P10: 1 | R10: Tab "Slaughtering" | S10: Från Ahlgren et al (2022):
A11: beef parent space | B11: 0.046 | C11: 0.054 | D11: 0.085 | E11: 0.055 | F11: 0.076 | G11: 0.072 | H11: 0.078 | I11: 0.094 | J11: 0.122 | K11: 0.053 | L11: 0.072 | M11: 0.061 | O11: 0 | P11: 1 | Q11: Assuming all animals on pasture during the grazing season and free-range indoor during the stable season
A12: welfare index beef calves 24m suckler syst | B12: =B15*B14*B13*100 -> 0.26728696 | C12: =C15*C14*C13*100 -> 0.24604108 | D12: =D15*D14*D13*100 -> 0.28491028 | E12: =E15*E14*E13*100 -> 0.28774959 | F12: =F15*F14*F13*100 -> 0.30361058 | G12: =G15*G14*G13*100 -> 0.25015318 | H12: =H15*H14*H13*100 -> 0.34766887 | I12: =I15*I14*I13*100 -> 0.25201342 | ... M12: =M15*M14*M13*100 -> 0.23135498 | O12: =O15*O14*O13*100 -> 0.00027257406 | P12: =P15*P14*P13*100 -> 1.3628703
A13: beef calves 24m level | B13: =(2*(B16+B17+B19))+B18 -> 0.91 | C13: =(2*(C16+C17+C19))+C18 -> 0.83766667 | D13: =(2*(D16+D17+D19))+D18 -> 0.97 | E13: =(2*(E16+E17+E19))+E18 -> 0.97966667 | F13: =(2*(F16+F17+F19))+F18 -> 1.0336667 | G13: =(2*(G16+G17+G19))+G18 -> 0.85166667 | H13: =(2*(H16+H17+H19))+H18 -> 1.1836667 | I13: =(2*(I16+I17+I19))+I18 -> 0.858 | ... M13: =(2*(M16+M17+M19))+M18 -> 0.78766667 | O13: =(2*(O16+O17+O19))+O18 -> 0.001 | P13: =(2*(P16+P17+P19))+P18 -> 5
A14: beef calves 24m ability | B14: =Ability!$B$5 -> 0.88410303 | C14: =Ability!$B$5 -> 0.88410303 | D14: =Ability!$B$5 -> 0.88410303 | E14: =Ability!$B$5 -> 0.88410303 | F14: =Ability!$B$5 -> 0.88410303 | G14: =Ability!$B$5 -> 0.88410303 | H14: =Ability!$B$5 -> 0.88410303 | I14: =Ability!$B$5 -> 0.88410303 | ... M14: =Ability!$B$5 -> 0.88410303 | O14: =Ability!$B$6 -> 0.82044792 | P14: =Ability!$B$6 -> 0.82044792
A15: beef calves 24m no per kg meat | B15: =$W$5 -> 0.0033222591 | C15: =$W$5 -> 0.0033222591 | D15: =$W$5 -> 0.0033222591 | E15: =$W$5 -> 0.0033222591 | F15: =$W$5 -> 0.0033222591 | G15: =$W$5 -> 0.0033222591 | H15: =$W$5 -> 0.0033222591 | I15: =$W$5 -> 0.0033222591 | ... M15: =$W$5 -> 0.0033222591 | O15: =$W$5 -> 0.0033222591 | P15: =$W$5 -> 0.0033222591
A16: beef calves 24m mortality | B16: 0.042 | C16: 0.042 | D16: 0.042 | E16: 0.042 | F16: 0.042 | G16: 0.042 | H16: 0.042 | I16: 0.042 | J16: 0.042 | K16: 0.042 | L16: 0.042 | M16: 0.042 | O16: 0 | P16: 0.5 | Q16: Mortality of live born from birth to slaughter. Based on combination of Swedish data. Most calves die first week and in UK 4.4% of suckler calves died from day 1 to day 21 (AHDP, 2021) | R16: Jordbruksverket 2012; 2022;2023; | S16: 2,7+1,5=4,2. Kombination av Jordbruksverket 2023 (4,7 tot vid 6 mån) och Jordbruksverket 2022 (2,7 dikokalv och 6,0 mjölkkokalv, tot 4,7 vid 6 mån) och Jordbruksverket 2012 (1,5% under 6-24 mån, tabell 2.14)
A17: beef calves 24m disease | B17: 0.05 | C17: 0.05 | D17: 0.05 | E17: 0.05 | F17: 0.05 | G17: 0.05 | H17: 0.05 | I17: 0.05 | J17: 0.05 | K17: 0.05 | L17: 0.05 | M17: 0.05 | O17: 0 | P17: 0.5 | Q17: Lower disease and injury risk for beef than dairy calves, and for calves raised to 18m than for veal calves (Mandel et al, 2022). Assumed value set to 50% of the value for young dairy calves. | R17: Jordbruksverket 2012; 2022; 2023; Mandel et al, 2022
A18: beef calves 24m slaughter | B18: =Slaughtering!$C$6 -> 0.25 | C18: =Slaughtering!$E$6 -> 0.34166667 | D18: =Slaughtering!$G$6 -> 0.25 | E18: =Slaughtering!$I$6 -> 0.34166667 | F18: =Slaughtering!$K$6 -> 0.34166667 | G18: =Slaughtering!$M$6 -> 0.34166667 | H18: =Slaughtering!$O$6 -> 0.34166667 | I18: =Slaughtering!$Q$6 -> 0.25 | J18: =Slaughtering!$S$6 -> 0.34166667 | K18: =Slaughtering!$U$6 -> 0.34166667 | L18: =Slaughtering!$W$6 -> 0.25 | M18: =Slaughtering!$Y$6 -> 0.34166667 | O18: 0.001 | P18: 1 | R18: Tab "Slaughtering"
A19: beef calves 24m space | B19: 0.238 | C19: 0.156 | D19: 0.268 | E19: 0.227 | F19: 0.254 | G19: 0.163 | H19: 0.329 | I19: 0.212 | J19: 0.298 | K19: 0.119 | L19: 0.135 | M19: 0.131 | O19: 0 | P19: 1
A20: dairy calf 9m tot welfare index | B20: =B23*B22*B21*100 -> 0.3859387 | C20: =C23*C22*C21*100 -> 0.49604281 | D20: =D23*D22*D21*100 -> 0.45091818 | E20: =E23*E22*E21*100 -> 0.49604281 | F20: =F23*F22*F21*100 -> 0.49604281 | G20: =G23*G22*G21*100 -> 0.49604281 | H20: =H23*H22*H21*100 -> 0.49604281 | I20: =I23*I22*I21*100 -> 0.45091818 | ... M20: =M23*M22*M21*100 -> 0.46749122 | O20: =O23*O22*O21*100 -> 0.00049226875 | P20: =P23*P22*P21*100 -> 2.4613438 | Q20: Parent (cow) is not included; all welfare isssues are allocated to the dairy production
A21: dairy calf 9m level | B21: =(2*(B24+B25+B27))+B26 -> 0.784 | C21: =(2*(C24+C25+C27))+C26 -> 1.0076667 | D21: =(2*(D24+D25+D27))+D26 -> 0.916 | E21: =(2*(E24+E25+E27))+E26 -> 1.0076667 | F21: =(2*(F24+F25+F27))+F26 -> 1.0076667 | G21: =(2*(G24+G25+G27))+G26 -> 1.0076667 | H21: =(2*(H24+H25+H27))+H26 -> 1.0076667 | I21: =(2*(I24+I25+I27))+I26 -> 0.916 | ... M21: =(2*(M24+M25+M27))+M26 -> 0.94966667 | O21: =(2*(O24+O25+O27))+O26 -> 0.001 | P21: =(2*(P24+P25+P27))+P26 -> 5
A22: dairy calf 9m ability | B22: =Ability!$B$6 -> 0.82044792 | C22: =Ability!$B$6 -> 0.82044792 | D22: =Ability!$B$6 -> 0.82044792 | E22: =Ability!$B$6 -> 0.82044792 | F22: =Ability!$B$6 -> 0.82044792 | G22: =Ability!$B$6 -> 0.82044792 | H22: =Ability!$B$6 -> 0.82044792 | I22: =Ability!$B$6 -> 0.82044792 | ... M22: =Ability!$B$6 -> 0.82044792 | O22: =Ability!$B$6 -> 0.82044792 | P22: =Ability!$B$6 -> 0.82044792 | Q22: Var kommer slaktvikten nedan ifrån?
A23: dairy calf 9m no per kg meat | B23: 0.006 | C23: 0.006 | D23: 0.006 | E23: 0.006 | F23: 0.006 | G23: 0.006 | H23: 0.006 | I23: 0.006 | J23: 0.006 | K23: 0.006 | L23: 0.006 | M23: 0.006 | O23: 0.006 | P23: 0.006 | Q23: Här ska vi ha 1/(slaktvikt (240 kg)*0.7), vi antar bara mjölkras och all impact för moderdjuren hamnar för mjölken
A24: dairy calf 9m mortality | B24: 0.065 | C24: 0.065 | D24: 0.065 | E24: 0.065 | F24: 0.065 | G24: 0.065 | H24: 0.065 | I24: 0.065 | J24: 0.065 | K24: 0.065 | L24: 0.065 | M24: 0.065 | O24: 0 | P24: 0.5 | Q24: Mortality of liveborn from birth to slaughter. Based on combination of Swedish data | R24: Jordbruksverket 2012; 2022; 2023; | S24: Kombination av Jordbruksverket 2023 (4,7 tot vid 6 mån) och Jordbruksverket 2022 (2,7 dikokalv och 6,0 mjölkkokalv, tot 4,7 vid 6 mån) och Jordbruksverket 2012 (0,5% under 6-9 mån, tabell 2.14)
A25: dairy calf 9m disease | B25: 0.1 | C25: 0.1 | D25: 0.1 | E25: 0.1 | F25: 0.1 | G25: 0.1 | H25: 0.1 | I25: 0.1 | J25: 0.1 | K25: 0.1 | L25: 0.1 | M25: 0.1 | O25: 0 | P25: 0.5 | Q25: Data are scarce. 10% is an assumed value within a range from 4% (0-15m, calculated from Jordbruksverket, 2023b) to 23% (0-3m, Svensson et al, 2003). | R25: Jordbruksverket 2023b, Svensson et al, 2003
A26: dairy calf 9m slaughter | B26: =Slaughtering!$C$6 -> 0.25 | C26: =Slaughtering!$E$6 -> 0.34166667 | D26: =Slaughtering!$G$6 -> 0.25 | E26: =Slaughtering!$I$6 -> 0.34166667 | F26: =Slaughtering!$K$6 -> 0.34166667 | G26: =Slaughtering!$M$6 -> 0.34166667 | H26: =Slaughtering!$O$6 -> 0.34166667 | I26: =Slaughtering!$Q$6 -> 0.25 | J26: =Slaughtering!$S$6 -> 0.34166667 | K26: =Slaughtering!$U$6 -> 0.34166667 | L26: =Slaughtering!$W$6 -> 0.25 | M26: =Slaughtering!$Y$6 -> 0.34166667 | O26: 0.001 | P26: 1 | R26: Tab "Slaughtering"
A27: dairy calf 9m space | B27: 0.102 | C27: 0.168 | D27: 0.168 | E27: 0.168 | F27: 0.168 | G27: 0.168 | H27: 0.168 | I27: 0.168 | J27: 0.168 | K27: 0.168 | L27: 0.163 | M27: 0.139 | O27: 0 | P27: 1 | Q27: Assuming all animals indoors all year
A28: dairy calf 24m tot welfare index | B28: =B31*B30*B29*100 -> 0.20061451 | C28: =C31*C30*C29*100 -> 0.24631609 | D28: =D31*D30*D29*100 -> 0.28238673 | E28: =E31*E30*E29*100 -> 0.28502161 | F28: =F31*F30*F29*100 -> 0.29974061 | G28: =G31*G30*G29*100 -> 0.25013213 | H28: =H31*H30*H29*100 -> 0.34062672 | I28: =I31*I30*I29*100 -> 0.25185843 | ... M28: =M31*M30*M29*100 -> 0.23268739 | O28: =O31*O30*O29*100 -> 0.00027257406 | P28: =P31*P30*P29*100 -> 1.3628703 | Q28: Parent (cow) is not included; all welfare isssues are allocated to the dairy production
A29: dairy calves 24m level | B29: =(2*(B32+B33+B35))+B34 -> 0.736 | C29: =(2*(C32+C33+C35))+C34 -> 0.90366667 | D29: =(2*(D32+D33+D35))+D34 -> 1.036 | E29: =(2*(E32+E33+E35))+E34 -> 1.0456667 | F29: =(2*(F32+F33+F35))+F34 -> 1.0996667 | G29: =(2*(G32+G33+G35))+G34 -> 0.91766667 | H29: =(2*(H32+H33+H35))+H34 -> 1.2496667 | I29: =(2*(I32+I33+I35))+I34 -> 0.924 | ... M29: =(2*(M32+M33+M35))+M34 -> 0.85366667 | O29: =(2*(O32+O33+O35))+O34 -> 0.001 | P29: =(2*(P32+P33+P35))+P34 -> 5
A30: dairy calves 24m ability | B30: =Ability!$B$6 -> 0.82044792 | C30: =Ability!$B$6 -> 0.82044792 | D30: =Ability!$B$6 -> 0.82044792 | E30: =Ability!$B$6 -> 0.82044792 | F30: =Ability!$B$6 -> 0.82044792 | G30: =Ability!$B$6 -> 0.82044792 | H30: =Ability!$B$6 -> 0.82044792 | I30: =Ability!$B$6 -> 0.82044792 | ... M30: =Ability!$B$6 -> 0.82044792 | O30: =Ability!$B$6 -> 0.82044792 | P30: =Ability!$B$6 -> 0.82044792 | Q30: Är rad 33 rätt? Det är inte 1/slaktvikt utan tagit från tabellen ovan, men borde det inte vara samma sak här som för 9m??
A31: dairy calves 24m no per kg meat | B31: =$W$5 -> 0.0033222591 | C31: =$W$5 -> 0.0033222591 | D31: =$W$5 -> 0.0033222591 | E31: =$W$5 -> 0.0033222591 | F31: =$W$5 -> 0.0033222591 | G31: =$W$5 -> 0.0033222591 | H31: =$W$5 -> 0.0033222591 | I31: =$W$5 -> 0.0033222591 | ... M31: =$W$5 -> 0.0033222591 | O31: =$W$5 -> 0.0033222591 | P31: =$W$5 -> 0.0033222591 | Q31: Här ska vi ha 1/(slaktvikt*0.7), vi antar bara mjölkras och all impact för moderdjuren hamnar för mjölken
A32: dairy calves 24m mortality | B32: 0.075 | C32: 0.075 | D32: 0.075 | E32: 0.075 | F32: 0.075 | G32: 0.075 | H32: 0.075 | I32: 0.075 | J32: 0.075 | K32: 0.075 | L32: 0.075 | M32: 0.075 | O32: 0 | P32: 0.5 | Q32: Mortality of liveborn from birth to slaughter. Based on combination of Swedish data | R32: Jordbruksverket 2012; 2022; 2023; | S32: Kombination av Jordbruksverket 2023 (4,7 tot vid 6 mån) och Jordbruksverket 2022 (2,7 dikokalv och 6,0 mjölkkokalv, tot 4,7 vid 6 mån) och Jordbruksverket 2012 (1,5% under 6-24 mån, tabell 2.14)
A33: dairy calves 24m disease | B33: 0.05 | C33: 0.05 | D33: 0.05 | E33: 0.05 | F33: 0.05 | G33: 0.05 | H33: 0.05 | I33: 0.05 | J33: 0.05 | K33: 0.05 | L33: 0.05 | M33: 0.05 | O33: 0 | P33: 0.5 | Q33: Lower disease and injury risk for beef than dairy calves, and for calves raised to 18m than for veal calves (Mandel et al, 2022). Assumed value set to 50% of the value for young dairy calves. | R33: Jordbruksverket 2023b, Svensson et al, 2003
A34: dairy calves 24m slaughter | B34: =Slaughtering!$C$6 -> 0.25 | C34: =Slaughtering!$E$6 -> 0.34166667 | D34: =Slaughtering!$G$6 -> 0.25 | E34: =Slaughtering!$I$6 -> 0.34166667 | F34: =Slaughtering!$K$6 -> 0.34166667 | G34: =Slaughtering!$M$6 -> 0.34166667 | H34: =Slaughtering!$O$6 -> 0.34166667 | I34: =Slaughtering!$Q$6 -> 0.25 | J34: =Slaughtering!$S$6 -> 0.34166667 | K34: =Slaughtering!$U$6 -> 0.34166667 | L34: =Slaughtering!$W$6 -> 0.25 | M34: =Slaughtering!$Y$6 -> 0.34166667 | O34: 0.001 | P34: 1 | R34: Tab "Slaughtering"
A35: dairy calves 24m space | B35: 0.118 | C35: 0.156 | D35: 0.268 | E35: 0.227 | F35: 0.254 | G35: 0.163 | H35: 0.329 | I35: 0.212 | J35: 0.298 | K35: 0.119 | L35: 0.135 | M35: 0.131 | O35: 0 | P35: 1
A36: dairy cow welfare index | B36: =B39*B38*B37*100 -> 0.0085404353 | C36: =C39*C38*C37*100 -> 0.0083960318 | D36: =D39*D38*D37*100 -> 0.0098489078 | E36: =E39*E38*E37*100 -> 0.012851911 | F36: =F39*F38*F37*100 -> 0.013134824 | G36: =G39*G38*G37*100 -> 0.0082192112 | H36: =H39*H38*H37*100 -> 0.011189797 | I36: =I39*I38*I37*100 -> 0.0086818918 | ... L36: =L39*L38*L37*100 -> 0.0080983838 | O36: =O39*O38*O37*100 -> 8.8410303e-06 | P36: =P39*P38*P37*100 -> 0.044205152 | Q36: Dairy cow space includes the cow's whole life. Disease and mortality in % affected cows per year. | R36: kan inte sudda här? | S36: Vad menas med detta? Förenklat genom att inte ha med en beräkning för kvigan. Sjukdom o dödlighet gäller vuxna kor per år
A37: dairy cow level | B37: =(2*(B40+B41+B43))+B42 -> 0.966 | C37: =(2*(C40+C41+C43))+C42 -> 0.94966667 | D37: =(2*(D40+D41+D43))+D42 -> 1.114 | E37: =(2*(E40+E41+E43))+E42 -> 1.4536667 | F37: =(2*(F40+F41+F43))+F42 -> 1.4856667 | G37: =(2*(G40+G41+G43))+G42 -> 0.92966667 | H37: =(2*(H40+H41+H43))+H42 -> 1.2656667 | I37: =(2*(I40+I41+I43))+I42 -> 0.982 | ... L37: =(2*(L40+L41+L43))+L42 -> 0.916 | O37: =(2*(O40+O41+O43))+O42 -> 0.001 | P37: =(2*(P40+P41+P43))+P42 -> 5
A38: dairy cow ability | B38: =Ability!$B$5 -> 0.88410303 | C38: =Ability!$B$5 -> 0.88410303 | D38: =Ability!$B$5 -> 0.88410303 | E38: =Ability!$B$5 -> 0.88410303 | F38: =Ability!$B$5 -> 0.88410303 | G38: =Ability!$B$5 -> 0.88410303 | H38: =Ability!$B$5 -> 0.88410303 | I38: =Ability!$B$5 -> 0.88410303 | ... L38: =Ability!$B$5 -> 0.88410303 | O38: =Ability!$B$5 -> 0.88410303 | P38: =Ability!$B$5 -> 0.88410303 | S38: See också Ingrids artikel: | T38: https://www.frontiersin.org/articles/10.3389/fsufs.2023.1171865/full
A39: dairy cows no per kg milk | B39: 0.0001 | C39: 0.0001 | D39: 0.0001 | E39: 0.0001 | F39: 0.0001 | G39: 0.0001 | H39: 0.0001 | I39: 0.0001 | J39: 0.0001 | K39: 0.0001 | L39: 0.0001 | O39: 0.0001 | P39: 0.0001 | Q39: 1/life time milk production, but here adjusted to 0.0001 | R39: Comes from Dairy.xlsx, tab Parameters, country specific
A40: dairy cows mortality | B40: 0.06 | C40: 0.06 | D40: 0.06 | E40: 0.06 | F40: 0.06 | G40: 0.06 | H40: 0.06 | I40: 0.06 | J40: 0.06 | K40: 0.06 | L40: 0.06 | O40: 0 | P40: 0.5 | Q40: Mortality per year | R40: Växa 2023b | S40: figur 4
...

Sheet Europe Utopia
A2: Averge beef Europe
B5: Shares_dairy_cows | C5: Shares_suckler | D5: Shares_dairy24m | E5: Shares_dairy9m
A6: Shares | B6: 0.2324815 | C6: 0.31773733 | D6: 0.30209765 | E6: 0.14768352 | G6: Average of SAFAD countries, calculated from Shares beef.xlsx
A7: AW | B7: 0 | C7: ='Animal welfare index'!O3 -> 0.00033131845 | D7: ='Animal welfare index'!O28 -> 0.00027257406 | E7: ='Animal welfare index'!O20 -> 0.00049226875 | G7: Utopia
A9: Average | B9: =SUMPRODUCT(B6:E6,B7:E7) -> 0.0002603162

Sheet Algorithm - only testing
G1: Weights
A2: Test av olika algoritmer | G2: Level | H2: 1
G3: Ability | H3: 1
G4: No of animals | H4: 0.0001
A5: Vårt index som vi har beslutat | B5: Kan anta värden mellan 0.001 och 5 teoretisk
B6: Level | C6: Ability | D6: No of anim | F6: Mult | G6: Add
A7: Wild ruminant | B7: 0.001 | C7: 1 | D7: 0.068 | F7: =(B7*C7*D7)*10 -> 0.00068 | G7: =B7+C7+D7 -> 1.069 | H7: Kycklingen kan få ett mkt lägre index med bättre skötsel tex om rastgård, låg sjukdom, låg dödlighet och snabb slakt
A8: Milk | B8: 0.966 | C8: 0.94680851 | D8: 0.001 | F8: =(B8*C8*D8)*10 -> 0.0091461702 | G8: =B8+C8+D8 -> 1.9138085 | H8: Att de är många är positivt för en förbättring i skötsel får stort genomslag
A9: Meat from suckler herds | B9: 0.91 | C9: 0.87765957 | D9: 0.00332 | F9: =(B9*C9*D9)*10 -> 0.026515851 | G9: =B9+C9+D9 -> 1.7909796
A10: Pig | B10: 2.276 | C10: 0.94148936 | D10: 0.018 | F10: =(B10*C10*D10)*10 -> 0.38570936 | G10: =B10+C10+D10 -> 3.2354894
A11: Chicken | B11: 1.7 | C11: 0.57978723 | D11: 0.75 | F11: =(B11*C11*D11)*10 -> 7.3922872 | G11: =B11+C11+D11 -> 3.0297872
A12: Shrimp | B12: 0.042 | C12: 0.15425532 | D12: =125/10 -> 12.5 | F12: =(B12*C12*D12)*10 -> 0.80984043 | G12: =B12+C12+D12 -> 12.696255
A14: Allt normerade
B15: Level | C15: Ability | D15: No of anim | F15: Mult | G15: Add | H15: Add with | I15: (level+ability)*no of animal | N15: Mult | O15: Add
A16: Wild ruminant | B16: =B7/5 -> 0.0002 | C16: 1 | D16: =0.068/0.0001 -> 680 | F16: =B16*C16*D16*1000 -> 136 | G16: =B16+C16+D16 -> 681.0002 | H16: =B16*$H$2+C16*$H$3+D16*$H$4 -> 1.0682 | I16: =(B16+C16)*D16 -> 680.136 | N16: =B16*C16*L16 -> 0 | O16: =B16+C16+L16 -> 1.0002 | P16: Wild ruminant
A17: Milk | B17: =B8/5 -> 0.1932 | C17: 0.94680851 | D17: 1 | F17: =B17*C17*D17*1000 -> 182.9234 | G17: =B17+C17+D17 -> 2.1400085 | H17: =B17*$H$2+C17*$H$3+D17*$H$4 -> 1.1401085 | I17: =(B17+C17)*D17 -> 1.1400085 | N17: =B17*C17*L17 -> 0 | O17: =B17+C17+L17 -> 1.1400085 | P17: Milk
A18: Meat from suckler herds | B18: =B9/5 -> 0.182 | C18: 0.87765957 | D18: =0.00332/0.0001 -> 33.2 | F18: =B18*C18*D18*1000 -> 5303.1702 | G18: =B18+C18+D18 -> 34.25966 | H18: =B18*$H$2+C18*$H$3+D18*$H$4 -> 1.0629796 | I18: =(B18+C18)*D18 -> 35.180698 | N18: =B18*C18*L18 -> 0 | O18: =B18+C18+L18 -> 1.0596596 | P18: Meat from suckler herds
A19: Pig | B19: =B10/5 -> 0.4552 | C19: 0.94148936 | D19: =0.018/0.0001 -> 180 | F19: =B19*C19*D19*1000 -> 77141.872 | G19: =B19+C19+D19 -> 181.39669 | H19: =B19*$H$2+C19*$H$3+D19*$H$4 -> 1.4146894 | I19: =(B19+C19)*D19 -> 251.40409 | N19: =B19*C19*L19 -> 0 | O19: =B19+C19+L19 -> 1.3966894 | P19: Pig
A20: Chicken | B20: =B11/5 -> 0.34 | C20: 0.57978723 | D20: =0.75/0.0001 -> 7500 | F20: =B20*C20*D20*1000 -> 1478457.4 | G20: =B20+C20+D20 -> 7500.9198 | H20: =B20*$H$2+C20*$H$3+D20*$H$4 -> 1.6697872 | I20: =(B20+C20)*D20 -> 6898.4043 | N20: =B20*C20*L20 -> 0 | O20: =B20+C20+L20 -> 0.91978723 | P20: Chicken
A21: Shrimp | B21: =B12/5 -> 0.0084 | C21: 0.15425532 | D21: =125/0.001 -> 125000 | F21: =B21*C21*D21*1000 -> 161968.09 | G21: =B21+C21+D21 -> 125000.16 | H21: =B21*$H$2+C21*$H$3+D21*$H$4 -> 12.662655 | I21: =(B21+C21)*D21 -> 20331.915 | N21: =B21*C21*L21 -> 0 | O21: =B21+C21+L21 -> 0.16265532 | P21: Shrimp
F23: Vid multiplikation blir det stora skillnader, level förr
A24: Animal welfare index
H25: nuvarande med liv/1
B26: weight=4 | C26: weight=1 | D26: weight=test | F26: beef suckler | G26: =D27 -> 0.29242437 | H26: 0.056
A27: beef suckler tot welfare index | B27: =B36+B28 -> 0.069383019 | C27: =C36+C28 -> 0.27753208 | D27: =D36+D28 -> 0.29242437 | F27: dairy calf 9 m | G27: =D44 -> 0.3859387
A28: welfare index beef parent | B28: =((B31/4)*B30*B29)*100 -> 0.0073724206 | C28: =((C31/1)*C30*C29)*100 -> 0.029489683 | D28: =((D31/1)*D30*D29)*100 -> 0.044381972 | F28: dairy calf 24m | G28: =D52 -> 0.20061451
A29: beef parent level | B29: =(2*(B32+B33+B35))+B34 -> 0.502 | C29: =(2*(C32+C33+C35))+C34 -> 0.502 | D29: =(2*(D32+D33+D35))+D34 -> 0.502 | F29: dairy cow milk | G29: =D60 -> 0.085404353 | H29: 0.00174
A30: beef parent ability | B30: =Ability!$B$5 -> 0.88410303 | C30: =Ability!$B$5 -> 0.88410303 | D30: =Ability!$B$5 -> 0.88410303 | F30: laying hen egg | G30: =D77 -> 6.5808693
A31: beef parent no per kg meat | B31: 0.00066445183 | C31: 0.00066445183 | D31: 0.001 | E31: sedan satt till 0,0001 | F31: chicken | G31: =D85 -> 35.512248 | H31: även kortat slaktprocess 2h
A32: beef parent mortality | B32: 0.04 | C32: 0.04 | D32: 0.04 | F32: pig | G32: =D102 -> 3.7765336 | H32: 0.757
A33: beef parent disease | B33: 0.04 | C33: 0.04 | D33: 0.04 | F33: sheep | G33: =D119 -> 3.0307415
A34: beef parent slaughter | B34: =Slaughtering!$C$6 -> 0.25 | C34: =Slaughtering!$C$6 -> 0.25 | D34: =Slaughtering!$C$6 -> 0.25 | F34: rabbit | G34: =D136 -> 35.007303
A35: beef parent space | B35: 0.046 | C35: 0.046 | D35: 0.046 | F35: salmon | G35: =D144 -> 6.8676114
A36: welfare index beef calves 24m suckler syst | B36: =((B39/4)*B38*B37)*100 -> 0.062010598 | C36: =((C39/1)*C38*C37)*100 -> 0.24804239 | D36: =((D39/1)*D38*D37)*100 -> 0.24804239 | F36: wild fish | G36: =D152 -> 1.8647869
A37: beef calves 24m level | B37: =(2*(B40+B41+B43))+B42 -> 0.91 | C37: =(2*(C40+C41+C43))+C42 -> 0.91 | D37: =(2*(D40+D41+D43))+D42 -> 0.91 | F37: wild ruminant | G37: =D160 -> 0.0044035906
A38: beef calves 24m ability | B38: =Ability!$B$6 -> 0.82044792 | C38: =Ability!$B$6 -> 0.82044792 | D38: =Ability!$B$6 -> 0.82044792 | F38: wild boar | G38: =D168 -> 0.00044740889
A39: beef calves 24m no per kg meat | B39: 0.0033222591 | C39: 0.0033222591 | D39: 0.0033222591 | F39: wild rabbit | G39: =D176 -> 0.0031514462
A40: beef calves 24m mortality | B40: 0.042 | C40: 0.042 | D40: 0.042 | F40: meal worm | G40: =D184 -> 2.7459417 | H40: =C184 -> 27.459417
A41: beef calves 24m disease | B41: 0.05 | C41: 0.05 | D41: 0.05 | F41: honey bee | G41: =D192 -> 3.698657 | H41: =C192 -> 36.98657
A42: beef calves 24m slaughter | B42: =Slaughtering!$C$6 -> 0.25 | C42: =Slaughtering!$C$6 -> 0.25 | D42: =Slaughtering!$C$6 -> 0.25 | F42: mussels | G42: =D200 -> 5.5325568 | H42: =C200 -> 55.325568
...

Sheet Ability
A2: Ability
A4: Species | B4: Ability score, norm | C4: Non-normalised
A5: Beef parents/cows | B5: =C5/$C$18 -> 0.88410303 | C5: 0.178
A6: Beef calves | B6: =C6/$C$18 -> 0.82044792 | C6: 0.16518406
A7: Male chick 10m | B7: =C7/$C$18 -> 0.25562743 | C7: 0.051466492
A8: Laying hens | B8: =C8/$C$18 -> 0.58534078 | C8: 0.117849
A9: Chicken | B9: =C9/$C$18 -> 0.54320828 | C9: 0.1093663
A10: Pigs, slaughtering | B10: =C10/$C$18 -> 0.87981166 | C10: 0.177136
A11: Pigs, parents/sows | B11: =C11/$C$18 -> 0.94805646 | C11: 0.190876
A12: Sheep/goat, lamb | B12: =C12/$C$18 -> 0.82044792 | C12: 0.16518406
A13: Sheep/goat, parents | B13: =C13/$C$18 -> 0.88410303 | C13: 0.178
A14: Rabbit | B14: =C14/$C$18 -> 0.67196797 | C14: 0.13529
A15: Salmon, farmed | B15: =C15/$C$18 -> 0.30307199 | C15: 0.061018697
A16: Wild fish | B16: =C16/$C$18 -> 0.31967775 | C16: 0.064362
... A21: Honey bees | B21: =C21/$C$18 -> 0.088767767 | C21: 0.01787197
A22: Mussels | B22: =C22/$C$18 -> 0.049917806 | C22: 0.010050152 | D22: Musslor har ett högre värde än mjölmask!
A23: Shrimps | B23: =C23/$C$18 -> 0.14608245 | C23: 0.029411364 | D23: Ja, och vi har nog egentligen ingen aning...
A24: Octopus, wild | B24: =C24/$C$18 -> 0.37054242 | C24: 0.074602788
A25: Horse | B25: =C25/$C$18 -> 0.87913616 | C25: 0.177

Sheet Slaughtering
A2: Slaughtering
A4: Slaughter process duration in hours and relative value for slaughter | B4: DK** | C4: DKrel | D4: FR | E4: FRrel | F4: DE** | G4: DErel | H4: GR | I4: GRrel | J4: HU | K4: HUrel | L4: IE | M4: IErel | N4: IT | O4: ITrel | P4: NL** | Q4: NLrel | R4: PL | S4: PLrel | T4: ES | U4: ESrel | V4: SE** | W4: SErel | X4: UK | Y4: UKrel | Z4: NZ | AA4: NZrel
A5: Horse | B5: 6 | C5: =B5/24 -> 0.25 | D5: 11.04 | E5: =D5/24 -> 0.46 | F5: 6 | G5: =F5/24 -> 0.25 | H5: 11.04 | I5: =H5/24 -> 0.46 | J5: 11.04 | K5: =J5/24 -> 0.46 | L5: 11.04 | M5: =L5/24 -> 0.46 | N5: 11.04 | O5: =N5/24 -> 0.46 | P5: 6 | Q5: =P5/24 -> 0.25 | R5: 11.04 | S5: =R5/24 -> 0.46 | T5: 11.04 | U5: =T5/24 -> 0.46 | V5: 6 | W5: =V5/24 -> 0.25
A6: Cattle | B6: 6 | C6: =B6/24 -> 0.25 | D6: 8.2 | E6: =D6/24 -> 0.34166667 | F6: 6 | G6: =F6/24 -> 0.25 | H6: 8.2 | I6: =H6/24 -> 0.34166667 | J6: 8.2 | K6: =J6/24 -> 0.34166667 | L6: 8.2 | M6: =L6/24 -> 0.34166667 | N6: 8.2 | O6: =N6/24 -> 0.34166667 | P6: 6 | Q6: =P6/24 -> 0.25 | R6: 8.2 | S6: =R6/24 -> 0.34166667 | T6: 8.2 | U6: =T6/24 -> 0.34166667 | V6: 6 | W6: =V6/24 -> 0.25 | X6: 8.2 | Y6: =X6/24 -> 0.34166667
