Workbook

Sheet Pigs timeseries
A3: Pigs
B4: 2010 | C4: 2011 | D4: 2012 | E4: 2013 | F4: 2014 | G4: 2015 | H4: 2016 | I4: 2017 | J4: 2018 | K4: 2019 | L4: 2020 | M4: 2021 | N4: 2022
A5: Austria | B5: ='2010'!W7 -> 92.074579 | C5: ='2011'!W7 -> 79.70935 | D5: ='2012'!W7 -> 80.568754 | E5: ='2013'!W7 -> 84.195367 | F5: ='2014'!W7 -> 83.207589 | G5: ='2015'!W7 -> 75.047204 | H5: ='2016'!W7 -> 68.518731 | I5: ='2017'!W7 -> 69.655733 | J5: ='2018'!W7 -> 75.387708 | K5: ='2019'!W7 -> 64.060761 | L5: ='2020'!W7 -> 69.489649 | M5: ='2021'!W7 -> 62.038097 | N5: ='2022'!W7 -> 55.195005
A6: Belgium | B6: ='2010'!W8 -> 230.5286 | C6: ='2011'!W8 -> 224.41766 | D6: ='2012'!W8 -> 208.42826 | E6: ='2013'!W8 -> 198.9799 | F6: ='2014'!W8 -> 202.17093 | G6: ='2015'!W8 -> 196.11577 | H6: ='2016'!W8 -> 185.08748 | I6: ='2017'!W8 -> 175.87159 | J6: ='2018'!W8 -> 152.40665 | K6: ='2019'!W8 -> 137.50247 | L6: ='2020'!W8 -> 140.97061 | M6: ='2021'!W8 -> 128.7558 | N6: ='2022'!W8 -> 100.06434
A7: Bulgaria | B7: ='2010'!W9 -> na | C7: ='2011'!W9 -> 191.90831 | D7: ='2012'!W9 -> 203.66134 | E7: ='2013'!W9 -> 238.77357 | F7: ='2014'!W9 -> 168.69567 | G7: ='2015'!W9 -> 235.24498 | H7: ='2016'!W9 -> 292.39292 | I7: ='2017'!W9 -> 241.41424 | J7: ='2018'!W9 -> 217.22629 | K7: ='2019'!W9 -> 204.14829 | L7: ='2020'!W9 -> 224.5409 | M7: ='2021'!W9 -> 222.75513 | N7: ='2022'!W9 -> 180.22729
A8: Croatia | B8: ='2010'!W10 -> na | C8: ='2011'!W10 -> na | D8: ='2012'!W10 -> na | E8: ='2013'!W10 -> na | F8: ='2014'!W10 -> 172.20973 | G8: ='2015'!W10 -> 149.75141 | H8: ='2016'!W10 -> 136.00023 | I8: ='2017'!W10 -> 110.97546 | J8: ='2018'!W10 -> 115.51593 | K8: ='2019'!W10 -> 101.75112 | L8: ='2020'!W10 -> 112.37541 | M8: ='2021'!W10 -> 100.81195 | N8: ='2022'!W10 -> 91.643486
A9: Cyprus | B9: ='2010'!W11 -> na | C9: ='2011'!W11 -> 529.60942 | D9: ='2012'!W11 -> 489.51071 | E9: ='2013'!W11 -> 540.13384 | F9: ='2014'!W11 -> 510.53495 | G9: ='2015'!W11 -> 563.95053 | H9: ='2016'!W11 -> 558.88912 | I9: ='2017'!W11 -> 542.04115 | J9: ='2018'!W11 -> 636.72267 | K9: ='2019'!W11 -> 566.99856 | L9: ='2020'!W11 -> 564.19293 | M9: ='2021'!W11 -> 492.72755 | N9: ='2022'!W11 -> 417.78279
A10: Czech Republic | B10: ='2010'!W12 -> 112.75634 | C10: ='2011'!W12 -> 103.8339 | D10: ='2012'!W12 -> 97.576021 | E10: ='2013'!W12 -> 103.51946 | F10: ='2014'!W12 -> 102.85525 | G10: ='2015'!W12 -> 90.175048 | H10: ='2016'!W12 -> 80.457089 | I10: ='2017'!W12 -> 84.010275 | J10: ='2018'!W12 -> 76.211326 | K10: ='2019'!W12 -> 72.529623 | L10: ='2020'!W12 -> 75.62084 | M10: ='2021'!W12 -> 66.845636 | N10: ='2022'!W12 -> 62.752327
A11: Denmark | B11: ='2010'!W13 -> 54.74162 | C11: ='2011'!W13 -> 48.971177 | D11: ='2012'!W13 -> 50.594641 | E11: ='2013'!W13 -> 51.855361 | F11: ='2014'!W13 -> 51.193939 | G11: ='2015'!W13 -> 48.644585 | H11: ='2016'!W13 -> 47.174063 | I11: ='2017'!W13 -> 45.478569 | J11: ='2018'!W13 -> 44.021035 | K11: ='2019'!W13 -> 43.404351 | L11: ='2020'!W13 -> 43.363948 | M11: ='2021'!W13 -> 38.71657 | N11: ='2022'!W13 -> 39.741335
A12: Estonia | B12: ='2010'!W14 -> 110.57772 | C12: ='2011'!W14 -> 110.5596 | D12: ='2012'!W14 -> 95.054745 | E12: ='2013'!W14 -> 103.6142 | F12: ='2014'!W14 -> 114.68219 | G12: ='2015'!W14 -> 98.15207 | H12: ='2016'!W14 -> 98.723424 | I12: ='2017'!W14 -> 87.220574 | J12: ='2018'!W14 -> 81.066557 | K12: ='2019'!W14 -> 81.325821 | L12: ='2020'!W14 -> 74.179542 | M12: ='2021'!W14 -> 70.145807 | N12: ='2022'!W14 -> 69.906445
A13: Finland | B13: ='2010'!W15 -> 33.747886 | C13: ='2011'!W15 -> 32.736631 | D13: ='2012'!W15 -> 33.104703 | E13: ='2013'!W15 -> 33.996701 | F13: ='2014'!W15 -> 34.327592 | G13: ='2015'!W15 -> 31.32344 | H13: ='2016'!W15 -> 28.459443 | I13: ='2017'!W15 -> 30.113531 | J13: ='2018'!W15 -> 29.449277 | K13: ='2019'!W15 -> 30.827209 | L13: ='2020'!W15 -> 25.983588 | M13: ='2021'!W15 -> 27.151577 | N13: ='2022'!W15 -> 23.948906
A14: France | B14: ='2010'!W16 -> 197.74156 | C14: ='2011'!W16 -> 167.27636 | D14: ='2012'!W16 -> 148.03668 | E14: ='2013'!W16 -> 137.47995 | F14: ='2014'!W16 -> 154.2295 | G14: ='2015'!W16 -> 101.43546 | H14: ='2016'!W16 -> 105.31049 | I14: ='2017'!W16 -> 100.82622 | J14: ='2018'!W16 -> 95.688898 | K14: ='2019'!W16 -> 86.822953 | L14: ='2020'!W16 -> 84.529064 | M14: ='2021'!W16 -> 76.905171 | N14: ='2022'!W16 -> 58.221092
A15: Germany | B15: ='2010'!W17 -> na | C15: ='2011'!W17 -> 292.27862 | D15: ='2012'!W17 -> 282.25046 | E15: ='2013'!W17 -> 248.60462 | F15: ='2014'!W17 -> 205.81884 | G15: ='2015'!W17 -> 130.30906 | H15: ='2016'!W17 -> 124.07536 | I15: ='2017'!W17 -> 121.55865 | J15: ='2018'!W17 -> 120.55138 | K15: ='2019'!W17 -> 108.96404 | L15: ='2020'!W17 -> 115.94308 | M15: ='2021'!W17 -> 100.80082 | N15: ='2022'!W17 -> 97.676296
A16: Greece | B16: ='2010'!W18 -> na | C16: ='2011'!W18 -> na | D16: ='2012'!W18 -> na | E16: ='2013'!W18 -> na | F16: ='2014'!W18 -> na | G16: ='2015'!W18 -> 120.21964 | H16: ='2016'!W18 -> 134.7335 | I16: ='2017'!W18 -> 199.82421 | J16: ='2018'!W18 -> 196.62182 | K16: ='2019'!W18 -> 179.33574 | L16: ='2020'!W18 -> 200.11239 | M16: ='2021'!W18 -> 223.72894 | N16: ='2022'!W18 -> 183.14391
... A20: Italy | B20: ='2010'!W22 -> 621.91598 | C20: ='2011'!W22 -> 557.06292 | D20: ='2012'!W22 -> 511.73849 | E20: ='2013'!W22 -> 453.7152 | F20: ='2014'!W22 -> 494.52725 | G20: ='2015'!W22 -> 483.99168 | H20: ='2016'!W22 -> 445.60174 | I20: ='2017'!W22 -> 418.46964 | J20: ='2018'!W22 -> 356.52116 | K20: ='2019'!W22 -> 287.06881 | L20: ='2020'!W22 -> 274.35698 | M20: ='2021'!W22 -> 261.81223 | N20: ='2022'!W22 -> 239.51567
A21: Latvia | B21: ='2010'!W23 -> 67.235649 | C21: ='2011'!W24 -> 63.25118 | D21: ='2012'!W23 -> 70.542747 | E21: ='2013'!W23 -> 64.61356 | F21: ='2014'!W23 -> 62.269021 | G21: ='2015'!W23 -> 62.82412 | H21: ='2016'!W23 -> 50.506477 | I21: ='2017'!W23 -> 55.120601 | J21: ='2018'!W23 -> 59.275065 | K21: ='2019'!W23 -> 46.251542 | L21: ='2020'!W23 -> 49.210428 | M21: ='2021'!W23 -> 42.873937 | N21: ='2022'!W23 -> 34.39866
A22: Lithuania | B22: ='2010'!W24 -> 80.97428 | C22: ='2011'!W25 -> 68.814599 | D22: ='2012'!W24 -> 65.286364 | E22: ='2013'!W24 -> 48.057547 | F22: ='2014'!W24 -> 58.886139 | G22: ='2015'!W24 -> 58.698418 | H22: ='2016'!W24 -> 62.854122 | I22: ='2017'!W24 -> 57.502983 | J22: ='2018'!W24 -> 55.279622 | K22: ='2019'!W24 -> 109.56599 | L22: ='2020'!W24 -> 99.502457 | M22: ='2021'!W24 -> 116.35466 | N22: ='2022'!W24 -> 79.530549
A23: Luxembourg | B23: ='2010'!W25 -> na | C23: ='2011'!W26 -> na | D23: ='2012'!W25 -> 72.637078 | E23: ='2013'!W25 -> 87.396353 | F23: ='2014'!W25 -> 68.385033 | G23: ='2015'!W25 -> 58.64019 | H23: ='2016'!W25 -> 60.103744 | I23: ='2017'!W25 -> 59.766392 | J23: ='2018'!W25 -> 57.769495 | K23: ='2019'!W25 -> 50.542946 | L23: ='2020'!W25 -> 50.604152 | M23: ='2021'!W25 -> 47.37016 | N23: ='2022'!W25 -> 42.91757
A24: Malta | B24: ='2010'!W26 -> na | C24: ='2011'!W27 -> na | D24: ='2012'!W26 -> na | E24: ='2013'!W26 -> na | F24: ='2014'!W26 -> na | G24: ='2015'!W26 -> na | H24: ='2016'!W26 -> na | I24: ='2017'!W26 -> 193.15603 | J24: ='2018'!W26 -> 221.83246 | K24: ='2019'!W26 -> 166.29897 | L24: ='2020'!W26 -> 178.40694 | M24: ='2021'!W26 -> 174.80585 | N24: ='2022'!W26 -> 120.22689
A25: Netherlands | B25: ='2010'!W27 -> 202.99206 | C25: ='2011'!W28 -> 157.50819 | D25: ='2012'!W27 -> 105.2406 | E25: ='2013'!W27 -> 97.811852 | F25: ='2014'!W27 -> 94.234924 | G25: ='2015'!W27 -> 86.436564 | H25: ='2016'!W27 -> 71.138928 | I25: ='2017'!W27 -> 76.170966 | J25: ='2018'!W27 -> 77.068913 | K25: ='2019'!W27 -> 64.031605 | L25: ='2020'!W27 -> 66.951534 | M25: ='2021'!W27 -> 64.102714 | N25: ='2022'!W27 -> 49.276256
A26: Norway | B26: ='2010'!W28 -> 6.2430937 | C26: ='2011'!W29 -> 5.5908346 | D26: ='2012'!W28 -> 5.8680547 | E26: ='2013'!W28 -> 5.5715914 | F26: ='2014'!W28 -> 4.7612496 | G26: ='2015'!W28 -> 4.4333277 | H26: ='2016'!W28 -> 4.4430118 | I26: ='2017'!W28 -> 4.7736727 | J26: ='2018'!W28 -> 4.5912538 | K26: ='2019'!W28 -> 3.6321287 | L26: ='2020'!W28 -> 3.62963 | M26: ='2021'!W28 -> 3.6225979 | N26: ='2022'!W28 -> 3.3096332
A27: Poland | B27: ='2010'!W29 -> na | C27: ='2011'!W30 -> 181.67066 | D27: ='2012'!W29 -> 203.00554 | E27: ='2013'!W29 -> 226.42319 | F27: ='2014'!W29 -> 207.77166 | G27: ='2015'!W29 -> 208.86029 | H27: ='2016'!W29 -> 195.29808 | I27: ='2017'!W29 -> 250.19703 | J27: ='2018'!W29 -> 259.35694 | K27: ='2019'!W29 -> 284.94223 | L27: ='2020'!W29 -> 290.52842 | M27: ='2021'!W29 -> 268.96978 | N27: ='2022'!W29 -> 307.99122
A28: Portugal | B28: ='2010'!W30 -> 241.5113 | C28: ='2011'!W31 -> 222.33324 | D28: ='2012'!W30 -> 214.68339 | E28: ='2013'!W30 -> 257.78724 | F28: ='2014'!W30 -> 275.22907 | G28: ='2015'!W30 -> 235.31389 | H28: ='2016'!W30 -> 290.45964 | I28: ='2017'!W30 -> 189.82332 | J28: ='2018'!W30 -> 263.13359 | K28: ='2019'!W30 -> 203.10456 | L28: ='2020'!W30 -> 245.02803 | M28: ='2021'!W30 -> 213.61599 | N28: ='2022'!W30 -> 112.88337
A29: Romania | B29: ='2010'!W31 -> na | C29: ='2011'!W32 -> na | D29: ='2012'!W31 -> na | E29: ='2013'!W31 -> na | F29: ='2014'!W31 -> 230.36561 | G29: ='2015'!W31 -> 213.22018 | H29: ='2016'!W31 -> 166.06172 | I29: ='2017'!W31 -> 177.93199 | J29: ='2018'!W31 -> 161.72276 | K29: ='2019'!W31 -> 98.118794 | L29: ='2020'!W31 -> 106.80986 | M29: ='2021'!W31 -> 105.70104 | N29: ='2022'!W31 -> 87.989311
A30: Slovakia | B30: ='2010'!W32 -> na | C30: ='2011'!W33 -> 73.696916 | D30: ='2012'!W32 -> 60.921362 | E30: ='2013'!W32 -> 99.436444 | F30: ='2014'!W32 -> 109.92665 | G30: ='2015'!W32 -> 85.172385 | H30: ='2016'!W32 -> 85.742394 | I30: ='2017'!W32 -> 108.24108 | J30: ='2018'!W32 -> 81.610048 | K30: ='2019'!W32 -> 69.460203 | L30: ='2020'!W32 -> 86.099778 | M30: ='2021'!W32 -> 68.160762 | N30: ='2022'!W32 -> 69.445566
A31: Slovenia | B31: ='2010'!W33 -> 85.694277 | C31: ='2011'!W34 -> 85.122879 | D31: ='2012'!W33 -> 58.521951 | E31: ='2013'!W33 -> 41.44489 | F31: ='2014'!W33 -> 63.042501 | G31: ='2015'!W33 -> 50.119014 | H31: ='2016'!W33 -> 57.890723 | I31: ='2017'!W33 -> 70.260625 | J31: ='2018'!W33 -> 82.949894 | K31: ='2019'!W33 -> 86.125197 | L31: ='2020'!W33 -> 64.152779 | M31: ='2021'!W33 -> 60.945419 | N31: ='2022'!W33 -> 49.591711
A32: Spain | B32: ='2010'!W34 -> 309.33247 | C32: ='2011'!W35 -> 408.79932 | D32: ='2012'!W34 -> 457.63292 | E32: ='2013'!W34 -> 382.71099 | F32: ='2014'!W34 -> 501.99987 | G32: ='2015'!W34 -> 487.70964 | H32: ='2016'!W34 -> 439.52638 | I32: ='2017'!W34 -> 280.25823 | J32: ='2018'!W34 -> 268.32153 | K32: ='2019'!W34 -> 156.13546 | L32: ='2020'!W34 -> 188.86064 | M32: ='2021'!W34 -> 193.0779 | N32: ='2022'!W34 -> 158.50137
... A35: United Kingdom | B35: ='2010'!W37 -> 149.30763 | C35: ='2011'!W38 -> 109.20259 | D35: ='2012'!W37 -> 141.62206 | E35: ='2013'!W37 -> 134.4507 | F35: ='2014'!W37 -> 133.63286 | G35: ='2015'!W37 -> 120.11782 | H35: ='2016'!W37 -> 82.772305 | I35: ='2017'!W37 -> na | J35: ='2018'!W37 -> na | K35: ='2019'!W37 -> na | L35: ='2020'!W37 -> na | M35: ='2021'!W37 -> na | N35: ='2022'!W37 -> na

Sheet 2010
A2: Use of antibiotics index 2010
A4: Actual use | B4: https://esvacbi.ema.europa.eu/analytics/saw.dll?Dashboard | K4: Expected use | U4: Antibiotic use index
A5: PCU tonne
A6: Country | B6: Cattle | C6: Pigs | D6: Poultry | E6: Sheep and goats | F6: Fish | G6: Rabbits | H6: Horses | I6: Total PCU (tonnes) | J6: mg/PCU | K6: Cattle | L6: Pigs | M6: Poultry | N6: Sheep and goats | O6: Fish | P6: Rabbits | Q6: Horses | R6: Total | S6: mg/PCU | T6: Actual use/ expected use | U6: Beef cattle | V6: Dairy cows | W6: Pigs | X6: Broiler | Y6: Sheep and goat | Z6: Fish | AA6: Rabbits | AB6: Horses | AC6: Egg | AD6: Milk
A7: Austria | B7: 444.33916 | C7: 403.20586 | D7: 79.225167 | E7: 34.4043 | F7: 0 | G7: 0 | H7: 33.0732 | I7: =SUM(B7:H7) -> 994.24769 | J7: 62.9 | K7: =B7*$K$39 -> 13330.175 | L7: =C7*$L$39 -> 24192.352 | M7: =D7*$M$39 -> 2376.755 | N7: =E7*$N$39 -> 688.086 | O7: =F7*$O$39 -> 0 | P7: =G7*$P$39 -> 0 | Q7: =H7*$Q$39 -> 165.366 | R7: =SUM(K7:Q7) -> 40752.734 | S7: =R7/I7 -> 40.988512 | T7: =J7/S7 -> 1.5345763 | U7: =$U$39*$T7 -> 12.430068 | V7: =$V$39*$T7 -> 33.607221 | W7: =$W$39*$T7 -> 92.074579 | X7: =$X$39*$T7 -> 46.03729 | Y7: =$Y$39*$T7 -> 30.691526 | Z7: =$Z$39*$T7 -> 61.383053 | AA7: =$AA$39*$T7 -> 1196.9695 | AB7: =$AB$39*$T7 -> 7.6728816 | AC7: =$AC$39*$T7 -> 0.58592914 | AD7: =$AD$39*$T7 -> 2.5320509
A8: Belgium | B8: 478.52147 | C8: 901.27764 | D8: 173.81867 | E8: 16.44681 | F8: 0.576 | G8: 4.2588 | H8: 85.5864 | I8: =SUM(B8:H8) -> 1660.4858 | J8: 179.9 | K8: =B8*$K$39 -> 14355.644 | L8: =C8*$L$39 -> 54076.658 | M8: =D8*$M$39 -> 5214.5602 | N8: =E8*$N$39 -> 328.9362 | O8: =F8*$O$39 -> 23.04 | P8: =G8*$P$39 -> 3321.864 | Q8: =H8*$Q$39 -> 427.932 | R8: =SUM(K8:Q8) -> 77748.635 | S8: =R8/I8 -> 46.822824 | T8: =J8/S8 -> 3.8421433 | U8: =$U$39*$T8 -> 31.121361 | V8: =$V$39*$T8 -> 84.142938 | W8: =$W$39*$T8 -> 230.5286 | X8: =$X$39*$T8 -> 115.2643 | Y8: =$Y$39*$T8 -> 76.842865 | Z8: =$Z$39*$T8 -> 153.68573 | AA8: =$AA$39*$T8 -> 2996.8718 | AB8: =$AB$39*$T8 -> 19.210716 | AC8: =$AC$39*$T8 -> 1.4670002 | AD8: =$AD$39*$T8 -> 6.3395364
A9: Bulgaria | B9: na | C9: na | D9: na | E9: na | F9: na | G9: na | H9: na | I9: na | J9: na | K9: na | L9: na | M9: na | N9: na | O9: na | P9: na | Q9: na | R9: na | S9: na | T9: na | U9: na | V9: na | W9: na | X9: na | Y9: na | Z9: na | AA9: na | AB9: na | AC9: na | AD9: na
A10: Croatia | B10: na | C10: na | D10: na | E10: na | F10: na | G10: na | H10: na | I10: na | J10: na | K10: na | L10: na | M10: na | N10: na | O10: na | P10: na | Q10: na | R10: na | S10: na | T10: na | U10: na | V10: na | W10: na | X10: na | Y10: na | Z10: na | AA10: na | AB10: na | AC10: na | AD10: na
A11: Cyprus | B11: na | C11: na | D11: na | E11: na | F11: na | G11: na | H11: na | I11: na | J11: na | K11: na | L11: na | M11: na | N11: na | O11: na | P11: na | Q11: na | R11: na | S11: na | T11: na | U11: na | V11: na | W11: na | X11: na | Y11: na | Z11: na | AA11: na | AB11: na | AC11: na | AD11: na
A12: Czech Republic | B12: 292.07171 | C12: 240.16889 | D12: 146.1986 | E12: 15.161855 | F12: 20.42 | G12: 11.6284 | H12: 29.5728 | I12: =SUM(B12:H12) -> 755.22226 | J12: 94.3 | K12: =B12*$K$39 -> 8762.1513 | L12: =C12*$L$39 -> 14410.134 | M12: =D12*$M$39 -> 4385.958 | N12: =E12*$N$39 -> 303.2371 | O12: =F12*$O$39 -> 816.8 | P12: =G12*$P$39 -> 9070.152 | Q12: =H12*$Q$39 -> 147.864 | R12: =SUM(K12:Q12) -> 37896.296 | S12: =R12/I12 -> 50.178998 | T12: =J12/S12 -> 1.8792723 | U12: =$U$39*$T12 -> 15.222106 | V12: =$V$39*$T12 -> 41.156063 | W12: =$W$39*$T12 -> 112.75634 | X12: =$X$39*$T12 -> 56.378169 | Y12: =$Y$39*$T12 -> 37.585446 | Z12: =$Z$39*$T12 -> 75.170892 | AA12: =$AA$39*$T12 -> 1465.8324 | AB12: =$AB$39*$T12 -> 9.3963614 | AC12: =$AC$39*$T12 -> 0.71754033 | AD12: =$AD$39*$T12 -> 3.1007993
A13: Denmark | B13: 409.08433 | C13: 1855.9095 | D13: 120.40682 | E13: 13.72725 | F13: 34.131 | G13: 0 | H13: 70 | I13: =SUM(B13:H13) -> 2503.2589 | J13: 47.1 | K13: =B13*$K$39 -> 12272.53 | L13: =C13*$L$39 -> 111354.57 | M13: =D13*$M$39 -> 3612.2047 | N13: =E13*$N$39 -> 274.545 | O13: =F13*$O$39 -> 1365.24 | P13: =G13*$P$39 -> 0 | Q13: =H13*$Q$39 -> 350 | R13: =SUM(K13:Q13) -> 129229.09 | S13: =R13/I13 -> 51.62434 | T13: =J13/S13 -> 0.91236033 | U13: =$U$39*$T13 -> 7.3901187 | V13: =$V$39*$T13 -> 19.980691 | W13: =$W$39*$T13 -> 54.74162 | X13: =$X$39*$T13 -> 27.37081 | Y13: =$Y$39*$T13 -> 18.247207 | Z13: =$Z$39*$T13 -> 36.494413 | AA13: =$AA$39*$T13 -> 711.64106 | AB13: =$AB$39*$T13 -> 4.5618016 | AC13: =$AC$39*$T13 -> 0.34835576 | AD13: =$AD$39*$T13 -> 1.5053945
A14: Estonia | B14: 61.116435 | C14: 34.959665 | D14: 2.095567 | E14: 4.80926 | F14: 0.654 | G14: 0 | H14: 4.04 | I14: =SUM(B14:H14) -> 107.67493 | J14: 70.8 | K14: =B14*$K$39 -> 1833.4931 | L14: =C14*$L$39 -> 2097.5799 | M14: =D14*$M$39 -> 62.86701 | N14: =E14*$N$39 -> 96.1852 | O14: =F14*$O$39 -> 26.16 | P14: =G14*$P$39 -> 0 | Q14: =H14*$Q$39 -> 20.2 | R14: =SUM(K14:Q14) -> 4136.4852 | S14: =R14/I14 -> 38.416419 | T14: =J14/S14 -> 1.842962 | U14: =$U$39*$T14 -> 14.927992 | V14: =$V$39*$T14 -> 40.360867 | W14: =$W$39*$T14 -> 110.57772 | X14: =$X$39*$T14 -> 55.288859 | Y14: =$Y$39*$T14 -> 36.859239 | Z14: =$Z$39*$T14 -> 73.718479 | AA14: =$AA$39*$T14 -> 1437.5103 | AB14: =$AB$39*$T14 -> 9.2148098 | AC14: =$AC$39*$T14 -> 0.70367639 | AD14: =$AD$39*$T14 -> 3.0408872
A15: Finland | B15: 224.39418 | C15: 181.24047 | D15: 59.537886 | E15: 10.17292 | F15: 11.8 | G15: 0 | H15: 29.72 | I15: =SUM(B15:H15) -> 516.86545 | J15: 22 | K15: =B15*$K$39 -> 6731.8254 | L15: =C15*$L$39 -> 10874.428 | M15: =D15*$M$39 -> 1786.1366 | N15: =E15*$N$39 -> 203.4584 | O15: =F15*$O$39 -> 472 | P15: =G15*$P$39 -> 0 | Q15: =H15*$Q$39 -> 148.6 | R15: =SUM(K15:Q15) -> 20216.448 | S15: =R15/I15 -> 39.113561 | T15: =J15/S15 -> 0.56246477 | U15: =$U$39*$T15 -> 4.5559646 | V15: =$V$39*$T15 -> 12.317978 | W15: =$W$39*$T15 -> 33.747886 | X15: =$X$39*$T15 -> 16.873943 | Y15: =$Y$39*$T15 -> 11.249295 | Z15: =$Z$39*$T15 -> 22.498591 | AA15: =$AA$39*$T15 -> 438.72252 | AB15: =$AB$39*$T15 -> 2.8123238 | AC15: =$AC$39*$T15 -> 0.21475928 | AD15: =$AD$39*$T15 -> 0.92806687
A16: France | B16: 3340.3962 | C16: 1886.973 | D16: 1150.9532 | E16: 695.50249 | F16: 45.042 | G16: 48.6514 | H16: 311.318 | I16: =SUM(B16:H16) -> 7478.8363 | J16: 133.6 | K16: =B16*$K$39 -> 100211.89 | L16: =C16*$L$39 -> 113218.38 | M16: =D16*$M$39 -> 34528.597 | N16: =E16*$N$39 -> 13910.05 | O16: =F16*$O$39 -> 1801.68 | P16: =G16*$P$39 -> 37948.092 | Q16: =H16*$Q$39 -> 1556.59 | R16: =SUM(K16:Q16) -> 303175.27 | S16: =R16/I16 -> 40.53776 | T16: =J16/S16 -> 3.2956927 | U16: =$U$39*$T16 -> 26.695111 | V16: =$V$39*$T16 -> 72.17567 | W16: =$W$39*$T16 -> 197.74156 | X16: =$X$39*$T16 -> 98.870781 | Y16: =$Y$39*$T16 -> 65.913854 | Z16: =$Z$39*$T16 -> 131.82771 | AA16: =$AA$39*$T16 -> 2570.6403 | AB16: =$AB$39*$T16 -> 16.478463 | AC16: =$AC$39*$T16 -> 1.2583554 | AD16: =$AD$39*$T16 -> 5.4378929
A17: Germany | B17: na | C17: na | D17: na | E17: na | F17: na | G17: na | H17: na | I17: na | J17: na | K17: na | L17: na | M17: na | N17: na | O17: na | P17: na | Q17: na | R17: na | S17: na | T17: na | U17: na | V17: na | W17: na | X17: na | Y17: na | Z17: na | AA17: na | AB17: na | AC17: na | AD17: na
A18: Greece | B18: na | C18: na | D18: na | E18: na | F18: na | G18: na | H18: na | I18: na | J18: na | K18: na | L18: na | M18: na | N18: na | O18: na | P18: na | Q18: na | R18: na | S18: na | T18: na | U18: na | V18: na | W18: na | X18: na | Y18: na | Z18: na | AA18: na | AB18: na | AC18: na | AD18: na
A19: Hungary | B19: 151.32915 | C19: 316.02211 | D19: 170.43446 | E19: 102.26428 | F19: 0 | G19: 1.1564 | H19: 27.2 | I19: =SUM(B19:H19) -> 768.4064 | J19: 269.9 | K19: =B19*$K$39 -> 4539.8744 | L19: =C19*$L$39 -> 18961.327 | M19: =D19*$M$39 -> 5113.0339 | N19: =E19*$N$39 -> 2045.2856 | O19: =F19*$O$39 -> 0 | P19: =G19*$P$39 -> 901.992 | Q19: =H19*$Q$39 -> 136 | R19: =SUM(K19:Q19) -> 31697.513 | S19: =R19/I19 -> 41.250974 | T19: =J19/S19 -> 6.5428758 | U19: =$U$39*$T19 -> 52.997294 | V19: =$V$39*$T19 -> 143.28898 | W19: =$W$39*$T19 -> 392.57255 | X19: =$X$39*$T19 -> 196.28627 | Y19: =$Y$39*$T19 -> 130.85752 | Z19: =$Z$39*$T19 -> 261.71503 | AA19: =$AA$39*$T19 -> 5103.4431 | AB19: =$AB$39*$T19 -> 32.714379 | AC19: =$AC$39*$T19 -> 2.4981889 | AD19: =$AD$39*$T19 -> 10.795745
A20: Iceland | B20: 18.9925 | C20: 5.804 | D20: 4.9265 | E20: 47.1 | F20: 5.05 | G20: 0 | H20: 30.8 | I20: =SUM(B20:H20) -> 112.673 | J20: 6.8 | K20: =B20*$K$39 -> 569.775 | L20: =C20*$L$39 -> 348.24 | M20: =D20*$M$39 -> 147.795 | N20: =E20*$N$39 -> 942 | O20: =F20*$O$39 -> 202 | P20: =G20*$P$39 -> 0 | Q20: =H20*$Q$39 -> 154 | R20: =SUM(K20:Q20) -> 2363.81 | S20: =R20/I20 -> 20.979383 | T20: =J20/S20 -> 0.32412774 | U20: =$U$39*$T20 -> 2.6254347 | V20: =$V$39*$T20 -> 7.0983976 | W20: =$W$39*$T20 -> 19.447665 | X20: =$X$39*$T20 -> 9.7238323 | Y20: =$Y$39*$T20 -> 6.4825549 | Z20: =$Z$39*$T20 -> 12.96511 | AA20: =$AA$39*$T20 -> 252.81964 | AB20: =$AB$39*$T20 -> 1.6206387 | AC20: =$AC$39*$T20 -> 0.12375787 | AD20: =$AD$39*$T20 -> 0.53481078
A21: Ireland | B21: 1091.1219 | C21: 249.53832 | D21: 79.870662 | E21: 274.752 | F21: 47.212 | G21: 0 | H21: 36 | I21: =SUM(B21:H21) -> 1778.4949 | J21: 51.4 | K21: =B21*$K$39 -> 32733.656 | L21: =C21*$L$39 -> 14972.299 | M21: =D21*$M$39 -> 2396.1199 | N21: =E21*$N$39 -> 5495.04 | O21: =F21*$O$39 -> 1888.48 | P21: =G21*$P$39 -> 0 | Q21: =H21*$Q$39 -> 180 | R21: =SUM(K21:Q21) -> 57665.595 | S21: =R21/I21 -> 32.423819 | T21: =J21/S21 -> 1.5852543 | U21: =$U$39*$T21 -> 12.84056 | V21: =$V$39*$T21 -> 34.71707 | W21: =$W$39*$T21 -> 95.115261 | X21: =$X$39*$T21 -> 47.55763 | Y21: =$Y$39*$T21 -> 31.705087 | Z21: =$Z$39*$T21 -> 63.410174 | AA21: =$AA$39*$T21 -> 1236.4984 | AB21: =$AB$39*$T21 -> 7.9262717 | AC21: =$AC$39*$T21 -> 0.60527893 | AD21: =$AD$39*$T21 -> 2.6156697
A22: Italy | B22: 1820.8867 | C22: 1032.1505 | D22: 674.80435 | E22: 614.43902 | F22: 232.13 | G22: 34.062 | H22: 164.0148 | I22: =SUM(B22:H22) -> 4572.4874 | J22: 421.1 | K22: =B22*$K$39 -> 54626.602 | L22: =C22*$L$39 -> 61929.028 | M22: =D22*$M$39 -> 20244.13 | N22: =E22*$N$39 -> 12288.78 | O22: =F22*$O$39 -> 9285.2 | P22: =G22*$P$39 -> 26568.36 | Q22: =H22*$Q$39 -> 820.074 | R22: =SUM(K22:Q22) -> 185762.18 | S22: =R22/I22 -> 40.626066 | T22: =J22/S22 -> 10.365266 | U22: =$U$39*$T22 -> 83.958658 | V22: =$V$39*$T22 -> 226.99933 | W22: =$W$39*$T22 -> 621.91598 | X22: =$X$39*$T22 -> 310.95799 | Y22: =$Y$39*$T22 -> 207.30533 | Z22: =$Z$39*$T22 -> 414.61066 | AA22: =$AA$39*$T22 -> 8084.9078 | AB22: =$AB$39*$T22 -> 51.826332 | AC22: =$AC$39*$T22 -> 3.9576472 | AD22: =$AD$39*$T22 -> 17.10269
A23: Latvia | B23: 103.77506 | C23: 33.447275 | D23: 16.298149 | E23: 5.9286 | F23: 0.517 | G23: 0.0243852 | H23: 4.71 | I23: =SUM(B23:H23) -> 164.70047 | J23: 39.4 | K23: =B23*$K$39 -> 3113.2518 | L23: =C23*$L$39 -> 2006.8365 | M23: =D23*$M$39 -> 488.94447 | N23: =E23*$N$39 -> 118.572 | O23: =F23*$O$39 -> 20.68 | P23: =G23*$P$39 -> 19.020456 | Q23: =H23*$Q$39 -> 23.55 | R23: =SUM(K23:Q23) -> 5790.8552 | S23: =R23/I23 -> 35.159919 | T23: =J23/S23 -> 1.1205941 | U23: =$U$39*$T23 -> 9.0768126 | V23: =$V$39*$T23 -> 24.541012 | W23: =$W$39*$T23 -> 67.235649 | X23: =$X$39*$T23 -> 33.617824 | Y23: =$Y$39*$T23 -> 22.411883 | Z23: =$Z$39*$T23 -> 44.823766 | AA23: =$AA$39*$T23 -> 874.06344 | AB23: =$AB$39*$T23 -> 5.6029707 | AC23: =$AC$39*$T23 -> 0.42786322 | AD23: =$AD$39*$T23 -> 1.8489803
A24: Lithuania | B24: 223.67621 | C24: 67.14788 | D24: 39.655015 | E24: 4.4866 | F24: 3.428 | G24: 0.042 | H24: 3.294 | I24: =SUM(B24:H24) -> 341.7297 | J24: 48.2 | K24: =B24*$K$39 -> 6710.2863 | L24: =C24*$L$39 -> 4028.8728 | M24: =D24*$M$39 -> 1189.6504 | N24: =E24*$N$39 -> 89.732 | O24: =F24*$O$39 -> 137.12 | P24: =G24*$P$39 -> 32.76 | Q24: =H24*$Q$39 -> 16.47 | R24: =SUM(K24:Q24) -> 12204.892 | S24: =R24/I24 -> 35.715044 | T24: =J24/S24 -> 1.3495713 | U24: =$U$39*$T24 -> 10.931528 | V24: =$V$39*$T24 -> 29.555612 | W24: =$W$39*$T24 -> 80.97428 | X24: =$X$39*$T24 -> 40.48714 | Y24: =$Y$39*$T24 -> 26.991427 | Z24: =$Z$39*$T24 -> 53.982853 | AA24: =$AA$39*$T24 -> 1052.6656 | AB24: =$AB$39*$T24 -> 6.7478567 | AC24: =$AC$39*$T24 -> 0.51529087 | AD24: =$AD$39*$T24 -> 2.2267927
A25: Luxembourg | B25: na | C25: na | D25: na | E25: na | F25: na | G25: na | H25: na | I25: na | J25: na | K25: na | L25: na | M25: na | N25: na | O25: na | P25: na | Q25: na | R25: na | S25: na | T25: na | U25: na | V25: na | W25: na | X25: na | Y25: na | Z25: na | AA25: na | AB25: na | AC25: na | AD25: na
A26: Malta | B26: na | C26: na | D26: na | E26: na | F26: na | G26: na | H26: na | I26: na | J26: na | K26: na | L26: na | M26: na | N26: na | O26: na | P26: na | Q26: na | R26: na | S26: na | T26: na | U26: na | V26: na | W26: na | X26: na | Y26: na | Z26: na | AA26: na | AB26: na | AC26: na | AD26: na
A27: Netherlands | B27: 982.97573 | C27: 1492.9684 | D27: 391.06258 | E27: 109.158 | F27: 7.36 | G27: 2.6208 | H27: 169.2 | I27: =SUM(B27:H27) -> 3155.3455 | J27: 146 | K27: =B27*$K$39 -> 29489.272 | L27: =C27*$L$39 -> 89578.101 | M27: =D27*$M$39 -> 11731.877 | N27: =E27*$N$39 -> 2183.16 | O27: =F27*$O$39 -> 294.4 | P27: =G27*$P$39 -> 2044.224 | Q27: =H27*$Q$39 -> 846 | R27: =SUM(K27:Q27) -> 136167.03 | S27: =R27/I27 -> 43.154398 | T27: =J27/S27 -> 3.3832009 | U27: =$U$39*$T27 -> 27.403928 | V27: =$V$39*$T27 -> 74.0921 | W27: =$W$39*$T27 -> 202.99206 | X27: =$X$39*$T27 -> 101.49603 | Y27: =$Y$39*$T27 -> 67.664019 | Z27: =$Z$39*$T27 -> 135.32804 | AA27: =$AA$39*$T27 -> 2638.8967 | AB27: =$AB$39*$T27 -> 16.916005 | AC27: =$AC$39*$T27 -> 1.2917676 | AD27: =$AD$39*$T27 -> 5.5822815
A28: Norway | B28: 221.56949 | C28: 125.10067 | D28: 62.374 | E28: 93.63918 | F28: 1019.711 | G28: 0 | H28: 50 | I28: =SUM(B28:H28) -> 1572.3944 | J28: 3.9 | K28: =B28*$K$39 -> 6647.0848 | L28: =C28*$L$39 -> 7506.0405 | M28: =D28*$M$39 -> 1871.22 | N28: =E28*$N$39 -> 1872.7836 | O28: =F28*$O$39 -> 40788.44 | P28: =G28*$P$39 -> 0 | Q28: =H28*$Q$39 -> 250 | R28: =SUM(K28:Q28) -> 58935.569 | S28: =R28/I28 -> 37.481417 | T28: =J28/S28 -> 0.10405156 | U28: =$U$39*$T28 -> 0.84281765 | V28: =$V$39*$T28 -> 2.2787292 | W28: =$W$39*$T28 -> 6.2430937 | X28: =$X$39*$T28 -> 3.1215468 | Y28: =$Y$39*$T28 -> 2.0810312 | Z28: =$Z$39*$T28 -> 4.1620625 | AA28: =$AA$39*$T28 -> 81.160218 | AB28: =$AB$39*$T28 -> 0.52025781 | AC28: =$AC$39*$T28 -> 0.039728778 | AD28: =$AD$39*$T28 -> 0.17168508
A29: Poland | B29: na | C29: na | D29: na | E29: na | F29: na | G29: na | H29: na | I29: na | J29: na | K29: na | L29: na | M29: na | N29: na | O29: na | P29: na | Q29: na | R29: na | S29: na | T29: na | U29: na | V29: na | W29: na | X29: na | Y29: na | Z29: na | AA29: na | AB29: na | AC29: na | AD29: na
A30: Portugal | B30: 237.72894 | C30: 348.62156 | D30: 204.7199 | E30: 190.35832 | F30: 7.979 | G30: 8.4413574 | H30: 38.8 | I30: =SUM(B30:H30) -> 1036.6491 | J30: 175.1 | K30: =B30*$K$39 -> 7131.8682 | L30: =C30*$L$39 -> 20917.293 | M30: =D30*$M$39 -> 6141.5971 | N30: =E30*$N$39 -> 3807.1664 | O30: =F30*$O$39 -> 319.16 | P30: =G30*$P$39 -> 6584.2588 | Q30: =H30*$Q$39 -> 194 | R30: =SUM(K30:Q30) -> 45095.344 | S30: =R30/I30 -> 43.50107 | T30: =J30/S30 -> 4.0251884 | U30: =$U$39*$T30 -> 32.604026 | V30: =$V$39*$T30 -> 88.151625 | W30: =$W$39*$T30 -> 241.5113 | X30: =$X$39*$T30 -> 120.75565 | Y30: =$Y$39*$T30 -> 80.503767 | Z30: =$Z$39*$T30 -> 161.00753 | AA30: =$AA$39*$T30 -> 3139.6469 | AB30: =$AB$39*$T30 -> 20.125942 | AC30: =$AC$39*$T30 -> 1.5368901 | AD30: =$AD$39*$T30 -> 6.6415608
A31: Romania | B31: na | C31: na | D31: na | E31: na | F31: na | G31: na | H31: na | I31: na | J31: na | K31: na | L31: na | M31: na | N31: na | O31: na | P31: na | Q31: na | R31: na | S31: na | T31: na | U31: na | V31: na | W31: na | X31: na | Y31: na | Z31: na | AA31: na | AB31: na | AC31: na | AD31: na
A32: Slovakia | B32: na | C32: na | D32: na | E32: na | F32: na | G32: na | H32: na | I32: na | J32: na | K32: na | L32: na | M32: na | N32: na | O32: na | P32: na | Q32: na | R32: na | S32: na | T32: na | U32: na | V32: na | W32: na | X32: na | Y32: na | Z32: na | AA32: na | AB32: na | AC32: na | AD32: na
A33: Slovenia | B33: 100.14521 | C33: 26.457355 | D33: 33.517241 | E33: 9.94866 | F33: 0.778 | G33: 0.02478 | H33: 8.92 | I33: =SUM(B33:H33) -> 179.79124 | J33: 46.8 | K33: =B33*$K$39 -> 3004.3562 | L33: =C33*$L$39 -> 1587.4413 | M33: =D33*$M$39 -> 1005.5172 | N33: =E33*$N$39 -> 198.9732 | O33: =F33*$O$39 -> 31.12 | P33: =G33*$P$39 -> 19.3284 | Q33: =H33*$Q$39 -> 44.6 | R33: =SUM(K33:Q33) -> 5891.3363 | S33: =R33/I33 -> 32.767649 | T33: =J33/S33 -> 1.428238 | U33: =$U$39*$T33 -> 11.568727 | V33: =$V$39*$T33 -> 31.278411 | W33: =$W$39*$T33 -> 85.694277 | X33: =$X$39*$T33 -> 42.847139 | Y33: =$Y$39*$T33 -> 28.564759 | Z33: =$Z$39*$T33 -> 57.129518 | AA33: =$AA$39*$T33 -> 1114.0256 | AB33: =$AB$39*$T33 -> 7.1411898 | AC33: =$AC$39*$T33 -> 0.54532722 | AD33: =$AD$39*$T33 -> 2.3565926
A34: Spain | B34: 925.64427 | C34: 3332.8806 | D34: 703.34684 | E34: 1651.007 | F34: 268.565 | G34: 73.686608 | H34: 0 | I34: =SUM(B34:H34) -> 6955.1303 | J34: 259.5 | K34: =B34*$K$39 -> 27769.328 | L34: =C34*$L$39 -> 199972.84 | M34: =D34*$M$39 -> 21100.405 | N34: =E34*$N$39 -> 33020.14 | O34: =F34*$O$39 -> 10742.6 | P34: =G34*$P$39 -> 57475.554 | Q34: =H34*$Q$39 -> 0 | R34: =SUM(K34:Q34) -> 350080.86 | S34: =R34/I34 -> 50.334192 | T34: =J34/S34 -> 5.1555412 | U34: =$U$39*$T34 -> 41.759884 | V34: =$V$39*$T34 -> 112.90635 | W34: =$W$39*$T34 -> 309.33247 | X34: =$X$39*$T34 -> 154.66624 | Y34: =$Y$39*$T34 -> 103.11082 | Z34: =$Z$39*$T34 -> 206.22165 | AA34: =$AA$39*$T34 -> 4021.3221 | AB34: =$AB$39*$T34 -> 25.777706 | AC34: =$AC$39*$T34 -> 1.9684794 | AD34: =$AD$39*$T34 -> 8.506643
A35: Sweden | B35: 320.10679 | C35: 230.03315 | D35: 81.726157 | E35: 47.47 | F35: 7.851 | G35: 0 | H35: 145.08 | I35: =SUM(B35:H35) -> 832.2671 | J35: 14.7 | K35: =B35*$K$39 -> 9603.2036 | L35: =C35*$L$39 -> 13801.989 | M35: =D35*$M$39 -> 2451.7847 | N35: =E35*$N$39 -> 949.4 | O35: =F35*$O$39 -> 314.04 | P35: =G35*$P$39 -> 0 | Q35: =H35*$Q$39 -> 725.4 | R35: =SUM(K35:Q35) -> 27845.818 | S35: =R35/I35 -> 33.45779 | T35: =J35/S35 -> 0.43935957 | U35: =$U$39*$T35 -> 3.5588125 | V35: =$V$39*$T35 -> 9.6219745 | W35: =$W$39*$T35 -> 26.361574 | X35: =$X$39*$T35 -> 13.180787 | Y35: =$Y$39*$T35 -> 8.7871913 | Z35: =$Z$39*$T35 -> 17.574383 | AA35: =$AA$39*$T35 -> 342.70046 | AB35: =$AB$39*$T35 -> 2.1967978 | AC35: =$AC$39*$T35 -> 0.16775547 | AD35: =$AD$39*$T35 -> 0.72494328
A36: Switzerland | B36: na | C36: na | D36: na | E36: na | F36: na | G36: na | H36: na | I36: na | J36: na | K36: na | L36: na | M36: na | N36: na | O36: na | P36: na | Q36: na | R36: na | S36: na | T36: na | U36: na | V36: na | W36: na | X36: na | Y36: na | Z36: na | AA36: na | AB36: na | AC36: na | AD36: na
A37: United Kingdom | B37: 1750.2787 | C37: 623.27045 | D37: 1008.8719 | E37: 2615.2822 | F37: 196.28 | G37: 0 | H37: 520 | I37: =SUM(B37:H37) -> 6713.9832 | J37: 67.8 | K37: =B37*$K$39 -> 52508.36 | L37: =C37*$L$39 -> 37396.227 | M37: =D37*$M$39 -> 30266.156 | N37: =E37*$N$39 -> 52305.644 | O37: =F37*$O$39 -> 7851.2 | P37: =G37*$P$39 -> 0 | Q37: =H37*$Q$39 -> 2600 | R37: =SUM(K37:Q37) -> 182927.59 | S37: =R37/I37 -> 27.245762 | T37: =J37/S37 -> 2.4884604 | U37: =$U$39*$T37 -> 20.156529 | V37: =$V$39*$T37 -> 54.497283 | W37: =$W$39*$T37 -> 149.30763 | X37: =$X$39*$T37 -> 74.653813 | Y37: =$Y$39*$T37 -> 49.769208 | Z37: =$Z$39*$T37 -> 99.538417 | AA37: =$AA$39*$T37 -> 1940.9991 | AB37: =$AB$39*$T37 -> 12.442302 | AC37: =$AC$39*$T37 -> 0.95013943 | AD37: =$AD$39*$T37 -> 4.1059597
A39: Standard, mg per kg | K39: ='Standard values'!B5 -> 30 | L39: ='Standard values'!D5 -> 60 | M39: ='Standard values'!E5 -> 30 | N39: ='Standard values'!F5 -> 20 | O39: ='Standard values'!G5 -> 40 | P39: ='Standard values'!H5 -> 780 | Q39: ='Standard values'!I5 -> 5 | U39: ='Standard values'!B6 -> 8.1 | V39: ='Standard values'!C6 -> 21.9 | W39: ='Standard values'!D6 -> 60 | X39: ='Standard values'!E6 -> 30 | Y39: ='Standard values'!F6 -> 20 | Z39: ='Standard values'!G6 -> 40 | AA39: ='Standard values'!H6 -> 780 | AB39: ='Standard values'!I6 -> 5 | ... AD39: ='Standard values'!K6 -> 1.65

Sheet 2011
A2: Use of antibiotics index 2011
A4: Actual use | B4: https://esvacbi.ema.europa.eu/analytics/saw.dll?Dashboard | K4: Expected use | U4: Antibiotic use index
A5: PCU tonne
A6: Country | B6: Cattle | C6: Pigs | D6: Poultry | E6: Sheep and goats | F6: Fish | G6: Rabbits | H6: Horses | I6: Total PCU (tonnes) | J6: mg/PCU | K6: Cattle | L6: Pigs | M6: Poultry | N6: Sheep and goats | O6: Fish | P6: Rabbits | Q6: Horses | R6: Total | S6: mg/PCU | T6: Actual use/ expected use | U6: Beef cattle | V6: Dairy cows | W6: Pigs | X6: Broiler | Y6: Sheep and goat | Z6: Fish | AA6: Rabbits | AB6: Horses | AC6: Egg | AD6: Milk
A7: Austria | B7: 439.59816 | C7: 392.44685 | D7: 80.204064 | E7: 34.98008 | F7: 0 | G7: 0 | H7: 29.2808 | I7: =SUM(B7:H7) -> 976.50995 | J7: 54.4 | K7: =B7*$K$40 -> 13187.945 | L7: =C7*$L$40 -> 23546.811 | M7: =D7*$M$40 -> 2406.1219 | N7: =E7*$N$40 -> 699.6016 | O7: =F7*$O$40 -> 0 | P7: =G7*$P$40 -> 0 | Q7: =H7*$Q$40 -> 146.404 | R7: =SUM(K7:Q7) -> 39986.883 | S7: =R7/I7 -> 40.948772 | T7: =J7/S7 -> 1.3284892 | U7: =$U$40*$T7 -> 10.760762 | V7: =$V$40*$T7 -> 29.093913 | W7: =$W$40*$T7 -> 79.70935 | X7: =$X$40*$T7 -> 39.854675 | Y7: =$Y$40*$T7 -> 26.569783 | Z7: =$Z$40*$T7 -> 53.139567 | AA7: =$AA$40*$T7 -> 1036.2216 | AB7: =$AB$40*$T7 -> 6.6424458 | AC7: =$AC$40*$T7 -> 0.50724132 | AD7: =$AD$40*$T7 -> 2.1920071
A8: Belgium | B8: 491.11774 | C8: 930.88077 | D8: 159.42369 | E8: 16.51302 | F8: 0.576 | G8: 4.077213 | H8: 92.7488 | I8: =SUM(B8:H8) -> 1695.3372 | J8: 175.1 | K8: =B8*$K$40 -> 14733.532 | L8: =C8*$L$40 -> 55852.846 | M8: =D8*$M$40 -> 4782.7107 | N8: =E8*$N$40 -> 330.2604 | O8: =F8*$O$40 -> 23.04 | P8: =G8*$P$40 -> 3180.2261 | Q8: =H8*$Q$40 -> 463.744 | R8: =SUM(K8:Q8) -> 79366.36 | S8: =R8/I8 -> 46.814497 | T8: =J8/S8 -> 3.7402944 | U8: =$U$40*$T8 -> 30.296385 | V8: =$V$40*$T8 -> 81.912447 | W8: =$W$40*$T8 -> 224.41766 | X8: =$X$40*$T8 -> 112.20883 | Y8: =$Y$40*$T8 -> 74.805888 | Z8: =$Z$40*$T8 -> 149.61178 | AA8: =$AA$40*$T8 -> 2917.4296 | AB8: =$AB$40*$T8 -> 18.701472 | AC8: =$AC$40*$T8 -> 1.4281124 | AD8: =$AD$40*$T8 -> 6.1714857
A9: Bulgaria | B9: 137.45612 | C9: 61.86941 | D9: 44.408234 | E9: 93.63994 | F9: 5.504 | G9: 0 | H9: 55.7084 | I9: =SUM(B9:H9) -> 398.58611 | J9: 92.6 | K9: =B9*$K$40 -> 4123.6837 | L9: =C9*$L$40 -> 3712.1646 | M9: =D9*$M$40 -> 1332.247 | N9: =E9*$N$40 -> 1872.7988 | O9: =F9*$O$40 -> 220.16 | P9: =G9*$P$40 -> 0 | Q9: =H9*$Q$40 -> 278.542 | R9: =SUM(K9:Q9) -> 11539.596 | S9: =R9/I9 -> 28.951325 | T9: =J9/S9 -> 3.1984719 | U9: =$U$40*$T9 -> 25.907622 | V9: =$V$40*$T9 -> 70.046534 | W9: =$W$40*$T9 -> 191.90831 | X9: =$X$40*$T9 -> 95.954156 | Y9: =$Y$40*$T9 -> 63.969437 | Z9: =$Z$40*$T9 -> 127.93887 | AA9: =$AA$40*$T9 -> 2494.8081 | AB9: =$AB$40*$T9 -> 15.992359 | AC9: =$AC$40*$T9 -> 1.2212347 | AD9: =$AD$40*$T9 -> 5.2774786
A10: Croatia | B10: na | C10: na | D10: na | E10: na | F10: na | G10: na | H10: na | I10: na | J10: na | K10: na | L10: na | M10: na | N10: na | O10: na | P10: na | Q10: na | R10: na | S10: na | T10: na | U10: na | V10: na | W10: na | X10: na | Y10: na | Z10: na | AA10: na | AB10: na | AC10: na | AD10: na
A11: Cyprus | B11: 17.984375 | C11: 55.842525 | D11: 13.79693 | E11: 60.23882 | F11: 5.014 | G11: 0.178962 | H11: 2.6616 | I11: =SUM(B11:H11) -> 155.71721 | J11: 332.3 | K11: =B11*$K$40 -> 539.53125 | L11: =C11*$L$40 -> 3350.5515 | M11: =D11*$M$40 -> 413.9079 | N11: =E11*$N$40 -> 1204.7764 | O11: =F11*$O$40 -> 200.56 | P11: =G11*$P$40 -> 139.59036 | Q11: =H11*$Q$40 -> 13.308 | R11: =SUM(K11:Q11) -> 5862.2254 | S11: =R11/I11 -> 37.646612 | T11: =J11/S11 -> 8.8268236 | U11: =$U$40*$T11 -> 71.497271 | V11: =$V$40*$T11 -> 193.30744 | W11: =$W$40*$T11 -> 529.60942 | X11: =$X$40*$T11 -> 264.80471 | Y11: =$Y$40*$T11 -> 176.53647 | Z11: =$Z$40*$T11 -> 353.07294 | AA11: =$AA$40*$T11 -> 6884.9224 | AB11: =$AB$40*$T11 -> 44.134118 | AC11: =$AC$40*$T11 -> 3.3702417 | AD11: =$AD$40*$T11 -> 14.564259
A12: Czech Republic | B12: 293.10895 | C12: 222.2604 | D12: 139.48458 | E12: 16.1533 | F12: 21.009 | G12: 9.597 | H12: 30.546 | I12: =SUM(B12:H12) -> 732.15923 | J12: 83 | K12: =B12*$K$40 -> 8793.2684 | L12: =C12*$L$40 -> 13335.624 | M12: =D12*$M$40 -> 4184.5375 | N12: =E12*$N$40 -> 323.066 | O12: =F12*$O$40 -> 840.36 | P12: =G12*$P$40 -> 7485.66 | Q12: =H12*$Q$40 -> 152.73 | R12: =SUM(K12:Q12) -> 35115.246 | S12: =R12/I12 -> 47.961215 | T12: =J12/S12 -> 1.730565 | U12: =$U$40*$T12 -> 14.017577 | V12: =$V$40*$T12 -> 37.899374 | W12: =$W$40*$T12 -> 103.8339 | X12: =$X$40*$T12 -> 51.91695 | Y12: =$Y$40*$T12 -> 34.6113 | Z12: =$Z$40*$T12 -> 69.222601 | AA12: =$AA$40*$T12 -> 1349.8407 | AB12: =$AB$40*$T12 -> 8.6528251 | AC12: =$AC$40*$T12 -> 0.66076119 | AD12: =$AD$40*$T12 -> 2.8554323
A13: Denmark | B13: 402.40635 | C13: 1835.8244 | D13: 120.4885 | E13: 13.055525 | F13: 34.9 | G13: 0 | H13: 72 | I13: =SUM(B13:H13) -> 2478.6748 | J13: 42.1 | K13: =B13*$K$40 -> 12072.19 | L13: =C13*$L$40 -> 110149.47 | M13: =D13*$M$40 -> 3614.6551 | N13: =E13*$N$40 -> 261.1105 | O13: =F13*$O$40 -> 1396 | P13: =G13*$P$40 -> 0 | Q13: =H13*$Q$40 -> 360 | R13: =SUM(K13:Q13) -> 127853.42 | S13: =R13/I13 -> 51.581362 | T13: =J13/S13 -> 0.81618628 | U13: =$U$40*$T13 -> 6.6111089 | V13: =$V$40*$T13 -> 17.87448 | W13: =$W$40*$T13 -> 48.971177 | X13: =$X$40*$T13 -> 24.485589 | Y13: =$Y$40*$T13 -> 16.323726 | Z13: =$Z$40*$T13 -> 32.647451 | AA13: =$AA$40*$T13 -> 636.6253 | AB13: =$AB$40*$T13 -> 4.0809314 | AC13: =$AC$40*$T13 -> 0.31163476 | AD13: =$AD$40*$T13 -> 1.3467074
A14: Estonia | B14: 60.851755 | C14: 34.1163 | D14: 2.107912 | E14: 4.81992 | F14: 0.42 | G14: 0 | H14: 4.04 | I14: =SUM(B14:H14) -> 106.35589 | J14: 70.5 | K14: =B14*$K$40 -> 1825.5526 | L14: =C14*$L$40 -> 2046.978 | M14: =D14*$M$40 -> 63.23736 | N14: =E14*$N$40 -> 96.3984 | O14: =F14*$O$40 -> 16.8 | P14: =G14*$P$40 -> 0 | Q14: =H14*$Q$40 -> 20.2 | R14: =SUM(K14:Q14) -> 4069.1664 | S14: =R14/I14 -> 38.259908 | T14: =J14/S14 -> 1.84266 | U14: =$U$40*$T14 -> 14.925546 | V14: =$V$40*$T14 -> 40.354253 | W14: =$W$40*$T14 -> 110.5596 | X14: =$X$40*$T14 -> 55.279799 | Y14: =$Y$40*$T14 -> 36.853199 | Z14: =$Z$40*$T14 -> 73.706399 | AA14: =$AA$40*$T14 -> 1437.2748 | AB14: =$AB$40*$T14 -> 9.2132998 | AC14: =$AC$40*$T14 -> 0.70356108 | AD14: =$AD$40*$T14 -> 3.0403889
A15: Finland | B15: 224.39443 | C15: 181.63017 | D15: 61.818425 | E15: 10.66308 | F15: 11.275 | G15: 0 | H15: 30.2 | I15: =SUM(B15:H15) -> 519.9811 | J15: 21.3 | K15: =B15*$K$40 -> 6731.8329 | L15: =C15*$L$40 -> 10897.81 | M15: =D15*$M$40 -> 1854.5527 | N15: =E15*$N$40 -> 213.2616 | O15: =F15*$O$40 -> 451 | P15: =G15*$P$40 -> 0 | Q15: =H15*$Q$40 -> 151 | R15: =SUM(K15:Q15) -> 20299.457 | S15: =R15/I15 -> 39.038837 | T15: =J15/S15 -> 0.54561052 | U15: =$U$40*$T15 -> 4.4194452 | V15: =$V$40*$T15 -> 11.94887 | W15: =$W$40*$T15 -> 32.736631 | X15: =$X$40*$T15 -> 16.368316 | Y15: =$Y$40*$T15 -> 10.91221 | Z15: =$Z$40*$T15 -> 21.824421 | AA15: =$AA$40*$T15 -> 425.57621 | AB15: =$AB$40*$T15 -> 2.7280526 | AC15: =$AC$40*$T15 -> 0.20832402 | AD15: =$AD$40*$T15 -> 0.90025736
A16: France | B16: 3376.1277 | C16: 1901.9279 | D16: 1218.9662 | E16: 687.50356 | F16: 234 | G16: 54.5202 | H16: 311.8012 | I16: =SUM(B16:H16) -> 7784.8467 | J16: 114.3 | K16: =B16*$K$40 -> 101283.83 | L16: =C16*$L$40 -> 114115.67 | M16: =D16*$M$40 -> 36568.985 | N16: =E16*$N$40 -> 13750.071 | O16: =F16*$O$40 -> 9360 | P16: =G16*$P$40 -> 42525.756 | Q16: =H16*$Q$40 -> 1559.006 | R16: =SUM(K16:Q16) -> 319163.32 | S16: =R16/I16 -> 40.998023 | T16: =J16/S16 -> 2.7879393 | U16: =$U$40*$T16 -> 22.582309 | V16: =$V$40*$T16 -> 61.055871 | W16: =$W$40*$T16 -> 167.27636 | X16: =$X$40*$T16 -> 83.63818 | Y16: =$Y$40*$T16 -> 55.758787 | Z16: =$Z$40*$T16 -> 111.51757 | AA16: =$AA$40*$T16 -> 2174.5927 | AB16: =$AB$40*$T16 -> 13.939697 | AC16: =$AC$40*$T16 -> 1.0644859 | AD16: =$AD$40*$T16 -> 4.6000999
A17: Germany | B17: 3169.2478 | C17: 4032.9262 | D17: 1045.333 | E17: 146.24738 | F17: 20.83 | G17: 0.3598 | H17: 184.7116 | I17: =SUM(B17:H17) -> 8599.6557 | J17: 211.5 | K17: =B17*$K$40 -> 95077.433 | L17: =C17*$L$40 -> 241975.57 | M17: =D17*$M$40 -> 31359.989 | N17: =E17*$N$40 -> 2924.9476 | O17: =F17*$O$40 -> 833.2 | P17: =G17*$P$40 -> 280.644 | Q17: =H17*$Q$40 -> 923.558 | R17: =SUM(K17:Q17) -> 373375.34 | S17: =R17/I17 -> 43.417476 | T17: =J17/S17 -> 4.8713104 | U17: =$U$40*$T17 -> 39.457614 | V17: =$V$40*$T17 -> 106.6817 | W17: =$W$40*$T17 -> 292.27862 | X17: =$X$40*$T17 -> 146.13931 | Y17: =$Y$40*$T17 -> 97.426207 | Z17: =$Z$40*$T17 -> 194.85241 | AA17: =$AA$40*$T17 -> 3799.6221 | AB17: =$AB$40*$T17 -> 24.356552 | AC17: =$AC$40*$T17 -> 1.8599549 | AD17: =$AD$40*$T17 -> 8.0376621
A18: Greece | B18: na | C18: na | D18: na | E18: na | F18: na | G18: na | H18: na | I18: na | J18: na | K18: na | L18: na | M18: na | N18: na | O18: na | P18: na | Q18: na | R18: na | S18: na | T18: na | U18: na | V18: na | W18: na | X18: na | Y18: na | Z18: na | AA18: na | AB18: na | AC18: na | AD18: na
A19: Hungary | B19: 142.09475 | C19: 314.25459 | D19: 169.93186 | E19: 89.24334 | F19: 20.25 | G19: 1.1564 | H19: 29.6 | I19: =SUM(B19:H19) -> 766.53094 | J19: 192.5 | K19: =B19*$K$40 -> 4262.8425 | L19: =C19*$L$40 -> 18855.275 | M19: =D19*$M$40 -> 5097.9559 | N19: =E19*$N$40 -> 1784.8668 | O19: =F19*$O$40 -> 810 | P19: =G19*$P$40 -> 901.992 | Q19: =H19*$Q$40 -> 148 | R19: =SUM(K19:Q19) -> 31860.932 | S19: =R19/I19 -> 41.565096 | T19: =J19/S19 -> 4.6312896 | U19: =$U$40*$T19 -> 37.513446 | V19: =$V$40*$T19 -> 101.42524 | W19: =$W$40*$T19 -> 277.87738 | X19: =$X$40*$T19 -> 138.93869 | Y19: =$Y$40*$T19 -> 92.625793 | Z19: =$Z$40*$T19 -> 185.25159 | AA19: =$AA$40*$T19 -> 3612.4059 | AB19: =$AB$40*$T19 -> 23.156448 | AC19: =$AC$40*$T19 -> 1.7683106 | AD19: =$AD$40*$T19 -> 7.6416279
A20: Iceland | B20: 18.954035 | C20: 5.78006 | D20: 4.8897045 | E20: 47.305325 | F20: 5.309 | G20: 0 | H20: 31.3108 | I20: =SUM(B20:H20) -> 113.54892 | J20: 6 | K20: =B20*$K$40 -> 568.62105 | L20: =C20*$L$40 -> 346.8036 | M20: =D20*$M$40 -> 146.69114 | N20: =E20*$N$40 -> 946.1065 | O20: =F20*$O$40 -> 212.36 | P20: =G20*$P$40 -> 0 | Q20: =H20*$Q$40 -> 156.554 | R20: =SUM(K20:Q20) -> 2377.1363 | S20: =R20/I20 -> 20.934908 | T20: =J20/S20 -> 0.28660265 | U20: =$U$40*$T20 -> 2.3214814 | V20: =$V$40*$T20 -> 6.2765979 | W20: =$W$40*$T20 -> 17.196159 | X20: =$X$40*$T20 -> 8.5980794 | Y20: =$Y$40*$T20 -> 5.7320529 | Z20: =$Z$40*$T20 -> 11.464106 | AA20: =$AA$40*$T20 -> 223.55006 | AB20: =$AB$40*$T20 -> 1.4330132 | AC20: =$AC$40*$T20 -> 0.1094301 | AD20: =$AD$40*$T20 -> 0.47289436
A21: Ireland | B21: 1050.0358 | C21: 264.93223 | D21: 79.472362 | E21: 288.54328 | F21: 44.289 | G21: 0 | H21: 42.4 | I21: =SUM(B21:H21) -> 1769.6726 | J21: 46.4 | K21: =B21*$K$40 -> 31501.073 | L21: =C21*$L$40 -> 15895.934 | M21: =D21*$M$40 -> 2384.1709 | N21: =E21*$N$40 -> 5770.8656 | O21: =F21*$O$40 -> 1771.56 | P21: =G21*$P$40 -> 0 | Q21: =H21*$Q$40 -> 212 | R21: =SUM(K21:Q21) -> 57535.603 | S21: =R21/I21 -> 32.512004 | T21: =J21/S21 -> 1.4271652 | U21: =$U$40*$T21 -> 11.560038 | V21: =$V$40*$T21 -> 31.254918 | W21: =$W$40*$T21 -> 85.629912 | X21: =$X$40*$T21 -> 42.814956 | Y21: =$Y$40*$T21 -> 28.543304 | Z21: =$Z$40*$T21 -> 57.086608 | AA21: =$AA$40*$T21 -> 1113.1889 | AB21: =$AB$40*$T21 -> 7.135826 | AC21: =$AC$40*$T21 -> 0.54491762 | AD21: =$AD$40*$T21 -> 2.3548226
A22: Italy | B22: 1700.8071 | C22: 988.69559 | D22: 694.82065 | E22: 680.48156 | F22: 203.81 | G22: 33.0246 | H22: 195.0848 | I22: =SUM(B22:H22) -> 4496.7242 | J22: 371 | K22: =B22*$K$40 -> 51024.212 | L22: =C22*$L$40 -> 59321.735 | M22: =D22*$M$40 -> 20844.619 | N22: =E22*$N$40 -> 13609.631 | O22: =F22*$O$40 -> 8152.4 | P22: =G22*$P$40 -> 25759.188 | Q22: =H22*$Q$40 -> 975.424 | R22: =SUM(K22:Q22) -> 179687.21 | S22: =R22/I22 -> 39.959579 | T22: =J22/S22 -> 9.284382 | U22: =$U$40*$T22 -> 75.203494 | V22: =$V$40*$T22 -> 203.32797 | W22: =$W$40*$T22 -> 557.06292 | X22: =$X$40*$T22 -> 278.53146 | Y22: =$Y$40*$T22 -> 185.68764 | Z22: =$Z$40*$T22 -> 371.37528 | AA22: =$AA$40*$T22 -> 7241.818 | AB22: =$AB$40*$T22 -> 46.42191 | AC22: =$AC$40*$T22 -> 3.5449459 | AD22: =$AD$40*$T22 -> 15.31923
A24: Latvia | B24: 110.81131 | C24: 33.32429 | D24: 14.741691 | E24: 6.47888 | F24: 0.546 | G24: 0.0023534 | H24: 4.8156 | I24: =SUM(B24:H24) -> 170.72013 | J24: 36.7 | K24: =B24*$K$40 -> 3324.3394 | L24: =C24*$L$40 -> 1999.4574 | M24: =D24*$M$40 -> 442.25073 | N24: =E24*$N$40 -> 129.5776 | O24: =F24*$O$40 -> 21.84 | P24: =G24*$P$40 -> 1.835652 | Q24: =H24*$Q$40 -> 24.078 | R24: =SUM(K24:Q24) -> 5943.3788 | S24: =R24/I24 -> 34.81358 | T24: =J24/S24 -> 1.0541863 | U24: =$U$40*$T24 -> 8.5389093 | V24: =$V$40*$T24 -> 23.086681 | W24: =$W$40*$T24 -> 63.25118 | X24: =$X$40*$T24 -> 31.62559 | Y24: =$Y$40*$T24 -> 21.083727 | Z24: =$Z$40*$T24 -> 42.167453 | AA24: =$AA$40*$T24 -> 822.26534 | AB24: =$AB$40*$T24 -> 5.2709317 | AC24: =$AC$40*$T24 -> 0.40250751 | AD24: =$AD$40*$T24 -> 1.7394075
A25: Lithuania | B25: 212.75782 | C25: 69.583485 | D25: 40.581815 | E25: 4.60766 | F25: 3.273 | G25: 0.042 | H25: 5.6764 | I25: =SUM(B25:H25) -> 336.52218 | J25: 41.1 | K25: =B25*$K$40 -> 6382.7346 | L25: =C25*$L$40 -> 4175.0091 | M25: =D25*$M$40 -> 1217.4545 | N25: =E25*$N$40 -> 92.1532 | O25: =F25*$O$40 -> 130.92 | P25: =G25*$P$40 -> 32.76 | Q25: =H25*$Q$40 -> 28.382 | R25: =SUM(K25:Q25) -> 12059.413 | S25: =R25/I25 -> 35.835419 | T25: =J25/S25 -> 1.14691 | U25: =$U$40*$T25 -> 9.2899709 | V25: =$V$40*$T25 -> 25.117329 | W25: =$W$40*$T25 -> 68.814599 | X25: =$X$40*$T25 -> 34.4073 | Y25: =$Y$40*$T25 -> 22.9382 | Z25: =$Z$40*$T25 -> 45.876399 | AA25: =$AA$40*$T25 -> 894.58979 | AB25: =$AB$40*$T25 -> 5.7345499 | AC25: =$AC$40*$T25 -> 0.43791109 | AD25: =$AD$40*$T25 -> 1.8924015
A26: Luxembourg | B26: na | C26: na | D26: na | E26: na | F26: na | G26: na | H26: na | I26: na | J26: na | K26: na | L26: na | M26: na | N26: na | O26: na | P26: na | Q26: na | R26: na | S26: na | T26: na | U26: na | V26: na | W26: na | X26: na | Y26: na | Z26: na | AA26: na | AB26: na | AC26: na | AD26: na
A27: Malta | B27: na | C27: na | D27: na | E27: na | F27: na | G27: na | H27: na | I27: na | J27: na | K27: na | L27: na | M27: na | N27: na | O27: na | P27: na | Q27: na | R27: na | S27: na | T27: na | U27: na | V27: na | W27: na | X27: na | Y27: na | Z27: na | AA27: na | AB27: na | AC27: na | AD27: na
A28: Netherlands | B28: 973.71164 | C28: 1508.4118 | D28: 386.85527 | E28: 101.4038 | F28: 43.72 | G28: 2.6208 | H28: 169.2 | I28: =SUM(B28:H28) -> 3185.9233 | J28: 113.7 | K28: =B28*$K$40 -> 29211.349 | L28: =C28*$L$40 -> 90504.708 | M28: =D28*$M$40 -> 11605.658 | N28: =E28*$N$40 -> 2028.076 | O28: =F28*$O$40 -> 1748.8 | P28: =G28*$P$40 -> 2044.224 | Q28: =H28*$Q$40 -> 846 | R28: =SUM(K28:Q28) -> 137988.82 | S28: =R28/I28 -> 43.312033 | T28: =J28/S28 -> 2.6251365 | U28: =$U$40*$T28 -> 21.263606 | V28: =$V$40*$T28 -> 57.49049 | W28: =$W$40*$T28 -> 157.50819 | X28: =$X$40*$T28 -> 78.754096 | Y28: =$Y$40*$T28 -> 52.502731 | Z28: =$Z$40*$T28 -> 105.00546 | AA28: =$AA$40*$T28 -> 2047.6065 | AB28: =$AB$40*$T28 -> 13.125683 | AC28: =$AC$40*$T28 -> 1.0023249 | AD28: =$AD$40*$T28 -> 4.3314753
A29: Norway | B29: 227.51147 | C29: 126.48148 | D29: 63.725881 | E29: 102.49929 | F29: 1145.053 | G29: 0 | H29: 50 | I29: =SUM(B29:H29) -> 1715.2711 | J29: 3.5 | K29: =B29*$K$40 -> 6825.3443 | L29: =C29*$L$40 -> 7588.8888 | M29: =D29*$M$40 -> 1911.7764 | N29: =E29*$N$40 -> 2049.9857 | O29: =F29*$O$40 -> 45802.12 | P29: =G29*$P$40 -> 0 | Q29: =H29*$Q$40 -> 250 | R29: =SUM(K29:Q29) -> 64428.115 | S29: =R29/I29 -> 37.561476 | T29: =J29/S29 -> 0.093180577 | U29: =$U$40*$T29 -> 0.75476267 | V29: =$V$40*$T29 -> 2.0406546 | W29: =$W$40*$T29 -> 5.5908346 | X29: =$X$40*$T29 -> 2.7954173 | Y29: =$Y$40*$T29 -> 1.8636115 | Z29: =$Z$40*$T29 -> 3.7272231 | AA29: =$AA$40*$T29 -> 72.68085 | AB29: =$AB$40*$T29 -> 0.46590288 | AC29: =$AC$40*$T29 -> 0.035578038 | AD29: =$AD$40*$T29 -> 0.15374795
A30: Poland | B30: 1610.4309 | C30: 1550.5423 | D30: 739.15913 | E30: 17.86902 | F30: 34.24577 | G30: 0 | H30: 10.568 | I30: =SUM(B30:H30) -> 3962.8151 | J30: 126.3 | K30: =B30*$K$40 -> 48312.926 | L30: =C30*$L$40 -> 93032.537 | M30: =D30*$M$40 -> 22174.774 | N30: =E30*$N$40 -> 357.3804 | O30: =F30*$O$40 -> 1369.8308 | P30: =G30*$P$40 -> 0 | Q30: =H30*$Q$40 -> 52.84 | R30: =SUM(K30:Q30) -> 165300.29 | S30: =R30/I30 -> 41.712844 | T30: =J30/S30 -> 3.0278444 | U30: =$U$40*$T30 -> 24.525539 | V30: =$V$40*$T30 -> 66.309791 | W30: =$W$40*$T30 -> 181.67066 | X30: =$X$40*$T30 -> 90.835331 | Y30: =$Y$40*$T30 -> 60.556887 | Z30: =$Z$40*$T30 -> 121.11377 | AA30: =$AA$40*$T30 -> 2361.7186 | AB30: =$AB$40*$T30 -> 15.139222 | AC30: =$AC$40*$T30 -> 1.156086 | AD30: =$AD$40*$T30 -> 4.9959432
A31: Portugal | B31: 238.71105 | C31: 347.84921 | D31: 205.74179 | E31: 185.23904 | F31: 9.167 | G31: 7.5822894 | H31: 38.8 | I31: =SUM(B31:H31) -> 1033.0904 | J31: 159.2 | K31: =B31*$K$40 -> 7161.3314 | L31: =C31*$L$40 -> 20870.953 | M31: =D31*$M$40 -> 6172.2539 | N31: =E31*$N$40 -> 3704.7808 | O31: =F31*$O$40 -> 366.68 | P31: =G31*$P$40 -> 5914.1857 | Q31: =H31*$Q$40 -> 194 | R31: =SUM(K31:Q31) -> 44384.184 | S31: =R31/I31 -> 42.962538 | T31: =J31/S31 -> 3.7055539 | U31: =$U$40*$T31 -> 30.014987 | V31: =$V$40*$T31 -> 81.151631 | W31: =$W$40*$T31 -> 222.33324 | X31: =$X$40*$T31 -> 111.16662 | Y31: =$Y$40*$T31 -> 74.111078 | Z31: =$Z$40*$T31 -> 148.22216 | AA31: =$AA$40*$T31 -> 2890.3321 | AB31: =$AB$40*$T31 -> 18.52777 | AC31: =$AC$40*$T31 -> 1.4148479 | AD31: =$AD$40*$T31 -> 6.114164
A32: Romania | B32: na | C32: na | D32: na | E32: na | F32: na | G32: na | H32: na | I32: na | J32: na | K32: na | L32: na | M32: na | N32: na | O32: na | P32: na | Q32: na | R32: na | S32: na | T32: na | U32: na | V32: na | W32: na | X32: na | Y32: na | Z32: na | AA32: na | AB32: na | AC32: na | AD32: na
A33: Slovakia | B33: 103.58711 | C33: 58.055505 | D33: 49.960989 | E33: 33.662175 | F33: 0.913 | G33: 0 | H33: 2 | I33: =SUM(B33:H33) -> 248.17878 | J33: 43.6 | K33: =B33*$K$40 -> 3107.6134 | L33: =C33*$L$40 -> 3483.3303 | M33: =D33*$M$40 -> 1498.8297 | N33: =E33*$N$40 -> 673.2435 | O33: =F33*$O$40 -> 36.52 | P33: =G33*$P$40 -> 0 | Q33: =H33*$Q$40 -> 10 | R33: =SUM(K33:Q33) -> 8809.5369 | S33: =R33/I33 -> 35.496737 | T33: =J33/S33 -> 1.2282819 | U33: =$U$40*$T33 -> 9.9490836 | V33: =$V$40*$T33 -> 26.899374 | W33: =$W$40*$T33 -> 73.696916 | X33: =$X$40*$T33 -> 36.848458 | Y33: =$Y$40*$T33 -> 24.565639 | Z33: =$Z$40*$T33 -> 49.131277 | AA33: =$AA$40*$T33 -> 958.0599 | AB33: =$AB$40*$T33 -> 6.1414096 | AC33: =$AC$40*$T33 -> 0.46898037 | AD33: =$AD$40*$T33 -> 2.0266652
A34: Slovenia | B34: 101.37596 | C34: 25.082955 | D34: 35.818346 | E34: 9.95658 | F34: 0.056 | G34: 0.02478 | H34: 9.2776 | I34: =SUM(B34:H34) -> 181.59222 | J34: 46 | K34: =B34*$K$40 -> 3041.2787 | L34: =C34*$L$40 -> 1504.9773 | M34: =D34*$M$40 -> 1074.5504 | N34: =E34*$N$40 -> 199.1316 | O34: =F34*$O$40 -> 2.24 | P34: =G34*$P$40 -> 19.3284 | Q34: =H34*$Q$40 -> 46.388 | R34: =SUM(K34:Q34) -> 5887.8943 | S34: =R34/I34 -> 32.423715 | T34: =J34/S34 -> 1.4187146 | U34: =$U$40*$T34 -> 11.491589 | V34: =$V$40*$T34 -> 31.069851 | W34: =$W$40*$T34 -> 85.122879 | X34: =$X$40*$T34 -> 42.561439 | Y34: =$Y$40*$T34 -> 28.374293 | Z34: =$Z$40*$T34 -> 56.748586 | AA34: =$AA$40*$T34 -> 1106.5974 | AB34: =$AB$40*$T34 -> 7.0935732 | AC34: =$AC$40*$T34 -> 0.54169105 | AD34: =$AD$40*$T34 -> 2.3408792
A35: Spain | B35: 877.19362 | C35: 3382.7752 | D35: 707.50312 | E35: 1527.3576 | F35: 274.223 | G35: 73.735064 | H35: 277.3936 | I35: =SUM(B35:H35) -> 7120.1812 | J35: 335.8 | K35: =B35*$K$40 -> 26315.809 | L35: =C35*$L$40 -> 202966.51 | M35: =D35*$M$40 -> 21225.094 | N35: =E35*$N$40 -> 30547.153 | O35: =F35*$O$40 -> 10968.92 | P35: =G35*$P$40 -> 57513.35 | Q35: =H35*$Q$40 -> 1386.968 | R35: =SUM(K35:Q35) -> 350923.8 | S35: =R35/I35 -> 49.285797 | T35: =J35/S35 -> 6.813322 | U35: =$U$40*$T35 -> 55.187908 | V35: =$V$40*$T35 -> 149.21175 | W35: =$W$40*$T35 -> 408.79932 | X35: =$X$40*$T35 -> 204.39966 | Y35: =$Y$40*$T35 -> 136.26644 | Z35: =$Z$40*$T35 -> 272.53288 | AA35: =$AA$40*$T35 -> 5314.3911 | AB35: =$AB$40*$T35 -> 34.06661 | AC35: =$AC$40*$T35 -> 2.6014502 | AD35: =$AD$40*$T35 -> 11.241981
A36: Sweden | B36: 322.59156 | C36: 222.48702 | D36: 81.916355 | E36: 51.94592 | F36: 11.97 | G36: 0 | H36: 145.08 | I36: =SUM(B36:H36) -> 835.99086 | J36: 13.1 | K36: =B36*$K$40 -> 9677.7468 | L36: =C36*$L$40 -> 13349.221 | M36: =D36*$M$40 -> 2457.4907 | N36: =E36*$N$40 -> 1038.9184 | O36: =F36*$O$40 -> 478.8 | P36: =G36*$P$40 -> 0 | Q36: =H36*$Q$40 -> 725.4 | R36: =SUM(K36:Q36) -> 27727.577 | S36: =R36/I36 -> 33.167321 | T36: =J36/S36 -> 0.39496708 | U36: =$U$40*$T36 -> 3.1992333 | V36: =$V$40*$T36 -> 8.6497791 | W36: =$W$40*$T36 -> 23.698025 | X36: =$X$40*$T36 -> 11.849012 | Y36: =$Y$40*$T36 -> 7.8993416 | Z36: =$Z$40*$T36 -> 15.798683 | AA36: =$AA$40*$T36 -> 308.07432 | AB36: =$AB$40*$T36 -> 1.9748354 | AC36: =$AC$40*$T36 -> 0.15080561 | AD36: =$AD$40*$T36 -> 0.65169568
A37: Switzerland | B37: na | C37: na | D37: na | E37: na | F37: na | G37: na | H37: na | I37: na | J37: na | K37: na | L37: na | M37: na | N37: na | O37: na | P37: na | Q37: na | R37: na | S37: na | T37: na | U37: na | V37: na | W37: na | X37: na | Y37: na | Z37: na | AA37: na | AB37: na | AC37: na | AD37: na
A38: United Kingdom | B38: 1766.5662 | C38: 717.05057 | D38: 1011.8585 | E38: 2663.694 | F38: 170 | G38: 0 | H38: 395.2 | I38: =SUM(B38:H38) -> 6724.3692 | J38: 51 | K38: =B38*$K$40 -> 52996.985 | L38: =C38*$L$40 -> 43023.035 | M38: =D38*$M$40 -> 30355.755 | N38: =E38*$N$40 -> 53273.879 | O38: =F38*$O$40 -> 6800 | P38: =G38*$P$40 -> 0 | Q38: =H38*$Q$40 -> 1976 | R38: =SUM(K38:Q38) -> 188425.65 | S38: =R38/I38 -> 28.021313 | T38: =J38/S38 -> 1.8200432 | U38: =$U$40*$T38 -> 14.74235 | V38: =$V$40*$T38 -> 39.858946 | W38: =$W$40*$T38 -> 109.20259 | X38: =$X$40*$T38 -> 54.601296 | Y38: =$Y$40*$T38 -> 36.400864 | Z38: =$Z$40*$T38 -> 72.801728 | AA38: =$AA$40*$T38 -> 1419.6337 | AB38: =$AB$40*$T38 -> 9.100216 | AC38: =$AC$40*$T38 -> 0.69492558 | AD38: =$AD$40*$T38 -> 3.0030713
A40: Standard, mg per kg | K40: ='Standard values'!B5 -> 30 | L40: ='Standard values'!D5 -> 60 | M40: ='Standard values'!E5 -> 30 | N40: ='Standard values'!F5 -> 20 | O40: ='Standard values'!G5 -> 40 | P40: ='Standard values'!H5 -> 780 | Q40: ='Standard values'!I5 -> 5 | U40: ='Standard values'!B6 -> 8.1 | V40: ='Standard values'!C6 -> 21.9 | W40: ='Standard values'!D6 -> 60 | X40: ='Standard values'!E6 -> 30 | Y40: ='Standard values'!F6 -> 20 | Z40: ='Standard values'!G6 -> 40 | AA40: ='Standard values'!H6 -> 780 | AB40: ='Standard values'!I6 -> 5 | ... AD40: ='Standard values'!K6 -> 1.65

Sheet 2012
A2: Use of antibiotics index 2012
A4: Actual use | B4: https://esvacbi.ema.europa.eu/analytics/saw.dll?Dashboard | K4: Expected use | U4: Antibiotic use index
A5: PCU tonne
A6: Country | B6: Cattle | C6: Pigs | D6: Poultry | E6: Sheep and goats | F6: Fish | G6: Rabbits | H6: Horses | I6: Total PCU (tonnes) | J6: mg/PCU | K6: Cattle | L6: Pigs | M6: Poultry | N6: Sheep and goats | O6: Fish | P6: Rabbits | Q6: Horses | R6: Total | S6: mg/PCU | T6: Actual use/ expected use | U6: Beef cattle | V6: Dairy cows | W6: Pigs | X6: Broiler | Y6: Sheep and goat | Z6: Fish | AA6: Rabbits | AB6: Horses | AC6: Egg | AD6: Milk
A7: Austria | B7: 434.98995 | C7: 384.44137 | D7: 81.330642 | E7: 35.29124 | F7: 0 | G7: 0 | H7: 29.6488 | I7: =SUM(B7:H7) -> 965.702 | J7: 54.8 | K7: =B7*$K$39 -> 13049.699 | L7: =C7*$L$39 -> 23066.482 | M7: =D7*$M$39 -> 2439.9193 | N7: =E7*$N$39 -> 705.8248 | O7: =F7*$O$39 -> 0 | P7: =G7*$P$39 -> 0 | Q7: =H7*$Q$39 -> 148.244 | R7: =SUM(K7:Q7) -> 39410.169 | S7: =R7/I7 -> 40.809865 | T7: =J7/S7 -> 1.3428126 | U7: =$U$39*$T7 -> 10.876782 | V7: =$V$39*$T7 -> 29.407595 | W7: =$W$39*$T7 -> 80.568754 | X7: =$X$39*$T7 -> 40.284377 | Y7: =$Y$39*$T7 -> 26.856251 | Z7: =$Z$39*$T7 -> 53.712503 | AA7: =$AA$39*$T7 -> 1047.3938 | AB7: =$AB$39*$T7 -> 6.7140628 | AC7: =$AC$39*$T7 -> 0.51271025 | AD7: =$AD$39*$T7 -> 2.2156407
A8: Belgium | B8: 460.89678 | C8: 915.58085 | D8: 166.96735 | E8: 15.97238 | F8: 0.576 | G8: 4.077213 | H8: 94.2436 | I8: =SUM(B8:H8) -> 1658.3142 | J8: 162.9 | K8: =B8*$K$39 -> 13826.903 | L8: =C8*$L$39 -> 54934.851 | M8: =D8*$M$39 -> 5009.0205 | N8: =E8*$N$39 -> 319.4476 | O8: =F8*$O$39 -> 23.04 | P8: =G8*$P$39 -> 3180.2261 | Q8: =H8*$Q$39 -> 471.218 | R8: =SUM(K8:Q8) -> 77764.707 | S8: =R8/I8 -> 46.893832 | T8: =J8/S8 -> 3.4738044 | U8: =$U$39*$T8 -> 28.137816 | V8: =$V$39*$T8 -> 76.076316 | W8: =$W$39*$T8 -> 208.42826 | X8: =$X$39*$T8 -> 104.21413 | Y8: =$Y$39*$T8 -> 69.476088 | Z8: =$Z$39*$T8 -> 138.95218 | AA8: =$AA$39*$T8 -> 2709.5674 | AB8: =$AB$39*$T8 -> 17.369022 | AC8: =$AC$39*$T8 -> 1.3263617 | AD8: =$AD$39*$T8 -> 5.7317772
A9: Bulgaria | B9: 134.26176 | C9: 61.53789 | D9: 45.342606 | E9: 99.04402 | F9: 0 | G9: 0.01218 | H9: 48 | I9: =SUM(B9:H9) -> 388.19846 | J9: 98.9 | K9: =B9*$K$39 -> 4027.8528 | L9: =C9*$L$39 -> 3692.2734 | M9: =D9*$M$39 -> 1360.2782 | N9: =E9*$N$39 -> 1980.8804 | O9: =F9*$O$39 -> 0 | P9: =G9*$P$39 -> 9.5004 | Q9: =H9*$Q$39 -> 240 | R9: =SUM(K9:Q9) -> 11310.785 | S9: =R9/I9 -> 29.136605 | T9: =J9/S9 -> 3.3943556 | U9: =$U$39*$T9 -> 27.494281 | V9: =$V$39*$T9 -> 74.336388 | W9: =$W$39*$T9 -> 203.66134 | X9: =$X$39*$T9 -> 101.83067 | Y9: =$Y$39*$T9 -> 67.887112 | Z9: =$Z$39*$T9 -> 135.77422 | AA9: =$AA$39*$T9 -> 2647.5974 | AB9: =$AB$39*$T9 -> 16.971778 | AC9: =$AC$39*$T9 -> 1.2960267 | AD9: =$AD$39*$T9 -> 5.6006868
A10: Croatia | B10: na | C10: na | D10: na | E10: na | F10: na | G10: na | H10: na | I10: na | J10: na | K10: na | L10: na | M10: na | N10: na | O10: na | P10: na | Q10: na | R10: na | S10: na | T10: na | U10: na | V10: na | W10: na | X10: na | Y10: na | Z10: na | AA10: na | AB10: na | AC10: na | AD10: na
A11: Cyprus | B11: 18.731055 | C11: 51.03311 | D11: 12.727735 | E11: 59.8868 | F11: 4.334 | G11: 0.1594278 | H11: 2.0716 | I11: =SUM(B11:H11) -> 148.94373 | J11: 301.9 | K11: =B11*$K$39 -> 561.93165 | L11: =C11*$L$39 -> 3061.9866 | M11: =D11*$M$39 -> 381.83207 | N11: =E11*$N$39 -> 1197.736 | O11: =F11*$O$39 -> 173.36 | P11: =G11*$P$39 -> 124.35368 | Q11: =H11*$Q$39 -> 10.358 | R11: =SUM(K11:Q11) -> 5511.558 | S11: =R11/I11 -> 37.004297 | T11: =J11/S11 -> 8.1585119 | U11: =$U$39*$T11 -> 66.083946 | V11: =$V$39*$T11 -> 178.67141 | W11: =$W$39*$T11 -> 489.51071 | X11: =$X$39*$T11 -> 244.75536 | Y11: =$Y$39*$T11 -> 163.17024 | Z11: =$Z$39*$T11 -> 326.34048 | AA11: =$AA$39*$T11 -> 6363.6393 | AB11: =$AB$39*$T11 -> 40.79256 | AC11: =$AC$39*$T11 -> 3.1150682 | AD11: =$AD$39*$T11 -> 13.461545
A12: Czech Republic | B12: 283.85251 | C12: 197.56821 | D12: 111.5174 | E12: 17.04437 | F12: 20.8 | G12: 10.213 | H12: 31.7892 | I12: =SUM(B12:H12) -> 672.78469 | J12: 79.8 | K12: =B12*$K$39 -> 8515.5753 | L12: =C12*$L$39 -> 11854.093 | M12: =D12*$M$39 -> 3345.5221 | N12: =E12*$N$39 -> 340.8874 | O12: =F12*$O$39 -> 832 | P12: =G12*$P$39 -> 7966.14 | Q12: =H12*$Q$39 -> 158.946 | R12: =SUM(K12:Q12) -> 33013.163 | S12: =R12/I12 -> 49.069433 | T12: =J12/S12 -> 1.626267 | U12: =$U$39*$T12 -> 13.172763 | V12: =$V$39*$T12 -> 35.615248 | W12: =$W$39*$T12 -> 97.576021 | X12: =$X$39*$T12 -> 48.78801 | Y12: =$Y$39*$T12 -> 32.52534 | Z12: =$Z$39*$T12 -> 65.05068 | AA12: =$AA$39*$T12 -> 1268.4883 | AB12: =$AB$39*$T12 -> 8.1313351 | AC12: =$AC$39*$T12 -> 0.62093831 | AD12: =$AD$39*$T12 -> 2.6833406
A13: Denmark | B13: 409.94621 | C13: 1807.7919 | D13: 104.81644 | E13: 1.68252 | F13: 34.1 | G13: 0 | H13: 66 | I13: =SUM(B13:H13) -> 2424.3371 | J13: 43.7 | K13: =B13*$K$39 -> 12298.386 | L13: =C13*$L$39 -> 108467.52 | M13: =D13*$M$39 -> 3144.4931 | N13: =E13*$N$39 -> 33.6504 | O13: =F13*$O$39 -> 1364 | P13: =G13*$P$39 -> 0 | Q13: =H13*$Q$39 -> 330 | R13: =SUM(K13:Q13) -> 125638.05 | S13: =R13/I13 -> 51.82367 | T13: =J13/S13 -> 0.84324402 | U13: =$U$39*$T13 -> 6.8302766 | V13: =$V$39*$T13 -> 18.467044 | W13: =$W$39*$T13 -> 50.594641 | X13: =$X$39*$T13 -> 25.297321 | Y13: =$Y$39*$T13 -> 16.86488 | Z13: =$Z$39*$T13 -> 33.729761 | AA13: =$AA$39*$T13 -> 657.73034 | AB13: =$AB$39*$T13 -> 4.2162201 | AC13: =$AC$39*$T13 -> 0.3219659 | AD13: =$AD$39*$T13 -> 1.3913526
