Workbook

Sheet README
A2: Supplementary Material 1 to
A4: Advancing Metrics for Animal Welfare and Antibiotic Use in Sustainability Assessments of Diets
A6: by
A7: Lotta Rydhmer, Professor in Animal Breeding, Swedish University of Agricultural Sciences
A8: Elin Röös, Associate Professor in Sustainable Food Systems, Swedish University of Agricultural Sciences
A10: Explanation of the sheets:
A11: Sheets DK-Wild | B11: Calculations of the animal welfare indices for the different countries and for wild animals
B12: We provide data and calculations for three indices: The PAALA (presented in two versions; one none-normalised and one normalised), ALYS and PAALYS.
A13: Mortality | B13: Mortality rates used to calculate 'suffering'
A14: Disease | B14: Disease rates used to calculate 'suffering'
A15: Slaughter | B15: Slaughtering times used to calculate 'suffering'
A16: Space | B16: Summary of space used to calculate 'suffering'
A17: No affected | B17: No of animals affected to produce 1 kg of edible product
A18: Ability | B18: Ability of animals to perceive negative effects of being used by humans, see SM4 for more information
A19: Life duration | B19: Life duration in years
A20: Space cattle-rabbit | B20: Calculations of the relative lack of space, summarised in tab 'Space'
A21: Fig.1-3 | B21: Figures 1-3 use in the manuscript
A23: See the main paper and SM5 for references and further information

Sheet DK
A2: Denmark
B5: Perception Adjusted Animal Lifes Affected (PAALA) | E5: Perception Adjusted Animal Lifes Affected (PAALA) - normalised | H5: Animal Life Years Suffered (ALYS) | K5: Perception Adjusted Animal Life Years Suffered (PAALYS)
B6: Total | C6: Prod. animal | D6: Parent | E6: Total | F6: Prod. animal | G6: Parent | H6: Total | I6: Prod. animal | J6: Parent | K6: Total | L6: Prod. animal | M6: Parent
A7: Beef suckler herds | B7: =C7+D7 -> 0.31576874 | C7: =B22*C22*D22*100 -> 0.28164624 | D7: =Q22*R22*S22*100 -> 0.034122499 | E7: =F7+G7 -> 0.05518435 | F7: =B22*C22*E22*100 -> 0.048895142 | G7: =Q22*R22*T22*100 -> 0.0062892076 | H7: =I7+J7 -> 0.0010560418 | I7: =B22*((O22-P22)*F22+P22) -> 0.00098695068 | J7: =Q22*((AD22-AE22)*U22+AE22) -> 6.9091138e-05 | K7: =L7+M7 -> 0.00093364977 | L7: =C22*B22*((O22-P22)*F22+P22) -> 0.00087256609 | M7: =R22*Q22*((AD22-AE22)*U22+AE22) -> 6.1083685e-05
A8: Beef dairy int | B8: =C8+D8 -> 0.57829644 | C8: =B23*C23*D23*100 -> 0.57829644 | E8: =F8+G8 -> 0.13307985 | F8: =B23*C23*E23*100 -> 0.13307985 | H8: =I8+J8 -> 0.00097634575 | I8: =B23*((O23-P23)*F23+P23) -> 0.00097634575 | K8: =L8+M8 -> 0.00080104083 | L8: =C23*B23*((O23-P23)*F23+P23) -> 0.00080104083
A9: Beef dairy ext | B9: =C9+D9 -> 0.32507461 | C9: =B24*C24*D24*100 -> 0.32507461 | E9: =F9+G9 -> 0.070582277 | F9: =B24*C24*E24*100 -> 0.070582277 | H9: =I9+J9 -> 0.0012286336 | I9: =B24*((O24-P24)*F24+P24) -> 0.0012286336 | K9: =L9+M9 -> 0.0010862387 | L9: =C24*B24*((O24-P24)*F24+P24) -> 0.0010862387
A10: Milk | B10: =C10+D10 -> 0.008538074 | C10: =B25*C25*D25*100 -> 0.008538074 | E10: =F10+G10 -> 0.0019170719 | F10: =B25*C25*E25*100 -> 0.0019170719 | H10: =I10+J10 -> 0.00013970636 | I10: =B25*((O25-P25)*F25+P25) -> 0.00013970636 | K10: =L10+M10 -> 0.00012351482 | L10: =C25*B25*((O25-P25)*F25+P25) -> 0.00012351482
A11: Horse meat | B11: =C11+D11 -> 0.34620382 | C11: =B26*C26*D26*100 -> 0.34620382 | E11: =F11+G11 -> 0.082186672 | F11: =B26*C26*E26*100 -> 0.082186672 | H11: =I11+J11 -> 0.0014989123 | I11: =B26*((O26-P26)*F26+P26) -> 0.0014989123 | K11: =L11+M11 -> 0.001317748 | L11: =C26*B26*((O26-P26)*F26+P26) -> 0.001317748
A12: Lamb meat | B12: =C12+D12 -> 4.1224012 | C12: =B27*C27*D27*100 -> 4.0471472 | D12: =Q27*R27*S27*100 -> 0.075254018 | E12: =F12+G12 -> 0.89923742 | F12: =B27*C27*E27*100 -> 0.88543037 | G12: =Q27*R27*T27*100 -> 0.013807045 | H12: =I12+J12 -> 0.0043800099 | I12: =B27*((O27-P27)*F27+P27) -> 0.0043086944 | J12: =Q27*((AD27-AE27)*U27+AE27) -> 7.1315515e-05 | K12: =L12+M12 -> 0.0035981096 | L12: =C27*B27*((O27-P27)*F27+P27) -> 0.0035350593 | M12: =R27*Q27*((AD27-AE27)*U27+AE27) -> 6.3050263e-05
A13: Pig meat | B13: =C13+D13 -> 3.681158 | C13: =B28*C28*D28*100 -> 3.6383624 | D13: =Q28*R28*S28*100 -> 0.042795565 | E13: =F13+G13 -> 0.61216208 | F13: =B28*C28*E28*100 -> 0.60450337 | G13: =Q28*R28*T28*100 -> 0.0076587134 | H13: =I13+J13 -> 0.0042211936 | I13: =B28*((O28-P28)*F28+P28) -> 0.0042190088 | J13: =Q28*((AD28-AE28)*U28+AE28) -> 2.1848155e-06 | K13: =L13+M13 -> 0.0037140045 | L13: =C28*B28*((O28-P28)*F28+P28) -> 0.0037119331 | M13: =R28*Q28*((AD28-AE28)*U28+AE28) -> 2.0713284e-06
A14: Chicken meat | B14: =C14+D14 -> 70.338716 | C14: =B29*C29*D29*100 -> 69.763721 | D14: =Q29*R29*S29*100 -> 0.57499416 | E14: =F14+G14 -> 9.2459382 | F14: =B29*C29*E29*100 -> 9.1214997 | G14: =Q29*R29*T29*100 -> 0.12443855 | H14: =I14+J14 -> 0.022516988 | I14: =B29*((O29-P29)*F29+P29) -> 0.022498842 | J14: =Q29*((AD29-AE29)*U29+AE29) -> 1.8145616e-05 | K14: =L14+M14 -> 0.012231414 | L14: =C29*B29*((O29-P29)*F29+P29) -> 0.012221557 | M14: =R29*Q29*((AD29-AE29)*U29+AE29) -> 9.8568487e-06
A15: Rabbit meat
A16: Egg | B16: =C16+D16 -> 6.7130159 | C16: =B31*C31*D31*100 -> 6.7032523 | D16: =Q31*R31*S31*100 -> 0.0097635475 | E16: =F16+G16 -> 1.3425309 | F16: =B31*C31*E31*100 -> 1.3411361 | G16: =Q31*R31*T31*100 -> 0.0013947925 | H16: =I16+J16 -> 0.031174696 | I16: =B31*((O31-P31)*F31+P31) -> 0.031173649 | J16: =Q31*((AD31-AE31)*U31+AE31) -> 1.0464231e-06 | K16: =L16+M16 -> 0.018247476 | L16: =C31*B31*((O31-P31)*F31+P31) -> 0.018247208 | M16: =R31*Q31*((AD31-AE31)*U31+AE31) -> 2.6749445e-07
A18: Animal data
B20: PRODUCTION ANIMALS | G20: Non-normalised | K20: Normalised | Q20: PARENT ANIMALS (male chicks for hen) | V20: Non-normalised | Z20: Normalised
B21: Number affected | C21: Ability - normalised | D21: Suffering | E21: Suffering - normalised | F21: Suffering norm ex. slaughter | G21: Mortality | H21: Disease | I21: Slaughter | J21: Space | K21: Mortality | L21: Disease | M21: Slaughter | N21: Space | O21: Life duration (years) | P21: Slaughter duration (years) | Q21: Number affected | R21: Ability | S21: Suffering | T21: Suffering norm | U21: Suffering norm ex. slaughter | V21: Mortality | W21: Disease | X21: Slaughter | Y21: Space | Z21: Mortality | AA21: Disease | AB21: Slaughter | AC21: Space | AD21: Life duration (years) | AE21: Slaughter duration (years)
A22: Cattle suckler herds | B22: ='No affected'!B7 -> 0.0035 | C22: =Ability!B6 -> 0.88410303 | D22: =2*G22+2*H22+I22+2*J22 -> 0.91019204 | E22: =(2*K22+2*L22+N22+2*M22)/7 -> 0.15801372 | F22: =(K22+L22+N22)/3 -> 0.14069867 | G22: =Mortality!B8 -> 0.042 | H22: =Disease!B8 -> 0.05 | I22: =Slaughter!B8/24 -> 0.25 | J22: =Space!B8/100 -> 0.23809602 | K22: =Mortality!B8/Mortality!$B$4 -> 0.084 | L22: =Disease!B8/Disease!$B$4 -> 0.1 | M22: =Slaughter!B8/Slaughter!$B$4 -> 0.25 | N22: =Space!B8/Space!$B$4 -> 0.23809602 | O22: ='Life duration'!B7 -> 2 | P22: =Slaughter!B8/(365*24) -> 0.00068493151 | Q22: ='No affected'!Q7 -> 0.0008 | R22: =Ability!D6 -> 0.88410303 | S22: =2*V22+2*W22+X22+2*Y22 -> 0.48244517 | T22: =(2*Z22+2*AA22+AB22+2*AC22)/7 -> 0.088920739 | U22: =(Z22+AA22+AC22)/3 -> 0.062074195 | V22: =Mortality!Q8 -> 0.03 | W22: =Disease!Q8 -> 0.04 | X22: =Slaughter!Q8/24 -> 0.25 | Y22: =Space!Q8/100 -> 0.046222585 | Z22: =Mortality!Q8/Mortality!$B$4 -> 0.06 | AA22: =Disease!Q8/Disease!$B$4 -> 0.08 | AB22: =Slaughter!Q8/Slaughter!$B$4 -> 0.25 | AC22: =Space!Q8/Space!$B$4 -> 0.046222585 | AD22: ='Life duration'!Q7 -> 1.3809524 | AE22: =Slaughter!Q8/(365*24) -> 0.00068493151
A23: Meat cattle dairy intensive | B23: ='No affected'!B8 -> 0.009 | C23: =Ability!B7 -> 0.82044792 | D23: =2*G23+2*H23+I23+2*J23 -> 0.78317172 | E23: =(2*K23+2*L23+N23+2*M23)/7 -> 0.18022655 | F23: =(K23+L23+N23)/3 -> 0.14386195 | G23: =Mortality!B9 -> 0.065 | H23: =Disease!B9 -> 0.1 | I23: =Slaughter!B9/24 -> 0.25 | J23: =Space!B9/100 -> 0.10158586 | K23: =Mortality!B9/Mortality!$B$4 -> 0.13 | L23: =Disease!B9/Disease!$B$4 -> 0.2 | M23: =Slaughter!B9/Slaughter!$B$4 -> 0.25 | N23: =Space!B9/Space!$B$4 -> 0.10158586 | O23: ='Life duration'!B8 -> 0.75 | P23: =Slaughter!B9/(365*24) -> 0.00068493151
A24: Meat cattle dairy extensive | B24: ='No affected'!B9 -> 0.005 | C24: =Ability!B8 -> 0.88410303 | D24: =2*G24+2*H24+I24+2*J24 -> 0.73537721 | E24: =(2*K24+2*L24+N24+2*M24)/7 -> 0.1596698 | F24: =(K24+L24+N24)/3 -> 0.12256287 | G24: =Mortality!B10 -> 0.075 | H24: =Disease!B10 -> 0.05 | I24: =Slaughter!B10/24 -> 0.25 | J24: =Space!B10/100 -> 0.1176886 | K24: =Mortality!B10/Mortality!$B$4 -> 0.15 | L24: =Disease!B10/Disease!$B$4 -> 0.1 | M24: =Slaughter!B10/Slaughter!$B$4 -> 0.25 | N24: =Space!B10/Space!$B$4 -> 0.1176886 | O24: ='Life duration'!B9 -> 2 | P24: =Slaughter!B10/(365*24) -> 0.00068493151
A25: Dairy cows | B25: ='No affected'!B10 -> 0.0001 | C25: =Ability!B9 -> 0.88410303 | D25: =2*G25+2*H25+I25+2*J25 -> 0.96573292 | E25: =(2*K25+2*L25+N25+2*M25)/7 -> 0.21683807 | F25: =(K25+L25+N25)/3 -> 0.19262215 | G25: =Mortality!B11 -> 0.06 | H25: =Disease!B11 -> 0.16 | I25: =Slaughter!B11/24 -> 0.25 | J25: =Space!B11/100 -> 0.13786646 | K25: =Mortality!B11/Mortality!$B$4 -> 0.12 | L25: =Disease!B11/Disease!$B$4 -> 0.32 | M25: =Slaughter!B11/Slaughter!$B$4 -> 0.25 | N25: =Space!B11/Space!$B$4 -> 0.13786646 | O25: ='Life duration'!B10 -> 7.25 | P25: =Slaughter!B11/(365*24) -> 0.00068493151
A26: Horse | B26: ='No affected'!B11 -> 0.005 | C26: =Ability!B10 -> 0.87913616 | D26: =2*G26+2*H26+I26+2*J26 -> 0.7876 | E26: =(2*K26+2*L26+N26+2*M26)/7 -> 0.18697143 | F26: =(K26+L26+N26)/3 -> 0.1496 | G26: =Mortality!B12 -> 0.03 | H26: =Disease!B12 -> 0.15 | I26: =Slaughter!B12/24 -> 0.25 | J26: =Space!B12/100 -> 0.0888 | K26: =Mortality!B12/Mortality!$B$4 -> 0.06 | L26: =Disease!B12/Disease!$B$4 -> 0.3 | M26: =Slaughter!B12/Slaughter!$B$4 -> 0.25 | N26: =Space!B12/Space!$B$4 -> 0.0888 | O26: ='Life duration'!B11 -> 2 | P26: =Slaughter!B12/(365*24) -> 0.00068493151
A27: Lamb | B27: ='No affected'!B12 -> 0.064 | C27: =Ability!B11 -> 0.82044792 | D27: =2*G27+2*H27+I27+2*J27 -> 0.77075794 | E27: =(2*K27+2*L27+N27+2*M27)/7 -> 0.16862557 | F27: =(K27+L27+N27)/3 -> 0.13345966 | G27: =Mortality!B13 -> 0.08 | H27: =Disease!B13 -> 0.06 | I27: =Slaughter!B13/24 -> 0.25 | J27: =Space!B13/100 -> 0.12037897 | K27: =Mortality!B13/Mortality!$B$4 -> 0.16 | L27: =Disease!B13/Disease!$B$4 -> 0.12 | M27: =Slaughter!B13/Slaughter!$B$4 -> 0.25 | N27: =Space!B13/Space!$B$4 -> 0.12037897 | O27: ='Life duration'!B12 -> 0.5 | P27: =Slaughter!B13/(365*24) -> 0.00068493151 | Q27: ='No affected'!Q12 -> 0.0011 | R27: =Ability!D11 -> 0.88410303 | S27: =2*V27+2*W27+X27+2*Y27 -> 0.77380963 | T27: =(2*Z27+2*AA27+AB27+2*AC27)/7 -> 0.1419728 | U27: =(Z27+AA27+AC27)/3 -> 0.12396827 | V27: =Mortality!Q13 -> 0.06 | W27: =Disease!Q13 -> 0.05 | X27: =Slaughter!Q13/24 -> 0.25 | Y27: =Space!Q13/100 -> 0.15190481 | Z27: =Mortality!Q13/Mortality!$B$4 -> 0.12 | AA27: =Disease!Q13/Disease!$B$4 -> 0.1 | AB27: =Slaughter!Q13/Slaughter!$B$4 -> 0.25 | AC27: =Space!Q13/Space!$B$4 -> 0.15190481 | AD27: ='Life duration'!Q12 -> 0.51813472 | AE27: =Slaughter!Q13/(365*24) -> 0.00068493151
A28: Pig | B28: ='No affected'!B13 -> 0.018170212 | C28: =Ability!B12 -> 0.87981166 | D28: =2*G28+2*H28+I28+2*J28 -> 2.2759161 | E28: =(2*K28+2*L28+N28+2*M28)/7 -> 0.37813686 | F28: =(K28+L28+N28)/3 -> 0.46365268 | G28: =Mortality!B14 -> 0.228 | H28: =Disease!B14 -> 0.15 | I28: =Slaughter!B14/24 -> 0.25 | J28: =Space!B14/100 -> 0.63495804 | K28: =Mortality!B14/Mortality!$B$4 -> 0.456 | L28: =Disease!B14/Disease!$B$4 -> 0.3 | M28: =Slaughter!B14/Slaughter!$B$4 -> 0.25 | N28: =Space!B14/Space!$B$4 -> 0.63495804 | O28: ='Life duration'!B13 -> 0.5 | P28: =Slaughter!B14/(365*24) -> 0.00068493151 | Q28: ='No affected'!Q13 -> 0.00031 | R28: =Ability!D12 -> 0.94805646 | S28: =2*V28+2*W28+X28+2*Y28 -> 1.4561391 | T28: =(2*Z28+2*AA28+AB28+2*AC28)/7 -> 0.2605913 | U28: =(Z28+AA28+AC28)/3 -> 0.26235652 | V28: =Mortality!Q14 -> 0.034 | W28: =Disease!Q14 -> 0.15 | X28: =Slaughter!Q14/24 -> 0.25 | Y28: =Space!Q14/100 -> 0.41906956 | Z28: =Mortality!Q14/Mortality!$B$4 -> 0.068 | AA28: =Disease!Q14/Disease!$B$4 -> 0.3 | AB28: =Slaughter!Q14/Slaughter!$B$4 -> 0.25 | AC28: =Space!Q14/Space!$B$4 -> 0.41906956 | AD28: ='Life duration'!Q13 -> 0.024937656 | AE28: =Slaughter!Q14/(365*24) -> 0.00068493151
A29: Chicken | B29: ='No affected'!B14 -> 0.75216903 | C29: =Ability!B13 -> 0.54320828 | D29: =2*G29+2*H29+I29+2*J29 -> 1.7074493 | E29: =(2*K29+2*L29+N29+2*M29)/7 -> 0.22324638 | F29: =(K29+L29+N29)/3 -> 0.3077971 | G29: =Mortality!B15 -> 0.038 | H29: =Disease!B15 -> 0.115 | I29: =Slaughter!B15/24 -> 0.16666667 | J29: =Space!B15/100 -> 0.6173913 | K29: =Mortality!B15/Mortality!$B$4 -> 0.076 | L29: =Disease!B15/Disease!$B$4 -> 0.23 | M29: =Slaughter!B15/Slaughter!$B$4 -> 0.16666667 | N29: =Space!B15/Space!$B$4 -> 0.6173913 | O29: ='Life duration'!B14 -> 0.096153846 | P29: =Slaughter!B15/(365*24) -> 0.000456621 | Q29: ='No affected'!Q14 -> 0.0054505002 | R29: =Ability!D13 -> 0.54320828 | S29: =2*V29+2*W29+X29+2*Y29 -> 1.9420513 | T29: =(2*Z29+2*AA29+AB29+2*AC29)/7 -> 0.42029304 | U29: =(Z29+AA29+AC29)/3 -> 0.4625641 | V29: =Mortality!Q15 -> 0.06 | W29: =Disease!Q15 -> 0.44 | X29: =Slaughter!Q15/24 -> 0.16666667 | Y29: =Space!Q15/100 -> 0.38769231 | Z29: =Mortality!Q15/Mortality!$B$4 -> 0.12 | AA29: =Disease!Q15/Disease!$B$4 -> 0.88 | AB29: =Slaughter!Q15/Slaughter!$B$4 -> 0.16666667 | AC29: =Space!Q15/Space!$B$4 -> 0.38769231 | AD29: ='Life duration'!Q14 -> 0.0066666667 | AE29: =Slaughter!Q15/(365*24) -> 0.000456621
A30: Rabbit
A31: Laying hen | B31: ='No affected'!B16 -> 0.055 | C31: =Ability!B15 -> 0.58534078 | D31: =2*G31+2*H31+I31+2*J31 -> 2.08216 | E31: =(2*K31+2*L31+N31+2*M31)/7 -> 0.41658286 | F31: =(K31+L31+N31)/3 -> 0.47202667 | G31: =Mortality!B17 -> 0.04 | H31: =Disease!B17 -> 0.46 | I31: =Slaughter!B17/24 -> 0.25 | J31: =Space!B17/100 -> 0.41608 | K31: =Mortality!B17/Mortality!$B$4 -> 0.08 | L31: =Disease!B17/Disease!$B$4 -> 0.92 | M31: =Slaughter!B17/Slaughter!$B$4 -> 0.25 | N31: =Space!B17/Space!$B$4 -> 0.41608 | O31: ='Life duration'!B16 -> 1.2 | P31: =Slaughter!B17/(365*24) -> 0.00068493151 | Q31: ='No affected'!Q16 -> 0.055 | R31: =Ability!D15 -> 0.25562743 | S31: =2*V31+2*W31+X31+2*Y31 -> 0.0069444444 | T31: =(2*Z31+2*AA31+AB31+2*AC31)/7 -> 0.00099206349 | U31: =(Z31+AA31+AC31)/3 -> 0 | V31: =Mortality!Q17 -> 0 | W31: =Disease!Q17 -> 0 | X31: =Slaughter!Q17/24 -> 0.0069444444 | Y31: =Space!Q17/100 -> 0 | Z31: =Mortality!Q17/Mortality!$B$4 -> 0 | AA31: =Disease!Q17/Disease!$B$4 -> 0 | AB31: =Slaughter!Q17/Slaughter!$B$4 -> 0.0069444444 | AC31: =Space!Q17/Space!$B$4 -> 0 | AD31: ='Life duration'!Q16 -> 3.1709792e-07 | AE31: =Slaughter!Q17/(365*24) -> 1.9025875e-05

Sheet FR
A2: France
B5: Perception Adjusted Animal Lifes Affected (PAALA) | E5: Perception Adjusted Animal Lifes Affected (PAALA) - normalised | H5: Animal Life Years Suffered (ALYS) | K5: Perception Adjusted Animal Life Years Suffered (PAALYS)
B6: Total | C6: Prod. animal | D6: Parent | E6: Total | F6: Prod. animal | G6: Parent | H6: Total | I6: Prod. animal | J6: Parent | K6: Total | L6: Prod. animal | M6: Parent
A7: Beef suckler herds | B7: =C7+D7 -> 0.30083659 | C7: =B22*C22*D22*100 -> 0.25915331 | D7: =Q22*R22*S22*100 -> 0.041683278 | E7: =F7+G7 -> 0.060736032 | F7: =B22*C22*E22*100 -> 0.053366713 | G7: =Q22*R22*T22*100 -> 0.0073693189 | H7: =I7+J7 -> 0.00086812858 | I7: =B22*((O22-P22)*F22+P22) -> 0.00079604621 | J7: =Q22*((AD22-AE22)*U22+AE22) -> 7.2082363e-05 | K7: =L7+M7 -> 0.00076751511 | L7: =C22*B22*((O22-P22)*F22+P22) -> 0.00070378687 | M7: =R22*Q22*((AD22-AE22)*U22+AE22) -> 6.3728236e-05
A8: Beef dairy int | B8: =C8+D8 -> 0.74383519 | C8: =B23*C23*D23*100 -> 0.74383519 | E8: =F8+G8 -> 0.15940839 | F8: =B23*C23*E23*100 -> 0.15940839 | H8: =I8+J8 -> 0.0011271777 | I8: =B23*((O23-P23)*F23+P23) -> 0.0011271777 | K8: =L8+M8 -> 0.00092479057 | L8: =C23*B23*((O23-P23)*F23+P23) -> 0.00092479057
A9: Beef dairy ext | B9: =C9+D9 -> 0.39939441 | C9: =B24*C24*D24*100 -> 0.39939441 | E9: =F9+G9 -> 0.08457399 | F9: =B24*C24*E24*100 -> 0.08457399 | H9: =I9+J9 -> 0.0013571059 | I9: =B24*((O24-P24)*F24+P24) -> 0.0013571059 | K9: =L9+M9 -> 0.0011998214 | L9: =C24*B24*((O24-P24)*F24+P24) -> 0.0011998214
A10: Milk | B10: =C10+D10 -> 0.0084023563 | C10: =B25*C25*D25*100 -> 0.0084023563 | E10: =F10+G10 -> 0.0020810409 | F10: =B25*C25*E25*100 -> 0.0020810409 | H10: =I10+J10 -> 0.00012679702 | I10: =B25*((O25-P25)*F25+P25) -> 0.00012679702 | K10: =L10+M10 -> 0.00011210163 | L10: =C25*B25*((O25-P25)*F25+P25) -> 0.00011210163
A11: Horse meat | B11: =C11+D11 -> 0.41846881 | C11: =B26*C26*D26*100 -> 0.41846881 | E11: =F11+G11 -> 0.10712902 | F11: =B26*C26*E26*100 -> 0.10712902 | H11: =I11+J11 -> 0.0014254066 | I11: =B26*((O26-P26)*F26+P26) -> 0.0014254066 | K11: =L11+M11 -> 0.0012531265 | L11: =C26*B26*((O26-P26)*F26+P26) -> 0.0012531265
A12: Lamb meat | B12: =C12+D12 -> 4.5747956 | C12: =B27*C27*D27*100 -> 4.4991578 | D12: =Q27*R27*S27*100 -> 0.075637895 | E12: =F12+G12 -> 1.0384714 | F12: =B27*C27*E27*100 -> 1.0246095 | G12: =Q27*R27*T27*100 -> 0.013861884 | H12: =I12+J12 -> 0.0043385944 | I12: =B27*((O27-P27)*F27+P27) -> 0.0042756616 | J12: =Q27*((AD27-AE27)*U27+AE27) -> 6.2932879e-05 | K12: =L12+M12 -> 0.0035635968 | L12: =C27*B27*((O27-P27)*F27+P27) -> 0.0035079576 | M12: =R27*Q27*((AD27-AE27)*U27+AE27) -> 5.5639149e-05
A13: Pig meat | B13: =C13+D13 -> 3.760599 | C13: =B28*C28*D28*100 -> 3.7095163 | D13: =Q28*R28*S28*100 -> 0.051082738 | E13: =F13+G13 -> 0.63515065 | F13: =B28*C28*E28*100 -> 0.62610869 | G13: =Q28*R28*T28*100 -> 0.009041958 | H13: =I13+J13 -> 0.0041152457 | I13: =B28*((O28-P28)*F28+P28) -> 0.0041124087 | J13: =Q28*((AD28-AE28)*U28+AE28) -> 2.8370451e-06 | K13: =L13+M13 -> 0.0036208348 | L13: =C28*B28*((O28-P28)*F28+P28) -> 0.0036181451 | M13: =R28*Q28*((AD28-AE28)*U28+AE28) -> 2.6896789e-06
A14: Chicken meat | B14: =C14+D14 -> 76.379315 | C14: =B29*C29*D29*100 -> 75.793303 | D14: =Q29*R29*S29*100 -> 0.586012 | E14: =F14+G14 -> 10.429945 | F14: =B29*C29*E29*100 -> 10.303688 | G14: =Q29*R29*T29*100 -> 0.12625711 | H14: =I14+J14 -> 0.024732817 | I14: =B29*((O29-P29)*F29+P29) -> 0.024714358 | J14: =Q29*((AD29-AE29)*U29+AE29) -> 1.8459069e-05 | K14: =L14+M14 -> 0.013435071 | L14: =C29*B29*((O29-P29)*F29+P29) -> 0.013425044 | M14: =R29*Q29*((AD29-AE29)*U29+AE29) -> 1.0027119e-05
A15: Rabbit meat | B15: =C15+D15 -> 121.28923 | C15: =B30*C30*D30*100 -> 121.28923 | E15: =F15+G15 -> 22.612554 | F15: =B30*C30*E30*100 -> 22.612554 | H15: =I15+J15 -> 0.059685451 | I15: =B30*((O30-P30)*F30+P30) -> 0.059685451 | K15: =L15+M15 -> 0.040106712 | L15: =C30*B30*((O30-P30)*F30+P30) -> 0.040106712
A16: Egg | B16: =C16+D16 -> 6.8057358 | C16: =B31*C31*D31*100 -> 6.8057358 | D16: =Q31*R31*S31*100 -> 0 | E16: =F16+G16 -> 1.3317846 | F16: =B31*C31*E31*100 -> 1.3317846 | G16: =Q31*R31*T31*100 -> 0 | H16: =I16+J16 -> 0.030692009 | I16: =B31*((O31-P31)*F31+P31) -> 0.030692009 | J16: =Q31*((AD31-AE31)*U31+AE31) -> 0 | K16: =L16+M16 -> 0.017965285 | L16: =C31*B31*((O31-P31)*F31+P31) -> 0.017965285 | M16: =R31*Q31*((AD31-AE31)*U31+AE31) -> 0
A18: Animal data
B20: PRODUCTION ANIMALS | G20: Non-normalised | K20: Normalised | Q20: PARENT ANIMALS (male chicks for hen) | V20: Non-normalised | Z20: Normalised
B21: Number affected | C21: Ability - normalised | D21: Suffering | E21: Suffering - normalised | F21: Suffering norm ex. slaughter | G21: Mortality | H21: Disease | I21: Slaughter | J21: Space | K21: Mortality | L21: Disease | M21: Slaughter | N21: Space | O21: Life duration (years) | P21: Slaughter duration (years) | Q21: Number affected | R21: Ability | S21: Suffering | T21: Suffering norm | U21: Suffering norm ex. slaughter | V21: Mortality | W21: Disease | X21: Slaughter | Y21: Space | Z21: Mortality | AA21: Disease | AB21: Slaughter | AC21: Space | AD21: Life duration (years) | AE21: Slaughter duration (years)
A22: Cattle suckler herds | B22: ='No affected'!C7 -> 0.0035 | C22: =Ability!B6 -> 0.88410303 | D22: =2*G22+2*H22+I22+2*J22 -> 0.83750196 | E22: =(2*K22+2*L22+N22+2*M22)/7 -> 0.17246443 | F22: =(K22+L22+N22)/3 -> 0.11330588 | G22: =Mortality!C8 -> 0.042 | H22: =Disease!C8 -> 0.05 | I22: =Slaughter!C8/24 -> 0.34166667 | J22: =Space!C8/100 -> 0.15591765 | K22: =Mortality!C8/Mortality!$B$4 -> 0.084 | L22: =Disease!C8/Disease!$B$4 -> 0.1 | M22: =Slaughter!C8/Slaughter!$B$4 -> 0.34166667 | N22: =Space!C8/Space!$B$4 -> 0.15591765 | O22: ='Life duration'!C7 -> 2 | P22: =Slaughter!C8/(365*24) -> 0.00093607306 | Q22: ='No affected'!R7 -> 0.0008 | R22: =Ability!D6 -> 0.88410303 | S22: =2*V22+2*W22+X22+2*Y22 -> 0.58934418 | T22: =(2*Z22+2*AA22+AB22+2*AC22)/7 -> 0.10419203 | U22: =(Z22+AA22+AC22)/3 -> 0.064612919 | V22: =Mortality!R8 -> 0.03 | W22: =Disease!R8 -> 0.04 | X22: =Slaughter!R8/24 -> 0.34166667 | Y22: =Space!R8/100 -> 0.053838756 | Z22: =Mortality!R8/Mortality!$B$4 -> 0.06 | AA22: =Disease!R8/Disease!$B$4 -> 0.08 | AB22: =Slaughter!R8/Slaughter!$B$4 -> 0.34166667 | AC22: =Space!R8/Space!$B$4 -> 0.053838756 | AD22: ='Life duration'!R7 -> 1.3809524 | AE22: =Slaughter!R8/(365*24) -> 0.00093607306
A23: Meat cattle dairy intensive | B23: ='No affected'!C8 -> 0.009 | C23: =Ability!B7 -> 0.82044792 | D23: =2*G23+2*H23+I23+2*J23 -> 1.0073565 | E23: =(2*K23+2*L23+N23+2*M23)/7 -> 0.21588261 | F23: =(K23+L23+N23)/3 -> 0.16594831 | G23: =Mortality!C9 -> 0.065 | H23: =Disease!C9 -> 0.1 | I23: =Slaughter!C9/24 -> 0.34166667 | J23: =Space!C9/100 -> 0.16784492 | K23: =Mortality!C9/Mortality!$B$4 -> 0.13 | L23: =Disease!C9/Disease!$B$4 -> 0.2 | M23: =Slaughter!C9/Slaughter!$B$4 -> 0.34166667 | N23: =Space!C9/Space!$B$4 -> 0.16784492 | O23: ='Life duration'!C8 -> 0.75 | P23: =Slaughter!C9/(365*24) -> 0.00093607306
A24: Meat cattle dairy extensive | B24: ='No affected'!C9 -> 0.005 | C24: =Ability!B8 -> 0.88410303 | D24: =2*G24+2*H24+I24+2*J24 -> 0.90350196 | E24: =(2*K24+2*L24+N24+2*M24)/7 -> 0.19132157 | F24: =(K24+L24+N24)/3 -> 0.13530588 | G24: =Mortality!C10 -> 0.075 | H24: =Disease!C10 -> 0.05 | I24: =Slaughter!C10/24 -> 0.34166667 | J24: =Space!C10/100 -> 0.15591765 | K24: =Mortality!C10/Mortality!$B$4 -> 0.15 | L24: =Disease!C10/Disease!$B$4 -> 0.1 | M24: =Slaughter!C10/Slaughter!$B$4 -> 0.34166667 | N24: =Space!C10/Space!$B$4 -> 0.15591765 | O24: ='Life duration'!C9 -> 2 | P24: =Slaughter!C10/(365*24) -> 0.00093607306
A25: Dairy cows | B25: ='No affected'!C10 -> 0.0001 | C25: =Ability!B9 -> 0.88410303 | D25: =2*G25+2*H25+I25+2*J25 -> 0.95038202 | E25: =(2*K25+2*L25+N25+2*M25)/7 -> 0.23538443 | F25: =(K25+L25+N25)/3 -> 0.17478589 | G25: =Mortality!C11 -> 0.06 | H25: =Disease!C11 -> 0.16 | I25: =Slaughter!C11/24 -> 0.34166667 | J25: =Space!C11/100 -> 0.084357678 | K25: =Mortality!C11/Mortality!$B$4 -> 0.12 | L25: =Disease!C11/Disease!$B$4 -> 0.32 | M25: =Slaughter!C11/Slaughter!$B$4 -> 0.34166667 | N25: =Space!C11/Space!$B$4 -> 0.084357678 | O25: ='Life duration'!C10 -> 7.25 | P25: =Slaughter!C11/(365*24) -> 0.00093607306
A26: Horse | B26: ='No affected'!C11 -> 0.005 | C26: =Ability!B10 -> 0.87913616 | D26: =2*G26+2*H26+I26+2*J26 -> 0.952 | E26: =(2*K26+2*L26+N26+2*M26)/7 -> 0.24371429 | F26: =(K26+L26+N26)/3 -> 0.142 | G26: =Mortality!C12 -> 0.03 | H26: =Disease!C12 -> 0.15 | I26: =Slaughter!C12/24 -> 0.46 | J26: =Space!C12/100 -> 0.066 | K26: =Mortality!C12/Mortality!$B$4 -> 0.06 | L26: =Disease!C12/Disease!$B$4 -> 0.3 | M26: =Slaughter!C12/Slaughter!$B$4 -> 0.46 | N26: =Space!C12/Space!$B$4 -> 0.066 | O26: ='Life duration'!C11 -> 2 | P26: =Slaughter!C12/(365*24) -> 0.001260274
A27: Lamb | B27: ='No affected'!C12 -> 0.064 | C27: =Ability!B11 -> 0.82044792 | D27: =2*G27+2*H27+I27+2*J27 -> 0.85684098 | E27: =(2*K27+2*L27+N27+2*M27)/7 -> 0.1951315 | F27: =(K27+L27+N27)/3 -> 0.1319735 | G27: =Mortality!C13 -> 0.08 | H27: =Disease!C13 -> 0.06 | I27: =Slaughter!C13/24 -> 0.345 | J27: =Space!C13/100 -> 0.11592049 | K27: =Mortality!C13/Mortality!$B$4 -> 0.16 | L27: =Disease!C13/Disease!$B$4 -> 0.12 | M27: =Slaughter!C13/Slaughter!$B$4 -> 0.345 | N27: =Space!C13/Space!$B$4 -> 0.11592049 | O27: ='Life duration'!C12 -> 0.5 | P27: =Slaughter!C13/(365*24) -> 0.00094520548 | Q27: ='No affected'!R12 -> 0.0011 | R27: =Ability!D11 -> 0.88410303 | S27: =2*V27+2*W27+X27+2*Y27 -> 0.77775689 | T27: =(2*Z27+2*AA27+AB27+2*AC27)/7 -> 0.1425367 | U27: =(Z27+AA27+AC27)/3 -> 0.10879282 | V27: =Mortality!R13 -> 0.06 | W27: =Disease!R13 -> 0.05 | X27: =Slaughter!R13/24 -> 0.345 | Y27: =Space!R13/100 -> 0.10637845 | Z27: =Mortality!R13/Mortality!$B$4 -> 0.12 | AA27: =Disease!R13/Disease!$B$4 -> 0.1 | AB27: =Slaughter!R13/Slaughter!$B$4 -> 0.345 | AC27: =Space!R13/Space!$B$4 -> 0.10637845 | AD27: ='Life duration'!R12 -> 0.51813472 | AE27: =Slaughter!R13/(365*24) -> 0.00094520548
A28: Pig | B28: ='No affected'!C13 -> 0.018116931 | C28: =Ability!B12 -> 0.87981166 | D28: =2*G28+2*H28+I28+2*J28 -> 2.3272494 | E28: =(2*K28+2*L28+N28+2*M28)/7 -> 0.39280353 | F28: =(K28+L28+N28)/3 -> 0.45298601 | G28: =Mortality!C14 -> 0.212 | H28: =Disease!C14 -> 0.15 | I28: =Slaughter!C14/24 -> 0.33333333 | J28: =Space!C14/100 -> 0.63495804 | K28: =Mortality!C14/Mortality!$B$4 -> 0.424 | L28: =Disease!C14/Disease!$B$4 -> 0.3 | M28: =Slaughter!C14/Slaughter!$B$4 -> 0.33333333 | N28: =Space!C14/Space!$B$4 -> 0.63495804 | O28: ='Life duration'!C13 -> 0.5 | P28: =Slaughter!C14/(365*24) -> 0.00091324201 | Q28: ='No affected'!R13 -> 0.00035 | R28: =Ability!D12 -> 0.94805646 | S28: =2*V28+2*W28+X28+2*Y28 -> 1.5394725 | T28: =(2*Z28+2*AA28+AB28+2*AC28)/7 -> 0.27249607 | U28: =(Z28+AA28+AC28)/3 -> 0.26235652 | V28: =Mortality!R14 -> 0.034 | W28: =Disease!R14 -> 0.15 | X28: =Slaughter!R14/24 -> 0.33333333 | Y28: =Space!R14/100 -> 0.41906956 | Z28: =Mortality!R14/Mortality!$B$4 -> 0.068 | AA28: =Disease!R14/Disease!$B$4 -> 0.3 | AB28: =Slaughter!R14/Slaughter!$B$4 -> 0.33333333 | AC28: =Space!R14/Space!$B$4 -> 0.41906956 | AD28: ='Life duration'!R13 -> 0.028328612 | AE28: =Slaughter!R14/(365*24) -> 0.00091324201
A29: Chicken | B29: ='No affected'!C14 -> 0.75216903 | C29: =Ability!B13 -> 0.54320828 | D29: =2*G29+2*H29+I29+2*J29 -> 1.8550217 | E29: =(2*K29+2*L29+N29+2*M29)/7 -> 0.25218012 | F29: =(K29+L29+N29)/3 -> 0.33808696 | G29: =Mortality!C15 -> 0.038 | H29: =Disease!C15 -> 0.145 | I29: =Slaughter!C15/24 -> 0.1925 | J29: =Space!C15/100 -> 0.64826087 | K29: =Mortality!C15/Mortality!$B$4 -> 0.076 | L29: =Disease!C15/Disease!$B$4 -> 0.29 | M29: =Slaughter!C15/Slaughter!$B$4 -> 0.1925 | N29: =Space!C15/Space!$B$4 -> 0.64826087 | O29: ='Life duration'!C14 -> 0.096153846 | P29: =Slaughter!C15/(365*24) -> 0.00052739726 | Q29: ='No affected'!R14 -> 0.0054820185 | R29: =Ability!D13 -> 0.54320828 | S29: =2*V29+2*W29+X29+2*Y29 -> 1.9678846 | T29: =(2*Z29+2*AA29+AB29+2*AC29)/7 -> 0.42398352 | U29: =(Z29+AA29+AC29)/3 -> 0.4625641 | V29: =Mortality!R15 -> 0.06 | W29: =Disease!R15 -> 0.44 | X29: =Slaughter!R15/24 -> 0.1925 | Y29: =Space!R15/100 -> 0.38769231 | Z29: =Mortality!R15/Mortality!$B$4 -> 0.12 | AA29: =Disease!R15/Disease!$B$4 -> 0.88 | AB29: =Slaughter!R15/Slaughter!$B$4 -> 0.1925 | AC29: =Space!R15/Space!$B$4 -> 0.38769231 | AD29: ='Life duration'!R14 -> 0.0066666667 | AE29: =Slaughter!R15/(365*24) -> 0.00052739726
A30: Rabbit | B30: ='No affected'!C15 -> 1.24 | C30: =Ability!B14 -> 0.67196797 | D30: =2*G30+2*H30+I30+2*J30 -> 1.4556333 | E30: =(2*K30+2*L30+N30+2*M30)/7 -> 0.27138095 | F30: =(K30+L30+N30)/3 -> 0.28573333 | G30: =Mortality!C16 -> 0.15 | H30: =Disease!C16 -> 0.11 | I30: =Slaughter!C16/24 -> 0.26123333 | J30: =Space!C16/100 -> 0.3372 | K30: =Mortality!C16/Mortality!$B$4 -> 0.3 | L30: =Disease!C16/Disease!$B$4 -> 0.22 | M30: =Slaughter!C16/Slaughter!$B$4 -> 0.26123333 | N30: =Space!C16/Space!$B$4 -> 0.3372 | O30: ='Life duration'!C15 -> 0.16666667 | P30: =Slaughter!C16/(365*24) -> 0.00071570776
A31: Laying hen | B31: ='No affected'!C16 -> 0.055 | C31: =Ability!B15 -> 0.58534078 | D31: =2*G31+2*H31+I31+2*J31 -> 2.1139933 | E31: =(2*K31+2*L31+N31+2*M31)/7 -> 0.4136781 | F31: =(K31+L31+N31)/3 -> 0.46469333 | G31: =Mortality!C17 -> 0.035 | H31: =Disease!C17 -> 0.44 | I31: =Slaughter!C17/24 -> 0.27583333 | J31: =Space!C17/100 -> 0.44408 | K31: =Mortality!C17/Mortality!$B$4 -> 0.07 | L31: =Disease!C17/Disease!$B$4 -> 0.88 | M31: =Slaughter!C17/Slaughter!$B$4 -> 0.27583333 | N31: =Space!C17/Space!$B$4 -> 0.44408 | O31: ='Life duration'!C16 -> 1.2 | P31: =Slaughter!C17/(365*24) -> 0.00075570776 | Q31: ='No affected'!R16 -> 0 | R31: =Ability!D15 -> 0.25562743 | S31: =2*V31+2*W31+X31+2*Y31 -> 0 | T31: =(2*Z31+2*AA31+AB31+2*AC31)/7 -> 0 | U31: =(Z31+AA31+AC31)/3 -> 0 | V31: =Mortality!R17 -> 0 | W31: =Disease!R17 -> 0 | X31: =Slaughter!R17/24 -> 0 | Y31: =Space!R17/100 -> 0 | Z31: =Mortality!R17/Mortality!$B$4 -> 0 | AA31: =Disease!R17/Disease!$B$4 -> 0 | AB31: =Slaughter!R17/Slaughter!$B$4 -> 0 | AC31: =Space!R17/Space!$B$4 -> 0 | AD31: ='Life duration'!R16 -> 3.1709792e-07 | AE31: =Slaughter!R17/(365*24) -> 0

Sheet DE
A2: Germany
B5: Perception Adjusted Animal Lifes Affected (PAALA) | E5: Perception Adjusted Animal Lifes Affected (PAALA) - normalised | H5: Animal Life Years Suffered (ALYS) | K5: Perception Adjusted Animal Life Years Suffered (PAALYS)
B6: Total | C6: Prod. animal | D6: Parent | E6: Total | F6: Prod. animal | G6: Parent | H6: Total | I6: Prod. animal | J6: Parent | K6: Total | L6: Prod. animal | M6: Parent
A7: Beef suckler herds | B7: =C7+D7 -> 0.33958714 | C7: =B22*C22*D22*100 -> 0.30001164 | D7: =Q22*R22*S22*100 -> 0.039575503 | E7: =F7+G7 -> 0.057275164 | F7: =B22*C22*E22*100 -> 0.050206956 | G7: =Q22*R22*T22*100 -> 0.0070682081 | H7: =I7+J7 -> 0.0011394499 | I7: =B22*((O22-P22)*F22+P22) -> 0.00105617 | J7: =Q22*((AD22-AE22)*U22+AE22) -> 8.3279913e-05 | K7: =L7+M7 -> 0.0010073911 | L7: =C22*B22*((O22-P22)*F22+P22) -> 0.00093376311 | M7: =R22*Q22*((AD22-AE22)*U22+AE22) -> 7.3628024e-05
A8: Beef dairy int | B8: =C8+D8 -> 0.67614824 | C8: =B23*C23*D23*100 -> 0.67614824 | E8: =F8+G8 -> 0.14006926 | F8: =B23*C23*E23*100 -> 0.14006926 | H8: =I8+J8 -> 0.0011252925 | I8: =B23*((O23-P23)*F23+P23) -> 0.0011252925 | K8: =L8+M8 -> 0.00092324388 | L8: =C23*B23*((O23-P23)*F23+P23) -> 0.00092324388
A9: Beef dairy ext | B9: =C9+D9 -> 0.45776345 | C9: =B24*C24*D24*100 -> 0.45776345 | E9: =F9+G9 -> 0.080060052 | F9: =B24*C24*E24*100 -> 0.080060052 | H9: =I9+J9 -> 0.001728739 | I9: =B24*((O24-P24)*F24+P24) -> 0.001728739 | K9: =L9+M9 -> 0.0015283834 | L9: =C24*B24*((O24-P24)*F24+P24) -> 0.0015283834
A10: Milk | B10: =C10+D10 -> 0.0098488023 | C10: =B25*C25*D25*100 -> 0.0098488023 | E10: =F10+G10 -> 0.0020106954 | F10: =B25*C25*E25*100 -> 0.0020106954 | H10: =I10+J10 -> 0.00015761883 | I10: =B25*((O25-P25)*F25+P25) -> 0.00015761883 | K10: =L10+M10 -> 0.00013935129 | L10: =C25*B25*((O25-P25)*F25+P25) -> 0.00013935129
A11: Horse meat | B11: =C11+D11 -> 0.35949636 | C11: =B26*C26*D26*100 -> 0.35949636 | E11: =F11+G11 -> 0.083136139 | F11: =B26*C26*E26*100 -> 0.083136139 | H11: =I11+J11 -> 0.0015492951 | I11: =B26*((O26-P26)*F26+P26) -> 0.0015492951 | K11: =L11+M11 -> 0.0013620413 | L11: =C26*B26*((O26-P26)*F26+P26) -> 0.0013620413
A12: Lamb meat | B12: =C12+D12 -> 4.9145137 | C12: =B27*C27*D27*100 -> 4.8431173 | D12: =Q27*R27*S27*100 -> 0.071396395 | E12: =F12+G12 -> 0.95554134 | F12: =B27*C27*E27*100 -> 0.94228538 | G12: =Q27*R27*T27*100 -> 0.013255955 | H12: =I12+J12 -> 0.0051836105 | I12: =B27*((O27-P27)*F27+P27) -> 0.005116058 | J12: =Q27*((AD27-AE27)*U27+AE27) -> 6.7552518e-05 | K12: =L12+M12 -> 0.0042571825 | L12: =C27*B27*((O27-P27)*F27+P27) -> 0.0041974591 | M12: =R27*Q27*((AD27-AE27)*U27+AE27) -> 5.9723386e-05
A13: Pig meat | B13: =C13+D13 -> 3.5716431 | C13: =B28*C28*D28*100 -> 3.524706 | D13: =Q28*R28*S28*100 -> 0.046937072 | E13: =F13+G13 -> 0.58609606 | F13: =B28*C28*E28*100 -> 0.57769618 | G13: =Q28*R28*T28*100 -> 0.0083998792 | H13: =I13+J13 -> 0.0040413655 | I13: =B28*((O28-P28)*F28+P28) -> 0.004038695 | J13: =Q28*((AD28-AE28)*U28+AE28) -> 2.6704135e-06 | K13: =L13+M13 -> 0.0035558227 | L13: =C28*B28*((O28-P28)*F28+P28) -> 0.003553291 | M13: =R28*Q28*((AD28-AE28)*U28+AE28) -> 2.5317028e-06
A14: Chicken meat | B14: =C14+D14 -> 67.863523 | C14: =B29*C29*D29*100 -> 67.276686 | D14: =Q29*R29*S29*100 -> 0.58683719 | E14: =F14+G14 -> 8.8090151 | F14: =B29*C29*E29*100 -> 8.6811928 | G14: =Q29*R29*T29*100 -> 0.12782227 | H14: =I14+J14 -> 0.0214273 | I14: =B29*((O29-P29)*F29+P29) -> 0.021408703 | J14: =Q29*((AD29-AE29)*U29+AE29) -> 1.859692e-05 | K14: =L14+M14 -> 0.011639487 | L14: =C29*B29*((O29-P29)*F29+P29) -> 0.011629385 | M14: =R29*Q29*((AD29-AE29)*U29+AE29) -> 1.0102001e-05
A15: Rabbit meat | B15: =C15+D15 -> 101.91201 | C15: =B30*C30*D30*100 -> 101.91201 | E15: =F15+G15 -> 18.921274 | F15: =B30*C30*E30*100 -> 18.921274 | H15: =I15+J15 -> 0.050517018 | I15: =B30*((O30-P30)*F30+P30) -> 0.050517018 | K15: =L15+M15 -> 0.033945818 | L15: =C30*B30*((O30-P30)*F30+P30) -> 0.033945818
A16: Egg | B16: =C16+D16 -> 6.9040125 | C16: =B31*C31*D31*100 -> 6.9040125 | D16: =Q31*R31*S31*100 -> 0 | E16: =F16+G16 -> 1.3554761 | F16: =B31*C31*E31*100 -> 1.3554761 | G16: =Q31*R31*T31*100 -> 0 | H16: =I16+J16 -> 0.031859218 | I16: =B31*((O31-P31)*F31+P31) -> 0.031859218 | J16: =Q31*((AD31-AE31)*U31+AE31) -> 0 | K16: =L16+M16 -> 0.018648499 | L16: =C31*B31*((O31-P31)*F31+P31) -> 0.018648499 | M16: =R31*Q31*((AD31-AE31)*U31+AE31) -> 0
A18: Animal data
B20: PRODUCTION ANIMALS | G20: Non-normalised | K20: Normalised | Q20: PARENT ANIMALS (male chicks for hen) | V20: Non-normalised | Z20: Normalised
B21: Number affected | C21: Ability - normalised | D21: Suffering | E21: Suffering - normalised | F21: Suffering norm ex. slaughter | G21: Mortality | H21: Disease | I21: Slaughter | J21: Space | K21: Mortality | L21: Disease | M21: Slaughter | N21: Space | O21: Life duration (years) | P21: Slaughter duration (years) | Q21: Number affected | R21: Ability | S21: Suffering | T21: Suffering norm | U21: Suffering norm ex. slaughter | V21: Mortality | W21: Disease | X21: Slaughter | Y21: Space | Z21: Mortality | AA21: Disease | AB21: Slaughter | AC21: Space | AD21: Life duration (years) | AE21: Slaughter duration (years)
A22: Cattle suckler herds | B22: ='No affected'!D7 -> 0.0035 | C22: =Ability!B6 -> 0.88410303 | D22: =2*G22+2*H22+I22+2*J22 -> 0.96954322 | E22: =(2*K22+2*L22+N22+2*M22)/7 -> 0.16225309 | F22: =(K22+L22+N22)/3 -> 0.15059054 | G22: =Mortality!D8 -> 0.042 | H22: =Disease!D8 -> 0.05 | I22: =Slaughter!D8/24 -> 0.25 | J22: =Space!D8/100 -> 0.26777161 | K22: =Mortality!D8/Mortality!$B$4 -> 0.084 | L22: =Disease!D8/Disease!$B$4 -> 0.1 | M22: =Slaughter!D8/Slaughter!$B$4 -> 0.25 | N22: =Space!D8/Space!$B$4 -> 0.26777161 | O22: ='Life duration'!D7 -> 2 | P22: =Slaughter!D8/(365*24) -> 0.00068493151 | Q22: ='No affected'!S7 -> 0.0008 | R22: =Ability!D6 -> 0.88410303 | S22: =2*V22+2*W22+X22+2*Y22 -> 0.55954314 | T22: =(2*Z22+2*AA22+AB22+2*AC22)/7 -> 0.099934734 | U22: =(Z22+AA22+AC22)/3 -> 0.074923856 | V22: =Mortality!S8 -> 0.03 | W22: =Disease!S8 -> 0.04 | X22: =Slaughter!S8/24 -> 0.25 | Y22: =Space!S8/100 -> 0.084771568 | Z22: =Mortality!S8/Mortality!$B$4 -> 0.06 | AA22: =Disease!S8/Disease!$B$4 -> 0.08 | AB22: =Slaughter!S8/Slaughter!$B$4 -> 0.25 | AC22: =Space!S8/Space!$B$4 -> 0.084771568 | AD22: ='Life duration'!S7 -> 1.3809524 | AE22: =Slaughter!S8/(365*24) -> 0.00068493151
A23: Meat cattle dairy intensive | B23: ='No affected'!D8 -> 0.009 | C23: =Ability!B7 -> 0.82044792 | D23: =2*G23+2*H23+I23+2*J23 -> 0.91568984 | E23: =(2*K23+2*L23+N23+2*M23)/7 -> 0.18969213 | F23: =(K23+L23+N23)/3 -> 0.16594831 | G23: =Mortality!D9 -> 0.065 | H23: =Disease!D9 -> 0.1 | I23: =Slaughter!D9/24 -> 0.25 | J23: =Space!D9/100 -> 0.16784492 | K23: =Mortality!D9/Mortality!$B$4 -> 0.13 | L23: =Disease!D9/Disease!$B$4 -> 0.2 | M23: =Slaughter!D9/Slaughter!$B$4 -> 0.25 | N23: =Space!D9/Space!$B$4 -> 0.16784492 | O23: ='Life duration'!D8 -> 0.75 | P23: =Slaughter!D9/(365*24) -> 0.00068493151
A24: Meat cattle dairy extensive | B24: ='No affected'!D9 -> 0.005 | C24: =Ability!B8 -> 0.88410303 | D24: =2*G24+2*H24+I24+2*J24 -> 1.0355432 | E24: =(2*K24+2*L24+N24+2*M24)/7 -> 0.18111023 | F24: =(K24+L24+N24)/3 -> 0.17259054 | G24: =Mortality!D10 -> 0.075 | H24: =Disease!D10 -> 0.05 | I24: =Slaughter!D10/24 -> 0.25 | J24: =Space!D10/100 -> 0.26777161 | K24: =Mortality!D10/Mortality!$B$4 -> 0.15 | L24: =Disease!D10/Disease!$B$4 -> 0.1 | M24: =Slaughter!D10/Slaughter!$B$4 -> 0.25 | N24: =Space!D10/Space!$B$4 -> 0.26777161 | O24: ='Life duration'!D9 -> 2 | P24: =Slaughter!D10/(365*24) -> 0.00068493151
A25: Dairy cows | B25: ='No affected'!D10 -> 0.0001 | C25: =Ability!B9 -> 0.88410303 | D25: =2*G25+2*H25+I25+2*J25 -> 1.1139881 | E25: =(2*K25+2*L25+N25+2*M25)/7 -> 0.22742772 | F25: =(K25+L25+N25)/3 -> 0.21733134 | G25: =Mortality!D11 -> 0.06 | H25: =Disease!D11 -> 0.16 | I25: =Slaughter!D11/24 -> 0.25 | J25: =Space!D11/100 -> 0.21199403 | K25: =Mortality!D11/Mortality!$B$4 -> 0.12 | L25: =Disease!D11/Disease!$B$4 -> 0.32 | M25: =Slaughter!D11/Slaughter!$B$4 -> 0.25 | N25: =Space!D11/Space!$B$4 -> 0.21199403 | O25: ='Life duration'!D10 -> 7.25 | P25: =Slaughter!D11/(365*24) -> 0.00068493151
A26: Horse | B26: ='No affected'!D11 -> 0.005 | C26: =Ability!B10 -> 0.87913616 | D26: =2*G26+2*H26+I26+2*J26 -> 0.81784 | E26: =(2*K26+2*L26+N26+2*M26)/7 -> 0.18913143 | F26: =(K26+L26+N26)/3 -> 0.15464 | G26: =Mortality!D12 -> 0.03 | H26: =Disease!D12 -> 0.15 | I26: =Slaughter!D12/24 -> 0.25 | J26: =Space!D12/100 -> 0.10392 | K26: =Mortality!D12/Mortality!$B$4 -> 0.06 | L26: =Disease!D12/Disease!$B$4 -> 0.3 | M26: =Slaughter!D12/Slaughter!$B$4 -> 0.25 | N26: =Space!D12/Space!$B$4 -> 0.10392 | O26: ='Life duration'!D11 -> 2 | P26: =Slaughter!D12/(365*24) -> 0.00068493151
A27: Lamb | B27: ='No affected'!D12 -> 0.064 | C27: =Ability!B11 -> 0.82044792 | D27: =2*G27+2*H27+I27+2*J27 -> 0.92234628 | E27: =(2*K27+2*L27+N27+2*M27)/7 -> 0.17945331 | F27: =(K27+L27+N27)/3 -> 0.15872438 | G27: =Mortality!D13 -> 0.08 | H27: =Disease!D13 -> 0.06 | I27: =Slaughter!D13/24 -> 0.25 | J27: =Space!D13/100 -> 0.19617314 | K27: =Mortality!D13/Mortality!$B$4 -> 0.16 | L27: =Disease!D13/Disease!$B$4 -> 0.12 | M27: =Slaughter!D13/Slaughter!$B$4 -> 0.25 | N27: =Space!D13/Space!$B$4 -> 0.19617314 | O27: ='Life duration'!D12 -> 0.5 | P27: =Slaughter!D13/(365*24) -> 0.00068493151 | Q27: ='No affected'!S12 -> 0.0011 | R27: =Ability!D11 -> 0.88410303 | S27: =2*V27+2*W27+X27+2*Y27 -> 0.73414309 | T27: =(2*Z27+2*AA27+AB27+2*AC27)/7 -> 0.13630616 | U27: =(Z27+AA27+AC27)/3 -> 0.11735718 | V27: =Mortality!S13 -> 0.06 | W27: =Disease!S13 -> 0.05 | X27: =Slaughter!S13/24 -> 0.25 | Y27: =Space!S13/100 -> 0.13207154 | Z27: =Mortality!S13/Mortality!$B$4 -> 0.12 | AA27: =Disease!S13/Disease!$B$4 -> 0.1 | AB27: =Slaughter!S13/Slaughter!$B$4 -> 0.25 | AC27: =Space!S13/Space!$B$4 -> 0.13207154 | AD27: ='Life duration'!S12 -> 0.51813472 | AE27: =Slaughter!S13/(365*24) -> 0.00068493151
A28: Pig | B28: ='No affected'!D13 -> 0.017933553 | C28: =Ability!B12 -> 0.87981166 | D28: =2*G28+2*H28+I28+2*J28 -> 2.2339161 | E28: =(2*K28+2*L28+N28+2*M28)/7 -> 0.36613686 | F28: =(K28+L28+N28)/3 -> 0.44965268 | G28: =Mortality!D14 -> 0.207 | H28: =Disease!D14 -> 0.15 | I28: =Slaughter!D14/24 -> 0.25 | J28: =Space!D14/100 -> 0.63495804 | K28: =Mortality!D14/Mortality!$B$4 -> 0.414 | L28: =Disease!D14/Disease!$B$4 -> 0.3 | M28: =Slaughter!D14/Slaughter!$B$4 -> 0.25 | N28: =Space!D14/Space!$B$4 -> 0.63495804 | O28: ='Life duration'!D13 -> 0.5 | P28: =Slaughter!D14/(365*24) -> 0.00068493151 | Q28: ='No affected'!S13 -> 0.00034 | R28: =Ability!D12 -> 0.94805646 | S28: =2*V28+2*W28+X28+2*Y28 -> 1.4561391 | T28: =(2*Z28+2*AA28+AB28+2*AC28)/7 -> 0.2605913 | U28: =(Z28+AA28+AC28)/3 -> 0.26235652 | V28: =Mortality!S14 -> 0.034 | W28: =Disease!S14 -> 0.15 | X28: =Slaughter!S14/24 -> 0.25 | Y28: =Space!S14/100 -> 0.41906956 | Z28: =Mortality!S14/Mortality!$B$4 -> 0.068 | AA28: =Disease!S14/Disease!$B$4 -> 0.3 | AB28: =Slaughter!S14/Slaughter!$B$4 -> 0.25 | AC28: =Space!S14/Space!$B$4 -> 0.41906956 | AD28: ='Life duration'!S13 -> 0.028011204 | AE28: =Slaughter!S14/(365*24) -> 0.00068493151
A29: Chicken | B29: ='No affected'!D14 -> 0.75216903 | C29: =Ability!B13 -> 0.54320828 | D29: =2*G29+2*H29+I29+2*J29 -> 1.6465797 | E29: =(2*K29+2*L29+N29+2*M29)/7 -> 0.21246998 | F29: =(K29+L29+N29)/3 -> 0.29265217 | G29: =Mortality!D15 -> 0.038 | H29: =Disease!D15 -> 0.1 | I29: =Slaughter!D15/24 -> 0.16666667 | J29: =Space!D15/100 -> 0.60195652 | K29: =Mortality!D15/Mortality!$B$4 -> 0.076 | L29: =Disease!D15/Disease!$B$4 -> 0.2 | M29: =Slaughter!D15/Slaughter!$B$4 -> 0.16666667 | N29: =Space!D15/Space!$B$4 -> 0.60195652 | O29: ='Life duration'!D14 -> 0.096153846 | P29: =Slaughter!D15/(365*24) -> 0.000456621 | Q29: ='No affected'!S14 -> 0.0054505002 | R29: =Ability!D13 -> 0.54320828 | S29: =2*V29+2*W29+X29+2*Y29 -> 1.9820513 | T29: =(2*Z29+2*AA29+AB29+2*AC29)/7 -> 0.43172161 | U29: =(Z29+AA29+AC29)/3 -> 0.47589744 | V29: =Mortality!S15 -> 0.06 | W29: =Disease!S15 -> 0.46 | X29: =Slaughter!S15/24 -> 0.16666667 | Y29: =Space!S15/100 -> 0.38769231 | Z29: =Mortality!S15/Mortality!$B$4 -> 0.12 | AA29: =Disease!S15/Disease!$B$4 -> 0.92 | AB29: =Slaughter!S15/Slaughter!$B$4 -> 0.16666667 | AC29: =Space!S15/Space!$B$4 -> 0.38769231 | AD29: ='Life duration'!S14 -> 0.0066666667 | AE29: =Slaughter!S15/(365*24) -> 0.000456621
A30: Rabbit | B30: ='No affected'!D15 -> 1.05 | C30: =Ability!B14 -> 0.67196797 | D30: =2*G30+2*H30+I30+2*J30 -> 1.4444 | E30: =(2*K30+2*L30+N30+2*M30)/7 -> 0.26817143 | F30: =(K30+L30+N30)/3 -> 0.28573333 | G30: =Mortality!D16 -> 0.15 | H30: =Disease!D16 -> 0.11 | I30: =Slaughter!D16/24 -> 0.25 | J30: =Space!D16/100 -> 0.3372 | K30: =Mortality!D16/Mortality!$B$4 -> 0.3 | L30: =Disease!D16/Disease!$B$4 -> 0.22 | M30: =Slaughter!D16/Slaughter!$B$4 -> 0.25 | N30: =Space!D16/Space!$B$4 -> 0.3372 | O30: ='Life duration'!D15 -> 0.16666667 | P30: =Slaughter!D16/(365*24) -> 0.00068493151
A31: Laying hen | B31: ='No affected'!D16 -> 0.055 | C31: =Ability!B15 -> 0.58534078 | D31: =2*G31+2*H31+I31+2*J31 -> 2.14452 | E31: =(2*K31+2*L31+N31+2*M31)/7 -> 0.42103714 | F31: =(K31+L31+N31)/3 -> 0.48242 | G31: =Mortality!D17 -> 0.04 | H31: =Disease!D17 -> 0.46 | I31: =Slaughter!D17/24 -> 0.25 | J31: =Space!D17/100 -> 0.44726 | K31: =Mortality!D17/Mortality!$B$4 -> 0.08 | L31: =Disease!D17/Disease!$B$4 -> 0.92 | M31: =Slaughter!D17/Slaughter!$B$4 -> 0.25 | N31: =Space!D17/Space!$B$4 -> 0.44726 | O31: ='Life duration'!D16 -> 1.2 | P31: =Slaughter!D17/(365*24) -> 0.00068493151 | Q31: ='No affected'!S16 -> 0 | R31: =Ability!D15 -> 0.25562743 | S31: =2*V31+2*W31+X31+2*Y31 -> 0 | T31: =(2*Z31+2*AA31+AB31+2*AC31)/7 -> 0 | U31: =(Z31+AA31+AC31)/3 -> 0 | V31: =Mortality!S17 -> 0 | W31: =Disease!S17 -> 0 | X31: =Slaughter!S17/24 -> 0 | Y31: =Space!S17/100 -> 0 | Z31: =Mortality!S17/Mortality!$B$4 -> 0 | AA31: =Disease!S17/Disease!$B$4 -> 0 | AB31: =Slaughter!S17/Slaughter!$B$4 -> 0 | AC31: =Space!S17/Space!$B$4 -> 0 | AD31: ='Life duration'!S16 -> 3.1709792e-07 | AE31: =Slaughter!S17/(365*24) -> 0

Sheet GR
A2: Greece
B5: Perception Adjusted Animal Lifes Affected (PAALA) | E5: Perception Adjusted Animal Lifes Affected (PAALA) - normalised | H5: Animal Life Years Suffered (ALYS) | K5: Perception Adjusted Animal Life Years Suffered (PAALYS)
B6: Total | C6: Prod. animal | D6: Parent | E6: Total | F6: Prod. animal | G6: Parent | H6: Total | I6: Prod. animal | J6: Parent | K6: Total | L6: Prod. animal | M6: Parent
A7: Beef suckler herds | B7: =C7+D7 -> 0.34502625 | C7: =B22*C22*D22*100 -> 0.3032045 | D7: =Q22*R22*S22*100 -> 0.041821748 | E7: =F7+G7 -> 0.063902327 | F7: =B22*C22*E22*100 -> 0.056513226 | G7: =Q22*R22*T22*100 -> 0.0073891003 | H7: =I7+J7 -> 0.0010344973 | I7: =B22*((O22-P22)*F22+P22) -> 0.00096205467 | J7: =Q22*((AD22-AE22)*U22+AE22) -> 7.2442598e-05 | K7: =L7+M7 -> 0.00091460217 | L7: =C22*B22*((O22-P22)*F22+P22) -> 0.00085055545 | M7: =R22*Q22*((AD22-AE22)*U22+AE22) -> 6.4046721e-05
A8: Beef dairy int | B8: =C8+D8 -> 0.74383519 | C8: =B23*C23*D23*100 -> 0.74383519 | E8: =F8+G8 -> 0.15940839 | F8: =B23*C23*E23*100 -> 0.15940839 | H8: =I8+J8 -> 0.0011271777 | I8: =B23*((O23-P23)*F23+P23) -> 0.0011271777 | K8: =L8+M8 -> 0.00092479057 | L8: =C23*B23*((O23-P23)*F23+P23) -> 0.00092479057
A9: Beef dairy ext | B9: =C9+D9 -> 0.46232468 | C9: =B24*C24*D24*100 -> 0.46232468 | E9: =F9+G9 -> 0.089069009 | F9: =B24*C24*E24*100 -> 0.089069009 | H9: =I9+J9 -> 0.0015942608 | I9: =B24*((O24-P24)*F24+P24) -> 0.0015942608 | K9: =L9+M9 -> 0.0014094908 | L9: =C24*B24*((O24-P24)*F24+P24) -> 0.0014094908
A10: Milk | B10: =C10+D10 -> 0.012843848 | C10: =B25*C25*D25*100 -> 0.012843848 | E10: =F10+G10 -> 0.0023982903 | F10: =B25*C25*E25*100 -> 0.0023982903 | H10: =I10+J10 -> 0.00018749254 | I10: =B25*((O25-P25)*F25+P25) -> 0.00018749254 | K10: =L10+M10 -> 0.00016576272 | L10: =C25*B25*((O25-P25)*F25+P25) -> 0.00016576272
A11: Horse meat | B11: =C11+D11 -> 0.41952378 | C11: =B26*C26*D26*100 -> 0.41952378 | E11: =F11+G11 -> 0.10720438 | F11: =B26*C26*E26*100 -> 0.10720438 | H11: =I11+J11 -> 0.0014294041 | I11: =B26*((O26-P26)*F26+P26) -> 0.0014294041 | K11: =L11+M11 -> 0.0012566408 | L11: =C26*B26*((O26-P26)*F26+P26) -> 0.0012566408
A12: Lamb meat | B12: =C12+D12 -> 3.8296803 | C12: =B27*C27*D27*100 -> 3.7500094 | D12: =Q27*R27*S27*100 -> 0.079670865 | E12: =F12+G12 -> 0.98553691 | F12: =B27*C27*E27*100 -> 0.97109889 | G12: =Q27*R27*T27*100 -> 0.014438023 | H12: =I12+J12 -> 0.003583051 | I12: =B27*((O27-P27)*F27+P27) -> 0.003516186 | J12: =Q27*((AD27-AE27)*U27+AE27) -> 6.6864943e-05 | K12: =L12+M12 -> 0.002943963 | L12: =C27*B27*((O27-P27)*F27+P27) -> 0.0028848475 | M12: =R27*Q27*((AD27-AE27)*U27+AE27) -> 5.9115499e-05
A13: Pig meat | B13: =C13+D13 -> 3.6851589 | C13: =B28*C28*D28*100 -> 3.6340761 | D13: =Q28*R28*S28*100 -> 0.051082738 | E13: =F13+G13 -> 0.61724275 | F13: =B28*C28*E28*100 -> 0.6082008 | G13: =Q28*R28*T28*100 -> 0.009041958 | H13: =I13+J13 -> 0.0039970465 | I13: =B28*((O28-P28)*F28+P28) -> 0.0039941551 | J13: =Q28*((AD28-AE28)*U28+AE28) -> 2.8913775e-06 | K13: =L13+M13 -> 0.0035168454 | L13: =C28*B28*((O28-P28)*F28+P28) -> 0.0035141042 | M13: =R28*Q28*((AD28-AE28)*U28+AE28) -> 2.7411891e-06
A14: Chicken meat | B14: =C14+D14 -> 76.375945 | C14: =B29*C29*D29*100 -> 75.793303 | D14: =Q29*R29*S29*100 -> 0.58264278 | E14: =F14+G14 -> 10.429219 | F14: =B29*C29*E29*100 -> 10.303688 | G14: =Q29*R29*T29*100 -> 0.12553121 | H14: =I14+J14 -> 0.024732711 | I14: =B29*((O29-P29)*F29+P29) -> 0.024714358 | J14: =Q29*((AD29-AE29)*U29+AE29) -> 1.835294e-05 | K14: =L14+M14 -> 0.013435013 | L14: =C29*B29*((O29-P29)*F29+P29) -> 0.013425044 | M14: =R29*Q29*((AD29-AE29)*U29+AE29) -> 9.969469e-06
A15: Rabbit meat | B15: =C15+D15 -> 102.70459 | C15: =B30*C30*D30*100 -> 102.70459 | E15: =F15+G15 -> 19.147727 | F15: =B30*C30*E30*100 -> 19.147727 | H15: =I15+J15 -> 0.0505401 | I15: =B30*((O30-P30)*F30+P30) -> 0.0505401 | K15: =L15+M15 -> 0.033961328 | L15: =C30*B30*((O30-P30)*F30+P30) -> 0.033961328
A16: Egg | B16: =C16+D16 -> 9.9251217 | C16: =B31*C31*D31*100 -> 9.9126953 | D16: =Q31*R31*S31*100 -> 0.012426333 | E16: =F16+G16 -> 1.7861202 | F16: =B31*C31*E31*100 -> 1.784345 | G16: =Q31*R31*T31*100 -> 0.0017751905 | H16: =I16+J16 -> 0.043335118 | I16: =B31*((O31-P31)*F31+P31) -> 0.043333786 | J16: =Q31*((AD31-AE31)*U31+AE31) -> 1.3318113e-06 | K16: =L16+M16 -> 0.025365372 | L16: =C31*B31*((O31-P31)*F31+P31) -> 0.025365032 | M16: =R31*Q31*((AD31-AE31)*U31+AE31) -> 3.4044748e-07
A18: Animal data
B20: PRODUCTION ANIMALS | G20: Non-normalised | K20: Normalised | Q20: PARENT ANIMALS (male chicks for hen) | V20: Non-normalised | Z20: Normalised
B21: Number affected | C21: Ability - normalised | D21: Suffering | E21: Suffering - normalised | F21: Suffering norm ex. slaughter | G21: Mortality | H21: Disease | I21: Slaughter | J21: Space | K21: Mortality | L21: Disease | M21: Slaughter | N21: Space | O21: Life duration (years) | P21: Slaughter duration (years) | Q21: Number affected | R21: Ability | S21: Suffering | T21: Suffering norm | U21: Suffering norm ex. slaughter | V21: Mortality | W21: Disease | X21: Slaughter | Y21: Space | Z21: Mortality | AA21: Disease | AB21: Slaughter | AC21: Space | AD21: Life duration (years) | AE21: Slaughter duration (years)
A22: Cattle suckler herds | B22: ='No affected'!E7 -> 0.0035 | C22: =Ability!B6 -> 0.88410303 | D22: =2*G22+2*H22+I22+2*J22 -> 0.97986155 | E22: =(2*K22+2*L22+N22+2*M22)/7 -> 0.18263297 | F22: =(K22+L22+N22)/3 -> 0.13703248 | G22: =Mortality!E8 -> 0.042 | H22: =Disease!E8 -> 0.05 | I22: =Slaughter!E8/24 -> 0.34166667 | J22: =Space!E8/100 -> 0.22709744 | K22: =Mortality!E8/Mortality!$B$4 -> 0.084 | L22: =Disease!E8/Disease!$B$4 -> 0.1 | M22: =Slaughter!E8/Slaughter!$B$4 -> 0.34166667 | N22: =Space!E8/Space!$B$4 -> 0.22709744 | O22: ='Life duration'!E7 -> 2 | P22: =Slaughter!E8/(365*24) -> 0.00093607306 | Q22: ='No affected'!T7 -> 0.0008 | R22: =Ability!D6 -> 0.88410303 | S22: =2*V22+2*W22+X22+2*Y22 -> 0.59130195 | T22: =(2*Z22+2*AA22+AB22+2*AC22)/7 -> 0.10447171 | U22: =(Z22+AA22+AC22)/3 -> 0.064939214 | V22: =Mortality!T8 -> 0.03 | W22: =Disease!T8 -> 0.04 | X22: =Slaughter!T8/24 -> 0.34166667 | Y22: =Space!T8/100 -> 0.054817642 | Z22: =Mortality!T8/Mortality!$B$4 -> 0.06 | AA22: =Disease!T8/Disease!$B$4 -> 0.08 | AB22: =Slaughter!T8/Slaughter!$B$4 -> 0.34166667 | AC22: =Space!T8/Space!$B$4 -> 0.054817642 | AD22: ='Life duration'!T7 -> 1.3809524 | AE22: =Slaughter!T8/(365*24) -> 0.00093607306
A23: Meat cattle dairy intensive | B23: ='No affected'!E8 -> 0.009 | C23: =Ability!B7 -> 0.82044792 | D23: =2*G23+2*H23+I23+2*J23 -> 1.0073565 | E23: =(2*K23+2*L23+N23+2*M23)/7 -> 0.21588261 | F23: =(K23+L23+N23)/3 -> 0.16594831 | G23: =Mortality!E9 -> 0.065 | H23: =Disease!E9 -> 0.1 | I23: =Slaughter!E9/24 -> 0.34166667 | J23: =Space!E9/100 -> 0.16784492 | K23: =Mortality!E9/Mortality!$B$4 -> 0.13 | L23: =Disease!E9/Disease!$B$4 -> 0.2 | M23: =Slaughter!E9/Slaughter!$B$4 -> 0.34166667 | N23: =Space!E9/Space!$B$4 -> 0.16784492 | O23: ='Life duration'!E8 -> 0.75 | P23: =Slaughter!E9/(365*24) -> 0.00093607306
A24: Meat cattle dairy extensive | B24: ='No affected'!E9 -> 0.005 | C24: =Ability!B8 -> 0.88410303 | D24: =2*G24+2*H24+I24+2*J24 -> 1.0458616 | E24: =(2*K24+2*L24+N24+2*M24)/7 -> 0.20149011 | F24: =(K24+L24+N24)/3 -> 0.15903248 | G24: =Mortality!E10 -> 0.075 | H24: =Disease!E10 -> 0.05 | I24: =Slaughter!E10/24 -> 0.34166667 | J24: =Space!E10/100 -> 0.22709744 | K24: =Mortality!E10/Mortality!$B$4 -> 0.15 | L24: =Disease!E10/Disease!$B$4 -> 0.1 | M24: =Slaughter!E10/Slaughter!$B$4 -> 0.34166667 | N24: =Space!E10/Space!$B$4 -> 0.22709744 | O24: ='Life duration'!E9 -> 2 | P24: =Slaughter!E10/(365*24) -> 0.00093607306
A25: Dairy cows | B25: ='No affected'!E10 -> 0.0001 | C25: =Ability!B9 -> 0.88410303 | D25: =2*G25+2*H25+I25+2*J25 -> 1.4527546 | E25: =(2*K25+2*L25+N25+2*M25)/7 -> 0.27126819 | F25: =(K25+L25+N25)/3 -> 0.25851466 | G25: =Mortality!E11 -> 0.06 | H25: =Disease!E11 -> 0.16 | I25: =Slaughter!E11/24 -> 0.34166667 | J25: =Space!E11/100 -> 0.33554397 | K25: =Mortality!E11/Mortality!$B$4 -> 0.12 | L25: =Disease!E11/Disease!$B$4 -> 0.32 | M25: =Slaughter!E11/Slaughter!$B$4 -> 0.34166667 | N25: =Space!E11/Space!$B$4 -> 0.33554397 | O25: ='Life duration'!E10 -> 7.25 | P25: =Slaughter!E11/(365*24) -> 0.00093607306
A26: Horse | B26: ='No affected'!E11 -> 0.005 | C26: =Ability!B10 -> 0.87913616 | D26: =2*G26+2*H26+I26+2*J26 -> 0.9544 | E26: =(2*K26+2*L26+N26+2*M26)/7 -> 0.24388571 | F26: =(K26+L26+N26)/3 -> 0.1424 | G26: =Mortality!E12 -> 0.03 | H26: =Disease!E12 -> 0.15 | I26: =Slaughter!E12/24 -> 0.46 | J26: =Space!E12/100 -> 0.0672 | K26: =Mortality!E12/Mortality!$B$4 -> 0.06 | L26: =Disease!E12/Disease!$B$4 -> 0.3 | M26: =Slaughter!E12/Slaughter!$B$4 -> 0.46 | N26: =Space!E12/Space!$B$4 -> 0.0672 | O26: ='Life duration'!E11 -> 2 | P26: =Slaughter!E12/(365*24) -> 0.001260274
A27: Lamb | B27: ='No affected'!E12 -> 0.064 | C27: =Ability!B11 -> 0.82044792 | D27: =2*G27+2*H27+I27+2*J27 -> 0.71416961 | E27: =(2*K27+2*L27+N27+2*M27)/7 -> 0.18494069 | F27: =(K27+L27+N27)/3 -> 0.10819493 | G27: =Mortality!E13 -> 0.08 | H27: =Disease!E13 -> 0.06 | I27: =Slaughter!E13/24 -> 0.345 | J27: =Space!E13/100 -> 0.044584804 | K27: =Mortality!E13/Mortality!$B$4 -> 0.16 | L27: =Disease!E13/Disease!$B$4 -> 0.12 | M27: =Slaughter!E13/Slaughter!$B$4 -> 0.345 | N27: =Space!E13/Space!$B$4 -> 0.044584804 | O27: ='Life duration'!E12 -> 0.5 | P27: =Slaughter!E13/(365*24) -> 0.00094520548 | Q27: ='No affected'!T12 -> 0.0011 | R27: =Ability!D11 -> 0.88410303 | S27: =2*V27+2*W27+X27+2*Y27 -> 0.81922645 | T27: =(2*Z27+2*AA27+AB27+2*AC27)/7 -> 0.14846092 | U27: =(Z27+AA27+AC27)/3 -> 0.11570441 | V27: =Mortality!T13 -> 0.06 | W27: =Disease!T13 -> 0.05 | X27: =Slaughter!T13/24 -> 0.345 | Y27: =Space!T13/100 -> 0.12711323 | Z27: =Mortality!T13/Mortality!$B$4 -> 0.12 | AA27: =Disease!T13/Disease!$B$4 -> 0.1 | AB27: =Slaughter!T13/Slaughter!$B$4 -> 0.345 | AC27: =Space!T13/Space!$B$4 -> 0.12711323 | AD27: ='Life duration'!T12 -> 0.51813472 | AE27: =Slaughter!T13/(365*24) -> 0.00094520548
A28: Pig | B28: ='No affected'!E13 -> 0.017964628 | C28: =Ability!B12 -> 0.87981166 | D28: =2*G28+2*H28+I28+2*J28 -> 2.2992494 | E28: =(2*K28+2*L28+N28+2*M28)/7 -> 0.38480353 | F28: =(K28+L28+N28)/3 -> 0.44365268 | G28: =Mortality!E14 -> 0.198 | H28: =Disease!E14 -> 0.15 | I28: =Slaughter!E14/24 -> 0.33333333 | J28: =Space!E14/100 -> 0.63495804 | K28: =Mortality!E14/Mortality!$B$4 -> 0.396 | L28: =Disease!E14/Disease!$B$4 -> 0.3 | M28: =Slaughter!E14/Slaughter!$B$4 -> 0.33333333 | N28: =Space!E14/Space!$B$4 -> 0.63495804 | O28: ='Life duration'!E13 -> 0.5 | P28: =Slaughter!E14/(365*24) -> 0.00091324201 | Q28: ='No affected'!T13 -> 0.00035 | R28: =Ability!D12 -> 0.94805646 | S28: =2*V28+2*W28+X28+2*Y28 -> 1.5394725 | T28: =(2*Z28+2*AA28+AB28+2*AC28)/7 -> 0.27249607 | U28: =(Z28+AA28+AC28)/3 -> 0.26235652 | V28: =Mortality!T14 -> 0.034 | W28: =Disease!T14 -> 0.15 | X28: =Slaughter!T14/24 -> 0.33333333 | Y28: =Space!T14/100 -> 0.41906956 | Z28: =Mortality!T14/Mortality!$B$4 -> 0.068 | AA28: =Disease!T14/Disease!$B$4 -> 0.3 | AB28: =Slaughter!T14/Slaughter!$B$4 -> 0.33333333 | AC28: =Space!T14/Space!$B$4 -> 0.41906956 | AD28: ='Life duration'!T13 -> 0.028920308 | AE28: =Slaughter!T14/(365*24) -> 0.00091324201
A29: Chicken | B29: ='No affected'!E14 -> 0.75216903 | C29: =Ability!B13 -> 0.54320828 | D29: =2*G29+2*H29+I29+2*J29 -> 1.8550217 | E29: =(2*K29+2*L29+N29+2*M29)/7 -> 0.25218012 | F29: =(K29+L29+N29)/3 -> 0.33808696 | G29: =Mortality!E15 -> 0.038 | H29: =Disease!E15 -> 0.145 | I29: =Slaughter!E15/24 -> 0.1925 | J29: =Space!E15/100 -> 0.64826087 | K29: =Mortality!E15/Mortality!$B$4 -> 0.076 | L29: =Disease!E15/Disease!$B$4 -> 0.29 | M29: =Slaughter!E15/Slaughter!$B$4 -> 0.1925 | N29: =Space!E15/Space!$B$4 -> 0.64826087 | O29: ='Life duration'!E14 -> 0.096153846 | P29: =Slaughter!E15/(365*24) -> 0.00052739726 | Q29: ='No affected'!T14 -> 0.0054505002 | R29: =Ability!D13 -> 0.54320828 | S29: =2*V29+2*W29+X29+2*Y29 -> 1.9678846 | T29: =(2*Z29+2*AA29+AB29+2*AC29)/7 -> 0.42398352 | U29: =(Z29+AA29+AC29)/3 -> 0.4625641 | V29: =Mortality!T15 -> 0.06 | W29: =Disease!T15 -> 0.44 | X29: =Slaughter!T15/24 -> 0.1925 | Y29: =Space!T15/100 -> 0.38769231 | Z29: =Mortality!T15/Mortality!$B$4 -> 0.12 | AA29: =Disease!T15/Disease!$B$4 -> 0.88 | AB29: =Slaughter!T15/Slaughter!$B$4 -> 0.1925 | AC29: =Space!T15/Space!$B$4 -> 0.38769231 | AD29: ='Life duration'!T14 -> 0.0066666667 | AE29: =Slaughter!T15/(365*24) -> 0.00052739726
A30: Rabbit | B30: ='No affected'!E15 -> 1.05 | C30: =Ability!B14 -> 0.67196797 | D30: =2*G30+2*H30+I30+2*J30 -> 1.4556333 | E30: =(2*K30+2*L30+N30+2*M30)/7 -> 0.27138095 | F30: =(K30+L30+N30)/3 -> 0.28573333 | G30: =Mortality!E16 -> 0.15 | H30: =Disease!E16 -> 0.11 | I30: =Slaughter!E16/24 -> 0.26123333 | J30: =Space!E16/100 -> 0.3372 | K30: =Mortality!E16/Mortality!$B$4 -> 0.3 | L30: =Disease!E16/Disease!$B$4 -> 0.22 | M30: =Slaughter!E16/Slaughter!$B$4 -> 0.26123333 | N30: =Space!E16/Space!$B$4 -> 0.3372 | O30: ='Life duration'!E15 -> 0.16666667 | P30: =Slaughter!E16/(365*24) -> 0.00071570776
A31: Laying hen | B31: ='No affected'!E16 -> 0.07 | C31: =Ability!B15 -> 0.58534078 | D31: =2*G31+2*H31+I31+2*J31 -> 2.4192733 | E31: =(2*K31+2*L31+N31+2*M31)/7 -> 0.43548381 | F31: =(K31+L31+N31)/3 -> 0.51557333 | G31: =Mortality!E17 -> 0.035 | H31: =Disease!E17 -> 0.44 | I31: =Slaughter!E17/24 -> 0.27583333 | J31: =Space!E17/100 -> 0.59672 | K31: =Mortality!E17/Mortality!$B$4 -> 0.07 | L31: =Disease!E17/Disease!$B$4 -> 0.88 | M31: =Slaughter!E17/Slaughter!$B$4 -> 0.27583333 | N31: =Space!E17/Space!$B$4 -> 0.59672 | O31: ='Life duration'!E16 -> 1.2 | P31: =Slaughter!E17/(365*24) -> 0.00075570776 | Q31: ='No affected'!T16 -> 0.07 | R31: =Ability!D15 -> 0.25562743 | S31: =2*V31+2*W31+X31+2*Y31 -> 0.0069444444 | T31: =(2*Z31+2*AA31+AB31+2*AC31)/7 -> 0.00099206349 | U31: =(Z31+AA31+AC31)/3 -> 0 | V31: =Mortality!T17 -> 0 | W31: =Disease!T17 -> 0 | X31: =Slaughter!T17/24 -> 0.0069444444 | Y31: =Space!T17/100 -> 0 | Z31: =Mortality!T17/Mortality!$B$4 -> 0 | AA31: =Disease!T17/Disease!$B$4 -> 0 | AB31: =Slaughter!T17/Slaughter!$B$4 -> 0.0069444444 | AC31: =Space!T17/Space!$B$4 -> 0 | AD31: ='Life duration'!T16 -> 3.1709792e-07 | AE31: =Slaughter!T17/(365*24) -> 1.9025875e-05

Sheet HU
A2: Hungary
B5: Perception Adjusted Animal Lifes Affected (PAALA) | E5: Perception Adjusted Animal Lifes Affected (PAALA) - normalised | H5: Animal Life Years Suffered (ALYS) | K5: Perception Adjusted Animal Life Years Suffered (PAALYS)
B6: Total | C6: Prod. animal | D6: Parent | E6: Total | F6: Prod. animal | G6: Parent | H6: Total | I6: Prod. animal | J6: Parent | K6: Total | L6: Prod. animal | M6: Parent
A7: Beef suckler herds | B7: =C7+D7 -> 0.36485399 | C7: =B22*C22*D22*100 -> 0.31998591 | D7: =Q22*R22*S22*100 -> 0.044868084 | E7: =F7+G7 -> 0.065536189 | F7: =B22*C22*E22*100 -> 0.057711898 | G7: =Q22*R22*T22*100 -> 0.0078242912 | H7: =I7+J7 -> 0.0011056637 | I7: =B22*((O22-P22)*F22+P22) -> 0.001025296 | J7: =Q22*((AD22-AE22)*U22+AE22) -> 8.0367756e-05 | K7: =L7+M7 -> 0.00097752067 | L7: =C22*B22*((O22-P22)*F22+P22) -> 0.00090646729 | M7: =R22*Q22*((AD22-AE22)*U22+AE22) -> 7.1053377e-05
A8: Beef dairy int | B8: =C8+D8 -> 0.74383519 | C8: =B23*C23*D23*100 -> 0.74383519 | E8: =F8+G8 -> 0.15940839 | F8: =B23*C23*E23*100 -> 0.15940839 | H8: =I8+J8 -> 0.0011271777 | I8: =B23*((O23-P23)*F23+P23) -> 0.0011271777 | K8: =L8+M8 -> 0.00092479057 | L8: =C23*B23*((O23-P23)*F23+P23) -> 0.00092479057
A9: Beef dairy ext | B9: =C9+D9 -> 0.48629812 | C9: =B24*C24*D24*100 -> 0.48629812 | E9: =F9+G9 -> 0.090781397 | F9: =B24*C24*E24*100 -> 0.090781397 | H9: =I9+J9 -> 0.0016846056 | I9: =B24*((O24-P24)*F24+P24) -> 0.0016846056 | K9: =L9+M9 -> 0.0014893649 | L9: =C24*B24*((O24-P24)*F24+P24) -> 0.0014893649
A10: Milk | B10: =C10+D10 -> 0.013130923 | C10: =B25*C25*D25*100 -> 0.013130923 | E10: =F10+G10 -> 0.0024187957 | F10: =B25*C25*E25*100 -> 0.0024187957 | H10: =I10+J10 -> 0.00019141559 | I10: =B25*((O25-P25)*F25+P25) -> 0.00019141559 | K10: =L10+M10 -> 0.0001692311 | L10: =C25*B25*((O25-P25)*F25+P25) -> 0.0001692311
A11: Horse meat | B11: =C11+D11 -> 0.44273297 | C11: =B26*C26*D26*100 -> 0.44273297 | E11: =F11+G11 -> 0.10886218 | F11: =B26*C26*E26*100 -> 0.10886218 | H11: =I11+J11 -> 0.0015173486 | I11: =B26*((O26-P26)*F26+P26) -> 0.0015173486 | K11: =L11+M11 -> 0.001333956 | L11: =C26*B26*((O26-P26)*F26+P26) -> 0.001333956
A12: Lamb meat | B12: =C12+D12 -> 5.9505124 | C12: =B27*C27*D27*100 -> 5.8569891 | D12: =Q27*R27*S27*100 -> 0.093523242 | E12: =F12+G12 -> 1.1380144 | F12: =B27*C27*E27*100 -> 1.1215974 | G12: =Q27*R27*T27*100 -> 0.016416934 | H12: =I12+J12 -> 0.0057325817 | I12: =B27*((O27-P27)*F27+P27) -> 0.005652211 | J12: =Q27*((AD27-AE27)*U27+AE27) -> 8.0370729e-05 | K12: =L12+M12 -> 0.0047084007 | L12: =C27*B27*((O27-P27)*F27+P27) -> 0.0046373447 | M12: =R27*Q27*((AD27-AE27)*U27+AE27) -> 7.1056005e-05
