Workbook

Sheet README
A2: Supplementary Material 2 to
A4: Advancing Metrics for Animal Welfare and Antibiotic Use in Sustainability Assessments of Diets
A5: by
A6: Lotta Rydhmer, Professor in Animal Breeding, Swedish University of Agricultural Sciences
A7: Elin Röös, Associate Professor in Sustainable Food Systems, Swedish University of Agricultural Sciences
A10: Explanation of the sheets:
A11: Antibiotics use | B11: Calculates the antibiotic use indicator for different animal species for all countries for which data is available in ESVAC
A12: Standard values | B12: Calculates the 'standardised values' for use of antibiotics for different animal species, i.e. a typical use of antibiotics for a certain species based on the limited amount of species-specific use in literature
A13: Simple indicator | B13: A comparison between the Antibiotic use indicator developed here and an indicator only considering the total use per country (without ajusting for varying use across species)
A14: Fig.4 | B14: Figure 4 used in manuscript

Sheet Antibiotics use index
A2: Antibiotic use 2022
A4: Actual use | B4: https://esvacbi.ema.europa.eu/analytics/saw.dll?Dashboard | K4: Expected use | U4: Antibiotic use index
A6: PCU tonne: | B6: Cattle | C6: Pigs | D6: Poultry | E6: Sheep and goats | F6: Fish | G6: Rabbits | H6: Horses | I6: Total PCU (tonnes) | J6: mg/PCU | K6: Cattle | L6: Pigs | M6: Poultry | N6: Sheep and goats | O6: Fish | P6: Rabbits | Q6: Horses | R6: Total | S6: mg/PCU | T6: Actual use/ expected use | U6: Cattle meat | V6: Milk | W6: Horse meat | X6: Lamb meat | Y6: Pig meat | Z6: Chicken meat | AA6: Rabbit meat | AB6: Egg | AC6: Farmed fish
A7: Austria | B7: 433.39881 | C7: 342.28736 | D7: 91.384443 | E7: 37.73044 | F7: 0 | G7: 0 | H7: 41.6336 | I7: =SUM(B7:H7) -> 946.43465 | J7: 36.2 | K7: =B7*$K$39 -> 13001.964 | L7: =C7*$L$39 -> 20537.242 | M7: =D7*$M$39 -> 2741.5333 | N7: =E7*$N$39 -> 754.6088 | O7: =F7*$O$39 -> 0 | P7: =G7*$P$39 -> 0 | Q7: =H7*$Q$39 -> 220.95546 | R7: =SUM(K7:Q7) -> 37256.303 | S7: =R7/I7 -> 39.364898 | T7: =J7/S7 -> 0.91960101 | U7: =$U$39*$T7 -> 8.2764091 | V7: =$V$39*$T7 -> 1.1704013 | W7: =$W$39*$T7 -> 4.880454 | X7: =$X$39*$T7 -> 18.39202 | Y7: =$Y$39*$T7 -> 55.176061 | Z7: =$Z$39*$T7 -> 24.001586 | AA7: =$AA$39*$T7 -> 717.28879 | AB7: =$AB$39*$T7 -> 0.33622912 | AC7: =$AC$39*$T7 -> 27.58803
A8: Belgium | B8: 465.93412 | C8: 783.63464 | D8: 247.59898 | E8: 18.817885 | F8: 0 | G8: 3.4118826 | H8: 115.1564 | I8: =SUM(B8:H8) -> 1634.5539 | J8: 73.5 | K8: =B8*$K$39 -> 13978.024 | L8: =C8*$L$39 -> 47018.079 | M8: =D8*$M$39 -> 7427.9693 | N8: =E8*$N$39 -> 376.3577 | O8: =F8*$O$39 -> 0 | P8: =G8*$P$39 -> 2661.2684 | Q8: =H8*$Q$39 -> 611.15147 | R8: =SUM(K8:Q8) -> 72072.849 | S8: =R8/I8 -> 44.093284 | T8: =J8/S8 -> 1.6669205 | U8: =$U$39*$T8 -> 15.002285 | V8: =$V$39*$T8 -> 2.1215352 | W8: =$W$39*$T8 -> 8.8465854 | X8: =$X$39*$T8 -> 33.338411 | Y8: =$Y$39*$T8 -> 100.01523 | Z8: =$Z$39*$T8 -> 43.506626 | AA8: =$AA$39*$T8 -> 1300.198 | AB8: =$AB$39*$T8 -> 0.60946782 | AC8: =$AC$39*$T8 -> 50.007616
A9: Bulgaria | B9: 102.00217 | C9: 90.70827 | D9: 50.3945 | E9: 83.51968 | F9: 13 | G9: 0.0023968 | H9: 18.334 | I9: =SUM(B9:H9) -> 357.96101 | J9: 103.2 | K9: =B9*$K$39 -> 3060.0649 | L9: =C9*$L$39 -> 5442.4962 | M9: =D9*$M$39 -> 1511.835 | N9: =E9*$N$39 -> 1670.3936 | O9: =F9*$O$39 -> 390 | P9: =G9*$P$39 -> 1.869504 | Q9: =H9*$Q$39 -> 97.301157 | R9: =SUM(K9:Q9) -> 12173.96 | S9: =R9/I9 -> 34.00918 | T9: =J9/S9 -> 3.0344748 | U9: =$U$39*$T9 -> 27.310273 | V9: =$V$39*$T9 -> 3.8620589 | W9: =$W$39*$T9 -> 16.104391 | X9: =$X$39*$T9 -> 60.689497 | Y9: =$Y$39*$T9 -> 182.06849 | Z9: =$Z$39*$T9 -> 79.199793 | AA9: =$AA$39*$T9 -> 2366.8904 | AB9: =$AB$39*$T9 -> 1.1094799 | AC9: =$AC$39*$T9 -> 91.034245
A10: Croatia | B10: 80.92152 | C10: 85.984885 | D10: 49.652929 | E10: 47.7028 | F10: 27.245 | G10: 0.0082236 | H10: 12.592 | I10: =SUM(B10:H10) -> 304.10736 | J10: 56.2 | K10: =B10*$K$39 -> 2427.6456 | L10: =C10*$L$39 -> 5159.0931 | M10: =D10*$M$39 -> 1489.5879 | N10: =E10*$N$39 -> 954.056 | O10: =F10*$O$39 -> 817.35 | P10: =G10*$P$39 -> 6.414408 | Q10: =H10*$Q$39 -> 66.827543 | R10: =SUM(K10:Q10) -> 10920.975 | S10: =R10/I10 -> 35.911576 | T10: =J10/S10 -> 1.564955 | U10: =$U$39*$T10 -> 14.084595 | V10: =$V$39*$T10 -> 1.9917609 | W10: =$W$39*$T10 -> 8.3054397 | X10: =$X$39*$T10 -> 31.2991 | Y10: =$Y$39*$T10 -> 93.897299 | Z10: =$Z$39*$T10 -> 40.845325 | AA10: =$AA$39*$T10 -> 1220.6649 | AB10: =$AB$39*$T10 -> 0.57218667 | AC10: =$AC$39*$T10 -> 46.948649
A11: Cyprus | B11: 28.66374 | C11: 42.43625 | D11: 13.856344 | E11: 44.99183 | F11: 8 | G11: 0.0786632 | H11: 1.7136 | I11: =SUM(B11:H11) -> 139.74043 | J11: 254.7 | K11: =B11*$K$39 -> 859.9122 | L11: =C11*$L$39 -> 2546.175 | M11: =D11*$M$39 -> 415.69032 | N11: =E11*$N$39 -> 899.8366 | O11: =F11*$O$39 -> 240 | P11: =G11*$P$39 -> 61.357296 | Q11: =H11*$Q$39 -> 9.09432 | R11: =SUM(K11:Q11) -> 5032.0657 | S11: =R11/I11 -> 36.010093 | T11: =J11/S11 -> 7.0730171 | U11: =$U$39*$T11 -> 63.657154 | V11: =$V$39*$T11 -> 9.0020217 | W11: =$W$39*$T11 -> 37.537512 | X11: =$X$39*$T11 -> 141.46034 | Y11: =$Y$39*$T11 -> 424.38102 | Z11: =$Z$39*$T11 -> 184.60575 | AA11: =$AA$39*$T11 -> 5516.9533 | AB11: =$AB$39*$T11 -> 2.5860719 | AC11: =$AC$39*$T11 -> 212.19051
A12: Czech Republic | B12: 293.47504 | C12: 189.8949 | D12: 132.62026 | E12: 13.64866 | F12: 19.259 | G12: 7.0329 | H12: 40.7788 | I12: =SUM(B12:H12) -> 696.70957 | J12: 46.4 | K12: =B12*$K$39 -> 8804.2512 | L12: =C12*$L$39 -> 11393.694 | M12: =D12*$M$39 -> 3978.6079 | N12: =E12*$N$39 -> 272.9732 | O12: =F12*$O$39 -> 577.77 | P12: =G12*$P$39 -> 5485.662 | Q12: =H12*$Q$39 -> 216.41892 | R12: =SUM(K12:Q12) -> 30729.378 | S12: =R12/I12 -> 44.106438 | T12: =J12/S12 -> 1.0520006 | U12: =$U$39*$T12 -> 9.4680055 | V12: =$V$39*$T12 -> 1.3389099 | W12: =$W$39*$T12 -> 5.5831175 | X12: =$X$39*$T12 -> 21.040012 | Y12: =$Y$39*$T12 -> 63.120037 | Z12: =$Z$39*$T12 -> 27.457216 | AA12: =$AA$39*$T12 -> 820.56048 | AB12: =$AB$39*$T12 -> 0.38463772 | AC12: =$AC$39*$T12 -> 31.560018
A13: Denmark | B13: 376.56768 | C13: 1736.7402 | D13: 117.04645 | E13: 14.818625 | F13: 40.699 | G13: 0 | H13: 70 | I13: =SUM(B13:H13) -> 2355.8719 | J13: 34.1 | K13: =B13*$K$39 -> 11297.03 | L13: =C13*$L$39 -> 104204.41 | M13: =D13*$M$39 -> 3511.3934 | N13: =E13*$N$39 -> 296.3725 | O13: =F13*$O$39 -> 1220.97 | P13: =G13*$P$39 -> 0 | Q13: =H13*$Q$39 -> 371.5 | R13: =SUM(K13:Q13) -> 120901.68 | S13: =R13/I13 -> 51.319291 | T13: =J13/S13 -> 0.66446748 | U13: =$U$39*$T13 -> 5.9802073 | V13: =$V$39*$T13 -> 0.84568588 | W13: =$W$39*$T13 -> 3.5264238 | X13: =$X$39*$T13 -> 13.28935 | Y13: =$Y$39*$T13 -> 39.868049 | Z13: =$Z$39*$T13 -> 17.342601 | AA13: =$AA$39*$T13 -> 518.28463 | AB13: =$AB$39*$T13 -> 0.24294592 | AC13: =$AC$39*$T13 -> 19.934024
A14: Estonia | B14: 59.675825 | C14: 41.236135 | D14: 2.5013695 | E14: 5.12738 | F14: 0.801 | G14: 0.000539 | H14: 5.138 | I14: =SUM(B14:H14) -> 114.48025 | J14: 45.8 | K14: =B14*$K$39 -> 1790.2748 | L14: =C14*$L$39 -> 2474.1681 | M14: =D14*$M$39 -> 75.041085 | N14: =E14*$N$39 -> 102.5476 | O14: =F14*$O$39 -> 24.03 | P14: =G14*$P$39 -> 0.42042 | Q14: =H14*$Q$39 -> 27.2681 | R14: =SUM(K14:Q14) -> 4493.7501 | S14: =R14/I14 -> 39.253497 | T14: =J14/S14 -> 1.166775 | U14: =$U$39*$T14 -> 10.500975 | V14: =$V$39*$T14 -> 1.4849864 | W14: =$W$39*$T14 -> 6.1922418 | X14: =$X$39*$T14 -> 23.335501 | Y14: =$Y$39*$T14 -> 70.006502 | Z14: =$Z$39*$T14 -> 30.452828 | AA14: =$AA$39*$T14 -> 910.08453 | AB14: =$AB$39*$T14 -> 0.42660212 | AC14: =$AC$39*$T14 -> 35.003251
A15: Finland | B15: 199.33572 | C15: 141.3841 | D15: 87.08421 | E15: 11.10662 | F15: 16.281 | G15: 0 | H15: 29.6 | I15: =SUM(B15:H15) -> 484.79165 | J15: 14.9 | K15: =B15*$K$39 -> 5980.0716 | L15: =C15*$L$39 -> 8483.046 | M15: =D15*$M$39 -> 2612.5263 | N15: =E15*$N$39 -> 222.1324 | O15: =F15*$O$39 -> 488.43 | P15: =G15*$P$39 -> 0 | Q15: =H15*$Q$39 -> 157.09143 | R15: =SUM(K15:Q15) -> 17943.298 | S15: =R15/I15 -> 37.01239 | T15: =J15/S15 -> 0.40256789 | U15: =$U$39*$T15 -> 3.623111 | V15: =$V$39*$T15 -> 0.51235914 | W15: =$W$39*$T15 -> 2.1364853 | X15: =$X$39*$T15 -> 8.0513579 | Y15: =$Y$39*$T15 -> 24.154074 | Z15: =$Z$39*$T15 -> 10.507022 | AA15: =$AA$39*$T15 -> 314.00296 | AB15: =$AB$39*$T15 -> 0.14718889 | AC15: =$AC$39*$T15 -> 12.077037
A16: France | B16: 2910.8983 | C16: 1719.8894 | D16: 989.88366 | E16: 595.0212 | F16: 45.164 | G16: 35.6286 | H16: 264.96 | I16: =SUM(B16:H16) -> 6561.4452 | J16: 38.9 | K16: =B16*$K$39 -> 87326.948 | L16: =C16*$L$39 -> 103193.37 | M16: =D16*$M$39 -> 29696.51 | N16: =E16*$N$39 -> 11900.424 | O16: =F16*$O$39 -> 1354.92 | P16: =G16*$P$39 -> 27790.308 | Q16: =H16*$Q$39 -> 1406.1806 | R16: =SUM(K16:Q16) -> 262668.66 | S16: =R16/I16 -> 40.032135 | T16: =J16/S16 -> 0.97171935 | U16: =$U$39*$T16 -> 8.7454742 | V16: =$V$39*$T16 -> 1.2367337 | W16: =$W$39*$T16 -> 5.1570534 | X16: =$X$39*$T16 -> 19.434387 | Y16: =$Y$39*$T16 -> 58.303161 | Z16: =$Z$39*$T16 -> 25.361875 | AA16: =$AA$39*$T16 -> 757.9411 | AB16: =$AB$39*$T16 -> 0.35528489 | AC16: =$AC$39*$T16 -> 29.151581
A17: Germany | B17: 2751.2838 | C17: 3171.0321 | D17: 985.57711 | E17: 132.02944 | F17: 17.833 | G17: 23.13248 | H17: 520 | I17: =SUM(B17:H17) -> 7600.888 | J17: 69.9 | K17: =B17*$K$39 -> 82538.515 | L17: =C17*$L$39 -> 190261.93 | M17: =D17*$M$39 -> 29567.313 | N17: =E17*$N$39 -> 2640.5888 | O17: =F17*$O$39 -> 534.99 | P17: =G17*$P$39 -> 18043.334 | Q17: =H17*$Q$39 -> 2759.7143 | R17: =SUM(K17:Q17) -> 326346.38 | S17: =R17/I17 -> 42.935297 | T17: =J17/S17 -> 1.6280311 | U17: =$U$39*$T17 -> 14.65228 | V17: =$V$39*$T17 -> 2.0720396 | W17: =$W$39*$T17 -> 8.6401938 | X17: =$X$39*$T17 -> 32.560623 | Y17: =$Y$39*$T17 -> 97.681868 | Z17: =$Z$39*$T17 -> 42.491612 | AA17: =$AA$39*$T17 -> 1269.8643 | AB17: =$AB$39*$T17 -> 0.59524888 | AC17: =$AC$39*$T17 -> 48.840934
A18: Greece | B18: 76.921365 | C18: 99.94041 | D18: 150.39825 | E18: 680.11078 | F18: 130.17741 | G18: 2.1253792 | H18: 2.2024 | I18: =SUM(B18:H18) -> 1141.876 | J18: 89 | K18: =B18*$K$39 -> 2307.6409 | L18: =C18*$L$39 -> 5996.4246 | M18: =D18*$M$39 -> 4511.9475 | N18: =E18*$N$39 -> 13602.216 | O18: =F18*$O$39 -> 3905.3222 | P18: =G18*$P$39 -> 1657.7958 | Q18: =H18*$Q$39 -> 11.688451 | R18: =SUM(K18:Q18) -> 31993.035 | S18: =R18/I18 -> 28.017959 | T18: =J18/S18 -> 3.176534 | U18: =$U$39*$T18 -> 28.588806 | V18: =$V$39*$T18 -> 4.0428614 | W18: =$W$39*$T18 -> 16.85832 | X18: =$X$39*$T18 -> 63.53068 | Y18: =$Y$39*$T18 -> 190.59204 | Z18: =$Z$39*$T18 -> 82.907537 | AA18: =$AA$39*$T18 -> 2477.6965 | AB18: =$AB$39*$T18 -> 1.1614202 | AC18: =$AC$39*$T18 -> 95.29602
... A37: UK | B37: 1740 | C37: 803 | D37: 1187 | E37: 2749 | F37: 220 | G37: 0 | H37: 339 | I37: =SUM(B37:H37) -> 7038 | J37: 25.7 | K37: =B37*$K$39 -> 52200 | L37: =C37*$L$39 -> 48180 | M37: =D37*$M$39 -> 35610 | N37: =E37*$N$39 -> 54980 | O37: =F37*$O$39 -> 6600 | P37: =G37*$P$39 -> 0 | Q37: =H37*$Q$39 -> 1799.1214 | R37: =SUM(K37:Q37) -> 199369.12 | S37: =R37/I37 -> 28.327525 | T37: =J37/S37 -> 0.90724481 | U37: =$U$39*$T37 -> 8.1652033 | V37: =$V$39*$T37 -> 1.1546752 | W37: =$W$39*$T37 -> 4.8148778 | X37: =$X$39*$T37 -> 18.144896 | Y37: =$Y$39*$T37 -> 54.434688 | Z37: =$Z$39*$T37 -> 23.679089 | AA37: =$AA$39*$T37 -> 707.65095 | AB37: =$AB$39*$T37 -> 0.33171138 | AC37: =$AC$39*$T37 -> 27.217344
A39: Standardised values, mg per kg | K39: ='Standardised values'!B34 -> 30 | L39: ='Standardised values'!D34 -> 60 | M39: ='Standardised values'!F34 -> 30 | N39: ='Standardised values'!H34 -> 20 | O39: ='Standardised values'!J34 -> 30 | P39: ='Standardised values'!L34 -> 780 | Q39: ='Standardised values'!N34 -> 5.3071429 | U39: ='Standardised values'!B39 -> 9 | V39: ='Standardised values'!B38 -> 1.2727273 | W39: ='Standardised values'!N34 -> 5.3071429 | X39: ='Standardised values'!H34 -> 20 | Y39: ='Standardised values'!D34 -> 60 | Z39: ='Standardised values'!B42 -> 26.1 | AA39: ='Standardised values'!L34 -> 780 | AB39: ='Standardised values'!B41 -> 0.365625 | AC39: ='Standardised values'!J34 -> 30

Sheet Standardised values
A2: Standardised values
A4: PCU in tonne and % of total national PCU year 2022 (ESVAC, 2023)
B5: Cattle | C5: % | D5: Pigs | E5: % | F5: Poultry | G5: % | H5: Sheep & goat | I5: % | J5: Fish | K5: % | L5: Rabbits | M5: % | N5: Horses | O5: % | P5: PCU total | R5: Population Correction Unit (PCU) is a theoretical unit of measurement developed by the European Medicines Agency (EMA) in 2009 and adopted across Europe.
A6: Austria | B6: 433 | C6: =(B6/P6)*100 -> 45.77167 | D6: 342.3 | E6: =(D6/P6)*100 -> 36.183932 | F6: 91.4 | G6: =(F6/P6)*100 -> 9.6617336 | H6: 37.7 | I6: =(H6/P6)*100 -> 3.9852008 | J6: 0 | K6: =(J6/P6)*100 -> 0 | L6: 0 | M6: =(L6/P6)*100 -> 0 | N6: 41.6 | O6: =(N6/P6)*100 -> 4.397463 | P6: =B6+D6+F6+H6+J6+L6+N6 -> 946 | R6: It takes into account a country’s animal population over a year, along with the estimated weight of each particular species at the time of treatment with antibiotics
A7: Denmark | B7: 377 | C7: =(B7/P7)*100 -> 15.998303 | D7: 1737 | E7: =(D7/P7)*100 -> 73.711012 | F7: 117 | G7: =(F7/P7)*100 -> 4.9649905 | H7: 14.8 | I7: =(H7/P7)*100 -> 0.62805007 | J7: 40.7 | K7: =(J7/P7)*100 -> 1.7271377 | L7: 0 | M7: =(L7/P7)*100 -> 0 | N7: 70 | O7: =(N7/P7)*100 -> 2.9705071 | P7: =B7+D7+F7+H7+J7+L7+N7 -> 2356.5
A8: France | B8: 2911 | C8: =(B8/P8)*100 -> 41.814499 | D8: 1720 | E8: =(D8/P8)*100 -> 24.706609 | F8: 989.9 | G8: =(F8/P8)*100 -> 14.219228 | H8: 595 | I8: =(H8/P8)*100 -> 8.546763 | J8: 445.2 | K8: =(J8/P8)*100 -> 6.3949897 | L8: 35.6 | M8: =(L8/P8)*100 -> 0.51136935 | N8: 265 | O8: =(N8/P8)*100 -> 3.8065415 | P8: =B8+D8+F8+H8+J8+L8+N8 -> 6961.7
A9: Germany | B9: 2751 | C9: =(B9/P9)*100 -> 36.194987 | D9: 3171 | E9: =(D9/P9)*100 -> 41.720939 | F9: 985.6 | G9: =(F9/P9)*100 -> 12.967568 | H9: 132 | I9: =(H9/P9)*100 -> 1.7367278 | J9: 17.8 | K9: =(J9/P9)*100 -> 0.23419512 | L9: 23.1 | M9: =(L9/P9)*100 -> 0.30392737 | N9: 520 | O9: =(N9/P9)*100 -> 6.8416552 | P9: =B9+D9+F9+H9+J9+L9+N9 -> 7600.5
A10: Greece | B10: 76.9 | C10: =(B10/P10)*100 -> 6.7361598 | D10: 99.9 | E10: =(D10/P10)*100 -> 8.750876 | F10: 150.4 | G10: =(F10/P10)*100 -> 13.174492 | H10: 680.1 | I10: =(H10/P10)*100 -> 59.574282 | J10: 130 | K10: =(J10/P10)*100 -> 11.387526 | L10: 2.1 | M10: =(L10/P10)*100 -> 0.18395235 | N10: 2.2 | O10: =(N10/P10)*100 -> 0.19271198 | P10: =B10+D10+F10+H10+J10+L10+N10 -> 1141.6
A11: Hungary | B11: 180 | C11: =(B11/P11)*100 -> 21.603457 | D11: 321.4 | E11: =(D11/P11)*100 -> 38.574172 | F11: 200.9 | G11: =(F11/P11)*100 -> 24.111858 | H11: 74 | I11: =(H11/P11)*100 -> 8.881421 | J11: 27 | K11: =(J11/P11)*100 -> 3.2405185 | L11: 5.5 | M11: =(L11/P11)*100 -> 0.66010562 | N11: 24.4 | O11: =(N11/P11)*100 -> 2.9284686 | P11: =B11+D11+F11+H11+J11+L11+N11 -> 833.2
A12: Ireland | B12: 1352 | C12: =(B12/P12)*100 -> 60.195904 | D12: 289.5 | E12: =(D12/P12)*100 -> 12.889581 | F12: 102 | G12: =(F12/P12)*100 -> 4.5414069 | H12: 357.8 | I12: =(H12/P12)*100 -> 15.930543 | J12: 44.7 | K12: =(J12/P12)*100 -> 1.9902048 | L12: 0 | M12: =(L12/P12)*100 -> 0 | N12: 100 | O12: =(N12/P12)*100 -> 4.4523598 | P12: =B12+D12+F12+H12+J12+L12+N12 -> 2246
A13: Italy | B13: 1458 | C13: =(B13/P13)*100 -> 39.233626 | D13: 796.8 | E13: =(D13/P13)*100 -> 21.441257 | F13: 666.7 | G13: =(F13/P13)*100 -> 17.940369 | H13: 536.9 | I13: =(H13/P13)*100 -> 14.447554 | J13: 53.9 | K13: =(J13/P13)*100 -> 1.4504063 | L13: 27.3 | M13: =(L13/P13)*100 -> 0.73462139 | N13: 176.6 | O13: =(N13/P13)*100 -> 4.7521662 | P13: =B13+D13+F13+H13+J13+L13+N13 -> 3716.2
A14: NL | B14: 1015 | C14: =(B14/P14)*100 -> 33.554828 | D14: 1562 | E14: =(D14/P14)*100 -> 51.638071 | F14: 330.9 | G14: =(F14/P14)*100 -> 10.939205 | H14: 72 | I14: =(H14/P14)*100 -> 2.380244 | J14: 5.6 | K14: =(J14/P14)*100 -> 0.18513009 | L14: 0.4 | M14: =(L14/P14)*100 -> 0.013223578 | N14: 39 | O14: =(N14/P14)*100 -> 1.2892988 | P14: =B14+D14+F14+H14+J14+L14+N14 -> 3024.9
A15: Poland | B15: 1480 | C15: =(B15/P15)*100 -> 34.59884 | D15: 1203 | E15: =(D15/P15)*100 -> 28.123247 | F15: 1411.5 | G15: =(F15/P15)*100 -> 32.997475 | H15: 21.2 | I15: =(H15/P15)*100 -> 0.49560501 | J15: 45.4 | K15: =(J15/P15)*100 -> 1.0613428 | L15: 2 | M15: =(L15/P15)*100 -> 0.04675519 | N15: 114.5 | O15: =(N15/P15)*100 -> 2.6767346 | P15: =B15+D15+F15+H15+J15+L15+N15 -> 4277.6
A16: Spain | B16: 1012 | C16: =(B16/P16)*100 -> 12.550537 | D16: 4270 | E16: =(D16/P16)*100 -> 52.955329 | F16: 880.2 | G16: =(F16/P16)*100 -> 10.915991 | H16: 1298.3 | I16: =(H16/P16)*100 -> 16.101148 | J16: 302 | K16: =(J16/P16)*100 -> 3.7453184 | L16: 46.9 | M16: =(L16/P16)*100 -> 0.5816405 | N16: 254 | O16: =(N16/P16)*100 -> 3.150036 | P16: =B16+D16+F16+H16+J16+L16+N16 -> 8063.4
A17: Sweden | B17: 284 | C17: =(B17/P17)*100 -> 36.017755 | D17: 203.9 | E17: =(D17/P17)*100 -> 25.859226 | F17: 116.3 | G17: =(F17/P17)*100 -> 14.749524 | H17: 30.2 | I17: =(H17/P17)*100 -> 3.8300571 | J17: 11.9 | K17: =(J17/P17)*100 -> 1.5091947 | L17: 0 | M17: =(L17/P17)*100 -> 0 | N17: 142.2 | O17: =(N17/P17)*100 -> 18.034242 | P17: =B17+D17+F17+H17+J17+L17+N17 -> 788.5
A18: UK | B18: 1740 | C18: =(B18/P18)*100 -> 24.722933 | D18: 803 | E18: =(D18/P18)*100 -> 11.409491 | F18: 1187 | G18: =(F18/P18)*100 -> 16.865587 | H18: 2749 | I18: =(H18/P18)*100 -> 39.059392 | J18: 220 | K18: =(J18/P18)*100 -> 3.125888 | L18: 0 | M18: =(L18/P18)*100 -> 0 | N18: 339 | O18: =(N18/P18)*100 -> 4.8167093 | P18: =B18+D18+F18+H18+J18+L18+N18 -> 7038
A19: Norway | B19: 220 | C19: =(B19/P19)*100 -> 10.005913 | D19: 115.6 | E19: =(D19/P19)*100 -> 5.2576522 | F19: 73.6 | G19: =(F19/P19)*100 -> 3.3474326 | H19: 93.5 | I19: =(H19/P19)*100 -> 4.2525128 | J19: 1646 | K19: =(J19/P19)*100 -> 74.862419 | L19: 0 | M19: =(L19/P19)*100 -> 0 | N19: 50 | O19: =(N19/P19)*100 -> 2.274071 | P19: =B19+D19+F19+H19+J19+L19+N19 -> 2198.7
A20: Average % | C20: =AVERAGE(C7:C18) -> 30.268486 | E20: =AVERAGE(E7:E18) -> 32.648318 | G20: =AVERAGE(G7:G18) -> 14.865641 | I20: =AVERAGE(I7:I18) -> 14.300982 | K20: =AVERAGE(K7:K18) -> 3.004321 | M20: =AVERAGE(M7:M18) -> 0.25296628 | O20: =AVERAGE(O7:O18) -> 4.6592859
A22: Species specific use of antibiotics as available in literature and calculation of standardised values
B23: Cattle | D23: Pigs | F23: Poultry | H23: Sheep&goat | J23: Fish | L23: Rabbits | N23: Horses
A24: DK PCU | B24: =B7 -> 377 | D24: =D7 -> 1737 | F24: =F7 -> 117 | H24: =H7 -> 14.8 | J24: =J7 -> 40.7 | N24: =N7 -> 70
A25: kg sold | B25: 9425 | D25: 72345 | F25: 1196 | H25: 15 | J25: 1771 | N25: 113 | P25: DANMAP, 2021
A26: DK mg/kg | B26: =(B25*1000)/(B7*1000) -> 25 | D26: =(D25*1000)/(D7*1000) -> 41.649396 | F26: =(F25*1000)/(F7*1000) -> 10.222222 | H26: =(H25*1000)/(H7*1000) -> 1.0135135 | J26: =(J25*1000)/(J7*1000) -> 43.513514 | N26: =(N25*1000)/(N7*1000) -> 1.6142857
A27: NL PCU | B27: =B14 -> 1015 | D27: =D14 -> 1562 | F27: =F14 -> 330.9 | L27: =L14 -> 0.4
A28: kg sold | B28: =12195+44208+5782 -> 62185 | D28: 52011 | F28: =5752+2184 -> 7936 | L28: 377 | P28: SDa, 2021
A29: NL mg/kg | B29: =(B28*1000)/(B14*1000) -> 61.26601 | D29: =(D28*1000)/(D14*1000) -> 33.297695 | F29: =(F28*1000)/(F14*1000) -> 23.983076 | L29: =(L28*1000)/(L14*1000) -> 942.5
A30: UK mg/kg | B30: 19.6 | D30: 87.3 | F30: 13.7 | H30: 8.4 | J30: 43.1 | N30: 9 | P30: Cattle, pig, poultry, fish UK-VARSS, 2022 (data fr 2021); Horse Tallon et al (2023) assuming 20% of all horses visits clinic per year; Sheep TESCO, 2024 (data fr 2021)
A31: France mg/kg | B31: 38 | D31: 73 | F31: 64 | H31: 51 | L31: 775 | P31: Nunan, 2022 (data fr 2020)
A32: Norway mg/kg | J32: 1 | P32: NORM-VET, 2021
A33: Austria mg/kg | B33: 15.6 | D33: 68.8 | F33: 25.1 | P33: AGES, 2023
A34: Standardised value, mg/kg | B34: =ROUND(AVERAGE(B26,B29,B30,B31,B33),-1) -> 30 | D34: =ROUND(AVERAGE(D26,D29,D30,D31,D33),-1) -> 60 | F34: =ROUND(AVERAGE(F26,F29,F30,F31,F33),-1) -> 30 | H34: =ROUND(AVERAGE(H26,H30,H31),-1) -> 20 | J34: =ROUND(AVERAGE(J26,J30,J32),-1) -> 30 | L34: =ROUND(L31,-1) -> 780 | N34: =AVERAGE(N30,N26) -> 5.3071429
A36: Allocation | L36: Rabbit set to 780 based on French data, since NL has such low rabbit production (i.e. assumed not representative)
A37: Allocating 70% to dairy cattle due to considerably more use of antibiotics in dairy than beef production (based on Humphry et al., 2021; Ferroni et al; 2020)
A38: Milk | B38: =B34*0.7*600/9900 -> 1.2727273 | C38: Assuming a dairy cow weighs 600 kg and yields 9900 kg of milk per year (Eurostat, average over included countries, 2017-2021)
A39: Cattle meat | B39: =B34*0.3 -> 9
A40: Allocating 87% to broilers and 13% to laying hens (based on UK-VARSS, 2022; TESCO, 2024)
A41: Egg | B41: =F34*0.13*1.5/16 -> 0.365625 | C41: Assuming a hen weighs 1.5 kg and lays 16 kg of eggs per year (Eurostat)
A42: Poultry meat | B42: =F34*0.87 -> 26.1
A44: References
A45: AGES, 2023 | B45: Antibiotic sales volumes in veterinary medicine. https://www.ages.at/en/animal/veterinary-medicines-hormones/antibiotic-sales-volumes-in-veterinary-medicine
...

Sheet Simple indicator
A2: Comparisson between the antibiotic use indicator and a simple indicator based on total use as reported to ESVAC
B5: ESVAC total use | D5: Expected pig use | F5: Expected lamb use
B6: mg/PCU | C6: rank | D6: mg/PCU | E6: rank | F6: mg/PCU | G6: rank
A7: Denmark | B7: 34.1 | C7: 3 | D7: 40 | E7: 2 | F7: 13 | G7: 2
A8: France | B8: 38.9 | C8: 5 | D8: 58 | E8: 4 | F8: 19 | G8: 4
A9: Germany | B9: 69.9 | C9: 6 | D9: 98 | E9: 6 | F9: 33 | G9: 6
A10: Greece | B10: 89 | C10: 7 | D10: 183 | E10: 9 | F10: 61 | G10: 9
A11: Hungary | B11: 111.2 | C11: 8 | D11: 148 | E11: 7 | F11: 49 | G11: 7
A12: Ireland | B12: 33.6 | C12: 2 | D12: 64 | E12: 5 | F12: 21 | G12: 5
A13: Italy | B13: 157.5 | C13: 10 | D13: 240 | E13: 10 | F13: 80 | G13: 10
A14: NL | B14: 37 | C14: 4 | D14: 49 | E14: 3 | F14: 16 | G14: 3
A15: Poland | B15: 196 | C15: 11 | D15: 308 | E15: 11 | F15: 103 | G15: 11
A16: Spain | B16: 127.4 | C16: 9 | D16: 159 | E16: 8 | F16: 53 | G16: 8
A17: Sweden | B17: 10.6 | C17: 1 | D17: 19 | E17: 1 | F17: 6 | G17: 1
I19: Lower rank is better. For the antibiotic use index, the rank order of countries is the same for all food products
I21: Ireland and Greece would get a more favourable outcome if the assessment was based only on total use from ESVAC (dark blue) than when based on the Antibiotic use index (lightblue and green)

Sheet Fig. 4
A2: Figure 4. Antibiotic use in mg per kg of product from different countries
A29: Rabbit meat, with an average indicator value of 1613 mg per kg meat for the 11 countries, is not included in the diagram.
