Workbook
Name _Ref32411070: 'Input - Microbial Protein'!$I$187
Name _Ref45878722: 'Input - Microbial Protein'!$I$149
Name _Ref45878756: 'Input - Microbial Protein'!$I$150
Name _Toc62923992: 'Input - Microbial Protein'!$I$169
Name _Toc62924001: 'Input - Microbial Protein'!$A$149
Name Bonefree_outof_CW_DE: '[1]Parameters, country spec'!$D$8
Name Bonefree_outof_CW_DK: '[1]Parameters, country spec'!$B$8
Name Bonefree_outof_CW_ES: '[1]Parameters, country spec'!$K$8
Name Bonefree_outof_CW_FR: '[1]Parameters, country spec'!$C$8
Name Bonefree_outof_CW_GR: '[1]Parameters, country spec'!$E$8
Name Bonefree_outof_CW_HU: '[1]Parameters, country spec'!$F$8
Name Bonefree_outof_CW_IE: '[1]Parameters, country spec'!$G$8
Name Bonefree_outof_CW_IT: '[1]Parameters, country spec'!$H$8
Name Bonefree_outof_CW_NL: '[1]Parameters, country spec'!$I$8
Name Bonefree_outof_CW_PL: '[1]Parameters, country spec'!$J$8
Name Bonefree_outof_CW_SE: '[1]Parameters, country spec'!$L$8
Name CF_CH4_bio: 'CF climate'!$C$5
Name CF_CH4_foss: 'CF climate'!$D$5
Name CF_CO2: 'CF climate'!$B$5
Name CF_N2O: 'CF climate'!$E$5
Name EF_biofuel_CH4: #REF!
Name EF_biofuel_N2O: #REF!
Name EF_biofuels_CO2: #REF!
Name EF_el_CH4_BR: #REF!
Name EF_el_CH4_DE: '[1]Parameters, country spec'!$D$91
Name EF_el_CH4_DK: '[1]Parameters, country spec'!$B$91
Name EF_el_CH4_ES: '[1]Parameters, country spec'!$K$91
Name EF_el_CH4_FR: #REF!
Name EF_el_CH4_GR: '[1]Parameters, country spec'!$E$91
Name EF_el_CH4_HU: '[1]Parameters, country spec'!$F$91
Name EF_el_CH4_IE: '[1]Parameters, country spec'!$G$91
Name EF_el_CH4_IT: '[1]Parameters, country spec'!$H$91
Name EF_el_CH4_NL: '[1]Parameters, country spec'!$I$91
Name EF_el_CH4_PL: '[1]Parameters, country spec'!$J$91
Name EF_el_CH4_SE: '[1]Parameters, country spec'!$L$91
Name EF_el_CO2_BR: #REF!
Name EF_el_CO2_DE: '[1]Parameters, country spec'!$D$90
Name EF_el_CO2_DK: '[1]Parameters, country spec'!$B$90
Name EF_el_CO2_ES: '[1]Parameters, country spec'!$K$90
Name EF_el_CO2_FR: #REF!
Name EF_el_CO2_GR: '[1]Parameters, country spec'!$E$90
Name EF_el_CO2_HU: '[1]Parameters, country spec'!$F$90
Name EF_el_CO2_IE: '[1]Parameters, country spec'!$G$90
Name EF_el_CO2_IT: '[1]Parameters, country spec'!$H$90
Name EF_el_CO2_NL: '[1]Parameters, country spec'!$I$90
Name EF_el_CO2_PL: '[1]Parameters, country spec'!$J$90
Name EF_el_CO2_SE: '[1]Parameters, country spec'!$L$90
Name EF_el_N2O_BR: #REF!
Name EF_el_N2O_DE: '[1]Parameters, country spec'!$D$92
Name EF_el_N2O_DK: '[1]Parameters, country spec'!$B$92
Name EF_el_N2O_ES: '[1]Parameters, country spec'!$K$92
Name EF_el_N2O_FR: #REF!
Name EF_el_N2O_GR: '[1]Parameters, country spec'!$E$92
Name EF_el_N2O_HU: '[1]Parameters, country spec'!$F$92
Name EF_el_N2O_IE: '[1]Parameters, country spec'!$G$92
Name EF_el_N2O_IT: '[1]Parameters, country spec'!$H$92
Name EF_el_N2O_NL: '[1]Parameters, country spec'!$I$92
Name EF_el_N2O_PL: '[1]Parameters, country spec'!$J$92
Name EF_el_N2O_SE: '[1]Parameters, country spec'!$L$92
Name EF_ent_ferm_DE: '[1]Parameters, country spec'!$D$75

Sheet Footprints, results per kg
A2: Novel foods
A4: Species | F4: Climate | L4: Land | M4: Nitrogen | N4: Phosphorus | O4: Water | P4: Pesticides | Q4: Biodiversity | R4: Ammonia | S4: Labour | T4: Animal welfare | U4: Use of antibiotics
A5: Code | B5: Species | C5: Category | D5: Country | E5: Country code | F5: Carbon footprint, kg CO2e/kg | G5: Carbon dioxide, kg CO2/kg | H5: Methane, fossil, kg CH4/kg | I5: Methane, biogenic, kg CH4/kg | J5: Nitrous oxide, kg N2O/kg | K5: HFCs, kg HFCs/kg | L5: Cropland use, m2/kg | M5: New N input, kg N/kg | N5: New P input, kg P/kg | O5: Blue freshwater use, m3/kg | P5: Pesticide use, g a.i./kg | Q5: Extinction rate, E/MSY/kg | R5: Ammonia emission, kg NH3/kg | S5: Labour requirements, h/kg | T5: Animal welfare index per kg of novel food
A6: NF-01 | B6: Cultured Meat (Bos. Spp.) | C6: Novel food | D6: Israel | E6: IL | F6: ='GHG detailed, results per kg'!G10 -> 17.194275 | G6: ='GHG detailed, results per kg'!G6 -> 15.279234 | H6: ='GHG detailed, results per kg'!G7 -> 0.046008135 | I6: ='GHG detailed, results per kg'!G8 -> 0 | J6: ='GHG detailed, results per kg'!G9 -> 0.0019926707 | L6: ='Novel foods, input data'!$AB$6*'Agri ing'!$P$27 -> 3.3515324 | M6: ='Novel foods, input data'!$AB$6*'Agri ing'!$Q$27 -> 0.04569437 | N6: ='Novel foods, input data'!$AB$6*'Agri ing'!$R$27 -> 0.014952789 | O6: ='Novel foods, input data'!$AB$6*'Agri ing'!$S$27 -> 0.17035718 | P6: ='Novel foods, input data'!$AB$6*'Agri ing'!$T$27 -> 0.85916204 | Q6: ='Novel foods, input data'!$AB$6*'Agri ing'!$U$27*100 -> 3.124086e-11 | R6: ='Novel foods, input data'!$AB$6*'Agri ing'!$V$27 -> 0.0027779711 | T6: 0 | U6: 0
A7: NF-01 | B7: Cultured Meat (Bos. Spp.) | C7: Novel food | D7: Netherlands | E7: NL | F7: ='GHG detailed, results per kg'!G15 -> 4.2362683 | G7: ='GHG detailed, results per kg'!G11 -> 3.5498417 | H7: ='GHG detailed, results per kg'!G12 -> 0.0070766997 | I7: ='GHG detailed, results per kg'!G13 -> 0 | J7: ='GHG detailed, results per kg'!G14 -> 0.0017419081 | L7: ='Novel foods, input data'!$AB$6*'Agri ing'!$P$27 -> 3.3515324 | M7: ='Novel foods, input data'!$AB$6*'Agri ing'!$Q$27 -> 0.04569437 | N7: ='Novel foods, input data'!$AB$6*'Agri ing'!$R$27 -> 0.014952789 | O7: ='Novel foods, input data'!$AB$6*'Agri ing'!$S$27 -> 0.17035718 | P7: ='Novel foods, input data'!$AB$6*'Agri ing'!$T$27 -> 0.85916204 | Q7: ='Novel foods, input data'!$AB$6*'Agri ing'!$U$27*100 -> 3.124086e-11 | R7: ='Novel foods, input data'!$AB$6*'Agri ing'!$V$27 -> 0.0027779711 | T7: 0 | U7: 0
A8: NF-01 | B8: Cultured Meat (Bos. Spp.) | C8: Novel food | D8: Sweden | E8: SE | F8: ='GHG detailed, results per kg'!G20 -> 1.61596 | G8: ='GHG detailed, results per kg'!G16 -> 1.1066169 | H8: ='GHG detailed, results per kg'!G17 -> 0.0017795518 | I8: ='GHG detailed, results per kg'!G18 -> 0 | J8: ='GHG detailed, results per kg'!G19 -> 0.0016714742 | L8: ='Novel foods, input data'!$AB$6*'Agri ing'!$P$27 -> 3.3515324 | M8: ='Novel foods, input data'!$AB$6*'Agri ing'!$Q$27 -> 0.04569437 | N8: ='Novel foods, input data'!$AB$6*'Agri ing'!$R$27 -> 0.014952789 | O8: ='Novel foods, input data'!$AB$6*'Agri ing'!$S$27 -> 0.17035718 | P8: ='Novel foods, input data'!$AB$6*'Agri ing'!$T$27 -> 0.85916204 | Q8: ='Novel foods, input data'!$AB$6*'Agri ing'!$U$27*100 -> 3.124086e-11 | R8: ='Novel foods, input data'!$AB$6*'Agri ing'!$V$27 -> 0.0027779711 | T8: 0 | U8: 0
A9: NF-01 | B9: Cultured Meat (Bos. Spp.) | C9: Novel food | D9: USA | E9: US | F9: ='GHG detailed, results per kg'!G25 -> 4.3700633 | G9: ='GHG detailed, results per kg'!G21 -> 3.7219655 | H9: ='GHG detailed, results per kg'!G22 -> 0.0060709677 | I9: ='GHG detailed, results per kg'!G23 -> 0 | J9: ='GHG detailed, results per kg'!G24 -> 0.001711293 | L9: ='Novel foods, input data'!$AB$6*'Agri ing'!$P$27 -> 3.3515324 | M9: ='Novel foods, input data'!$AB$6*'Agri ing'!$Q$27 -> 0.04569437 | N9: ='Novel foods, input data'!$AB$6*'Agri ing'!$R$27 -> 0.014952789 | O9: ='Novel foods, input data'!$AB$6*'Agri ing'!$S$27 -> 0.17035718 | P9: ='Novel foods, input data'!$AB$6*'Agri ing'!$T$27 -> 0.85916204 | Q9: ='Novel foods, input data'!$AB$6*'Agri ing'!$U$27*100 -> 3.124086e-11 | R9: ='Novel foods, input data'!$AB$6*'Agri ing'!$V$27 -> 0.0027779711 | T9: 0 | U9: 0
A10: NF-02 | B10: Microbial Milk (T. reesei) | C10: Novel food | D10: Denmark | E10: DK | F10: ='GHG detailed, results per kg'!G30 -> 1.3241574 | G10: ='GHG detailed, results per kg'!G26 -> 1.054122 | H10: ='GHG detailed, results per kg'!G27 -> 0.001308799 | I10: ='GHG detailed, results per kg'!G28 -> 0 | J10: ='GHG detailed, results per kg'!G29 -> 0.00084627547 | L10: ='Novel foods, input data'!$AB$7*'Agri ing'!$P$27 -> 1.6935889 | M10: ='Novel foods, input data'!$AB$7*'Agri ing'!$O$27 -> 0.00081991307 | N10: ='Novel foods, input data'!$AB$7*'Agri ing'!$R$27 -> 0.0075559101 | O10: ='Novel foods, input data'!$AB$7*'Agri ing'!$S$27 -> 0.086084513 | P10: ='Novel foods, input data'!$AB$7*'Agri ing'!$T$27 -> 0.43414986 | Q10: ='Novel foods, input data'!$AB$7*'Agri ing'!$U$27*100 -> 1.5786562e-11 | R10: ='Novel foods, input data'!$AB$7*'Agri ing'!$V$27 -> 0.0014037582 | T10: 0 | U10: 0
A11: NF-02 | B11: Microbial Milk (T. reesei) | C11: Novel food | D11: Germany | E11: DE | F11: ='GHG detailed, results per kg'!G35 -> 1.4688404 | G11: ='GHG detailed, results per kg'!G31 -> 1.1826885 | H11: ='GHG detailed, results per kg'!G32 -> 0.0018281417 | I11: ='GHG detailed, results per kg'!G33 -> 0 | J11: ='GHG detailed, results per kg'!G34 -> 0.00084861989 | L11: ='Novel foods, input data'!$AB$7*'Agri ing'!$P$27 -> 1.6935889 | M11: ='Novel foods, input data'!$AB$7*'Agri ing'!$O$27 -> 0.00081991307 | N11: ='Novel foods, input data'!$AB$7*'Agri ing'!$R$27 -> 0.0075559101 | O11: ='Novel foods, input data'!$AB$7*'Agri ing'!$S$27 -> 0.086084513 | P11: ='Novel foods, input data'!$AB$7*'Agri ing'!$T$27 -> 0.43414986 | Q11: ='Novel foods, input data'!$AB$7*'Agri ing'!$U$27*100 -> 1.5786562e-11 | R11: ='Novel foods, input data'!$AB$7*'Agri ing'!$V$27 -> 0.0014037582 | T11: 0 | U11: 0
A12: NF-02 | B12: Microbial Milk (T. reesei) | C12: Novel food | D12: Sweden | E12: SE | F12: ='GHG detailed, results per kg'!G40 -> 0.91295494 | G12: ='GHG detailed, results per kg'!G36 -> 0.66404222 | H12: ='GHG detailed, results per kg'!G37 -> 0.00073795969 | I12: ='GHG detailed, results per kg'!G38 -> 0 | J12: ='GHG detailed, results per kg'!G35 -> 1.4688404 | L12: ='Novel foods, input data'!$AB$7*'Agri ing'!$P$27 -> 1.6935889 | M12: ='Novel foods, input data'!$AB$7*'Agri ing'!$O$27 -> 0.00081991307 | N12: ='Novel foods, input data'!$AB$7*'Agri ing'!$R$27 -> 0.0075559101 | O12: ='Novel foods, input data'!$AB$7*'Agri ing'!$S$27 -> 0.086084513 | P12: ='Novel foods, input data'!$AB$7*'Agri ing'!$T$27 -> 0.43414986 | Q12: ='Novel foods, input data'!$AB$7*'Agri ing'!$U$27*100 -> 1.5786562e-11 | R12: ='Novel foods, input data'!$AB$7*'Agri ing'!$V$27 -> 0.0014037582 | T12: 0 | U12: 0
A13: NF-02 | B13: Microbial Milk (T. reesei) | C13: Novel food | D13: Switzerland | E13: CH | F13: ='GHG detailed, results per kg'!G45 -> 0.91295494 | G13: ='GHG detailed, results per kg'!G41 -> 0.66404222 | H13: ='GHG detailed, results per kg'!G42 -> 0.00073795969 | I13: ='GHG detailed, results per kg'!G43 -> 0 | J13: ='GHG detailed, results per kg'!G39 -> 0.00083121437 | L13: ='Novel foods, input data'!$AB$7*'Agri ing'!$P$27 -> 1.6935889 | M13: ='Novel foods, input data'!$AB$7*'Agri ing'!$O$27 -> 0.00081991307 | N13: ='Novel foods, input data'!$AB$7*'Agri ing'!$R$27 -> 0.0075559101 | O13: ='Novel foods, input data'!$AB$7*'Agri ing'!$S$27 -> 0.086084513 | P13: ='Novel foods, input data'!$AB$7*'Agri ing'!$T$27 -> 0.43414986 | Q13: ='Novel foods, input data'!$AB$7*'Agri ing'!$U$27*100 -> 1.5786562e-11 | R13: ='Novel foods, input data'!$AB$7*'Agri ing'!$V$27 -> 0.0014037582 | T13: 0 | U13: 0
A14: NF-02 | B14: Microbial Milk (T. reesei) | C14: Novel food | D14: USA | E14: US | F14: ='GHG detailed, results per kg'!G50 -> 1.5493915 | G14: ='GHG detailed, results per kg'!G46 -> 1.2684144 | H14: ='GHG detailed, results per kg'!G47 -> 0.0017296487 | I14: ='GHG detailed, results per kg'!G48 -> 0 | J14: ='GHG detailed, results per kg'!G44 -> 0.00083121437 | L14: ='Novel foods, input data'!$AB$7*'Agri ing'!$P$27 -> 1.6935889 | M14: ='Novel foods, input data'!$AB$7*'Agri ing'!$O$27 -> 0.00081991307 | N14: ='Novel foods, input data'!$AB$7*'Agri ing'!$R$27 -> 0.0075559101 | O14: ='Novel foods, input data'!$AB$7*'Agri ing'!$S$27 -> 0.086084513 | P14: ='Novel foods, input data'!$AB$7*'Agri ing'!$T$27 -> 0.43414986 | Q14: ='Novel foods, input data'!$AB$7*'Agri ing'!$U$27*100 -> 1.5786562e-11 | R14: ='Novel foods, input data'!$AB$7*'Agri ing'!$V$27 -> 0.0014037582 | T14: 0 | U14: 0
A15: NF-03 | B15: Microbial Ovalbumin (T. reesei) | C15: Novel food | D15: Denmark | E15: DK | F15: ='GHG detailed, results per kg'!G55 -> 6.183196 | G15: ='GHG detailed, results per kg'!G51 -> 5.4401856 | H15: ='GHG detailed, results per kg'!G52 -> 0.004702669 | I15: ='GHG detailed, results per kg'!G53 -> 0 | J15: ='GHG detailed, results per kg'!G49 -> 0.00084041596 | L15: ='Novel foods, input data'!$AB$8*'Agri ing'!$P$27 -> 4.3173585 | M15: ='Novel foods, input data'!$AB$8*'Agri ing'!$O$27 -> 0.0020901522 | N15: ='Novel foods, input data'!$AB$8*'Agri ing'!$R$27 -> 0.019261801 | O15: ='Novel foods, input data'!$AB$8*'Agri ing'!$S$27 -> 0.21944977 | P15: ='Novel foods, input data'!$AB$8*'Agri ing'!$T$27 -> 1.1067506 | Q15: ='Novel foods, input data'!$AB$8*'Agri ing'!$U$27*100 -> 4.0243678e-11 | R15: ='Novel foods, input data'!$AB$8*'Agri ing'!$V$27 -> 0.0035785114 | T15: 0 | U15: 0
A16: NF-03 | B16: Microbial Ovalbumin (T. reesei) | C16: Novel food | D16: Germany | E16: DE | F16: ='GHG detailed, results per kg'!G60 -> 6.8317181 | G16: ='GHG detailed, results per kg'!G56 -> 6.0164679 | H16: ='GHG detailed, results per kg'!G57 -> 0.007030554 | I16: ='GHG detailed, results per kg'!G58 -> 0 | J16: ='GHG detailed, results per kg'!G54 -> 0.0022083182 | L16: ='Novel foods, input data'!$AB$8*'Agri ing'!$P$27 -> 4.3173585 | M16: ='Novel foods, input data'!$AB$8*'Agri ing'!$O$27 -> 0.0020901522 | N16: ='Novel foods, input data'!$AB$8*'Agri ing'!$R$27 -> 0.019261801 | O16: ='Novel foods, input data'!$AB$8*'Agri ing'!$S$27 -> 0.21944977 | P16: ='Novel foods, input data'!$AB$8*'Agri ing'!$T$27 -> 1.1067506 | Q16: ='Novel foods, input data'!$AB$8*'Agri ing'!$U$27*100 -> 4.0243678e-11 | R16: ='Novel foods, input data'!$AB$8*'Agri ing'!$V$27 -> 0.0035785114 | T16: 0 | U16: 0
A17: NF-03 | B17: Microbial Ovalbumin (T. reesei) | C17: Novel food | D17: Sweden | E17: SE | F17: ='GHG detailed, results per kg'!G65 -> 4.3400351 | G17: ='GHG detailed, results per kg'!G61 -> 3.6917044 | H17: ='GHG detailed, results per kg'!G62 -> 0.0021439571 | I17: ='GHG detailed, results per kg'!G63 -> 0 | J17: ='GHG detailed, results per kg'!G59 -> 0.0022188267 | L17: ='Novel foods, input data'!$AB$8*'Agri ing'!$P$27 -> 4.3173585 | M17: ='Novel foods, input data'!$AB$8*'Agri ing'!$O$27 -> 0.0020901522 | N17: ='Novel foods, input data'!$AB$8*'Agri ing'!$R$27 -> 0.019261801 | O17: ='Novel foods, input data'!$AB$8*'Agri ing'!$S$27 -> 0.21944977 | P17: ='Novel foods, input data'!$AB$8*'Agri ing'!$T$27 -> 1.1067506 | Q17: ='Novel foods, input data'!$AB$8*'Agri ing'!$U$27*100 -> 4.0243678e-11 | R17: ='Novel foods, input data'!$AB$8*'Agri ing'!$V$27 -> 0.0035785114 | T17: 0 | U17: 0
A18: NF-03 | B18: Microbial Ovalbumin (T. reesei) | C18: Novel food | D18: Switzerland | E18: CH | F18: ='GHG detailed, results per kg'!G70 -> 4.3400351 | G18: ='GHG detailed, results per kg'!G66 -> 3.6917044 | H18: ='GHG detailed, results per kg'!G67 -> 0.0021439571 | I18: ='GHG detailed, results per kg'!G68 -> 0 | J18: ='GHG detailed, results per kg'!G64 -> 0.0021408088 | L18: ='Novel foods, input data'!$AB$8*'Agri ing'!$P$27 -> 4.3173585 | M18: ='Novel foods, input data'!$AB$8*'Agri ing'!$O$27 -> 0.0020901522 | N18: ='Novel foods, input data'!$AB$8*'Agri ing'!$R$27 -> 0.019261801 | O18: ='Novel foods, input data'!$AB$8*'Agri ing'!$S$27 -> 0.21944977 | P18: ='Novel foods, input data'!$AB$8*'Agri ing'!$T$27 -> 1.1067506 | Q18: ='Novel foods, input data'!$AB$8*'Agri ing'!$U$27*100 -> 4.0243678e-11 | R18: ='Novel foods, input data'!$AB$8*'Agri ing'!$V$27 -> 0.0035785114 | T18: 0 | U18: 0
A19: NF-03 | B19: Microbial Ovalbumin (T. reesei) | C19: Novel food | D19: USA | E19: US | F19: ='GHG detailed, results per kg'!G75 -> 7.1927779 | G19: ='GHG detailed, results per kg'!G71 -> 6.4007229 | H19: ='GHG detailed, results per kg'!G72 -> 0.0065890719 | I19: ='GHG detailed, results per kg'!G73 -> 0 | J19: ='GHG detailed, results per kg'!G69 -> 0.0021408088 | L19: ='Novel foods, input data'!$AB$8*'Agri ing'!$P$27 -> 4.3173585 | M19: ='Novel foods, input data'!$AB$8*'Agri ing'!$O$27 -> 0.0020901522 | N19: ='Novel foods, input data'!$AB$8*'Agri ing'!$R$27 -> 0.019261801 | O19: ='Novel foods, input data'!$AB$8*'Agri ing'!$S$27 -> 0.21944977 | P19: ='Novel foods, input data'!$AB$8*'Agri ing'!$T$27 -> 1.1067506 | Q19: ='Novel foods, input data'!$AB$8*'Agri ing'!$U$27*100 -> 4.0243678e-11 | R19: ='Novel foods, input data'!$AB$8*'Agri ing'!$V$27 -> 0.0035785114 | T19: 0 | U19: 0
A20: NF-04 | B20: Microbial Protein (Solein) | C20: Novel food | D20: Finland | E20: FI | F20: ='GHG detailed, results per kg'!G80 -> 6.2223283 | G20: ='GHG detailed, results per kg'!G76 -> 5.8015207 | H20: ='GHG detailed, results per kg'!G77 -> 0.0109117 | I20: ='GHG detailed, results per kg'!G78 -> 0 | J20: ='GHG detailed, results per kg'!G74 -> 0.0021820537 | L20: 0 | M20: 0 | N20: 0 | O20: 0 | P20: 0 | Q20: 0 | R20: 0 | T20: 0 | U20: 0
A21: NF-04 | B21: Microbial Protein (Solein) | C21: Novel food | D21: Sweden | E21: SE | F21: ='GHG detailed, results per kg'!G85 -> 2.1205044 | G21: ='GHG detailed, results per kg'!G81 -> 2.0272184 | H21: ='GHG detailed, results per kg'!G82 -> 0.001776827 | I21: ='GHG detailed, results per kg'!G83 -> 0 | J21: ='GHG detailed, results per kg'!G79 -> 0.00035032584 | L21: 0 | M21: 0 | N21: 0 | O21: 0 | P21: 0 | Q21: 0 | R21: 0 | T21: 0 | U21: 0
A22: NF-05 | B22: Mycoprotein (Quorn) | C22: Novel food | D22: Sweden | E22: SE | F22: ='GHG detailed, results per kg'!G90 -> 1.9266956 | G22: ='GHG detailed, results per kg'!G86 -> 1.065323 | H22: ='GHG detailed, results per kg'!G87 -> 0.0024494886 | I22: ='GHG detailed, results per kg'!G88 -> 7.0753259e-05 | J22: ='GHG detailed, results per kg'!G84 -> 0.00014775292 | L22: ='Novel foods, input data'!$AD$10*'Agri ing'!N21+'Novel foods, input data'!$AE$10*'Agri ing'!P26 -> 4.0200759 | M22: ='Novel foods, input data'!$AD$10*'Agri ing'!O21+'Novel foods, input data'!$AE$10*'Agri ing'!Q26 -> 0.051406516 | N22: ='Novel foods, input data'!$AD$10*'Agri ing'!P21+'Novel foods, input data'!$AE$10*'Agri ing'!R26 -> 0.0047428771 | O22: ='Novel foods, input data'!$AD$10*'Agri ing'!Q21+'Novel foods, input data'!$AE$10*'Agri ing'!S26 -> 0.01731524 | P22: ='Novel foods, input data'!$AD$10*'Agri ing'!R21+'Novel foods, input data'!$AE$10*'Agri ing'!T26 -> 0.51524659 | Q22: =('Novel foods, input data'!$AD$10*'Agri ing'!S21+'Novel foods, input data'!$AE$10*'Agri ing'!U26)*100 -> 1.0074487e-10 | R22: ='Novel foods, input data'!$AD$10*'Agri ing'!T21+'Novel foods, input data'!$AE$10*'Agri ing'!V26 -> 0.0031181532 | T22: ='Novel foods, input data'!$AD$10*'Agri ing'!U21+'Novel foods, input data'!$AE$10*'Agri ing'!W26 -> 0.29204351 | U22: ='Novel foods, input data'!$AD$10*'Agri ing'!V21+'Novel foods, input data'!$AE$10*'Agri ing'!X26 -> 0.0082673929
A23: NF-05 | B23: Mycoprotein (Quorn) | C23: Novel food | D23: UK | E23: GB | F23: ='GHG detailed, results per kg'!G95 -> 2.0031952 | G23: ='GHG detailed, results per kg'!G91 -> 1.1247856 | H23: ='GHG detailed, results per kg'!G92 -> 0.0027051407 | I23: ='GHG detailed, results per kg'!G93 -> 7.0753259e-05 | J23: ='GHG detailed, results per kg'!G89 -> 0.0028808334 | L23: ='Novel foods, input data'!$AD$10*'Agri ing'!N21+'Novel foods, input data'!$AE$10*'Agri ing'!P26 -> 4.0200759 | M23: ='Novel foods, input data'!$AD$10*'Agri ing'!O21+'Novel foods, input data'!$AE$10*'Agri ing'!Q26 -> 0.051406516 | N23: ='Novel foods, input data'!$AD$10*'Agri ing'!P21+'Novel foods, input data'!$AE$10*'Agri ing'!R26 -> 0.0047428771 | O23: ='Novel foods, input data'!$AD$10*'Agri ing'!Q21+'Novel foods, input data'!$AE$10*'Agri ing'!S26 -> 0.01731524 | P23: ='Novel foods, input data'!$AD$10*'Agri ing'!R21+'Novel foods, input data'!$AE$10*'Agri ing'!T26 -> 0.51524659 | Q23: =('Novel foods, input data'!$AD$10*'Agri ing'!S21+'Novel foods, input data'!$AE$10*'Agri ing'!U26)*100 -> 1.0074487e-10 | R23: ='Novel foods, input data'!$AD$10*'Agri ing'!T21+'Novel foods, input data'!$AE$10*'Agri ing'!V26 -> 0.0031181532 | T23: ='Novel foods, input data'!$AD$10*'Agri ing'!U21+'Novel foods, input data'!$AE$10*'Agri ing'!W26 -> 0.29204351 | U23: ='Novel foods, input data'!$AD$10*'Agri ing'!V21+'Novel foods, input data'!$AE$10*'Agri ing'!X26 -> 0.0082673929
A24: NF-06 | B24: Yeast Fat (Rhodotorula babjevae) | C24: Novel food | D24: Israel | E24: IL | F24: ='GHG detailed, results per kg'!G100 -> 0.93463893 | G24: ='GHG detailed, results per kg'!G96 -> 0.85944291 | H24: ='GHG detailed, results per kg'!G97 -> 0.0020750212 | I24: ='GHG detailed, results per kg'!G98 -> 0 | J24: ='GHG detailed, results per kg'!G94 -> 0.0029153335 | L24: 0 | M24: 0 | N24: 0 | O24: 0 | P24: 0 | Q24: 0 | R24: 0 | T24: 0 | U24: 0
A25: NF-06 | B25: Yeast Fat (Rhodotorula babjevae) | C25: Novel food | D25: Netherlands | E25: NL | F25: ='GHG detailed, results per kg'!G105 -> 0.66161793 | G25: ='GHG detailed, results per kg'!G101 -> 0.61230844 | H25: ='GHG detailed, results per kg'!G102 -> 0.0012547486 | I25: ='GHG detailed, results per kg'!G103 -> 0 | J25: ='GHG detailed, results per kg'!G104 -> 4.365563e-05 | L25: 0 | M25: 0 | N25: 0 | O25: 0 | P25: 0 | Q25: 0 | R25: 0 | T25: 0 | U25: 0
A26: NF-06 | B26: Yeast Fat (Rhodotorula babjevae) | C26: Novel food | D26: Sweden | E26: SE | F26: ='GHG detailed, results per kg'!G110 -> 0.60640889 | G26: ='GHG detailed, results per kg'!G106 -> 0.56083048 | H26: ='GHG detailed, results per kg'!G107 -> 0.0011431394 | I26: ='GHG detailed, results per kg'!G108 -> 0 | J26: ='GHG detailed, results per kg'!G109 -> 4.2171613e-05 | L26: 0 | M26: 0 | N26: 0 | O26: 0 | P26: 0 | Q26: 0 | R26: 0 | T26: 0 | U26: 0
A27: NF-06 | B27: Yeast Fat (Rhodotorula babjevae) | C27: Novel food | D27: USA | E27: US | F27: ='GHG detailed, results per kg'!G115 -> 0.66443695 | G27: ='GHG detailed, results per kg'!G111 -> 0.61593503 | H27: ='GHG detailed, results per kg'!G112 -> 0.0012335581 | I27: ='GHG detailed, results per kg'!G113 -> 0 | J27: ='GHG detailed, results per kg'!G114 -> 4.3010581e-05 | L27: 0 | M27: 0 | N27: 0 | O27: 0 | P27: 0 | Q27: 0 | R27: 0 | T27: 0 | U27: 0
A28: NF-07 | B28: Algae Fat (Schizochytrium) | C28: Novel food | D28: Denmark | E28: DK | F28: ='GHG detailed, results per kg'!G120 -> 3.4589034 | G28: ='GHG detailed, results per kg'!G116 -> 2.5190595 | H28: ='GHG detailed, results per kg'!G117 -> 0.0037988689 | I28: ='GHG detailed, results per kg'!G118 -> 0 | J28: ='GHG detailed, results per kg'!G119 -> 0.0030279764 | L28: ='Novel foods, input data'!$AB$12*'Agri ing'!P27 -> 6.1296969 | M28: ='Novel foods, input data'!$AB$12*'Agri ing'!Q27 -> 0.083571514 | N28: ='Novel foods, input data'!$AB$12*'Agri ing'!R27 -> 0.027347509 | O28: ='Novel foods, input data'!$AB$12*'Agri ing'!S27 -> 0.31157027 | P28: ='Novel foods, input data'!$AB$12*'Agri ing'!T27 -> 1.5713418 | Q28: ='Novel foods, input data'!$AB$12*'Agri ing'!U27*100 -> 5.7137148e-11 | R28: ='Novel foods, input data'!$AB$12*'Agri ing'!V27 -> 0.005080697 | T28: 0 | U28: 0
A29: NF-07 | B29: Algae Fat (Schizochytrium) | C29: Novel food | D29: Germany | E29: DE | F29: ='GHG detailed, results per kg'!G125 -> 3.790509 | G29: ='GHG detailed, results per kg'!G121 -> 2.8137271 | H29: ='GHG detailed, results per kg'!G122 -> 0.0049891751 | I29: ='GHG detailed, results per kg'!G123 -> 0 | J29: ='GHG detailed, results per kg'!G124 -> 0.0030333497 | L29: ='Novel foods, input data'!$AB$12*'Agri ing'!P27 -> 6.1296969 | M29: ='Novel foods, input data'!$AB$12*'Agri ing'!Q27 -> 0.083571514 | N29: ='Novel foods, input data'!$AB$12*'Agri ing'!R27 -> 0.027347509 | O29: ='Novel foods, input data'!$AB$12*'Agri ing'!S27 -> 0.31157027 | P29: ='Novel foods, input data'!$AB$12*'Agri ing'!T27 -> 1.5713418 | Q29: ='Novel foods, input data'!$AB$12*'Agri ing'!U27*100 -> 5.7137148e-11 | R29: ='Novel foods, input data'!$AB$12*'Agri ing'!V27 -> 0.005080697 | T29: 0 | U29: 0
A30: NF-07 | B30: Algae Fat (Schizochytrium) | C30: Novel food | D30: Sweden | E30: SE | F30: ='GHG detailed, results per kg'!G130 -> 2.5164488 | G30: ='GHG detailed, results per kg'!G126 -> 1.6250171 | H30: ='GHG detailed, results per kg'!G127 -> 0.0024905351 | I30: ='GHG detailed, results per kg'!G128 -> 0 | J30: ='GHG detailed, results per kg'!G129 -> 0.0029934572 | L30: ='Novel foods, input data'!$AB$12*'Agri ing'!P27 -> 6.1296969 | M30: ='Novel foods, input data'!$AB$12*'Agri ing'!Q27 -> 0.083571514 | N30: ='Novel foods, input data'!$AB$12*'Agri ing'!R27 -> 0.027347509 | O30: ='Novel foods, input data'!$AB$12*'Agri ing'!S27 -> 0.31157027 | P30: ='Novel foods, input data'!$AB$12*'Agri ing'!T27 -> 1.5713418 | Q30: ='Novel foods, input data'!$AB$12*'Agri ing'!U27*100 -> 5.7137148e-11 | R30: ='Novel foods, input data'!$AB$12*'Agri ing'!V27 -> 0.005080697 | T30: 0 | U30: 0
A31: NF-07 | B31: Algae Fat (Schizochytrium) | C31: Novel food | D31: Switzerland | E31: CH | F31: ='GHG detailed, results per kg'!G135 -> 2.5164488 | G31: ='GHG detailed, results per kg'!G131 -> 1.6250171 | H31: ='GHG detailed, results per kg'!G132 -> 0.0024905351 | I31: ='GHG detailed, results per kg'!G133 -> 0 | J31: ='GHG detailed, results per kg'!G134 -> 0.0029934572 | L31: ='Novel foods, input data'!$AB$12*'Agri ing'!P27 -> 6.1296969 | M31: ='Novel foods, input data'!$AB$12*'Agri ing'!Q27 -> 0.083571514 | N31: ='Novel foods, input data'!$AB$12*'Agri ing'!R27 -> 0.027347509 | O31: ='Novel foods, input data'!$AB$12*'Agri ing'!S27 -> 0.31157027 | P31: ='Novel foods, input data'!$AB$12*'Agri ing'!T27 -> 1.5713418 | Q31: ='Novel foods, input data'!$AB$12*'Agri ing'!U27*100 -> 5.7137148e-11 | R31: ='Novel foods, input data'!$AB$12*'Agri ing'!V27 -> 0.005080697 | T31: 0 | U31: 0
A32: NF-07 | B32: Algae Fat (Schizochytrium) | C32: Novel food | D32: USA | E32: US | F32: ='GHG detailed, results per kg'!G140 -> 3.975128 | G32: ='GHG detailed, results per kg'!G136 -> 3.0102064 | H32: ='GHG detailed, results per kg'!G137 -> 0.0047634341 | I32: ='GHG detailed, results per kg'!G138 -> 0 | J32: ='GHG detailed, results per kg'!G139 -> 0.0030145467 | L32: ='Novel foods, input data'!$AB$12*'Agri ing'!P27 -> 6.1296969 | M32: ='Novel foods, input data'!$AB$12*'Agri ing'!Q27 -> 0.083571514 | N32: ='Novel foods, input data'!$AB$12*'Agri ing'!R27 -> 0.027347509 | O32: ='Novel foods, input data'!$AB$12*'Agri ing'!S27 -> 0.31157027 | P32: ='Novel foods, input data'!$AB$12*'Agri ing'!T27 -> 1.5713418 | Q32: ='Novel foods, input data'!$AB$12*'Agri ing'!U27*100 -> 5.7137148e-11 | R32: ='Novel foods, input data'!$AB$12*'Agri ing'!V27 -> 0.005080697 | T32: 0 | U32: 0

Sheet GHG detailed, results per kg
A2: GHG emissions (per kg of novel food)
A4: Product | G4: Sum | H4: Inputs | J4: Soil emissions | L4: Energy use | P4: Land use change | Q4: Feed processing | R4: Transports
A5: Code | B5: Species | C5: Category | D5: Country | E5: Country code | F5: Gas | G5: GHG | H5: Production of mineral fertilizer | I5: Production of capital goods | J5: Direct emissions | K5: Indirect emissions | L5: Diesel use field mach | M5: Energy use in greenhouses | N5: Energy use for irrigation | O5: Energy use for processing of novel foods and for minor ingredients | P5: LUC emissions | Q5: Feed processing | R5: Feed transports | S5: Enteric fermentation | T5: Manure management - tot | U5: Manure management - direct | V5: Manure management - indirect | W5: Energy use in stables | X5: Energy use for slaughter
A6: NF-01 | B6: Cultured Meat (Bos. Spp.) | C6: Novel food | D6: Israel | E6: IL | F6: CO2 | G6: =SUM(H6:X6) -> 15.279234 | H6: ='Novel foods, input data'!$AB$6*'Agri ing'!$AF$27 -> 0.16530307 | I6: ='Novel foods, input data'!$AB$6*'Agri ing'!$AG$27 -> 0.19564101 | J6: 0 | K6: 0 | L6: ='Novel foods, input data'!$AB$6*'Agri ing'!$AH$27 -> 0.21637121 | M6: 0 | N6: 0 | O6: ='Novel foods, input data'!$D$6*'Emission factors'!$B$12+'Novel foods, input data'!$AF$6 -> 14.701919 | P6: 0 | Q6: 0 | R6: 0 | S6: 0 | T6: 0 | U6: 0 | V6: 0 | W6: 0 | X6: 0
A7: NF-01 | B7: Cultured Meat (Bos. Spp.) | C7: Novel food | D7: Israel | E7: IL | F7: CH4, fossil | G7: =SUM(H7:X7) -> 0.046008135 | H7: ='Novel foods, input data'!$AB$6*'Agri ing'!$AJ$27 -> 0.00028384273 | I7: ='Novel foods, input data'!$AB$6*'Agri ing'!$AK$27 -> 0.00068836653 | J7: 0 | K7: 0 | L7: ='Novel foods, input data'!$AB$6*'Agri ing'!$AL$27 -> 0.00021922736 | M7: 0 | N7: 0 | O7: ='Novel foods, input data'!$D$6*'Emission factors'!$C$12+'Novel foods, input data'!$AG$6 -> 0.044816698 | P7: 0 | Q7: 0 | R7: 0 | S7: 0 | T7: 0 | U7: 0 | V7: 0 | W7: 0 | X7: 0
A8: NF-01 | B8: Cultured Meat (Bos. Spp.) | C8: Novel food | D8: Israel | E8: IL | F8: CH4, biogenic | G8: =SUM(H8:T8)+SUM(W8:X8) -> 0 | H8: 0 | I8: 0 | J8: 0 | K8: 0 | L8: 0 | M8: 0 | N8: 0 | O8: 0 | P8: 0 | Q8: 0 | R8: 0 | S8: 0 | T8: 0 | U8: 0 | V8: 0 | W8: 0 | X8: 0
A9: NF-01 | B9: Cultured Meat (Bos. Spp.) | C9: Novel food | D9: Israel | E9: IL | F9: N2O | G9: =SUM(H9:T9)+SUM(W9:X9) -> 0.0019926707 | H9: ='Novel foods, input data'!$AB$6*'Agri ing'!$AP$27 -> 0.00036002414 | I9: ='Novel foods, input data'!$AB$6*'Agri ing'!$AQ$27 -> 7.9705599e-06 | J9: ='Novel foods, input data'!$AB$6*'Agri ing'!$AR$27 -> 0.0012460278 | K9: 0 | L9: ='Novel foods, input data'!$AB$6*'Agri ing'!$AS$27 -> 8.5467492e-06 | M9: 0 | N9: 0 | O9: ='Novel foods, input data'!$D$6*'Emission factors'!$D$12+'Novel foods, input data'!$AH$6 -> 0.0003701015 | P9: 0 | Q9: 0 | R9: 0 | S9: 0 | T9: 0 | U9: 0 | V9: 0 | W9: 0 | X9: 0
A10: NF-01 | B10: Cultured Meat (Bos. Spp.) | C10: Novel food | D10: Israel | E10: IL | F10: CO2e | G10: =SUM(H10:X10) -> 17.194275 | H10: =H6+H7*CF_CH4_foss+H8*CF_CH4_bio+H9*CF_N2O -> 0.27204817 | I10: =I6+I7*CF_CH4_foss+I8*CF_CH4_bio+I9*CF_N2O -> 0.2183303 | J10: =J6+J7*CF_CH4_foss+J8*CF_CH4_bio+J9*CF_N2O -> 0.34016558 | K10: =K6+K7*CF_CH4_foss+K8*CF_CH4_bio+K9*CF_N2O -> 0 | L10: =L6+L7*CF_CH4_foss+L8*CF_CH4_bio+L9*CF_N2O -> 0.22523744 | M10: =M6+M7*CF_CH4_foss+M8*CF_CH4_bio+M9*CF_N2O -> 0 | N10: =N6+N7*CF_CH4_foss+N8*CF_CH4_bio+N9*CF_N2O -> 0 | O10: =O6+O7*CF_CH4_foss+O8*CF_CH4_bio+O9*CF_N2O -> 16.138494 | ... T10: =T6+T7*CF_CH4_foss+T8*CF_CH4_bio+T9*CF_N2O -> 0 | W10: =W6+W7*CF_CH4_foss+W8*CF_CH4_bio+W9*CF_N2O -> 0 | X10: =X6+X7*CF_CH4_foss+X8*CF_CH4_bio+X9*CF_N2O -> 0
A11: NF-01 | B11: Cultured Meat (Bos. Spp.) | C11: Novel food | D11: Netherlands | E11: NL | F11: CO2 | G11: =SUM(H11:X11) -> 3.5498417 | H11: ='Novel foods, input data'!$AB$6*'Agri ing'!$AF$27 -> 0.16530307 | I11: ='Novel foods, input data'!$AB$6*'Agri ing'!$AG$27 -> 0.19564101 | J11: 0 | K11: 0 | L11: ='Novel foods, input data'!$AB$6*'Agri ing'!$AH$27 -> 0.21637121 | M11: 0 | N11: 0 | O11: ='Novel foods, input data'!$D$6*'Emission factors'!$B$7+'Novel foods, input data'!$AF$6 -> 2.9725264 | P11: 0 | Q11: 0 | R11: 0 | S11: 0 | T11: 0 | U11: 0 | V11: 0 | W11: 0 | X11: 0
A12: NF-01 | B12: Cultured Meat (Bos. Spp.) | C12: Novel food | D12: Netherlands | E12: NL | F12: CH4, fossil | G12: =SUM(H12:X12) -> 0.0070766997 | H12: ='Novel foods, input data'!$AB$6*'Agri ing'!$AJ$27 -> 0.00028384273 | I12: ='Novel foods, input data'!$AB$6*'Agri ing'!$AK$27 -> 0.00068836653 | J12: 0 | K12: 0 | L12: ='Novel foods, input data'!$AB$6*'Agri ing'!$AL$27 -> 0.00021922736 | M12: 0 | N12: 0 | O12: ='Novel foods, input data'!$D$6*'Emission factors'!$C$7+'Novel foods, input data'!$AG$6 -> 0.0058852631 | P12: 0 | Q12: 0 | R12: 0 | S12: 0 | T12: 0 | U12: 0 | V12: 0 | W12: 0 | X12: 0
A13: NF-01 | B13: Cultured Meat (Bos. Spp.) | C13: Novel food | D13: Netherlands | E13: NL | F13: CH4, biogenic | G13: =SUM(H13:T13)+SUM(W13:X13) -> 0 | H13: 0 | I13: 0 | J13: 0 | K13: 0 | L13: 0 | M13: 0 | N13: 0 | O13: 0 | P13: 0 | Q13: 0 | R13: 0 | S13: 0 | T13: 0 | U13: 0 | V13: 0 | W13: 0 | X13: 0
A14: NF-01 | B14: Cultured Meat (Bos. Spp.) | C14: Novel food | D14: Netherlands | E14: NL | F14: N2O | G14: =SUM(H14:T14)+SUM(W14:X14) -> 0.0017419081 | H14: ='Novel foods, input data'!$AB$6*'Agri ing'!$AP$27 -> 0.00036002414 | I14: ='Novel foods, input data'!$AB$6*'Agri ing'!$AQ$27 -> 7.9705599e-06 | J14: ='Novel foods, input data'!$AB$6*'Agri ing'!$AR$27 -> 0.0012460278 | K14: 0 | L14: ='Novel foods, input data'!$AB$6*'Agri ing'!$AS$27 -> 8.5467492e-06 | M14: 0 | N14: 0 | O14: ='Novel foods, input data'!$D$6*'Emission factors'!$D$7+'Novel foods, input data'!$AH$6 -> 0.00011933884 | P14: 0 | Q14: 0 | R14: 0 | S14: 0 | T14: 0 | U14: 0 | V14: 0 | W14: 0 | X14: 0
A15: NF-01 | B15: Cultured Meat (Bos. Spp.) | C15: Novel food | D15: Netherlands | E15: NL | F15: CO2e | G15: =SUM(H15:X15) -> 4.2362683 | H15: =H11+H12*CF_CH4_foss+H13*CF_CH4_bio+H14*CF_N2O -> 0.27204817 | I15: =I11+I12*CF_CH4_foss+I13*CF_CH4_bio+I14*CF_N2O -> 0.2183303 | J15: =J11+J12*CF_CH4_foss+J13*CF_CH4_bio+J14*CF_N2O -> 0.34016558 | K15: =K11+K12*CF_CH4_foss+K13*CF_CH4_bio+K14*CF_N2O -> 0 | L15: =L11+L12*CF_CH4_foss+L13*CF_CH4_bio+L14*CF_N2O -> 0.22523744 | M15: =M11+M12*CF_CH4_foss+M13*CF_CH4_bio+M14*CF_N2O -> 0 | N15: =N11+N12*CF_CH4_foss+N13*CF_CH4_bio+N14*CF_N2O -> 0 | O15: =O11+O12*CF_CH4_foss+O13*CF_CH4_bio+O14*CF_N2O -> 3.1804868 | ... T15: =T11+T12*CF_CH4_foss+T13*CF_CH4_bio+T14*CF_N2O -> 0 | W15: =W11+W12*CF_CH4_foss+W13*CF_CH4_bio+W14*CF_N2O -> 0 | X15: =X11+X12*CF_CH4_foss+X13*CF_CH4_bio+X14*CF_N2O -> 0
A16: NF-01 | B16: Cultured Meat (Bos. Spp.) | C16: Novel food | D16: Sweden | E16: SE | F16: CO2 | G16: =SUM(H16:X16) -> 1.1066169 | H16: ='Novel foods, input data'!$AB$6*'Agri ing'!$AF$27 -> 0.16530307 | I16: ='Novel foods, input data'!$AB$6*'Agri ing'!$AG$27 -> 0.19564101 | J16: 0 | K16: 0 | L16: ='Novel foods, input data'!$AB$6*'Agri ing'!$AH$27 -> 0.21637121 | M16: 0 | N16: 0 | O16: ='Novel foods, input data'!$D$6*'Emission factors'!$B$11+'Novel foods, input data'!$AF$6 -> 0.52930157 | P16: 0 | Q16: 0 | R16: 0 | S16: 0 | T16: 0 | U16: 0 | V16: 0 | W16: 0 | X16: 0
A17: NF-01 | B17: Cultured Meat (Bos. Spp.) | C17: Novel food | D17: Sweden | E17: SE | F17: CH4, fossil | G17: =SUM(H17:X17) -> 0.0017795518 | H17: ='Novel foods, input data'!$AB$6*'Agri ing'!$AJ$27 -> 0.00028384273 | I17: ='Novel foods, input data'!$AB$6*'Agri ing'!$AK$27 -> 0.00068836653 | J17: 0 | K17: 0 | L17: ='Novel foods, input data'!$AB$6*'Agri ing'!$AL$27 -> 0.00021922736 | M17: 0 | N17: 0 | O17: ='Novel foods, input data'!$D$6*'Emission factors'!$C$11+'Novel foods, input data'!$AG$6 -> 0.00058811521 | P17: 0 | Q17: 0 | R17: 0 | S17: 0 | T17: 0 | U17: 0 | V17: 0 | W17: 0 | X17: 0
A18: NF-01 | B18: Cultured Meat (Bos. Spp.) | C18: Novel food | D18: Sweden | E18: SE | F18: CH4, biogenic | G18: =SUM(H18:T18)+SUM(W18:X18) -> 0 | H18: 0 | I18: 0 | J18: 0 | K18: 0 | L18: 0 | M18: 0 | N18: 0 | O18: 0 | P18: 0 | Q18: 0 | R18: 0 | S18: 0 | T18: 0 | U18: 0 | V18: 0 | W18: 0 | X18: 0
A19: NF-01 | B19: Cultured Meat (Bos. Spp.) | C19: Novel food | D19: Sweden | E19: SE | F19: N2O | G19: =SUM(H19:T19)+SUM(W19:X19) -> 0.0016714742 | H19: ='Novel foods, input data'!$AB$6*'Agri ing'!$AP$27 -> 0.00036002414 | I19: ='Novel foods, input data'!$AB$6*'Agri ing'!$AQ$27 -> 7.9705599e-06 | J19: ='Novel foods, input data'!$AB$6*'Agri ing'!$AR$27 -> 0.0012460278 | K19: 0 | L19: ='Novel foods, input data'!$AB$6*'Agri ing'!$AS$27 -> 8.5467492e-06 | M19: 0 | N19: 0 | O19: ='Novel foods, input data'!$D$6*'Emission factors'!$D$11+'Novel foods, input data'!$AH$6 -> 4.8905009e-05 | P19: 0 | Q19: 0 | R19: 0 | S19: 0 | T19: 0 | U19: 0 | V19: 0 | W19: 0 | X19: 0
A20: NF-01 | B20: Cultured Meat (Bos. Spp.) | C20: Novel food | D20: Sweden | E20: SE | F20: CO2e | G20: =SUM(H20:X20) -> 1.61596 | H20: =H16+H17*CF_CH4_foss+H18*CF_CH4_bio+H19*CF_N2O -> 0.27204817 | I20: =I16+I17*CF_CH4_foss+I18*CF_CH4_bio+I19*CF_N2O -> 0.2183303 | J20: =J16+J17*CF_CH4_foss+J18*CF_CH4_bio+J19*CF_N2O -> 0.34016558 | K20: =K16+K17*CF_CH4_foss+K18*CF_CH4_bio+K19*CF_N2O -> 0 | L20: =L16+L17*CF_CH4_foss+L18*CF_CH4_bio+L19*CF_N2O -> 0.22523744 | M20: =M16+M17*CF_CH4_foss+M18*CF_CH4_bio+M19*CF_N2O -> 0 | N20: =N16+N17*CF_CH4_foss+N18*CF_CH4_bio+N19*CF_N2O -> 0 | O20: =O16+O17*CF_CH4_foss+O18*CF_CH4_bio+O19*CF_N2O -> 0.56017848 | ... T20: =T16+T17*CF_CH4_foss+T18*CF_CH4_bio+T19*CF_N2O -> 0 | W20: =W16+W17*CF_CH4_foss+W18*CF_CH4_bio+W19*CF_N2O -> 0 | X20: =X16+X17*CF_CH4_foss+X18*CF_CH4_bio+X19*CF_N2O -> 0
A21: NF-01 | B21: Cultured Meat (Bos. Spp.) | C21: Novel food | D21: USA | E21: US | F21: CO2 | G21: =SUM(H21:X21) -> 3.7219655 | H21: ='Novel foods, input data'!$AB$6*'Agri ing'!$AF$27 -> 0.16530307 | I21: ='Novel foods, input data'!$AB$6*'Agri ing'!$AG$27 -> 0.19564101 | J21: 0 | K21: 0 | L21: ='Novel foods, input data'!$AB$6*'Agri ing'!$AH$27 -> 0.21637121 | M21: 0 | N21: 0 | O21: ='Novel foods, input data'!$D$6*'Emission factors'!$B$13+'Novel foods, input data'!$AF$6 -> 3.1446502 | P21: 0 | Q21: 0 | R21: 0 | S21: 0 | T21: 0 | U21: 0 | V21: 0 | W21: 0 | X21: 0
A22: NF-01 | B22: Cultured Meat (Bos. Spp.) | C22: Novel food | D22: USA | E22: US | F22: CH4, fossil | G22: =SUM(H22:X22) -> 0.0060709677 | H22: ='Novel foods, input data'!$AB$6*'Agri ing'!$AJ$27 -> 0.00028384273 | I22: ='Novel foods, input data'!$AB$6*'Agri ing'!$AK$27 -> 0.00068836653 | J22: 0 | K22: 0 | L22: ='Novel foods, input data'!$AB$6*'Agri ing'!$AL$27 -> 0.00021922736 | M22: 0 | N22: 0 | O22: ='Novel foods, input data'!$D$6*'Emission factors'!$C$13+'Novel foods, input data'!$AG$6 -> 0.0048795311 | P22: 0 | Q22: 0 | R22: 0 | S22: 0 | T22: 0 | U22: 0 | V22: 0 | W22: 0 | X22: 0
A23: NF-01 | B23: Cultured Meat (Bos. Spp.) | C23: Novel food | D23: USA | E23: US | F23: CH4, biogenic | G23: =SUM(H23:T23)+SUM(W23:X23) -> 0 | H23: 0 | I23: 0 | J23: 0 | K23: 0 | L23: 0 | M23: 0 | N23: 0 | O23: 0 | P23: 0 | Q23: 0 | R23: 0 | S23: 0 | T23: 0 | U23: 0 | V23: 0 | W23: 0 | X23: 0
A24: NF-01 | B24: Cultured Meat (Bos. Spp.) | C24: Novel food | D24: USA | E24: US | F24: N2O | G24: =SUM(H24:T24)+SUM(W24:X24) -> 0.001711293 | H24: ='Novel foods, input data'!$AB$6*'Agri ing'!$AP$27 -> 0.00036002414 | I24: ='Novel foods, input data'!$AB$6*'Agri ing'!$AQ$27 -> 7.9705599e-06 | J24: ='Novel foods, input data'!$AB$6*'Agri ing'!$AR$27 -> 0.0012460278 | K24: 0 | L24: ='Novel foods, input data'!$AB$6*'Agri ing'!$AS$27 -> 8.5467492e-06 | M24: 0 | N24: 0 | O24: ='Novel foods, input data'!$D$6*'Emission factors'!$D$13+'Novel foods, input data'!$AH$6 -> 8.8723775e-05 | P24: 0 | Q24: 0 | R24: 0 | S24: 0 | T24: 0 | U24: 0 | V24: 0 | W24: 0 | X24: 0
A25: NF-01 | B25: Cultured Meat (Bos. Spp.) | C25: Novel food | D25: USA | E25: US | F25: CO2e | G25: =SUM(H25:X25) -> 4.3700633 | H25: =H21+H22*CF_CH4_foss+H23*CF_CH4_bio+H24*CF_N2O -> 0.27204817 | I25: =I21+I22*CF_CH4_foss+I23*CF_CH4_bio+I24*CF_N2O -> 0.2183303 | J25: =J21+J22*CF_CH4_foss+J23*CF_CH4_bio+J24*CF_N2O -> 0.34016558 | K25: =K21+K22*CF_CH4_foss+K23*CF_CH4_bio+K24*CF_N2O -> 0 | L25: =L21+L22*CF_CH4_foss+L23*CF_CH4_bio+L24*CF_N2O -> 0.22523744 | M25: =M21+M22*CF_CH4_foss+M23*CF_CH4_bio+M24*CF_N2O -> 0 | N25: =N21+N22*CF_CH4_foss+N23*CF_CH4_bio+N24*CF_N2O -> 0 | O25: =O21+O22*CF_CH4_foss+O23*CF_CH4_bio+O24*CF_N2O -> 3.3142818 | ... T25: =T21+T22*CF_CH4_foss+T23*CF_CH4_bio+T24*CF_N2O -> 0 | W25: =W21+W22*CF_CH4_foss+W23*CF_CH4_bio+W24*CF_N2O -> 0 | X25: =X21+X22*CF_CH4_foss+X23*CF_CH4_bio+X24*CF_N2O -> 0
A26: NF-02 | B26: Microbial Milk (T. reesei) | C26: Novel food | D26: Denmark | E26: DK | F26: CO2 | G26: =SUM(H26:X26) -> 1.054122 | H26: ='Novel foods, input data'!$AB$7*'Agri ing'!$AF$27 -> 0.083530581 | I26: ='Novel foods, input data'!$AB$7*'Agri ing'!$AG$27 -> 0.098860883 | J26: 0 | K26: 0 | L26: ='Novel foods, input data'!$AB$7*'Agri ing'!$AH$27 -> 0.10933622 | M26: 0 | N26: 0 | O26: ='Novel foods, input data'!$D$7*'Emission factors'!$B$6+'Novel foods, input data'!$AF$7 -> 0.76239434 | P26: 0 | Q26: 0 | R26: 0 | S26: 0 | T26: 0 | U26: 0 | V26: 0 | W26: 0 | X26: 0
A27: NF-02 | B27: Microbial Milk (T. reesei) | C27: Novel food | D27: Denmark | E27: DK | F27: CH4, fossil | G27: =SUM(H27:X27) -> 0.001308799 | H27: ='Novel foods, input data'!$AB$7*'Agri ing'!$AJ$27 -> 0.00014343078 | I27: ='Novel foods, input data'!$AB$7*'Agri ing'!$AK$27 -> 0.00034784385 | J27: 0 | K27: 0 | L27: ='Novel foods, input data'!$AB$7*'Agri ing'!$AL$27 -> 0.00011077948 | M27: 0 | N27: 0 | O27: ='Novel foods, input data'!$D$7*'Emission factors'!$C$6+'Novel foods, input data'!$AG$7 -> 0.00070674494 | P27: 0 | Q27: 0 | R27: 0 | S27: 0 | T27: 0 | U27: 0 | V27: 0 | W27: 0 | X27: 0
A28: NF-02 | B28: Microbial Milk (T. reesei) | C28: Novel food | D28: Denmark | E28: DK | F28: CH4, biogenic | G28: =SUM(H28:T28)+SUM(W28:X28) -> 0 | H28: 0 | I28: 0 | J28: 0 | K28: 0 | L28: 0 | M28: 0 | N28: 0 | O28: 0 | P28: 0 | Q28: 0 | R28: 0 | S28: 0 | T28: 0 | U28: 0 | V28: 0 | W28: 0 | X28: 0
A29: NF-02 | B29: Microbial Milk (T. reesei) | C29: Novel food | D29: Denmark | E29: DK | F29: N2O | G29: =SUM(H29:T29)+SUM(W29:X29) -> 0.00084627547 | H29: ='Novel foods, input data'!$AB$7*'Agri ing'!$AP$27 -> 0.0001819266 | I29: ='Novel foods, input data'!$AB$7*'Agri ing'!$AQ$27 -> 4.0276656e-06 | J29: ='Novel foods, input data'!$AB$7*'Agri ing'!$AR$27 -> 0.00062963999 | K29: 0 | L29: ='Novel foods, input data'!$AB$7*'Agri ing'!$AS$27 -> 4.3188243e-06 | M29: 0 | N29: 0 | O29: ='Novel foods, input data'!$D$7*'Emission factors'!$D$6+'Novel foods, input data'!$AH$7 -> 2.63624e-05 | P29: 0 | Q29: 0 | R29: 0 | S29: 0 | T29: 0 | U29: 0 | V29: 0 | W29: 0 | X29: 0
A30: NF-02 | B30: Microbial Milk (T. reesei) | C30: Novel food | D30: Denmark | E30: DK | F30: CO2e | G30: =SUM(H30:X30) -> 1.3241574 | H30: =H26+H27*CF_CH4_foss+H28*CF_CH4_bio+H29*CF_N2O -> 0.13747078 | I30: =I26+I27*CF_CH4_foss+I28*CF_CH4_bio+I29*CF_N2O -> 0.11032618 | J30: =J26+J27*CF_CH4_foss+J28*CF_CH4_bio+J29*CF_N2O -> 0.17189172 | K30: =K26+K27*CF_CH4_foss+K28*CF_CH4_bio+K29*CF_N2O -> 0 | L30: =L26+L27*CF_CH4_foss+L28*CF_CH4_bio+L29*CF_N2O -> 0.11381649 | M30: =M26+M27*CF_CH4_foss+M28*CF_CH4_bio+M29*CF_N2O -> 0 | N30: =N26+N27*CF_CH4_foss+N28*CF_CH4_bio+N29*CF_N2O -> 0 | O30: =O26+O27*CF_CH4_foss+O28*CF_CH4_bio+O29*CF_N2O -> 0.79065228 | ... T30: =T26+T27*CF_CH4_foss+T28*CF_CH4_bio+T29*CF_N2O -> 0 | W30: =W26+W27*CF_CH4_foss+W28*CF_CH4_bio+W29*CF_N2O -> 0 | X30: =X26+X27*CF_CH4_foss+X28*CF_CH4_bio+X29*CF_N2O -> 0
A31: NF-02 | B31: Microbial Milk (T. reesei) | C31: Novel food | D31: Germany | E31: DE | F31: CO2 | G31: =SUM(H31:X31) -> 1.1826885 | H31: ='Novel foods, input data'!$AB$7*'Agri ing'!$AF$27 -> 0.083530581 | I31: ='Novel foods, input data'!$AB$7*'Agri ing'!$AG$27 -> 0.098860883 | J31: 0 | K31: 0 | L31: ='Novel foods, input data'!$AB$7*'Agri ing'!$AH$27 -> 0.10933622 | M31: 0 | N31: 0 | O31: ='Novel foods, input data'!$D$7*'Emission factors'!$B$8+'Novel foods, input data'!$AF$7 -> 0.89096082 | P31: 0 | Q31: 0 | R31: 0 | S31: 0 | T31: 0 | U31: 0 | V31: 0 | W31: 0 | X31: 0
A32: NF-02 | B32: Microbial Milk (T. reesei) | C32: Novel food | D32: Germany | E32: DE | F32: CH4, fossil | G32: =SUM(H32:X32) -> 0.0018281417 | H32: ='Novel foods, input data'!$AB$7*'Agri ing'!$AJ$27 -> 0.00014343078 | I32: ='Novel foods, input data'!$AB$7*'Agri ing'!$AK$27 -> 0.00034784385 | J32: 0 | K32: 0 | L32: ='Novel foods, input data'!$AB$7*'Agri ing'!$AL$27 -> 0.00011077948 | M32: 0 | N32: 0 | O32: ='Novel foods, input data'!$D$7*'Emission factors'!$C$8+'Novel foods, input data'!$AG$7 -> 0.0012260876 | P32: 0 | Q32: 0 | R32: 0 | S32: 0 | T32: 0 | U32: 0 | V32: 0 | W32: 0 | X32: 0
A33: NF-02 | B33: Microbial Milk (T. reesei) | C33: Novel food | D33: Germany | E33: DE | F33: CH4, biogenic | G33: =SUM(H33:T33)+SUM(W33:X33) -> 0 | H33: 0 | I33: 0 | J33: 0 | K33: 0 | L33: 0 | M33: 0 | N33: 0 | O33: 0 | P33: 0 | Q33: 0 | R33: 0 | S33: 0 | T33: 0 | U33: 0 | V33: 0 | W33: 0 | X33: 0
A34: NF-02 | B34: Microbial Milk (T. reesei) | C34: Novel food | D34: Germany | E34: DE | F34: N2O | G34: =SUM(H34:T34)+SUM(W34:X34) -> 0.00084861989 | H34: ='Novel foods, input data'!$AB$7*'Agri ing'!$AP$27 -> 0.0001819266 | I34: ='Novel foods, input data'!$AB$7*'Agri ing'!$AQ$27 -> 4.0276656e-06 | J34: ='Novel foods, input data'!$AB$7*'Agri ing'!$AR$27 -> 0.00062963999 | K34: 0 | L34: ='Novel foods, input data'!$AB$7*'Agri ing'!$AS$27 -> 4.3188243e-06 | M34: 0 | N34: 0 | O34: ='Novel foods, input data'!$D$7*'Emission factors'!$D$8+'Novel foods, input data'!$AH$7 -> 2.8706814e-05 | P34: 0 | Q34: 0 | R34: 0 | S34: 0 | T34: 0 | U34: 0 | V34: 0 | W34: 0 | X34: 0
A35: NF-02 | B35: Microbial Milk (T. reesei) | C35: Novel food | D35: Germany | E35: DE | F35: CO2e | G35: =SUM(H35:X35) -> 1.4688404 | H35: =H31+H32*CF_CH4_foss+H33*CF_CH4_bio+H34*CF_N2O -> 0.13747078 | I35: =I31+I32*CF_CH4_foss+I33*CF_CH4_bio+I34*CF_N2O -> 0.11032618 | J35: =J31+J32*CF_CH4_foss+J33*CF_CH4_bio+J34*CF_N2O -> 0.17189172 | K35: =K31+K32*CF_CH4_foss+K33*CF_CH4_bio+K34*CF_N2O -> 0 | L35: =L31+L32*CF_CH4_foss+L33*CF_CH4_bio+L34*CF_N2O -> 0.11381649 | M35: =M31+M32*CF_CH4_foss+M33*CF_CH4_bio+M34*CF_N2O -> 0 | N35: =N31+N32*CF_CH4_foss+N33*CF_CH4_bio+N34*CF_N2O -> 0 | O35: =O31+O32*CF_CH4_foss+O33*CF_CH4_bio+O34*CF_N2O -> 0.93533519 | ... T35: =T31+T32*CF_CH4_foss+T33*CF_CH4_bio+T34*CF_N2O -> 0 | W35: =W31+W32*CF_CH4_foss+W33*CF_CH4_bio+W34*CF_N2O -> 0 | X35: =X31+X32*CF_CH4_foss+X33*CF_CH4_bio+X34*CF_N2O -> 0
A36: NF-02 | B36: Microbial Milk (T. reesei) | C36: Novel food | D36: Sweden | E36: SE | F36: CO2 | G36: =SUM(H36:X36) -> 0.66404222 | H36: ='Novel foods, input data'!$AB$7*'Agri ing'!$AF$27 -> 0.083530581 | I36: ='Novel foods, input data'!$AB$7*'Agri ing'!$AG$27 -> 0.098860883 | J36: 0 | K36: 0 | L36: ='Novel foods, input data'!$AB$7*'Agri ing'!$AH$27 -> 0.10933622 | M36: 0 | N36: 0 | O36: ='Novel foods, input data'!$D$7*'Emission factors'!$B$11+'Novel foods, input data'!$AF$7 -> 0.37231454 | P36: 0 | Q36: 0 | R36: 0 | S36: 0 | T36: 0 | U36: 0 | V36: 0 | W36: 0 | X36: 0
A37: NF-02 | B37: Microbial Milk (T. reesei) | C37: Novel food | D37: Sweden | E37: SE | F37: CH4, fossil | G37: =SUM(H37:X37) -> 0.00073795969 | H37: ='Novel foods, input data'!$AB$7*'Agri ing'!$AJ$27 -> 0.00014343078 | I37: ='Novel foods, input data'!$AB$7*'Agri ing'!$AK$27 -> 0.00034784385 | J37: 0 | K37: 0 | L37: ='Novel foods, input data'!$AB$7*'Agri ing'!$AL$27 -> 0.00011077948 | M37: 0 | N37: 0 | O37: ='Novel foods, input data'!$D$7*'Emission factors'!$C$11+'Novel foods, input data'!$AG$7 -> 0.00013590558 | P37: 0 | Q37: 0 | R37: 0 | S37: 0 | T37: 0 | U37: 0 | V37: 0 | W37: 0 | X37: 0
A38: NF-02 | B38: Microbial Milk (T. reesei) | C38: Novel food | D38: Sweden | E38: SE | F38: CH4, biogenic | G38: =SUM(H38:T38)+SUM(W38:X38) -> 0 | H38: 0 | I38: 0 | J38: 0 | K38: 0 | L38: 0 | M38: 0 | N38: 0 | O38: 0 | P38: 0 | Q38: 0 | R38: 0 | S38: 0 | T38: 0 | U38: 0 | V38: 0 | W38: 0 | X38: 0
A39: NF-02 | B39: Microbial Milk (T. reesei) | C39: Novel food | D39: Sweden | E39: SE | F39: N2O | G39: =SUM(H39:T39)+SUM(W39:X39) -> 0.00083121437 | H39: ='Novel foods, input data'!$AB$7*'Agri ing'!$AP$27 -> 0.0001819266 | I39: ='Novel foods, input data'!$AB$7*'Agri ing'!$AQ$27 -> 4.0276656e-06 | J39: ='Novel foods, input data'!$AB$7*'Agri ing'!$AR$27 -> 0.00062963999 | K39: 0 | L39: ='Novel foods, input data'!$AB$7*'Agri ing'!$AS$27 -> 4.3188243e-06 | M39: 0 | N39: 0 | O39: ='Novel foods, input data'!$D$7*'Emission factors'!$D$11+'Novel foods, input data'!$AH$7 -> 1.1301295e-05 | P39: 0 | Q39: 0 | R39: 0 | S39: 0 | T39: 0 | U39: 0 | V39: 0 | W39: 0 | X39: 0
A40: NF-02 | B40: Microbial Milk (T. reesei) | C40: Novel food | D40: Sweden | E40: SE | F40: CO2e | G40: =SUM(H40:X40) -> 0.91295494 | H40: =H36+H37*CF_CH4_foss+H38*CF_CH4_bio+H39*CF_N2O -> 0.13747078 | I40: =I36+I37*CF_CH4_foss+I38*CF_CH4_bio+I39*CF_N2O -> 0.11032618 | J40: =J36+J37*CF_CH4_foss+J38*CF_CH4_bio+J39*CF_N2O -> 0.17189172 | K40: =K36+K37*CF_CH4_foss+K38*CF_CH4_bio+K39*CF_N2O -> 0 | L40: =L36+L37*CF_CH4_foss+L38*CF_CH4_bio+L39*CF_N2O -> 0.11381649 | M40: =M36+M37*CF_CH4_foss+M38*CF_CH4_bio+M39*CF_N2O -> 0 | N40: =N36+N37*CF_CH4_foss+N38*CF_CH4_bio+N39*CF_N2O -> 0 | O40: =O36+O37*CF_CH4_foss+O38*CF_CH4_bio+O39*CF_N2O -> 0.37944978 | ... T40: =T36+T37*CF_CH4_foss+T38*CF_CH4_bio+T39*CF_N2O -> 0 | W40: =W36+W37*CF_CH4_foss+W38*CF_CH4_bio+W39*CF_N2O -> 0 | X40: =X36+X37*CF_CH4_foss+X38*CF_CH4_bio+X39*CF_N2O -> 0
A41: NF-02 | B41: Microbial Milk (T. reesei) | C41: Novel food | D41: Switzerland | E41: CH | F41: CO2 | G41: =SUM(H41:X41) -> 0.66404222 | H41: ='Novel foods, input data'!$AB$7*'Agri ing'!$AF$27 -> 0.083530581 | I41: ='Novel foods, input data'!$AB$7*'Agri ing'!$AG$27 -> 0.098860883 | J41: 0 | K41: 0 | L41: ='Novel foods, input data'!$AB$7*'Agri ing'!$AH$27 -> 0.10933622 | M41: 0 | N41: 0 | O41: ='Novel foods, input data'!$D$7*'Emission factors'!$B$9+'Novel foods, input data'!$AF$7 -> 0.37231454 | P41: 0 | Q41: 0 | R41: 0 | S41: 0 | T41: 0 | U41: 0 | V41: 0 | W41: 0 | X41: 0
A42: NF-02 | B42: Microbial Milk (T. reesei) | C42: Novel food | D42: Switzerland | E42: CH | F42: CH4, fossil | G42: =SUM(H42:X42) -> 0.00073795969 | H42: ='Novel foods, input data'!$AB$7*'Agri ing'!$AJ$27 -> 0.00014343078 | I42: ='Novel foods, input data'!$AB$7*'Agri ing'!$AK$27 -> 0.00034784385 | J42: 0 | K42: 0 | L42: ='Novel foods, input data'!$AB$7*'Agri ing'!$AL$27 -> 0.00011077948 | M42: 0 | N42: 0 | O42: ='Novel foods, input data'!$D$7*'Emission factors'!$C$9+'Novel foods, input data'!$AG$7 -> 0.00013590558 | P42: 0 | Q42: 0 | R42: 0 | S42: 0 | T42: 0 | U42: 0 | V42: 0 | W42: 0 | X42: 0
...

Sheet Novel foods, input data
A2: Novel foods, input data per kg final product | AF2: SMALL INGREDIENTS DONE FOR ALL PRODUCTS (EXCEPT CULT MEAT-not needed)
A4: Novel foods | D4: Energy (MJ/kg food) | AB4: Ingredients from agriculture (kg/kg food) | AF4: Other small ingredients/input
A5: Code | B5: Food | C5: Category | D5: Total Electicity | E5: Total Heat | F5: Energy ingredients (NOTE: this is done differently for cultured meat as the ingredients were a large part of the impacts, and not "minor") | G5: Bioreactor energy (Average) | H5: Bioreactor Cleaning/Cleaning in Place | I5: Water Sterilisation | J5: Microfiltration | K5: Combined ultra- and diafiltration | L5: Spray drying | M5: SMB system (Chromatographic separation) | N5: Fermentation (including transport, sterilization, electrolysis, and pasteurization) | O5: Separation | P5: Electricity - Feeding/harvesting/processing | Q5: Heat - Feeding/harvesting/processing | R5: Electricity - High moisture intermediate production | S5: Electricity (water pumping, lamps, sparger) - Cultivation, nursery | T5: Heat (Steam) - Pre-treatment and hydrolysis | U5: Electricity - Pre-treatment and hydrolysis | V5: Heating - nutrient production | W5: Electricity - Lipid extraction and refining | X5: Heat (steam) - Lipid extraction and refining | Y5: Electricity (fractionation) - Lipid extraction and refining | Z5: Diesel (L/kg food) | AA5: Petrol (L/kg food) | AB5: Glucose | AC5: Sugar beet | AD5: Wheat | AE5: Egg white | AF5: CO2 | AG5: CH4 | AH5: N2O
A6: NF-01 | B6: Cultured Meat (Bos. Spp.) | C6: Novel food | D6: =F6+G6+H6+I6 -> 21.543 | F6: ='Inputs - Cultured Meat'!B10 -> 4.057 | G6: ='Inputs - Cultured Meat'!B7 -> 8.407 | H6: ='Inputs - Cultured Meat'!B8 -> 0.848 | I6: ='Inputs - Cultured Meat'!B9 -> 8.231 | AB6: ='Inputs - Cultured Meat'!F7 -> 1.81404
A7: NF-02 | B7: Microbial Milk (T. reesei) | C7: Novel food | D7: =SUM(J7:M7) -> 4.9783 | J7: ='Inputs - Microbial Milk'!B8 -> 0.0072 | K7: ='Inputs - Microbial Milk'!B9 -> 0.07092 | L7: ='Inputs - Microbial Milk'!B10 -> 4.9 | M7: ='Inputs - Microbial Milk'!B11 -> 0.00018 | AB7: ='Inputs - Microbial Milk'!F8 -> 0.91666667 | AF7: ='Inputs - Microbial Milk'!J25 -> 0.25 | AG7: 0 | AH7: 0
A8: NF-03 | B8: Microbial Ovalbumin (T. reesei) | C8: Novel food | D8: =SUM(G8:H8) -> 22.314572 | G8: 20.605572 | H8: 1.709 | AB8: ='Input - Microbial Ovalbumin'!F7 -> 2.3368 | AF8: ='Input - Microbial Ovalbumin'!J28 -> 2.3997629 | AG8: 0 | AH8: 0
A9: NF-04 | B9: Microbial Protein (Solein) | C9: Novel food | D9: =SUM(G9:O9) -> 65.0862 | H9: =0.0795*3.6 -> 0.2862 | L9: =0.12*3.6 -> 0.432 | N9: =17.83*3.6 -> 64.188 | O9: =0.05*3.6 -> 0.18 | AF9: ='Input - Microbial Protein'!J36 -> 0.42808047 | AG9: 0 | AH9: 0
A10: NF-05 | B10: Mycoprotein (Quorn) | C10: Novel food | D10: =SUM(G10:O10) -> 21.32 | N10: ='Input - Mycoprotein'!B7 -> 21.32 | AD10: 2.1 | AE10: ='Input - Mycoprotein'!F8 -> 0.04 | AF10: ='Input - Mycoprotein'!J20 -> 0.12 | AG10: 0 | AH10: 0
A11: NF-06 | B11: Yeast Fat (Rhodotorula babjevae) | C11: Novel food | D11: =Z11*'Emission factors'!E22 -> 0.453904 | Z11: ='Input - Yeast Microb. Fat'!B10 -> 0.012895 | AF11: ='Input - Yeast Microb. Fat'!Q14 -> 0.54869928 | AG11: ='Input - Yeast Microb. Fat'!R14 -> 0.001130748 | AH11: ='Input - Yeast Microb. Fat'!S14 -> 4.11412e-05
A12: NF-07 | B12: Algae Fat (Schizochytrium) | C12: Novel food | D12: =SUM(N12,O12,R12,S12,W12) -> 11.410002 | N12: ='Input - Algae Microb. Fat'!B9 -> 0.42666984 | O12: ='Input - Algae Microb. Fat'!B8+'Input - Algae Microb. Fat'!B10 -> 0.54275063 | R12: ='Input - Algae Microb. Fat'!B10 -> 0.33375063 | S12: ='Input - Algae Microb. Fat'!B7 -> 10 | W12: ='Input - Algae Microb. Fat'!B11 -> 0.10683118 | AB12: ='Input - Algae Microb. Fat'!F7 -> 3.3177406 | AF12: ='Input - Algae Microb. Fat'!J27 -> 0.288813 | AG12: 0 | AH12: 0

Sheet Agri ing
A2: Agricultural ingredients
A4: Average European wheat, from SAFAD ID Footprints RPC.csv
A6: Long code | B6: FoodEx2 code | C6: FoodEx2 name | D6: SUA code | E6: SUA name | F6: Category | G6: Country name | H6: Country code | I6: Carbon footprint, primary production | J6: Carbon dioxide, primary production | K6: Methane, fossil, primary production | L6: Methane, biogenic, primary production | M6: Nitrous oxide, primary production | N6: Land | O6: N input | P6: P input | Q6: Water | R6: Pesticides | S6: Biodiversity | T6: Ammonia | U6: Animal welfare | V6: Antibiotics | W6: Mineral fertiliser production (CO2e) | X6: Capital goods (CO2e) | Y6: Soil emissions (CO2e) | Z6: Energy primary production (CO2e) | AA6: Land use change (CO2e) | AB6: Enteric fermentation (CO2e) | AC6: Manure management (CO2e) | AD6: Mineral fertiliser production (CO2) | AE6: Capital goods (CO2) | AF6: Energy primary production (CO2) | AG6: Land use change (CO2) | AH6: Mineral fertiliser production (CH4, fossil) | AI6: Capital goods (CH4, fossil) | AJ6: Energy primary production (CH4, fossil) | AK6: Soil emissions (CH4, biogenic) | AL6: Enteric fermentation (CH4, biogenic) | AM6: Manure management (CH4, biogenic) | AN6: Mineral fertiliser production (N2O) | AO6: Capital goods (N2O) | AP6: Soil emissions (N2O) | AQ6: Energy primary production (N2O) | AR6: Manure management (N2O)
A7: A.01.02.001.003 | B7: A001N | C7: Wheat grain soft | D7: 111 | E7: Wheat, average | F7: Cereals, incl feed | G7: Spain | H7: ES | I7: 0.35858385 | J7: 0.21240208 | K7: 0.00033073111 | L7: 0 | M7: 0.00049936257 | N7: 2.8117689 | O7: 0.023505915 | P7: 0.002150868 | Q7: 0.047600962 | R7: 0.21934758 | S7: 1.9212074e-12 | T7: 0.0014290328 | W7: 0.15101916 | X7: 0.0301313 | Y7: 0.080341633 | Z7: 0.097091753 | AA7: 0 | AD7: 0.090958865 | AE7: 0.027 | AF7: 0.094443212 | AH7: 0.00017394359 | AI7: 9.5e-05 | AJ7: 6.1787517e-05 | AN7: 0.00020101383 | AO7: 1.1e-06 | AP7: 0.0002942917 | AQ7: 2.9570446e-06
A8: A.01.02.001.003 | B8: A001N | C8: Wheat grain soft | D8: 111 | E8: Wheat, average | F8: Cereals, incl feed | G8: Greece | H8: GR | I8: 0.37848193 | J8: 0.23180504 | K8: 0.00034268734 | L8: 0 | M8: 0.00049987108 | N8: 3.4819669 | O8: 0.023505915 | P8: 0.002150868 | Q8: 0.028818304 | R8: 0.097309934 | S8: 1.6393528e-12 | T8: 0.0014290328 | W8: 0.15101916 | X8: 0.0301313 | Y8: 0.080341633 | Z8: 0.11698983 | AA8: 0 | AD8: 0.090958865 | AE8: 0.027 | AF8: 0.11384618 | AH8: 0.00017394359 | AI8: 9.5e-05 | AJ8: 7.3743743e-05 | AN8: 0.00020101383 | AO8: 1.1e-06 | AP8: 0.0002942917 | AQ8: 3.4655481e-06
A9: A.01.02.001.003 | B9: A001N | C9: Wheat grain soft | D9: 111 | E9: Wheat, average | F9: Cereals, incl feed | G9: Italy | H9: IT | I9: 0.35454064 | J9: 0.20809208 | K9: 0.0003406528 | L9: 0 | M9: 0.00049925678 | N9: 2.5320815 | O9: 0.023505915 | P9: 0.002150868 | Q9: 0.016090387 | R9: 0.10403672 | S9: 1.362592e-12 | T9: 0.0014290328 | W9: 0.15101916 | X9: 0.0301313 | Y9: 0.080341633 | Z9: 0.093048542 | AA9: 0 | AD9: 0.090958865 | AE9: 0.027 | AF9: 0.090133217 | AH9: 0.00017394359 | AI9: 9.5e-05 | AJ9: 7.1709208e-05 | AN9: 0.00020101383 | AO9: 1.1e-06 | AP9: 0.0002942917 | AQ9: 2.8512453e-06
A10: A.01.02.001.003 | B10: A001N | C10: Wheat grain soft | D10: 111 | E10: Wheat, average | F10: Cereals, incl feed | G10: Bulgaria | H10: BG | I10: 0.34480681 | J10: 0.199461 | K10: 0.00030775188 | L10: 0 | M10: 0.00049880882 | N10: 1.947761 | O10: 0.023505915 | P10: 0.002150868 | Q10: 2.7644003e-05 | R10: 0.17870363 | S10: 3.5470211e-13 | T10: 0.0014290328 | W10: 0.15101916 | X10: 0.0301313 | Y10: 0.080341633 | Z10: 0.083314718 | AA10: 0 | AD10: 0.090958865 | AE10: 0.027 | AF10: 0.081502132 | AH10: 0.00017394359 | AI10: 9.5e-05 | AJ10: 3.880829e-05 | AN10: 0.00020101383 | AO10: 1.1e-06 | AP10: 0.0002942917 | AQ10: 2.4032944e-06
A11: A.01.02.001.003 | B11: A001N | C11: Wheat grain soft | D11: 111 | E11: Wheat, average | F11: Cereals, incl feed | G11: Hungary | H11: HU | I11: 0.34040676 | J11: 0.19470709 | K11: 0.00031949299 | L11: 0 | M11: 0.00049882337 | N11: 1.8354416 | O11: 0.023505915 | P11: 0.002150868 | Q11: 0.0018303203 | R11: 0.17803784 | S11: 2.3049048e-13 | T11: 0.0014290328 | W11: 0.15101916 | X11: 0.0301313 | Y11: 0.080341633 | Z11: 0.078914671 | AA11: 0 | AD11: 0.090958865 | AE11: 0.027 | AF11: 0.076748228 | AH11: 0.00017394359 | AI11: 9.5e-05 | AJ11: 5.0549395e-05 | AN11: 0.00020101383 | AO11: 1.1e-06 | AP11: 0.0002942917 | AQ11: 2.4178415e-06
A12: A.01.02.001.003 | B12: A001N | C12: Wheat grain soft | D12: 111 | E12: Wheat, average | F12: Cereals, incl feed | G12: France | H12: FR | I12: 0.40512466 | J12: 0.17977536 | K12: 0.00029952406 | L12: 0 | M12: 0.00079276 | N12: 1.4134955 | O12: 0.023505915 | P12: 0.002150868 | Q12: 0.0013300634 | R12: 0.2654611 | S12: 1.6992252e-13 | T12: 0.0014290328 | W12: 0.15101916 | X12: 0.0301313 | Y12: 0.16068327 | Z12: 0.063290932 | AA12: 0 | AD12: 0.090958865 | AE12: 0.027 | AF12: 0.061816498 | AH12: 0.00017394359 | AI12: 9.5e-05 | AJ12: 3.0580471e-05 | AN12: 0.00020101383 | AO12: 1.1e-06 | AP12: 0.00058858339 | AQ12: 2.0627704e-06
A13: A.01.02.001.003 | B13: A001N | C13: Wheat grain soft | D13: 111 | E13: Wheat, average | F13: Cereals, incl feed | G13: Germany | H13: DE | I13: 0.4118356 | J13: 0.18608858 | K13: 0.00031088175 | L13: 0 | M13: 0.00079297711 | N13: 1.3573899 | O13: 0.023505915 | P13: 0.002150868 | Q13: 1.0074339e-09 | R13: 0.25897847 | S13: 1.2449839e-13 | T13: 0.0014290328 | W13: 0.15101916 | X13: 0.0301313 | Y13: 0.16068327 | Z13: 0.070001877 | AA13: 0 | AD13: 0.090958865 | AE13: 0.027 | AF13: 0.068129712 | AH13: 0.00017394359 | AI13: 9.5e-05 | AJ13: 4.1938154e-05 | AN13: 0.00020101383 | AO13: 1.1e-06 | AP13: 0.00058858339 | AQ13: 2.2798815e-06
A14: A.01.02.001.003 | B14: A001N | C14: Wheat grain soft | D14: 111 | E14: Wheat, average | F14: Cereals, incl feed | G14: Netherlands | H14: NL | I14: 0.45626277 | J14: 0.18377756 | K14: 0.00031454821 | L14: 0 | M14: 0.000963779 | N14: 1.1452051 | O14: 0.023505915 | P14: 0.002150868 | Q14: 0 | R14: 0.25898128 | S14: 9.2731183e-14 | T14: 0.0014290328 | W14: 0.15101916 | X14: 0.0301313 | Y14: 0.20733437 | Z14: 0.067777935 | AA14: 0 | AD14: 0.090958865 | AE14: 0.027 | AF14: 0.065818698 | AH14: 0.00017394359 | AI14: 9.5e-05 | AJ14: 4.5604613e-05 | AN14: 0.00020101383 | AO14: 1.1e-06 | AP14: 0.00075946656 | AQ14: 2.1986047e-06
A15: A.01.02.001.003 | B15: A001N | C15: Wheat grain soft | D15: 111 | E15: Wheat, average | F15: Cereals, incl feed | G15: Poland | H15: PL | I15: 0.43778024 | J15: 0.21115429 | K15: 0.0003373049 | L15: 0 | M15: 0.00079331234 | N15: 2.1388178 | O15: 0.023505915 | P15: 0.002150868 | Q15: 0.00039847055 | R15: 0.24782973 | S15: 8.5197036e-14 | T15: 0.0014290328 | W15: 0.15101916 | X15: 0.0301313 | Y15: 0.16068327 | Z15: 0.095946514 | AA15: 0 | AD15: 0.090958865 | AE15: 0.027 | AF15: 0.093195422 | AH15: 0.00017394359 | AI15: 9.5e-05 | AJ15: 6.8361302e-05 | AN15: 0.00020101383 | AO15: 1.1e-06 | AP15: 0.00058858339 | AQ15: 2.6151121e-06
