Workbook

Sheet Forage crops
A2: Feed name | C2: Alfalfa | D2: Cocksfoot | E2: Timothy | L2: Grass | M2: Fodder other on arable land
A3: Feed name (Feedipedia/ Feedtables/ Other) | C3: Alfalfa, aerial part, fresh | D3: Cocksfoot, aerial part, fresh | E3: Timothy (Phleum pratense), aerial part, fresh
A4: URL | C4: https://www.feedipedia.org/node/11745 | D4: https://www.feedipedia.org/node/11991 | E4: https://www.feedipedia.org/node/16887
A6: Fraction in pastures | C6: 0 | D6: 0.5 | E6: 0.5 | L6: =SUM(C6:J6) -> 1
A7: Fraction in arable forage | C7: 0.25 | D7: 0.25 | E7: 0.5 | M7: =SUM(C7:J7) -> 1
A9: GENERAL | B9: Unit | P9: Vilka gräs är vanliga i Europeiska betesmarker? | V9: Ryegrass | AG9: Cocksfoot
A10: DM (EU standard) | B10: % | C10: =100-65 -> 35 | D10: 35 | E10: =100-65 -> 35 | L10: =SUMPRODUCT(C$6:J$6,C10:J10) -> 35 | M10: =SUMPRODUCT(C$7:J$7,C10:J10) -> 35
A11: DM | B11: % as fed | C11: 19.9 | D11: 20.7 | E11: 27 | L11: =SUMPRODUCT(C$6:J$6,C11:J11) -> 23.85 | M11: =SUMPRODUCT(C$7:J$7,C11:J11) -> 23.65
A12: Crude protein | B12: % DM | C12: 20.6 | D12: 16.3 | E12: 13.8 | L12: =SUMPRODUCT(C$6:J$6,C12:J12) -> 15.05 | M12: =SUMPRODUCT(C$7:J$7,C12:J12) -> 16.125
A13: Crude fibre | B13: % DM | C13: 26.7 | D13: 29.7 | E13: 31.8 | L13: =SUMPRODUCT(C$6:J$6,C13:J13) -> 30.75 | M13: =SUMPRODUCT(C$7:J$7,C13:J13) -> 30
A14: NDF | B14: % DM | C14: 39.3 | D14: 59.9 | E14: 62.2 | L14: =SUMPRODUCT(C$6:J$6,C14:J14) -> 61.05 | M14: =SUMPRODUCT(C$7:J$7,C14:J14) -> 55.9
A15: ADF | B15: % DM | C15: 30.9 | D15: 32.3 | E15: 34.2 | L15: =SUMPRODUCT(C$6:J$6,C15:J15) -> 33.25 | M15: =SUMPRODUCT(C$7:J$7,C15:J15) -> 32.9
A16: Lignin | B16: % DM | C16: 7.6 | D16: 4.5 | E16: 4.6 | L16: =SUMPRODUCT(C$6:J$6,C16:J16) -> 4.55 | M16: =SUMPRODUCT(C$7:J$7,C16:J16) -> 5.325
A17: Ether extract | B17: % DM | C17: 2.9 | D17: 4 | E17: 2.2 | L17: =SUMPRODUCT(C$6:J$6,C17:J17) -> 3.1 | M17: =SUMPRODUCT(C$7:J$7,C17:J17) -> 2.825
A18: Ash | B18: % DM | C18: 11.5 | D18: 9.7 | E18: 8 | L18: =SUMPRODUCT(C$6:J$6,C18:J18) -> 8.85 | M18: =SUMPRODUCT(C$7:J$7,C18:J18) -> 9.3 | V18: Fescue
A19: Starch (polarimetry) | B19: % DM | C19: 0.3 | L19: =SUMPRODUCT(C$6:J$6,C19:J19) -> 0 | M19: =SUMPRODUCT(C$7:J$7,C19:J19) -> 0.075
A20: Total sugars | B20: % DM | D20: 10.1 | L20: =SUMPRODUCT(C$6:J$6,C20:J20) -> 5.05 | M20: =SUMPRODUCT(C$7:J$7,C20:J20) -> 2.525
A21: Gross energy | B21: MJ/kg DM | C21: 18.1 | D21: 18 | E21: 18.2 | L21: =SUMPRODUCT(C$6:J$6,C21:J21) -> 18.1 | M21: =SUMPRODUCT(C$7:J$7,C21:J21) -> 18.125
A23: AMINO ACIDS
A24: Lysine | B24: % protein | C24: 5.5 | D24: 6.3 | L24: =SUMPRODUCT(C$6:J$6,C24:J24) -> 3.15 | M24: =SUMPRODUCT(C$7:J$7,C24:J24) -> 2.95
A25: Metheonin | B25: % protein | C25: 1.6 | D25: 2.2
A27: RUMINANT
A28: ME ruminants | B28: MJ/kg DM | C28: 9.4 | D28: 9.5 | E28: 9.3 | L28: =SUMPRODUCT(C$6:J$6,C28:J28) -> 9.4 | M28: =SUMPRODUCT(C$7:J$7,C28:J28) -> 9.375
A29: Nitrogen digestibility, ruminants | B29: % | C29: 78.5 | D29: 58.9 | E29: 68 | L29: =SUMPRODUCT(C$6:J$6,C29:J29) -> 63.45 | M29: =SUMPRODUCT(C$7:J$7,C29:J29) -> 68.35 | AG29: Timothy

Sheet Main table
A1: CAPRI code | C1: SWHE | D1: DWHE | E1: RYEM | F1: BARL | G1: OATS | H1: MAIZ | I1: OCER | J1: PARI | K1: RICE | L1: PULS | M1: PULS | N1: PULS | O1: RAPO | P1: SUNO | Q1: SOYO | R1: OLIO | S1: OTHO | T1: RAPC | U1: SUNC | V1: SOYC | W1: OLIC | X1: DDGS | Y1: FPRI | Z1: FPRI | AA1: FPRI | AB1: FPRI | AC1: FPRI | AD1: FPRI | AE1: FPRI | AF1: SFIS | AG1: FFIS | AH1: ACQU | AI1: MOLA | AJ1: STAR | AK1: FENI | AL1: SMIP | AM1: WMIO | AN1: CASE | AO1: WHEP | AP1: BUTT | AQ1: CREM | AR1: COCM | AS1: CHES | AT1: FRMI | AU1: POTA | AV1: RAPE | AW1: SUNF | AX1: SOYA | AY1: OLIO | AZ1: OOIL | BA1: TEXT | BB1: TOMA | BC1: OVEG | BD1: APPL | BE1: OFRU | BF1: CITR | BG1: TAGR | BH1: TABO | BI1: TWIN | BJ1: SUGA | BK1: EGGS | BL1: PORK | BM1: BEEF | BN1: FGRA | BO1: FMAI | BP1: FOFA | BQ1: FROO | BR1: FSTR | BS1: FCOM | BT1: FSGM
A2: Feed name | C2: Soft wheat | D2: Durum wheat | E2: Rye and meslin | F2: Barley | G2: Oats | H2: Grain maize | I2: Other cereals | J2: Paddy rice | K2: Rice milled | L2: Field peas | M2: Broad beans | N2: Lupins | O2: Rape seed oil | P2: Sunflower seed oil | Q2: Soya oil | R2: Olive oil | S2: Other oil | T2: Rape seed cake | U2: Sunflowe seed cake | V2: Soya cake | W2: Olive cakes | X2: Destilled dried grains from bio-ethanol processing | Y2: Wheat bran | Z2: Wheat gluten feed | AA2: Corn gluten meal | AB2: Corn gluten feed | AC2: Corn germ meal | AD2: Wheat distillers grains | AE2: Corn distillers grains | AF2: Saltwater fish | AG2: Fresh water fish | AH2: Fish and other acquatic products | AI2: Molasse | AJ2: Starch | AK2: Energy rich by products | AL2: Skimmed milk powder | AM2: Whole milk powder | AN2: Casein | AO2: Whey powder | AP2: Butter | AQ2: Cream | AR2: Concentrated milk | AS2: Cheese | AT2: Fresh milk products | AU2: Potatoes | AV2: Rape seed | AW2: Sunflower seed | AX2: Soya seed | AY2: Olive oil | AZ2: Other oil | BA2: Flax and hemp | BB2: Tomatoes | BC2: Other vegetables | BD2: Apples pears and peaches | BE2: Other fruits | BF2: Citrus fruits | BG2: Table grapes | BH2: Table olives | BI2: Wine | BJ2: Sugar | BK2: Eggs | BL2: Pork meat | BM2: Beef | BN2: Gras | BO2: Fodder maize | BP2: Fodder other on arable land | BQ2: Fodder root crops | BR2: Straw | BS2: Milk for feeding | BT2: Sheep and Goat Milk for feeding
A3: Feed name (Feedipedia/ Feedtables/ Other) | C3: Wheat grain | D3: Wheat, durum | E3: Rye grain | F3: Barley grain | G3: Oats | H3: Maize grain, Europé | I3: Triticale grain | J3: (not used) | K3: Rice grain, polished | L3: Pea seeds | M3: Faba bean (Vicia faba), all cultivars | N3: Blue lupin (Lupinus angustifolius) seeds | O3: Rapeseed oil | P3: Sunflower oil | Q3: Soybean oil | R3: (not used) | S3: (copy) | T3: Rapeseed meal, 00 type, oil < 5% as fed, solvent extraction | U3: Sunflower meal, solvent-extracted, dehulled or non-dehulled | V3: Soybean meal, low protein (non-dehulled) | W3: (not used) | X3: (copy) | Y3: Wheat bran | Z3: Wheat gluten | AA3: Maize gluten meal | AB3: Corn gluten feed | AC3: Maize germ meal, protein 20-30%, oil > 5% | AD3: Wheat distillers grain with solubles, starch < 7 | AE3: Maize distillers dried grains and solubles | AF3: (not used) | AG3: (not used) | AH3: (not used) | AI3: (not used) | AJ3: (not used) | AK3: Molasses, beet | AL3: Milk powder, skimmed | AM3: Milk powder, whole | AN3: (copy) | AO3: Whey, sweet, dehydrated, skimmed | AP3: (not used) | AQ3: (not used) | AR3: (copy) | AS3: USDA food database | AT3: (copy) | AU3: Potato, tuber, raw | AV3: Rapeseeds, low erucic, low glucosinolates | AW3: Sonflower seeds | AX3: Soybeans (all) | AY3: (not used) | AZ3: (not used) | BA3: (not used) | BB3: Tomato fruits, fresh | BC3: (copy) | BD3: Apples, whole, fresh | BE3: (copy) | BF3: (copy) | BG3: (not used) | BH3: (not used) | BI3: (not used) | BL3: (not used) | BM3: (not used) | BN3: (Forage sheet) | BO3: Maize silage, dry matter 30-35% | BP3: (Forage sheet) | BQ3: Beet root, fodder type, fresh | BR3: Wheat straw | BS3: (copy) | BT3: (copy)
A4: URL | C4: https://www.feedipedia.org/node/12754 | D4: https://feedtables.com/content/wheat-durum | E4: https://www.feedipedia.org/node/12542 | F4: https://www.feedipedia.org/node/11705 | G4: https://www.feedipedia.org/node/12391 | H4: https://www.feedipedia.org/node/11660 | I4: https://www.feedipedia.org/node/12800 | K4: https://www.feedipedia.org/node/12526 | L4: https://www.feedipedia.org/node/12434 | M4: https://www.feedipedia.org/node/12799 | N4: https://www.feedipedia.org/node/12271 | O4: https://feedtables.com/content/rapeseed-oil | P4: https://feedtables.com/content/sunflower-oil | Q4: https://feedtables.com/content/soybean-oil | T4: https://www.feedipedia.org/node/12503 | U4: https://www.feedipedia.org/node/12663 | V4: https://www.feedipedia.org/node/11682 | Y4: https://www.feedipedia.org/node/12751 | Z4: https://feedtables.com/content/wheat-gluten | AA4: https://www.feedipedia.org/node/12288 | AB4: https://www.feedipedia.org/node/12287 | AC4: https://www.feedipedia.org/node/12286 | AD4: https://www.feedipedia.org/node/12801 | AE4: https://www.feedipedia.org/node/12282 | AK4: https://www.feedipedia.org/node/12340 | AL4: https://feedtables.com/content/milk-powder-skimmed | AM4: https://feedtables.com/content/milk-powder-whole | AO4: https://www.feedipedia.org/node/12893 | AU4: https://www.feedipedia.org/node/12472 | AV4: https://www.feedipedia.org/node/12504 | AW4: https://www.feedipedia.org/node/12666 | AX4: https://www.feedipedia.org/node/12625 | BB4: https://www.feedipedia.org/node/12903 | BD4: https://www.feedipedia.org/node/22401 | BO4: https://www.feedipedia.org/node/12871 | BQ4: https://www.feedipedia.org/node/11842 | BR4: https://www.feedipedia.org/node/12758
A6: GENERAL | B6: Unit
A7: DM (EU standard) | B7: % | C7: =100-14 -> 86 | D7: =100-14 -> 86 | E7: =100-14 -> 86 | F7: =100-14 -> 86 | G7: =100-14 -> 86 | H7: =100-14 -> 86 | I7: =100-14 -> 86 | K7: =100-13 -> 87 | L7: =100-14 -> 86 | M7: =100-14 -> 86 | N7: =100-14 -> 86 | O7: 100 | P7: 100 | Q7: 100 | S7: =O7 -> 100 | T7: 88.8 | U7: 89 | V7: 87.9 | X7: =AD7 -> 90.6 | Y7: 87 | Z7: 93.8 | AA7: 90 | AB7: 88.3 | AC7: 95.6 | AD7: 90.6 | AE7: 89 | AK7: 75.7 | AL7: 94.8 | AM7: 96 | AN7: =AO7 -> 97 | AO7: 97 | AR7: 25 | AS7: 64 | AT7: =100-87 -> 13 | AU7: 20.6 | AV7: =100-9 -> 91 | AW7: =100-9 -> 91 | AX7: =100-14 -> 86 | BB7: 7.3 | BC7: =BB7 -> 7.3 | BD7: 14 | BE7: =BD7 -> 14 | BF7: =BD7 -> 14 | BJ7: 100 | BK7: =BK8 -> 23.85 | BN7: =100-65 -> 35 | BO7: =100-65 -> 35 | BP7: =100-65 -> 35 | BQ7: 16.3 | BR7: 91 | BS7: =AT7 -> 13 | BT7: =AT7 -> 13
A8: DM | B8: % as fed | C8: 87 | D8: 87.8 | E8: 86.6 | F8: 87.1 | G8: 87.9 | H8: 86.3 | I8: 87.1 | K8: 89.2 | L8: 86.5 | M8: 86.6 | N8: 90.2 | O8: 100 | P8: 99.3 | Q8: 100 | S8: =O8 -> 100 | T8: 88.8 | U8: 89 | V8: 87.9 | X8: =AD8 -> 90.6 | Y8: 87 | Z8: 93.8 | AA8: 90 | AB8: 88.3 | AC8: 95.6 | AD8: 90.6 | AE8: 89 | AK8: 75.7 | AL8: 94.8 | AM8: 96 | AN8: =AO8 -> 97 | AO8: 97 | AR8: 25 | AS8: 64 | AT8: =100-87 -> 13 | AU8: 20.6 | AV8: 92.3 | AW8: 92.8 | AX8: 88.7 | BB8: 7.3 | BC8: =BB8 -> 7.3 | BD8: 14 | BE8: =BD8 -> 14 | BF8: =BD8 -> 14 | BJ8: 100 | BK8: =100-76.15 -> 23.85 | BN8: ='Forage crops'!L12 -> 15.05 | BO8: 32.5 | BP8: ='Forage crops'!M12 -> 16.125 | BQ8: 16.3 | BR8: 91 | BS8: =AT8 -> 13 | BT8: =AT8 -> 13
A9: Crude protein | B9: % DM | C9: 12.6 | D9: 16.3 | E9: 10.3 | F9: 11.8 | G9: 11 | H9: 9.4 | I9: 11.7 | K9: 10.4 | L9: 23.9 | M9: 29 | N9: 33.7 | O9: 0 | P9: 0 | Q9: 0 | S9: =O9 -> 0 | T9: 38.3 | U9: 32.4 | V9: 51.8 | X9: =AD9 -> 37.3 | Y9: 17.3 | Z9: 85.5 | AA9: 67.2 | AB9: 21.7 | AC9: 25.6 | AD9: 37.3 | AE9: 29.5 | AK9: 14.3 | AL9: 35.8 | AM9: 25.4 | AN9: =AO9 -> 12.5 | AO9: 12.5 | AR9: =AM9 -> 25.4 | AS9: 38 | AT9: =AM9 -> 25.4 | AU9: 10.8 | AV9: 20.9 | AW9: 16.6 | AX9: 39.6 | BB9: 16.7 | BC9: =BB9 -> 16.7 | BD9: 1.5 | BE9: =BD9 -> 1.5 | BF9: =BD9 -> 1.5 | BJ9: 0 | BK9: =12.56/BK8*100 -> 52.662474 | BN9: ='Forage crops'!L12 -> 15.05 | BO9: 6.9 | BP9: ='Forage crops'!M12 -> 16.125 | BQ9: 6.7 | BR9: 4.2 | BS9: =AT9 -> 25.4 | BT9: =AT9 -> 25.4
A10: Crude fibre | B10: % DM | C10: 2.6 | D10: 3 | E10: 2.2 | F10: 5.2 | G10: 13.9 | H10: 2.5 | I10: 2.7 | K10: 0.4 | L10: 6 | M10: 9.1 | N10: 16.1 | O10: 0 | P10: 0 | Q10: 0 | S10: =O10 -> 0 | T10: 14.1 | U10: 27.9 | V10: 6.7 | X10: =AD10 -> 7.7 | Y10: 10.4 | Z10: 0.7 | AA10: 1.2 | AB10: 8.3 | AC10: 10.4 | AD10: 7.7 | AE10: 7.9 | AK10: 0.1 | AL10: 0 | AM10: 0 | AR10: =AM10 -> 0 | AT10: =AM10 -> 0 | AU10: 2.5 | AV10: 10.1 | AW10: 17.2 | AX10: 6.2 | BD10: 5.5 | BE10: =BD10 -> 5.5 | BF10: =BD10 -> 5.5 | BN10: ='Forage crops'!L13 -> 30.75 | BO10: 20.2 | BP10: ='Forage crops'!M13 -> 30 | BQ10: 5.8 | BR10: 41.5 | BS10: =AT10 -> 0 | BT10: =AT10 -> 0
A11: NDF | B11: % DM | C11: 13.9 | D11: 15.9 | E11: 13.9 | F11: 21.7 | G11: 35.5 | H11: 12.2 | I11: 14.6 | K11: 4.8 | L11: 14.2 | M11: 15.9 | T11: 31.1 | U11: 45 | V11: 13.7 | X11: =AD11 -> 34 | Y11: 45.2 | Z11: 0.4 | AA11: 4.1 | AB11: 39.6 | AC11: 45 | AD11: 34 | AE11: 34.2 | AL11: 0 | AM11: 0 | AR11: =AM11 -> 0 | AT11: =AM11 -> 0 | AU11: 8.3 | AV11: 20.4 | AW11: 29.6 | AX11: 13.2 | BB11: 30.5 | BC11: =BB11 -> 30.5 | BD11: 10.5 | BE11: =BD11 -> 10.5 | BF11: =BD11 -> 10.5 | BN11: ='Forage crops'!L14 -> 61.05 | BO11: 44.3 | BP11: ='Forage crops'!M14 -> 55.9 | BQ11: 13.3 | BR11: 77.5 | BS11: =AT11 -> 0 | BT11: =AT11 -> 0
A12: ADF | B12: % DM | C12: 3.6 | D12: 4.2 | E12: 3.2 | F12: 6.4 | G12: 16.2 | H12: 3 | I12: 3.7 | K12: 1.2 | L12: 7 | M12: 10.7 | T12: 20.4 | U12: 32 | V12: 8.3 | X12: =AD12 -> 14.5 | Y12: 13.4 | Z12: 0.7 | AA12: 1.6 | AB12: 10.6 | AC12: 12.2 | AD12: 14.5 | AE12: 13.6 | AL12: 0 | AM12: 0 | AR12: =AM12 -> 0 | AT12: =AM12 -> 0 | AU12: 3.6 | AV12: 14.4 | AW12: 19.5 | AX12: 7.7 | BB12: 20 | BC12: =BB12 -> 20 | BD12: 7.4 | BE12: =BD12 -> 7.4 | BF12: =BD12 -> 7.4 | BN12: ='Forage crops'!L15 -> 33.25 | BO12: 23.3 | BP12: ='Forage crops'!M15 -> 32.9 | BQ12: 7.1 | BR12: 50 | BS12: =AT12 -> 0 | BT12: =AT12 -> 0
A13: Lignin | B13: % DM | C13: 1.1 | D13: 1.3 | E13: 1.1 | F13: 1.1 | G13: 2.5 | H13: 0.6 | I13: 1.1 | K13: 0.8 | L13: 0.4 | M13: 1 | N13: 1.2 | T13: 9.5 | U13: 10.7 | V13: 0.8 | X13: =AD13 -> 4.6 | Y13: 3.8 | Z13: 0.3 | AA13: 0.3 | AB13: 1.2 | AC13: 2.4 | AD13: 4.6 | AE13: 4.3 | AL13: 0 | AM13: 0 | AR13: =AM13 -> 0 | AT13: =AM13 -> 0 | AU13: 0.9 | AV13: 6.3 | AW13: 6.3 | AX13: 1.2 | BB13: 19.5 | BC13: =BB13 -> 19.5 | BD13: 1.8 | BE13: =BD13 -> 1.8 | BF13: =BD13 -> 1.8 | BN13: ='Forage crops'!L16 -> 4.55 | BO13: 2.7 | BP13: ='Forage crops'!M16 -> 5.325 | BQ13: 1 | BR13: 7.2 | BS13: =AT13 -> 0 | BT13: =AT13 -> 0
A14: Ether extract | B14: % DM | C14: 1.7 | D14: 2 | E14: 1.4 | F14: 2 | G14: 5.4 | H14: 4.3 | I14: 1.5 | K14: 0.5 | L14: 1.2 | M14: 1.4 | N14: 6 | O14: 99.8 | P14: 100 | Q14: 99.8 | S14: =O14 -> 99.8 | T14: 2.7 | U14: 2.2 | V14: 2 | X14: =AD14 -> 5 | Y14: 3.9 | Z14: 1.6 | AA14: 2.9 | AB14: 3.4 | AC14: 8.1 | AD14: 5 | AE14: 11.1 | AK14: 0.2 | AL14: 1.6 | AM14: 25.1 | AN14: =AO14 -> 1.3 | AO14: 1.3 | AR14: =AM14 -> 25.1 | AS14: 53 | AT14: =AM14 -> 25.1 | AU14: 0.5 | AV14: 46 | AW14: 47.9 | AX14: 21.4 | BB14: 1.5 | BC14: =BB14 -> 1.5 | BD14: 0.9 | BE14: =BD14 -> 0.9 | BF14: =BD14 -> 0.9 | BJ14: 0 | BK14: =9.51/BK8*100 -> 39.874214 | BN14: ='Forage crops'!L17 -> 3.1 | BO14: 2.8 | BP14: ='Forage crops'!M17 -> 2.825 | BQ14: 0.5 | BR14: 1.4 | BS14: =AT14 -> 25.1 | BT14: =AT14 -> 25.1
A15: Ash | B15: % DM | C15: 1.8 | D15: 2.1 | E15: 2 | F15: 2.6 | G15: 3 | H15: 1.4 | I15: 2.1 | K15: 0.6 | L15: 3.5 | M15: 3.9 | N15: 3.5 | O15: 0.2 | P15: 0.05 | Q15: 0.2 | S15: =O15 -> 0.2 | T15: 4.1 | U15: 7.1 | V15: 7.1 | X15: =AD15 -> 5.9 | Y15: 5.6 | Z15: 0.9 | AA15: 2.1 | AB15: 6.9 | AC15: 2 | AD15: 5.9 | AE15: 5.4 | AK15: 12.7 | AL15: 8.5 | AM15: 6.5 | AN15: =AO15 -> 8.2 | AO15: 8.2 | AR15: =AM15 -> 6.5 | AS15: 5.7 | AT15: =AM15 -> 6.5 | AU15: 7.3 | AV15: 4.3 | AW15: 3.5 | AX15: 5.7 | BD15: 2.3 | BE15: =BD15 -> 2.3 | BF15: =BD15 -> 2.3 | BN15: ='Forage crops'!L18 -> 8.85 | BO15: 3.7 | BP15: ='Forage crops'!M18 -> 9.3 | BQ15: 7.2 | BR15: 6.7 | BS15: =AT15 -> 6.5 | BT15: =AT15 -> 6.5
A16: Starch (polarimetry) | B16: % DM | C16: 69.1 | D16: 64.1 | E16: 62.2 | F16: 59.7 | G16: 40.6 | H16: 73.4 | I16: 67.6 | K16: 85.5 | L16: 51.3 | M16: 44.7 | N16: 4.8 | O16: 0 | P16: 0 | Q16: 0 | S16: =O16 -> 0 | T16: 7.8 | X16: =AD16 -> 4.2 | Y16: 23.1 | Z16: 5.7 | AA16: 17.6 | AB16: 21.5 | AC16: 22.1 | AD16: 4.2 | AE16: 9.3 | AL16: 0 | AU16: 71.9 | AV16: 3.7 | AW16: 1.3 | AX16: 6.4 | BO16: 29.1 | BP16: ='Forage crops'!M19 -> 0.075 | BR16: 1
A17: Total sugars | B17: % DM | C17: 3.2 | D17: 3.2 | E17: 3.6 | F17: 2.8 | G17: 1.6 | H17: 2.1 | I17: 3.7 | K17: 0.7 | L17: 4.9 | M17: 3.6 | N17: 5.8 | T17: 10.4 | U17: 6.1 | V17: 9.4 | X17: =AD17 -> 2.9 | Y17: 7.2 | Z17: 0 | AA17: 0.5 | AB17: 1.8 | AC17: 0.7 | AD17: 2.9 | AE17: 1.7 | AK17: 63.2 | AU17: 6.6 | AV17: 5.5 | AW17: 2.7 | AX17: 8.7 | BJ17: 100 | BK17: =0.37/BK8 -> 0.015513627 | BO17: 0.2 | BQ17: 72.5 | BR17: 1.2
A18: Gross energy | B18: MJ/kg DM | C18: 18.2 | D18: 18.5 | E18: 18 | F18: 18.4 | G18: 19.5 | H18: 18.7 | I18: 18.1 | K18: 18 | L18: 18.3 | M18: 18.7 | N18: 20.3 | O18: 39.3 | P18: 39.3 | Q18: 39.3 | S18: =O18 -> 39.3 | T18: 19.4 | U18: 19.4 | V18: 19.7 | X18: =AD18 -> 20.5 | Y18: 18.9 | Z18: 22.8 | AA18: 23.1 | AB18: 18.8 | AC18: 20.7 | AD18: 20.5 | AE18: 21.4 | AK18: 15.5 | AL18: 18.3 | AM18: 23.2 | AN18: =AO18 -> 16.1 | AO18: 16.1 | AR18: =AM18 -> 23.2 | AS18: 27 | AT18: =AM18 -> 23.2 | AU18: 16.8 | AV18: 28.8 | AW18: 28.7 | AX18: 23.6 | BB18: 18.2 | BC18: =BB18 -> 18.2 | BD18: 17.4 | BE18: =BD18 -> 17.4 | BF18: =BD18 -> 17.4 | BJ18: 16.2 | BK18: =5.99/(BK8/100) -> 25.115304 | BN18: ='Forage crops'!L21 -> 18.1 | BO18: 18.8 | BP18: ='Forage crops'!M21 -> 18.125 | BQ18: 16.7 | BR18: 18.5 | BS18: =AT18 -> 23.2 | BT18: =AT18 -> 23.2
A20: AMINO ACIDS
A21: Lysine | B21: % protein | C21: 2.9 | D21: =4.3/1000/(D9/100)*100 -> 2.6380368 | E21: 3.9 | F21: 3.7 | G21: 4.3 | H21: 3.1 | I21: 3.5 | K21: 3.7 | L21: 7.2 | M21: 6.2 | N21: 5 | O21: 0 | P21: 0 | Q21: 0 | S21: =O21 -> 0 | T21: 5.5 | U21: 3.5 | V21: 6.1 | X21: =AD21 -> 2.3 | Y21: 4 | Z21: =16.2/1000/(Z9/100)*100 -> 1.8947368 | AA21: 1.7 | AB21: 2.9 | AC21: 4 | AD21: 2.3 | AE21: 3 | AK21: 1.4 | AL21: =28.2/1000/(AL9/100)*100 -> 7.877095 | AM21: =7.8 -> 7.8 | AN21: =AO21 -> 7.6 | AO21: 7.6 | AR21: =AM21 -> 7.8 | AS21: 8.4 | AT21: =AM21 -> 7.8 | AU21: 4.6 | AV21: 6.3 | AW21: 3.9 | AX21: 6.2 | BB21: 3.9 | BC21: =BB21 -> 3.9 | BD21: 7.7 | BE21: =BD21 -> 7.7 | BF21: =BD21 -> 7.7 | BN21: ='Forage crops'!L24 -> 3.15 | BO21: 3 | BP21: ='Forage crops'!M24 -> 2.95 | BQ21: 5.8 | BS21: =AT21 -> 7.8 | BT21: =AT21 -> 7.8
A22: Methionine | B22: % protein | C22: 1.6 | D22: 1.6 | E22: 1.7 | F22: 1.7 | G22: 1.8 | H22: 2.1 | I22: 1.6 | K22: 2.4 | L22: 1 | M22: 0.8 | N22: 0.9 | O22: 0 | P22: 0 | Q22: 0 | S22: =O22 -> 0 | T22: 2 | U22: 2.3 | V22: 1.4 | X22: =AD22 -> 1.5 | Y22: 1.5 | Z22: 1.4 | AA22: 2.4 | AB22: 1.7 | AC22: 1.7 | AD22: 1.5 | AE22: 2 | AK22: 0.2 | AL22: 2.8 | AM22: 2.2 | AN22: =AO22 -> 1.4 | AO22: 1.4 | AR22: =AM22 -> 2.2 | AS22: 2.4 | AT22: =AM22 -> 2.2 | AU22: 1.4 | AV22: 2 | AW22: 2.2 | AX22: 1.4 | BB22: 0.8 | BC22: =BB22 -> 0.8 | BD22: 0.9 | BE22: =BD22 -> 0.9 | BF22: =BD22 -> 0.9
A24: RUMINANT
A25: ME ruminants | B25: MJ/kg DM | C25: 13.1 | D25: 13.1 | E25: 13 | F25: 12.4 | G25: 12.2 | H25: 13.6 | I25: 12.9 | K25: 13.4 | L25: 13.4 | M25: 13.3 | N25: 14.1 | O25: 29.8 | P25: 29.8 | Q25: 29.8 | S25: =O25 -> 29.8 | T25: 11.2 | U25: 9.1 | V25: 13.6 | X25: =AD25 -> 12.5 | Y25: 11 | Z25: 17.3 | AA25: 16.6 | AB25: 12.2 | AC25: 13.1 | AD25: 12.5 | AE25: 14.2 | AK25: 11.4 | AL25: 13.5 | AM25: 18.1 | AN25: =AO25 -> 12.3 | AO25: 12.3 | AR25: =AM25 -> 18.1 | AS25: =AM25/AM$18*AS$18 -> 21.064655 | AT25: =AM25 -> 18.1 | AU25: 11.9 | AV25: 20.3 | AX25: 15.3 | BB25: 5.1 | BC25: =BB25 -> 5.1 | BD25: 11.9 | BE25: =BD25 -> 11.9 | BF25: =BD25 -> 11.9 | BJ25: 11 | BK25: 15 | BN25: ='Forage crops'!L28 -> 9.4 | BO25: 10.8 | BP25: ='Forage crops'!M28 -> 9.375 | BQ25: 11.9 | BR25: 6.8 | BS25: =AT25 -> 18.1 | BT25: =AT25 -> 18.1
A26: Nitrogen digestibility, ruminants | B26: % | C26: 70.4 | D26: 72.8 | E26: 68.3 | F26: 66.6 | G26: 63.9 | H26: 66.3 | I26: 69.5 | K26: 70 | L26: 78 | M26: 78.9 | N26: 80 | O26: 0 | P26: 0 | Q26: 0 | S26: =O26 -> 0 | T26: 74.7 | U26: 84.5 | V26: 80.4 | X26: =AD26 -> 77.1 | Y26: 68 | Z26: 81.2 | AA26: 81 | AB26: 74.4 | AC26: 75.2 | AD26: 77.1 | AE26: 77 | AK26: 72.1 | AL26: 79.5 | AM26: 78.4 | AN26: =AO26 -> 73.9 | AO26: 73.9 | AR26: =AM26 -> 78.4 | AS26: 78 | AT26: =AM26 -> 78.4 | AU26: 69 | AV26: 74.6 | AW26: 90.1 | AX26: 92.5 | BB26: 66.1 | BC26: =BB26 -> 66.1 | BD26: 0 | BE26: =BD26 -> 0 | BF26: =BD26 -> 0 | BJ26: 0 | BK26: 90 | BN26: ='Forage crops'!L29 -> 63.45 | BO26: 54.6 | BP26: ='Forage crops'!M29 -> 68.35 | BQ26: 52.1 | BR26: 3.5 | BS26: =AT26 -> 78.4 | BT26: =AT26 -> 78.4
A28: PIG
A29: DE growing pig | B29: MJ/kg DM | C29: 15.8 | D29: 15.9 | E29: 15.1 | F29: 14.7 | G29: 12.7 | H29: 16.5 | I29: 15.6 | K29: 17.1 | L29: 16.5 | M29: 15.5 | N29: 15.8 | O29: 33.4 | P29: 33.4 | Q29: 33.4 | S29: =O29 -> 33.4 | T29: 13.4 | U29: 10.3 | V29: 16.8 | X29: =AD29 -> 13.9 | Y29: 10.8 | Z29: 21.8 | AA29: 21.4 | AB29: 12.3 | AC29: 15.4 | AD29: 13.9 | AE29: 16.3 | AK29: 13.9 | AL29: 17.4 | AM29: 21.5 | AN29: =AO29 -> 15.3 | AO29: 15.3 | AR29: =AM29 -> 21.5 | AS29: =AM29/AM$18*AS$18 -> 25.021552 | AT29: =AM29 -> 21.5 | AU29: 15.4 | BB29: 7.3 | BC29: =BB29 -> 7.3 | BD29: 14.5 | BE29: =BD29 -> 14.5 | BF29: =BD29 -> 14.5 | BJ29: 14
A30: NE growing pig | B30: MJ/kg DM | C30: 12.1 | D30: 11.8 | E30: 11.3 | F30: 11.1 | G30: 9.1 | H30: 12.9 | I30: 11.9 | K30: 13.4 | L30: 13.4 | M30: 14.7 | N30: 9.3 | O30: 29.7 | P30: 29.8 | Q30: 29.8 | S30: =O30 -> 29.7 | T30: 7.6 | U30: 5.3 | V30: 9.3 | X30: =AD30 -> 8.2 | Y30: 7.2 | Z30: 11.6 | AA30: 12.7 | AB30: 11.6 | AC30: 9.2 | AD30: 8.2 | AE30: 9.5 | AK30: =8.8 -> 8.8 | AL30: 12 | AM30: 16.2 | AN30: =AO30 -> 12.4 | AO30: 12.4 | AR30: =AM30 -> 16.2 | AS30: =AM30/AM$18*AS$18 -> 18.853448 | AT30: =AM30 -> 16.2 | AU30: 11.8 | AV30: 17.8 | AW30: 14.5 | AX30: 14 | BB30: 3.4 | BC30: =BB30 -> 3.4 | BD30: =BD29*(BB30/BB29) -> 6.7534247 | BE30: =BD30 -> 6.7534247 | BF30: =BD30 -> 6.7534247 | BJ30: 8.8 | BK30: 14 | BO30: =1150*4.184/1000/0.4536 -> 10.607584
A31: Nitrogen digestibility, growing pig | B31: % | C31: 83.5 | D31: 82.5 | E31: 70.9 | F31: 76.2 | G31: 75.9 | H31: 80.8 | I31: 83.9 | K31: 92 | L31: 84.9 | M31: 82 | N31: 84 | O31: 0 | P31: 0 | Q31: 0 | S31: =O31 -> 0 | T31: 80.3 | U31: 78.4 | V31: 87 | X31: =AD31 -> 71.4 | Y31: 64.9 | Z31: 88.1 | AA31: 86.2 | AB31: 60.2 | AC31: 71 | AD31: 71.4 | AE31: 83 | AK31: 50 | AL31: 95 | AM31: 95 | AN31: 95 | AO31: 95 | AR31: =AM31 -> 95 | AS31: 95 | AT31: =AM31 -> 95 | AU31: 60 | AV31: 73.3 | AW31: 79.4 | AX31: 86.5 | BB31: 39.6 | BC31: =BB31 -> 39.6 | BD31: 73.5 | BE31: =BD31 -> 73.5 | BF31: =BD31 -> 73.5 | BJ31: 0 | BK31: 70 | BO31: =BO26 -> 54.6
A33: POULTRY
A34: AME poultry | B34: MJ/kg DM | E34: 13.2 | M34: 12.2 | X34: =AD34 -> 9.9 | AD34: 9.9
A35: AMEn cockerel | B35: MJ/kg DM | C35: 14.4 | D35: 14.3 | E35: 13.3 | F35: 13.2 | G35: 11.1 | H35: 15.4 | I35: 14.2 | K35: 15.9 | L35: 12.5 | M35: 12.1 | N35: 9.7 | O35: 38.1 | P35: 38.1 | Q35: 38.1 | S35: =O35 -> 38.1 | T35: 7.4 | U35: 7.3 | V35: 10.9 | X35: =AD35 -> 9.3 | Y35: 7.8 | Z35: 16.9 | AA35: 16.8 | AB35: 8.7 | AC35: 10.4 | AD35: 9.3 | AE35: 12.6 | AK35: 12.3 | AL35: 11 | AM35: 16 | AN35: =AO35 -> 8.5 | AO35: 8.5 | AR35: =AM35 -> 16 | AS35: =AM35/AM$18*AS$18 -> 18.62069 | AT35: =AM35 -> 16 | AU35: 14.9 | AV35: 16.8 | AW35: 19.6 | AX35: 16 | BB35: =BB36 -> 9.8 | BC35: =BB35 -> 9.8 | BD35: =BD29*(BB35/BB29) -> 19.465753 | BE35: =BD35 -> 19.465753 | BF35: =BD35 -> 19.465753 | BJ35: 12 | BK35: 16
A36: AMEn broiler | B36: MJ/kg DM | C36: 13.8 | D36: 13.8 | E36: 11.2 | F36: 11.3 | G36: 11.9 | H36: 15.1 | I36: 13.5 | K36: 15.6 | L36: 11.7 | M36: 11.8 | N36: 9.5 | O36: 37.7 | P36: 37.7 | Q36: 37.7 | S36: =O36 -> 37.7 | T36: 9.6 | U36: 7.2 | V36: 10.7 | X36: =AD36 -> 9.1 | Y36: 7.4 | Z36: 16.9 | AA36: 16.6 | AB36: 8.5 | AC36: 10.1 | AD36: 9.1 | AE36: 12.3 | AK36: =AK35 -> 12.3 | AL36: 11 | AM36: 16 | AN36: =AO36 -> 8.5 | AO36: 8.5 | AR36: =AM36 -> 16 | AS36: =AM36/AM$18*AS$18 -> 18.62069 | AT36: =AM36 -> 16 | AU36: 14.8 | AV36: =AV35 -> 16.8 | AW36: 18.5 | AX36: 17.1 | BB36: 9.8 | BC36: =BB36 -> 9.8 | BD36: =BD35 -> 19.465753 | BE36: =BD36 -> 19.465753 | BF36: =BD36 -> 19.465753 | BJ36: 12 | BK36: 16
A37: Nitrogen digestibility, growing pig | B37: %
A39: LOSSES (%)
A40: Field | C40: 2 | D40: 2 | E40: 2 | F40: 2 | G40: 2 | H40: 2 | I40: 2 | K40: 2 | L40: 2 | M40: 2 | N40: 2 | AV40: 10 | AW40: 10 | AX40: 10 | BO40: 10 | BP40: 10 | BQ40: 5
A41: Handling, storage and feed out | C41: 5 | D41: 5 | E41: 5 | F41: 5 | G41: 5 | H41: 5 | I41: 5 | K41: 5 | L41: 5 | M41: 5 | N41: 5 | T41: 5 | U41: 5 | V41: 5 | X41: 5 | Y41: 5 | Z41: 5 | AA41: 5 | AB41: 5 | AC41: 5 | AD41: 5 | AE41: 5 | AK41: 5 | AL41: 5 | AM41: 5 | AN41: 5 | AO41: 5 | AR41: 10 | AS41: 10 | AT41: 10 | AU41: 10 | AV41: 5 | AW41: 5 | AX41: 5 | BB41: 10 | BC41: 10 | BD41: 10 | BE41: 10 | BF41: 10 | BJ41: 0 | BK41: 10 | BN41: 0 | BO41: 20 | BP41: 20 | BQ41: 10 | BR41: 10 | BS41: 0 | BT41: 0
A43: Total | C43: =100-(1-C40/100)*(1-C41/100)*100 -> 6.9 | D43: =100-(1-D40/100)*(1-D41/100)*100 -> 6.9 | E43: =100-(1-E40/100)*(1-E41/100)*100 -> 6.9 | F43: =100-(1-F40/100)*(1-F41/100)*100 -> 6.9 | G43: =100-(1-G40/100)*(1-G41/100)*100 -> 6.9 | H43: =100-(1-H40/100)*(1-H41/100)*100 -> 6.9 | I43: =100-(1-I40/100)*(1-I41/100)*100 -> 6.9 | K43: =100-(1-K40/100)*(1-K41/100)*100 -> 6.9 | L43: =100-(1-L40/100)*(1-L41/100)*100 -> 6.9 | M43: =100-(1-M40/100)*(1-M41/100)*100 -> 6.9 | N43: =100-(1-N40/100)*(1-N41/100)*100 -> 6.9 | O43: =100-(1-O40/100)*(1-O41/100)*100 -> 0 | P43: =100-(1-P40/100)*(1-P41/100)*100 -> 0 | Q43: =100-(1-Q40/100)*(1-Q41/100)*100 -> 0 | S43: =100-(1-S40/100)*(1-S41/100)*100 -> 0 | T43: =100-(1-T40/100)*(1-T41/100)*100 -> 5 | U43: =100-(1-U40/100)*(1-U41/100)*100 -> 5 | V43: =100-(1-V40/100)*(1-V41/100)*100 -> 5 | X43: =100-(1-X40/100)*(1-X41/100)*100 -> 5 | Y43: =100-(1-Y40/100)*(1-Y41/100)*100 -> 5 | Z43: =100-(1-Z40/100)*(1-Z41/100)*100 -> 5 | AA43: =100-(1-AA40/100)*(1-AA41/100)*100 -> 5 | AB43: =100-(1-AB40/100)*(1-AB41/100)*100 -> 5 | AC43: =100-(1-AC40/100)*(1-AC41/100)*100 -> 5 | AD43: =100-(1-AD40/100)*(1-AD41/100)*100 -> 5 | AE43: =100-(1-AE40/100)*(1-AE41/100)*100 -> 5 | AK43: =100-(1-AK40/100)*(1-AK41/100)*100 -> 5 | AL43: =100-(1-AL40/100)*(1-AL41/100)*100 -> 5 | AM43: =100-(1-AM40/100)*(1-AM41/100)*100 -> 5 | AN43: =100-(1-AN40/100)*(1-AN41/100)*100 -> 5 | AO43: =100-(1-AO40/100)*(1-AO41/100)*100 -> 5 | AR43: =100-(1-AR40/100)*(1-AR41/100)*100 -> 10 | AS43: =100-(1-AS40/100)*(1-AS41/100)*100 -> 10 | AT43: =100-(1-AT40/100)*(1-AT41/100)*100 -> 10 | AU43: =100-(1-AU40/100)*(1-AU41/100)*100 -> 10 | AV43: =100-(1-AV40/100)*(1-AV41/100)*100 -> 14.5 | AW43: =100-(1-AW40/100)*(1-AW41/100)*100 -> 14.5 | AX43: =100-(1-AX40/100)*(1-AX41/100)*100 -> 14.5 | BB43: =100-(1-BB40/100)*(1-BB41/100)*100 -> 10 | BC43: =100-(1-BC40/100)*(1-BC41/100)*100 -> 10 | BD43: =100-(1-BD40/100)*(1-BD41/100)*100 -> 10 | BE43: =100-(1-BE40/100)*(1-BE41/100)*100 -> 10 | BF43: =100-(1-BF40/100)*(1-BF41/100)*100 -> 10 | BJ43: =100-(1-BJ40/100)*(1-BJ41/100)*100 -> 0 | BK43: =100-(1-BK40/100)*(1-BK41/100)*100 -> 10 | BL43: =100-(1-BL40/100)*(1-BL41/100)*(1-BL42/100)*100 -> 0 | BM43: =100-(1-BM40/100)*(1-BM41/100)*(1-BM42/100)*100 -> 0 | BN43: =100-(1-BN40/100)*(1-BN41/100)*100 -> 0 | BO43: =100-(1-BO40/100)*(1-BO41/100)*100 -> 28 | BP43: =100-(1-BP40/100)*(1-BP41/100)*100 -> 28 | BQ43: =100-(1-BQ40/100)*(1-BQ41/100)*100 -> 14.5 | BR43: =100-(1-BR40/100)*(1-BR41/100)*100 -> 10 | BS43: =100-(1-BS40/100)*(1-BS41/100)*100 -> 0 | BT43: =100-(1-BT40/100)*(1-BT41/100)*100 -> 0

Sheet Rapes&Sun meals
B2: Rapeseed meal
B3: Heuzé V., Tran G., Sauvant D., Lessire M., Lebas F., 2018. Rapeseed meal. Feedipedia, a programme by INRA, CIRAD, AFZ and FAO. https://www.feedipedia.org/node/52 Last updated on June 15, 2018, 15:53
D5: Limit | E5: Limit (high)
B6: Ruminants | D6: no limit | E6: no limit
B8: Growing pigs | D8: no limit | E8: no limit
B10: Broilers | D10: 0.2 | E10: 0.3
B11: Egglayers | D11: 0.1 | E11: 0.2
B14: Sunflower seed meal
B15: Heuzé V., Tran G., Hassoun P., Lessire M., Lebas F., 2016. Sunflower meal. Feedipedia, a programme by INRA, CIRAD, AFZ and FAO. https://www.feedipedia.org/node/732 Last updated on September 1, 2016, 15:14
D17: Limit | E17: Limit (high)
B18: Ruminants | D18: no limit | E18: no limit
B20: Pigs | D20: 0.1 | E20: 0.2
B22: Broilers | D22: 0.3
B23: Egglayers | D23: 0.3

Sheet Losses
B3: Losses during ensilage, %
B5: Linn Abrahamsson (2012) Förluster i olika ensileringssystem
D6: w.w. | E6: d.m.
B7: Plansilo 121 | D7: 17.1 | E7: 29.2
B8: Plansilo 122 | D8: 14.7 | E8: 26.2
B9: Tornsilo 139 | D9: 28.4 | E9: 24.3
B10: Tornsilo 140 | D10: 32.5 | E10: 24.9
B11: Slang 1 | D11: 16.62 | E11: 21.7
B12: Slang 2-4 | D12: 26.7 | E12: 18.1
B13: Balar | D13: 0.8 | E13: 0.78
B14: G. Borreani et al. (2018) Silage review: Factors affecting dry matter and quality losses in silages | L14: https://doi.org/10.3168/jds.2017-13837
E15: Direct ensiling | G15: Field curing, respiration and harvesting | H15: In silo respiration, fermentation and effluent | I15: Top spoilage and feedout | K15: Total
B16: Good management | E16: 1 | G16: 4 | H16: 5 | I16: 3 | K16: =100-(1-G16/100)*(1-H16/100)*(1-I16/100)*100 -> 11.536
B17: Not so good man… | E17: =E16+3 -> 4 | G17: =G16+11 -> 15 | H17: =H16+13 -> 18 | I17: =I16+18 -> 21 | K17: =100-(1-G17/100)*(1-H17/100)*(1-I17/100)*100 -> 44.937
B18: Without covering | E18: =E17 -> 4 | G18: =G17 -> 15 | H18: =H17+3 -> 21 | I18: =I17+13 -> 34 | K18: =100-(1-G18/100)*(1-H18/100)*(1-I18/100)*100 -> 55.681
B19: + Rain | E19: =E18 -> 4 | G19: =G18+5 -> 20 | H19: =H18 -> 21 | I19: =I18 -> 34 | K19: =100-(1-G19/100)*(1-H19/100)*(1-I19/100)*100 -> 58.288
B21: Average management | E21: =AVERAGE(E16:E17) -> 2.5 | G21: =AVERAGE(G16:G17) -> 9.5 | H21: =AVERAGE(H16:H17) -> 11.5 | I21: =AVERAGE(I16:I17) -> 12 | K21: =100-(1-G21/100)*(1-H21/100)*(1-I21/100)*100 -> 29.5186 | M21: =100-(1-H21/100)*(1-I21/100)*100 -> 22.12
B25: Losses during feeding, %
B26: British Columbia Ministry of Agriculture (2015) Farm Mechanization FACTSHEET - FORAGE HARVESTING, STORAGE AND FEEDING LOSSES | O26: https://www2.gov.bc.ca/assets/gov/farming-natural-resources-and-industry/agriculture-and-seafood/farm-management/structures-and-mechanization/200-series/240100-4_forage_harvesting_-_storage_and_feeding_losses.pdf
O27: (accessed 2018-01-09)
E28: min | F28: max | G28: avg
B29: Harves losses | E29: 0.02 | F29: 0.1 | G29: =AVERAGE(E29:F29) -> 0.06 | J29: "On average, 25% of the value of the standing forage
B30: Respiration weathering | E30: 0.04 | F30: 0.1 | G30: =AVERAGE(E30:F30) -> 0.07 | J30: crop is lost before it even enters the animals’ digestive
B31: Storage losses | E31: 0.03 | F31: 0.1 | G31: =AVERAGE(E31:F31) -> 0.065 | J31: tract."
B32: Feeding losses | E32: 0.15 | F32: 0.4 | G32: =AVERAGE(E32:F32) -> 0.275
B34: Total | E34: =1-(1-E29)*(1-E30)*(1-E31)*(1-E32) -> 0.2243104 | F34: =1-(1-F29)*(1-F30)*(1-F31)*(1-F32) -> 0.5626 | G34: =1-(1-G29)*(1-G30)*(1-G31)*(1-G32) -> 0.40740168

Sheet Grass
B3: https://doi.org/10.5194/bg-13-3757-2016 | P3: CAPRI documentation
N4: Table 3
D5: Grassland area (1000 km2, 2000) | H5: Mean productivity (kg DM m-2 yr-1) | L5: Herbage use efficiency (%)
D6: Total | E6: Mown | F6: Grazed | H6: Total | I6: Mown | J6: Grazed | L6: Total
B7: Western Europé | D7: 555 | E7: 44 | F7: 522 | H7: =SUMPRODUCT(I7:J7,E7:F7)/SUM(E7:F7) -> 0.3519788 | I7: 0.85 | J7: 0.31 | L7: 10.6
B8: Eastern Europé | D8: 366 | E8: 93 | F8: 274 | H8: =SUMPRODUCT(I8:J8,E8:F8)/SUM(E8:F8) -> 0.29362398 | I8: 0.54 | J8: 0.21 | L8: 9.8
D10: (1000 ha) | H10: (t DM ha-1 yr-1) | L10: Herbage use (t DM ha-1 yr-1)
B11: Western Europé | D11: =D7*100 -> 55500 | E11: =E7*100 -> 4400 | F11: =F7*100 -> 52200 | H11: =H7*10000/1000 -> 3.519788 | I11: =I7*10000/1000 -> 8.5 | J11: =J7*10000/1000 -> 3.1 | L11: =H11*$L7/100 -> 0.37309753 | M11: =I11*$L7/100 -> 0.901 | N11: =J11*$L7/100 -> 0.3286
B12: Eastern Europé | D12: =D8*100 -> 36600 | E12: =E8*100 -> 9300 | F12: =F8*100 -> 27400 | H12: =H8*10000/1000 -> 2.9362398 | I12: =I8*10000/1000 -> 5.4 | J12: =J8*10000/1000 -> 2.1 | L12: =H12*$L8/100 -> 0.2877515 | M12: =I12*$L8/100 -> 0.5292 | N12: =J12*$L8/100 -> 0.2058
B14: CAPRI | D14: 60121.797 | H14: 4.43 | L14: =H14*$L7/100 -> 0.46958
B16: Using 89% losses for grass (i.e. 11% herbage-use-efficiency) results in too little energy in feed rations for countries with a lot of
B17: grass in the rations. Using 70% losses for grass (30% use-efficiency) results in more balanced rations.
I23: =(E11*I11+F11*J11)*1000/1000000 -> 199.22 | J23: Mt DM | L23: =(E11*M11+F11*N11)*1000/1000000 -> 21.11732
I24: =(E12*I12+F12*J12)*1000/1000000 -> 107.76 | J24: Mt DM | L24: =(E12*M12+F12*N12)*1000/1000000 -> 10.56048

Sheet in.dry_matter.csv
A1: ='Main table'!C2 -> Soft wheat | B1: ='Main table'!D2 -> Durum wheat | C1: ='Main table'!E2 -> Rye and meslin | D1: ='Main table'!F2 -> Barley | E1: ='Main table'!G2 -> Oats | F1: ='Main table'!H2 -> Grain maize | G1: ='Main table'!I2 -> Other cereals | H1: ='Main table'!J2 -> Paddy rice | ... BR1: ='Main table'!BT2 -> Sheep and Goat Milk for feeding
A2: ='Main table'!C7/100 -> 0.86 | B2: ='Main table'!D7/100 -> 0.86 | C2: ='Main table'!E7/100 -> 0.86 | D2: ='Main table'!F7/100 -> 0.86 | E2: ='Main table'!G7/100 -> 0.86 | F2: ='Main table'!H7/100 -> 0.86 | G2: ='Main table'!I7/100 -> 0.86 | H2: ='Main table'!J7/100 -> 0 | ... BR2: ='Main table'!BT7/100 -> 0.13

Sheet in.feed.csv
A1: Animal | B1: Parameter | C1: Constrain (1 = min, -1 = max) | D1: ='Main table'!C2 -> Soft wheat | E1: ='Main table'!D2 -> Durum wheat | F1: ='Main table'!E2 -> Rye and meslin | G1: ='Main table'!F2 -> Barley | H1: ='Main table'!G2 -> Oats | I1: ='Main table'!H2 -> Grain maize | J1: ='Main table'!I2 -> Other cereals | K1: ='Main table'!J2 -> Paddy rice | ... BU1: ='Main table'!BT2 -> Sheep and Goat Milk for feeding
A2: Dairy Cows | B2: Tot Feed, kg | C2: -1 | D2: =1-'Main table'!C$43/100 -> 0.931 | E2: =1-'Main table'!D$43/100 -> 0.931 | F2: =1-'Main table'!E$43/100 -> 0.931 | G2: =1-'Main table'!F$43/100 -> 0.931 | H2: =1-'Main table'!G$43/100 -> 0.931 | I2: =1-'Main table'!H$43/100 -> 0.931 | J2: =1-'Main table'!I$43/100 -> 0.931 | K2: =1-'Main table'!J$43/100 -> 1 | ... BU2: =1-'Main table'!BT$43/100 -> 1
A3: Dairy Cows | B3: ME, MJ/kg | C3: 1 | D3: ='Main table'!C$7/100*(1-'Main table'!C$43/100)*'Main table'!C$25 -> 10.488646 | E3: ='Main table'!D$7/100*(1-'Main table'!D$43/100)*'Main table'!D$25 -> 10.488646 | F3: ='Main table'!E$7/100*(1-'Main table'!E$43/100)*'Main table'!E$25 -> 10.40858 | G3: ='Main table'!F$7/100*(1-'Main table'!F$43/100)*'Main table'!F$25 -> 9.928184 | H3: ='Main table'!G$7/100*(1-'Main table'!G$43/100)*'Main table'!G$25 -> 9.768052 | I3: ='Main table'!H$7/100*(1-'Main table'!H$43/100)*'Main table'!H$25 -> 10.888976 | J3: ='Main table'!I$7/100*(1-'Main table'!I$43/100)*'Main table'!I$25 -> 10.328514 | K3: ='Main table'!J$7/100*(1-'Main table'!J$43/100)*'Main table'!J$25 -> 0 | ... BU3: ='Main table'!BT$7/100*(1-'Main table'!BT$43/100)*'Main table'!BT$25 -> 2.353
A4: Dairy Cows | B4: Digestible CP, % | C4: 1 | D4: ='Main table'!C$7/100*(1-'Main table'!C$43/100)*'Main table'!C$9*'Main table'!C$26/100 -> 7.1021745 | E4: ='Main table'!D$7/100*(1-'Main table'!D$43/100)*'Main table'!D$9*'Main table'!D$26/100 -> 9.5009518 | F4: ='Main table'!E$7/100*(1-'Main table'!E$43/100)*'Main table'!E$9*'Main table'!E$26/100 -> 5.632563 | G4: ='Main table'!F$7/100*(1-'Main table'!F$43/100)*'Main table'!F$9*'Main table'!F$26/100 -> 6.2922268 | H4: ='Main table'!G$7/100*(1-'Main table'!G$43/100)*'Main table'!G$9*'Main table'!G$26/100 -> 5.6278391 | I4: ='Main table'!H$7/100*(1-'Main table'!H$43/100)*'Main table'!H$9*'Main table'!H$26/100 -> 4.9898733 | J4: ='Main table'!I$7/100*(1-'Main table'!I$43/100)*'Main table'!I$9*'Main table'!I$26/100 -> 6.5105668 | K4: ='Main table'!J$7/100*(1-'Main table'!J$43/100)*'Main table'!J$9*'Main table'!J$26/100 -> 0 | ... BU4: ='Main table'!BT$7/100*(1-'Main table'!BT$43/100)*'Main table'!BT$9*'Main table'!BT$26/100 -> 2.588768
A5: Other Cattle and Buffalo | B5: Tot Feed, kg | C5: -1 | D5: =1-'Main table'!C$43/100 -> 0.931 | E5: =1-'Main table'!D$43/100 -> 0.931 | F5: =1-'Main table'!E$43/100 -> 0.931 | G5: =1-'Main table'!F$43/100 -> 0.931 | H5: =1-'Main table'!G$43/100 -> 0.931 | I5: =1-'Main table'!H$43/100 -> 0.931 | J5: =1-'Main table'!I$43/100 -> 0.931 | K5: =1-'Main table'!J$43/100 -> 1 | ... BU5: =1-'Main table'!BT$43/100 -> 1
A6: Other Cattle and Buffalo | B6: ME, MJ/kg | C6: 1 | D6: ='Main table'!C$7/100*(1-'Main table'!C$43/100)*'Main table'!C$25 -> 10.488646 | E6: ='Main table'!D$7/100*(1-'Main table'!D$43/100)*'Main table'!D$25 -> 10.488646 | F6: ='Main table'!E$7/100*(1-'Main table'!E$43/100)*'Main table'!E$25 -> 10.40858 | G6: ='Main table'!F$7/100*(1-'Main table'!F$43/100)*'Main table'!F$25 -> 9.928184 | H6: ='Main table'!G$7/100*(1-'Main table'!G$43/100)*'Main table'!G$25 -> 9.768052 | I6: ='Main table'!H$7/100*(1-'Main table'!H$43/100)*'Main table'!H$25 -> 10.888976 | J6: ='Main table'!I$7/100*(1-'Main table'!I$43/100)*'Main table'!I$25 -> 10.328514 | K6: ='Main table'!J$7/100*(1-'Main table'!J$43/100)*'Main table'!J$25 -> 0 | ... BU6: ='Main table'!BT$7/100*(1-'Main table'!BT$43/100)*'Main table'!BT$25 -> 2.353
A7: Other Cattle and Buffalo | B7: Digestible CP, % | C7: 1 | D7: ='Main table'!C$7/100*(1-'Main table'!C$43/100)*'Main table'!C$9*'Main table'!C$26/100 -> 7.1021745 | E7: ='Main table'!D$7/100*(1-'Main table'!D$43/100)*'Main table'!D$9*'Main table'!D$26/100 -> 9.5009518 | F7: ='Main table'!E$7/100*(1-'Main table'!E$43/100)*'Main table'!E$9*'Main table'!E$26/100 -> 5.632563 | G7: ='Main table'!F$7/100*(1-'Main table'!F$43/100)*'Main table'!F$9*'Main table'!F$26/100 -> 6.2922268 | H7: ='Main table'!G$7/100*(1-'Main table'!G$43/100)*'Main table'!G$9*'Main table'!G$26/100 -> 5.6278391 | I7: ='Main table'!H$7/100*(1-'Main table'!H$43/100)*'Main table'!H$9*'Main table'!H$26/100 -> 4.9898733 | J7: ='Main table'!I$7/100*(1-'Main table'!I$43/100)*'Main table'!I$9*'Main table'!I$26/100 -> 6.5105668 | K7: ='Main table'!J$7/100*(1-'Main table'!J$43/100)*'Main table'!J$9*'Main table'!J$26/100 -> 0 | ... BU7: ='Main table'!BT$7/100*(1-'Main table'!BT$43/100)*'Main table'!BT$9*'Main table'!BT$26/100 -> 2.588768
A8: Sheep and Goat | B8: Tot Feed, kg | C8: -1 | D8: =1-'Main table'!C$43/100 -> 0.931 | E8: =1-'Main table'!D$43/100 -> 0.931 | F8: =1-'Main table'!E$43/100 -> 0.931 | G8: =1-'Main table'!F$43/100 -> 0.931 | H8: =1-'Main table'!G$43/100 -> 0.931 | I8: =1-'Main table'!H$43/100 -> 0.931 | J8: =1-'Main table'!I$43/100 -> 0.931 | K8: =1-'Main table'!J$43/100 -> 1 | ... BU8: =1-'Main table'!BT$43/100 -> 1
A9: Sheep and Goat | B9: ME, MJ/kg | C9: 1 | D9: ='Main table'!C$7/100*(1-'Main table'!C$43/100)*'Main table'!C$25 -> 10.488646 | E9: ='Main table'!D$7/100*(1-'Main table'!D$43/100)*'Main table'!D$25 -> 10.488646 | F9: ='Main table'!E$7/100*(1-'Main table'!E$43/100)*'Main table'!E$25 -> 10.40858 | G9: ='Main table'!F$7/100*(1-'Main table'!F$43/100)*'Main table'!F$25 -> 9.928184 | H9: ='Main table'!G$7/100*(1-'Main table'!G$43/100)*'Main table'!G$25 -> 9.768052 | I9: ='Main table'!H$7/100*(1-'Main table'!H$43/100)*'Main table'!H$25 -> 10.888976 | J9: ='Main table'!I$7/100*(1-'Main table'!I$43/100)*'Main table'!I$25 -> 10.328514 | K9: ='Main table'!J$7/100*(1-'Main table'!J$43/100)*'Main table'!J$25 -> 0 | ... BU9: ='Main table'!BT$7/100*(1-'Main table'!BT$43/100)*'Main table'!BT$25 -> 2.353
A10: Sheep and Goat | B10: Digestible CP, % | C10: 1 | D10: ='Main table'!C$7/100*(1-'Main table'!C$43/100)*'Main table'!C$9*'Main table'!C$26/100 -> 7.1021745 | E10: ='Main table'!D$7/100*(1-'Main table'!D$43/100)*'Main table'!D$9*'Main table'!D$26/100 -> 9.5009518 | F10: ='Main table'!E$7/100*(1-'Main table'!E$43/100)*'Main table'!E$9*'Main table'!E$26/100 -> 5.632563 | G10: ='Main table'!F$7/100*(1-'Main table'!F$43/100)*'Main table'!F$9*'Main table'!F$26/100 -> 6.2922268 | H10: ='Main table'!G$7/100*(1-'Main table'!G$43/100)*'Main table'!G$9*'Main table'!G$26/100 -> 5.6278391 | I10: ='Main table'!H$7/100*(1-'Main table'!H$43/100)*'Main table'!H$9*'Main table'!H$26/100 -> 4.9898733 | J10: ='Main table'!I$7/100*(1-'Main table'!I$43/100)*'Main table'!I$9*'Main table'!I$26/100 -> 6.5105668 | K10: ='Main table'!J$7/100*(1-'Main table'!J$43/100)*'Main table'!J$9*'Main table'!J$26/100 -> 0 | ... BU10: ='Main table'!BT$7/100*(1-'Main table'!BT$43/100)*'Main table'!BT$9*'Main table'!BT$26/100 -> 2.588768
A11: Pig Fattening | B11: Tot Feed, kg | C11: -1 | D11: =1-'Main table'!C$43/100 -> 0.931 | E11: =1-'Main table'!D$43/100 -> 0.931 | F11: =1-'Main table'!E$43/100 -> 0.931 | G11: =1-'Main table'!F$43/100 -> 0.931 | H11: =1-'Main table'!G$43/100 -> 0.931 | I11: =1-'Main table'!H$43/100 -> 0.931 | J11: =1-'Main table'!I$43/100 -> 0.931 | K11: =1-'Main table'!J$43/100 -> 1 | ... BU11: =1-'Main table'!BT$43/100 -> 1
A12: Pig Fattening | B12: NE, MJ/kg | C12: 1 | D12: ='Main table'!C$7/100*(1-'Main table'!C$43/100)*'Main table'!C$30 -> 9.687986 | E12: ='Main table'!D$7/100*(1-'Main table'!D$43/100)*'Main table'!D$30 -> 9.447788 | F12: ='Main table'!E$7/100*(1-'Main table'!E$43/100)*'Main table'!E$30 -> 9.047458 | G12: ='Main table'!F$7/100*(1-'Main table'!F$43/100)*'Main table'!F$30 -> 8.887326 | H12: ='Main table'!G$7/100*(1-'Main table'!G$43/100)*'Main table'!G$30 -> 7.286006 | I12: ='Main table'!H$7/100*(1-'Main table'!H$43/100)*'Main table'!H$30 -> 10.328514 | J12: ='Main table'!I$7/100*(1-'Main table'!I$43/100)*'Main table'!I$30 -> 9.527854 | K12: ='Main table'!J$7/100*(1-'Main table'!J$43/100)*'Main table'!J$30 -> 0 | ... BU12: ='Main table'!BT$7/100*(1-'Main table'!BT$43/100)*'Main table'!BT$30 -> 0
A13: Pig Fattening | B13: Digestible CP, % | C13: 1 | D13: ='Main table'!C$7/100*(1-'Main table'!C$43/100)*'Main table'!C$9*'Main table'!C$31/100 -> 8.4237439 | E13: ='Main table'!D$7/100*(1-'Main table'!D$43/100)*'Main table'!D$9*'Main table'!D$31/100 -> 10.766875 | F13: ='Main table'!E$7/100*(1-'Main table'!E$43/100)*'Main table'!E$9*'Main table'!E$31/100 -> 5.8469798 | G13: ='Main table'!F$7/100*(1-'Main table'!F$43/100)*'Main table'!F$9*'Main table'!F$31/100 -> 7.1992145 | H13: ='Main table'!G$7/100*(1-'Main table'!G$43/100)*'Main table'!G$9*'Main table'!G$31/100 -> 6.6847103 | I13: ='Main table'!H$7/100*(1-'Main table'!H$43/100)*'Main table'!H$9*'Main table'!H$31/100 -> 6.0811728 | J13: ='Main table'!I$7/100*(1-'Main table'!I$43/100)*'Main table'!I$9*'Main table'!I$31/100 -> 7.8595188 | K13: ='Main table'!J$7/100*(1-'Main table'!J$43/100)*'Main table'!J$9*'Main table'!J$31/100 -> 0 | ... BU13: ='Main table'!BT$7/100*(1-'Main table'!BT$43/100)*'Main table'!BT$9*'Main table'!BT$31/100 -> 0
A14: Pig Fattening | B14: Lysine, % | C14: 1 | D14: ='Main table'!C$7/100*(1-'Main table'!C$43/100)*'Main table'!C$9*'Main table'!C$21/100 -> 0.29256116 | E14: ='Main table'!D$7/100*(1-'Main table'!D$43/100)*'Main table'!D$9*'Main table'!D$21/100 -> 0.3442838 | F14: ='Main table'!E$7/100*(1-'Main table'!E$43/100)*'Main table'!E$9*'Main table'!E$21/100 -> 0.32162512 | G14: ='Main table'!F$7/100*(1-'Main table'!F$43/100)*'Main table'!F$9*'Main table'!F$21/100 -> 0.34956816 | H14: ='Main table'!G$7/100*(1-'Main table'!G$43/100)*'Main table'!G$9*'Main table'!G$21/100 -> 0.37871218 | I14: ='Main table'!H$7/100*(1-'Main table'!H$43/100)*'Main table'!H$9*'Main table'!H$21/100 -> 0.23331232 | J14: ='Main table'!I$7/100*(1-'Main table'!I$43/100)*'Main table'!I$9*'Main table'!I$21/100 -> 0.32787027 | K14: ='Main table'!J$7/100*(1-'Main table'!J$43/100)*'Main table'!J$9*'Main table'!J$21/100 -> 0 | ... BU14: ='Main table'!BT$7/100*(1-'Main table'!BT$43/100)*'Main table'!BT$9*'Main table'!BT$21/100 -> 0.257556
A15: Pig Fattening | B15: Metheonine, % | C15: 1 | D15: ='Main table'!C$7/100*(1-'Main table'!C$43/100)*'Main table'!C$9*'Main table'!C$22/100 -> 0.16141306 | E15: ='Main table'!D$7/100*(1-'Main table'!D$43/100)*'Main table'!D$9*'Main table'!D$22/100 -> 0.20881213 | F15: ='Main table'!E$7/100*(1-'Main table'!E$43/100)*'Main table'!E$9*'Main table'!E$22/100 -> 0.14019557 | G15: ='Main table'!F$7/100*(1-'Main table'!F$43/100)*'Main table'!F$9*'Main table'!F$22/100 -> 0.1606124 | H15: ='Main table'!G$7/100*(1-'Main table'!G$43/100)*'Main table'!G$9*'Main table'!G$22/100 -> 0.15853068 | I15: ='Main table'!H$7/100*(1-'Main table'!H$43/100)*'Main table'!H$9*'Main table'!H$22/100 -> 0.15805028 | J15: ='Main table'!I$7/100*(1-'Main table'!I$43/100)*'Main table'!I$9*'Main table'!I$22/100 -> 0.14988355 | K15: ='Main table'!J$7/100*(1-'Main table'!J$43/100)*'Main table'!J$9*'Main table'!J$22/100 -> 0 | ... BU15: ='Main table'!BT$7/100*(1-'Main table'!BT$43/100)*'Main table'!BT$9*'Main table'!BT$22/100 -> 0
A16: Pig Breeding | B16: Tot Feed, kg | C16: -1 | D16: =1-'Main table'!C$43/100 -> 0.931 | E16: =1-'Main table'!D$43/100 -> 0.931 | F16: =1-'Main table'!E$43/100 -> 0.931 | G16: =1-'Main table'!F$43/100 -> 0.931 | H16: =1-'Main table'!G$43/100 -> 0.931 | I16: =1-'Main table'!H$43/100 -> 0.931 | J16: =1-'Main table'!I$43/100 -> 0.931 | K16: =1-'Main table'!J$43/100 -> 1 | ... BU16: =1-'Main table'!BT$43/100 -> 1
A17: Pig Breeding | B17: NE, MJ/kg | C17: 1 | D17: ='Main table'!C$7/100*(1-'Main table'!C$43/100)*'Main table'!C$30 -> 9.687986 | E17: ='Main table'!D$7/100*(1-'Main table'!D$43/100)*'Main table'!D$30 -> 9.447788 | F17: ='Main table'!E$7/100*(1-'Main table'!E$43/100)*'Main table'!E$30 -> 9.047458 | G17: ='Main table'!F$7/100*(1-'Main table'!F$43/100)*'Main table'!F$30 -> 8.887326 | H17: ='Main table'!G$7/100*(1-'Main table'!G$43/100)*'Main table'!G$30 -> 7.286006 | I17: ='Main table'!H$7/100*(1-'Main table'!H$43/100)*'Main table'!H$30 -> 10.328514 | J17: ='Main table'!I$7/100*(1-'Main table'!I$43/100)*'Main table'!I$30 -> 9.527854 | K17: ='Main table'!J$7/100*(1-'Main table'!J$43/100)*'Main table'!J$30 -> 0 | ... BU17: ='Main table'!BT$7/100*(1-'Main table'!BT$43/100)*'Main table'!BT$30 -> 0
A18: Pig Breeding | B18: Digestible CP, % | C18: 1 | D18: ='Main table'!C$7/100*(1-'Main table'!C$43/100)*'Main table'!C$9*'Main table'!C$31/100 -> 8.4237439 | E18: ='Main table'!D$7/100*(1-'Main table'!D$43/100)*'Main table'!D$9*'Main table'!D$31/100 -> 10.766875 | F18: ='Main table'!E$7/100*(1-'Main table'!E$43/100)*'Main table'!E$9*'Main table'!E$31/100 -> 5.8469798 | G18: ='Main table'!F$7/100*(1-'Main table'!F$43/100)*'Main table'!F$9*'Main table'!F$31/100 -> 7.1992145 | H18: ='Main table'!G$7/100*(1-'Main table'!G$43/100)*'Main table'!G$9*'Main table'!G$31/100 -> 6.6847103 | I18: ='Main table'!H$7/100*(1-'Main table'!H$43/100)*'Main table'!H$9*'Main table'!H$31/100 -> 6.0811728 | J18: ='Main table'!I$7/100*(1-'Main table'!I$43/100)*'Main table'!I$9*'Main table'!I$31/100 -> 7.8595188 | K18: ='Main table'!J$7/100*(1-'Main table'!J$43/100)*'Main table'!J$9*'Main table'!J$31/100 -> 0 | ... BU18: ='Main table'!BT$7/100*(1-'Main table'!BT$43/100)*'Main table'!BT$9*'Main table'!BT$31/100 -> 0
A19: Pig Breeding | B19: Lysine, %CP | C19: 1 | D19: ='Main table'!C$7/100*(1-'Main table'!C$43/100)*'Main table'!C$9*'Main table'!C$21/100 -> 0.29256116 | E19: ='Main table'!D$7/100*(1-'Main table'!D$43/100)*'Main table'!D$9*'Main table'!D$21/100 -> 0.3442838 | F19: ='Main table'!E$7/100*(1-'Main table'!E$43/100)*'Main table'!E$9*'Main table'!E$21/100 -> 0.32162512 | G19: ='Main table'!F$7/100*(1-'Main table'!F$43/100)*'Main table'!F$9*'Main table'!F$21/100 -> 0.34956816 | H19: ='Main table'!G$7/100*(1-'Main table'!G$43/100)*'Main table'!G$9*'Main table'!G$21/100 -> 0.37871218 | I19: ='Main table'!H$7/100*(1-'Main table'!H$43/100)*'Main table'!H$9*'Main table'!H$21/100 -> 0.23331232 | J19: ='Main table'!I$7/100*(1-'Main table'!I$43/100)*'Main table'!I$9*'Main table'!I$21/100 -> 0.32787027 | K19: ='Main table'!J$7/100*(1-'Main table'!J$43/100)*'Main table'!J$9*'Main table'!J$21/100 -> 0 | ... BU19: ='Main table'!BT$7/100*(1-'Main table'!BT$43/100)*'Main table'!BT$9*'Main table'!BT$21/100 -> 0.257556
A20: Pig Breeding | B20: Metheonine, % | C20: 1 | D20: ='Main table'!C$7/100*(1-'Main table'!C$43/100)*'Main table'!C$9*'Main table'!C$22/100 -> 0.16141306 | E20: ='Main table'!D$7/100*(1-'Main table'!D$43/100)*'Main table'!D$9*'Main table'!D$22/100 -> 0.20881213 | F20: ='Main table'!E$7/100*(1-'Main table'!E$43/100)*'Main table'!E$9*'Main table'!E$22/100 -> 0.14019557 | G20: ='Main table'!F$7/100*(1-'Main table'!F$43/100)*'Main table'!F$9*'Main table'!F$22/100 -> 0.1606124 | H20: ='Main table'!G$7/100*(1-'Main table'!G$43/100)*'Main table'!G$9*'Main table'!G$22/100 -> 0.15853068 | I20: ='Main table'!H$7/100*(1-'Main table'!H$43/100)*'Main table'!H$9*'Main table'!H$22/100 -> 0.15805028 | J20: ='Main table'!I$7/100*(1-'Main table'!I$43/100)*'Main table'!I$9*'Main table'!I$22/100 -> 0.14988355 | K20: ='Main table'!J$7/100*(1-'Main table'!J$43/100)*'Main table'!J$9*'Main table'!J$22/100 -> 0 | ... BU20: ='Main table'!BT$7/100*(1-'Main table'!BT$43/100)*'Main table'!BT$9*'Main table'!BT$22/100 -> 0
A21: Poultry Eggs | B21: Tot Feed, kg | C21: -1 | D21: =1-'Main table'!C$43/100 -> 0.931 | E21: =1-'Main table'!D$43/100 -> 0.931 | F21: =1-'Main table'!E$43/100 -> 0.931 | G21: =1-'Main table'!F$43/100 -> 0.931 | H21: =1-'Main table'!G$43/100 -> 0.931 | I21: =1-'Main table'!H$43/100 -> 0.931 | J21: =1-'Main table'!I$43/100 -> 0.931 | K21: =1-'Main table'!J$43/100 -> 1 | ... BU21: =1-'Main table'!BT$43/100 -> 1
A22: Poultry Eggs | B22: AMEn, MJ/kg | C22: 1 | D22: ='Main table'!C$7/100*(1-'Main table'!C$43/100)*'Main table'!C$36 -> 11.049108 | E22: ='Main table'!D$7/100*(1-'Main table'!D$43/100)*'Main table'!D$36 -> 11.049108 | F22: ='Main table'!E$7/100*(1-'Main table'!E$43/100)*'Main table'!E$36 -> 8.967392 | G22: ='Main table'!F$7/100*(1-'Main table'!F$43/100)*'Main table'!F$36 -> 9.047458 | H22: ='Main table'!G$7/100*(1-'Main table'!G$43/100)*'Main table'!G$36 -> 9.527854 | I22: ='Main table'!H$7/100*(1-'Main table'!H$43/100)*'Main table'!H$36 -> 12.089966 | J22: ='Main table'!I$7/100*(1-'Main table'!I$43/100)*'Main table'!I$36 -> 10.80891 | K22: ='Main table'!J$7/100*(1-'Main table'!J$43/100)*'Main table'!J$36 -> 0 | ... BU22: ='Main table'!BT$7/100*(1-'Main table'!BT$43/100)*'Main table'!BT$36 -> 0
A23: Poultry Eggs | B23: CP, % | C23: 1 | D23: ='Main table'!C$7/100*(1-'Main table'!C$43/100)*'Main table'!C$9 -> 10.088316 | E23: ='Main table'!D$7/100*(1-'Main table'!D$43/100)*'Main table'!D$9 -> 13.050758 | F23: ='Main table'!E$7/100*(1-'Main table'!E$43/100)*'Main table'!E$9 -> 8.246798 | G23: ='Main table'!F$7/100*(1-'Main table'!F$43/100)*'Main table'!F$9 -> 9.447788 | H23: ='Main table'!G$7/100*(1-'Main table'!G$43/100)*'Main table'!G$9 -> 8.80726 | I23: ='Main table'!H$7/100*(1-'Main table'!H$43/100)*'Main table'!H$9 -> 7.526204 | J23: ='Main table'!I$7/100*(1-'Main table'!I$43/100)*'Main table'!I$9 -> 9.367722 | K23: ='Main table'!J$7/100*(1-'Main table'!J$43/100)*'Main table'!J$9 -> 0 | ... BU23: ='Main table'!BT$7/100*(1-'Main table'!BT$43/100)*'Main table'!BT$9 -> 3.302
A24: Poultry Eggs | B24: Lysine, % | C24: 1 | D24: ='Main table'!C$7/100*(1-'Main table'!C$43/100)*'Main table'!C$9*'Main table'!C$21/100 -> 0.29256116 | E24: ='Main table'!D$7/100*(1-'Main table'!D$43/100)*'Main table'!D$9*'Main table'!D$21/100 -> 0.3442838 | F24: ='Main table'!E$7/100*(1-'Main table'!E$43/100)*'Main table'!E$9*'Main table'!E$21/100 -> 0.32162512 | G24: ='Main table'!F$7/100*(1-'Main table'!F$43/100)*'Main table'!F$9*'Main table'!F$21/100 -> 0.34956816 | H24: ='Main table'!G$7/100*(1-'Main table'!G$43/100)*'Main table'!G$9*'Main table'!G$21/100 -> 0.37871218 | I24: ='Main table'!H$7/100*(1-'Main table'!H$43/100)*'Main table'!H$9*'Main table'!H$21/100 -> 0.23331232 | J24: ='Main table'!I$7/100*(1-'Main table'!I$43/100)*'Main table'!I$9*'Main table'!I$21/100 -> 0.32787027 | K24: ='Main table'!J$7/100*(1-'Main table'!J$43/100)*'Main table'!J$9*'Main table'!J$21/100 -> 0 | ... BU24: ='Main table'!BT$7/100*(1-'Main table'!BT$43/100)*'Main table'!BT$9*'Main table'!BT$21/100 -> 0.257556
A25: Poultry Eggs | B25: Metheonine, % | C25: 1 | D25: ='Main table'!C$7/100*(1-'Main table'!C$43/100)*'Main table'!C$9*'Main table'!C$22/100 -> 0.16141306 | E25: ='Main table'!D$7/100*(1-'Main table'!D$43/100)*'Main table'!D$9*'Main table'!D$22/100 -> 0.20881213 | F25: ='Main table'!E$7/100*(1-'Main table'!E$43/100)*'Main table'!E$9*'Main table'!E$22/100 -> 0.14019557 | G25: ='Main table'!F$7/100*(1-'Main table'!F$43/100)*'Main table'!F$9*'Main table'!F$22/100 -> 0.1606124 | H25: ='Main table'!G$7/100*(1-'Main table'!G$43/100)*'Main table'!G$9*'Main table'!G$22/100 -> 0.15853068 | I25: ='Main table'!H$7/100*(1-'Main table'!H$43/100)*'Main table'!H$9*'Main table'!H$22/100 -> 0.15805028 | J25: ='Main table'!I$7/100*(1-'Main table'!I$43/100)*'Main table'!I$9*'Main table'!I$22/100 -> 0.14988355 | K25: ='Main table'!J$7/100*(1-'Main table'!J$43/100)*'Main table'!J$9*'Main table'!J$22/100 -> 0 | ... BU25: ='Main table'!BT$7/100*(1-'Main table'!BT$43/100)*'Main table'!BT$9*'Main table'!BT$22/100 -> 0
A26: Poultry Fattening | B26: Tot Feed, kg | C26: -1 | D26: =1-'Main table'!C$43/100 -> 0.931 | E26: =1-'Main table'!D$43/100 -> 0.931 | F26: =1-'Main table'!E$43/100 -> 0.931 | G26: =1-'Main table'!F$43/100 -> 0.931 | H26: =1-'Main table'!G$43/100 -> 0.931 | I26: =1-'Main table'!H$43/100 -> 0.931 | J26: =1-'Main table'!I$43/100 -> 0.931 | K26: =1-'Main table'!J$43/100 -> 1 | ... BU26: =1-'Main table'!BT$43/100 -> 1
A27: Poultry Fattening | B27: AMEn, MJ/kg | C27: 1 | D27: ='Main table'!C$7/100*(1-'Main table'!C$43/100)*'Main table'!C$36 -> 11.049108 | E27: ='Main table'!D$7/100*(1-'Main table'!D$43/100)*'Main table'!D$36 -> 11.049108 | F27: ='Main table'!E$7/100*(1-'Main table'!E$43/100)*'Main table'!E$36 -> 8.967392 | G27: ='Main table'!F$7/100*(1-'Main table'!F$43/100)*'Main table'!F$36 -> 9.047458 | H27: ='Main table'!G$7/100*(1-'Main table'!G$43/100)*'Main table'!G$36 -> 9.527854 | I27: ='Main table'!H$7/100*(1-'Main table'!H$43/100)*'Main table'!H$36 -> 12.089966 | J27: ='Main table'!I$7/100*(1-'Main table'!I$43/100)*'Main table'!I$36 -> 10.80891 | K27: ='Main table'!J$7/100*(1-'Main table'!J$43/100)*'Main table'!J$36 -> 0 | ... BU27: ='Main table'!BT$7/100*(1-'Main table'!BT$43/100)*'Main table'!BT$36 -> 0
A28: Poultry Fattening | B28: CP, % | C28: 1 | D28: ='Main table'!C$7/100*(1-'Main table'!C$43/100)*'Main table'!C$9 -> 10.088316 | E28: ='Main table'!D$7/100*(1-'Main table'!D$43/100)*'Main table'!D$9 -> 13.050758 | F28: ='Main table'!E$7/100*(1-'Main table'!E$43/100)*'Main table'!E$9 -> 8.246798 | G28: ='Main table'!F$7/100*(1-'Main table'!F$43/100)*'Main table'!F$9 -> 9.447788 | H28: ='Main table'!G$7/100*(1-'Main table'!G$43/100)*'Main table'!G$9 -> 8.80726 | I28: ='Main table'!H$7/100*(1-'Main table'!H$43/100)*'Main table'!H$9 -> 7.526204 | J28: ='Main table'!I$7/100*(1-'Main table'!I$43/100)*'Main table'!I$9 -> 9.367722 | K28: ='Main table'!J$7/100*(1-'Main table'!J$43/100)*'Main table'!J$9 -> 0 | ... BU28: ='Main table'!BT$7/100*(1-'Main table'!BT$43/100)*'Main table'!BT$9 -> 3.302
A29: Poultry Fattening | B29: Lysine, % | C29: 1 | D29: ='Main table'!C$7/100*(1-'Main table'!C$43/100)*'Main table'!C$9*'Main table'!C$21/100 -> 0.29256116 | E29: ='Main table'!D$7/100*(1-'Main table'!D$43/100)*'Main table'!D$9*'Main table'!D$21/100 -> 0.3442838 | F29: ='Main table'!E$7/100*(1-'Main table'!E$43/100)*'Main table'!E$9*'Main table'!E$21/100 -> 0.32162512 | G29: ='Main table'!F$7/100*(1-'Main table'!F$43/100)*'Main table'!F$9*'Main table'!F$21/100 -> 0.34956816 | H29: ='Main table'!G$7/100*(1-'Main table'!G$43/100)*'Main table'!G$9*'Main table'!G$21/100 -> 0.37871218 | I29: ='Main table'!H$7/100*(1-'Main table'!H$43/100)*'Main table'!H$9*'Main table'!H$21/100 -> 0.23331232 | J29: ='Main table'!I$7/100*(1-'Main table'!I$43/100)*'Main table'!I$9*'Main table'!I$21/100 -> 0.32787027 | K29: ='Main table'!J$7/100*(1-'Main table'!J$43/100)*'Main table'!J$9*'Main table'!J$21/100 -> 0 | ... BU29: ='Main table'!BT$7/100*(1-'Main table'!BT$43/100)*'Main table'!BT$9*'Main table'!BT$21/100 -> 0.257556
A30: Poultry Fattening | B30: Metheonine, % | C30: 1 | D30: ='Main table'!C$7/100*(1-'Main table'!C$43/100)*'Main table'!C$9*'Main table'!C$22/100 -> 0.16141306 | E30: ='Main table'!D$7/100*(1-'Main table'!D$43/100)*'Main table'!D$9*'Main table'!D$22/100 -> 0.20881213 | F30: ='Main table'!E$7/100*(1-'Main table'!E$43/100)*'Main table'!E$9*'Main table'!E$22/100 -> 0.14019557 | G30: ='Main table'!F$7/100*(1-'Main table'!F$43/100)*'Main table'!F$9*'Main table'!F$22/100 -> 0.1606124 | H30: ='Main table'!G$7/100*(1-'Main table'!G$43/100)*'Main table'!G$9*'Main table'!G$22/100 -> 0.15853068 | I30: ='Main table'!H$7/100*(1-'Main table'!H$43/100)*'Main table'!H$9*'Main table'!H$22/100 -> 0.15805028 | J30: ='Main table'!I$7/100*(1-'Main table'!I$43/100)*'Main table'!I$9*'Main table'!I$22/100 -> 0.14988355 | K30: ='Main table'!J$7/100*(1-'Main table'!J$43/100)*'Main table'!J$9*'Main table'!J$22/100 -> 0 | ... BU30: ='Main table'!BT$7/100*(1-'Main table'!BT$43/100)*'Main table'!BT$9*'Main table'!BT$22/100 -> 0
A32: Not used
A33: Dairy Cows | B33: Fibre max, % | C33: 0.9 | D33: ='Main table'!C7/100*'Main table'!C10 -> 2.236 | E33: ='Main table'!D7/100*'Main table'!D10 -> 2.58 | F33: ='Main table'!E7/100*'Main table'!E10 -> 1.892 | G33: ='Main table'!F7/100*'Main table'!F10 -> 4.472 | H33: ='Main table'!G7/100*'Main table'!G10 -> 11.954 | I33: ='Main table'!H7/100*'Main table'!H10 -> 2.15 | J33: ='Main table'!I7/100*'Main table'!I10 -> 2.322 | K33: ='Main table'!J7/100*'Main table'!J10 -> 0 | ... BU33: ='Main table'!BT7/100*'Main table'!BT10 -> 0
A34: Dairy Cows | B34: Fibre min, % | C34: -1.1 | D34: ='Main table'!C7/100*'Main table'!C10 -> 2.236 | E34: ='Main table'!D7/100*'Main table'!D10 -> 2.58 | F34: ='Main table'!E7/100*'Main table'!E10 -> 1.892 | G34: ='Main table'!F7/100*'Main table'!F10 -> 4.472 | H34: ='Main table'!G7/100*'Main table'!G10 -> 11.954 | I34: ='Main table'!H7/100*'Main table'!H10 -> 2.15 | J34: ='Main table'!I7/100*'Main table'!I10 -> 2.322 | K34: ='Main table'!J7/100*'Main table'!J10 -> 0 | ... BU34: ='Main table'!BT7/100*'Main table'!BT10 -> 0
A35: Other Cattle and Buffalo | B35: Fibre max, % | C35: 0.9 | D35: ='Main table'!C7/100*'Main table'!C10 -> 2.236 | E35: ='Main table'!D7/100*'Main table'!D10 -> 2.58 | F35: ='Main table'!E7/100*'Main table'!E10 -> 1.892 | G35: ='Main table'!F7/100*'Main table'!F10 -> 4.472 | H35: ='Main table'!G7/100*'Main table'!G10 -> 11.954 | I35: ='Main table'!H7/100*'Main table'!H10 -> 2.15 | J35: ='Main table'!I7/100*'Main table'!I10 -> 2.322 | K35: ='Main table'!J7/100*'Main table'!J10 -> 0 | ... BU35: ='Main table'!BT7/100*'Main table'!BT10 -> 0
A36: Other Cattle and Buffalo | B36: Fibre min, % | C36: -1.1 | D36: ='Main table'!C7/100*'Main table'!C10 -> 2.236 | E36: ='Main table'!D7/100*'Main table'!D10 -> 2.58 | F36: ='Main table'!E7/100*'Main table'!E10 -> 1.892 | G36: ='Main table'!F7/100*'Main table'!F10 -> 4.472 | H36: ='Main table'!G7/100*'Main table'!G10 -> 11.954 | I36: ='Main table'!H7/100*'Main table'!H10 -> 2.15 | J36: ='Main table'!I7/100*'Main table'!I10 -> 2.322 | K36: ='Main table'!J7/100*'Main table'!J10 -> 0 | ... BU36: ='Main table'!BT7/100*'Main table'!BT10 -> 0
A37: Sheep and Goat | B37: Fibre max, % | C37: 0.9 | D37: ='Main table'!C7/100*'Main table'!C10 -> 2.236 | E37: ='Main table'!D7/100*'Main table'!D10 -> 2.58 | F37: ='Main table'!E7/100*'Main table'!E10 -> 1.892 | G37: ='Main table'!F7/100*'Main table'!F10 -> 4.472 | H37: ='Main table'!G7/100*'Main table'!G10 -> 11.954 | I37: ='Main table'!H7/100*'Main table'!H10 -> 2.15 | J37: ='Main table'!I7/100*'Main table'!I10 -> 2.322 | K37: ='Main table'!J7/100*'Main table'!J10 -> 0 | ... BU37: ='Main table'!BT7/100*'Main table'!BT10 -> 0
A38: Sheep and Goat | B38: Fibre min, % | C38: -1.1 | D38: ='Main table'!C7/100*'Main table'!C10 -> 2.236 | E38: ='Main table'!D7/100*'Main table'!D10 -> 2.58 | F38: ='Main table'!E7/100*'Main table'!E10 -> 1.892 | G38: ='Main table'!F7/100*'Main table'!F10 -> 4.472 | H38: ='Main table'!G7/100*'Main table'!G10 -> 11.954 | I38: ='Main table'!H7/100*'Main table'!H10 -> 2.15 | J38: ='Main table'!I7/100*'Main table'!I10 -> 2.322 | K38: ='Main table'!J7/100*'Main table'!J10 -> 0 | ... BU38: ='Main table'!BT7/100*'Main table'!BT10 -> 0

Sheet in.feed_general.csv
