Workbook
Name Crop_data: 'N fert'!$A$6:$AA$118
Name Crop_data_codes: 'N fert'!$A$6:$A$118

Sheet N fert
A2: Nitrogen fertiliser per crop and country, kg per hectare
A4: Crops | F4: Afghanistan | G4: Albania | H4: Algeria | I4: Angola | J4: Antigua and Barbuda | K4: Argentina | L4: Armenia | M4: Australia | N4: Austria | O4: Azerbaijan | P4: Bahamas | Q4: Bahrain | R4: Bangladesh | S4: Barbados | T4: Belarus | U4: Belgium | V4: Belize | W4: Benin | X4: Bhutan | Y4: Bolivia | Z4: Bosnia and Herzegovina | AA4: Botswana | AB4: Brazil | AC4: Brunei Darussalam | AD4: Bulgaria | AE4: Burkina Faso | AF4: Burundi | AG4: Cabo Verde | AH4: Cambodia | AI4: Cameroon | AJ4: Canada | AK4: Central African Republic | AL4: Chad | AM4: Chile | AN4: China, Hong Kong SAR | AO4: China, Macao SAR | AP4: China, Taiwan Province of | AQ4: China, mainland | AR4: Colombia | AS4: Comoros | AT4: Congo | AU4: Cook Islands | AV4: Costa Rica | AW4: Croatia | AX4: Cuba | AY4: Cyprus | AZ4: Czechia | BA4: Côte d'Ivoire | BB4: Democratic People's Republic of Korea | BC4: Democratic Republic of the Congo | BD4: Denmark | BE4: Djibouti | BF4: Dominica | BG4: Dominican Republic | BH4: Ecuador | BI4: Egypt | BJ4: El Salvador | BK4: Equatorial Guinea | BL4: Eritrea | BM4: Estonia | BN4: Eswatini | BO4: Ethiopia | BP4: Faroe Islands | BQ4: Fiji | BR4: Finland | BS4: France | BT4: French Polynesia | BU4: Gabon | BV4: Gambia | BW4: Georgia | BX4: Germany | BY4: Ghana | BZ4: Greece | CA4: Grenada | CB4: Guatemala | CC4: Guinea | CD4: Guinea-Bissau | CE4: Guyana | CF4: Haiti | CG4: Honduras | CH4: Hungary | CI4: Iceland | CJ4: India | CK4: Indonesia | CL4: Iran | CM4: Iraq | CN4: Ireland | CO4: Israel | CP4: Italy | CQ4: Jamaica | CR4: Japan | CS4: Jordan | CT4: Kazakhstan | CU4: Kenya | CV4: Kiribati | CW4: Kuwait | CX4: Kyrgyzstan | CY4: Lao People's Democratic Republic | CZ4: Latvia | DA4: Lebanon | DB4: Lesotho | DC4: Liberia | DD4: Libya | DE4: Lithuania | DF4: Luxembourg | DG4: Madagascar | DH4: Malawi | DI4: Malaysia | DJ4: Maldives | DK4: Mali | DL4: Malta | DM4: Marshall Islands | DN4: Mauritania | DO4: Mauritius | DP4: Mexico | DQ4: Micronesia (Federated States of) | DR4: Mongolia | DS4: Montenegro | DT4: Morocco | DU4: Mozambique | DV4: Myanmar | DW4: Namibia | DX4: Nauru | DY4: Nepal | DZ4: Netherlands | EA4: New Caledonia | EB4: New Zealand | EC4: Nicaragua | ED4: Niger | EE4: Nigeria | EF4: Niue | EG4: North Macedonia | EH4: Norway | EI4: Oman | EJ4: Pakistan | EK4: Palestine | EL4: Panama | EM4: Papua New Guinea | EN4: Paraguay | EO4: Peru | EP4: Philippines | EQ4: Poland | ER4: Portugal | ES4: Puerto Rico | ET4: Qatar | EU4: Republic of Korea | EV4: Republic of Moldova | EW4: Romania | EX4: Russian Federation | EY4: Rwanda | EZ4: Saint Kitts and Nevis | FA4: Saint Lucia | FB4: Saint Vincent and the Grenadines | FC4: Samoa | FD4: Sao Tome and Principe | FE4: Saudi Arabia | FF4: Senegal | FG4: Serbia | FH4: Seychelles | FI4: Sierra Leone | FJ4: Singapore | FK4: Slovakia | FL4: Slovenia | FM4: Solomon Islands | FN4: Somalia | FO4: South Africa | FP4: South Sudan | FQ4: Spain | FR4: Sri Lanka | FS4: Sudan | FT4: Suriname | FU4: Sweden | FV4: Switzerland | FW4: Syrian Arab Republic | FX4: Tajikistan | FY4: Thailand | FZ4: Timor-Leste | GA4: Togo | GB4: Tonga | GC4: Trinidad and Tobago | GD4: Tunisia | GE4: Turkmenistan | GF4: Tuvalu | GG4: Türkiye | GH4: Uganda | GI4: Ukraine | GJ4: United Arab Emirates | GK4: United Kingdom of Great Britain and Northern Ireland | GL4: United Republic of Tanzania | GM4: United States of America | GN4: Uruguay | GO4: Uzbekistan | GP4: Vanuatu | GQ4: Venezuela | GR4: Viet Nam | GS4: Yemen | GT4: Zambia | GU4: Zimbabwe
A5: Crop code | B5: Crop | C5: Category | D5: Default | E5: Yield | F5: AF | G5: AL | H5: DZ | I5: AO | J5: AG | K5: AR | L5: AM | M5: AU | N5: AT | O5: AZ | P5: BS | Q5: BH | R5: BD | S5: BB | T5: BY | U5: BE | V5: BZ | W5: BJ | X5: BT | Y5: BO | Z5: BA | AA5: BW | AB5: BR | AC5: BN | AD5: BG | AE5: BF | AF5: BI | AG5: CV | AH5: KH | AI5: CM | AJ5: CA | AK5: CF | AL5: TD | AM5: CL | AN5: HK | AO5: MO | AP5: TW | AQ5: CN | AR5: CO | AS5: KM | AT5: CG | AU5: CK | AV5: CR | AW5: HR | AX5: CU | AY5: CY | AZ5: CZ | BA5: CI | BB5: KP | BC5: CD | BD5: DK | BE5: DJ | BF5: DM | BG5: DO | BH5: EC | BI5: EG | BJ5: SV | BK5: GQ | BL5: ER | BM5: EE | BN5: SZ | BO5: ET | BP5: FO | BQ5: FJ | BR5: FI | BS5: FR | BT5: PF | BU5: GA | BV5: GM | BW5: GE | BX5: DE | BY5: GH | BZ5: GR | CA5: GD | CB5: GT | CC5: GN | CD5: GW | CE5: GY | CF5: HT | CG5: HN | CH5: HU | CI5: IS | CJ5: IN | CK5: ID | CL5: IR | CM5: IQ | CN5: IE | CO5: IL | CP5: IT | CQ5: JM | CR5: JP | CS5: JO | CT5: KZ | CU5: KE | CV5: KI | CW5: KW | CX5: KG | CY5: LA | CZ5: LV | DA5: LB | DB5: LS | DC5: LR | DD5: LY | DE5: LT | DF5: LU | DG5: MG | DH5: MW | DI5: MY | DJ5: MV | DK5: ML | DL5: MT | DM5: MH | DN5: MR | DO5: MU | DP5: MX | DQ5: FM | DR5: MN | DS5: ME | DT5: MA | DU5: MZ | DV5: MM | DW5: NA | DX5: NR | DY5: NP | DZ5: NL | EA5: NC | EB5: NZ | EC5: NI | ED5: NE | EE5: NG | EF5: NU | EG5: MK | EH5: NO | EI5: OM | EJ5: PK | EK5: PS | EL5: PA | EM5: PG | EN5: PY | EO5: PE | EP5: PH | EQ5: PL | ER5: PT | ES5: PR | ET5: QA | EU5: KR | EV5: MD | EW5: RO | EX5: RU | EY5: RW | EZ5: KN | FA5: LC | FB5: VC | FC5: WS | FD5: ST | FE5: SA | FF5: SN | FG5: RS | FH5: SC | FI5: SL | FJ5: SG | FK5: SK | FL5: SI | FM5: SB | FN5: SO | FO5: ZA | FP5: SS | FQ5: ES | FR5: LK | FS5: SD | FT5: SR | FU5: SE | FV5: CH | FW5: SY | FX5: TJ | FY5: TH | FZ5: TL | GA5: TG | GB5: TO | GC5: TT | GD5: TN | GE5: TM | GF5: TV | GG5: TR | GH5: UG | GI5: UA | GJ5: AE | GK5: GB | GL5: TZ | GM5: US | GN5: UY | GO5: UZ | GP5: VU | GQ5: VE | GR5: VN | GS5: YE | GT5: ZM | GU5: ZW
A6: =Defaults!A6 -> 01371 | B6: =Defaults!B6 -> Almonds, in shell | C6: =Defaults!C6 -> Nuts | D6: 114 | E6: 1435
A7: =Defaults!A7 -> 01654 | B7: =Defaults!B7 -> Anise, badian, coriander, cumin, caraway, fennel and juniper berries, raw | C7: =Defaults!C7 -> Vegetables | D7: 170 | E7: 9000 | AD7: 22
A8: =Defaults!A8 -> 01341 | B8: =Defaults!B8 -> Apples | C8: =Defaults!C8 -> Fruits | D8: SE | E8: SE | FU8: 41.000997
A9: =Defaults!A9 -> 01343 | B9: =Defaults!B9 -> Apricots | C9: =Defaults!C9 -> Fruits | D9: Default-01341
A10: =Defaults!A10 -> 01216 | B10: =Defaults!B10 -> Artichokes | C10: =Defaults!C10 -> Vegetables | D10: Default-01251
A11: =Defaults!A11 -> 01211 | B11: =Defaults!B11 -> Asparagus | C11: =Defaults!C11 -> Vegetables | D11: SE | E11: SE | FU11: 20
A12: =Defaults!A12 -> 01311 | B12: =Defaults!B12 -> Avocados | C12: =Defaults!C12 -> Vegetables | D12: 136
A13: =Defaults!A13 -> 01312 | B13: =Defaults!B13 -> Bananas | C13: =Defaults!C13 -> Fruits | D13: 44 | AV13: 450
A14: =Defaults!A14 -> 0115 | B14: =Defaults!B14 -> Barley, average | C14: =Defaults!C14 -> Cereals, incl feed | D14: SE | E14: SE | FU14: 94
A15: =Defaults!A15 -> 0115_s | B15: =Defaults!B15 -> Barley, spring | C15: =Defaults!C15 -> Cereals | D15: SE | E15: SE | FU15: 90
A16: =Defaults!A16 -> 0115_w | B16: =Defaults!B16 -> Barley, winter | C16: =Defaults!C16 -> Cereals | D16: SE | E16: SE | FU16: 126
A17: =Defaults!A17 -> 01701 | B17: =Defaults!B17 -> Beans, dry | C17: =Defaults!C17 -> Pulses | D17: SE | E17: SE | FU17: 30
A18: =Defaults!A18 -> 01355.01 | B18: =Defaults!B18 -> Blueberries | C18: =Defaults!C18 -> Berries | D18: Default-01353.01
A19: =Defaults!A19 -> 01377 | B19: =Defaults!B19 -> Brazil nuts, in shell | C19: =Defaults!C19 -> Nuts
A20: =Defaults!A20 -> 01702 | B20: =Defaults!B20 -> Broad beans and horse beans, dry | C20: =Defaults!C20 -> Pulses, incl feed | D20: SE | E20: SE | FU20: 2
A21: =Defaults!A21 -> 01243 | B21: =Defaults!B21 -> Broad beans and horse beans, green | C21: =Defaults!C21 -> Vegetables | D21: Default-01702
A22: =Defaults!A22 -> 01213_b | B22: =Defaults!B22 -> Broccoli | C22: =Defaults!C22 -> Vegetables | FU22: 150
A23: =Defaults!A23 -> 01192 | B23: =Defaults!B23 -> Buckwheat | C23: =Defaults!C23 -> Seeds
A24: =Defaults!A24 -> 01212 | B24: =Defaults!B24 -> Cabbages | C24: =Defaults!C24 -> Vegetables | D24: SE | E24: SE | FU24: 200.00036
A25: =Defaults!A25 -> 01229 | B25: =Defaults!B25 -> Cantaloupes and other melons | C25: =Defaults!C25 -> Fruits | D25: ES | E25: ES | FQ25: 135
A26: =Defaults!A26 -> 01251 | B26: =Defaults!B26 -> Carrots and turnips | C26: =Defaults!C26 -> Vegetables | D26: SE | E26: SE | FU26: 83
A27: =Defaults!A27 -> 01372 | B27: =Defaults!B27 -> Cashew nuts, in shell | C27: =Defaults!C27 -> Nuts
A28: =Defaults!A28 -> 01213_cf | B28: =Defaults!B28 -> Cauliflowers | C28: =Defaults!C28 -> Vegetables | D28: SE | E28: SE | FU28: 220
A29: =Defaults!A29 -> 01213 | B29: =Defaults!B29 -> Cauliflowers and broccoli, average | C29: =Defaults!C29 -> Vegetables | D29: SE | E29: SE | FU29: 192
A30: =Defaults!A30 -> 01199.90 | B30: =Defaults!B30 -> Cereals n.e.c. | C30: =Defaults!C30 -> Cereals | D30: Default-0111
A31: =Defaults!A31 -> 01344.02 | B31: =Defaults!B31 -> Cherries | C31: =Defaults!C31 -> Berries | D31: Default-01353.01 | N31: 810
A32: =Defaults!A32 -> 01373 | B32: =Defaults!B32 -> Chestnuts, in shell | C32: =Defaults!C32 -> Nuts | D32: Default-01371
A33: =Defaults!A33 -> 01703 | B33: =Defaults!B33 -> Chick peas, dry | C33: =Defaults!C33 -> Pulses | D33: Default-01705
A34: =Defaults!A34 -> 01231 | B34: =Defaults!B34 -> Chillies and peppers, green (Capsicum spp. and Pimenta spp.), raw | C34: =Defaults!C34 -> Spices | D34: ES | E34: ES | FQ34: 260
A35: =Defaults!A35 -> 01640 | B35: =Defaults!B35 -> Cocoa beans | C35: =Defaults!C35 -> Stimulants
A36: =Defaults!A36 -> 01460 | B36: =Defaults!B36 -> Coconut, in shell | C36: =Defaults!C36 -> Nuts
A37: =Defaults!A37 -> 01610 | B37: =Defaults!B37 -> Coffee, green | C37: =Defaults!C37 -> Stimulants | D37: CR | E37: CR | AV37: 212
A38: =Defaults!A38 -> 01232 | B38: =Defaults!B38 -> Cucumbers and gherkins, averrage | C38: =Defaults!C38 -> Vegetables | FU38: 1385.8545
A39: =Defaults!A39 -> 01232_gh | B39: =Defaults!B39 -> Cucumbers and gherkins, greenhouse | C39: =Defaults!C39 -> Vegetables | D39: SE | E39: SE | FU39: 1451.4258
A40: =Defaults!A40 -> 01232_of | B40: =Defaults!B40 -> Cucumbers and gherkins, openfield | C40: =Defaults!C40 -> Vegetables | D40: SE | E40: SE | FU40: 140
A41: =Defaults!A41 -> 01351.01 | B41: =Defaults!B41 -> Currants | C41: =Defaults!C41 -> Berries | D41: SE | E41: SE | FU41: 32
A42: =Defaults!A42 -> 01314 | B42: =Defaults!B42 -> Dates | C42: =Defaults!C42 -> Fruits | D42: ES | E42: ES | FQ42: 34
...

Sheet N inst
A2: Instructions N mineral fertiliser
A4: Crop code | B4: Crop | C4: Category | D4: Default | E4: Yield
A5: 01371 | B5: Almonds, in shell | C5: Nuts | D5: 114 | E5: 1435 | H5: Scale default value 114 with the yield, ie 114/1435*yield for almond in country
A6: 01341 | B6: Apples | C6: Fruits | D6: SE | E6: SE | H6: Use Swedish value and scale with Swedish yield, if Yield left blank do not scale
A7: 01343 | B7: Apricots | C7: Fruits | D7: SE-01341 | E7: SE-01341 | G7: Behöv den här?? | H7: Use Swedish value for crop 01341 (apples), divide with Swedish apple yield and multiply with apricot yield for the country
A8: 01311 | B8: Avocados | C8: Vegetables | D8: 136 | H8: Use 136 without scaling
A9: 01229 | B9: Cantaloupes and other melons | C9: Fruits | D9: ES | E9: ES | H9: Use Spanish value and scale with Spanish yield, if Yield left blank do not scale
A10: 01373 | B10: Chestnuts, in shell | C10: Nuts | D10: Default-01371 | H10: Use Default value for crop 01371
A14: Crop code | B14: Crop | C14: Category | D14: Default | E14: Yield | F14: SE | G14: Resultat
A15: 01371 | B15: Almonds, in shell | C15: Nuts | D15: 114 | E15: 1435 | F15: 10
A16: 01341 | B16: Apples | C16: Fruits | D16: SE | E16: SE
A17: 01343 | B17: Apricots | C17: Fruits | D17: SE-01341 | E17: SE-01341
A18: 01311 | B18: Avocados | C18: Vegetables | D18: 136
A19: 01229 | B19: Cantaloupes and other melons | C19: Fruits | D19: ES | E19: ES
A20: 01373 | B20: Chestnuts, in shell | C20: Nuts | D20: Default-01371

Sheet N fert sources
A2: Nitrogen fertiliser per crop and country, kg per hectare
A4: Crops | E4: Afghanistan | F4: Albania | G4: Algeria | H4: Angola | I4: Antigua and Barbuda | J4: Argentina | K4: Armenia | L4: Australia | M4: Austria | N4: Azerbaijan | O4: Bahamas | P4: Bahrain | Q4: Bangladesh | R4: Barbados | S4: Belarus | T4: Belgium | U4: Belize | V4: Benin | W4: Bhutan | X4: Bolivia | Y4: Bosnia and Herzegovina | Z4: Botswana | AA4: Brazil | AB4: Brunei Darussalam | AC4: Bulgaria | AD4: Burkina Faso | AE4: Burundi | AF4: Cabo Verde | AG4: Cambodia | AH4: Cameroon | AI4: Canada | AJ4: Central African Republic | AK4: Chad | AL4: Chile | AM4: China | AN4: China, Hong Kong SAR | AO4: China, Macao SAR | AP4: China, Taiwan Province of | AQ4: China, mainland | AR4: Colombia | AS4: Comoros | AT4: Congo | AU4: Cook Islands | AV4: Costa Rica | AW4: Croatia | AX4: Cuba | AY4: Cyprus | AZ4: Czechia | BA4: Côte d'Ivoire | BB4: Democratic People's Republic of Korea | BC4: Democratic Republic of the Congo | BD4: Denmark | BE4: Djibouti | BF4: Dominica | BG4: Dominican Republic | BH4: Ecuador | BI4: Egypt | BJ4: El Salvador | BK4: Equatorial Guinea | BL4: Eritrea | BM4: Estonia | BN4: Eswatini | BO4: Ethiopia | BP4: Faroe Islands | BQ4: Fiji | BR4: Finland | BS4: France | BT4: French Polynesia | BU4: Gabon | BV4: Gambia | BW4: Georgia | BX4: Germany | BY4: Ghana | BZ4: Greece | CA4: Grenada | CB4: Guatemala | CC4: Guinea | CD4: Guinea-Bissau | CE4: Guyana | CF4: Haiti | CG4: Honduras | CH4: Hungary | CI4: Iceland | CJ4: India | CK4: Indonesia | CL4: Iran | CM4: Iraq | CN4: Ireland | CO4: Israel | CP4: Italy | CQ4: Jamaica | CR4: Japan | CS4: Jordan | CT4: Kazakhstan | CU4: Kenya | CV4: Kiribati | CW4: Kuwait | CX4: Kyrgyzstan | CY4: Lao People's Democratic Republic | CZ4: Latvia | DA4: Lebanon | DB4: Lesotho | DC4: Liberia | DD4: Libya | DE4: Lithuania | DF4: Luxembourg | DG4: Madagascar | DH4: Malawi | DI4: Malaysia | DJ4: Maldives | DK4: Mali | DL4: Malta | DM4: Marshall Islands | DN4: Mauritania | DO4: Mauritius | DP4: Mexico | DQ4: Micronesia (Federated States of) | DR4: Mongolia | DS4: Montenegro | DT4: Morocco | DU4: Mozambique | DV4: Myanmar | DW4: Namibia | DX4: Nauru | DY4: Nepal | DZ4: Netherlands | EA4: New Caledonia | EB4: New Zealand | EC4: Nicaragua | ED4: Niger | EE4: Nigeria | EF4: Niue | EG4: North Macedonia | EH4: Norway | EI4: Oman | EJ4: Pakistan | EK4: Palestine | EL4: Panama | EM4: Papua New Guinea | EN4: Paraguay | EO4: Peru | EP4: Philippines | EQ4: Poland | ER4: Portugal | ES4: Puerto Rico | ET4: Qatar | EU4: Republic of Korea | EV4: Republic of Moldova | EW4: Romania | EX4: Russian Federation | EY4: Rwanda | EZ4: Saint Kitts and Nevis | FA4: Saint Lucia | FB4: Saint Vincent and the Grenadines | FC4: Samoa | FD4: Sao Tome and Principe | FE4: Saudi Arabia | FF4: Senegal | FG4: Serbia | FH4: Seychelles | FI4: Sierra Leone | FJ4: Singapore | FK4: Slovakia | FL4: Slovenia | FM4: Solomon Islands | FN4: Somalia | FO4: South Africa | FP4: South Sudan | FQ4: Spain | FR4: Sri Lanka | FS4: Sudan | FT4: Suriname | FU4: Sweden | FV4: Switzerland | FW4: Syrian Arab Republic | FX4: Tajikistan | FY4: Thailand | FZ4: Timor-Leste | GA4: Togo | GB4: Tonga | GC4: Trinidad and Tobago | GD4: Tunisia | GE4: Turkmenistan | GF4: Tuvalu | GG4: Türkiye | GH4: Uganda | GI4: Ukraine | GJ4: United Arab Emirates | GK4: United Kingdom of Great Britain and Northern Ireland | GL4: United Republic of Tanzania | GM4: United States of America | GN4: Uruguay | GO4: Uzbekistan | GP4: Vanuatu | GQ4: Venezuela | GR4: Viet Nam | GS4: Yemen | GT4: Zambia | GU4: Zimbabwe
A5: Crop code | B5: Crop | C5: Category | D5: Default | E5: AF | F5: AL | G5: DZ | H5: AO | I5: AG | J5: AR | K5: AM | L5: AU | M5: AT | N5: AZ | O5: BS | P5: BH | Q5: BD | R5: BB | S5: BY | T5: BE | U5: BZ | V5: BJ | W5: BT | X5: BO | Y5: BA | Z5: BW | AA5: BR | AB5: BN | AC5: BG | AD5: BF | AE5: BI | AF5: CV | AG5: KH | AH5: CM | AI5: CA | AJ5: CF | AK5: TD | AL5: CL | AM5: CN | AN5: HK | AO5: MO | AP5: TW | AQ5: CN | AR5: CO | AS5: KM | AT5: CG | AU5: CK | AV5: CR | AW5: HR | AX5: CU | AY5: CY | AZ5: CZ | BA5: CI | BB5: KP | BC5: CD | BD5: DK | BE5: DJ | BF5: DM | BG5: DO | BH5: EC | BI5: EG | BJ5: SV | BK5: GQ | BL5: ER | BM5: EE | BN5: SZ | BO5: ET | BP5: FO | BQ5: FJ | BR5: FI | BS5: FR | BT5: PF | BU5: GA | BV5: GM | BW5: GE | BX5: DE | BY5: GH | BZ5: GR | CA5: GD | CB5: GT | CC5: GN | CD5: GW | CE5: GY | CF5: HT | CG5: HN | CH5: HU | CI5: IS | CJ5: IN | CK5: ID | CL5: IR | CM5: IQ | CN5: IE | CO5: IL | CP5: IT | CQ5: JM | CR5: JP | CS5: JO | CT5: KZ | CU5: KE | CV5: KI | CW5: KW | CX5: KG | CY5: LA | CZ5: LV | DA5: LB | DB5: LS | DC5: LR | DD5: LY | DE5: LT | DF5: LU | DG5: MG | DH5: MW | DI5: MY | DJ5: MV | DK5: ML | DL5: MT | DM5: MH | DN5: MR | DO5: MU | DP5: MX | DQ5: FM | DR5: MN | DS5: ME | DT5: MA | DU5: MZ | DV5: MM | DW5: NA | DX5: NR | DY5: NP | DZ5: NL | EA5: NC | EB5: NZ | EC5: NI | ED5: NE | EE5: NG | EF5: NU | EG5: MK | EH5: NO | EI5: OM | EJ5: PK | EK5: PS | EL5: PA | EM5: PG | EN5: PY | EO5: PE | EP5: PH | EQ5: PL | ER5: PT | ES5: PR | ET5: QA | EU5: KR | EV5: MD | EW5: RO | EX5: RU | EY5: RW | EZ5: KN | FA5: LC | FB5: VC | FC5: WS | FD5: ST | FE5: SA | FF5: SN | FG5: RS | FH5: SC | FI5: SL | FJ5: SG | FK5: SK | FL5: SI | FM5: SB | FN5: SO | FO5: ZA | FP5: SS | FQ5: ES | FR5: LK | FS5: SD | FT5: SR | FU5: SE | FV5: CH | FW5: SY | FX5: TJ | FY5: TH | FZ5: TL | GA5: TG | GB5: TO | GC5: TT | GD5: TN | GE5: TM | GF5: TV | GG5: TR | GH5: UG | GI5: UA | GJ5: AE | GK5: GB | GL5: TZ | GM5: US | GN5: UY | GO5: UZ | GP5: VU | GQ5: VE | GR5: VN | GS5: YE | GT5: ZM | GU5: ZW
A6: =Defaults!A6 -> 01371 | B6: =Defaults!B6 -> Almonds, in shell | C6: =Defaults!C6 -> Nuts | D6: Ecoinvent version 3.6 (2019), "Almond production, RoW" (incl yield), oklar skalning | L6: Ecoinvent version 3.6 (2019), "Almond production, RoW" (incl yield), oklar skalning
A7: =Defaults!A7 -> 01654 | B7: =Defaults!B7 -> Anise, badian, coriander, cumin, caraway, fennel and juniper berries, raw | C7: =Defaults!C7 -> Vegetables | AC7: Landqvist and Woodhouse, 2015, oklar skalning
A8: =Defaults!A8 -> 01341 | B8: =Defaults!B8 -> Apples | C8: =Defaults!C8 -> Fruits
A9: =Defaults!A9 -> 01343 | B9: =Defaults!B9 -> Apricots | C9: =Defaults!C9 -> Fruits
A10: =Defaults!A10 -> 01216 | B10: =Defaults!B10 -> Artichokes | C10: =Defaults!C10 -> Vegetables
A11: =Defaults!A11 -> 01211 | B11: =Defaults!B11 -> Asparagus | C11: =Defaults!C11 -> Vegetables
A12: =Defaults!A12 -> 01311 | B12: =Defaults!B12 -> Avocados | C12: =Defaults!C12 -> Vegetables
A13: =Defaults!A13 -> 01312 | B13: =Defaults!B13 -> Bananas | C13: =Defaults!C13 -> Fruits | AV13: International Fertilizer Industry Association et al. (2002)
A14: =Defaults!A14 -> 0115 | B14: =Defaults!B14 -> Barley, average | C14: =Defaults!C14 -> Cereals, incl feed
A15: =Defaults!A15 -> 0115_s | B15: =Defaults!B15 -> Barley, spring | C15: =Defaults!C15 -> Cereals
A16: =Defaults!A16 -> 0115_w | B16: =Defaults!B16 -> Barley, winter | C16: =Defaults!C16 -> Cereals
A17: =Defaults!A17 -> 01701 | B17: =Defaults!B17 -> Beans, dry | C17: =Defaults!C17 -> Pulses
A18: =Defaults!A18 -> 01355.01 | B18: =Defaults!B18 -> Blueberries | C18: =Defaults!C18 -> Berries
A19: =Defaults!A19 -> 01377 | B19: =Defaults!B19 -> Brazil nuts, in shell | C19: =Defaults!C19 -> Nuts
A20: =Defaults!A20 -> 01702 | B20: =Defaults!B20 -> Broad beans and horse beans, dry | C20: =Defaults!C20 -> Pulses, incl feed
A21: =Defaults!A21 -> 01243 | B21: =Defaults!B21 -> Broad beans and horse beans, green | C21: =Defaults!C21 -> Vegetables
A22: =Defaults!A22 -> 01213_b | B22: =Defaults!B22 -> Broccoli | C22: =Defaults!C22 -> Vegetables
A23: =Defaults!A23 -> 01192 | B23: =Defaults!B23 -> Buckwheat | C23: =Defaults!C23 -> Seeds
A24: =Defaults!A24 -> 01212 | B24: =Defaults!B24 -> Cabbages | C24: =Defaults!C24 -> Vegetables
A25: =Defaults!A25 -> 01229 | B25: =Defaults!B25 -> Cantaloupes and other melons | C25: =Defaults!C25 -> Fruits
... A30: =Defaults!A30 -> 01199.90 | B30: =Defaults!B30 -> Cereals n.e.c. | C30: =Defaults!C30 -> Cereals
A31: =Defaults!A31 -> 01344.02 | B31: =Defaults!B31 -> Cherries | C31: =Defaults!C31 -> Berries | M31: Approx SE raspberries
A32: =Defaults!A32 -> 01373 | B32: =Defaults!B32 -> Chestnuts, in shell | C32: =Defaults!C32 -> Nuts
A33: =Defaults!A33 -> 01703 | B33: =Defaults!B33 -> Chick peas, dry | C33: =Defaults!C33 -> Pulses | D33: approx pea
A34: =Defaults!A34 -> 01231 | B34: =Defaults!B34 -> Chillies and peppers, green (Capsicum spp. and Pimenta spp.), raw | C34: =Defaults!C34 -> Spices
A35: =Defaults!A35 -> 01640 | B35: =Defaults!B35 -> Cocoa beans | C35: =Defaults!C35 -> Stimulants | AV35: Castro-Tanzi et al. 2012, Costa Rica
A36: =Defaults!A36 -> 01460 | B36: =Defaults!B36 -> Coconut, in shell | C36: =Defaults!C36 -> Nuts
A37: =Defaults!A37 -> 01610 | B37: =Defaults!B37 -> Coffee, green | C37: =Defaults!C37 -> Stimulants
A38: =Defaults!A38 -> 01232 | B38: =Defaults!B38 -> Cucumbers and gherkins, averrage | C38: =Defaults!C38 -> Vegetables
A39: =Defaults!A39 -> 01232_gh | B39: =Defaults!B39 -> Cucumbers and gherkins, greenhouse | C39: =Defaults!C39 -> Vegetables
A40: =Defaults!A40 -> 01232_of | B40: =Defaults!B40 -> Cucumbers and gherkins, openfield | C40: =Defaults!C40 -> Vegetables
A41: =Defaults!A41 -> 01351.01 | B41: =Defaults!B41 -> Currants | C41: =Defaults!C41 -> Berries
A42: =Defaults!A42 -> 01314 | B42: =Defaults!B42 -> Dates | C42: =Defaults!C42 -> Fruits
A43: =Defaults!A43 -> 01599.10 | B43: =Defaults!B43 -> Edible roots and tubers with high starch or inulin content, n.e.c., fresh | C43: =Defaults!C43 -> Roots
A44: =Defaults!A44 -> 01233 | B44: =Defaults!B44 -> Eggplants (aubergines) | C44: =Defaults!C44 -> Vegetables
A45: =Defaults!A45 -> 01315 | B45: =Defaults!B45 -> Figs | C45: =Defaults!C45 -> Fruits
A46: =Defaults!A46 -> 01351.02 | B46: =Defaults!B46 -> Gooseberries | C46: =Defaults!C46 -> Berries
...

Sheet README
A2: Introduction to the dataset
A4: This is a dataset that includes input data for calculating the environmental footprints.
A6: Fertilisers

Sheet Diesel
A2: Diesel use per hectare and country
E3: Afghanistan | F3: Albania | G3: Algeria | H3: American Samoa | I3: Andorra | J3: Angola | K3: Anguilla | L3: Antarcticaâ€Š[b] | M3: Antigua and Barbuda | N3: Argentina | O3: Armenia | P3: Aruba | Q3: Australia | R3: Australiaâ€Š[c] | S3: Austria | T3: Azerbaijan | U3: Bahamas (the) | V3: Bahamas | W3: Bahrain | X3: Bangladesh | Y3: Barbados | Z3: Belarus | AA3: Belgium | AB3: Belize | AC3: Benin | AD3: Bermuda | AE3: Bhutan | AF3: Bolivia (Plurinational State of) | AG3: Bolivia | AH3: BonaireÂ Sint EustatiusÂ Saba | AI3: Bosnia and Herzegovina | AJ3: Botswana | AK3: Bouvet Island | AL3: Brazil | AM3: British Indian Ocean Territory (the) | AN3: Brunei Darussalam | AO3: Brunei Darussalamâ€Š[f] | AP3: Bulgaria | AQ3: Burkina Faso | AR3: Burundi | AS3: Cabo Verde | AT3: Cabo Verdeâ€Š[g] | AU3: Cambodia | AV3: Cameroon | AW3: Canada | AX3: Cayman Islands (the) | AY3: Central African Republic (the) | AZ3: Central African Republic | BA3: Chad | BB3: Chile | BC3: China | BD3: China, Hong Kong SAR | BE3: China, Macao SAR | BF3: China, Taiwan Province of | BG3: China, mainland | BH3: Christmas Island | BI3: Cocos (Keeling) Islands (the) | BJ3: Colombia | BK3: Comoros (the) | BL3: Comoros | BM3: Congo (the Democratic Republic of the) | BN3: Congo (the)â€Š[h] | BO3: Congo | BP3: Cook Islands (the) | BQ3: Cook Islands | BR3: Costa Rica | BS3: Cote d'Ivoire | BT3: Croatia | BU3: Cuba | BV3: CuraÃ§ao | BW3: Cyprus | BX3: Czechia | BY3: Czechiaâ€Š[j] | BZ3: CÃ´te d'Ivoire | CA3: Democratic People's Republic of Korea | CB3: Democratic Republic of the Congo | CC3: Denmark | CD3: Djibouti | CE3: Dominica | CF3: Dominican Republic (the) | CG3: Dominican Republic | CH3: Ecuador | CI3: Egypt | CJ3: El Salvador | CK3: Equatorial Guinea | CL3: Eritrea | CM3: Estonia | CN3: Eswatini | CO3: Eswatiniâ€Š[k] | CP3: Ethiopia | CQ3: Falkland Islands (the) [Malvinas]â€Š[l] | CR3: Faroe Islands (the) | CS3: Faroe Islands | CT3: Fiji | CU3: Finland | CV3: France | CW3: Franceâ€Š[m] | CX3: French Guiana | CY3: French Polynesia | CZ3: French Southern Territories (the)â€Š[n] | DA3: Gabon | DB3: Gambia (the) | DC3: Gambia | DD3: Georgia | DE3: Germany | DF3: Ghana | DG3: Gibraltar | DH3: Greece | DI3: Greenland | DJ3: Grenada | DK3: Guadeloupe | DL3: Guam | DM3: Guatemala | DN3: Guernsey | DO3: Guinea | DP3: Guinea-Bissau | DQ3: Guyana | DR3: Haiti | DS3: Heard Island and McDonald Islands | DT3: Holy See (the)â€Š[o] | DU3: Honduras | DV3: Hong Kong | DW3: Hungary | DX3: Iceland | DY3: India | DZ3: Indonesia | EA3: Iran (Islamic Republic of) | EB3: Iran | EC3: Iraq | ED3: Ireland | EE3: Isle of Man | EF3: Israel | EG3: Italy | EH3: Jamaica | EI3: Japan | EJ3: Jersey | EK3: Jordan | EL3: Kazakhstan | EM3: Kenya | EN3: Kiribati | EO3: Korea (the Democratic People's Republic of)â€Š[p] | EP3: Korea (the Republic of)â€Š[q] | EQ3: Kuwait | ER3: Kyrgyzstan | ES3: Lao People's Democratic Republic (the)â€Š[r] | ET3: Lao People's Democratic Republic | EU3: Latvia | EV3: Lebanon | EW3: Lesotho | EX3: Liberia | EY3: Libya | EZ3: Liechtenstein | FA3: Lithuania | FB3: Luxembourg | FC3: Macaoâ€Š[s] | FD3: Madagascar | FE3: Malawi | FF3: Malaysia | FG3: Maldives | FH3: Mali | FI3: Malta | FJ3: Marshall Islands (the) | FK3: Marshall Islands | FL3: Martinique | FM3: Mauritania | FN3: Mauritius | FO3: Mayotte | FP3: Mexico | FQ3: Micronesia (Federated States of) | FR3: Moldova (the Republic of) | FS3: Monaco | FT3: Mongolia | FU3: Montenegro | FV3: Montserrat | FW3: Morocco | FX3: Mozambique | FY3: Myanmar | FZ3: Namibia | GA3: Nauru | GB3: Nepal | GC3: Netherlands (Kingdom of the) | GD3: Netherlands Antilles (former) | GE3: Netherlands | GF3: Netherlands, Kingdom of the | GG3: New Caledonia | GH3: New Zealand | GI3: Nicaragua | GJ3: Niger (the) | GK3: Niger | GL3: Nigeria | GM3: Niue | GN3: Norfolk Island | GO3: North Macedonia | GP3: North Macedoniaâ€Š[t] | GQ3: Northern Mariana Islands (the) | GR3: Norway | GS3: Oman | GT3: Pakistan | GU3: Palau | GV3: Palestine | GW3: Palestine, State of | GX3: Panama | GY3: Papua New Guinea | GZ3: Paraguay | HA3: Peru | HB3: Philippines (the) | HC3: Philippines | HD3: Pitcairnâ€Š[v] | HE3: Poland | HF3: Portugal | HG3: Puerto Rico | HH3: Qatar | HI3: Republic of Korea | HJ3: Republic of Moldova | HK3: Romania | HL3: Russia | HM3: Russian Federation (the) | HN3: Russian Federation | HO3: Rwanda | HP3: RÃ©union | HQ3: Saint BarthÃ©lemy | HR3: Saint HelenaÂ Ascension IslandÂ Tristan da Cunha | HS3: Saint Kitts and Nevis | HT3: Saint Lucia | HU3: Saint Martin (French part) | HV3: Saint Pierre and Miquelon | HW3: Saint Vincent and the Grenadines | HX3: Samoa | HY3: San Marino | HZ3: Sao Tome and Principe | IA3: Saudi Arabia | IB3: Senegal | IC3: Serbia | ID3: Seychelles | IE3: Sierra Leone | IF3: Singapore | IG3: Sint Maarten (Dutch part) | IH3: Slovakia | II3: Slovenia | IJ3: Solomon Islands | IK3: Somalia | IL3: South Africa | IM3: South Georgia and the South Sandwich Islands | IN3: South Sudan | IO3: Spain | IP3: Sri Lanka | IQ3: Sudan (the) | IR3: Sudan | IS3: Suriname | IT3: SvalbardÂ Jan Mayen | IU3: Sweden | IV3: Switzerland | IW3: Syrian Arab Republic (the)â€Š[y] | IX3: Syrian Arab Republic | IY3: Taiwan (Province of China)â€Š[z] | IZ3: Tajikistan | JA3: Tanzania, the United Republic of | JB3: Thailand | JC3: Timor-Leste | JD3: Timor-Lesteâ€Š[ab] | JE3: Togo | JF3: Tokelau | JG3: Tonga | JH3: Trinidad and Tobago | JI3: Tunisia | JJ3: Turkey | JK3: Turkmenistan | JL3: Turks and Caicos Islands (the) | JM3: Tuvalu | JN3: TÃ¼rkiye [ac] | JO3: TÃ¼rkiye | JP3: UK | JQ3: USA | JR3: Uganda | JS3: Ukraine | JT3: United Arab Emirates (the) | JU3: United Arab Emirates | JV3: United Kingdom of Great Britain and Northern Ireland (the) | JW3: United Kingdom of Great Britain and Northern Ireland | JX3: United Kingdom | JY3: United Republic of Tanzania | JZ3: United States Minor Outlying Islands (the)â€Š[ae] | KA3: United States of America (the) | KB3: United States of America | KC3: Uruguay | KD3: Uzbekistan | KE3: Vanuatu | KF3: Venezuela (Bolivarian Republic of) | KG3: Viet Nam | KH3: Viet Namâ€Š[ag] | KI3: Virgin Islands (British)â€Š[ah] | KJ3: Virgin Islands (U.S.)â€Š[ai] | KK3: Wallis and Futuna | KL3: Western Saharaâ€Š[aj] | KM3: Yemen | KN3: Zambia | KO3: Zimbabwe | KP3: Ã…land Islands
A4: Crops
A5: Crop code | B5: Crop | C5: Category | D5: Default | E5: AF | F5: AL | G5: DZ | H5: AS | I5: AD | J5: AO | K5: AI | L5: AQ | M5: AG | N5: AR | O5: AM | P5: AW | Q5: AU | R5: AU | S5: AT | T5: AZ | U5: BS | V5: BS | W5: BH | X5: BD | Y5: BB | Z5: BY | AA5: BE | AB5: BZ | AC5: BJ | AD5: BM | AE5: BT | AF5: BO | AG5: BO | AH5: BQ | AI5: BA | AJ5: BW | AK5: BV | AL5: BR | AM5: IO | AN5: BN | AO5: BN | AP5: BG | AQ5: BF | AR5: BI | AS5: CV | AT5: CV | AU5: KH | AV5: CM | AW5: CA | AX5: KY | AY5: CF | AZ5: CF | BA5: TD | BB5: CL | BC5: CN | BD5: HK | BE5: MO | BF5: TW | BG5: CN | BH5: CX | BI5: CC | BJ5: CO | BK5: KM | BL5: KM | BM5: CD | BN5: CG | BO5: CG | BP5: CK | BQ5: CK | BR5: CR | BS5: CI | BT5: HR | BU5: CU | BV5: CW | BW5: CY | BX5: CZ | BY5: CZ | BZ5: CI | CA5: KP | CB5: CD | CC5: DK | CD5: DJ | CE5: DM | CF5: DO | CG5: DO | CH5: EC | CI5: EG | CJ5: SV | CK5: GQ | CL5: ER | CM5: EE | CN5: SZ | CO5: SZ | CP5: ET | CQ5: FK | CR5: FO | CS5: FO | CT5: FJ | CU5: FI | CV5: FR | CW5: FR | CX5: GF | CY5: PF | CZ5: TF | DA5: GA | DB5: GM | DC5: GM | DD5: GE | DE5: DE | DF5: GH | DG5: GI | DH5: GR | DI5: GL | DJ5: GD | DK5: GP | DL5: GU | DM5: GT | DN5: GG | DO5: GN | DP5: GW | DQ5: GY | DR5: HT | DS5: HM | DT5: VA | DU5: HN | DV5: HK | DW5: HU | DX5: IS | DY5: IN | DZ5: ID | EA5: IR | EB5: IR | EC5: IQ | ED5: IE | EE5: IM | EF5: IL | EG5: IT | EH5: JM | EI5: JP | EJ5: JE | EK5: JO | EL5: KZ | EM5: KE | EN5: KI | EO5: KP | EP5: KR | EQ5: KW | ER5: KG | ES5: LA | ET5: LA | EU5: LV | EV5: LB | EW5: LS | EX5: LR | EY5: LY | EZ5: LI | FA5: LT | FB5: LU | FC5: MO | FD5: MG | FE5: MW | FF5: MY | FG5: MV | FH5: ML | FI5: MT | FJ5: MH | FK5: MH | FL5: MQ | FM5: MR | FN5: MU | FO5: YT | FP5: MX | FQ5: FM | FR5: MD | FS5: MC | FT5: MN | FU5: ME | FV5: MS | FW5: MA | FX5: MZ | FY5: MM | FZ5: NA | GA5: NR | GB5: NP | GC5: NL | GD5: NL | GE5: NL | GF5: NL | GG5: NC | GH5: NZ | GI5: NI | GJ5: NE | GK5: NE | GL5: NG | GM5: NU | GN5: NF | GO5: MK | GP5: MK | GQ5: MP | GR5: NO | GS5: OM | GT5: PK | GU5: PW | GV5: PL | GW5: PS | GX5: PA | GY5: PG | GZ5: PY | HA5: PE | HB5: PH | HC5: PH | HD5: PN | HE5: PL | HF5: PT | HG5: PR | HH5: QA | HI5: KR | HJ5: MD | HK5: RO | HL5: RU | HM5: RU | HN5: RU | HO5: RW | HP5: RE | HQ5: BL | HR5: SH | HS5: KN | HT5: LC | HU5: MF | HV5: PM | HW5: VC | HX5: WS | HY5: SM | HZ5: ST | IA5: SA | IB5: SN | IC5: RS | ID5: SC | IE5: SL | IF5: SG | IG5: SX | IH5: SK | II5: SI | IJ5: SB | IK5: SO | IL5: ZA | IM5: GS | IN5: SS | IO5: ES | IP5: LK | IQ5: SD | IR5: SD | IS5: SR | IT5: SJ | IU5: SE | IV5: CH | IW5: SY | IX5: SY | IY5: TW | IZ5: TJ | JA5: TZ | JB5: TH | JC5: TL | JD5: TL | JE5: TG | JF5: TK | JG5: TO | JH5: TT | JI5: TN | JJ5: TR | JK5: TM | JL5: TC | JM5: TV | JN5: TR | JO5: TR | JP5: GB | JQ5: US | JR5: UG | JS5: UA | JT5: AE | JU5: AE | JV5: GB | JW5: GB | JX5: GB | JY5: TZ | JZ5: UM | KA5: US | KB5: US | KC5: UY | KD5: UZ | KE5: VU | KF5: VE | KG5: VN | KH5: VN | KI5: VG | KJ5: VI | KK5: WF | KL5: EH | KM5: YE | KN5: ZM | KO5: ZW | KP5: AX
A6: =Defaults!A6 -> 01371 | B6: =Defaults!B6 -> Almonds, in shell | C6: =Defaults!C6 -> Nuts
A7: =Defaults!A7 -> 01654 | B7: =Defaults!B7 -> Anise, badian, coriander, cumin, caraway, fennel and juniper berries, raw | C7: =Defaults!C7 -> Vegetables
A8: =Defaults!A8 -> 01341 | B8: =Defaults!B8 -> Apples | C8: =Defaults!C8 -> Fruits | D8: 450
A9: =Defaults!A9 -> 01343 | B9: =Defaults!B9 -> Apricots | C9: =Defaults!C9 -> Fruits | H9: Afghanistan
A10: =Defaults!A10 -> 01216 | B10: =Defaults!B10 -> Artichokes | C10: =Defaults!C10 -> Vegetables | H10: Albania
A11: =Defaults!A11 -> 01211 | B11: =Defaults!B11 -> Asparagus | C11: =Defaults!C11 -> Vegetables | D11: 140 | H11: Algeria
A12: =Defaults!A12 -> 01311 | B12: =Defaults!B12 -> Avocados | C12: =Defaults!C12 -> Vegetables | H12: American Samoa
A13: =Defaults!A13 -> 01312 | B13: =Defaults!B13 -> Bananas | C13: =Defaults!C13 -> Fruits | H13: Andorra
A14: =Defaults!A14 -> 0115 | B14: =Defaults!B14 -> Barley, average | C14: =Defaults!C14 -> Cereals, incl feed | D14: 69.7 | H14: Angola
A15: =Defaults!A15 -> 0115_s | B15: =Defaults!B15 -> Barley, spring | C15: =Defaults!C15 -> Cereals | D15: 70 | H15: Anguilla
A16: =Defaults!A16 -> 0115_w | B16: =Defaults!B16 -> Barley, winter | C16: =Defaults!C16 -> Cereals | D16: 66.7 | H16: Antarctica
A17: =Defaults!A17 -> 01701 | B17: =Defaults!B17 -> Beans, dry | C17: =Defaults!C17 -> Pulses | D17: 65 | H17: Antigua and Barbuda
A18: =Defaults!A18 -> 01355.01 | B18: =Defaults!B18 -> Blueberries | C18: =Defaults!C18 -> Berries | H18: Argentina
A19: =Defaults!A19 -> 01377 | B19: =Defaults!B19 -> Brazil nuts, in shell | C19: =Defaults!C19 -> Nuts | H19: Armenia
A20: =Defaults!A20 -> 01702 | B20: =Defaults!B20 -> Broad beans and horse beans, dry | C20: =Defaults!C20 -> Pulses, incl feed | D20: 63.2 | H20: Aruba
A21: =Defaults!A21 -> 01243 | B21: =Defaults!B21 -> Broad beans and horse beans, green | C21: =Defaults!C21 -> Vegetables | H21: Australia
A22: =Defaults!A22 -> 01213_b | B22: =Defaults!B22 -> Broccoli | C22: =Defaults!C22 -> Vegetables | D22: 140 | H22: Australia
A23: =Defaults!A23 -> 01192 | B23: =Defaults!B23 -> Buckwheat | C23: =Defaults!C23 -> Seeds | H23: Austria
A24: =Defaults!A24 -> 01212 | B24: =Defaults!B24 -> Cabbages | C24: =Defaults!C24 -> Vegetables | D24: 140 | H24: Azerbaijan
A25: =Defaults!A25 -> 01229 | B25: =Defaults!B25 -> Cantaloupes and other melons | C25: =Defaults!C25 -> Fruits | H25: Bahamas
A26: =Defaults!A26 -> 01251 | B26: =Defaults!B26 -> Carrots and turnips | C26: =Defaults!C26 -> Vegetables | D26: 140 | H26: Bahamas
A27: =Defaults!A27 -> 01372 | B27: =Defaults!B27 -> Cashew nuts, in shell | C27: =Defaults!C27 -> Nuts | H27: Bahrain
A28: =Defaults!A28 -> 01213_cf | B28: =Defaults!B28 -> Cauliflowers | C28: =Defaults!C28 -> Vegetables | D28: 140 | H28: Bangladesh
A29: =Defaults!A29 -> 01213 | B29: =Defaults!B29 -> Cauliflowers and broccoli, average | C29: =Defaults!C29 -> Vegetables | D29: 140 | H29: Barbados
A30: =Defaults!A30 -> 01199.90 | B30: =Defaults!B30 -> Cereals n.e.c. | C30: =Defaults!C30 -> Cereals | H30: Belarus
A31: =Defaults!A31 -> 01344.02 | B31: =Defaults!B31 -> Cherries | C31: =Defaults!C31 -> Berries | H31: Belgium
A32: =Defaults!A32 -> 01373 | B32: =Defaults!B32 -> Chestnuts, in shell | C32: =Defaults!C32 -> Nuts | H32: Belize
A33: =Defaults!A33 -> 01703 | B33: =Defaults!B33 -> Chick peas, dry | C33: =Defaults!C33 -> Pulses | H33: Benin
A34: =Defaults!A34 -> 01231 | B34: =Defaults!B34 -> Chillies and peppers, green (Capsicum spp. and Pimenta spp.), raw | C34: =Defaults!C34 -> Spices | H34: Bermuda
A35: =Defaults!A35 -> 01640 | B35: =Defaults!B35 -> Cocoa beans | C35: =Defaults!C35 -> Stimulants | H35: Bhutan
A36: =Defaults!A36 -> 01460 | B36: =Defaults!B36 -> Coconut, in shell | C36: =Defaults!C36 -> Nuts | H36: Bolivia (Plurinational State of)
A37: =Defaults!A37 -> 01610 | B37: =Defaults!B37 -> Coffee, green | C37: =Defaults!C37 -> Stimulants | H37: Bolivia
A38: =Defaults!A38 -> 01232 | B38: =Defaults!B38 -> Cucumbers and gherkins, averrage | C38: =Defaults!C38 -> Vegetables | D38: 7 | H38: Bonaire Sint Eustatius Saba
A39: =Defaults!A39 -> 01232_gh | B39: =Defaults!B39 -> Cucumbers and gherkins, greenhouse | C39: =Defaults!C39 -> Vegetables | D39: 0 | H39: Bosnia and Herzegovina
A40: =Defaults!A40 -> 01232_of | B40: =Defaults!B40 -> Cucumbers and gherkins, openfield | C40: =Defaults!C40 -> Vegetables | D40: 140 | H40: Botswana
A41: =Defaults!A41 -> 01351.01 | B41: =Defaults!B41 -> Currants | C41: =Defaults!C41 -> Berries | D41: 300 | H41: Bouvet Island
...

Sheet Att göra
A2: Se över gödsel till baljväxter, nu är det inkonsekvant, tex chick peas har noll
A3: Special Other
A4: Sen i R-skriptet, ta bort allt som inte finns med i Kastner

Sheet Share of GH system

Sheet EF 
E2: Länder
A3: min fer co2
A4: min fer ch4
A8: el co2
A12: N20 direkt
A13: N20 indirekt

Sheet Crop residues
A1: EF
A3: Antingen 7 rader för varje gröda eller bara ha med det som skuljer mellan grödor och hårdkoda det andra.

Sheet Argentina
A2: Inputs per hectare, Argentina
A4: Crops | F4: Nutrient inputs | I4: Energy | J4: Pesticides | K4: Nutrient inputs | N4: Energy | O4: Pesticides
A5: Crop code | B5: Crop | C5: Category | D5: Grown in country | E5: Share | F5: Min N fertiliser, kg N/ha | G5: N fixation, kg N/ha | H5: Min P fertiliser, kg P/ha | I5: Diesel use, l/ha | J5: Pesticide use, kg a.i./ha | K5: Mineral N fertiliser, kg N/ha | L5: N fixation, kg N/ha | M5: Min P fertilier, kg P/ha | N5: Diesel use, l/ha | O5: Pesticide use, kg a.i./ha
A6: =Defaults!A6 -> 01371 | B6: =Defaults!B6 -> Almonds, in shell | C6: =Defaults!C6 -> Nuts | D6: No
A7: =Defaults!A7 -> 01654 | B7: =Defaults!B7 -> Anise, badian, coriander, cumin, caraway, fennel and juniper berries, raw | C7: =Defaults!C7 -> Vegetables | D7: No
A8: =Defaults!A8 -> 01341 | B8: =Defaults!B8 -> Apples | C8: =Defaults!C8 -> Fruits | D8: Yes | I8: =Defaults!F8 -> 450 | J8: 10.56 | K8: SBA, 2004 | M8: SBA, 2004
A9: =Defaults!A9 -> 01343 | B9: =Defaults!B9 -> Apricots | C9: =Defaults!C9 -> Fruits | D9: No
A10: =Defaults!A10 -> 01216 | B10: =Defaults!B10 -> Artichokes | C10: =Defaults!C10 -> Vegetables | D10: No
A11: =Defaults!A11 -> 01211 | B11: =Defaults!B11 -> Asparagus | C11: =Defaults!C11 -> Vegetables | D11: No | K11: Jensen, 2013 | M11: Jensen, 2013
A12: =Defaults!A12 -> 01311 | B12: =Defaults!B12 -> Avocados | C12: =Defaults!C12 -> Vegetables | D12: No
A13: =Defaults!A13 -> 01312 | B13: =Defaults!B13 -> Bananas | C13: =Defaults!C13 -> Fruits | D13: No
A14: =Defaults!A14 -> 0115 | B14: =Defaults!B14 -> Barley, average | C14: =Defaults!C14 -> Cereals, incl feed | D14: No
A15: =Defaults!A15 -> 0115_s | B15: =Defaults!B15 -> Barley, spring | C15: =Defaults!C15 -> Cereals | D15: No | K15: SS, 2020 | M15: SS, 2020
A16: =Defaults!A16 -> 0115_w | B16: =Defaults!B16 -> Barley, winter | C16: =Defaults!C16 -> Cereals | D16: No | K16: SS, 2020 | M16: SS, 2020
A17: =Defaults!A17 -> 01701 | B17: =Defaults!B17 -> Beans, dry | C17: =Defaults!C17 -> Pulses | D17: Yes | I17: =Defaults!F17 -> 65 | J17: =Defaults!G17 -> 1.1 | K17: Tidåker et al., 2021 | M17: Tidåker et al, 2021
A18: =Defaults!A18 -> 01355.01 | B18: =Defaults!B18 -> Blueberries | C18: =Defaults!C18 -> Berries | D18: No
A19: =Defaults!A19 -> 01377 | B19: =Defaults!B19 -> Brazil nuts, in shell | C19: =Defaults!C19 -> Nuts | D19: No
A20: =Defaults!A20 -> 01702 | B20: =Defaults!B20 -> Broad beans and horse beans, dry | C20: =Defaults!C20 -> Pulses, incl feed | D20: No | I20: =Defaults!F20 -> 63.2 | J20: =Defaults!G20 -> 0.61 | K20: SS, 2020 | M20: SS 2020
A21: =Defaults!A21 -> 01243 | B21: =Defaults!B21 -> Broad beans and horse beans, green | C21: =Defaults!C21 -> Vegetables | D21: No
A22: =Defaults!A22 -> 01213_b | B22: =Defaults!B22 -> Broccoli | C22: =Defaults!C22 -> Vegetables | D22: No | I22: =Defaults!F22 -> 140 | J22: =Defaults!G22 -> 1.65 | K22: Marmolin & Björkholm, n.d., Björkholm, A-M., pers. comm. (2019) | M22: Marmolin & Björkholm, n.d., Björkholm, A-M., pers. comm. (2019)
A23: =Defaults!A23 -> 01192 | B23: =Defaults!B23 -> Buckwheat | C23: =Defaults!C23 -> Seeds | D23: No
A24: =Defaults!A24 -> 01212 | B24: =Defaults!B24 -> Cabbages | C24: =Defaults!C24 -> Vegetables | D24: No | I24: =Defaults!F24 -> 140 | J24: =Defaults!G24 -> 1.65 | K24: Marmolin & Björkholm, n.d., Björkholm, A-M., pers. comm. (2019) | M24: Marmolin & Björkholm, n.d., Björkholm, A-M., pers. comm. (2019)
A25: =Defaults!A25 -> 01229 | B25: =Defaults!B25 -> Cantaloupes and other melons | C25: =Defaults!C25 -> Fruits | D25: No
A26: =Defaults!A26 -> 01251 | B26: =Defaults!B26 -> Carrots and turnips | C26: =Defaults!C26 -> Vegetables | D26: No | I26: =Defaults!F26 -> 140 | J26: =Defaults!G26 -> 2.23 | K26: Marmolin & Björkholm, n.d. | M26: Marmolin & Björkholm, n.d.
A27: =Defaults!A27 -> 01372 | B27: =Defaults!B27 -> Cashew nuts, in shell | C27: =Defaults!C27 -> Nuts | D27: No
A28: =Defaults!A28 -> 01213_cf | B28: =Defaults!B28 -> Cauliflowers | C28: =Defaults!C28 -> Vegetables | D28: No | I28: =Defaults!F28 -> 140 | J28: =Defaults!G28 -> 1.65 | K28: Marmolin & Björkholm, n.d., Björkholm, A-M., pers. comm. (2019) | M28: Marmolin & Björkholm, n.d., Björkholm, A-M., pers. comm. (2019)
A29: =Defaults!A29 -> 01213 | B29: =Defaults!B29 -> Cauliflowers and broccoli, average | C29: =Defaults!C29 -> Vegetables | D29: No | I29: =Defaults!F29 -> 140 | J29: =Defaults!G29 -> 1.65
A30: =Defaults!A30 -> 01199.90 | B30: =Defaults!B30 -> Cereals n.e.c. | C30: =Defaults!C30 -> Cereals | D30: No
A31: =Defaults!A31 -> 01344.02 | B31: =Defaults!B31 -> Cherries | C31: =Defaults!C31 -> Berries | D31: No
A32: =Defaults!A32 -> 01373 | B32: =Defaults!B32 -> Chestnuts, in shell | C32: =Defaults!C32 -> Nuts | D32: No
A33: =Defaults!A33 -> 01703 | B33: =Defaults!B33 -> Chick peas, dry | C33: =Defaults!C33 -> Pulses | D33: Yes
A34: =Defaults!A34 -> 01231 | B34: =Defaults!B34 -> Chillies and peppers, green (Capsicum spp. and Pimenta spp.), raw | C34: =Defaults!C34 -> Spices | D34: No
A35: =Defaults!A35 -> 01640 | B35: =Defaults!B35 -> Cocoa beans | C35: =Defaults!C35 -> Stimulants | D35: No
A36: =Defaults!A36 -> 01460 | B36: =Defaults!B36 -> Coconut, in shell | C36: =Defaults!C36 -> Nuts | D36: No
A37: =Defaults!A37 -> 01610 | B37: =Defaults!B37 -> Coffee, green | C37: =Defaults!C37 -> Stimulants | D37: No
A38: =Defaults!A38 -> 01232 | B38: =Defaults!B38 -> Cucumbers and gherkins, averrage | C38: =Defaults!C38 -> Vegetables | D38: No | I38: =Defaults!F38 -> 7 | J38: =Defaults!G38 -> 1.65
A39: =Defaults!A39 -> 01232_gh | B39: =Defaults!B39 -> Cucumbers and gherkins, greenhouse | C39: =Defaults!C39 -> Vegetables | D39: No | I39: =Defaults!F39 -> 0 | J39: =Defaults!G39 -> 1.65 | K39: Davis et al. 2011 | M39: Davis et al. (2011)
A40: =Defaults!A40 -> 01232_of | B40: =Defaults!B40 -> Cucumbers and gherkins, openfield | C40: =Defaults!C40 -> Vegetables | D40: No | I40: =Defaults!F40 -> 140 | J40: =Defaults!G40 -> 1.65 | K40: Marmolin & Björkholm, n.d., Björkholm, A-M., pers. comm. (2019) | M40: Marmolin & Björkholm, n.d., Björkholm, A-M., pers. comm. (2019)
A41: =Defaults!A41 -> 01351.01 | B41: =Defaults!B41 -> Currants | C41: =Defaults!C41 -> Berries | D41: No | I41: =Defaults!F41 -> 300 | J41: =Defaults!G41 -> 2.25 | K41: SBA, undated. | M41: SBA, undated.
A42: =Defaults!A42 -> 01314 | B42: =Defaults!B42 -> Dates | C42: =Defaults!C42 -> Fruits | D42: No
...

Sheet Blad4

Sheet Pesticides
A2: Pesticides per hectare and country
A4: Crops
A5: Crop code | B5: Crop | C5: Category | D5: Default | E5: AR | F5: AU | G5: AT | H5: BE | I5: BO | J5: BR | K5: BG
A6: =Defaults!A6 -> 01371 | B6: =Defaults!B6 -> Almonds, in shell | C6: =Defaults!C6 -> Nuts
A7: =Defaults!A7 -> 01654 | B7: =Defaults!B7 -> Anise, badian, coriander, cumin, caraway, fennel and juniper berries, raw | C7: =Defaults!C7 -> Vegetables
A8: =Defaults!A8 -> 01341 | B8: =Defaults!B8 -> Apples | C8: =Defaults!C8 -> Fruits
A9: =Defaults!A9 -> 01343 | B9: =Defaults!B9 -> Apricots | C9: =Defaults!C9 -> Fruits
A10: =Defaults!A10 -> 01216 | B10: =Defaults!B10 -> Artichokes | C10: =Defaults!C10 -> Vegetables
A11: =Defaults!A11 -> 01211 | B11: =Defaults!B11 -> Asparagus | C11: =Defaults!C11 -> Vegetables
A12: =Defaults!A12 -> 01311 | B12: =Defaults!B12 -> Avocados | C12: =Defaults!C12 -> Vegetables
A13: =Defaults!A13 -> 01312 | B13: =Defaults!B13 -> Bananas | C13: =Defaults!C13 -> Fruits
A14: =Defaults!A14 -> 0115 | B14: =Defaults!B14 -> Barley, average | C14: =Defaults!C14 -> Cereals, incl feed
A15: =Defaults!A15 -> 0115_s | B15: =Defaults!B15 -> Barley, spring | C15: =Defaults!C15 -> Cereals
A16: =Defaults!A16 -> 0115_w | B16: =Defaults!B16 -> Barley, winter | C16: =Defaults!C16 -> Cereals
A17: =Defaults!A17 -> 01701 | B17: =Defaults!B17 -> Beans, dry | C17: =Defaults!C17 -> Pulses
... A118: =Defaults!A118 -> 0111_w | B118: =Defaults!B118 -> Wheat, winter | C118: =Defaults!C118 -> Cereals

Sheet Pesticides sources
A2: Pesticides per hectare and country
A4: Crops
A5: Crop code | B5: Crop | C5: Category | D5: AR | E5: AU | F5: AT | G5: BE | H5: BO | I5: BR | J5: BG
A6: =Defaults!A6 -> 01371 | B6: =Defaults!B6 -> Almonds, in shell | C6: =Defaults!C6 -> Nuts
A7: =Defaults!A7 -> 01654 | B7: =Defaults!B7 -> Anise, badian, coriander, cumin, caraway, fennel and juniper berries, raw | C7: =Defaults!C7 -> Vegetables
A8: =Defaults!A8 -> 01341 | B8: =Defaults!B8 -> Apples | C8: =Defaults!C8 -> Fruits
A9: =Defaults!A9 -> 01343 | B9: =Defaults!B9 -> Apricots | C9: =Defaults!C9 -> Fruits
A10: =Defaults!A10 -> 01216 | B10: =Defaults!B10 -> Artichokes | C10: =Defaults!C10 -> Vegetables
A11: =Defaults!A11 -> 01211 | B11: =Defaults!B11 -> Asparagus | C11: =Defaults!C11 -> Vegetables
A12: =Defaults!A12 -> 01311 | B12: =Defaults!B12 -> Avocados | C12: =Defaults!C12 -> Vegetables
A13: =Defaults!A13 -> 01312 | B13: =Defaults!B13 -> Bananas | C13: =Defaults!C13 -> Fruits
A14: =Defaults!A14 -> 0115 | B14: =Defaults!B14 -> Barley, average | C14: =Defaults!C14 -> Cereals, incl feed
A15: =Defaults!A15 -> 0115_s | B15: =Defaults!B15 -> Barley, spring | C15: =Defaults!C15 -> Cereals
A16: =Defaults!A16 -> 0115_w | B16: =Defaults!B16 -> Barley, winter | C16: =Defaults!C16 -> Cereals
A17: =Defaults!A17 -> 01701 | B17: =Defaults!B17 -> Beans, dry | C17: =Defaults!C17 -> Pulses
... A118: =Defaults!A118 -> 0111_w | B118: =Defaults!B118 -> Wheat, winter | C118: =Defaults!C118 -> Cereals

Sheet Sweden
A2: Inputs per hectare, Sweden
A4: Crops | F4: Nutrient inputs | I4: Energy | J4: Pesticides | K4: Nutrient inputs | N4: Energy | O4: Pesticides
A5: Crop code | B5: Crop | C5: Category | D5: Grown in country | E5: Share | F5: Min N fertiliser, kg N/ha | G5: N fixation, kg N/ha | H5: Min P fertiliser, kg P/ha | I5: Diesel use, l/ha | J5: Pesticide use, kg a.i./ha | K5: Mineral N fertiliser, kg N/ha | L5: N fixation, kg N/ha | M5: Min P fertilier, kg P/ha | N5: Diesel use, l/ha | O5: Pesticide use, kg a.i./ha
A6: =Defaults!A6 -> 01371 | B6: =Defaults!B6 -> Almonds, in shell | C6: =Defaults!C6 -> Nuts | D6: =IF(ISBLANK(F6),"No","Yes") -> No
A7: =Defaults!A7 -> 01654 | B7: =Defaults!B7 -> Anise, badian, coriander, cumin, caraway, fennel and juniper berries, raw | C7: =Defaults!C7 -> Vegetables | D7: =IF(ISBLANK(F7),"No","Yes") -> No
A8: =Defaults!A8 -> 01341 | B8: =Defaults!B8 -> Apples | C8: =Defaults!C8 -> Fruits | D8: =IF(ISBLANK(F8),"No","Yes") -> Yes | F8: 41.000997 | H8: 6.0001459 | I8: =Defaults!F8 -> 450 | J8: =Defaults!G8 -> 5.97 | K8: SBA, 2004 | M8: SBA, 2004
A9: =Defaults!A9 -> 01343 | B9: =Defaults!B9 -> Apricots | C9: =Defaults!C9 -> Fruits | D9: =IF(ISBLANK(F9),"No","Yes") -> No
A10: =Defaults!A10 -> 01216 | B10: =Defaults!B10 -> Artichokes | C10: =Defaults!C10 -> Vegetables | D10: =IF(ISBLANK(F10),"No","Yes") -> No
A11: =Defaults!A11 -> 01211 | B11: =Defaults!B11 -> Asparagus | C11: =Defaults!C11 -> Vegetables | D11: =IF(ISBLANK(F11),"No","Yes") -> Yes | F11: 20 | H11: 4 | I11: =Defaults!F11 -> 140 | J11: =Defaults!G11 -> 1.65 | K11: Jensen, 2013 | M11: Jensen, 2013
A12: =Defaults!A12 -> 01311 | B12: =Defaults!B12 -> Avocados | C12: =Defaults!C12 -> Vegetables | D12: =IF(ISBLANK(F12),"No","Yes") -> No
A13: =Defaults!A13 -> 01312 | B13: =Defaults!B13 -> Bananas | C13: =Defaults!C13 -> Fruits | D13: =IF(ISBLANK(F13),"No","Yes") -> No
A14: =Defaults!A14 -> 0115 | B14: =Defaults!B14 -> Barley, average | C14: =Defaults!C14 -> Cereals, incl feed | D14: =IF(ISBLANK(F14),"No","Yes") -> Yes | F14: 94 | H14: 7 | I14: =Defaults!F14 -> 69.7 | J14: =Defaults!G14 -> 0.52
A15: =Defaults!A15 -> 0115_s | B15: =Defaults!B15 -> Barley, spring | C15: =Defaults!C15 -> Cereals | D15: =IF(ISBLANK(F15),"No","Yes") -> Yes | E15: =Defaults!D15 -> 90 | F15: 90 | H15: 7 | I15: =Defaults!F15 -> 70 | J15: =Defaults!G15 -> 0.47 | K15: SS, 2020 | M15: SS, 2020
A16: =Defaults!A16 -> 0115_w | B16: =Defaults!B16 -> Barley, winter | C16: =Defaults!C16 -> Cereals | D16: =IF(ISBLANK(F16),"No","Yes") -> Yes | E16: =Defaults!D16 -> 10 | F16: 126 | H16: 8 | I16: =Defaults!F16 -> 66.7 | J16: 1 | K16: SS, 2020 | M16: SS, 2020
A17: =Defaults!A17 -> 01701 | B17: =Defaults!B17 -> Beans, dry | C17: =Defaults!C17 -> Pulses | D17: =IF(ISBLANK(F17),"No","Yes") -> Yes | F17: 30 | G17: =Defaults!E17 -> 25 | H17: 10 | I17: =Defaults!F17 -> 65 | J17: =Defaults!G17 -> 1.1 | K17: Tidåker et al., 2021 | M17: Tidåker et al, 2021
A18: =Defaults!A18 -> 01355.01 | B18: =Defaults!B18 -> Blueberries | C18: =Defaults!C18 -> Berries | D18: =IF(ISBLANK(F18),"No","Yes") -> No
A19: =Defaults!A19 -> 01377 | B19: =Defaults!B19 -> Brazil nuts, in shell | C19: =Defaults!C19 -> Nuts | D19: =IF(ISBLANK(F19),"No","Yes") -> No
A20: =Defaults!A20 -> 01702 | B20: =Defaults!B20 -> Broad beans and horse beans, dry | C20: =Defaults!C20 -> Pulses, incl feed | D20: =IF(ISBLANK(F20),"No","Yes") -> Yes | F20: 2 | G20: =Defaults!E20 -> 24 | H20: 4 | I20: =Defaults!F20 -> 63.2 | J20: =Defaults!G20 -> 0.61 | K20: SS, 2020 | M20: SS 2020
A21: =Defaults!A21 -> 01243 | B21: =Defaults!B21 -> Broad beans and horse beans, green | C21: =Defaults!C21 -> Vegetables | D21: =IF(ISBLANK(F21),"No","Yes") -> No
A22: =Defaults!A22 -> 01213_b | B22: =Defaults!B22 -> Broccoli | C22: =Defaults!C22 -> Vegetables | D22: =IF(ISBLANK(F22),"No","Yes") -> Yes | E22: =Defaults!D22 -> 40 | F22: 150 | H22: 22.944752 | I22: =Defaults!F22 -> 140 | J22: =Defaults!G22 -> 1.65 | K22: Marmolin & Björkholm, n.d., Björkholm, A-M., pers. comm. (2019) | M22: Marmolin & Björkholm, n.d., Björkholm, A-M., pers. comm. (2019)
A23: =Defaults!A23 -> 01192 | B23: =Defaults!B23 -> Buckwheat | C23: =Defaults!C23 -> Seeds | D23: =IF(ISBLANK(F23),"No","Yes") -> No
A24: =Defaults!A24 -> 01212 | B24: =Defaults!B24 -> Cabbages | C24: =Defaults!C24 -> Vegetables | D24: =IF(ISBLANK(F24),"No","Yes") -> Yes | F24: 200.00036 | H24: 16.000029 | I24: =Defaults!F24 -> 140 | J24: =Defaults!G24 -> 1.65 | K24: Marmolin & Björkholm, n.d., Björkholm, A-M., pers. comm. (2019) | M24: Marmolin & Björkholm, n.d., Björkholm, A-M., pers. comm. (2019)
A25: =Defaults!A25 -> 01229 | B25: =Defaults!B25 -> Cantaloupes and other melons | C25: =Defaults!C25 -> Fruits | D25: =IF(ISBLANK(F25),"No","Yes") -> No
A26: =Defaults!A26 -> 01251 | B26: =Defaults!B26 -> Carrots and turnips | C26: =Defaults!C26 -> Vegetables | D26: =IF(ISBLANK(F26),"No","Yes") -> Yes | F26: 83 | H26: 29.746 | I26: =Defaults!F26 -> 140 | J26: =Defaults!G26 -> 2.23 | K26: Marmolin & Björkholm, n.d. | M26: Marmolin & Björkholm, n.d.
A27: =Defaults!A27 -> 01372 | B27: =Defaults!B27 -> Cashew nuts, in shell | C27: =Defaults!C27 -> Nuts | D27: =IF(ISBLANK(F27),"No","Yes") -> No
A28: =Defaults!A28 -> 01213_cf | B28: =Defaults!B28 -> Cauliflowers | C28: =Defaults!C28 -> Vegetables | D28: =IF(ISBLANK(F28),"No","Yes") -> Yes | E28: =Defaults!D28 -> 60 | F28: 220 | H28: 21.384 | I28: =Defaults!F28 -> 140 | J28: =Defaults!G28 -> 1.65 | K28: Marmolin & Björkholm, n.d., Björkholm, A-M., pers. comm. (2019) | M28: Marmolin & Björkholm, n.d., Björkholm, A-M., pers. comm. (2019)
A29: =Defaults!A29 -> 01213 | B29: =Defaults!B29 -> Cauliflowers and broccoli, average | C29: =Defaults!C29 -> Vegetables | D29: =IF(ISBLANK(F29),"No","Yes") -> Yes | F29: 192 | H29: 22 | I29: =Defaults!F29 -> 140 | J29: =Defaults!G29 -> 1.65
A30: =Defaults!A30 -> 01199.90 | B30: =Defaults!B30 -> Cereals n.e.c. | C30: =Defaults!C30 -> Cereals | D30: =IF(ISBLANK(F30),"No","Yes") -> No
A31: =Defaults!A31 -> 01344.02 | B31: =Defaults!B31 -> Cherries | C31: =Defaults!C31 -> Berries | D31: =IF(ISBLANK(F31),"No","Yes") -> No
A32: =Defaults!A32 -> 01373 | B32: =Defaults!B32 -> Chestnuts, in shell | C32: =Defaults!C32 -> Nuts | D32: =IF(ISBLANK(F32),"No","Yes") -> No
A33: =Defaults!A33 -> 01703 | B33: =Defaults!B33 -> Chick peas, dry | C33: =Defaults!C33 -> Pulses | D33: =IF(ISBLANK(F33),"No","Yes") -> No
A34: =Defaults!A34 -> 01231 | B34: =Defaults!B34 -> Chillies and peppers, green (Capsicum spp. and Pimenta spp.), raw | C34: =Defaults!C34 -> Spices | D34: =IF(ISBLANK(F34),"No","Yes") -> No
A35: =Defaults!A35 -> 01640 | B35: =Defaults!B35 -> Cocoa beans | C35: =Defaults!C35 -> Stimulants | D35: =IF(ISBLANK(F35),"No","Yes") -> No
A36: =Defaults!A36 -> 01460 | B36: =Defaults!B36 -> Coconut, in shell | C36: =Defaults!C36 -> Nuts | D36: =IF(ISBLANK(F36),"No","Yes") -> No
A37: =Defaults!A37 -> 01610 | B37: =Defaults!B37 -> Coffee, green | C37: =Defaults!C37 -> Stimulants | D37: =IF(ISBLANK(F37),"No","Yes") -> No
A38: =Defaults!A38 -> 01232 | B38: =Defaults!B38 -> Cucumbers and gherkins, averrage | C38: =Defaults!C38 -> Vegetables | D38: =IF(ISBLANK(F38),"No","Yes") -> Yes | E38: =Defaults!D38 -> 0 | F38: 1385.8545 | H38: 7 | I38: =Defaults!F38 -> 7 | J38: =Defaults!G38 -> 1.65
A39: =Defaults!A39 -> 01232_gh | B39: =Defaults!B39 -> Cucumbers and gherkins, greenhouse | C39: =Defaults!C39 -> Vegetables | D39: =IF(ISBLANK(F39),"No","Yes") -> Yes | E39: =Defaults!D39 -> 95 | F39: 1451.4258 | H39: 703.7216 | I39: =Defaults!F39 -> 0 | J39: =Defaults!G39 -> 1.65 | K39: Davis et al. 2011 | M39: Davis et al. (2011)
A40: =Defaults!A40 -> 01232_of | B40: =Defaults!B40 -> Cucumbers and gherkins, openfield | C40: =Defaults!C40 -> Vegetables | D40: =IF(ISBLANK(F40),"No","Yes") -> Yes | E40: =Defaults!D40 -> 5 | F40: 140 | H40: 36.184615 | I40: =Defaults!F40 -> 140 | J40: =Defaults!G40 -> 1.65 | K40: Marmolin & Björkholm, n.d., Björkholm, A-M., pers. comm. (2019) | M40: Marmolin & Björkholm, n.d., Björkholm, A-M., pers. comm. (2019)
A41: =Defaults!A41 -> 01351.01 | B41: =Defaults!B41 -> Currants | C41: =Defaults!C41 -> Berries | D41: =IF(ISBLANK(F41),"No","Yes") -> Yes | F41: 32 | H41: 20 | I41: =Defaults!F41 -> 300 | J41: =Defaults!G41 -> 2.25 | K41: SBA, undated. | M41: SBA, undated.
A42: =Defaults!A42 -> 01314 | B42: =Defaults!B42 -> Dates | C42: =Defaults!C42 -> Fruits | D42: =IF(ISBLANK(F42),"No","Yes") -> No
...

Sheet Defaults
A2: Default inputs per hectare
A4: Crops | E4: Nitrogen fixation | F4: Energy | G4: Pesticides | H4: Nitrogen fixation | I4: Energy | J4: Pesticides
A5: Crop code | B5: Crop | C5: Category | D5: Share | E5: N fixation, kg N/ha | F5: Diesel use, l/ha | G5: Pesticide use, kg a.i./ha | H5: N fixation, kg N/ha | I5: Diesel use, l/ha | J5: Pesticide use, kg a.i./ha
A6: 01371 | B6: Almonds, in shell | C6: Nuts
A7: 01654 | B7: Anise, badian, coriander, cumin, caraway, fennel and juniper berries, raw | C7: Vegetables
A8: 01341 | B8: Apples | C8: Fruits | F8: 450 | G8: 5.97 | I8: SBA, 2011 | J8: SS, 2022
A9: 01343 | B9: Apricots | C9: Fruits
A10: 01216 | B10: Artichokes | C10: Vegetables
A11: 01211 | B11: Asparagus | C11: Vegetables | F11: 140 | G11: 1.65 | I11: Baky et al., 2010, average for vegetables | J11: SS, 2022. Avg for vegetables
A12: 01311 | B12: Avocados | C12: Vegetables
A13: 01312 | B13: Bananas | C13: Fruits
A14: 0115 | B14: Barley, average | C14: Cereals, incl feed | F14: 69.7 | G14: 0.52
A15: 0115_s | B15: Barley, spring | C15: Cereals | D15: 90 | F15: 70 | G15: 0.47 | I15: Baky et al., 2010 | J15: SS, 2022
A16: 0115_w | B16: Barley, winter | C16: Cereals | D16: 10 | F16: 66.7 | G16: 1 | I16: Baky et al., 2010 | J16: SS, 2022
A17: 01701 | B17: Beans, dry | C17: Pulses | E17: 25 | F17: 65 | G17: 1.1 | H17: Tidåker et al., 2021 | I17: Tidåker et al, 2021, common bean conv | J17: Tidåker et al, 2021
A18: 01355.01 | B18: Blueberries | C18: Berries
A19: 01377 | B19: Brazil nuts, in shell | C19: Nuts
A20: 01702 | B20: Broad beans and horse beans, dry | C20: Pulses, incl feed | E20: 24 | F20: 63.2 | G20: 0.61 | H20: Lassaletta et al., 2014 | I20: Baky et al., 2010 | J20: SS, 2022
A21: 01243 | B21: Broad beans and horse beans, green | C21: Vegetables
A22: 01213_b | B22: Broccoli | C22: Vegetables | D22: 40 | F22: 140 | G22: 1.65 | I22: Baky et al., 2010 | J22: SS, 2022. Avg for vegetables
A23: 01192 | B23: Buckwheat | C23: Seeds
A24: 01212 | B24: Cabbages | C24: Vegetables | F24: 140 | G24: 1.65 | I24: Baky et al., 2010 | J24: SS, 2022. Avg for vegetables
A25: 01229 | B25: Cantaloupes and other melons | C25: Fruits
A26: 01251 | B26: Carrots and turnips | C26: Vegetables | F26: 140 | G26: 2.23 | I26: Baky et al., 2010 | J26: SS, 2022
A27: 01372 | B27: Cashew nuts, in shell | C27: Nuts
A28: 01213_cf | B28: Cauliflowers | C28: Vegetables | D28: 60 | F28: 140 | G28: 1.65 | I28: Baky et al., 2010 | J28: SS, 2022. Avg for vegetables
A29: 01213 | B29: Cauliflowers and broccoli, average | C29: Vegetables | F29: 140 | G29: 1.65
A30: 01199.90 | B30: Cereals n.e.c. | C30: Cereals
A31: 01344.02 | B31: Cherries | C31: Berries
A32: 01373 | B32: Chestnuts, in shell | C32: Nuts
A33: 01703 | B33: Chick peas, dry | C33: Pulses
A34: 01231 | B34: Chillies and peppers, green (Capsicum spp. and Pimenta spp.), raw | C34: Spices
A35: 01640 | B35: Cocoa beans | C35: Stimulants
A36: 01460 | B36: Coconut, in shell | C36: Nuts
A37: 01610 | B37: Coffee, green | C37: Stimulants
A38: 01232 | B38: Cucumbers and gherkins, averrage | C38: Vegetables | F38: 7 | G38: 1.65
A39: 01232_gh | B39: Cucumbers and gherkins, greenhouse | C39: Vegetables | D39: 95 | F39: 0 | G39: 1.65 | J39: SS, 2022. Avg for vegetables
A40: 01232_of | B40: Cucumbers and gherkins, openfield | C40: Vegetables | D40: 5 | F40: 140 | G40: 1.65 | I40: Baky et al., 2010, average for vegetables | J40: SS, 2022. Avg for vegetables
A41: 01351.01 | B41: Currants | C41: Berries | F41: 300 | G41: 2.25 | I41: Baky et al., 2010, average for berries | J41: SS, 2022. Strawberry
A42: 01314 | B42: Dates | C42: Fruits
...

Sheet Reference list
A2: Reference list
A4: Baky, A., Sundberg, M., Brown, N. 2010. Kartläggning av jordbrukets energianvändning. Ett projekt utfört på uppdrag av Jordbruksverket. JTI – Institutet för jordbruks- och miljöteknik, Uppsala, Sweden.
A5: Berglund, M., Cederberg, C., Clason, C., Henriksson, M., Törner, L. 2009. Jordbrukets klimatpåverkan – underlag för att beräkna växthusgasutsläpp på gårdsnivå och nulägesanalyser av exempelgårdar. Delrapport i JoKer-proJeKtet, Hushållningssällskapet Halland, Sweden.
A6: Chaudhary, A., Brooks, T.M. 2018. Land use intensity-specific global characterization factors to assess product biodiversity footprints. Environmental Science Technology 52, 5094–5104.
A7: Davis, J. Wallman, M., Sund, V., Emanuelsson, A., Cederberg, C., Sonesson, U. 2011. Emissions of greenhouse gases from production of horticultural products: analysis of 17 products cultivated in Sweden, SIK Institutet för livsmedel och bioteknik, Gothenburg, Sweden.
A8: Ecoinvent centre. 2023. Ecoinvent Database Version 3.9.1. Dübendorf, Switzerland: Swiss Centre for Life Cycle Inventories.
A9: Edström, M., Pettersson, O., Nilsson, L., Hörndahl, T. 2005. Jordbrukssektorns energianvändning. JTI-rapport Lantbruk & Industri 342. JTI – Institutet för jordbruks- och miljöteknik, Uppsala, Sweden. | R9: SS. 2020. Gödselmedel i jordbruket 2018/19. Mineral- och stallgödsel till olika grödor samt hantering och lagring av stallgödsel. Use of fertilisers and animal manure in agriculture in 2018/19. MI 30 SM 2002. Statistics Sweden, Örebro, Sweden.
A10: EU. 2023. Eurostat Statistical Database. European Union.
A11: FAO. 2023. FAOSTAT Statistical Database. Food and Agricultural Organization of the United Nations.
A12: Flysjö, A., Cederberg, C., Strid, I. 2008. LCA-databas för konventionella fodermedel: miljöpåverkan i samband med produktion, SIK Institutet för livsmedel och bioteknik, Gothenburg, Sweden.
