Workbook
Name CF_biog_CH4: 'CF climate'!$C$5
Name CF_fossil_CH4: 'CF climate'!$D$5
Name CF_HCFC: 'CF climate'!$F$5
Name CF_N2O: 'CF climate'!$E$5
Name CH4_bio_codes: 'Crops CH4, bio'!$A$6:$A$118
Name CH4_bio_data: 'Crops CH4, bio'!$E$6:$N$118
Name CH4_codes: 'Crops CH4, bio'!$A$6:$A$118
Name CH4_codes: 'Crops CH4, fossil'!$A$6:$A$118
Name CH4_data: 'Crops CH4, bio'!$E$6:$N$118
Name CH4_data: 'Crops CH4, fossil'!$E$6:$N$118
Name CO2_codes: 'Crops CO2'!$A$6:$A$118
Name CO2_data: 'Crops CO2'!$E$6:$N$118
Name CO2e_codes: 'Crops CO2e'!$A$6:$A$118
Name CO2e_data: 'Crops CO2e'!$E$6:$N$118
Name Crop_codes: 'Footprints, results per kg'!$A$6:$A$116
Name Crop_codes: 'Crops, input data per ha'!$A$6:$A$118
Name Crop_data: 'Crops, input data per ha'!$A$6:$Z$118
Name Crop_data_codes: 'Crops, input data per ha'!$A$6:$A$118
Name Crops: 'Crops CH4, bio'!$B:$B
Name Crops: 'Crops CH4, fossil'!$B:$B
Name Crops: 'Crops CO2e'!$B:$B
Name Crops: 'Crops N2O'!$B:$B
Name Crops: 'Crops CO2'!$B:$B
Name EF_capital_goods_CH4: 'Emission factors'!$C$35
Name EF_capital_goods_CO2: 'Emission factors'!$B$35
Name EF_capital_goods_N2O: 'Emission factors'!$D$35
Name EF_chips_CH4: 'Emission factors'!$C$10
Name EF_chips_CO2: 'Emission factors'!$B$10
Name EF_chips_N2O: 'Emission factors'!$D$10
Name EF_diesel_CH4: 'Emission factors'!$C$13
Name EF_diesel_CO2: 'Emission factors'!$B$13
Name EF_diesel_N2O: 'Emission factors'!$D$13
Name EF_district_heating_CH4: 'Emission factors'!$C$14
Name EF_district_heating_CO2: 'Emission factors'!$B$14
Name EF_district_heating_N2O: 'Emission factors'!$D$14
Name EF_electricity_CH4: 'Emission factors'!$C$6
Name EF_electricity_CO2: 'Emission factors'!$B$6
Name EF_electricity_N2O: 'Emission factors'!$D$6
Name EF_heating_oil_CH4: 'Emission factors'!$C$7
Name EF_heating_oil_CO2: 'Emission factors'!$B$7
Name EF_heating_oil_N2O: 'Emission factors'!$D$7
Name EF_irrigation_CH4: 'Emission factors'!$C$28
Name EF_irrigation_CO2: 'Emission factors'!$B$28
Name EF_irrigation_N2O: 'Emission factors'!$D$28
Name EF_min_fert_AN_CH4: 'Emission factors'!$C$21
Name EF_min_fert_AN_CO2: 'Emission factors'!$B$21
Name EF_min_fert_AN_N2O: 'Emission factors'!$D$21
Name EF_min_fert_BAT_CH4: 'Emission factors'!$C$20
Name EF_min_fert_BAT_CO2: 'Emission factors'!$B$20
Name EF_min_fert_BAT_N2O: 'Emission factors'!$D$20
Name EF_min_fert_CH4: 'Emission factors'!$C$20
Name EF_min_fert_CO2: 'Emission factors'!$B$20
Name EF_N2O_soils_crop_res: 'Emission factors'!$B$63
Name EF_N2O_soils_indirect: 'Emission factors'!$B$64
Name EF_N2O_soils_min_fert: 'Emission factors'!$B$62
Name EF_natural_gas_CH4: 'Emission factors'!$C$8
Name EF_natural_gas_CO2: 'Emission factors'!$B$8
Name EF_natural_gas_N2O: 'Emission factors'!$D$8
Name EF_NH3: 'Emission factors'!$B$73
Name EF_other_fossil_CH4: 'Emission factors'!$C$9

Sheet README
A2: Introduction to the dataset
A4: This is a dataset that includes data on the environmental and social indicators for crops for Sweden.
A6: Results are presented in the tab "Crops, results per kg"
A7: These are calculated from the input data in tab "Crops, input data per ha"
A8: For climate, there is an intermediate step in the calculations for each gas in the tabs "Crops CO2", "Crops CH4" and "Crops N2O"
A10: Figures in blue are input data that change across countries, these are only found in tabs:
B11: - Crops, input data per ha
B12: - Emission factors
A14: Figures in black are calculated or the same across countries and should not be changed
A16: Figures in green are input data that do differ between countries but that are not changed, but calculated from the Swedish values or where Swedish data is used as a place-holder for now.

Sheet Footprints, results per kg
A2: Footprints (per kg of crop)
A4: Crops | F4: Climate | L4: Land | M4: Nitrogen | N4: Phosphorus | O4: Water | P4: Pesticides | Q4: Biodiversity | R4: Ammonia | S4: Labour
A5: Crop code | B5: Crop | C5: Category | D5: Grown in country | E5: Share | F5: Carbon footprint, kg CO2e/kg | G5: Carbon dioxide, kg CO2/kg | H5: Methane, fossil, kg CH4/kg | I5: Methane, biogenic, kg CH4/kg | J5: Nitrous oxide, kg N2O/kg | K5: HFCs, kg HFCs/kg | L5: Cropland use, m2/kg | M5: New N input, kg N/kg | N5: New P input, kg P/kg | O5: Blue freshwater use, m3/kg | P5: Pesticide use, g a.i./kg | Q5: Extinction rate, E/MSY/kg | R5: Ammonia emission, kg NH3/kg | S5: Labour requirements, h/kg
A6: 01371 | B6: =INDEX(Crop_data,MATCH(A6,Crop_data_codes,0),2) -> Almonds, in shell | C6: =INDEX(Crop_data,MATCH(A6,Crop_data_codes,0),3) -> Nuts | D6: =IF(INDEX(Crop_data,MATCH(A6,Crop_data_codes,0),6)>0,"Yes","No") -> No | F6: =IF(D6="Yes",INDEX(CO2e_data,MATCH(A6,CO2e_codes,0),1),"") | G6: =IF(D6="Yes",INDEX(CO2_data,MATCH(A6,CO2_codes,0),1),"") | H6: =IF(D6="Yes",INDEX(CH4_data,MATCH(A6,CH4_codes,0),1),"") | I6: =IF(D6="Yes",INDEX(CH4_bio_data,MATCH(A6,CH4_bio_codes,0),1),"") | J6: =IF(D6="Yes",INDEX(N2O_data,MATCH(A6,N2O_codes,0),1),"") | L6: =IF(D6="Yes",1/INDEX(Crop_data,MATCH(A6,Crop_data_codes,0),6)*10000,"") | M6: =IF(D6="Yes",(INDEX(Crop_data,MATCH(A6,Crop_data_codes,0),7)+INDEX(Crop_data,MATCH(A6,Crop_data_codes,0),8))/INDEX(Crop_data,MATCH(A6,Crop_data_codes,0),6),"") | N6: =IF(D6="Yes",INDEX(Crop_data,MATCH(A6,Crop_data_codes,0),10)/INDEX(Crop_data,MATCH(A6,Crop_data_codes,0),6),"") | O6: =IF(D6="Yes",INDEX(Crop_data,MATCH(A6,Crop_data_codes,0),12)/INDEX(Crop_data,MATCH(A6,Crop_data_codes,0),6),"") | P6: =IF(D6="Yes",INDEX(Crop_data,MATCH(A6,Crop_data_codes,0),13)/INDEX(Crop_data,MATCH(A6,Crop_data_codes,0),6)*1000,"") | Q6: =IF(D6="Yes",SUM(INDEX(Crop_data,MATCH(A6,Crop_data_codes,0),21):INDEX(Crop_data,MATCH(A6,Crop_data_codes,0),22):INDEX(Crop_data,MATCH(A6,Crop_data_codes,0),23):INDEX(Crop_data,MATCH(A6,Crop_data_codes,0),24):INDEX(Crop_data,MATCH(A6,Crop_data_codes,0),25))*(1/INDEX(Crop_data,MATCH(A6,Crop_data_codes,0),6)*10000)/(No_species/1000000),"") | R6: =IF(D6="Yes",INDEX(Crop_data,MATCH(A6,Crop_data_codes,0),7)/INDEX(Crop_data,MATCH(A6,Crop_data_codes,0),6)*EF_NH3*N_to_NH3,"") | S6: =IF(D6="Yes",INDEX(Crop_data,MATCH(A6,Crop_data_codes,0),26)/INDEX(Crop_data,MATCH(A6,Crop_data_codes,0),6),"")
A7: 01654 | B7: =INDEX(Crop_data,MATCH(A7,Crop_data_codes,0),2) -> Anise, badian, coriander, cumin, caraway, fennel and juniper berries, raw | C7: =INDEX(Crop_data,MATCH(A7,Crop_data_codes,0),3) -> Vegetables | D7: =IF(INDEX(Crop_data,MATCH(A7,Crop_data_codes,0),6)>0,"Yes","No") -> No | F7: =IF(D7="Yes",INDEX(CO2e_data,MATCH(A7,CO2e_codes,0),1),"") | G7: =IF(D7="Yes",INDEX(CO2_data,MATCH(A7,CO2_codes,0),1),"") | H7: =IF(D7="Yes",INDEX(CH4_data,MATCH(A7,CH4_codes,0),1),"") | I7: =IF(D7="Yes",INDEX(CH4_bio_data,MATCH(A7,CH4_bio_codes,0),1),"") | J7: =IF(D7="Yes",INDEX(N2O_data,MATCH(A7,N2O_codes,0),1),"") | L7: =IF(D7="Yes",1/INDEX(Crop_data,MATCH(A7,Crop_data_codes,0),6)*10000,"") | M7: =IF(D7="Yes",(INDEX(Crop_data,MATCH(A7,Crop_data_codes,0),7)+INDEX(Crop_data,MATCH(A7,Crop_data_codes,0),8))/INDEX(Crop_data,MATCH(A7,Crop_data_codes,0),6),"") | N7: =IF(D7="Yes",INDEX(Crop_data,MATCH(A7,Crop_data_codes,0),10)/INDEX(Crop_data,MATCH(A7,Crop_data_codes,0),6),"") | O7: =IF(D7="Yes",INDEX(Crop_data,MATCH(A7,Crop_data_codes,0),12)/INDEX(Crop_data,MATCH(A7,Crop_data_codes,0),6),"") | P7: =IF(D7="Yes",INDEX(Crop_data,MATCH(A7,Crop_data_codes,0),13)/INDEX(Crop_data,MATCH(A7,Crop_data_codes,0),6)*1000,"") | Q7: =IF(D7="Yes",SUM(INDEX(Crop_data,MATCH(A7,Crop_data_codes,0),21):INDEX(Crop_data,MATCH(A7,Crop_data_codes,0),22):INDEX(Crop_data,MATCH(A7,Crop_data_codes,0),23):INDEX(Crop_data,MATCH(A7,Crop_data_codes,0),24):INDEX(Crop_data,MATCH(A7,Crop_data_codes,0),25))*(1/INDEX(Crop_data,MATCH(A7,Crop_data_codes,0),6)*10000)/(No_species/1000000),"") | R7: =IF(D7="Yes",INDEX(Crop_data,MATCH(A7,Crop_data_codes,0),7)/INDEX(Crop_data,MATCH(A7,Crop_data_codes,0),6)*EF_NH3*N_to_NH3,"") | S7: =IF(D7="Yes",INDEX(Crop_data,MATCH(A7,Crop_data_codes,0),26)/INDEX(Crop_data,MATCH(A7,Crop_data_codes,0),6),"")
A8: 01341 | B8: =INDEX(Crop_data,MATCH(A8,Crop_data_codes,0),2) -> Apples | C8: =INDEX(Crop_data,MATCH(A8,Crop_data_codes,0),3) -> Fruits | D8: =IF(INDEX(Crop_data,MATCH(A8,Crop_data_codes,0),6)>0,"Yes","No") -> Yes | F8: =IF(D8="Yes",INDEX(CO2e_data,MATCH(A8,CO2e_codes,0),1),"") -> 0.15649168 | G8: =IF(D8="Yes",INDEX(CO2_data,MATCH(A8,CO2_codes,0),1),"") -> 0.10494615 | H8: =IF(D8="Yes",INDEX(CH4_data,MATCH(A8,CH4_codes,0),1),"") -> 0.00014499388 | I8: =IF(D8="Yes",INDEX(CH4_bio_data,MATCH(A8,CH4_bio_codes,0),1),"") -> 0 | J8: =IF(D8="Yes",INDEX(N2O_data,MATCH(A8,N2O_codes,0),1),"") -> 0.00017298429 | L8: =IF(D8="Yes",1/INDEX(Crop_data,MATCH(A8,Crop_data_codes,0),6)*10000,"") -> 0.52858425 | M8: =IF(D8="Yes",(INDEX(Crop_data,MATCH(A8,Crop_data_codes,0),7)+INDEX(Crop_data,MATCH(A8,Crop_data_codes,0),8))/INDEX(Crop_data,MATCH(A8,Crop_data_codes,0),6),"") -> 0.0021672481 | N8: =IF(D8="Yes",INDEX(Crop_data,MATCH(A8,Crop_data_codes,0),10)/INDEX(Crop_data,MATCH(A8,Crop_data_codes,0),6),"") -> 0.00031715826 | O8: =IF(D8="Yes",INDEX(Crop_data,MATCH(A8,Crop_data_codes,0),12)/INDEX(Crop_data,MATCH(A8,Crop_data_codes,0),6),"") -> 0.028999998 | P8: =IF(D8="Yes",INDEX(Crop_data,MATCH(A8,Crop_data_codes,0),13)/INDEX(Crop_data,MATCH(A8,Crop_data_codes,0),6)*1000,"") -> 0.3155648 | Q8: =IF(D8="Yes",SUM(INDEX(Crop_data,MATCH(A8,Crop_data_codes,0),21):INDEX(Crop_data,MATCH(A8,Crop_data_codes,0),22):INDEX(Crop_data,MATCH(A8,Crop_data_codes,0),23):INDEX(Crop_data,MATCH(A8,Crop_data_codes,0),24):INDEX(Crop_data,MATCH(A8,Crop_data_codes,0),25))*(1/INDEX(Crop_data,MATCH(A8,Crop_data_codes,0),6)*10000)/(No_species/1000000),"") -> 4.3089214e-12 | R8: =IF(D8="Yes",INDEX(Crop_data,MATCH(A8,Crop_data_codes,0),7)/INDEX(Crop_data,MATCH(A8,Crop_data_codes,0),6)*EF_NH3*N_to_NH3,"") -> 0.00013175699 | S8: =IF(D8="Yes",INDEX(Crop_data,MATCH(A8,Crop_data_codes,0),26)/INDEX(Crop_data,MATCH(A8,Crop_data_codes,0),6),"") -> 0.015687323
A9: 01343 | B9: =INDEX(Crop_data,MATCH(A9,Crop_data_codes,0),2) -> Apricots | C9: =INDEX(Crop_data,MATCH(A9,Crop_data_codes,0),3) -> Fruits | D9: =IF(INDEX(Crop_data,MATCH(A9,Crop_data_codes,0),6)>0,"Yes","No") -> No | F9: =IF(D9="Yes",INDEX(CO2e_data,MATCH(A9,CO2e_codes,0),1),"") | G9: =IF(D9="Yes",INDEX(CO2_data,MATCH(A9,CO2_codes,0),1),"") | H9: =IF(D9="Yes",INDEX(CH4_data,MATCH(A9,CH4_codes,0),1),"") | I9: =IF(D9="Yes",INDEX(CH4_bio_data,MATCH(A9,CH4_bio_codes,0),1),"") | J9: =IF(D9="Yes",INDEX(N2O_data,MATCH(A9,N2O_codes,0),1),"") | L9: =IF(D9="Yes",1/INDEX(Crop_data,MATCH(A9,Crop_data_codes,0),6)*10000,"") | M9: =IF(D9="Yes",(INDEX(Crop_data,MATCH(A9,Crop_data_codes,0),7)+INDEX(Crop_data,MATCH(A9,Crop_data_codes,0),8))/INDEX(Crop_data,MATCH(A9,Crop_data_codes,0),6),"") | N9: =IF(D9="Yes",INDEX(Crop_data,MATCH(A9,Crop_data_codes,0),10)/INDEX(Crop_data,MATCH(A9,Crop_data_codes,0),6),"") | O9: =IF(D9="Yes",INDEX(Crop_data,MATCH(A9,Crop_data_codes,0),12)/INDEX(Crop_data,MATCH(A9,Crop_data_codes,0),6),"") | P9: =IF(D9="Yes",INDEX(Crop_data,MATCH(A9,Crop_data_codes,0),13)/INDEX(Crop_data,MATCH(A9,Crop_data_codes,0),6)*1000,"") | Q9: =IF(D9="Yes",SUM(INDEX(Crop_data,MATCH(A9,Crop_data_codes,0),21):INDEX(Crop_data,MATCH(A9,Crop_data_codes,0),22):INDEX(Crop_data,MATCH(A9,Crop_data_codes,0),23):INDEX(Crop_data,MATCH(A9,Crop_data_codes,0),24):INDEX(Crop_data,MATCH(A9,Crop_data_codes,0),25))*(1/INDEX(Crop_data,MATCH(A9,Crop_data_codes,0),6)*10000)/(No_species/1000000),"") | R9: =IF(D9="Yes",INDEX(Crop_data,MATCH(A9,Crop_data_codes,0),7)/INDEX(Crop_data,MATCH(A9,Crop_data_codes,0),6)*EF_NH3*N_to_NH3,"") | S9: =IF(D9="Yes",INDEX(Crop_data,MATCH(A9,Crop_data_codes,0),26)/INDEX(Crop_data,MATCH(A9,Crop_data_codes,0),6),"")
A10: 01216 | B10: =INDEX(Crop_data,MATCH(A10,Crop_data_codes,0),2) -> Artichokes | C10: =INDEX(Crop_data,MATCH(A10,Crop_data_codes,0),3) -> Vegetables | D10: =IF(INDEX(Crop_data,MATCH(A10,Crop_data_codes,0),6)>0,"Yes","No") -> No | F10: =IF(D10="Yes",INDEX(CO2e_data,MATCH(A10,CO2e_codes,0),1),"") | G10: =IF(D10="Yes",INDEX(CO2_data,MATCH(A10,CO2_codes,0),1),"") | H10: =IF(D10="Yes",INDEX(CH4_data,MATCH(A10,CH4_codes,0),1),"") | I10: =IF(D10="Yes",INDEX(CH4_bio_data,MATCH(A10,CH4_bio_codes,0),1),"") | J10: =IF(D10="Yes",INDEX(N2O_data,MATCH(A10,N2O_codes,0),1),"") | L10: =IF(D10="Yes",1/INDEX(Crop_data,MATCH(A10,Crop_data_codes,0),6)*10000,"") | M10: =IF(D10="Yes",(INDEX(Crop_data,MATCH(A10,Crop_data_codes,0),7)+INDEX(Crop_data,MATCH(A10,Crop_data_codes,0),8))/INDEX(Crop_data,MATCH(A10,Crop_data_codes,0),6),"") | N10: =IF(D10="Yes",INDEX(Crop_data,MATCH(A10,Crop_data_codes,0),10)/INDEX(Crop_data,MATCH(A10,Crop_data_codes,0),6),"") | O10: =IF(D10="Yes",INDEX(Crop_data,MATCH(A10,Crop_data_codes,0),12)/INDEX(Crop_data,MATCH(A10,Crop_data_codes,0),6),"") | P10: =IF(D10="Yes",INDEX(Crop_data,MATCH(A10,Crop_data_codes,0),13)/INDEX(Crop_data,MATCH(A10,Crop_data_codes,0),6)*1000,"") | Q10: =IF(D10="Yes",SUM(INDEX(Crop_data,MATCH(A10,Crop_data_codes,0),21):INDEX(Crop_data,MATCH(A10,Crop_data_codes,0),22):INDEX(Crop_data,MATCH(A10,Crop_data_codes,0),23):INDEX(Crop_data,MATCH(A10,Crop_data_codes,0),24):INDEX(Crop_data,MATCH(A10,Crop_data_codes,0),25))*(1/INDEX(Crop_data,MATCH(A10,Crop_data_codes,0),6)*10000)/(No_species/1000000),"") | R10: =IF(D10="Yes",INDEX(Crop_data,MATCH(A10,Crop_data_codes,0),7)/INDEX(Crop_data,MATCH(A10,Crop_data_codes,0),6)*EF_NH3*N_to_NH3,"") | S10: =IF(D10="Yes",INDEX(Crop_data,MATCH(A10,Crop_data_codes,0),26)/INDEX(Crop_data,MATCH(A10,Crop_data_codes,0),6),"")
A11: 01211 | B11: =INDEX(Crop_data,MATCH(A11,Crop_data_codes,0),2) -> Asparagus | C11: =INDEX(Crop_data,MATCH(A11,Crop_data_codes,0),3) -> Vegetables | D11: =IF(INDEX(Crop_data,MATCH(A11,Crop_data_codes,0),6)>0,"Yes","No") -> Yes | E11: 90 | F11: =IF(D11="Yes",INDEX(CO2e_data,MATCH(A11,CO2e_codes,0),1),"") -> 0.44756952 | G11: =IF(D11="Yes",INDEX(CO2_data,MATCH(A11,CO2_codes,0),1),"") -> 0.29879835 | H11: =IF(D11="Yes",INDEX(CH4_data,MATCH(A11,CH4_codes,0),1),"") -> 0.00025729579 | I11: =IF(D11="Yes",INDEX(CH4_bio_data,MATCH(A11,CH4_bio_codes,0),1),"") -> 0 | J11: =IF(D11="Yes",INDEX(N2O_data,MATCH(A11,N2O_codes,0),1),"") -> 0.00051686357 | L11: =IF(D11="Yes",1/INDEX(Crop_data,MATCH(A11,Crop_data_codes,0),6)*10000,"") -> 6.0392856 | M11: =IF(D11="Yes",(INDEX(Crop_data,MATCH(A11,Crop_data_codes,0),7)+INDEX(Crop_data,MATCH(A11,Crop_data_codes,0),8))/INDEX(Crop_data,MATCH(A11,Crop_data_codes,0),6),"") -> 0.012078571 | N11: =IF(D11="Yes",INDEX(Crop_data,MATCH(A11,Crop_data_codes,0),10)/INDEX(Crop_data,MATCH(A11,Crop_data_codes,0),6),"") -> 0.0024157142 | O11: =IF(D11="Yes",INDEX(Crop_data,MATCH(A11,Crop_data_codes,0),12)/INDEX(Crop_data,MATCH(A11,Crop_data_codes,0),6),"") -> 0.034 | P11: =IF(D11="Yes",INDEX(Crop_data,MATCH(A11,Crop_data_codes,0),13)/INDEX(Crop_data,MATCH(A11,Crop_data_codes,0),6)*1000,"") -> 0.99648212 | Q11: =IF(D11="Yes",SUM(INDEX(Crop_data,MATCH(A11,Crop_data_codes,0),21):INDEX(Crop_data,MATCH(A11,Crop_data_codes,0),22):INDEX(Crop_data,MATCH(A11,Crop_data_codes,0),23):INDEX(Crop_data,MATCH(A11,Crop_data_codes,0),24):INDEX(Crop_data,MATCH(A11,Crop_data_codes,0),25))*(1/INDEX(Crop_data,MATCH(A11,Crop_data_codes,0),6)*10000)/(No_species/1000000),"") -> 4.9231142e-11 | R11: =IF(D11="Yes",INDEX(Crop_data,MATCH(A11,Crop_data_codes,0),7)/INDEX(Crop_data,MATCH(A11,Crop_data_codes,0),6)*EF_NH3*N_to_NH3,"") -> 0.00073431193 | S11: =IF(D11="Yes",INDEX(Crop_data,MATCH(A11,Crop_data_codes,0),26)/INDEX(Crop_data,MATCH(A11,Crop_data_codes,0),6),"") -> 0.21294521
A12: 01311 | B12: =INDEX(Crop_data,MATCH(A12,Crop_data_codes,0),2) -> Avocados | C12: =INDEX(Crop_data,MATCH(A12,Crop_data_codes,0),3) -> Vegetables | D12: =IF(INDEX(Crop_data,MATCH(A12,Crop_data_codes,0),6)>0,"Yes","No") -> No | E12: 10 | F12: =IF(D12="Yes",INDEX(CO2e_data,MATCH(A12,CO2e_codes,0),1),"") | G12: =IF(D12="Yes",INDEX(CO2_data,MATCH(A12,CO2_codes,0),1),"") | H12: =IF(D12="Yes",INDEX(CH4_data,MATCH(A12,CH4_codes,0),1),"") | I12: =IF(D12="Yes",INDEX(CH4_bio_data,MATCH(A12,CH4_bio_codes,0),1),"") | J12: =IF(D12="Yes",INDEX(N2O_data,MATCH(A12,N2O_codes,0),1),"") | L12: =IF(D12="Yes",1/INDEX(Crop_data,MATCH(A12,Crop_data_codes,0),6)*10000,"") | M12: =IF(D12="Yes",(INDEX(Crop_data,MATCH(A12,Crop_data_codes,0),7)+INDEX(Crop_data,MATCH(A12,Crop_data_codes,0),8))/INDEX(Crop_data,MATCH(A12,Crop_data_codes,0),6),"") | N12: =IF(D12="Yes",INDEX(Crop_data,MATCH(A12,Crop_data_codes,0),10)/INDEX(Crop_data,MATCH(A12,Crop_data_codes,0),6),"") | O12: =IF(D12="Yes",INDEX(Crop_data,MATCH(A12,Crop_data_codes,0),12)/INDEX(Crop_data,MATCH(A12,Crop_data_codes,0),6),"") | P12: =IF(D12="Yes",INDEX(Crop_data,MATCH(A12,Crop_data_codes,0),13)/INDEX(Crop_data,MATCH(A12,Crop_data_codes,0),6)*1000,"") | Q12: =IF(D12="Yes",SUM(INDEX(Crop_data,MATCH(A12,Crop_data_codes,0),21):INDEX(Crop_data,MATCH(A12,Crop_data_codes,0),22):INDEX(Crop_data,MATCH(A12,Crop_data_codes,0),23):INDEX(Crop_data,MATCH(A12,Crop_data_codes,0),24):INDEX(Crop_data,MATCH(A12,Crop_data_codes,0),25))*(1/INDEX(Crop_data,MATCH(A12,Crop_data_codes,0),6)*10000)/(No_species/1000000),"") | R12: =IF(D12="Yes",INDEX(Crop_data,MATCH(A12,Crop_data_codes,0),7)/INDEX(Crop_data,MATCH(A12,Crop_data_codes,0),6)*EF_NH3*N_to_NH3,"") | S12: =IF(D12="Yes",INDEX(Crop_data,MATCH(A12,Crop_data_codes,0),26)/INDEX(Crop_data,MATCH(A12,Crop_data_codes,0),6),"")
A13: 01312 | B13: =INDEX(Crop_data,MATCH(A13,Crop_data_codes,0),2) -> Bananas | C13: =INDEX(Crop_data,MATCH(A13,Crop_data_codes,0),3) -> Fruits | D13: =IF(INDEX(Crop_data,MATCH(A13,Crop_data_codes,0),6)>0,"Yes","No") -> No | F13: =IF(D13="Yes",INDEX(CO2e_data,MATCH(A13,CO2e_codes,0),1),"") | G13: =IF(D13="Yes",INDEX(CO2_data,MATCH(A13,CO2_codes,0),1),"") | H13: =IF(D13="Yes",INDEX(CH4_data,MATCH(A13,CH4_codes,0),1),"") | I13: =IF(D13="Yes",INDEX(CH4_bio_data,MATCH(A13,CH4_bio_codes,0),1),"") | J13: =IF(D13="Yes",INDEX(N2O_data,MATCH(A13,N2O_codes,0),1),"") | L13: =IF(D13="Yes",1/INDEX(Crop_data,MATCH(A13,Crop_data_codes,0),6)*10000,"") | M13: =IF(D13="Yes",(INDEX(Crop_data,MATCH(A13,Crop_data_codes,0),7)+INDEX(Crop_data,MATCH(A13,Crop_data_codes,0),8))/INDEX(Crop_data,MATCH(A13,Crop_data_codes,0),6),"") | N13: =IF(D13="Yes",INDEX(Crop_data,MATCH(A13,Crop_data_codes,0),10)/INDEX(Crop_data,MATCH(A13,Crop_data_codes,0),6),"") | O13: =IF(D13="Yes",INDEX(Crop_data,MATCH(A13,Crop_data_codes,0),12)/INDEX(Crop_data,MATCH(A13,Crop_data_codes,0),6),"") | P13: =IF(D13="Yes",INDEX(Crop_data,MATCH(A13,Crop_data_codes,0),13)/INDEX(Crop_data,MATCH(A13,Crop_data_codes,0),6)*1000,"") | Q13: =IF(D13="Yes",SUM(INDEX(Crop_data,MATCH(A13,Crop_data_codes,0),21):INDEX(Crop_data,MATCH(A13,Crop_data_codes,0),22):INDEX(Crop_data,MATCH(A13,Crop_data_codes,0),23):INDEX(Crop_data,MATCH(A13,Crop_data_codes,0),24):INDEX(Crop_data,MATCH(A13,Crop_data_codes,0),25))*(1/INDEX(Crop_data,MATCH(A13,Crop_data_codes,0),6)*10000)/(No_species/1000000),"") | R13: =IF(D13="Yes",INDEX(Crop_data,MATCH(A13,Crop_data_codes,0),7)/INDEX(Crop_data,MATCH(A13,Crop_data_codes,0),6)*EF_NH3*N_to_NH3,"") | S13: =IF(D13="Yes",INDEX(Crop_data,MATCH(A13,Crop_data_codes,0),26)/INDEX(Crop_data,MATCH(A13,Crop_data_codes,0),6),"")
A14: 0115 | B14: =INDEX(Crop_data,MATCH(A14,Crop_data_codes,0),2) -> Barley, average | C14: =INDEX(Crop_data,MATCH(A14,Crop_data_codes,0),3) -> Cereals, incl feed | D14: =IF(INDEX(Crop_data,MATCH(A14,Crop_data_codes,0),6)>0,"Yes","No") -> Yes | F14: =IF(D14="Yes",INDEX(CO2e_data,MATCH(A14,CO2e_codes,0),1),"") -> 0.40169841 | G14: =IF(D14="Yes",INDEX(CO2_data,MATCH(A14,CO2_codes,0),1),"") -> 0.16693756 | H14: =IF(D14="Yes",INDEX(CH4_data,MATCH(A14,CH4_codes,0),1),"") -> 0.00020851912 | I14: =IF(D14="Yes",INDEX(CH4_bio_data,MATCH(A14,CH4_bio_codes,0),1),"") -> 0 | J14: =IF(D14="Yes",INDEX(N2O_data,MATCH(A14,N2O_codes,0),1),"") -> 0.00083716842 | L14: =IF(D14="Yes",1/INDEX(Crop_data,MATCH(A14,Crop_data_codes,0),6)*10000,"") -> 2.1815009 | M14: =IF(D14="Yes",(INDEX(Crop_data,MATCH(A14,Crop_data_codes,0),7)+INDEX(Crop_data,MATCH(A14,Crop_data_codes,0),8))/INDEX(Crop_data,MATCH(A14,Crop_data_codes,0),6),"") -> 0.020506108 | N14: =IF(D14="Yes",INDEX(Crop_data,MATCH(A14,Crop_data_codes,0),10)/INDEX(Crop_data,MATCH(A14,Crop_data_codes,0),6),"") -> 0.0015270506 | O14: =IF(D14="Yes",INDEX(Crop_data,MATCH(A14,Crop_data_codes,0),12)/INDEX(Crop_data,MATCH(A14,Crop_data_codes,0),6),"") -> 0 | P14: =IF(D14="Yes",INDEX(Crop_data,MATCH(A14,Crop_data_codes,0),13)/INDEX(Crop_data,MATCH(A14,Crop_data_codes,0),6)*1000,"") -> 0.11343805 | Q14: =IF(D14="Yes",SUM(INDEX(Crop_data,MATCH(A14,Crop_data_codes,0),21):INDEX(Crop_data,MATCH(A14,Crop_data_codes,0),22):INDEX(Crop_data,MATCH(A14,Crop_data_codes,0),23):INDEX(Crop_data,MATCH(A14,Crop_data_codes,0),24):INDEX(Crop_data,MATCH(A14,Crop_data_codes,0),25))*(1/INDEX(Crop_data,MATCH(A14,Crop_data_codes,0),6)*10000)/(No_species/1000000),"") -> 1.7783193e-11 | R14: =IF(D14="Yes",INDEX(Crop_data,MATCH(A14,Crop_data_codes,0),7)/INDEX(Crop_data,MATCH(A14,Crop_data_codes,0),6)*EF_NH3*N_to_NH3,"") -> 0.0012466607 | S14: =IF(D14="Yes",INDEX(Crop_data,MATCH(A14,Crop_data_codes,0),26)/INDEX(Crop_data,MATCH(A14,Crop_data_codes,0),6),"") -> 0.0034904014
A15: 0115_s | B15: =INDEX(Crop_data,MATCH(A15,Crop_data_codes,0),2) -> Barley, spring | C15: =INDEX(Crop_data,MATCH(A15,Crop_data_codes,0),3) -> Cereals | D15: =IF(INDEX(Crop_data,MATCH(A15,Crop_data_codes,0),6)>0,"Yes","No") -> Yes | F15: =IF(D15="Yes",INDEX(CO2e_data,MATCH(A15,CO2e_codes,0),1),"") -> 0.39997434 | G15: =IF(D15="Yes",INDEX(CO2_data,MATCH(A15,CO2_codes,0),1),"") -> 0.16737855 | H15: =IF(D15="Yes",INDEX(CH4_data,MATCH(A15,CH4_codes,0),1),"") -> 0.00020804148 | I15: =IF(D15="Yes",INDEX(CH4_bio_data,MATCH(A15,CH4_bio_codes,0),1),"") -> 0 | J15: =IF(D15="Yes",INDEX(N2O_data,MATCH(A15,N2O_codes,0),1),"") -> 0.00082928993 | L15: =IF(D15="Yes",1/INDEX(Crop_data,MATCH(A15,Crop_data_codes,0),6)*10000,"") -> 2.2492128 | M15: =IF(D15="Yes",(INDEX(Crop_data,MATCH(A15,Crop_data_codes,0),7)+INDEX(Crop_data,MATCH(A15,Crop_data_codes,0),8))/INDEX(Crop_data,MATCH(A15,Crop_data_codes,0),6),"") -> 0.020242915 | N15: =IF(D15="Yes",INDEX(Crop_data,MATCH(A15,Crop_data_codes,0),10)/INDEX(Crop_data,MATCH(A15,Crop_data_codes,0),6),"") -> 0.0015744489 | O15: =IF(D15="Yes",INDEX(Crop_data,MATCH(A15,Crop_data_codes,0),12)/INDEX(Crop_data,MATCH(A15,Crop_data_codes,0),6),"") -> 0 | P15: =IF(D15="Yes",INDEX(Crop_data,MATCH(A15,Crop_data_codes,0),13)/INDEX(Crop_data,MATCH(A15,Crop_data_codes,0),6)*1000,"") -> 0.105713 | Q15: =IF(D15="Yes",SUM(INDEX(Crop_data,MATCH(A15,Crop_data_codes,0),21):INDEX(Crop_data,MATCH(A15,Crop_data_codes,0),22):INDEX(Crop_data,MATCH(A15,Crop_data_codes,0),23):INDEX(Crop_data,MATCH(A15,Crop_data_codes,0),24):INDEX(Crop_data,MATCH(A15,Crop_data_codes,0),25))*(1/INDEX(Crop_data,MATCH(A15,Crop_data_codes,0),6)*10000)/(No_species/1000000),"") -> 1.8335168e-11 | R15: =IF(D15="Yes",INDEX(Crop_data,MATCH(A15,Crop_data_codes,0),7)/INDEX(Crop_data,MATCH(A15,Crop_data_codes,0),6)*EF_NH3*N_to_NH3,"") -> 0.00123066 | S15: =IF(D15="Yes",INDEX(Crop_data,MATCH(A15,Crop_data_codes,0),26)/INDEX(Crop_data,MATCH(A15,Crop_data_codes,0),6),"") -> 0.0035987404
A16: 0115_w | B16: =INDEX(Crop_data,MATCH(A16,Crop_data_codes,0),2) -> Barley, winter | C16: =INDEX(Crop_data,MATCH(A16,Crop_data_codes,0),3) -> Cereals | D16: =IF(INDEX(Crop_data,MATCH(A16,Crop_data_codes,0),6)>0,"Yes","No") -> Yes | F16: =IF(D16="Yes",INDEX(CO2e_data,MATCH(A16,CO2e_codes,0),1),"") -> 0.40316862 | G16: =IF(D16="Yes",INDEX(CO2_data,MATCH(A16,CO2_codes,0),1),"") -> 0.16024114 | H16: =IF(D16="Yes",INDEX(CH4_data,MATCH(A16,CH4_codes,0),1),"") -> 0.00020841946 | I16: =IF(D16="Yes",INDEX(CH4_bio_data,MATCH(A16,CH4_bio_codes,0),1),"") -> 0 | J16: =IF(D16="Yes",INDEX(N2O_data,MATCH(A16,N2O_codes,0),1),"") -> 0.00086709368 | L16: =IF(D16="Yes",1/INDEX(Crop_data,MATCH(A16,Crop_data_codes,0),6)*10000,"") -> 1.7164435 | M16: =IF(D16="Yes",(INDEX(Crop_data,MATCH(A16,Crop_data_codes,0),7)+INDEX(Crop_data,MATCH(A16,Crop_data_codes,0),8))/INDEX(Crop_data,MATCH(A16,Crop_data_codes,0),6),"") -> 0.021627188 | N16: =IF(D16="Yes",INDEX(Crop_data,MATCH(A16,Crop_data_codes,0),10)/INDEX(Crop_data,MATCH(A16,Crop_data_codes,0),6),"") -> 0.0013731548 | O16: =IF(D16="Yes",INDEX(Crop_data,MATCH(A16,Crop_data_codes,0),12)/INDEX(Crop_data,MATCH(A16,Crop_data_codes,0),6),"") -> 0 | P16: =IF(D16="Yes",INDEX(Crop_data,MATCH(A16,Crop_data_codes,0),13)/INDEX(Crop_data,MATCH(A16,Crop_data_codes,0),6)*1000,"") -> 0.17164435 | Q16: =IF(D16="Yes",SUM(INDEX(Crop_data,MATCH(A16,Crop_data_codes,0),21):INDEX(Crop_data,MATCH(A16,Crop_data_codes,0),22):INDEX(Crop_data,MATCH(A16,Crop_data_codes,0),23):INDEX(Crop_data,MATCH(A16,Crop_data_codes,0),24):INDEX(Crop_data,MATCH(A16,Crop_data_codes,0),25))*(1/INDEX(Crop_data,MATCH(A16,Crop_data_codes,0),6)*10000)/(No_species/1000000),"") -> 1.3992131e-11 | R16: =IF(D16="Yes",INDEX(Crop_data,MATCH(A16,Crop_data_codes,0),7)/INDEX(Crop_data,MATCH(A16,Crop_data_codes,0),6)*EF_NH3*N_to_NH3,"") -> 0.0013148163 | S16: =IF(D16="Yes",INDEX(Crop_data,MATCH(A16,Crop_data_codes,0),26)/INDEX(Crop_data,MATCH(A16,Crop_data_codes,0),6),"") -> 0.0027463096
A17: 01701 | B17: =INDEX(Crop_data,MATCH(A17,Crop_data_codes,0),2) -> Beans, dry | C17: =INDEX(Crop_data,MATCH(A17,Crop_data_codes,0),3) -> Pulses | D17: =IF(INDEX(Crop_data,MATCH(A17,Crop_data_codes,0),6)>0,"Yes","No") -> Yes | F17: =IF(D17="Yes",INDEX(CO2e_data,MATCH(A17,CO2e_codes,0),1),"") -> 0.42886957 | G17: =IF(D17="Yes",INDEX(CO2_data,MATCH(A17,CO2_codes,0),1),"") -> 0.21066187 | H17: =IF(D17="Yes",INDEX(CH4_data,MATCH(A17,CH4_codes,0),1),"") -> 0.00021828768 | I17: =IF(D17="Yes",INDEX(CH4_bio_data,MATCH(A17,CH4_bio_codes,0),1),"") -> 0 | J17: =IF(D17="Yes",INDEX(N2O_data,MATCH(A17,N2O_codes,0),1),"") -> 0.00077546789 | L17: =IF(D17="Yes",1/INDEX(Crop_data,MATCH(A17,Crop_data_codes,0),6)*10000,"") -> 5.5555556 | M17: =IF(D17="Yes",(INDEX(Crop_data,MATCH(A17,Crop_data_codes,0),7)+INDEX(Crop_data,MATCH(A17,Crop_data_codes,0),8))/INDEX(Crop_data,MATCH(A17,Crop_data_codes,0),6),"") -> 0.030555556 | N17: =IF(D17="Yes",INDEX(Crop_data,MATCH(A17,Crop_data_codes,0),10)/INDEX(Crop_data,MATCH(A17,Crop_data_codes,0),6),"") -> 0.0055555556 | O17: =IF(D17="Yes",INDEX(Crop_data,MATCH(A17,Crop_data_codes,0),12)/INDEX(Crop_data,MATCH(A17,Crop_data_codes,0),6),"") -> 0.001 | P17: =IF(D17="Yes",INDEX(Crop_data,MATCH(A17,Crop_data_codes,0),13)/INDEX(Crop_data,MATCH(A17,Crop_data_codes,0),6)*1000,"") -> 0.61111111 | Q17: =IF(D17="Yes",SUM(INDEX(Crop_data,MATCH(A17,Crop_data_codes,0),21):INDEX(Crop_data,MATCH(A17,Crop_data_codes,0),22):INDEX(Crop_data,MATCH(A17,Crop_data_codes,0),23):INDEX(Crop_data,MATCH(A17,Crop_data_codes,0),24):INDEX(Crop_data,MATCH(A17,Crop_data_codes,0),25))*(1/INDEX(Crop_data,MATCH(A17,Crop_data_codes,0),6)*10000)/(No_species/1000000),"") -> 4.5287865e-11 | R17: =IF(D17="Yes",INDEX(Crop_data,MATCH(A17,Crop_data_codes,0),7)/INDEX(Crop_data,MATCH(A17,Crop_data_codes,0),6)*EF_NH3*N_to_NH3,"") -> 0.0010132434 | S17: =IF(D17="Yes",INDEX(Crop_data,MATCH(A17,Crop_data_codes,0),26)/INDEX(Crop_data,MATCH(A17,Crop_data_codes,0),6),"") -> 0.0076333333
A18: 01355.01 | B18: =INDEX(Crop_data,MATCH(A18,Crop_data_codes,0),2) -> Blueberries | C18: =INDEX(Crop_data,MATCH(A18,Crop_data_codes,0),3) -> Berries | D18: =IF(INDEX(Crop_data,MATCH(A18,Crop_data_codes,0),6)>0,"Yes","No") -> No | F18: =IF(D18="Yes",INDEX(CO2e_data,MATCH(A18,CO2e_codes,0),1),"") | G18: =IF(D18="Yes",INDEX(CO2_data,MATCH(A18,CO2_codes,0),1),"") | H18: =IF(D18="Yes",INDEX(CH4_data,MATCH(A18,CH4_codes,0),1),"") | I18: =IF(D18="Yes",INDEX(CH4_bio_data,MATCH(A18,CH4_bio_codes,0),1),"") | J18: =IF(D18="Yes",INDEX(N2O_data,MATCH(A18,N2O_codes,0),1),"") | L18: =IF(D18="Yes",1/INDEX(Crop_data,MATCH(A18,Crop_data_codes,0),6)*10000,"") | M18: =IF(D18="Yes",(INDEX(Crop_data,MATCH(A18,Crop_data_codes,0),7)+INDEX(Crop_data,MATCH(A18,Crop_data_codes,0),8))/INDEX(Crop_data,MATCH(A18,Crop_data_codes,0),6),"") | N18: =IF(D18="Yes",INDEX(Crop_data,MATCH(A18,Crop_data_codes,0),10)/INDEX(Crop_data,MATCH(A18,Crop_data_codes,0),6),"") | O18: =IF(D18="Yes",INDEX(Crop_data,MATCH(A18,Crop_data_codes,0),12)/INDEX(Crop_data,MATCH(A18,Crop_data_codes,0),6),"") | P18: =IF(D18="Yes",INDEX(Crop_data,MATCH(A18,Crop_data_codes,0),13)/INDEX(Crop_data,MATCH(A18,Crop_data_codes,0),6)*1000,"") | Q18: =IF(D18="Yes",SUM(INDEX(Crop_data,MATCH(A18,Crop_data_codes,0),21):INDEX(Crop_data,MATCH(A18,Crop_data_codes,0),22):INDEX(Crop_data,MATCH(A18,Crop_data_codes,0),23):INDEX(Crop_data,MATCH(A18,Crop_data_codes,0),24):INDEX(Crop_data,MATCH(A18,Crop_data_codes,0),25))*(1/INDEX(Crop_data,MATCH(A18,Crop_data_codes,0),6)*10000)/(No_species/1000000),"") | R18: =IF(D18="Yes",INDEX(Crop_data,MATCH(A18,Crop_data_codes,0),7)/INDEX(Crop_data,MATCH(A18,Crop_data_codes,0),6)*EF_NH3*N_to_NH3,"") | S18: =IF(D18="Yes",INDEX(Crop_data,MATCH(A18,Crop_data_codes,0),26)/INDEX(Crop_data,MATCH(A18,Crop_data_codes,0),6),"")
A19: 01377 | B19: =INDEX(Crop_data,MATCH(A19,Crop_data_codes,0),2) -> Brazil nuts, in shell | C19: =INDEX(Crop_data,MATCH(A19,Crop_data_codes,0),3) -> Nuts | D19: =IF(INDEX(Crop_data,MATCH(A19,Crop_data_codes,0),6)>0,"Yes","No") -> No | E19: 10 | F19: =IF(D19="Yes",INDEX(CO2e_data,MATCH(A19,CO2e_codes,0),1),"") | G19: =IF(D19="Yes",INDEX(CO2_data,MATCH(A19,CO2_codes,0),1),"") | H19: =IF(D19="Yes",INDEX(CH4_data,MATCH(A19,CH4_codes,0),1),"") | I19: =IF(D19="Yes",INDEX(CH4_bio_data,MATCH(A19,CH4_bio_codes,0),1),"") | J19: =IF(D19="Yes",INDEX(N2O_data,MATCH(A19,N2O_codes,0),1),"") | L19: =IF(D19="Yes",1/INDEX(Crop_data,MATCH(A19,Crop_data_codes,0),6)*10000,"") | M19: =IF(D19="Yes",(INDEX(Crop_data,MATCH(A19,Crop_data_codes,0),7)+INDEX(Crop_data,MATCH(A19,Crop_data_codes,0),8))/INDEX(Crop_data,MATCH(A19,Crop_data_codes,0),6),"") | N19: =IF(D19="Yes",INDEX(Crop_data,MATCH(A19,Crop_data_codes,0),10)/INDEX(Crop_data,MATCH(A19,Crop_data_codes,0),6),"") | O19: =IF(D19="Yes",INDEX(Crop_data,MATCH(A19,Crop_data_codes,0),12)/INDEX(Crop_data,MATCH(A19,Crop_data_codes,0),6),"") | P19: =IF(D19="Yes",INDEX(Crop_data,MATCH(A19,Crop_data_codes,0),13)/INDEX(Crop_data,MATCH(A19,Crop_data_codes,0),6)*1000,"") | Q19: =IF(D19="Yes",SUM(INDEX(Crop_data,MATCH(A19,Crop_data_codes,0),21):INDEX(Crop_data,MATCH(A19,Crop_data_codes,0),22):INDEX(Crop_data,MATCH(A19,Crop_data_codes,0),23):INDEX(Crop_data,MATCH(A19,Crop_data_codes,0),24):INDEX(Crop_data,MATCH(A19,Crop_data_codes,0),25))*(1/INDEX(Crop_data,MATCH(A19,Crop_data_codes,0),6)*10000)/(No_species/1000000),"") | R19: =IF(D19="Yes",INDEX(Crop_data,MATCH(A19,Crop_data_codes,0),7)/INDEX(Crop_data,MATCH(A19,Crop_data_codes,0),6)*EF_NH3*N_to_NH3,"") | S19: =IF(D19="Yes",INDEX(Crop_data,MATCH(A19,Crop_data_codes,0),26)/INDEX(Crop_data,MATCH(A19,Crop_data_codes,0),6),"")
A20: 01702 | B20: =INDEX(Crop_data,MATCH(A20,Crop_data_codes,0),2) -> Broad beans and horse beans, dry | C20: =INDEX(Crop_data,MATCH(A20,Crop_data_codes,0),3) -> Pulses, incl feed | D20: =IF(INDEX(Crop_data,MATCH(A20,Crop_data_codes,0),6)>0,"Yes","No") -> Yes | E20: 90 | F20: =IF(D20="Yes",INDEX(CO2e_data,MATCH(A20,CO2e_codes,0),1),"") -> 0.22007 | G20: =IF(D20="Yes",INDEX(CO2_data,MATCH(A20,CO2_codes,0),1),"") -> 0.15034279 | H20: =IF(D20="Yes",INDEX(CH4_data,MATCH(A20,CH4_codes,0),1),"") -> 0.0001515342 | I20: =IF(D20="Yes",INDEX(CH4_bio_data,MATCH(A20,CH4_bio_codes,0),1),"") -> 0 | J20: =IF(D20="Yes",INDEX(N2O_data,MATCH(A20,N2O_codes,0),1),"") -> 0.00023886993 | L20: =IF(D20="Yes",1/INDEX(Crop_data,MATCH(A20,Crop_data_codes,0),6)*10000,"") -> 5.0505051 | M20: =IF(D20="Yes",(INDEX(Crop_data,MATCH(A20,Crop_data_codes,0),7)+INDEX(Crop_data,MATCH(A20,Crop_data_codes,0),8))/INDEX(Crop_data,MATCH(A20,Crop_data_codes,0),6),"") -> 0.013131313 | N20: =IF(D20="Yes",INDEX(Crop_data,MATCH(A20,Crop_data_codes,0),10)/INDEX(Crop_data,MATCH(A20,Crop_data_codes,0),6),"") -> 0.002020202 | O20: =IF(D20="Yes",INDEX(Crop_data,MATCH(A20,Crop_data_codes,0),12)/INDEX(Crop_data,MATCH(A20,Crop_data_codes,0),6),"") -> 0.001 | P20: =IF(D20="Yes",INDEX(Crop_data,MATCH(A20,Crop_data_codes,0),13)/INDEX(Crop_data,MATCH(A20,Crop_data_codes,0),6)*1000,"") -> 0.30808081 | Q20: =IF(D20="Yes",SUM(INDEX(Crop_data,MATCH(A20,Crop_data_codes,0),21):INDEX(Crop_data,MATCH(A20,Crop_data_codes,0),22):INDEX(Crop_data,MATCH(A20,Crop_data_codes,0),23):INDEX(Crop_data,MATCH(A20,Crop_data_codes,0),24):INDEX(Crop_data,MATCH(A20,Crop_data_codes,0),25))*(1/INDEX(Crop_data,MATCH(A20,Crop_data_codes,0),6)*10000)/(No_species/1000000),"") -> 4.1170786e-11 | R20: =IF(D20="Yes",INDEX(Crop_data,MATCH(A20,Crop_data_codes,0),7)/INDEX(Crop_data,MATCH(A20,Crop_data_codes,0),6)*EF_NH3*N_to_NH3,"") -> 6.140869e-05 | S20: =IF(D20="Yes",INDEX(Crop_data,MATCH(A20,Crop_data_codes,0),26)/INDEX(Crop_data,MATCH(A20,Crop_data_codes,0),6),"") -> 0.0069393939
A21: 01243 | B21: =INDEX(Crop_data,MATCH(A21,Crop_data_codes,0),2) -> Broad beans and horse beans, green | C21: =INDEX(Crop_data,MATCH(A21,Crop_data_codes,0),3) -> Vegetables | D21: =IF(INDEX(Crop_data,MATCH(A21,Crop_data_codes,0),6)>0,"Yes","No") -> No | F21: =IF(D21="Yes",INDEX(CO2e_data,MATCH(A21,CO2e_codes,0),1),"") | G21: =IF(D21="Yes",INDEX(CO2_data,MATCH(A21,CO2_codes,0),1),"") | H21: =IF(D21="Yes",INDEX(CH4_data,MATCH(A21,CH4_codes,0),1),"") | I21: =IF(D21="Yes",INDEX(CH4_bio_data,MATCH(A21,CH4_bio_codes,0),1),"") | J21: =IF(D21="Yes",INDEX(N2O_data,MATCH(A21,N2O_codes,0),1),"") | L21: =IF(D21="Yes",1/INDEX(Crop_data,MATCH(A21,Crop_data_codes,0),6)*10000,"") | M21: =IF(D21="Yes",(INDEX(Crop_data,MATCH(A21,Crop_data_codes,0),7)+INDEX(Crop_data,MATCH(A21,Crop_data_codes,0),8))/INDEX(Crop_data,MATCH(A21,Crop_data_codes,0),6),"") | N21: =IF(D21="Yes",INDEX(Crop_data,MATCH(A21,Crop_data_codes,0),10)/INDEX(Crop_data,MATCH(A21,Crop_data_codes,0),6),"") | O21: =IF(D21="Yes",INDEX(Crop_data,MATCH(A21,Crop_data_codes,0),12)/INDEX(Crop_data,MATCH(A21,Crop_data_codes,0),6),"") | P21: =IF(D21="Yes",INDEX(Crop_data,MATCH(A21,Crop_data_codes,0),13)/INDEX(Crop_data,MATCH(A21,Crop_data_codes,0),6)*1000,"") | Q21: =IF(D21="Yes",SUM(INDEX(Crop_data,MATCH(A21,Crop_data_codes,0),21):INDEX(Crop_data,MATCH(A21,Crop_data_codes,0),22):INDEX(Crop_data,MATCH(A21,Crop_data_codes,0),23):INDEX(Crop_data,MATCH(A21,Crop_data_codes,0),24):INDEX(Crop_data,MATCH(A21,Crop_data_codes,0),25))*(1/INDEX(Crop_data,MATCH(A21,Crop_data_codes,0),6)*10000)/(No_species/1000000),"") | R21: =IF(D21="Yes",INDEX(Crop_data,MATCH(A21,Crop_data_codes,0),7)/INDEX(Crop_data,MATCH(A21,Crop_data_codes,0),6)*EF_NH3*N_to_NH3,"") | S21: =IF(D21="Yes",INDEX(Crop_data,MATCH(A21,Crop_data_codes,0),26)/INDEX(Crop_data,MATCH(A21,Crop_data_codes,0),6),"")
A22: 01213_b | B22: =INDEX(Crop_data,MATCH(A22,Crop_data_codes,0),2) -> Broccoli | C22: =INDEX(Crop_data,MATCH(A22,Crop_data_codes,0),3) -> Vegetables | D22: =IF(INDEX(Crop_data,MATCH(A22,Crop_data_codes,0),6)>0,"Yes","No") -> Yes | E22: 40 | F22: =IF(D22="Yes",INDEX(CO2e_data,MATCH(A22,CO2e_codes,0),1),"") -> 0.39467025 | G22: =IF(D22="Yes",INDEX(CO2_data,MATCH(A22,CO2_codes,0),1),"") -> 0.15759026 | H22: =IF(D22="Yes",INDEX(CH4_data,MATCH(A22,CH4_codes,0),1),"") -> 0.00021954447 | I22: =IF(D22="Yes",INDEX(CH4_bio_data,MATCH(A22,CH4_bio_codes,0),1),"") -> 0 | J22: =IF(D22="Yes",INDEX(N2O_data,MATCH(A22,N2O_codes,0),1),"") -> 0.00084445993 | L22: =IF(D22="Yes",1/INDEX(Crop_data,MATCH(A22,Crop_data_codes,0),6)*10000,"") -> 1.4518002 | M22: =IF(D22="Yes",(INDEX(Crop_data,MATCH(A22,Crop_data_codes,0),7)+INDEX(Crop_data,MATCH(A22,Crop_data_codes,0),8))/INDEX(Crop_data,MATCH(A22,Crop_data_codes,0),6),"") -> 0.021777003 | N22: =IF(D22="Yes",INDEX(Crop_data,MATCH(A22,Crop_data_codes,0),10)/INDEX(Crop_data,MATCH(A22,Crop_data_codes,0),6),"") -> 0.0033311197 | O22: =IF(D22="Yes",INDEX(Crop_data,MATCH(A22,Crop_data_codes,0),12)/INDEX(Crop_data,MATCH(A22,Crop_data_codes,0),6),"") -> 0.034 | P22: =IF(D22="Yes",INDEX(Crop_data,MATCH(A22,Crop_data_codes,0),13)/INDEX(Crop_data,MATCH(A22,Crop_data_codes,0),6)*1000,"") -> 0.23954704 | Q22: =IF(D22="Yes",SUM(INDEX(Crop_data,MATCH(A22,Crop_data_codes,0),21):INDEX(Crop_data,MATCH(A22,Crop_data_codes,0),22):INDEX(Crop_data,MATCH(A22,Crop_data_codes,0),23):INDEX(Crop_data,MATCH(A22,Crop_data_codes,0),24):INDEX(Crop_data,MATCH(A22,Crop_data_codes,0),25))*(1/INDEX(Crop_data,MATCH(A22,Crop_data_codes,0),6)*10000)/(No_species/1000000),"") -> 1.1834808e-11 | R22: =IF(D22="Yes",INDEX(Crop_data,MATCH(A22,Crop_data_codes,0),7)/INDEX(Crop_data,MATCH(A22,Crop_data_codes,0),6)*EF_NH3*N_to_NH3,"") -> 0.0013239243 | S22: =IF(D22="Yes",INDEX(Crop_data,MATCH(A22,Crop_data_codes,0),26)/INDEX(Crop_data,MATCH(A22,Crop_data_codes,0),6),"") -> 0.036309524
A23: 01192 | B23: =INDEX(Crop_data,MATCH(A23,Crop_data_codes,0),2) -> Buckwheat | C23: =INDEX(Crop_data,MATCH(A23,Crop_data_codes,0),3) -> Seeds | D23: =IF(INDEX(Crop_data,MATCH(A23,Crop_data_codes,0),6)>0,"Yes","No") -> No | F23: =IF(D23="Yes",INDEX(CO2e_data,MATCH(A23,CO2e_codes,0),1),"") | G23: =IF(D23="Yes",INDEX(CO2_data,MATCH(A23,CO2_codes,0),1),"") | H23: =IF(D23="Yes",INDEX(CH4_data,MATCH(A23,CH4_codes,0),1),"") | I23: =IF(D23="Yes",INDEX(CH4_bio_data,MATCH(A23,CH4_bio_codes,0),1),"") | J23: =IF(D23="Yes",INDEX(N2O_data,MATCH(A23,N2O_codes,0),1),"") | L23: =IF(D23="Yes",1/INDEX(Crop_data,MATCH(A23,Crop_data_codes,0),6)*10000,"") | M23: =IF(D23="Yes",(INDEX(Crop_data,MATCH(A23,Crop_data_codes,0),7)+INDEX(Crop_data,MATCH(A23,Crop_data_codes,0),8))/INDEX(Crop_data,MATCH(A23,Crop_data_codes,0),6),"") | N23: =IF(D23="Yes",INDEX(Crop_data,MATCH(A23,Crop_data_codes,0),10)/INDEX(Crop_data,MATCH(A23,Crop_data_codes,0),6),"") | O23: =IF(D23="Yes",INDEX(Crop_data,MATCH(A23,Crop_data_codes,0),12)/INDEX(Crop_data,MATCH(A23,Crop_data_codes,0),6),"") | P23: =IF(D23="Yes",INDEX(Crop_data,MATCH(A23,Crop_data_codes,0),13)/INDEX(Crop_data,MATCH(A23,Crop_data_codes,0),6)*1000,"") | Q23: =IF(D23="Yes",SUM(INDEX(Crop_data,MATCH(A23,Crop_data_codes,0),21):INDEX(Crop_data,MATCH(A23,Crop_data_codes,0),22):INDEX(Crop_data,MATCH(A23,Crop_data_codes,0),23):INDEX(Crop_data,MATCH(A23,Crop_data_codes,0),24):INDEX(Crop_data,MATCH(A23,Crop_data_codes,0),25))*(1/INDEX(Crop_data,MATCH(A23,Crop_data_codes,0),6)*10000)/(No_species/1000000),"") | R23: =IF(D23="Yes",INDEX(Crop_data,MATCH(A23,Crop_data_codes,0),7)/INDEX(Crop_data,MATCH(A23,Crop_data_codes,0),6)*EF_NH3*N_to_NH3,"") | S23: =IF(D23="Yes",INDEX(Crop_data,MATCH(A23,Crop_data_codes,0),26)/INDEX(Crop_data,MATCH(A23,Crop_data_codes,0),6),"")
A24: 01212 | B24: =INDEX(Crop_data,MATCH(A24,Crop_data_codes,0),2) -> Cabbages | C24: =INDEX(Crop_data,MATCH(A24,Crop_data_codes,0),3) -> Vegetables | D24: =IF(INDEX(Crop_data,MATCH(A24,Crop_data_codes,0),6)>0,"Yes","No") -> Yes | F24: =IF(D24="Yes",INDEX(CO2e_data,MATCH(A24,CO2e_codes,0),1),"") -> 0.15132479 | G24: =IF(D24="Yes",INDEX(CO2_data,MATCH(A24,CO2_codes,0),1),"") -> 0.064836586 | H24: =IF(D24="Yes",INDEX(CH4_data,MATCH(A24,CH4_codes,0),1),"") -> 0.00013803061 | I24: =IF(D24="Yes",INDEX(CH4_bio_data,MATCH(A24,CH4_bio_codes,0),1),"") -> 0 | J24: =IF(D24="Yes",INDEX(N2O_data,MATCH(A24,N2O_codes,0),1),"") -> 0.00030173952 | L24: =IF(D24="Yes",1/INDEX(Crop_data,MATCH(A24,Crop_data_codes,0),6)*10000,"") -> 0.29833772 | M24: =IF(D24="Yes",(INDEX(Crop_data,MATCH(A24,Crop_data_codes,0),7)+INDEX(Crop_data,MATCH(A24,Crop_data_codes,0),8))/INDEX(Crop_data,MATCH(A24,Crop_data_codes,0),6),"") -> 0.0059667651 | N24: =IF(D24="Yes",INDEX(Crop_data,MATCH(A24,Crop_data_codes,0),10)/INDEX(Crop_data,MATCH(A24,Crop_data_codes,0),6),"") -> 0.00047734121 | O24: =IF(D24="Yes",INDEX(Crop_data,MATCH(A24,Crop_data_codes,0),12)/INDEX(Crop_data,MATCH(A24,Crop_data_codes,0),6),"") -> 0.034 | P24: =IF(D24="Yes",INDEX(Crop_data,MATCH(A24,Crop_data_codes,0),13)/INDEX(Crop_data,MATCH(A24,Crop_data_codes,0),6)*1000,"") -> 0.049225724 | Q24: =IF(D24="Yes",SUM(INDEX(Crop_data,MATCH(A24,Crop_data_codes,0),21):INDEX(Crop_data,MATCH(A24,Crop_data_codes,0),22):INDEX(Crop_data,MATCH(A24,Crop_data_codes,0),23):INDEX(Crop_data,MATCH(A24,Crop_data_codes,0),24):INDEX(Crop_data,MATCH(A24,Crop_data_codes,0),25))*(1/INDEX(Crop_data,MATCH(A24,Crop_data_codes,0),6)*10000)/(No_species/1000000),"") -> 2.4319941e-12 | R24: =IF(D24="Yes",INDEX(Crop_data,MATCH(A24,Crop_data_codes,0),7)/INDEX(Crop_data,MATCH(A24,Crop_data_codes,0),6)*EF_NH3*N_to_NH3,"") -> 0.00036274711 | S24: =IF(D24="Yes",INDEX(Crop_data,MATCH(A24,Crop_data_codes,0),26)/INDEX(Crop_data,MATCH(A24,Crop_data_codes,0),6),"") -> 0.0048927386
A25: 01229 | B25: =INDEX(Crop_data,MATCH(A25,Crop_data_codes,0),2) -> Cantaloupes and other melons | C25: =INDEX(Crop_data,MATCH(A25,Crop_data_codes,0),3) -> Fruits | D25: =IF(INDEX(Crop_data,MATCH(A25,Crop_data_codes,0),6)>0,"Yes","No") -> No | F25: =IF(D25="Yes",INDEX(CO2e_data,MATCH(A25,CO2e_codes,0),1),"") | G25: =IF(D25="Yes",INDEX(CO2_data,MATCH(A25,CO2_codes,0),1),"") | H25: =IF(D25="Yes",INDEX(CH4_data,MATCH(A25,CH4_codes,0),1),"") | I25: =IF(D25="Yes",INDEX(CH4_bio_data,MATCH(A25,CH4_bio_codes,0),1),"") | J25: =IF(D25="Yes",INDEX(N2O_data,MATCH(A25,N2O_codes,0),1),"") | L25: =IF(D25="Yes",1/INDEX(Crop_data,MATCH(A25,Crop_data_codes,0),6)*10000,"") | M25: =IF(D25="Yes",(INDEX(Crop_data,MATCH(A25,Crop_data_codes,0),7)+INDEX(Crop_data,MATCH(A25,Crop_data_codes,0),8))/INDEX(Crop_data,MATCH(A25,Crop_data_codes,0),6),"") | N25: =IF(D25="Yes",INDEX(Crop_data,MATCH(A25,Crop_data_codes,0),10)/INDEX(Crop_data,MATCH(A25,Crop_data_codes,0),6),"") | O25: =IF(D25="Yes",INDEX(Crop_data,MATCH(A25,Crop_data_codes,0),12)/INDEX(Crop_data,MATCH(A25,Crop_data_codes,0),6),"") | P25: =IF(D25="Yes",INDEX(Crop_data,MATCH(A25,Crop_data_codes,0),13)/INDEX(Crop_data,MATCH(A25,Crop_data_codes,0),6)*1000,"") | Q25: =IF(D25="Yes",SUM(INDEX(Crop_data,MATCH(A25,Crop_data_codes,0),21):INDEX(Crop_data,MATCH(A25,Crop_data_codes,0),22):INDEX(Crop_data,MATCH(A25,Crop_data_codes,0),23):INDEX(Crop_data,MATCH(A25,Crop_data_codes,0),24):INDEX(Crop_data,MATCH(A25,Crop_data_codes,0),25))*(1/INDEX(Crop_data,MATCH(A25,Crop_data_codes,0),6)*10000)/(No_species/1000000),"") | R25: =IF(D25="Yes",INDEX(Crop_data,MATCH(A25,Crop_data_codes,0),7)/INDEX(Crop_data,MATCH(A25,Crop_data_codes,0),6)*EF_NH3*N_to_NH3,"") | S25: =IF(D25="Yes",INDEX(Crop_data,MATCH(A25,Crop_data_codes,0),26)/INDEX(Crop_data,MATCH(A25,Crop_data_codes,0),6),"")
A26: 01251 | B26: =INDEX(Crop_data,MATCH(A26,Crop_data_codes,0),2) -> Carrots and turnips | C26: =INDEX(Crop_data,MATCH(A26,Crop_data_codes,0),3) -> Vegetables | D26: =IF(INDEX(Crop_data,MATCH(A26,Crop_data_codes,0),6)>0,"Yes","No") -> Yes | F26: =IF(D26="Yes",INDEX(CO2e_data,MATCH(A26,CO2e_codes,0),1),"") -> 0.068674823 | G26: =IF(D26="Yes",INDEX(CO2_data,MATCH(A26,CO2_codes,0),1),"") -> 0.045113215 | H26: =IF(D26="Yes",INDEX(CH4_data,MATCH(A26,CH4_codes,0),1),"") -> 0.00011743398 | I26: =IF(D26="Yes",INDEX(CH4_bio_data,MATCH(A26,CH4_bio_codes,0),1),"") -> 0 | J26: =IF(D26="Yes",INDEX(N2O_data,MATCH(A26,N2O_codes,0),1),"") -> 7.3487455e-05 | L26: =IF(D26="Yes",1/INDEX(Crop_data,MATCH(A26,Crop_data_codes,0),6)*10000,"") -> 0.16007427 | M26: =IF(D26="Yes",(INDEX(Crop_data,MATCH(A26,Crop_data_codes,0),7)+INDEX(Crop_data,MATCH(A26,Crop_data_codes,0),8))/INDEX(Crop_data,MATCH(A26,Crop_data_codes,0),6),"") -> 0.0013286165 | N26: =IF(D26="Yes",INDEX(Crop_data,MATCH(A26,Crop_data_codes,0),10)/INDEX(Crop_data,MATCH(A26,Crop_data_codes,0),6),"") -> 0.00047615694 | O26: =IF(D26="Yes",INDEX(Crop_data,MATCH(A26,Crop_data_codes,0),12)/INDEX(Crop_data,MATCH(A26,Crop_data_codes,0),6),"") -> 0.034 | P26: =IF(D26="Yes",INDEX(Crop_data,MATCH(A26,Crop_data_codes,0),13)/INDEX(Crop_data,MATCH(A26,Crop_data_codes,0),6)*1000,"") -> 0.035696563 | Q26: =IF(D26="Yes",SUM(INDEX(Crop_data,MATCH(A26,Crop_data_codes,0),21):INDEX(Crop_data,MATCH(A26,Crop_data_codes,0),22):INDEX(Crop_data,MATCH(A26,Crop_data_codes,0),23):INDEX(Crop_data,MATCH(A26,Crop_data_codes,0),24):INDEX(Crop_data,MATCH(A26,Crop_data_codes,0),25))*(1/INDEX(Crop_data,MATCH(A26,Crop_data_codes,0),6)*10000)/(No_species/1000000),"") -> 1.304896e-12 | R26: =IF(D26="Yes",INDEX(Crop_data,MATCH(A26,Crop_data_codes,0),7)/INDEX(Crop_data,MATCH(A26,Crop_data_codes,0),6)*EF_NH3*N_to_NH3,"") -> 8.0772711e-05 | S26: =IF(D26="Yes",INDEX(Crop_data,MATCH(A26,Crop_data_codes,0),26)/INDEX(Crop_data,MATCH(A26,Crop_data_codes,0),6),"") -> 0.00144387
A27: 01372 | B27: =INDEX(Crop_data,MATCH(A27,Crop_data_codes,0),2) -> Cashew nuts, in shell | C27: =INDEX(Crop_data,MATCH(A27,Crop_data_codes,0),3) -> Nuts | D27: =IF(INDEX(Crop_data,MATCH(A27,Crop_data_codes,0),6)>0,"Yes","No") -> No | F27: =IF(D27="Yes",INDEX(CO2e_data,MATCH(A27,CO2e_codes,0),1),"") | G27: =IF(D27="Yes",INDEX(CO2_data,MATCH(A27,CO2_codes,0),1),"") | H27: =IF(D27="Yes",INDEX(CH4_data,MATCH(A27,CH4_codes,0),1),"") | I27: =IF(D27="Yes",INDEX(CH4_bio_data,MATCH(A27,CH4_bio_codes,0),1),"") | J27: =IF(D27="Yes",INDEX(N2O_data,MATCH(A27,N2O_codes,0),1),"") | P27: =IF(D27="Yes",INDEX(Crop_data,MATCH(A27,Crop_data_codes,0),13)/INDEX(Crop_data,MATCH(A27,Crop_data_codes,0),6)*1000,"") | Q27: =IF(D27="Yes",SUM(INDEX(Crop_data,MATCH(A27,Crop_data_codes,0),21):INDEX(Crop_data,MATCH(A27,Crop_data_codes,0),22):INDEX(Crop_data,MATCH(A27,Crop_data_codes,0),23):INDEX(Crop_data,MATCH(A27,Crop_data_codes,0),24):INDEX(Crop_data,MATCH(A27,Crop_data_codes,0),25))*(1/INDEX(Crop_data,MATCH(A27,Crop_data_codes,0),6)*10000)/(No_species/1000000),"") | S27: =IF(D27="Yes",INDEX(Crop_data,MATCH(A27,Crop_data_codes,0),26)/INDEX(Crop_data,MATCH(A27,Crop_data_codes,0),6),"")
A28: 01213_cf | B28: =INDEX(Crop_data,MATCH(A28,Crop_data_codes,0),2) -> Cauliflowers | C28: =INDEX(Crop_data,MATCH(A28,Crop_data_codes,0),3) -> Vegetables | D28: =IF(INDEX(Crop_data,MATCH(A28,Crop_data_codes,0),6)>0,"Yes","No") -> Yes | E28: 60 | F28: =IF(D28="Yes",INDEX(CO2e_data,MATCH(A28,CO2e_codes,0),1),"") -> 0.27215527 | G28: =IF(D28="Yes",INDEX(CO2_data,MATCH(A28,CO2_codes,0),1),"") -> 0.10493009 | H28: =IF(D28="Yes",INDEX(CH4_data,MATCH(A28,CH4_codes,0),1),"") -> 0.00017751872 | I28: =IF(D28="Yes",INDEX(CH4_bio_data,MATCH(A28,CH4_bio_codes,0),1),"") -> 0 | J28: =IF(D28="Yes",INDEX(N2O_data,MATCH(A28,N2O_codes,0),1),"") -> 0.00059316895 | L28: =IF(D28="Yes",1/INDEX(Crop_data,MATCH(A28,Crop_data_codes,0),6)*10000,"") -> 0.6574622 | M28: =IF(D28="Yes",(INDEX(Crop_data,MATCH(A28,Crop_data_codes,0),7)+INDEX(Crop_data,MATCH(A28,Crop_data_codes,0),8))/INDEX(Crop_data,MATCH(A28,Crop_data_codes,0),6),"") -> 0.014464168 | N28: =IF(D28="Yes",INDEX(Crop_data,MATCH(A28,Crop_data_codes,0),10)/INDEX(Crop_data,MATCH(A28,Crop_data_codes,0),6),"") -> 0.0014059172 | O28: =IF(D28="Yes",INDEX(Crop_data,MATCH(A28,Crop_data_codes,0),12)/INDEX(Crop_data,MATCH(A28,Crop_data_codes,0),6),"") -> 0.034 | P28: =IF(D28="Yes",INDEX(Crop_data,MATCH(A28,Crop_data_codes,0),13)/INDEX(Crop_data,MATCH(A28,Crop_data_codes,0),6)*1000,"") -> 0.10848126 | Q28: =IF(D28="Yes",SUM(INDEX(Crop_data,MATCH(A28,Crop_data_codes,0),21):INDEX(Crop_data,MATCH(A28,Crop_data_codes,0),22):INDEX(Crop_data,MATCH(A28,Crop_data_codes,0),23):INDEX(Crop_data,MATCH(A28,Crop_data_codes,0),24):INDEX(Crop_data,MATCH(A28,Crop_data_codes,0),25))*(1/INDEX(Crop_data,MATCH(A28,Crop_data_codes,0),6)*10000)/(No_species/1000000),"") -> 5.3595106e-12 | R28: =IF(D28="Yes",INDEX(Crop_data,MATCH(A28,Crop_data_codes,0),7)/INDEX(Crop_data,MATCH(A28,Crop_data_codes,0),6)*EF_NH3*N_to_NH3,"") -> 0.00087934337 | S28: =IF(D28="Yes",INDEX(Crop_data,MATCH(A28,Crop_data_codes,0),26)/INDEX(Crop_data,MATCH(A28,Crop_data_codes,0),6),"") -> 0.01644313
A29: 01213 | B29: =INDEX(Crop_data,MATCH(A29,Crop_data_codes,0),2) -> Cauliflowers and broccoli, average | C29: =INDEX(Crop_data,MATCH(A29,Crop_data_codes,0),3) -> Vegetables | D29: =IF(INDEX(Crop_data,MATCH(A29,Crop_data_codes,0),6)>0,"Yes","No") -> Yes | F29: =IF(D29="Yes",INDEX(CO2e_data,MATCH(A29,CO2e_codes,0),1),"") -> 0.30051533 | G29: =IF(D29="Yes",INDEX(CO2_data,MATCH(A29,CO2_codes,0),1),"") -> 0.11714315 | H29: =IF(D29="Yes",INDEX(CH4_data,MATCH(A29,CH4_codes,0),1),"") -> 0.00018726562 | I29: =IF(D29="Yes",INDEX(CH4_bio_data,MATCH(A29,CH4_bio_codes,0),1),"") -> 0 | J29: =IF(D29="Yes",INDEX(N2O_data,MATCH(A29,N2O_codes,0),1),"") -> 0.00065125155 | L29: =IF(D29="Yes",1/INDEX(Crop_data,MATCH(A29,Crop_data_codes,0),6)*10000,"") -> 0.84167999 | M29: =IF(D29="Yes",(INDEX(Crop_data,MATCH(A29,Crop_data_codes,0),7)+INDEX(Crop_data,MATCH(A29,Crop_data_codes,0),8))/INDEX(Crop_data,MATCH(A29,Crop_data_codes,0),6),"") -> 0.016160256 | N29: =IF(D29="Yes",INDEX(Crop_data,MATCH(A29,Crop_data_codes,0),10)/INDEX(Crop_data,MATCH(A29,Crop_data_codes,0),6),"") -> 0.001851696 | O29: =IF(D29="Yes",INDEX(Crop_data,MATCH(A29,Crop_data_codes,0),12)/INDEX(Crop_data,MATCH(A29,Crop_data_codes,0),6),"") -> 0.034 | P29: =IF(D29="Yes",INDEX(Crop_data,MATCH(A29,Crop_data_codes,0),13)/INDEX(Crop_data,MATCH(A29,Crop_data_codes,0),6)*1000,"") -> 0.1388772 | Q29: =IF(D29="Yes",SUM(INDEX(Crop_data,MATCH(A29,Crop_data_codes,0),21):INDEX(Crop_data,MATCH(A29,Crop_data_codes,0),22):INDEX(Crop_data,MATCH(A29,Crop_data_codes,0),23):INDEX(Crop_data,MATCH(A29,Crop_data_codes,0),24):INDEX(Crop_data,MATCH(A29,Crop_data_codes,0),25))*(1/INDEX(Crop_data,MATCH(A29,Crop_data_codes,0),6)*10000)/(No_species/1000000),"") -> 6.8612201e-12 | R29: =IF(D29="Yes",INDEX(Crop_data,MATCH(A29,Crop_data_codes,0),7)/INDEX(Crop_data,MATCH(A29,Crop_data_codes,0),6)*EF_NH3*N_to_NH3,"") -> 0.00098245634 | S29: =IF(D29="Yes",INDEX(Crop_data,MATCH(A29,Crop_data_codes,0),26)/INDEX(Crop_data,MATCH(A29,Crop_data_codes,0),6),"") -> 0.021050417
A30: 01199.90 | B30: =INDEX(Crop_data,MATCH(A30,Crop_data_codes,0),2) -> Cereals n.e.c. | C30: =INDEX(Crop_data,MATCH(A30,Crop_data_codes,0),3) -> Cereals | D30: =IF(INDEX(Crop_data,MATCH(A30,Crop_data_codes,0),6)>0,"Yes","No") -> No | F30: =IF(D30="Yes",INDEX(CO2e_data,MATCH(A30,CO2e_codes,0),1),"") | G30: =IF(D30="Yes",INDEX(CO2_data,MATCH(A30,CO2_codes,0),1),"") | H30: =IF(D30="Yes",INDEX(CH4_data,MATCH(A30,CH4_codes,0),1),"") | I30: =IF(D30="Yes",INDEX(CH4_bio_data,MATCH(A30,CH4_bio_codes,0),1),"") | J30: =IF(D30="Yes",INDEX(N2O_data,MATCH(A30,N2O_codes,0),1),"") | L30: =IF(D30="Yes",1/INDEX(Crop_data,MATCH(A30,Crop_data_codes,0),6)*10000,"") | M30: =IF(D30="Yes",(INDEX(Crop_data,MATCH(A30,Crop_data_codes,0),7)+INDEX(Crop_data,MATCH(A30,Crop_data_codes,0),8))/INDEX(Crop_data,MATCH(A30,Crop_data_codes,0),6),"") | N30: =IF(D30="Yes",INDEX(Crop_data,MATCH(A30,Crop_data_codes,0),10)/INDEX(Crop_data,MATCH(A30,Crop_data_codes,0),6),"") | O30: =IF(D30="Yes",INDEX(Crop_data,MATCH(A30,Crop_data_codes,0),12)/INDEX(Crop_data,MATCH(A30,Crop_data_codes,0),6),"") | P30: =IF(D30="Yes",INDEX(Crop_data,MATCH(A30,Crop_data_codes,0),13)/INDEX(Crop_data,MATCH(A30,Crop_data_codes,0),6)*1000,"") | Q30: =IF(D30="Yes",SUM(INDEX(Crop_data,MATCH(A30,Crop_data_codes,0),21):INDEX(Crop_data,MATCH(A30,Crop_data_codes,0),22):INDEX(Crop_data,MATCH(A30,Crop_data_codes,0),23):INDEX(Crop_data,MATCH(A30,Crop_data_codes,0),24):INDEX(Crop_data,MATCH(A30,Crop_data_codes,0),25))*(1/INDEX(Crop_data,MATCH(A30,Crop_data_codes,0),6)*10000)/(No_species/1000000),"") | R30: =IF(D30="Yes",INDEX(Crop_data,MATCH(A30,Crop_data_codes,0),7)/INDEX(Crop_data,MATCH(A30,Crop_data_codes,0),6)*EF_NH3*N_to_NH3,"") | S30: =IF(D30="Yes",INDEX(Crop_data,MATCH(A30,Crop_data_codes,0),26)/INDEX(Crop_data,MATCH(A30,Crop_data_codes,0),6),"")
A31: 01344.02 | B31: =INDEX(Crop_data,MATCH(A31,Crop_data_codes,0),2) -> Cherries | C31: =INDEX(Crop_data,MATCH(A31,Crop_data_codes,0),3) -> Berries | D31: =IF(INDEX(Crop_data,MATCH(A31,Crop_data_codes,0),6)>0,"Yes","No") -> No | F31: =IF(D31="Yes",INDEX(CO2e_data,MATCH(A31,CO2e_codes,0),1),"") | G31: =IF(D31="Yes",INDEX(CO2_data,MATCH(A31,CO2_codes,0),1),"") | H31: =IF(D31="Yes",INDEX(CH4_data,MATCH(A31,CH4_codes,0),1),"") | I31: =IF(D31="Yes",INDEX(CH4_bio_data,MATCH(A31,CH4_bio_codes,0),1),"") | J31: =IF(D31="Yes",INDEX(N2O_data,MATCH(A31,N2O_codes,0),1),"") | L31: =IF(D31="Yes",1/INDEX(Crop_data,MATCH(A31,Crop_data_codes,0),6)*10000,"") | M31: =IF(D31="Yes",(INDEX(Crop_data,MATCH(A31,Crop_data_codes,0),7)+INDEX(Crop_data,MATCH(A31,Crop_data_codes,0),8))/INDEX(Crop_data,MATCH(A31,Crop_data_codes,0),6),"") | N31: =IF(D31="Yes",INDEX(Crop_data,MATCH(A31,Crop_data_codes,0),10)/INDEX(Crop_data,MATCH(A31,Crop_data_codes,0),6),"") | O31: =IF(D31="Yes",INDEX(Crop_data,MATCH(A31,Crop_data_codes,0),12)/INDEX(Crop_data,MATCH(A31,Crop_data_codes,0),6),"") | P31: =IF(D31="Yes",INDEX(Crop_data,MATCH(A31,Crop_data_codes,0),13)/INDEX(Crop_data,MATCH(A31,Crop_data_codes,0),6)*1000,"") | Q31: =IF(D31="Yes",SUM(INDEX(Crop_data,MATCH(A31,Crop_data_codes,0),21):INDEX(Crop_data,MATCH(A31,Crop_data_codes,0),22):INDEX(Crop_data,MATCH(A31,Crop_data_codes,0),23):INDEX(Crop_data,MATCH(A31,Crop_data_codes,0),24):INDEX(Crop_data,MATCH(A31,Crop_data_codes,0),25))*(1/INDEX(Crop_data,MATCH(A31,Crop_data_codes,0),6)*10000)/(No_species/1000000),"") | R31: =IF(D31="Yes",INDEX(Crop_data,MATCH(A31,Crop_data_codes,0),7)/INDEX(Crop_data,MATCH(A31,Crop_data_codes,0),6)*EF_NH3*N_to_NH3,"") | S31: =IF(D31="Yes",INDEX(Crop_data,MATCH(A31,Crop_data_codes,0),26)/INDEX(Crop_data,MATCH(A31,Crop_data_codes,0),6),"")
A32: 01373 | B32: =INDEX(Crop_data,MATCH(A32,Crop_data_codes,0),2) -> Chestnuts, in shell | C32: =INDEX(Crop_data,MATCH(A32,Crop_data_codes,0),3) -> Nuts | D32: =IF(INDEX(Crop_data,MATCH(A32,Crop_data_codes,0),6)>0,"Yes","No") -> No | F32: =IF(D32="Yes",INDEX(CO2e_data,MATCH(A32,CO2e_codes,0),1),"") | G32: =IF(D32="Yes",INDEX(CO2_data,MATCH(A32,CO2_codes,0),1),"") | H32: =IF(D32="Yes",INDEX(CH4_data,MATCH(A32,CH4_codes,0),1),"") | I32: =IF(D32="Yes",INDEX(CH4_bio_data,MATCH(A32,CH4_bio_codes,0),1),"") | J32: =IF(D32="Yes",INDEX(N2O_data,MATCH(A32,N2O_codes,0),1),"") | L32: =IF(D32="Yes",1/INDEX(Crop_data,MATCH(A32,Crop_data_codes,0),6)*10000,"") | M32: =IF(D32="Yes",(INDEX(Crop_data,MATCH(A32,Crop_data_codes,0),7)+INDEX(Crop_data,MATCH(A32,Crop_data_codes,0),8))/INDEX(Crop_data,MATCH(A32,Crop_data_codes,0),6),"") | N32: =IF(D32="Yes",INDEX(Crop_data,MATCH(A32,Crop_data_codes,0),10)/INDEX(Crop_data,MATCH(A32,Crop_data_codes,0),6),"") | O32: =IF(D32="Yes",INDEX(Crop_data,MATCH(A32,Crop_data_codes,0),12)/INDEX(Crop_data,MATCH(A32,Crop_data_codes,0),6),"") | P32: =IF(D32="Yes",INDEX(Crop_data,MATCH(A32,Crop_data_codes,0),13)/INDEX(Crop_data,MATCH(A32,Crop_data_codes,0),6)*1000,"") | Q32: =IF(D32="Yes",SUM(INDEX(Crop_data,MATCH(A32,Crop_data_codes,0),21):INDEX(Crop_data,MATCH(A32,Crop_data_codes,0),22):INDEX(Crop_data,MATCH(A32,Crop_data_codes,0),23):INDEX(Crop_data,MATCH(A32,Crop_data_codes,0),24):INDEX(Crop_data,MATCH(A32,Crop_data_codes,0),25))*(1/INDEX(Crop_data,MATCH(A32,Crop_data_codes,0),6)*10000)/(No_species/1000000),"") | R32: =IF(D32="Yes",INDEX(Crop_data,MATCH(A32,Crop_data_codes,0),7)/INDEX(Crop_data,MATCH(A32,Crop_data_codes,0),6)*EF_NH3*N_to_NH3,"") | S32: =IF(D32="Yes",INDEX(Crop_data,MATCH(A32,Crop_data_codes,0),26)/INDEX(Crop_data,MATCH(A32,Crop_data_codes,0),6),"")
A33: 01703 | B33: =INDEX(Crop_data,MATCH(A33,Crop_data_codes,0),2) -> Chick peas, dry | C33: =INDEX(Crop_data,MATCH(A33,Crop_data_codes,0),3) -> Pulses | D33: =IF(INDEX(Crop_data,MATCH(A33,Crop_data_codes,0),6)>0,"Yes","No") -> No | F33: =IF(D33="Yes",INDEX(CO2e_data,MATCH(A33,CO2e_codes,0),1),"") | G33: =IF(D33="Yes",INDEX(CO2_data,MATCH(A33,CO2_codes,0),1),"") | H33: =IF(D33="Yes",INDEX(CH4_data,MATCH(A33,CH4_codes,0),1),"") | I33: =IF(D33="Yes",INDEX(CH4_bio_data,MATCH(A33,CH4_bio_codes,0),1),"") | J33: =IF(D33="Yes",INDEX(N2O_data,MATCH(A33,N2O_codes,0),1),"") | L33: =IF(D33="Yes",1/INDEX(Crop_data,MATCH(A33,Crop_data_codes,0),6)*10000,"") | M33: =IF(D33="Yes",(INDEX(Crop_data,MATCH(A33,Crop_data_codes,0),7)+INDEX(Crop_data,MATCH(A33,Crop_data_codes,0),8))/INDEX(Crop_data,MATCH(A33,Crop_data_codes,0),6),"") | N33: =IF(D33="Yes",INDEX(Crop_data,MATCH(A33,Crop_data_codes,0),10)/INDEX(Crop_data,MATCH(A33,Crop_data_codes,0),6),"") | O33: =IF(D33="Yes",INDEX(Crop_data,MATCH(A33,Crop_data_codes,0),12)/INDEX(Crop_data,MATCH(A33,Crop_data_codes,0),6),"") | P33: =IF(D33="Yes",INDEX(Crop_data,MATCH(A33,Crop_data_codes,0),13)/INDEX(Crop_data,MATCH(A33,Crop_data_codes,0),6)*1000,"") | Q33: =IF(D33="Yes",SUM(INDEX(Crop_data,MATCH(A33,Crop_data_codes,0),21):INDEX(Crop_data,MATCH(A33,Crop_data_codes,0),22):INDEX(Crop_data,MATCH(A33,Crop_data_codes,0),23):INDEX(Crop_data,MATCH(A33,Crop_data_codes,0),24):INDEX(Crop_data,MATCH(A33,Crop_data_codes,0),25))*(1/INDEX(Crop_data,MATCH(A33,Crop_data_codes,0),6)*10000)/(No_species/1000000),"") | R33: =IF(D33="Yes",INDEX(Crop_data,MATCH(A33,Crop_data_codes,0),7)/INDEX(Crop_data,MATCH(A33,Crop_data_codes,0),6)*EF_NH3*N_to_NH3,"") | S33: =IF(D33="Yes",INDEX(Crop_data,MATCH(A33,Crop_data_codes,0),26)/INDEX(Crop_data,MATCH(A33,Crop_data_codes,0),6),"")
A34: 01231 | B34: =INDEX(Crop_data,MATCH(A34,Crop_data_codes,0),2) -> Chillies and peppers, green (Capsicum spp. and Pimenta spp.), raw | C34: =INDEX(Crop_data,MATCH(A34,Crop_data_codes,0),3) -> Spices | D34: =IF(INDEX(Crop_data,MATCH(A34,Crop_data_codes,0),6)>0,"Yes","No") -> No | F34: =IF(D34="Yes",INDEX(CO2e_data,MATCH(A34,CO2e_codes,0),1),"") | G34: =IF(D34="Yes",INDEX(CO2_data,MATCH(A34,CO2_codes,0),1),"") | H34: =IF(D34="Yes",INDEX(CH4_data,MATCH(A34,CH4_codes,0),1),"") | I34: =IF(D34="Yes",INDEX(CH4_bio_data,MATCH(A34,CH4_bio_codes,0),1),"") | J34: =IF(D34="Yes",INDEX(N2O_data,MATCH(A34,N2O_codes,0),1),"") | L34: =IF(D34="Yes",1/INDEX(Crop_data,MATCH(A34,Crop_data_codes,0),6)*10000,"") | M34: =IF(D34="Yes",(INDEX(Crop_data,MATCH(A34,Crop_data_codes,0),7)+INDEX(Crop_data,MATCH(A34,Crop_data_codes,0),8))/INDEX(Crop_data,MATCH(A34,Crop_data_codes,0),6),"") | N34: =IF(D34="Yes",INDEX(Crop_data,MATCH(A34,Crop_data_codes,0),10)/INDEX(Crop_data,MATCH(A34,Crop_data_codes,0),6),"") | O34: =IF(D34="Yes",INDEX(Crop_data,MATCH(A34,Crop_data_codes,0),12)/INDEX(Crop_data,MATCH(A34,Crop_data_codes,0),6),"") | P34: =IF(D34="Yes",INDEX(Crop_data,MATCH(A34,Crop_data_codes,0),13)/INDEX(Crop_data,MATCH(A34,Crop_data_codes,0),6)*1000,"") | Q34: =IF(D34="Yes",SUM(INDEX(Crop_data,MATCH(A34,Crop_data_codes,0),21):INDEX(Crop_data,MATCH(A34,Crop_data_codes,0),22):INDEX(Crop_data,MATCH(A34,Crop_data_codes,0),23):INDEX(Crop_data,MATCH(A34,Crop_data_codes,0),24):INDEX(Crop_data,MATCH(A34,Crop_data_codes,0),25))*(1/INDEX(Crop_data,MATCH(A34,Crop_data_codes,0),6)*10000)/(No_species/1000000),"") | R34: =IF(D34="Yes",INDEX(Crop_data,MATCH(A34,Crop_data_codes,0),7)/INDEX(Crop_data,MATCH(A34,Crop_data_codes,0),6)*EF_NH3*N_to_NH3,"") | S34: =IF(D34="Yes",INDEX(Crop_data,MATCH(A34,Crop_data_codes,0),26)/INDEX(Crop_data,MATCH(A34,Crop_data_codes,0),6),"")
