Workbook
Name Ability_to_perceive_handling: #REF!
Name BGBE: #REF!
Name Boars_per_sow: #REF!
Name Bonefree_outof_CW_AT: #REF!
Name Bonefree_outof_CW_BE: #REF!
Name Bonefree_outof_CW_BG: #REF!
Name Bonefree_outof_CW_BR: #REF!
Name Bonefree_outof_CW_CY: #REF!
Name Bonefree_outof_CW_CZ: #REF!
Name Bonefree_outof_CW_DE: #REF!
Name Bonefree_outof_CW_DK: #REF!
Name Bonefree_outof_CW_EE: #REF!
Name Bonefree_outof_CW_ES: #REF!
Name Bonefree_outof_CW_FI: #REF!
Name Bonefree_outof_CW_FR: #REF!
Name Bonefree_outof_CW_GB: #REF!
Name Bonefree_outof_CW_GR: #REF!
Name Bonefree_outof_CW_HR: #REF!
Name Bonefree_outof_CW_HU: #REF!
Name Bonefree_outof_CW_IE: #REF!
Name Bonefree_outof_CW_IT: #REF!
Name Bonefree_outof_CW_LT: #REF!
Name Bonefree_outof_CW_LV: #REF!
Name Bonefree_outof_CW_MT: #REF!
Name Bonefree_outof_CW_NL: #REF!
Name Bonefree_outof_CW_PL: #REF!
Name Bonefree_outof_CW_PT: #REF!
Name Bonefree_outof_CW_RO: #REF!
Name Bonefree_outof_CW_SE: #REF!
Name Bonefree_outof_CW_SI: #REF!
Name Bonefree_outof_CW_SK: #REF!
Name Bonefree_outof_CW_TH: #REF!
Name Bonefree_outof_CW_US: #REF!
Name CF_GWP_CH4_fossil: #REF!
Name CF_GWP_N2O: #REF!
Name CY: #REF!
Name EF_ammonia_AT: #REF!
Name EF_ammonia_BE: #REF!
Name EF_ammonia_BG: #REF!
Name EF_ammonia_BR: #REF!
Name EF_ammonia_CY: #REF!
Name EF_ammonia_CZ: #REF!
Name EF_ammonia_DE: #REF!
Name EF_ammonia_DK: #REF!
Name EF_ammonia_EE: #REF!
Name EF_ammonia_ES: #REF!
Name EF_ammonia_FI: #REF!
Name EF_ammonia_FR: #REF!
Name EF_ammonia_GB: #REF!
Name EF_ammonia_GR: #REF!
Name EF_ammonia_HR: #REF!
Name EF_ammonia_HU: #REF!
Name EF_ammonia_IE: #REF!
Name EF_ammonia_IT: #REF!
Name EF_ammonia_LT: #REF!
Name EF_ammonia_LV: #REF!
Name EF_ammonia_MT: #REF!
Name EF_ammonia_NL: #REF!
Name EF_ammonia_PL: #REF!
Name EF_ammonia_PT: #REF!

Sheet README
A2: Read me
A4: This is a file that contains the environmental footprint data from beef.
A6: Beef comes from a range of different systems with great variation in impact.
A7: Here we assess the beef footprint based on beef from the following sources:
A8: 1. Culled dairy cows
A9: 2. Suckler herds (meat from both the mother animal and the offspring assumed to be raised at 'medium intensity')
A10: 3. Dairy calves slaughtered at young age raised at high intensity
A11: 4. Dairy offspring raise at 'medium intensity' and slaughtered at a higher age
A13: We calculate the share of meat that comes from these different systems for the different countries based on data from Eurostat (see tab 'Shares in prod syst')
A15: These shares are used to establish a weighted average of the footprints per kg of beef.
A17: The different footprints are gathered from the following sources:
A19: Climate, land use, ammonia | C19: Ahlgren et al. (2022) using the following systems to represent the different production systems above:
C20: 1. Calculated in Milk.xlsx (but for now 3 is used)
C21: 2. Köttrasstut, Gsk
C22: 3. Mjölkrastjur, Gsk
C23: 4. Mjölkrasstut, Gsk
A24: N and P input, pesticides | C24: From Moberg et al (2021) Table S6
A25: Water | C25: From Mekonnen et al (2011)
A26: Biodiversity | C26: Ludvig
A27: Animal welfare | C27: Calculated for each system and aggregated based on the shares of production systems in different countries
A28: Antibiotics | C28: ???
A31: Color codes:
B33: Results
B34: Sheets for input
B35: Intermediate calculations

Sheet Footprints, results per kg
A2: Footprints (per kg of bonefree meat) | M2: * Adjusted for manure
M3: Att göra | N3: Att göra | P3: Att göra | Q3: Beräkna utifrån nya markanvändningen men måste få med betet också
A5: Animal products | F5: Climate | L5: Land | M5: Nitrogen* | N5: Phosphorus | O5: Water | P5: Pesticides | Q5: Biodiversity | R5: Ammonia | S5: Labour | T5: Animal welfare | U5: Use of antibiotics
A6: Code | B6: Name | C6: Category | D6: Country | E6: Country code | F6: Carbon footprint, kg CO2e/kg | G6: Carbon dioxide, kg CO2/kg | H6: Methane, fossil, kg CH4/kg | I6: Methane, biogenic, kg CH4/kg | J6: Nitrous oxide, kg N2O/kg | K6: HFCs, kg HFCs/kg | L6: Cropland use, m2/kg | M6: New N input, kg N/kg | N6: New P input, kg P/kg | O6: Blue freshwater use, m3/kg | P6: Pesticide use, g a.i./kg | Q6: Extinction rate, E/MSY/kg | R6: Ammonia emission, kg NH3/kg | S6: Labour requirements, h/kg | T6: Animal welfare index per kg of bonefree meat
A7: 21111.02 | B7: Bovine meat | C7: Red meat | D7: Denmark | E7: DK | F7: ='GHG detailed, results per kg'!G11 -> 24.491332 | G7: ='GHG detailed, results per kg'!G7 -> 3.6306623 | H7: ='GHG detailed, results per kg'!G8 -> 0 | I7: ='GHG detailed, results per kg'!G9 -> 0.52822121 | J7: ='GHG detailed, results per kg'!G10 -> 0.024171053 | L7: =('Shares in prod syst'!$B$46*'Data from Ahlgren et al'!$K$8+'Shares in prod syst'!$B$47*'Data from Ahlgren et al'!$K$12+'Shares in prod syst'!$B$48*'Data from Ahlgren et al'!$K$20+'Shares in prod syst'!$B$49*'Data from Ahlgren et al'!$K$8)/0.7 -> 27.381064 | M7: 0.39287936 | N7: 0.015901371 | O7: =([1]Production!$B$5*'[1]Parameters, country spec'!$B$51*'[1]EFP per kg feed'!I20+([1]Production!$B$6+[1]Production!$B$7)*'[1]Parameters, country spec'!$B$52*'[1]EFP per kg feed'!I21)/[1]Production!$B$21 -> 23.183337 | P7: 0.81908393 | Q7: 2.2515202e-09 | R7: 0.21242026 | T7: ='Shares in prod syst'!B55 -> 0.015511432 | U7: 19.4
A8: 21111.02 | B8: Bovine meat | C8: Red meat | D8: France | E8: FR | F8: ='GHG detailed, results per kg'!G16 -> 30.653248 | G8: ='GHG detailed, results per kg'!G12 -> 4.2563774 | H8: ='GHG detailed, results per kg'!G13 -> 0 | I8: ='GHG detailed, results per kg'!G14 -> 0.675642 | J8: ='GHG detailed, results per kg'!G15 -> 0.029870097 | L8: =('Shares in prod syst'!$C$46*'Data from Ahlgren et al'!$K$8+'Shares in prod syst'!$C$47*'Data from Ahlgren et al'!$K$12+'Shares in prod syst'!$C$48*'Data from Ahlgren et al'!$K$20+'Shares in prod syst'!$C$49*'Data from Ahlgren et al'!$K$8)/0.7 -> 28.435205 | M8: 0.4844356 | N8: 0.03806657 | O8: =([1]Production!$C$5*'[1]Parameters, country spec'!$C$51*'[1]EFP per kg feed'!I36+([1]Production!$C$6+[1]Production!$C$7)*'[1]Parameters, country spec'!$C$52*'[1]EFP per kg feed'!I37)/[1]Production!C21 -> 73.351292 | P8: 1.7710491 | Q8: 1.4163738e-08 | R8: 0.21144096 | T8: ='Shares in prod syst'!C55 -> 0.015018662 | U8: 38.1
A9: 21111.02 | B9: Bovine meat | C9: Red meat | D9: Germany | E9: DE | F9: ='GHG detailed, results per kg'!G21 -> 27.640825 | G9: ='GHG detailed, results per kg'!G17 -> 3.863894 | H9: ='GHG detailed, results per kg'!G18 -> 0 | I9: ='GHG detailed, results per kg'!G19 -> 0.60987053 | J9: ='GHG detailed, results per kg'!G20 -> 0.02677812 | L9: =('Shares in prod syst'!$D$46*'Data from Ahlgren et al'!$K$8+'Shares in prod syst'!$D$47*'Data from Ahlgren et al'!$K$12+'Shares in prod syst'!$D$48*'Data from Ahlgren et al'!$K$20+'Shares in prod syst'!$D$49*'Data from Ahlgren et al'!$K$8)/0.7 -> 25.551047 | M9: 0.39972859 | N9: 0.019914925 | O9: =([1]Production!$D$5*'[1]Parameters, country spec'!$D$51*'[1]EFP per kg feed'!I52+([1]Production!$D$6+[1]Production!$D$7)*'[1]Parameters, country spec'!$D$52*'[1]EFP per kg feed'!I53)/[1]Production!$D$21 -> 20.817882 | P9: 1.0667984 | Q9: 2.1447671e-09 | R9: 0.23798811 | T9: ='Shares in prod syst'!D55 -> 0.015002948 | U9: 50.4
A10: 21111.02 | B10: Bovine meat | C10: Red meat | D10: Greece | E10: GR | F10: ='GHG detailed, results per kg'!G26 -> 32.102287 | G10: ='GHG detailed, results per kg'!G22 -> 4.3652178 | H10: ='GHG detailed, results per kg'!G23 -> 0 | I10: ='GHG detailed, results per kg'!G24 -> 0.71556993 | J10: ='GHG detailed, results per kg'!G25 -> 0.030830334 | L10: =('Shares in prod syst'!$E$46*'Data from Ahlgren et al'!$K$8+'Shares in prod syst'!$E$47*'Data from Ahlgren et al'!$K$12+'Shares in prod syst'!$E$48*'Data from Ahlgren et al'!$K$20+'Shares in prod syst'!$E$49*'Data from Ahlgren et al'!$K$8)/0.7 -> 28.761705 | M10: 0.7703812 | N10: 0.086791142 | O10: =([1]Production!$E$5*'[1]Parameters, country spec'!$E$51*'[1]EFP per kg feed'!I68+([1]Production!$E$6+[1]Production!$E$7)*'[1]Parameters, country spec'!$E$52*'[1]EFP per kg feed'!I69)/[1]Production!$E$21 -> 171.27636 | P10: 2.1588876 | Q10: 1.8194035e-07 | R10: 0.25261273 | T10: ='Shares in prod syst'!E55 -> 0.017647318 | U10: 111.7
A11: 21111.02 | B11: Bovine meat | C11: Red meat | D11: Hungary | E11: HU | F11: ='GHG detailed, results per kg'!G31 -> 27.457044 | G11: ='GHG detailed, results per kg'!G27 -> 3.9270738 | H11: ='GHG detailed, results per kg'!G28 -> 0 | I11: ='GHG detailed, results per kg'!G29 -> 0.59951948 | J11: ='GHG detailed, results per kg'!G30 -> 0.026897231 | L11: =('Shares in prod syst'!$F$46*'Data from Ahlgren et al'!$K$8+'Shares in prod syst'!$F$47*'Data from Ahlgren et al'!$K$12+'Shares in prod syst'!$F$48*'Data from Ahlgren et al'!$K$20+'Shares in prod syst'!$F$49*'Data from Ahlgren et al'!$K$8)/0.7 -> 27.758651 | M11: 0.78493395 | N11: 0.063892939 | O11: =([1]Production!$F$5*'[1]Parameters, country spec'!$F$51*'[1]EFP per kg feed'!I84+([1]Production!$F$6+[1]Production!$F$7)*'[1]Parameters, country spec'!$F$52*'[1]EFP per kg feed'!I85)/[1]Production!$F$21 -> 6.4058135 | P11: 2.5117464 | Q11: 4.619002e-09 | R11: 0.2560465 | T11: ='Shares in prod syst'!F55 -> 0.016337906 | U11: 102.5
A12: 21111.02 | B12: Bovine meat | C12: Red meat | D12: Ireland | E12: IE | F12: ='GHG detailed, results per kg'!G36 -> 32.478388 | G12: ='GHG detailed, results per kg'!G32 -> 4.3879948 | H12: ='GHG detailed, results per kg'!G33 -> 0 | I12: ='GHG detailed, results per kg'!G34 -> 0.72321564 | J12: ='GHG detailed, results per kg'!G35 -> 0.031368392 | L12: =('Shares in prod syst'!$G$46*'Data from Ahlgren et al'!$K$8+'Shares in prod syst'!$G$47*'Data from Ahlgren et al'!$K$12+'Shares in prod syst'!$G$48*'Data from Ahlgren et al'!$K$20+'Shares in prod syst'!$G$49*'Data from Ahlgren et al'!$K$8)/0.7 -> 27.277828 | M12: 0.59205666 | N12: 0.03635779 | O12: =([1]Production!$G$5*'[1]Parameters, country spec'!$G$51*'[1]EFP per kg feed'!I100+([1]Production!$G$6+[1]Production!$G$7)*'[1]Parameters, country spec'!$G$52*'[1]EFP per kg feed'!I101)/[1]Production!$G$21 -> 10.484319 | P12: 3.1877282 | Q12: 1.4763208e-09 | R12: 0.21090107 | T12: ='Shares in prod syst'!G55 -> 0.013176995 | U12: 40.6
A13: 21111.02 | B13: Bovine meat | C13: Red meat | D13: Italy | E13: IT | F13: ='GHG detailed, results per kg'!G41 -> 28.042385 | G13: ='GHG detailed, results per kg'!G37 -> 3.9003357 | H13: ='GHG detailed, results per kg'!G38 -> 0 | I13: ='GHG detailed, results per kg'!G39 -> 0.61979304 | J13: ='GHG detailed, results per kg'!G40 -> 0.027134204 | L13: =('Shares in prod syst'!$H$46*'Data from Ahlgren et al'!$K$8+'Shares in prod syst'!$H$47*'Data from Ahlgren et al'!$K$12+'Shares in prod syst'!$H$48*'Data from Ahlgren et al'!$K$20+'Shares in prod syst'!$H$49*'Data from Ahlgren et al'!$K$8)/0.7 -> 25.501147 | M13: 0.56074497 | N13: 0.034194009 | O13: =([1]Production!$H$5*'[1]Parameters, country spec'!$H$51*'[1]EFP per kg feed'!I116+([1]Production!$H$6+[1]Production!$H$7)*'[1]Parameters, country spec'!$H$52*'[1]EFP per kg feed'!I117)/[1]Production!$H$21 -> 67.848745 | P13: 1.9859225 | Q13: 5.7557651e-08 | R13: 0.33933506 | T13: ='Shares in prod syst'!H55 -> 0.018516204 | U13: 129.1
A14: 21111.02 | B14: Bovine meat | C14: Red meat | D14: Netherlands | E14: NL | F14: ='GHG detailed, results per kg'!G46 -> 20.197475 | G14: ='GHG detailed, results per kg'!G42 -> 3.2080793 | H14: ='GHG detailed, results per kg'!G43 -> 0 | I14: ='GHG detailed, results per kg'!G44 -> 0.42451506 | J14: ='GHG detailed, results per kg'!G45 -> 0.020247213 | L14: =('Shares in prod syst'!$I$46*'Data from Ahlgren et al'!$K$8+'Shares in prod syst'!$I$47*'Data from Ahlgren et al'!$K$12+'Shares in prod syst'!$I$48*'Data from Ahlgren et al'!$K$20+'Shares in prod syst'!$I$49*'Data from Ahlgren et al'!$K$8)/0.7 -> 27.014168 | M14: 1.0370691 | N14: 0.025728359 | O14: =([1]Production!$I$5*'[1]Parameters, country spec'!$I$51*'[1]EFP per kg feed'!I132+([1]Production!$I$6+[1]Production!$I$7)*'[1]Parameters, country spec'!$I$52*'[1]EFP per kg feed'!I133)/[1]Production!$I$21 -> 23.514263 | P14: 2.1230752 | Q14: 3.6414625e-09 | R14: 0.17542994 | T14: ='Shares in prod syst'!I55 -> 0.021441076 | U14: 32.1
A15: 21111.02 | B15: Bovine meat | C15: Red meat | D15: Poland | E15: PL | F15: ='GHG detailed, results per kg'!G51 -> 26.501178 | G15: ='GHG detailed, results per kg'!G47 -> 3.6958259 | H15: ='GHG detailed, results per kg'!G38 -> 0 | I15: ='GHG detailed, results per kg'!G49 -> 0.58641304 | J15: ='GHG detailed, results per kg'!G50 -> 0.025539195 | L15: =('Shares in prod syst'!$J$46*'Data from Ahlgren et al'!$K$8+'Shares in prod syst'!$J$47*'Data from Ahlgren et al'!$K$12+'Shares in prod syst'!$J$48*'Data from Ahlgren et al'!$K$20+'Shares in prod syst'!$J$49*'Data from Ahlgren et al'!$K$8)/0.7 -> 23.924102 | M15: 0.62792157 | N15: 0.053780363 | O15: =([1]Production!$J$5*'[1]Parameters, country spec'!$J$51*'[1]EFP per kg feed'!I148+([1]Production!$J$6+[1]Production!$J$7)*'[1]Parameters, country spec'!$J$52*'[1]EFP per kg feed'!I149)/[1]Production!$J$21 -> 8.8326623 | P15: 2.7832697 | Q15: 4.3043857e-09 | R15: 0.27758662 | T15: ='Shares in prod syst'!J55 -> 0.016488161 | U15: 134.7
A16: 21111.02 | B16: Bovine meat | C16: Red meat | D16: Spain | E16: ES | F16: ='GHG detailed, results per kg'!G56 -> 31.536945 | G16: ='GHG detailed, results per kg'!G52 -> 4.3646161 | H16: ='GHG detailed, results per kg'!G53 -> 0 | I16: ='GHG detailed, results per kg'!G54 -> 0.69543787 | J16: ='GHG detailed, results per kg'!G55 -> 0.030752771 | L16: =('Shares in prod syst'!$K$46*'Data from Ahlgren et al'!$K$8+'Shares in prod syst'!$K$47*'Data from Ahlgren et al'!$K$12+'Shares in prod syst'!$K$48*'Data from Ahlgren et al'!$K$20+'Shares in prod syst'!$K$49*'Data from Ahlgren et al'!$K$8)/0.7 -> 29.092595 | M16: 0.6986156 | N16: 0.06674488 | O16: =([1]Production!$K$5*'[1]Parameters, country spec'!$K$51*'[1]EFP per kg feed'!I164+([1]Production!$K$6+[1]Production!$K$7)*'[1]Parameters, country spec'!$K$52*'[1]EFP per kg feed'!I165)/[1]Production!$K$21 -> 176.74609 | P16: 2.6239911 | Q16: 1.6644677e-07 | R16: 0.1814084 | T16: ='Shares in prod syst'!K55 -> 0.016086334 | U16: 95.7
A17: 21111.02 | B17: Bovine meat | C17: Red meat | D17: Sweden | E17: SE | F17: ='GHG detailed, results per kg'!G61 -> 32.35646 | G17: ='GHG detailed, results per kg'!G57 -> 4.4044399 | H17: ='GHG detailed, results per kg'!G58 -> 0 | I17: ='GHG detailed, results per kg'!G59 -> 0.7182014 | J17: ='GHG detailed, results per kg'!G60 -> 0.031357445 | L17: =('Shares in prod syst'!$L$46*'Data from Ahlgren et al'!$K$8+'Shares in prod syst'!$L$47*'Data from Ahlgren et al'!$K$12+'Shares in prod syst'!$L$48*'Data from Ahlgren et al'!$K$20+'Shares in prod syst'!$L$49*'Data from Ahlgren et al'!$K$8)/0.7 -> 28.045604 | M17: 0.74075572 | N17: 0.0060849689 | O17: =([1]Production!$L$5*'[1]Parameters, country spec'!$L$51*'[1]EFP per kg feed'!I180+([1]Production!$L$6+[1]Production!$L$7)*'[1]Parameters, country spec'!$L$52*'[1]EFP per kg feed'!I181)/[1]Production!$L$21 -> 0.022770162 | P17: 0.017649507 | Q17: -4.3908668e-09 | R17: 0.20378096 | T17: ='Shares in prod syst'!L55 -> 0.011209704 | U17: 10.1
A18: 21111.02 | B18: Bovine meat | C18: Red meat | D18: UK | E18: GB | F18: ='GHG detailed, results per kg'!G66 -> 33.581689 | G18: ='GHG detailed, results per kg'!G62 -> 4.5211218 | H18: ='GHG detailed, results per kg'!G63 -> 0 | I18: ='GHG detailed, results per kg'!G64 -> 0.7480771 | J18: ='GHG detailed, results per kg'!G65 -> 0.032463316 | L18: =('Shares in prod syst'!$M$46*'Data from Ahlgren et al'!$K$8+'Shares in prod syst'!$M$47*'Data from Ahlgren et al'!$K$12+'Shares in prod syst'!$M$48*'Data from Ahlgren et al'!$K$20+'Shares in prod syst'!$M$49*'Data from Ahlgren et al'!$K$8)/0.7 -> 28.043603 | M18: 0.85821459 | N18: 0.048203506 | O18: =([1]Production!$M$5*'[1]Parameters, country spec'!$M$51*'[1]EFP per kg feed'!I196+([1]Production!$M$6+[1]Production!$M$7)*'[1]Parameters, country spec'!$M$52*'[1]EFP per kg feed'!I197)/[1]Production!$M$21 -> 3.8174783 | P18: 0.63437034 | Q18: 3.8526631e-09 | R18: 0.20496686 | T18: ='Shares in prod syst'!M55 -> 0.013176995 | U18: 29.8

Sheet GHG detailed, results per kg
H1: * Production of mineral fertiliser is adjusted to account for the N supplied by manure.
A2: GHG emissions (per kg of bonefree weight) | H2: ** Adjusted for use of manure instead of mineral fertiliser (lower emission factor for manure)
H3: *** Calculated as percentage of direct emissions due to assumption due to data limitations regarding nitrogen leaching and volatilization from soils in different regions.
S4: Animals | W4: Stables | X4: Slaughter
A5: Animal products | G5: Sum | H5: Inputs | J5: Soil emissions | L5: Energy use | P5: Land use change | Q5: Feed processing | R5: Transports
A6: FoodEx code | B6: FoodEx name | C6: Food Ex category (L1) | D6: Country | E6: Country code | F6: Gas | G6: GHG | H6: Production of mineral fertilizer* | I6: Production of capital goods | J6: Direct emissions** | K6: Indirect emissions*** | L6: Diesel use field mach | M6: Energy use in greenhouses | N6: Energy use for irrigation | O6: Energy use for post-harvest proc | P6: LUC emissions | Q6: Feed processing | R6: Feed transports | S6: Enteric fermentation* | T6: Manure management - tot | U6: Manure management - direct | V6: Manure management - indirect | W6: Energy use in stables | X6: Energy use for slaughter
A7: A01QV | B7: Bovine muscle | C7: Meat and meat products | D7: Denmark | E7: DK | F7: CO2 | G7: =SUM(H7:X7) -> 3.6306623 | H7: ='GHG detailed, results per kg CW'!H7/Meat_yield -> 0.64063351 | I7: ='GHG detailed, results per kg CW'!I7/Meat_yield -> 0 | J7: ='GHG detailed, results per kg CW'!J7/Meat_yield -> 0 | K7: ='GHG detailed, results per kg CW'!K7/Meat_yield -> 0 | L7: ='GHG detailed, results per kg CW'!L7/Meat_yield -> 0.76876021 | M7: ='GHG detailed, results per kg CW'!M7/Meat_yield -> 0 | N7: ='GHG detailed, results per kg CW'!N7/Meat_yield -> 0 | O7: ='GHG detailed, results per kg CW'!O7/Meat_yield -> 0 | P7: ='GHG detailed, results per kg CW'!P7/Meat_yield -> 0 | Q7: 0 | R7: ='GHG detailed, results per kg CW'!Q7/Meat_yield -> 1.0230475 | S7: ='GHG detailed, results per kg CW'!R7/Meat_yield -> 0 | T7: ='GHG detailed, results per kg CW'!S7/Meat_yield -> 0 | U7: ='GHG detailed, results per kg CW'!T7/Meat_yield -> 0 | V7: ='GHG detailed, results per kg CW'!U7/Meat_yield -> 0 | W7: ='GHG detailed, results per kg CW'!V7/Meat_yield -> 0.51250681 | X7: ='GHG detailed, results per kg CW'!W7/Meat_yield -> 0.68571429
A8: A01QV | B8: Bovine muscle | C8: Meat and meat products | D8: Denmark | E8: DK | F8: CH4, fossil | G8: =SUM(H8:X8) -> 0 | H8: ='GHG detailed, results per kg CW'!H8/Meat_yield -> 0 | I8: ='GHG detailed, results per kg CW'!I8/Meat_yield -> 0 | J8: ='GHG detailed, results per kg CW'!J8/Meat_yield -> 0 | K8: ='GHG detailed, results per kg CW'!K8/Meat_yield -> 0 | L8: ='GHG detailed, results per kg CW'!L8/Meat_yield -> 0 | M8: ='GHG detailed, results per kg CW'!M8/Meat_yield -> 0 | N8: ='GHG detailed, results per kg CW'!N8/Meat_yield -> 0 | O8: ='GHG detailed, results per kg CW'!O8/Meat_yield -> 0 | P8: ='GHG detailed, results per kg CW'!P8/Meat_yield -> 0 | Q8: 0 | R8: ='GHG detailed, results per kg CW'!Q8/Meat_yield -> 0 | S8: ='GHG detailed, results per kg CW'!R8/Meat_yield -> 0 | T8: ='GHG detailed, results per kg CW'!S8/Meat_yield -> 0 | U8: ='GHG detailed, results per kg CW'!T8/Meat_yield -> 0 | V8: ='GHG detailed, results per kg CW'!U8/Meat_yield -> 0 | W8: ='GHG detailed, results per kg CW'!V8/Meat_yield -> 0 | X8: ='GHG detailed, results per kg CW'!W8/Meat_yield -> 0
A9: A01QV | B9: Bovine muscle | C9: Meat and meat products | D9: Denmark | E9: DK | F9: CH4, biogenic | G9: =SUM(H9:T9)+SUM(W9:X9) -> 0.52822121 | H9: ='GHG detailed, results per kg CW'!H9/Meat_yield -> 0 | I9: ='GHG detailed, results per kg CW'!I9/Meat_yield -> 0 | J9: ='GHG detailed, results per kg CW'!J9/Meat_yield -> 0 | K9: ='GHG detailed, results per kg CW'!K9/Meat_yield -> 0 | L9: ='GHG detailed, results per kg CW'!L9/Meat_yield -> 0 | M9: ='GHG detailed, results per kg CW'!M9/Meat_yield -> 0 | N9: ='GHG detailed, results per kg CW'!N9/Meat_yield -> 0 | O9: ='GHG detailed, results per kg CW'!O9/Meat_yield -> 0 | P9: ='GHG detailed, results per kg CW'!P9/Meat_yield -> 0 | Q9: 0 | R9: ='GHG detailed, results per kg CW'!Q9/Meat_yield -> 0 | S9: ='GHG detailed, results per kg CW'!R9/Meat_yield -> 0.42063229 | T9: ='GHG detailed, results per kg CW'!S9/Meat_yield -> 0.10758892 | U9: ='GHG detailed, results per kg CW'!T9/Meat_yield -> 0 | V9: ='GHG detailed, results per kg CW'!U9/Meat_yield -> 0 | W9: ='GHG detailed, results per kg CW'!V9/Meat_yield -> 0 | X9: ='GHG detailed, results per kg CW'!W9/Meat_yield -> 0
A10: A01QV | B10: Bovine muscle | C10: Meat and meat products | D10: Denmark | E10: DK | F10: N2O | G10: =SUM(H10:T10)+SUM(W10:X10) -> 0.024171053 | H10: ='GHG detailed, results per kg CW'!H10/Meat_yield -> 0.0023466429 | I10: ='GHG detailed, results per kg CW'!I10/Meat_yield -> 0 | J10: ='GHG detailed, results per kg CW'!J10/Meat_yield -> 0.010167043 | K10: ='GHG detailed, results per kg CW'!K10/Meat_yield -> 0.0010167043 | L10: ='GHG detailed, results per kg CW'!L10/Meat_yield -> 0 | M10: ='GHG detailed, results per kg CW'!M10/Meat_yield -> 0 | N10: ='GHG detailed, results per kg CW'!N10/Meat_yield -> 0 | O10: ='GHG detailed, results per kg CW'!O10/Meat_yield -> 0 | P10: ='GHG detailed, results per kg CW'!P10/Meat_yield -> 0 | Q10: 0 | R10: ='GHG detailed, results per kg CW'!Q10/Meat_yield -> 0 | S10: ='GHG detailed, results per kg CW'!R10/Meat_yield -> 0 | T10: ='GHG detailed, results per kg CW'!S10/Meat_yield -> 0.010640662 | U10: ='GHG detailed, results per kg CW'!T10/Meat_yield -> 0 | V10: ='GHG detailed, results per kg CW'!U10/Meat_yield -> 0 | W10: ='GHG detailed, results per kg CW'!V10/Meat_yield -> 0 | X10: ='GHG detailed, results per kg CW'!W10/Meat_yield -> 0
A11: A01QV | B11: Bovine muscle | C11: Meat and meat products | D11: Denmark | E11: DK | F11: CO2e | G11: =SUM(H11:X11) -> 24.491332 | H11: =SUMPRODUCT(H7:H10,'CF Climate'!$B$5:$B$8) -> 1.281267 | I11: =SUMPRODUCT(I7:I10,'CF Climate'!$B$5:$B$8) -> 0 | J11: =SUMPRODUCT(J7:J10,'CF Climate'!$B$5:$B$8) -> 2.7756028 | K11: =SUMPRODUCT(K7:K10,'CF Climate'!$B$5:$B$8) -> 0.27756028 | L11: =SUMPRODUCT(L7:L10,'CF Climate'!$B$5:$B$8) -> 0.76876021 | M11: =SUMPRODUCT(M7:M10,'CF Climate'!$B$5:$B$8) -> 0 | N11: =SUMPRODUCT(N7:N10,'CF Climate'!$B$5:$B$8) -> 0 | O11: =SUMPRODUCT(O7:O10,'CF Climate'!$B$5:$B$8) -> 0 | P11: =SUMPRODUCT(P7:P10,'CF Climate'!$B$5:$B$8) -> 0 | Q11: 0 | R11: =SUMPRODUCT(R7:R10,'CF Climate'!$B$5:$B$8) -> 1.0230475 | S11: =SUMPRODUCT(S7:S10,'CF Climate'!$B$5:$B$8) -> 11.357072 | T11: =SUMPRODUCT(T7:T10,'CF Climate'!$B$5:$B$8) -> 5.8098017 | U11: =SUMPRODUCT(U7:U10,'CF Climate'!$B$5:$B$8) -> 0 | V11: =SUMPRODUCT(V7:V10,'CF Climate'!$B$5:$B$8) -> 0 | W11: =SUMPRODUCT(W7:W10,'CF Climate'!$B$5:$B$8) -> 0.51250681 | X11: =SUMPRODUCT(X7:X10,'CF Climate'!$B$5:$B$8) -> 0.68571429
A12: A01QV | B12: Bovine muscle | C12: Meat and meat products | D12: France | E12: FR | F12: CO2 | G12: =SUM(H12:X12) -> 4.2563774 | H12: ='GHG detailed, results per kg CW'!H12/Meat_yield -> 0.68293422 | I12: ='GHG detailed, results per kg CW'!I12/Meat_yield -> 0 | J12: ='GHG detailed, results per kg CW'!J12/Meat_yield -> 0 | K12: ='GHG detailed, results per kg CW'!K12/Meat_yield -> 0 | L12: ='GHG detailed, results per kg CW'!L12/Meat_yield -> 0.81952107 | M12: ='GHG detailed, results per kg CW'!M12/Meat_yield -> 0 | N12: ='GHG detailed, results per kg CW'!N12/Meat_yield -> 0 | O12: ='GHG detailed, results per kg CW'!O12/Meat_yield -> 0 | P12: ='GHG detailed, results per kg CW'!P12/Meat_yield -> 0 | Q12: 0 | R12: ='GHG detailed, results per kg CW'!Q12/Meat_yield -> 1.5218605 | S12: ='GHG detailed, results per kg CW'!R12/Meat_yield -> 0 | T12: ='GHG detailed, results per kg CW'!S12/Meat_yield -> 0 | U12: ='GHG detailed, results per kg CW'!T12/Meat_yield -> 0 | V12: ='GHG detailed, results per kg CW'!U12/Meat_yield -> 0 | W12: ='GHG detailed, results per kg CW'!V12/Meat_yield -> 0.54634738 | X12: ='GHG detailed, results per kg CW'!W12/Meat_yield -> 0.68571429
A13: A01QV | B13: Bovine muscle | C13: Meat and meat products | D13: France | E13: FR | F13: CH4, fossil | G13: =SUM(H13:X13) -> 0 | H13: ='GHG detailed, results per kg CW'!H13/Meat_yield -> 0 | I13: ='GHG detailed, results per kg CW'!I13/Meat_yield -> 0 | J13: ='GHG detailed, results per kg CW'!J13/Meat_yield -> 0 | K13: ='GHG detailed, results per kg CW'!K13/Meat_yield -> 0 | L13: ='GHG detailed, results per kg CW'!L13/Meat_yield -> 0 | M13: ='GHG detailed, results per kg CW'!M13/Meat_yield -> 0 | N13: ='GHG detailed, results per kg CW'!N13/Meat_yield -> 0 | O13: ='GHG detailed, results per kg CW'!O13/Meat_yield -> 0 | P13: ='GHG detailed, results per kg CW'!P13/Meat_yield -> 0 | Q13: 0 | R13: ='GHG detailed, results per kg CW'!Q13/Meat_yield -> 0 | S13: ='GHG detailed, results per kg CW'!R13/Meat_yield -> 0 | T13: ='GHG detailed, results per kg CW'!S13/Meat_yield -> 0 | U13: ='GHG detailed, results per kg CW'!T13/Meat_yield -> 0 | V13: ='GHG detailed, results per kg CW'!U13/Meat_yield -> 0 | W13: ='GHG detailed, results per kg CW'!V13/Meat_yield -> 0 | X13: ='GHG detailed, results per kg CW'!W13/Meat_yield -> 0
A14: A01QV | B14: Bovine muscle | C14: Meat and meat products | D14: France | E14: FR | F14: CH4, biogenic | G14: =SUM(H14:T14)+SUM(W14:X14) -> 0.675642 | H14: ='GHG detailed, results per kg CW'!H14/Meat_yield -> 0 | I14: ='GHG detailed, results per kg CW'!I14/Meat_yield -> 0 | J14: ='GHG detailed, results per kg CW'!J14/Meat_yield -> 0 | K14: ='GHG detailed, results per kg CW'!K14/Meat_yield -> 0 | L14: ='GHG detailed, results per kg CW'!L14/Meat_yield -> 0 | M14: ='GHG detailed, results per kg CW'!M14/Meat_yield -> 0 | N14: ='GHG detailed, results per kg CW'!N14/Meat_yield -> 0 | O14: ='GHG detailed, results per kg CW'!O14/Meat_yield -> 0 | P14: ='GHG detailed, results per kg CW'!P14/Meat_yield -> 0 | Q14: 0 | R14: ='GHG detailed, results per kg CW'!Q14/Meat_yield -> 0 | S14: ='GHG detailed, results per kg CW'!R14/Meat_yield -> 0.53166582 | T14: ='GHG detailed, results per kg CW'!S14/Meat_yield -> 0.14397617 | U14: ='GHG detailed, results per kg CW'!T14/Meat_yield -> 0 | V14: ='GHG detailed, results per kg CW'!U14/Meat_yield -> 0 | W14: ='GHG detailed, results per kg CW'!V14/Meat_yield -> 0 | X14: ='GHG detailed, results per kg CW'!W14/Meat_yield -> 0
A15: A01QV | B15: Bovine muscle | C15: Meat and meat products | D15: France | E15: FR | F15: N2O | G15: =SUM(H15:T15)+SUM(W15:X15) -> 0.029870097 | H15: ='GHG detailed, results per kg CW'!H15/Meat_yield -> 0.0025015906 | I15: ='GHG detailed, results per kg CW'!I15/Meat_yield -> 0 | J15: ='GHG detailed, results per kg CW'!J15/Meat_yield -> 0.01193555 | K15: ='GHG detailed, results per kg CW'!K15/Meat_yield -> 0.001193555 | L15: ='GHG detailed, results per kg CW'!L15/Meat_yield -> 0 | M15: ='GHG detailed, results per kg CW'!M15/Meat_yield -> 0 | N15: ='GHG detailed, results per kg CW'!N15/Meat_yield -> 0 | O15: ='GHG detailed, results per kg CW'!O15/Meat_yield -> 0 | P15: ='GHG detailed, results per kg CW'!P15/Meat_yield -> 0 | Q15: 0 | R15: ='GHG detailed, results per kg CW'!Q15/Meat_yield -> 0 | S15: ='GHG detailed, results per kg CW'!R15/Meat_yield -> 0 | T15: ='GHG detailed, results per kg CW'!S15/Meat_yield -> 0.014239402 | U15: ='GHG detailed, results per kg CW'!T15/Meat_yield -> 0 | V15: ='GHG detailed, results per kg CW'!U15/Meat_yield -> 0 | W15: ='GHG detailed, results per kg CW'!V15/Meat_yield -> 0 | X15: ='GHG detailed, results per kg CW'!W15/Meat_yield -> 0
A16: A01QV | B16: Bovine muscle | C16: Meat and meat products | D16: France | E16: FR | F16: CO2e | G16: =SUM(H16:X16) -> 30.653248 | H16: =SUMPRODUCT(H12:H15,'CF Climate'!$B$5:$B$8) -> 1.3658684 | I16: =SUMPRODUCT(I12:I15,'CF Climate'!$B$5:$B$8) -> 0 | J16: =SUMPRODUCT(J12:J15,'CF Climate'!$B$5:$B$8) -> 3.2584051 | K16: =SUMPRODUCT(K12:K15,'CF Climate'!$B$5:$B$8) -> 0.32584051 | L16: =SUMPRODUCT(L12:L15,'CF Climate'!$B$5:$B$8) -> 0.81952107 | M16: =SUMPRODUCT(M12:M15,'CF Climate'!$B$5:$B$8) -> 0 | N16: =SUMPRODUCT(N12:N15,'CF Climate'!$B$5:$B$8) -> 0 | O16: =SUMPRODUCT(O12:O15,'CF Climate'!$B$5:$B$8) -> 0 | P16: =SUMPRODUCT(P12:P15,'CF Climate'!$B$5:$B$8) -> 0 | Q16: 0 | R16: =SUMPRODUCT(R12:R15,'CF Climate'!$B$5:$B$8) -> 1.5218605 | S16: =SUMPRODUCT(S12:S15,'CF Climate'!$B$5:$B$8) -> 14.354977 | T16: =SUMPRODUCT(T12:T15,'CF Climate'!$B$5:$B$8) -> 7.7747133 | U16: =SUMPRODUCT(U12:U15,'CF Climate'!$B$5:$B$8) -> 0 | V16: =SUMPRODUCT(V12:V15,'CF Climate'!$B$5:$B$8) -> 0 | W16: =SUMPRODUCT(W12:W15,'CF Climate'!$B$5:$B$8) -> 0.54634738 | X16: =SUMPRODUCT(X12:X15,'CF Climate'!$B$5:$B$8) -> 0.68571429
A17: A01QV | B17: Bovine muscle | C17: Meat and meat products | D17: Germany | E17: DE | F17: CO2 | G17: =SUM(H17:X17) -> 3.863894 | H17: ='GHG detailed, results per kg CW'!H17/Meat_yield -> 0.60051189 | I17: ='GHG detailed, results per kg CW'!I17/Meat_yield -> 0 | J17: ='GHG detailed, results per kg CW'!J17/Meat_yield -> 0 | K17: ='GHG detailed, results per kg CW'!K17/Meat_yield -> 0 | L17: ='GHG detailed, results per kg CW'!L17/Meat_yield -> 0.72061427 | M17: ='GHG detailed, results per kg CW'!M17/Meat_yield -> 0 | N17: ='GHG detailed, results per kg CW'!N17/Meat_yield -> 0 | O17: ='GHG detailed, results per kg CW'!O17/Meat_yield -> 0 | P17: ='GHG detailed, results per kg CW'!P17/Meat_yield -> 0 | Q17: 0 | R17: ='GHG detailed, results per kg CW'!Q17/Meat_yield -> 1.376644 | S17: ='GHG detailed, results per kg CW'!R17/Meat_yield -> 0 | T17: ='GHG detailed, results per kg CW'!S17/Meat_yield -> 0 | U17: ='GHG detailed, results per kg CW'!T17/Meat_yield -> 0 | V17: ='GHG detailed, results per kg CW'!U17/Meat_yield -> 0 | W17: ='GHG detailed, results per kg CW'!V17/Meat_yield -> 0.48040951 | X17: ='GHG detailed, results per kg CW'!W17/Meat_yield -> 0.68571429
A18: A01QV | B18: Bovine muscle | C18: Meat and meat products | D18: Germany | E18: DE | F18: CH4, fossil | G18: =SUM(H18:X18) -> 0 | H18: ='GHG detailed, results per kg CW'!H18/Meat_yield -> 0 | I18: ='GHG detailed, results per kg CW'!I18/Meat_yield -> 0 | J18: ='GHG detailed, results per kg CW'!J18/Meat_yield -> 0 | K18: ='GHG detailed, results per kg CW'!K18/Meat_yield -> 0 | L18: ='GHG detailed, results per kg CW'!L18/Meat_yield -> 0 | M18: ='GHG detailed, results per kg CW'!M18/Meat_yield -> 0 | N18: ='GHG detailed, results per kg CW'!N18/Meat_yield -> 0 | O18: ='GHG detailed, results per kg CW'!O18/Meat_yield -> 0 | P18: ='GHG detailed, results per kg CW'!P18/Meat_yield -> 0 | Q18: 0 | R18: ='GHG detailed, results per kg CW'!Q18/Meat_yield -> 0 | S18: ='GHG detailed, results per kg CW'!R18/Meat_yield -> 0 | T18: ='GHG detailed, results per kg CW'!S18/Meat_yield -> 0 | U18: ='GHG detailed, results per kg CW'!T18/Meat_yield -> 0 | V18: ='GHG detailed, results per kg CW'!U18/Meat_yield -> 0 | W18: ='GHG detailed, results per kg CW'!V18/Meat_yield -> 0 | X18: ='GHG detailed, results per kg CW'!W18/Meat_yield -> 0
A19: A01QV | B19: Bovine muscle | C19: Meat and meat products | D19: Germany | E19: DE | F19: CH4, biogenic | G19: =SUM(H19:T19)+SUM(W19:X19) -> 0.60987053 | H19: ='GHG detailed, results per kg CW'!H19/Meat_yield -> 0 | I19: ='GHG detailed, results per kg CW'!I19/Meat_yield -> 0 | J19: ='GHG detailed, results per kg CW'!J19/Meat_yield -> 0 | K19: ='GHG detailed, results per kg CW'!K19/Meat_yield -> 0 | L19: ='GHG detailed, results per kg CW'!L19/Meat_yield -> 0 | M19: ='GHG detailed, results per kg CW'!M19/Meat_yield -> 0 | N19: ='GHG detailed, results per kg CW'!N19/Meat_yield -> 0 | O19: ='GHG detailed, results per kg CW'!O19/Meat_yield -> 0 | P19: ='GHG detailed, results per kg CW'!P19/Meat_yield -> 0 | Q19: 0 | R19: ='GHG detailed, results per kg CW'!Q19/Meat_yield -> 0 | S19: ='GHG detailed, results per kg CW'!R19/Meat_yield -> 0.4826014 | T19: ='GHG detailed, results per kg CW'!S19/Meat_yield -> 0.12726913 | U19: ='GHG detailed, results per kg CW'!T19/Meat_yield -> 0 | V19: ='GHG detailed, results per kg CW'!U19/Meat_yield -> 0 | W19: ='GHG detailed, results per kg CW'!V19/Meat_yield -> 0 | X19: ='GHG detailed, results per kg CW'!W19/Meat_yield -> 0
A20: A01QV | B20: Bovine muscle | C20: Meat and meat products | D20: Germany | E20: DE | F20: N2O | G20: =SUM(H20:T20)+SUM(W20:X20) -> 0.02677812 | H20: ='GHG detailed, results per kg CW'!H20/Meat_yield -> 0.0021996773 | I20: ='GHG detailed, results per kg CW'!I20/Meat_yield -> 0 | J20: ='GHG detailed, results per kg CW'!J20/Meat_yield -> 0.01090126 | K20: ='GHG detailed, results per kg CW'!K20/Meat_yield -> 0.001090126 | L20: ='GHG detailed, results per kg CW'!L20/Meat_yield -> 0 | M20: ='GHG detailed, results per kg CW'!M20/Meat_yield -> 0 | N20: ='GHG detailed, results per kg CW'!N20/Meat_yield -> 0 | O20: ='GHG detailed, results per kg CW'!O20/Meat_yield -> 0 | P20: ='GHG detailed, results per kg CW'!P20/Meat_yield -> 0 | Q20: 0 | R20: ='GHG detailed, results per kg CW'!Q20/Meat_yield -> 0 | S20: ='GHG detailed, results per kg CW'!R20/Meat_yield -> 0 | T20: ='GHG detailed, results per kg CW'!S20/Meat_yield -> 0.012587057 | U20: ='GHG detailed, results per kg CW'!T20/Meat_yield -> 0 | V20: ='GHG detailed, results per kg CW'!U20/Meat_yield -> 0 | W20: ='GHG detailed, results per kg CW'!V20/Meat_yield -> 0 | X20: ='GHG detailed, results per kg CW'!W20/Meat_yield -> 0
A21: A01QV | B21: Bovine muscle | C21: Meat and meat products | D21: Germany | E21: DE | F21: CO2e | G21: =SUM(H21:X21) -> 27.640825 | H21: =SUMPRODUCT(H17:H20,'CF Climate'!$B$5:$B$8) -> 1.2010238 | I21: =SUMPRODUCT(I17:I20,'CF Climate'!$B$5:$B$8) -> 0 | J21: =SUMPRODUCT(J17:J20,'CF Climate'!$B$5:$B$8) -> 2.9760439 | K21: =SUMPRODUCT(K17:K20,'CF Climate'!$B$5:$B$8) -> 0.29760439 | L21: =SUMPRODUCT(L17:L20,'CF Climate'!$B$5:$B$8) -> 0.72061427 | M21: =SUMPRODUCT(M17:M20,'CF Climate'!$B$5:$B$8) -> 0 | N21: =SUMPRODUCT(N17:N20,'CF Climate'!$B$5:$B$8) -> 0 | O21: =SUMPRODUCT(O17:O20,'CF Climate'!$B$5:$B$8) -> 0 | P21: =SUMPRODUCT(P17:P20,'CF Climate'!$B$5:$B$8) -> 0 | Q21: 0 | R21: =SUMPRODUCT(R17:R20,'CF Climate'!$B$5:$B$8) -> 1.376644 | S21: =SUMPRODUCT(S17:S20,'CF Climate'!$B$5:$B$8) -> 13.030238 | T21: =SUMPRODUCT(T17:T20,'CF Climate'!$B$5:$B$8) -> 6.8725331 | U21: =SUMPRODUCT(U17:U20,'CF Climate'!$B$5:$B$8) -> 0 | V21: =SUMPRODUCT(V17:V20,'CF Climate'!$B$5:$B$8) -> 0 | W21: =SUMPRODUCT(W17:W20,'CF Climate'!$B$5:$B$8) -> 0.48040951 | X21: =SUMPRODUCT(X17:X20,'CF Climate'!$B$5:$B$8) -> 0.68571429
A22: A01QV | B22: Bovine muscle | C22: Meat and meat products | D22: Greece | E22: GR | F22: CO2 | G22: =SUM(H22:X22) -> 4.3652178 | H22: ='GHG detailed, results per kg CW'!H22/Meat_yield -> 0.69389097 | I22: ='GHG detailed, results per kg CW'!I22/Meat_yield -> 0 | J22: ='GHG detailed, results per kg CW'!J22/Meat_yield -> 0 | K22: ='GHG detailed, results per kg CW'!K22/Meat_yield -> 0 | L22: ='GHG detailed, results per kg CW'!L22/Meat_yield -> 0.83266917 | M22: ='GHG detailed, results per kg CW'!M22/Meat_yield -> 0 | N22: ='GHG detailed, results per kg CW'!N22/Meat_yield -> 0 | O22: ='GHG detailed, results per kg CW'!O22/Meat_yield -> 0 | P22: ='GHG detailed, results per kg CW'!P22/Meat_yield -> 0 | Q22: 0 | R22: ='GHG detailed, results per kg CW'!Q22/Meat_yield -> 1.5978306 | S22: ='GHG detailed, results per kg CW'!R22/Meat_yield -> 0 | T22: ='GHG detailed, results per kg CW'!S22/Meat_yield -> 0 | U22: ='GHG detailed, results per kg CW'!T22/Meat_yield -> 0 | V22: ='GHG detailed, results per kg CW'!U22/Meat_yield -> 0 | W22: ='GHG detailed, results per kg CW'!V22/Meat_yield -> 0.55511278 | X22: ='GHG detailed, results per kg CW'!W22/Meat_yield -> 0.68571429
A23: A01QV | B23: Bovine muscle | C23: Meat and meat products | D23: Greece | E23: GR | F23: CH4, fossil | G23: =SUM(H23:X23) -> 0 | H23: ='GHG detailed, results per kg CW'!H23/Meat_yield -> 0 | I23: ='GHG detailed, results per kg CW'!I23/Meat_yield -> 0 | J23: ='GHG detailed, results per kg CW'!J23/Meat_yield -> 0 | K23: ='GHG detailed, results per kg CW'!K23/Meat_yield -> 0 | L23: ='GHG detailed, results per kg CW'!L23/Meat_yield -> 0 | M23: ='GHG detailed, results per kg CW'!M23/Meat_yield -> 0 | N23: ='GHG detailed, results per kg CW'!N23/Meat_yield -> 0 | O23: ='GHG detailed, results per kg CW'!O23/Meat_yield -> 0 | P23: ='GHG detailed, results per kg CW'!P23/Meat_yield -> 0 | Q23: 0 | R23: ='GHG detailed, results per kg CW'!Q23/Meat_yield -> 0 | S23: ='GHG detailed, results per kg CW'!R23/Meat_yield -> 0 | T23: ='GHG detailed, results per kg CW'!S23/Meat_yield -> 0 | U23: ='GHG detailed, results per kg CW'!T23/Meat_yield -> 0 | V23: ='GHG detailed, results per kg CW'!U23/Meat_yield -> 0 | W23: ='GHG detailed, results per kg CW'!V23/Meat_yield -> 0 | X23: ='GHG detailed, results per kg CW'!W23/Meat_yield -> 0
A24: A01QV | B24: Bovine muscle | C24: Meat and meat products | D24: Greece | E24: GR | F24: CH4, biogenic | G24: =SUM(H24:T24)+SUM(W24:X24) -> 0.71556993 | H24: ='GHG detailed, results per kg CW'!H24/Meat_yield -> 0.0025417252 | I24: ='GHG detailed, results per kg CW'!I24/Meat_yield -> 0 | J24: ='GHG detailed, results per kg CW'!J24/Meat_yield -> 0.012238343 | K24: ='GHG detailed, results per kg CW'!K24/Meat_yield -> 0.0012238343 | L24: ='GHG detailed, results per kg CW'!L24/Meat_yield -> 0 | M24: ='GHG detailed, results per kg CW'!M24/Meat_yield -> 0 | N24: ='GHG detailed, results per kg CW'!N24/Meat_yield -> 0 | O24: ='GHG detailed, results per kg CW'!O24/Meat_yield -> 0 | P24: ='GHG detailed, results per kg CW'!P24/Meat_yield -> 0 | Q24: 0 | R24: ='GHG detailed, results per kg CW'!Q24/Meat_yield -> 0 | S24: ='GHG detailed, results per kg CW'!R24/Meat_yield -> 0.54965434 | T24: ='GHG detailed, results per kg CW'!S24/Meat_yield -> 0.14991169 | U24: ='GHG detailed, results per kg CW'!T24/Meat_yield -> 0 | V24: ='GHG detailed, results per kg CW'!U24/Meat_yield -> 0 | W24: ='GHG detailed, results per kg CW'!V24/Meat_yield -> 0 | X24: ='GHG detailed, results per kg CW'!W24/Meat_yield -> 0
A25: A01QV | B25: Bovine muscle | C25: Meat and meat products | D25: Greece | E25: GR | F25: N2O | G25: =SUM(H25:T25)+SUM(W25:X25) -> 0.030830334 | H25: ='GHG detailed, results per kg CW'!H25/Meat_yield -> 0.0025417252 | I25: ='GHG detailed, results per kg CW'!I25/Meat_yield -> 0 | J25: ='GHG detailed, results per kg CW'!J25/Meat_yield -> 0.012238343 | K25: ='GHG detailed, results per kg CW'!K25/Meat_yield -> 0.0012238343 | L25: ='GHG detailed, results per kg CW'!L25/Meat_yield -> 0 | M25: ='GHG detailed, results per kg CW'!M25/Meat_yield -> 0 | N25: ='GHG detailed, results per kg CW'!N25/Meat_yield -> 0 | O25: ='GHG detailed, results per kg CW'!O25/Meat_yield -> 0 | P25: ='GHG detailed, results per kg CW'!P25/Meat_yield -> 0 | Q25: 0 | R25: ='GHG detailed, results per kg CW'!Q25/Meat_yield -> 0 | S25: ='GHG detailed, results per kg CW'!R25/Meat_yield -> 0 | T25: ='GHG detailed, results per kg CW'!S25/Meat_yield -> 0.014826431 | U25: ='GHG detailed, results per kg CW'!T25/Meat_yield -> 0 | V25: ='GHG detailed, results per kg CW'!U25/Meat_yield -> 0 | W25: ='GHG detailed, results per kg CW'!V25/Meat_yield -> 0 | X25: ='GHG detailed, results per kg CW'!W25/Meat_yield -> 0
A26: A01QV | B26: Bovine muscle | C26: Meat and meat products | D26: Greece | E26: GR | F26: CO2e | G26: =SUM(H26:X26) -> 32.102287 | H26: =SUMPRODUCT(H22:H25,'CF Climate'!$B$5:$B$8) -> 1.4564085 | I26: =SUMPRODUCT(I22:I25,'CF Climate'!$B$5:$B$8) -> 0 | J26: =SUMPRODUCT(J22:J25,'CF Climate'!$B$5:$B$8) -> 3.671503 | K26: =SUMPRODUCT(K22:K25,'CF Climate'!$B$5:$B$8) -> 0.3671503 | L26: =SUMPRODUCT(L22:L25,'CF Climate'!$B$5:$B$8) -> 0.83266917 | M26: =SUMPRODUCT(M22:M25,'CF Climate'!$B$5:$B$8) -> 0 | N26: =SUMPRODUCT(N22:N25,'CF Climate'!$B$5:$B$8) -> 0 | O26: =SUMPRODUCT(O22:O25,'CF Climate'!$B$5:$B$8) -> 0 | P26: =SUMPRODUCT(P22:P25,'CF Climate'!$B$5:$B$8) -> 0 | Q26: 0 | R26: =SUMPRODUCT(R22:R25,'CF Climate'!$B$5:$B$8) -> 1.5978306 | S26: =SUMPRODUCT(S22:S25,'CF Climate'!$B$5:$B$8) -> 14.840667 | T26: =SUMPRODUCT(T22:T25,'CF Climate'!$B$5:$B$8) -> 8.0952315 | U26: =SUMPRODUCT(U22:U25,'CF Climate'!$B$5:$B$8) -> 0 | V26: =SUMPRODUCT(V22:V25,'CF Climate'!$B$5:$B$8) -> 0 | W26: =SUMPRODUCT(W22:W25,'CF Climate'!$B$5:$B$8) -> 0.55511278 | X26: =SUMPRODUCT(X22:X25,'CF Climate'!$B$5:$B$8) -> 0.68571429
A27: A01QV | B27: Bovine muscle | C27: Meat and meat products | D27: Hungary | E27: HU | F27: CO2 | G27: =SUM(H27:X27) -> 3.9270738 | H27: ='GHG detailed, results per kg CW'!H27/Meat_yield -> 0.65761035 | I27: ='GHG detailed, results per kg CW'!I27/Meat_yield -> 0 | J27: ='GHG detailed, results per kg CW'!J27/Meat_yield -> 0 | K27: ='GHG detailed, results per kg CW'!K27/Meat_yield -> 0 | L27: ='GHG detailed, results per kg CW'!L27/Meat_yield -> 0.78913243 | M27: ='GHG detailed, results per kg CW'!M27/Meat_yield -> 0 | N27: ='GHG detailed, results per kg CW'!N27/Meat_yield -> 0 | O27: ='GHG detailed, results per kg CW'!O27/Meat_yield -> 0 | P27: ='GHG detailed, results per kg CW'!P27/Meat_yield -> 0 | Q27: 0 | R27: ='GHG detailed, results per kg CW'!Q27/Meat_yield -> 1.2685285 | S27: ='GHG detailed, results per kg CW'!R27/Meat_yield -> 0 | T27: ='GHG detailed, results per kg CW'!S27/Meat_yield -> 0 | U27: ='GHG detailed, results per kg CW'!T27/Meat_yield -> 0 | V27: ='GHG detailed, results per kg CW'!U27/Meat_yield -> 0 | W27: ='GHG detailed, results per kg CW'!V27/Meat_yield -> 0.52608828 | X27: ='GHG detailed, results per kg CW'!W27/Meat_yield -> 0.68571429
A28: A01QV | B28: Bovine muscle | C28: Meat and meat products | D28: Hungary | E28: HU | F28: CH4, fossil | G28: =SUM(H28:X28) -> 0 | H28: ='GHG detailed, results per kg CW'!H28/Meat_yield -> 0 | I28: ='GHG detailed, results per kg CW'!I28/Meat_yield -> 0 | J28: ='GHG detailed, results per kg CW'!J28/Meat_yield -> 0 | K28: ='GHG detailed, results per kg CW'!K28/Meat_yield -> 0 | L28: ='GHG detailed, results per kg CW'!L28/Meat_yield -> 0 | M28: ='GHG detailed, results per kg CW'!M28/Meat_yield -> 0 | N28: ='GHG detailed, results per kg CW'!N28/Meat_yield -> 0 | O28: ='GHG detailed, results per kg CW'!O28/Meat_yield -> 0 | P28: ='GHG detailed, results per kg CW'!P28/Meat_yield -> 0 | Q28: 0 | R28: ='GHG detailed, results per kg CW'!Q28/Meat_yield -> 0 | S28: ='GHG detailed, results per kg CW'!R28/Meat_yield -> 0 | T28: ='GHG detailed, results per kg CW'!S28/Meat_yield -> 0 | U28: ='GHG detailed, results per kg CW'!T28/Meat_yield -> 0 | V28: ='GHG detailed, results per kg CW'!U28/Meat_yield -> 0 | W28: ='GHG detailed, results per kg CW'!V28/Meat_yield -> 0 | X28: ='GHG detailed, results per kg CW'!W28/Meat_yield -> 0
A29: A01QV | B29: Bovine muscle | C29: Meat and meat products | D29: Hungary | E29: HU | F29: CH4, biogenic | G29: =SUM(H29:T29)+SUM(W29:X29) -> 0.59951948 | H29: ='GHG detailed, results per kg CW'!H29/Meat_yield -> 0 | I29: ='GHG detailed, results per kg CW'!I29/Meat_yield -> 0 | J29: ='GHG detailed, results per kg CW'!J29/Meat_yield -> 0 | K29: ='GHG detailed, results per kg CW'!K29/Meat_yield -> 0 | L29: ='GHG detailed, results per kg CW'!L29/Meat_yield -> 0 | M29: ='GHG detailed, results per kg CW'!M29/Meat_yield -> 0 | N29: ='GHG detailed, results per kg CW'!N29/Meat_yield -> 0 | O29: ='GHG detailed, results per kg CW'!O29/Meat_yield -> 0 | P29: ='GHG detailed, results per kg CW'!P29/Meat_yield -> 0 | Q29: 0 | R29: ='GHG detailed, results per kg CW'!Q29/Meat_yield -> 0 | S29: ='GHG detailed, results per kg CW'!R29/Meat_yield -> 0.47435821 | T29: ='GHG detailed, results per kg CW'!S29/Meat_yield -> 0.12516126 | U29: ='GHG detailed, results per kg CW'!T29/Meat_yield -> 0 | V29: ='GHG detailed, results per kg CW'!U29/Meat_yield -> 0 | W29: ='GHG detailed, results per kg CW'!V29/Meat_yield -> 0 | X29: ='GHG detailed, results per kg CW'!W29/Meat_yield -> 0
A30: A01QV | B30: Bovine muscle | C30: Meat and meat products | D30: Hungary | E30: HU | F30: N2O | G30: =SUM(H30:T30)+SUM(W30:X30) -> 0.026897231 | H30: ='GHG detailed, results per kg CW'!H30/Meat_yield -> 0.0024088291 | I30: ='GHG detailed, results per kg CW'!I30/Meat_yield -> 0 | J30: ='GHG detailed, results per kg CW'!J30/Meat_yield -> 0.011008923 | K30: ='GHG detailed, results per kg CW'!K30/Meat_yield -> 0.0011008923 | L30: ='GHG detailed, results per kg CW'!L30/Meat_yield -> 0 | M30: ='GHG detailed, results per kg CW'!M30/Meat_yield -> 0 | N30: ='GHG detailed, results per kg CW'!N30/Meat_yield -> 0 | O30: ='GHG detailed, results per kg CW'!O30/Meat_yield -> 0 | P30: ='GHG detailed, results per kg CW'!P30/Meat_yield -> 0 | Q30: 0 | R30: ='GHG detailed, results per kg CW'!Q30/Meat_yield -> 0 | S30: ='GHG detailed, results per kg CW'!R30/Meat_yield -> 0 | T30: ='GHG detailed, results per kg CW'!S30/Meat_yield -> 0.012378586 | U30: ='GHG detailed, results per kg CW'!T30/Meat_yield -> 0 | V30: ='GHG detailed, results per kg CW'!U30/Meat_yield -> 0 | W30: ='GHG detailed, results per kg CW'!V30/Meat_yield -> 0 | X30: ='GHG detailed, results per kg CW'!W30/Meat_yield -> 0
A31: A01QV | B31: Bovine muscle | C31: Meat and meat products | D31: Hungary | E31: HU | F31: CO2e | G31: =SUM(H31:X31) -> 27.457044 | H31: =SUMPRODUCT(H27:H30,'CF Climate'!$B$5:$B$8) -> 1.3152207 | I31: =SUMPRODUCT(I27:I30,'CF Climate'!$B$5:$B$8) -> 0 | J31: =SUMPRODUCT(J27:J30,'CF Climate'!$B$5:$B$8) -> 3.0054361 | K31: =SUMPRODUCT(K27:K30,'CF Climate'!$B$5:$B$8) -> 0.30054361 | L31: =SUMPRODUCT(L27:L30,'CF Climate'!$B$5:$B$8) -> 0.78913243 | M31: =SUMPRODUCT(M27:M30,'CF Climate'!$B$5:$B$8) -> 0 | N31: =SUMPRODUCT(N27:N30,'CF Climate'!$B$5:$B$8) -> 0 | O31: =SUMPRODUCT(O27:O30,'CF Climate'!$B$5:$B$8) -> 0 | P31: =SUMPRODUCT(P27:P30,'CF Climate'!$B$5:$B$8) -> 0 | Q31: 0 | R31: =SUMPRODUCT(R27:R30,'CF Climate'!$B$5:$B$8) -> 1.2685285 | S31: =SUMPRODUCT(S27:S30,'CF Climate'!$B$5:$B$8) -> 12.807672 | T31: =SUMPRODUCT(T27:T30,'CF Climate'!$B$5:$B$8) -> 6.7587082 | U31: =SUMPRODUCT(U27:U30,'CF Climate'!$B$5:$B$8) -> 0 | V31: =SUMPRODUCT(V27:V30,'CF Climate'!$B$5:$B$8) -> 0 | W31: =SUMPRODUCT(W27:W30,'CF Climate'!$B$5:$B$8) -> 0.52608828 | X31: =SUMPRODUCT(X27:X30,'CF Climate'!$B$5:$B$8) -> 0.68571429
A32: A01QV | B32: Bovine muscle | C32: Meat and meat products | D32: Ireland | E32: IE | F32: CO2 | G32: =SUM(H32:X32) -> 4.3879948 | H32: ='GHG detailed, results per kg CW'!H32/Meat_yield -> 0.65715858 | I32: ='GHG detailed, results per kg CW'!I32/Meat_yield -> 0 | J32: ='GHG detailed, results per kg CW'!J32/Meat_yield -> 0 | K32: ='GHG detailed, results per kg CW'!K32/Meat_yield -> 0 | L32: ='GHG detailed, results per kg CW'!L32/Meat_yield -> 0.78859029 | M32: ='GHG detailed, results per kg CW'!M32/Meat_yield -> 0 | N32: ='GHG detailed, results per kg CW'!N32/Meat_yield -> 0 | O32: ='GHG detailed, results per kg CW'!O32/Meat_yield -> 0 | P32: ='GHG detailed, results per kg CW'!P32/Meat_yield -> 0 | Q32: 0 | R32: ='GHG detailed, results per kg CW'!Q32/Meat_yield -> 1.7308048 | S32: ='GHG detailed, results per kg CW'!R32/Meat_yield -> 0 | T32: ='GHG detailed, results per kg CW'!S32/Meat_yield -> 0 | U32: ='GHG detailed, results per kg CW'!T32/Meat_yield -> 0 | V32: ='GHG detailed, results per kg CW'!U32/Meat_yield -> 0 | W32: ='GHG detailed, results per kg CW'!V32/Meat_yield -> 0.52572686 | X32: ='GHG detailed, results per kg CW'!W32/Meat_yield -> 0.68571429
A33: A01QV | B33: Bovine muscle | C33: Meat and meat products | D33: Ireland | E33: IE | F33: CH4, fossil | G33: =SUM(H33:X33) -> 0 | H33: ='GHG detailed, results per kg CW'!H33/Meat_yield -> 0 | I33: ='GHG detailed, results per kg CW'!I33/Meat_yield -> 0 | J33: ='GHG detailed, results per kg CW'!J33/Meat_yield -> 0 | K33: ='GHG detailed, results per kg CW'!K33/Meat_yield -> 0 | L33: ='GHG detailed, results per kg CW'!L33/Meat_yield -> 0 | M33: ='GHG detailed, results per kg CW'!M33/Meat_yield -> 0 | N33: ='GHG detailed, results per kg CW'!N33/Meat_yield -> 0 | O33: ='GHG detailed, results per kg CW'!O33/Meat_yield -> 0 | P33: ='GHG detailed, results per kg CW'!P33/Meat_yield -> 0 | Q33: 0 | R33: ='GHG detailed, results per kg CW'!Q33/Meat_yield -> 0 | S33: ='GHG detailed, results per kg CW'!R33/Meat_yield -> 0 | T33: ='GHG detailed, results per kg CW'!S33/Meat_yield -> 0 | U33: ='GHG detailed, results per kg CW'!T33/Meat_yield -> 0 | V33: ='GHG detailed, results per kg CW'!U33/Meat_yield -> 0 | W33: ='GHG detailed, results per kg CW'!V33/Meat_yield -> 0 | X33: ='GHG detailed, results per kg CW'!W33/Meat_yield -> 0
A34: A01QV | B34: Bovine muscle | C34: Meat and meat products | D34: Ireland | E34: IE | F34: CH4, biogenic | G34: =SUM(H34:T34)+SUM(W34:X34) -> 0.72321564 | H34: ='GHG detailed, results per kg CW'!H34/Meat_yield -> 0 | I34: ='GHG detailed, results per kg CW'!I34/Meat_yield -> 0 | J34: ='GHG detailed, results per kg CW'!J34/Meat_yield -> 0 | K34: ='GHG detailed, results per kg CW'!K34/Meat_yield -> 0 | L34: ='GHG detailed, results per kg CW'!L34/Meat_yield -> 0 | M34: ='GHG detailed, results per kg CW'!M34/Meat_yield -> 0 | N34: ='GHG detailed, results per kg CW'!N34/Meat_yield -> 0 | O34: ='GHG detailed, results per kg CW'!O34/Meat_yield -> 0 | P34: ='GHG detailed, results per kg CW'!P34/Meat_yield -> 0 | Q34: 0 | R34: ='GHG detailed, results per kg CW'!Q34/Meat_yield -> 0 | S34: ='GHG detailed, results per kg CW'!R34/Meat_yield -> 0.56779048 | T34: ='GHG detailed, results per kg CW'!S34/Meat_yield -> 0.15542516 | U34: ='GHG detailed, results per kg CW'!T34/Meat_yield -> 0 | V34: ='GHG detailed, results per kg CW'!U34/Meat_yield -> 0 | W34: ='GHG detailed, results per kg CW'!V34/Meat_yield -> 0 | X34: ='GHG detailed, results per kg CW'!W34/Meat_yield -> 0
A35: A01QV | B35: Bovine muscle | C35: Meat and meat products | D35: Ireland | E35: IE | F35: N2O | G35: =SUM(H35:T35)+SUM(W35:X35) -> 0.031368392 | H35: ='GHG detailed, results per kg CW'!H35/Meat_yield -> 0.0024071743 | I35: ='GHG detailed, results per kg CW'!I35/Meat_yield -> 0 | J35: ='GHG detailed, results per kg CW'!J35/Meat_yield -> 0.01235409 | K35: ='GHG detailed, results per kg CW'!K35/Meat_yield -> 0.001235409 | L35: ='GHG detailed, results per kg CW'!L35/Meat_yield -> 0 | M35: ='GHG detailed, results per kg CW'!M35/Meat_yield -> 0 | N35: ='GHG detailed, results per kg CW'!N35/Meat_yield -> 0 | O35: ='GHG detailed, results per kg CW'!O35/Meat_yield -> 0 | P35: ='GHG detailed, results per kg CW'!P35/Meat_yield -> 0 | Q35: 0 | R35: ='GHG detailed, results per kg CW'!Q35/Meat_yield -> 0 | S35: ='GHG detailed, results per kg CW'!R35/Meat_yield -> 0 | T35: ='GHG detailed, results per kg CW'!S35/Meat_yield -> 0.015371719 | U35: ='GHG detailed, results per kg CW'!T35/Meat_yield -> 0 | V35: ='GHG detailed, results per kg CW'!U35/Meat_yield -> 0 | W35: ='GHG detailed, results per kg CW'!V35/Meat_yield -> 0 | X35: ='GHG detailed, results per kg CW'!W35/Meat_yield -> 0
A36: A01QV | B36: Bovine muscle | C36: Meat and meat products | D36: Ireland | E36: IE | F36: CO2e | G36: =SUM(H36:X36) -> 32.478388 | H36: =SUMPRODUCT(H32:H35,'CF Climate'!$B$5:$B$8) -> 1.3143172 | I36: =SUMPRODUCT(I32:I35,'CF Climate'!$B$5:$B$8) -> 0 | J36: =SUMPRODUCT(J32:J35,'CF Climate'!$B$5:$B$8) -> 3.3726665 | K36: =SUMPRODUCT(K32:K35,'CF Climate'!$B$5:$B$8) -> 0.33726665 | L36: =SUMPRODUCT(L32:L35,'CF Climate'!$B$5:$B$8) -> 0.78859029 | M36: =SUMPRODUCT(M32:M35,'CF Climate'!$B$5:$B$8) -> 0 | N36: =SUMPRODUCT(N32:N35,'CF Climate'!$B$5:$B$8) -> 0 | O36: =SUMPRODUCT(O32:O35,'CF Climate'!$B$5:$B$8) -> 0 | P36: =SUMPRODUCT(P32:P35,'CF Climate'!$B$5:$B$8) -> 0 | Q36: 0 | R36: =SUMPRODUCT(R32:R35,'CF Climate'!$B$5:$B$8) -> 1.7308048 | S36: =SUMPRODUCT(S32:S35,'CF Climate'!$B$5:$B$8) -> 15.330343 | T36: =SUMPRODUCT(T32:T35,'CF Climate'!$B$5:$B$8) -> 8.3929585 | U36: =SUMPRODUCT(U32:U35,'CF Climate'!$B$5:$B$8) -> 0 | V36: =SUMPRODUCT(V32:V35,'CF Climate'!$B$5:$B$8) -> 0 | W36: =SUMPRODUCT(W32:W35,'CF Climate'!$B$5:$B$8) -> 0.52572686 | X36: =SUMPRODUCT(X32:X35,'CF Climate'!$B$5:$B$8) -> 0.68571429
A37: A01QV | B37: Bovine muscle | C37: Meat and meat products | D37: Italy | E37: IT | F37: CO2 | G37: =SUM(H37:X37) -> 3.9003357 | H37: ='GHG detailed, results per kg CW'!H37/Meat_yield -> 0.60017738 | I37: ='GHG detailed, results per kg CW'!I37/Meat_yield -> 0 | J37: ='GHG detailed, results per kg CW'!J37/Meat_yield -> 0 | K37: ='GHG detailed, results per kg CW'!K37/Meat_yield -> 0 | L37: ='GHG detailed, results per kg CW'!L37/Meat_yield -> 0.72021285 | M37: ='GHG detailed, results per kg CW'!M37/Meat_yield -> 0 | N37: ='GHG detailed, results per kg CW'!N37/Meat_yield -> 0 | O37: ='GHG detailed, results per kg CW'!O37/Meat_yield -> 0 | P37: ='GHG detailed, results per kg CW'!P37/Meat_yield -> 0 | Q37: 0 | R37: ='GHG detailed, results per kg CW'!Q37/Meat_yield -> 1.4140893 | S37: ='GHG detailed, results per kg CW'!R37/Meat_yield -> 0 | T37: ='GHG detailed, results per kg CW'!S37/Meat_yield -> 0 | U37: ='GHG detailed, results per kg CW'!T37/Meat_yield -> 0 | V37: ='GHG detailed, results per kg CW'!U37/Meat_yield -> 0 | W37: ='GHG detailed, results per kg CW'!V37/Meat_yield -> 0.4801419 | X37: ='GHG detailed, results per kg CW'!W37/Meat_yield -> 0.68571429
A38: A01QV | B38: Bovine muscle | C38: Meat and meat products | D38: Italy | E38: IT | F38: CH4, fossil | G38: =SUM(H38:X38) -> 0 | H38: ='GHG detailed, results per kg CW'!H38/Meat_yield -> 0 | I38: ='GHG detailed, results per kg CW'!I38/Meat_yield -> 0 | J38: ='GHG detailed, results per kg CW'!J38/Meat_yield -> 0 | K38: ='GHG detailed, results per kg CW'!K38/Meat_yield -> 0 | L38: ='GHG detailed, results per kg CW'!L38/Meat_yield -> 0 | M38: ='GHG detailed, results per kg CW'!M38/Meat_yield -> 0 | N38: ='GHG detailed, results per kg CW'!N38/Meat_yield -> 0 | O38: ='GHG detailed, results per kg CW'!O38/Meat_yield -> 0 | P38: ='GHG detailed, results per kg CW'!P38/Meat_yield -> 0 | Q38: 0 | R38: ='GHG detailed, results per kg CW'!Q38/Meat_yield -> 0 | S38: ='GHG detailed, results per kg CW'!R38/Meat_yield -> 0 | T38: ='GHG detailed, results per kg CW'!S38/Meat_yield -> 0 | U38: ='GHG detailed, results per kg CW'!T38/Meat_yield -> 0 | V38: ='GHG detailed, results per kg CW'!U38/Meat_yield -> 0 | W38: ='GHG detailed, results per kg CW'!V38/Meat_yield -> 0 | X38: ='GHG detailed, results per kg CW'!W38/Meat_yield -> 0
A39: A01QV | B39: Bovine muscle | C39: Meat and meat products | D39: Italy | E39: IT | F39: CH4, biogenic | G39: =SUM(H39:T39)+SUM(W39:X39) -> 0.61979304 | H39: ='GHG detailed, results per kg CW'!H39/Meat_yield -> 0 | I39: ='GHG detailed, results per kg CW'!I39/Meat_yield -> 0 | J39: ='GHG detailed, results per kg CW'!J39/Meat_yield -> 0 | K39: ='GHG detailed, results per kg CW'!K39/Meat_yield -> 0 | L39: ='GHG detailed, results per kg CW'!L39/Meat_yield -> 0 | M39: ='GHG detailed, results per kg CW'!M39/Meat_yield -> 0 | N39: ='GHG detailed, results per kg CW'!N39/Meat_yield -> 0 | O39: ='GHG detailed, results per kg CW'!O39/Meat_yield -> 0 | P39: ='GHG detailed, results per kg CW'!P39/Meat_yield -> 0 | Q39: 0 | R39: ='GHG detailed, results per kg CW'!Q39/Meat_yield -> 0 | S39: ='GHG detailed, results per kg CW'!R39/Meat_yield -> 0.49009846 | T39: ='GHG detailed, results per kg CW'!S39/Meat_yield -> 0.12969459 | U39: ='GHG detailed, results per kg CW'!T39/Meat_yield -> 0 | V39: ='GHG detailed, results per kg CW'!U39/Meat_yield -> 0 | W39: ='GHG detailed, results per kg CW'!V39/Meat_yield -> 0 | X39: ='GHG detailed, results per kg CW'!W39/Meat_yield -> 0
A40: A01QV | B40: Bovine muscle | C40: Meat and meat products | D40: Italy | E40: IT | F40: N2O | G40: =SUM(H40:T40)+SUM(W40:X40) -> 0.027134204 | H40: ='GHG detailed, results per kg CW'!H40/Meat_yield -> 0.0021984519 | I40: ='GHG detailed, results per kg CW'!I40/Meat_yield -> 0 | J40: ='GHG detailed, results per kg CW'!J40/Meat_yield -> 0.011008013 | K40: ='GHG detailed, results per kg CW'!K40/Meat_yield -> 0.0011008013 | L40: ='GHG detailed, results per kg CW'!L40/Meat_yield -> 0 | M40: ='GHG detailed, results per kg CW'!M40/Meat_yield -> 0 | N40: ='GHG detailed, results per kg CW'!N40/Meat_yield -> 0 | O40: ='GHG detailed, results per kg CW'!O40/Meat_yield -> 0 | P40: ='GHG detailed, results per kg CW'!P40/Meat_yield -> 0 | Q40: 0 | R40: ='GHG detailed, results per kg CW'!Q40/Meat_yield -> 0 | S40: ='GHG detailed, results per kg CW'!R40/Meat_yield -> 0 | T40: ='GHG detailed, results per kg CW'!S40/Meat_yield -> 0.012826937 | U40: ='GHG detailed, results per kg CW'!T40/Meat_yield -> 0 | V40: ='GHG detailed, results per kg CW'!U40/Meat_yield -> 0 | W40: ='GHG detailed, results per kg CW'!V40/Meat_yield -> 0 | X40: ='GHG detailed, results per kg CW'!W40/Meat_yield -> 0
...

Sheet GHG detailed, results per kg CW
H1: * Production of mineral fertiliser is adjusted to account for the N supplied by manure.
A2: GHG emissions (per kg of meat carcass weight) | H2: ** Adjusted for use of manure instead of mineral fertiliser (lower emission factor for manure)
H3: *** Calculated as percentage of direct emissions due to assumption due to data limitations regarding nitrogen leaching and volatilization from soils in different regions.
R4: Animals | V4: Stables | W4: Slaughter
A5: Animal products | G5: Sum | H5: Inputs | J5: Soil emissions | L5: Energy use | P5: Land use change | Q5: Transports
A6: FoodEx code | B6: FoodEx name | C6: Food Ex category (L1) | D6: Country | E6: Country code | F6: Gas | G6: GHG | H6: Production of mineral fertilizer* | I6: Production of capital goods | J6: Direct emissions** | K6: Indirect emissions*** | L6: Diesel use field mach | M6: Energy use in greenhouses | N6: Energy use for irrigation | O6: Energy use for post-harvest proc | P6: LUC emissions | Q6: Feed transports | R6: Enteric fermentation* | S6: Manure management - tot | T6: Manure management - direct | U6: Manure management - indirect | V6: Energy use in stables | W6: Energy use for slaughter
