Workbook

Sheet INFO
A2: Wild foods
A4: Wild boar
A5: Source: | B5: Behaderovic, D., & Berglund, M. (2022). Klimatavtryck av vildsvinskött. Hushållningssällskapet Halland. https://hushallningssallskapet.se/wp-content/uploads/2023/10/rapport-klimatavtryck-av-vildsvinskott2022.pdf
C7: In CO2e | D7: In gases
A8: Jakt - transports | C8: 3.4
B9: CO2 | C9: =$C$8*E32/100 -> 3.3315826 | D9: =C9 -> 3.3315826
B10: CH4 | C10: =$C$8*E33/100 -> 0.043978207 | D10: =C10/29.8 -> 0.0014757787
B11: N2O | C11: =$C$8*E34/100 -> 0.024439212 | D11: =C11/273 -> 8.9520923e-05
A12: Feeding - utfodring | C12: 0.5
B13: CO2 | C13: =$C$12*E38/100 -> 0.19552218 | D13: =C13 -> 0.19552218
B14: CH4 | C14: =$C$12*E39/100 -> 0.0076241523 | D14: =C14/29.8 -> 0.00025584404
B15: N2O | C15: =$C$12*E40/100 -> 0.29685367 | D15: =C15/273 -> 0.0010873761
A16: Vildsvin - from the animal | C16: 0.1
B17: CO2 | C17: =$C$16*E44/100 -> 0 | D17: =C17 -> 0
B18: CH4 | C18: =$C$16*E45/100 -> 0.063807155 | D18: =C18/27 -> 0.002363228
B19: N2O | C19: =$C$16*E46/100 -> 0.036192845 | D19: =C19/273 -> 0.00013257452
A20: VHA - vilthantering - el och transport - assume same distribution as for diesel | C20: 0.8 | K20: Note! Total 4.85 so 4.8 not entirely correct in the table.
B21: CO2 | C21: =$C$20*E32/100 -> 0.78390178 | D21: =C21 -> 0.78390178 | F21: Allocation, %: | G21: 30
B22: CH4 | C22: =$C$20*E33/100 -> 0.010347813 | D22: =C22/29.8 -> 0.00034724206
B23: N2O | C23: =$C$20*E34/100 -> 0.0057504028 | D23: =C23/273 -> 2.1063747e-05
H24: Check | I24: =J27+K27*28.9+L27*27+M27*273 -> 4.798129
A25: Long code | B25: FoodEx2 code | C25: FoodEx2 name | D25: SUA code | E25: SUA name | F25: Category | G25: Country name | H25: Country code | I25: Carbon footprint, primary production | J25: Carbon dioxide, primary production | K25: Methane, fossil, primary production | L25: Methane, biogenic, primary production | M25: Nitrous oxide, primary production | N25: Land | O25: N input | P25: P input | Q25: Water | R25: Pesticides | S25: Biodiversity | T25: Ammonia | U25: Animal welfare | V25: Antibiotics | W25: Mineral fertiliser production (CO2e) | X25: Capital goods (CO2e) | Y25: Soil emissions (CO2e) | Z25: Energy primary production (CO2e) | AA25: Land use change (CO2e) | AB25: Enteric fermentation (CO2e) | AC25: Manure management (CO2e) | AD25: Mineral fertiliser production (CO2) | AE25: Capital goods (CO2) | AF25: Energy primary production (CO2) | AG25: Land use change (CO2) | AH25: Mineral fertiliser production (CH4, fossil) | AI25: Capital goods (CH4, fossil) | AJ25: Energy primary production (CH4, fossil) | AK25: Soil emissions (CH4, biogenic) | AL25: Enteric fermentation (CH4, biogenic) | AM25: Manure management (CH4, biogenic) | AN25: Mineral fertiliser production (N2O) | AO25: Capital goods (N2O) | AP25: Soil emissions (N2O) | AQ25: Energy primary production (N2O) | AR25: Manure management (N2O)
A26: Unallocated
A27: A.06.03.001 | B27: A01SH | C27: Wild boar fresh meat | D27: 21170.02 | E27: Game meat | F27: Wild foods | G27: Sweden | H27: SE | I27: =(C8+C12+C16+C20) -> 4.8 | J27: =(D9+D13+D17+D21) -> 4.3110065 | K27: =D10+D14+D22 -> 0.0020788648 | L27: =D18 -> 0.002363228 | M27: =(D11+D15+D19+D23) -> 0.0013305353 | N27: =$C$12*R39 -> 1.8222966 | O27: =$C$12*S39 -> 0.027881137 | P27: =$C$12*T39 -> 0.0025512152 | Q27: =$C$12*U39 -> 0 | R27: =$C$12*V39 -> 0.13484995 | S27: =$C$12*W39 -> 3.7286522e-14 | T27: =$C$12*X39 -> 0.0016950227 | U27: =$C$12*Y39 -> 0 | ... AE27: =$C$12*AI39 -> 0.032025586 | AF27: =$C$12*AJ39+D9+D21 -> 4.1915142 | AG27: =$C$12*AK39 -> 0 | AH27: =$C$12*AL39 -> 0.00011003744 | AI27: =$C$12*AM39 -> 0.00011268262 | AJ27: =$C$12*AN39+D10+D22 -> 0.0018561448 | AK27: =$C$12*AO39 -> 0 | AL27: =$C$12*AP39+D18 -> 0.002363228 | AM27: =$C$12*AQ39 -> 0 | AN27: =$C$12*AR39 -> 0.00018392245 | AO27: =$C$12*AS39 -> 1.3047461e-06 | AP27: =$C$12*AT39 -> 0.00089963136 | AQ27: =$C$12*AU39+D11+D23 -> 0.0001131022 | AR27: =$C$12*AV39+D19 -> 0.00013257452
A28: Allocated
A29: A.06.03.001 | B29: A01SH | C29: Wild boar fresh meat | D29: 21170.02 | E29: Game meat | F29: Wild foods | G29: Sweden | H29: SE | I29: =I27*$G$21/100 -> 1.44 | J29: =J27*$G$21/100 -> 1.293302 | K29: =K27*$G$21/100 -> 0.00062365945 | L29: =L27*$G$21/100 -> 0.00070896839 | M29: =M27*$G$21/100 -> 0.00039916058 | N29: =N27*$G$21/100 -> 0.54668897 | O29: =O27*$G$21/100 -> 0.0083643412 | P29: =P27*$G$21/100 -> 0.00076536455 | ... AR29: =AR27*$G$21/100 -> 3.9772357e-05
A31: Diesel | B31: EF | D31: In CO2e | E31: % | F31: Source
A32: CO2 | B32: 0.07592 | C32: kg CO2 per MJ | D32: =B32 -> 0.07592 | E32: =D32/$D$35*100 -> 97.987723 | F32: Gode et al. 2011
A33: CH4 | B33: 3.363e-05 | C33: kg CH4 per MJ | D33: =B33*29.8 -> 0.001002174 | E33: =D33/$D$35*100 -> 1.2934767 | F33: Gode et al. 2011
A34: N2O | B34: 2.04e-06 | C34: kg N2O per MJ | D34: =B34*273 -> 0.00055692 | E34: =D34/$D$35*100 -> 0.71880035 | F34: Gode et al. 2011
A35: Total | D35: =SUM(D32:D34) -> 0.077479094
A37: Wheat | B37: EF | D37: In CO2e | E37: % | F37: Source | H37: SUA code | I37: SUA name | J37: Category | K37: Country name | L37: Country code | M37: Carbon footprint, primary production | N37: Carbon dioxide, primary production | O37: Methane, fossil, primary production | P37: Methane, biogenic, primary production | Q37: Nitrous oxide, primary production | R37: Land | S37: N input | T37: P input | U37: Water | V37: Pesticides | W37: Biodiversity | X37: Ammonia | Y37: Animal welfare | Z37: Antibiotics | AA37: Mineral fertiliser production (CO2e) | AB37: Capital goods (CO2e) | AC37: Soil emissions (CO2e) | AD37: Energy primary production (CO2e) | AE37: Land use change (CO2e) | AF37: Enteric fermentation (CO2e) | AG37: Manure management (CO2e) | AH37: Mineral fertiliser production (CO2) | AI37: Capital goods (CO2) | AJ37: Energy primary production (CO2) | AK37: Land use change (CO2) | AL37: Mineral fertiliser production (CH4, fossil) | AM37: Capital goods (CH4, fossil) | AN37: Energy primary production (CH4, fossil) | AO37: Soil emissions (CH4, biogenic) | AP37: Enteric fermentation (CH4, biogenic) | AQ37: Manure management (CH4, biogenic) | AR37: Mineral fertiliser production (N2O) | AS37: Capital goods (N2O) | AT37: Soil emissions (N2O) | AU37: Energy primary production (N2O) | AV37: Manure management (N2O)
A38: CO2 | B38: 0.16484003 | C38: kg CO2 per kg | D38: =B38 -> 0.16484003 | E38: =D38/$D$41*100 -> 39.104435 | F38: SAFAD, wheat SE | H38: 0111 | I38: Wheat, average | J38: Cereals, incl feed | K38: Sweden | L38: SE | M38: 0.42153794927943045 | N38: 0.16484003368588274 | O38: 2.1569594254895508E-4 | P38: 0 | Q38: 9.1674057328054498E-4 | R38: 1.5363343063450607 | S38: 2.350591488707943E-2 | T38: 2.150868028883085E-3 | U38: 0 | V38: 0.11368873866953449 | W38: 3.14353683629948e-14 | X38: 1.4290327566282921E-3 | AA38: 0.11883715916280413 | AB38: 3.01313E-2 | AC38: 0.2070589 | AD38: 0.065510587 | AE38: 0 | AH38: 7.3741076533864705E-2 | AI38: 2.7E-2 | AJ38: 0.064098957 | AL38: 9.2769916609057948E-5 | AM38: 9.5000000000000005E-5 | AN38: 2.79260259398971e-05 | AR38: 1.5506058283512638E-4 | AS38: 1.1000000000000001E-6 | AT38: 0.00075845752 | AU38: 2.12247008898919e-06
A39: CH4 | B39: 0.00021569594 | C39: kg CH4 per MJ | D39: =B39*29.8 -> 0.0064277391 | E39: =D39/$D$41*100 -> 1.5248305 | F39: SAFAD, wheat SE | K39: Scaling factor: | M39: =M38/$M$38 -> 1 | N39: =N38/$M$38 -> 0.39104435 | O39: =O38/$M$38 -> 0.00051168808 | P39: =P38/$M$38 -> 0 | Q39: =Q38/$M$38 -> 0.0021747522 | R39: =R38/$M$38 -> 3.6445931 | S39: =S38/$M$38 -> 0.055762275 | T39: =T38/$M$38 -> 0.0051024304 | ... AV39: =AV38/$M$38 -> 0
A40: N2O | B40: 0.00091674057 | C40: kg N2O per MJ | D40: =B40*273 -> 0.25027018 | E40: =D40/$D$41*100 -> 59.370734 | F40: SAFAD, wheat SE
A41: Total | D41: =SUM(D38:D40) -> 0.42153795
A43: Pig meat | B43: EF - ent ferm+manure | D43: In CO2e | E43: % | F43: Source
A44: CO2 | C44: kg CO2 per kg | D44: =B44 -> 0 | E44: =D44/$D$47*100 -> 0 | F44: SAFAD, pig meat SE
A45: CH4 | B45: =0.00942446314340999+0.01286441904522 -> 0.022288882 | C45: kg CH4 per MJ | D45: =B45*27 -> 0.60179982 | E45: =D45/$D$47*100 -> 63.807155 | F45: SAFAD, pig meat SE
A46: N2O | B46: 0.0012503821 | C46: kg N2O per MJ | D46: =B46*273 -> 0.34135432 | E46: =D46/$D$47*100 -> 36.192845 | F46: SAFAD, pig meat SE
...

Sheet Wild foods
A1: Long code | B1: FoodEx2 code | C1: FoodEx2 name | D1: SUA code | E1: SUA name | F1: Category | G1: Country name | H1: Country code | I1: Carbon footprint, primary production | J1: Carbon dioxide, primary production | K1: Methane, fossil, primary production | L1: Methane, biogenic, primary production | M1: Nitrous oxide, primary production | N1: Land | O1: N input | P1: P input | Q1: Water | R1: Pesticides | S1: Biodiversity | T1: Ammonia | U1: Animal welfare | V1: Antibiotics | W1: Mineral fertiliser production (CO2e) | X1: Capital goods (CO2e) | Y1: Soil emissions (CO2e) | Z1: Energy primary production (CO2e) | AA1: Land use change (CO2e) | AB1: Enteric fermentation (CO2e) | AC1: Manure management (CO2e) | AD1: Mineral fertiliser production (CO2) | AE1: Capital goods (CO2) | AF1: Energy primary production (CO2) | AG1: Land use change (CO2) | AH1: Mineral fertiliser production (CH4, fossil) | AI1: Capital goods (CH4, fossil) | AJ1: Energy primary production (CH4, fossil) | AK1: Soil emissions (CH4, biogenic) | AL1: Enteric fermentation (CH4, biogenic) | AM1: Manure management (CH4, biogenic) | AN1: Mineral fertiliser production (N2O) | AO1: Capital goods (N2O) | AP1: Soil emissions (N2O) | AQ1: Energy primary production (N2O) | AR1: Manure management (N2O) | AS1: Direct Values (N-P-Diesel)
A2: A.06.04.005 | B2: A01TB | C2: Quail fresh meat | D2: 21170.02 | E2: Game meat | F2: Wild foods | G2: Sweden | H2: SE | I2: =INFO!I83 -> 1.26 | J2: =INFO!J83 -> 1.2346453 | K2: =INFO!K83 -> 0.00054690624 | L2: =INFO!L83 -> 0 | M2: =INFO!M83 -> 3.3175401e-05 | N2: =INFO!N83 -> 0 | O2: =INFO!O83 -> 0 | P2: =INFO!P83 -> 0 | ... AR2: =INFO!AR83 -> 0 | AS2: N/P/Diesel
A3: A.06.04.003 | B3: A01TG | C3: Mallard fresh meat | D3: 21170.02 | E3: Game meat | F3: Wild foods | G3: Sweden | H3: SE | I3: =INFO!I83 -> 1.26 | J3: =INFO!J83 -> 1.2346453 | K3: =INFO!K83 -> 0.00054690624 | L3: =INFO!L83 -> 0 | M3: =INFO!M83 -> 3.3175401e-05 | N3: =INFO!N83 -> 0 | O3: =INFO!O83 -> 0 | P3: =INFO!P83 -> 0 | ... AR3: =INFO!AR83 -> 0 | AS3: N/P/Diesel
A4: A.06.04.004 | B4: A01SY | C4: Partridge fresh meat | D4: 21170.02 | E4: Game meat | F4: Wild foods | G4: Sweden | H4: SE | I4: =INFO!I83 -> 1.26 | J4: =INFO!J83 -> 1.2346453 | K4: =INFO!K83 -> 0.00054690624 | L4: =INFO!L83 -> 0 | M4: =INFO!M83 -> 3.3175401e-05 | N4: =INFO!N83 -> 0 | O4: =INFO!O83 -> 0 | P4: =INFO!P83 -> 0 | ... AR4: =INFO!AR83 -> 0 | AS4: N/P/Diesel
A5: A.06.03.003 | B5: A01SE | C5: European moose meat | D5: 21170.02 | E5: Game meat | F5: Wild foods | G5: Sweden | H5: SE | I5: =INFO!I68 -> 24.345 | J5: =INFO!J68 -> 1.2346453 | K5: =INFO!K68 -> 0.00054690624 | L5: =INFO!L68 -> 0.855 | M5: =INFO!M68 -> 3.3175401e-05 | N5: =INFO!N68 -> 0 | O5: =INFO!O68 -> 0 | P5: =INFO!P68 -> 0 | ... AR5: =INFO!AR68 -> 0 | AS5: N/P/Diesel
A6: A.06.03.001 | B6: A01SH | C6: Wild boar fresh meat | D6: 21170.02 | E6: Game meat | F6: Wild foods | G6: Sweden | H6: SE | I6: =INFO!I29 -> 1.44 | J6: =INFO!J29 -> 1.293302 | K6: =INFO!K29 -> 0.00062365945 | L6: =INFO!L29 -> 0.00070896839 | M6: =INFO!M29 -> 0.00039916058 | N6: =INFO!N29 -> 0.54668897 | O6: =INFO!O29 -> 0.0083643412 | P6: =INFO!P29 -> 0.00076536455 | ... AR6: =INFO!AR29 -> 3.9772357e-05 | AS6: N/P/Diesel
A7: A.06.02.007 | B7: A01ST | C7: Ratites fresh meat | D7: 21170.02 | E7: Game meat | F7: Wild foods | G7: Sweden | H7: SE | I7: =INFO!I83 -> 1.26 | J7: =INFO!J83 -> 1.2346453 | K7: =INFO!K83 -> 0.00054690624 | L7: =INFO!L83 -> 0 | M7: =INFO!M83 -> 3.3175401e-05 | N7: =INFO!N83 -> 0 | O7: =INFO!O83 -> 0 | P7: =INFO!P83 -> 0 | ... AR7: =INFO!AR83 -> 0 | AS7: N/P/Diesel
A8: A.06.03.004 | B8: A01SF | C8: Reindeer meat | D8: 21170.02 | E8: Game meat | F8: Wild foods | G8: Sweden | H8: SE | I8: =INFO!I68 -> 24.345 | J8: =INFO!J68 -> 1.2346453 | K8: =INFO!K68 -> 0.00054690624 | L8: =INFO!L68 -> 0.855 | M8: =INFO!M68 -> 3.3175401e-05 | N8: =INFO!N68 -> 0 | O8: =INFO!O68 -> 0 | P8: =INFO!P68 -> 0 | ... AR8: =INFO!AR68 -> 0 | AS8: N/P/Diesel
A9: A.06.04.001 | B9: A01SZ | C9: Pheasant fresh meat | D9: 21170.02 | E9: Game meat | F9: Wild foods | G9: Sweden | H9: SE | I9: =INFO!I83 -> 1.26 | J9: =INFO!J83 -> 1.2346453 | K9: =INFO!K83 -> 0.00054690624 | L9: =INFO!L83 -> 0 | M9: =INFO!M83 -> 3.3175401e-05 | N9: =INFO!N83 -> 0 | O9: =INFO!O83 -> 0 | P9: =INFO!P83 -> 0 | ... AR9: =INFO!AR83 -> 0 | AS9: N/P/Diesel
A10: A.06.03.002 | B10: A01SC | C10: Deer, red fresh meat | D10: 21170.02 | E10: Game meat | F10: Wild foods | G10: Sweden | H10: SE | I10: =INFO!I68 -> 24.345 | J10: =INFO!J68 -> 1.2346453 | K10: =INFO!K68 -> 0.00054690624 | L10: =INFO!L68 -> 0.855 | M10: =INFO!M68 -> 3.3175401e-05 | N10: =INFO!N68 -> 0 | O10: =INFO!O68 -> 0 | P10: =INFO!P68 -> 0 | ... AR10: =INFO!AR68 -> 0 | AS10: N/P/Diesel
A11: A.06.04.005 | B11: A01TB | C11: Quail fresh meat | D11: 21170.02 | E11: Game meat | F11: Wild foods | G11: Rest of World | H11: RoW | I11: =I2 -> 1.26 | J11: =J2 -> 1.2346453 | K11: =K2 -> 0.00054690624 | L11: =L2 -> 0 | M11: =M2 -> 3.3175401e-05 | N11: =N2 -> 0 | O11: =O2 -> 0 | P11: =P2 -> 0 | ... AR11: =AR2 -> 0
A12: A.06.04.003 | B12: A01TG | C12: Mallard fresh meat | D12: 21170.02 | E12: Game meat | F12: Wild foods | G12: Rest of World | H12: RoW | I12: =I3 -> 1.26 | J12: =J3 -> 1.2346453 | K12: =K3 -> 0.00054690624 | L12: =L3 -> 0 | M12: =M3 -> 3.3175401e-05 | N12: =N3 -> 0 | O12: =O3 -> 0 | P12: =P3 -> 0 | ... AR12: =AR3 -> 0
A13: A.06.04.004 | B13: A01SY | C13: Partridge fresh meat | D13: 21170.02 | E13: Game meat | F13: Wild foods | G13: Rest of World | H13: RoW | I13: =I4 -> 1.26 | J13: =J4 -> 1.2346453 | K13: =K4 -> 0.00054690624 | L13: =L4 -> 0 | M13: =M4 -> 3.3175401e-05 | N13: =N4 -> 0 | O13: =O4 -> 0 | P13: =P4 -> 0 | ... AR13: =AR4 -> 0
A14: A.06.03.003 | B14: A01SE | C14: European moose meat | D14: 21170.02 | E14: Game meat | F14: Wild foods | G14: Rest of World | H14: RoW | I14: =I5 -> 24.345 | J14: =J5 -> 1.2346453 | K14: =K5 -> 0.00054690624 | L14: =L5 -> 0.855 | M14: =M5 -> 3.3175401e-05 | N14: =N5 -> 0 | O14: =O5 -> 0 | P14: =P5 -> 0 | ... AR14: =AR5 -> 0
A15: A.06.03.001 | B15: A01SH | C15: Wild boar fresh meat | D15: 21170.02 | E15: Game meat | F15: Wild foods | G15: Rest of World | H15: RoW | I15: =I6 -> 1.44 | J15: =J6 -> 1.293302 | K15: =K6 -> 0.00062365945 | L15: =L6 -> 0.00070896839 | M15: =M6 -> 0.00039916058 | N15: =N6 -> 0.54668897 | O15: =O6 -> 0.0083643412 | P15: =P6 -> 0.00076536455 | ... AR15: =AR6 -> 3.9772357e-05
A16: A.06.02.007 | B16: A01ST | C16: Ratites fresh meat | D16: 21170.02 | E16: Game meat | F16: Wild foods | G16: Rest of World | H16: RoW | I16: =I7 -> 1.26 | J16: =J7 -> 1.2346453 | K16: =K7 -> 0.00054690624 | L16: =L7 -> 0 | M16: =M7 -> 3.3175401e-05 | N16: =N7 -> 0 | O16: =O7 -> 0 | P16: =P7 -> 0 | ... AR16: =AR7 -> 0
A17: A.06.03.004 | B17: A01SF | C17: Reindeer meat | D17: 21170.02 | E17: Game meat | F17: Wild foods | G17: Rest of World | H17: RoW | I17: =I8 -> 24.345 | J17: =J8 -> 1.2346453 | K17: =K8 -> 0.00054690624 | L17: =L8 -> 0.855 | M17: =M8 -> 3.3175401e-05 | N17: =N8 -> 0 | O17: =O8 -> 0 | P17: =P8 -> 0 | ... AR17: =AR8 -> 0
A18: A.06.04.001 | B18: A01SZ | C18: Pheasant fresh meat | D18: 21170.02 | E18: Game meat | F18: Wild foods | G18: Rest of World | H18: RoW | I18: =I9 -> 1.26 | J18: =J9 -> 1.2346453 | K18: =K9 -> 0.00054690624 | L18: =L9 -> 0 | M18: =M9 -> 3.3175401e-05 | N18: =N9 -> 0 | O18: =O9 -> 0 | P18: =P9 -> 0 | ... AR18: =AR9 -> 0
A19: A.06.03.002 | B19: A01SC | C19: Deer, red fresh meat | D19: 21170.02 | E19: Game meat | F19: Wild foods | G19: Rest of World | H19: RoW | I19: =I10 -> 24.345 | J19: =J10 -> 1.2346453 | K19: =K10 -> 0.00054690624 | L19: =L10 -> 0.855 | M19: =M10 -> 3.3175401e-05 | N19: =N10 -> 0 | O19: =O10 -> 0 | P19: =P10 -> 0 | ... AR19: =AR10 -> 0

Sheet Sheet1
